Workbook

Sheet Overview
B2: Ticker
B3: Price | C3: =[1]Sheet1!$C$4 -> 103.45
B7: Units | C7: K
B11: PE | C11: =$C$3/'Statement Q'!$N$22 -> #DIV/0!
B12: PE adjusted | C12: =$C$3/Statements!S20 -> #DIV/0!
B13: PS | C13: =$C$3/('Statement Q'!$N$5/'Statement Q'!$N$20) -> #DIV/0!
B15: Market cap | C15: =C3*'Statement Q'!N116 -> 0
B16: Cash | C16: =Statements!S23 -> 0
B17: Debt | C17: ='Statement Q'!N47 -> 0
B18: EV | C18: =C15+C17-C16 -> 0
B19: Cash per share | C19: =C16/'Statement Q'!J116 -> #DIV/0!
B21: CAGR 10y Revenue | C21: =_xlfn.RRI(5,Statements!C5,Statements!H5) -> 0
B22: YoY Net income | C22: =(Statements!H18-Statements!C18)/ABS(Statements!C18) -> #DIV/0!
B23: YoY EPS | C23: =(Statements!H20-Statements!C20)/ABS(Statements!C20) -> #DIV/0!
B28: Notes
B29: For ownership shearch in the proxy statement for: "Security Ownership of Certain Beneficial Owners and Management"
B30: Calculate insider ownership: ClassA + ClassB held by insiders/Total classA + classB shares
B31: The total share number is on the 10-K/Q front page
B33: Shares held by insiders
B34: Total shares | C34: ='Statement Y'!H113 -> 0
B35: Insider % | C35: =C33/C34 -> #DIV/0!
B37: ROIC = NOPAT/Invested capital
B38: NOPAT = EBIT * (1-tax rate)
B39: Invested capital = (Total assets - Cash and equivalents) -non-interest bearing current liabilities
B40: NIBCL usually are accounts payable and accrued expenses and other operating items that do not have interest attached
B41: NIBCL does not include any sort of debt
B42: An easier denominator is Total debt + Equity -Cash
B44: NOPAT | C44: =Statements!S12*(1-'Statement Y'!G117) -> #DIV/0!
B45: Debt
B46: Equity
B47: Cash
B48: ROIC | C48: =C44/(C45+C46-C47) -> #DIV/0!

Sheet Financials ->
B13: Financials ->

Sheet Statement Y
B2: Date | C2: 31.12.2020 | D2: 31.12.2021 | E2: 30.09.2022 | F2: 31.12.2023 | G2: 31.12.2024 | H2: 31.12.2025
B3: FY | C3: 2020 | D3: =C3+1 -> 2021 | E3: =D3+1 -> 2022 | F3: =E3+1 -> 2023 | G3: =F3+1 -> 2024 | H3: =G3+1 -> 2025 | I3: =H3+1 -> 2026 | J3: =I3+1 -> 2027 | K3: =J3+1 -> 2028 | L3: =K3+1 -> 2029
B4: Income statement
B5: Revenue
B6: COGS
B7: Gross Profit | C7: =C5-C6 -> 0 | D7: =D5-D6 -> 0 | E7: =E5-E6 -> 0 | F7: =F5-F6 -> 0 | G7: =G5-G6 -> 0 | H7: =H5-H6 -> 0 | I7: =I5-I6 -> 0 | J7: =J5-J6 -> 0 | ... L7: =L5-L6 -> 0
B8: R&D
B9: Sales and marketing
B10: General and administrative
B11: OpEx | C11: =SUM(C8:C10) -> 0 | D11: =SUM(D8:D10) -> 0 | E11: =SUM(E8:E10) -> 0 | F11: =SUM(F8:F10) -> 0 | G11: =SUM(G8:G10) -> 0 | H11: =SUM(H8:H10) -> 0 | I11: =SUM(I8:I10) -> 0 | J11: =SUM(J8:J10) -> 0 | ... L11: =SUM(L8:L10) -> 0
B12: Operating income
B13: Other income
B14: Other expense
B15: Interest income
B16: Income before taxes
B17: Income tax expense/benefit
B18: Net income
B19: Basic Shares outstanding avg
B20: Diluted Shares outstanding avg
B21: Basic EPS
B22: Diluted EPS
B24: Balance sheet
... B39: Other assets
B40: Long term assets | C40: =SUM(C32:C39) -> 0 | D40: =SUM(D32:D39) -> 0 | E40: =SUM(E32:E39) -> 0 | F40: =SUM(F32:F39) -> 0 | G40: =SUM(G32:G39) -> 0 | H40: =SUM(H32:H39) -> 0 | I40: =SUM(I32:I39) -> 0 | J40: =SUM(J32:J39) -> 0 | ... L40: =SUM(L32:L39) -> 0
B41: Total assets
B42: Acc payable
B43: Deferred revenues
B44: Income tax payable
B45: Accrued expenses and other current
B46: Current liabilities
B47: Long term obligation operating lease
B48: Deferred tax liabilities
B49: Long term liabilities | C49: =SUM(C47:C48) -> 0 | D49: =SUM(D47:D48) -> 0 | E49: =SUM(E47:E48) -> 0 | F49: =SUM(F47:F48) -> 0 | G49: =SUM(G47:G48) -> 0 | H49: =SUM(H47:H48) -> 0 | I49: =SUM(I47:I48) -> 0 | J49: =SUM(J47:J48) -> 0 | ... L49: =SUM(L47:L48) -> 0
B50: Total liabilities
B51: Common stock par value
B52: Additional paid-in capital
B53: Retained earnings
B54: Stockholder equity
B55: Total liabilities and equity
B57: Cashflow statement
...

Sheet Statement Q
B2: Date | C2: 31.03.2024 | D2: 30.06.2024 | E2: 30.09.2024 | F2: 31.12.2024 | G2: 31.03.2025 | H2: 30.06.2025 | I2: 30.09.2025 | J2: 31.12.2025
B3: Q | C3: Q1 2024 | D3: Q2 2024 | E3: Q3 2024 | F3: Q4 2024 | G3: Q1 2025 | H3: Q2 2025 | I3: Q3 2025 | J3: Q4 2025 | P3: =I3 -> Q3 2025 | Q3: =J3 -> Q4 2025 | R3: Growth Rate
B4: Income statement | N4: TTM | P4: Quarter compare
B5: Revenue | N5: =SUM(G5:J5) -> 0 | P5: =I5 -> 0 | Q5: =J5 -> 0 | R5: =IF(P5=0, IF(Q5=0,0,IF(Q5>0,1,-1)), (Q5-P5)/ABS(P5) ) -> 0
B6: COGS | N6: =SUM(G6:J6) -> 0 | P6: =I6 -> 0 | Q6: =J6 -> 0 | R6: =IF(P6=0, IF(Q6=0,0,IF(Q6>0,1,-1)), (Q6-P6)/ABS(P6) ) -> 0
B7: Gross Profit | C7: =C5-C6 -> 0 | D7: =D5-D6 -> 0 | E7: =E5-E6 -> 0 | F7: =F5-F6 -> 0 | G7: =G5-G6 -> 0 | H7: =H5-H6 -> 0 | I7: =I5-I6 -> 0 | J7: =J5-J6 -> 0 | N7: =SUM(G7:J7) -> 0 | P7: =I7 -> 0 | Q7: =J7 -> 0 | R7: =IF(P7=0, IF(Q7=0,0,IF(Q7>0,1,-1)), (Q7-P7)/ABS(P7) ) -> 0
B8: R&D | N8: =SUM(G8:J8) -> 0 | P8: =I8 -> 0 | Q8: =J8 -> 0 | R8: =IF(P8=0, IF(Q8=0,0,IF(Q8>0,1,-1)), (Q8-P8)/ABS(P8) ) -> 0
B9: Sales and marketing | N9: =SUM(G9:J9) -> 0 | P9: =I9 -> 0 | Q9: =J9 -> 0 | R9: =IF(P9=0, IF(Q9=0,0,IF(Q9>0,1,-1)), (Q9-P9)/ABS(P9) ) -> 0
B10: General and administrative | N10: =SUM(G10:J10) -> 0 | P10: =I10 -> 0 | Q10: =J10 -> 0 | R10: =IF(P10=0, IF(Q10=0,0,IF(Q10>0,1,-1)), (Q10-P10)/ABS(P10) ) -> 0
B11: OpEx | C11: =SUM(C8:C10) -> 0 | D11: =SUM(D8:D10) -> 0 | E11: =SUM(E8:E10) -> 0 | F11: =SUM(F8:F10) -> 0 | G11: =SUM(G8:G10) -> 0 | H11: =SUM(H8:H10) -> 0 | I11: =SUM(I8:I10) -> 0 | J11: =SUM(J8:J10) -> 0 | N11: =SUM(G11:J11) -> 0 | P11: =I11 -> 0 | Q11: =J11 -> 0 | R11: =IF(P11=0, IF(Q11=0,0,IF(Q11>0,1,-1)), (Q11-P11)/ABS(P11) ) -> 0
B12: Operating income | N12: =SUM(G12:J12) -> 0 | P12: =I12 -> 0 | Q12: =J12 -> 0 | R12: =IF(P12=0, IF(Q12=0,0,IF(Q12>0,1,-1)), (Q12-P12)/ABS(P12) ) -> 0
B13: Other income | N13: =SUM(G13:J13) -> 0 | P13: =I13 -> 0 | Q13: =J13 -> 0 | R13: =IF(P13=0, IF(Q13=0,0,IF(Q13>0,1,-1)), (Q13-P13)/ABS(P13) ) -> 0
B14: Other expense | N14: =SUM(G14:J14) -> 0 | P14: =I14 -> 0 | Q14: =J14 -> 0 | R14: =IF(P14=0, IF(Q14=0,0,IF(Q14>0,1,-1)), (Q14-P14)/ABS(P14) ) -> 0
B15: Interest income | N15: =SUM(G15:J15) -> 0 | P15: =I15 -> 0 | Q15: =J15 -> 0 | R15: =IF(P15=0, IF(Q15=0,0,IF(Q15>0,1,-1)), (Q15-P15)/ABS(P15) ) -> 0
B16: Income before taxes | N16: =SUM(G16:J16) -> 0 | P16: =I16 -> 0 | Q16: =J16 -> 0 | R16: =IF(P16=0, IF(Q16=0,0,IF(Q16>0,1,-1)), (Q16-P16)/ABS(P16) ) -> 0
B17: Income tax expense/benefit | N17: =SUM(G17:J17) -> 0 | P17: =I17 -> 0 | Q17: =J17 -> 0 | R17: =IF(P17=0, IF(Q17=0,0,IF(Q17>0,1,-1)), (Q17-P17)/ABS(P17) ) -> 0
B18: Net income | N18: =SUM(G18:J18) -> 0 | P18: =I18 -> 0 | Q18: =J18 -> 0 | R18: =IF(P18=0, IF(Q18=0,0,IF(Q18>0,1,-1)), (Q18-P18)/ABS(P18) ) -> 0
B19: Basic Shares outstanding avg | N19: =AVERAGE(G19:J19) -> #DIV/0! | P19: =I19 -> 0 | Q19: =J19 -> 0 | R19: =IF(P19=0, IF(Q19=0,0,IF(Q19>0,1,-1)), (Q19-P19)/ABS(P19) ) -> 0
B20: Diluted Shares outstanding avg | N20: =AVERAGE((G20:J20)) -> #DIV/0! | P20: =I20 -> 0 | Q20: =J20 -> 0 | R20: =IF(P20=0, IF(Q20=0,0,IF(Q20>0,1,-1)), (Q20-P20)/ABS(P20) ) -> 0
B21: Basic EPS | N21: =N18/N19 -> #DIV/0! | P21: =I21 -> 0 | Q21: =J21 -> 0 | R21: =IF(P21=0, IF(Q21=0,0,IF(Q21>0,1,-1)), (Q21-P21)/ABS(P21) ) -> 0
B22: Diluted EPS | N22: =N18/N20 -> #DIV/0! | P22: =I22 -> 0 | Q22: =J22 -> 0 | R22: =IF(P22=0, IF(Q22=0,0,IF(Q22>0,1,-1)), (Q22-P22)/ABS(P22) ) -> 0
B24: Balance sheet
B25: Cash and cash equivalents | N25: =J25 -> 0
B26: Short-term investments | N26: =J26 -> 0
B27: Acc receivable | N27: =J27 -> 0
B28: Deferred cost of revenues | N28: =J28 -> 0
B29: Income tax receivable | N29: =J29 -> 0
B30: Prepaid expenses & Other current assets | N30: =J30 -> 0
B31: Current assets | N31: =J31 -> 0
B32: PP&E | N32: =J32 -> 0
B33: Goodwill | N33: =J33 -> 0
B34: Intangible assets | N34: =J34 -> 0
B35: Operating lease right of use | N35: =J35 -> 0
B36: Long term investments | N36: =J36 -> 0
... B39: Other assets | N39: =J39 -> 0
B40: Long term assets | C40: =SUM(C32:C39) -> 0 | D40: =SUM(D32:D39) -> 0 | E40: =SUM(E32:E39) -> 0 | F40: =SUM(F32:F39) -> 0 | G40: =SUM(G32:G39) -> 0 | H40: =SUM(H32:H39) -> 0 | I40: =SUM(I32:I39) -> 0 | J40: =SUM(J32:J39) -> 0 | N40: =J40 -> 0
B41: Total assets | N41: =J41 -> 0
B42: Acc payable | N42: =J42 -> 0
B43: Deferred revenues | N43: =J43 -> 0
B44: Income tax payable | N44: =J44 -> 0
...

Sheet Statements
B2: Date | C2: ='Statement Y'!C2 -> 31.12.2020 | D2: ='Statement Y'!D2 -> 31.12.2021 | E2: ='Statement Y'!E2 -> 30.09.2022 | F2: ='Statement Y'!F2 -> 31.12.2023 | G2: ='Statement Y'!G2 -> 31.12.2024 | H2: ='Statement Y'!H2 -> 31.12.2025 | J2: ='Statement Q'!C2 -> 31.03.2024 | K2: ='Statement Q'!D2 -> 30.06.2024 | L2: ='Statement Q'!E2 -> 30.09.2024 | M2: ='Statement Q'!F2 -> 31.12.2024 | N2: ='Statement Q'!G2 -> 31.03.2025 | O2: ='Statement Q'!H2 -> 30.06.2025 | P2: ='Statement Q'!I2 -> 30.09.2025 | Q2: ='Statement Q'!J2 -> 31.12.2025
B3: FY | C3: ='Statement Y'!C3 -> 2020 | D3: ='Statement Y'!D3 -> 2021 | E3: ='Statement Y'!E3 -> 2022 | F3: ='Statement Y'!F3 -> 2023 | G3: ='Statement Y'!G3 -> 2024 | H3: ='Statement Y'!H3 -> 2025 | J3: ='Statement Q'!C3 -> Q1 2024 | K3: ='Statement Q'!D3 -> Q2 2024 | L3: ='Statement Q'!E3 -> Q3 2024 | M3: ='Statement Q'!F3 -> Q4 2024 | N3: ='Statement Q'!G3 -> Q1 2025 | O3: ='Statement Q'!H3 -> Q2 2025 | P3: ='Statement Q'!I3 -> Q3 2025 | Q3: ='Statement Q'!J3 -> Q4 2025 | S3: TTM
B4: Income statement
B5: Revenue | C5: ='Statement Y'!C5 -> 0 | D5: ='Statement Y'!D5 -> 0 | E5: ='Statement Y'!E5 -> 0 | F5: ='Statement Y'!F5 -> 0 | G5: ='Statement Y'!G5 -> 0 | H5: ='Statement Y'!H5 -> 0 | J5: ='Statement Q'!C5 -> 0 | K5: ='Statement Q'!D5 -> 0 | L5: ='Statement Q'!E5 -> 0 | M5: ='Statement Q'!F5 -> 0 | N5: ='Statement Q'!G5 -> 0 | O5: ='Statement Q'!H5 -> 0 | P5: ='Statement Q'!I5 -> 0 | Q5: ='Statement Q'!J5 -> 0 | S5: =SUM(N5:Q5) -> 0
B6: COGS | C6: ='Statement Y'!C6 -> 0 | D6: ='Statement Y'!D6 -> 0 | E6: ='Statement Y'!E6 -> 0 | F6: ='Statement Y'!F6 -> 0 | G6: ='Statement Y'!G6 -> 0 | H6: ='Statement Y'!H6 -> 0 | J6: ='Statement Q'!C6 -> 0 | K6: ='Statement Q'!D6 -> 0 | L6: ='Statement Q'!E6 -> 0 | M6: ='Statement Q'!F6 -> 0 | N6: ='Statement Q'!G6 -> 0 | O6: ='Statement Q'!H6 -> 0 | P6: ='Statement Q'!I6 -> 0 | Q6: ='Statement Q'!J6 -> 0 | S6: =SUM(N6:Q6) -> 0
B7: Gross Profit | C7: ='Statement Y'!C7 -> 0 | D7: ='Statement Y'!D7 -> 0 | E7: ='Statement Y'!E7 -> 0 | F7: ='Statement Y'!F7 -> 0 | G7: ='Statement Y'!G7 -> 0 | H7: ='Statement Y'!H7 -> 0 | J7: ='Statement Q'!C7 -> 0 | K7: ='Statement Q'!D7 -> 0 | L7: ='Statement Q'!E7 -> 0 | M7: ='Statement Q'!F7 -> 0 | N7: ='Statement Q'!G7 -> 0 | O7: ='Statement Q'!H7 -> 0 | P7: ='Statement Q'!I7 -> 0 | Q7: ='Statement Q'!J7 -> 0 | S7: =SUM(N7:Q7) -> 0
B8: R&D | C8: ='Statement Y'!C8 -> 0 | D8: ='Statement Y'!D8 -> 0 | E8: ='Statement Y'!E8 -> 0 | F8: ='Statement Y'!F8 -> 0 | G8: ='Statement Y'!G8 -> 0 | H8: ='Statement Y'!H8 -> 0 | J8: ='Statement Q'!C8 -> 0 | K8: ='Statement Q'!D8 -> 0 | L8: ='Statement Q'!E8 -> 0 | M8: ='Statement Q'!F8 -> 0 | N8: ='Statement Q'!G8 -> 0 | O8: ='Statement Q'!H8 -> 0 | P8: ='Statement Q'!I8 -> 0 | Q8: ='Statement Q'!J8 -> 0 | S8: =SUM(N8:Q8) -> 0
B9: Sales and marketing | C9: ='Statement Y'!C9 -> 0 | D9: ='Statement Y'!D9 -> 0 | E9: ='Statement Y'!E9 -> 0 | F9: ='Statement Y'!F9 -> 0 | G9: ='Statement Y'!G9 -> 0 | H9: ='Statement Y'!H9 -> 0 | J9: ='Statement Q'!C9 -> 0 | K9: ='Statement Q'!D9 -> 0 | L9: ='Statement Q'!E9 -> 0 | M9: ='Statement Q'!F9 -> 0 | N9: ='Statement Q'!G9 -> 0 | O9: ='Statement Q'!H9 -> 0 | P9: ='Statement Q'!I9 -> 0 | Q9: ='Statement Q'!J9 -> 0 | S9: =SUM(N9:Q9) -> 0
B10: General and administrative | C10: ='Statement Y'!C10 -> 0 | D10: ='Statement Y'!D10 -> 0 | E10: ='Statement Y'!E10 -> 0 | F10: ='Statement Y'!F10 -> 0 | G10: ='Statement Y'!G10 -> 0 | H10: ='Statement Y'!H10 -> 0 | J10: ='Statement Q'!C10 -> 0 | K10: ='Statement Q'!D10 -> 0 | L10: ='Statement Q'!E10 -> 0 | M10: ='Statement Q'!F10 -> 0 | N10: ='Statement Q'!G10 -> 0 | O10: ='Statement Q'!H10 -> 0 | P10: ='Statement Q'!I10 -> 0 | Q10: ='Statement Q'!J10 -> 0 | S10: =SUM(N10:Q10) -> 0
B11: OpEx | C11: ='Statement Y'!C11 -> 0 | D11: ='Statement Y'!D11 -> 0 | E11: ='Statement Y'!E11 -> 0 | F11: ='Statement Y'!F11 -> 0 | G11: ='Statement Y'!G11 -> 0 | H11: ='Statement Y'!H11 -> 0 | J11: ='Statement Q'!C11 -> 0 | K11: ='Statement Q'!D11 -> 0 | L11: ='Statement Q'!E11 -> 0 | M11: ='Statement Q'!F11 -> 0 | N11: ='Statement Q'!G11 -> 0 | O11: ='Statement Q'!H11 -> 0 | P11: ='Statement Q'!I11 -> 0 | Q11: ='Statement Q'!J11 -> 0 | S11: =SUM(N11:Q11) -> 0
B12: Operating income | C12: ='Statement Y'!C12 -> 0 | D12: ='Statement Y'!D12 -> 0 | E12: ='Statement Y'!E12 -> 0 | F12: ='Statement Y'!F12 -> 0 | G12: ='Statement Y'!G12 -> 0 | H12: ='Statement Y'!H12 -> 0 | J12: ='Statement Q'!C12 -> 0 | K12: ='Statement Q'!D12 -> 0 | L12: ='Statement Q'!E12 -> 0 | M12: ='Statement Q'!F12 -> 0 | N12: ='Statement Q'!G12 -> 0 | O12: ='Statement Q'!H12 -> 0 | P12: ='Statement Q'!I12 -> 0 | Q12: ='Statement Q'!J12 -> 0 | S12: =SUM(N12:Q12) -> 0
B13: EBITDA | C13: =C12+C56 -> 0 | D13: =D12+D56 -> 0 | E13: =E12+E56 -> 0 | F13: =F12+F56 -> 0 | G13: =G12+G56 -> 0 | H13: =H12+H56 -> 0 | J13: =J12+J56 -> 0 | K13: =K12+K56 -> 0 | L13: =L12+L56 -> 0 | M13: =M12+M56 -> 0 | N13: =N12+N56 -> 0 | O13: =O12+O56 -> 0 | P13: =P12+P56 -> 0 | Q13: =Q12+Q56 -> 0 | S13: =SUM(N13:Q13) -> 0
B14: Other income/expense | C14: ='Statement Y'!C13+'Statement Y'!C14 -> 0 | D14: ='Statement Y'!D13+'Statement Y'!D14 -> 0 | E14: ='Statement Y'!E13+'Statement Y'!E14 -> 0 | F14: ='Statement Y'!F13+'Statement Y'!F14 -> 0 | G14: ='Statement Y'!G13+'Statement Y'!G14 -> 0 | H14: ='Statement Y'!H13+'Statement Y'!H14 -> 0 | J14: ='Statement Q'!C13+'Statement Q'!C14 -> 0 | K14: ='Statement Q'!D13+'Statement Q'!D14 -> 0 | L14: ='Statement Q'!E13+'Statement Q'!E14 -> 0 | M14: ='Statement Q'!F13+'Statement Q'!F14 -> 0 | N14: ='Statement Q'!G13+'Statement Q'!G14 -> 0 | O14: ='Statement Q'!H13+'Statement Q'!H14 -> 0 | P14: ='Statement Q'!I13+'Statement Q'!I14 -> 0 | Q14: ='Statement Q'!J13+'Statement Q'!J14 -> 0 | S14: =SUM(N14:Q14) -> 0
B15: Interest income/expense | C15: ='Statement Y'!C15 -> 0 | D15: ='Statement Y'!D15 -> 0 | E15: ='Statement Y'!E15 -> 0 | F15: ='Statement Y'!F15 -> 0 | G15: ='Statement Y'!G15 -> 0 | H15: ='Statement Y'!H15 -> 0 | J15: ='Statement Q'!C15 -> 0 | K15: ='Statement Q'!D15 -> 0 | L15: ='Statement Q'!E15 -> 0 | M15: ='Statement Q'!F15 -> 0 | N15: ='Statement Q'!G15 -> 0 | O15: ='Statement Q'!H15 -> 0 | P15: ='Statement Q'!I15 -> 0 | Q15: ='Statement Q'!J15 -> 0 | S15: =SUM(N15:Q15) -> 0
B16: Income before taxes | C16: ='Statement Y'!C16 -> 0 | D16: ='Statement Y'!D16 -> 0 | E16: ='Statement Y'!E16 -> 0 | F16: ='Statement Y'!F16 -> 0 | G16: ='Statement Y'!G16 -> 0 | H16: ='Statement Y'!H16 -> 0 | J16: ='Statement Q'!C16 -> 0 | K16: ='Statement Q'!D16 -> 0 | L16: ='Statement Q'!E16 -> 0 | M16: ='Statement Q'!F16 -> 0 | N16: ='Statement Q'!G16 -> 0 | O16: ='Statement Q'!H16 -> 0 | P16: ='Statement Q'!I16 -> 0 | Q16: ='Statement Q'!J16 -> 0 | S16: =SUM(N16:Q16) -> 0
B17: Income tax expense/benefit | C17: ='Statement Y'!C17 -> 0 | D17: ='Statement Y'!D17 -> 0 | E17: ='Statement Y'!E17 -> 0 | F17: ='Statement Y'!F17 -> 0 | G17: ='Statement Y'!G17 -> 0 | H17: ='Statement Y'!H17 -> 0 | J17: ='Statement Q'!C17 -> 0 | K17: ='Statement Q'!D17 -> 0 | L17: ='Statement Q'!E17 -> 0 | M17: ='Statement Q'!F17 -> 0 | N17: ='Statement Q'!G17 -> 0 | O17: ='Statement Q'!H17 -> 0 | P17: ='Statement Q'!I17 -> 0 | Q17: ='Statement Q'!J17 -> 0 | S17: =SUM(N17:Q17) -> 0
B18: Net income | C18: ='Statement Y'!C18 -> 0 | D18: ='Statement Y'!D18 -> 0 | E18: ='Statement Y'!E18 -> 0 | F18: ='Statement Y'!F18 -> 0 | G18: ='Statement Y'!G18 -> 0 | H18: ='Statement Y'!H18 -> 0 | J18: ='Statement Q'!C18 -> 0 | K18: ='Statement Q'!D18 -> 0 | L18: ='Statement Q'!E18 -> 0 | M18: ='Statement Q'!F18 -> 0 | N18: ='Statement Q'!G18 -> 0 | O18: ='Statement Q'!H18 -> 0 | P18: ='Statement Q'!I18 -> 0 | Q18: ='Statement Q'!J18 -> 0 | S18: =SUM(N18:Q18) -> 0
B19: Diluted Shares outstanding avg | C19: ='Statement Y'!C20 -> 0 | D19: ='Statement Y'!D20 -> 0 | E19: ='Statement Y'!E20 -> 0 | F19: ='Statement Y'!F20 -> 0 | G19: ='Statement Y'!G20 -> 0 | H19: ='Statement Y'!H20 -> 0 | J19: ='Statement Q'!C20 -> 0 | K19: ='Statement Q'!D20 -> 0 | L19: ='Statement Q'!E20 -> 0 | M19: ='Statement Q'!F20 -> 0 | N19: ='Statement Q'!G20 -> 0 | O19: ='Statement Q'!H20 -> 0 | P19: ='Statement Q'!I20 -> 0 | Q19: ='Statement Q'!J20 -> 0 | S19: =AVERAGE(N19:Q19) -> 0
B20: Diluted EPS | C20: ='Statement Y'!C22 -> 0 | D20: ='Statement Y'!D22 -> 0 | E20: ='Statement Y'!E22 -> 0 | F20: ='Statement Y'!F22 -> 0 | G20: ='Statement Y'!G22 -> 0 | H20: ='Statement Y'!H22 -> 0 | J20: ='Statement Q'!C22 -> 0 | K20: ='Statement Q'!D22 -> 0 | L20: ='Statement Q'!E22 -> 0 | M20: ='Statement Q'!F22 -> 0 | N20: ='Statement Q'!G22 -> 0 | O20: ='Statement Q'!H22 -> 0 | P20: ='Statement Q'!I22 -> 0 | Q20: ='Statement Q'!J22 -> 0 | S20: =S18/S19 -> #DIV/0!
B22: Balance sheet
B23: Cash and cash equivalents | C23: ='Statement Y'!C25+'Statement Y'!C26 -> 0 | D23: ='Statement Y'!D25+'Statement Y'!D26 -> 0 | E23: ='Statement Y'!E25+'Statement Y'!E26 -> 0 | F23: ='Statement Y'!F25+'Statement Y'!F26 -> 0 | G23: ='Statement Y'!G25+'Statement Y'!G26 -> 0 | H23: ='Statement Y'!H25+'Statement Y'!H26 -> 0 | J23: ='Statement Q'!C25+'Statement Q'!C26 -> 0 | K23: ='Statement Q'!D25+'Statement Q'!D26 -> 0 | L23: ='Statement Q'!E25+'Statement Q'!E26 -> 0 | M23: ='Statement Q'!F25+'Statement Q'!F26 -> 0 | N23: ='Statement Q'!G25+'Statement Q'!G26 -> 0 | O23: ='Statement Q'!H25+'Statement Q'!H26 -> 0 | P23: ='Statement Q'!I25+'Statement Q'!I26 -> 0 | Q23: ='Statement Q'!J25+'Statement Q'!J26 -> 0 | S23: =Q23 -> 0
B24: Acc receivable | C24: ='Statement Y'!C27 -> 0 | D24: ='Statement Y'!D27 -> 0 | E24: ='Statement Y'!E27 -> 0 | F24: ='Statement Y'!F27 -> 0 | G24: ='Statement Y'!G27 -> 0 | H24: ='Statement Y'!H27 -> 0 | J24: ='Statement Q'!C27 -> 0 | K24: ='Statement Q'!D27 -> 0 | L24: ='Statement Q'!E27 -> 0 | M24: ='Statement Q'!F27 -> 0 | N24: ='Statement Q'!G27 -> 0 | O24: ='Statement Q'!H27 -> 0 | P24: ='Statement Q'!I27 -> 0 | Q24: ='Statement Q'!J27 -> 0 | S24: =Q24 -> 0
B25: Deferred cost of revenues | C25: ='Statement Y'!C28 -> 0 | D25: ='Statement Y'!D28 -> 0 | E25: ='Statement Y'!E28 -> 0 | F25: ='Statement Y'!F28 -> 0 | G25: ='Statement Y'!G28 -> 0 | H25: ='Statement Y'!H28 -> 0 | J25: ='Statement Q'!C28 -> 0 | K25: ='Statement Q'!D28 -> 0 | L25: ='Statement Q'!E28 -> 0 | M25: ='Statement Q'!F28 -> 0 | N25: ='Statement Q'!G28 -> 0 | O25: ='Statement Q'!H28 -> 0 | P25: ='Statement Q'!I28 -> 0 | Q25: ='Statement Q'!J28 -> 0 | S25: =Q25 -> 0
B26: Income tax receivable | C26: ='Statement Y'!C29 -> 0 | D26: ='Statement Y'!D29 -> 0 | E26: ='Statement Y'!E29 -> 0 | F26: ='Statement Y'!F29 -> 0 | G26: ='Statement Y'!G29 -> 0 | H26: ='Statement Y'!H29 -> 0 | J26: ='Statement Q'!C29 -> 0 | K26: ='Statement Q'!D29 -> 0 | L26: ='Statement Q'!E29 -> 0 | M26: ='Statement Q'!F29 -> 0 | N26: ='Statement Q'!G29 -> 0 | O26: ='Statement Q'!H29 -> 0 | P26: ='Statement Q'!I29 -> 0 | Q26: ='Statement Q'!J29 -> 0 | S26: =Q26 -> 0
B27: Prepaid expenses & Other current assets | C27: ='Statement Y'!C30 -> 0 | D27: ='Statement Y'!D30 -> 0 | E27: ='Statement Y'!E30 -> 0 | F27: ='Statement Y'!F30 -> 0 | G27: ='Statement Y'!G30 -> 0 | H27: ='Statement Y'!H30 -> 0 | J27: ='Statement Q'!C30 -> 0 | K27: ='Statement Q'!D30 -> 0 | L27: ='Statement Q'!E30 -> 0 | M27: ='Statement Q'!F30 -> 0 | N27: ='Statement Q'!G30 -> 0 | O27: ='Statement Q'!H30 -> 0 | P27: ='Statement Q'!I30 -> 0 | Q27: ='Statement Q'!J30 -> 0 | S27: =Q27 -> 0
B28: Current assets | C28: ='Statement Y'!C31 -> 0 | D28: ='Statement Y'!D31 -> 0 | E28: ='Statement Y'!E31 -> 0 | F28: ='Statement Y'!F31 -> 0 | G28: ='Statement Y'!G31 -> 0 | H28: ='Statement Y'!H31 -> 0 | J28: ='Statement Q'!C31 -> 0 | K28: ='Statement Q'!D31 -> 0 | L28: ='Statement Q'!E31 -> 0 | M28: ='Statement Q'!F31 -> 0 | N28: ='Statement Q'!G31 -> 0 | O28: ='Statement Q'!H31 -> 0 | P28: ='Statement Q'!I31 -> 0 | Q28: ='Statement Q'!J31 -> 0 | S28: =Q28 -> 0
B29: PP&E | C29: ='Statement Y'!C32 -> 0 | D29: ='Statement Y'!D32 -> 0 | E29: ='Statement Y'!E32 -> 0 | F29: ='Statement Y'!F32 -> 0 | G29: ='Statement Y'!G32 -> 0 | H29: ='Statement Y'!H32 -> 0 | J29: ='Statement Q'!C32 -> 0 | K29: ='Statement Q'!D32 -> 0 | L29: ='Statement Q'!E32 -> 0 | M29: ='Statement Q'!F32 -> 0 | N29: ='Statement Q'!G32 -> 0 | O29: ='Statement Q'!H32 -> 0 | P29: ='Statement Q'!I32 -> 0 | Q29: ='Statement Q'!J32 -> 0 | S29: =Q29 -> 0
B30: Goodwill | C30: ='Statement Y'!C33 -> 0 | D30: ='Statement Y'!D33 -> 0 | E30: ='Statement Y'!E33 -> 0 | F30: ='Statement Y'!F33 -> 0 | G30: ='Statement Y'!G33 -> 0 | H30: ='Statement Y'!H33 -> 0 | J30: ='Statement Q'!C33 -> 0 | K30: ='Statement Q'!D33 -> 0 | L30: ='Statement Q'!E33 -> 0 | M30: ='Statement Q'!F33 -> 0 | N30: ='Statement Q'!G33 -> 0 | O30: ='Statement Q'!H33 -> 0 | P30: ='Statement Q'!I33 -> 0 | Q30: ='Statement Q'!J33 -> 0 | S30: =Q30 -> 0
B31: Intangible assets | C31: ='Statement Y'!C34 -> 0 | D31: ='Statement Y'!D34 -> 0 | E31: ='Statement Y'!E34 -> 0 | F31: ='Statement Y'!F34 -> 0 | G31: ='Statement Y'!G34 -> 0 | H31: ='Statement Y'!H34 -> 0 | J31: ='Statement Q'!C34 -> 0 | K31: ='Statement Q'!D34 -> 0 | L31: ='Statement Q'!E34 -> 0 | M31: ='Statement Q'!F34 -> 0 | N31: ='Statement Q'!G34 -> 0 | O31: ='Statement Q'!H34 -> 0 | P31: ='Statement Q'!I34 -> 0 | Q31: ='Statement Q'!J34 -> 0 | S31: =Q31 -> 0
B32: Operating lease right of use | C32: ='Statement Y'!C35 -> 0 | D32: ='Statement Y'!D35 -> 0 | E32: ='Statement Y'!E35 -> 0 | F32: ='Statement Y'!F35 -> 0 | G32: ='Statement Y'!G35 -> 0 | H32: ='Statement Y'!H35 -> 0 | J32: ='Statement Q'!C35 -> 0 | K32: ='Statement Q'!D35 -> 0 | L32: ='Statement Q'!E35 -> 0 | M32: ='Statement Q'!F35 -> 0 | N32: ='Statement Q'!G35 -> 0 | O32: ='Statement Q'!H35 -> 0 | P32: ='Statement Q'!I35 -> 0 | Q32: ='Statement Q'!J35 -> 0 | S32: =Q32 -> 0
B33: Long term investments | C33: ='Statement Y'!C36 -> 0 | D33: ='Statement Y'!D36 -> 0 | E33: ='Statement Y'!E36 -> 0 | F33: ='Statement Y'!F36 -> 0 | G33: ='Statement Y'!G36 -> 0 | H33: ='Statement Y'!H36 -> 0 | J33: ='Statement Q'!C36 -> 0 | K33: ='Statement Q'!D36 -> 0 | L33: ='Statement Q'!E36 -> 0 | M33: ='Statement Q'!F36 -> 0 | N33: ='Statement Q'!G36 -> 0 | O33: ='Statement Q'!H36 -> 0 | P33: ='Statement Q'!I36 -> 0 | Q33: ='Statement Q'!J36 -> 0 | S33: =Q33 -> 0
B34: Deferred tax assets | C34: ='Statement Y'!C37 -> 0 | D34: ='Statement Y'!D37 -> 0 | E34: ='Statement Y'!E37 -> 0 | F34: ='Statement Y'!F37 -> 0 | G34: ='Statement Y'!G37 -> 0 | H34: ='Statement Y'!H37 -> 0 | J34: ='Statement Q'!C37 -> 0 | K34: ='Statement Q'!D37 -> 0 | L34: ='Statement Q'!E37 -> 0 | M34: ='Statement Q'!F37 -> 0 | N34: ='Statement Q'!G37 -> 0 | O34: ='Statement Q'!H37 -> 0 | P34: ='Statement Q'!I37 -> 0 | Q34: ='Statement Q'!J37 -> 0 | S34: =Q34 -> 0
B35: Restricted cash | C35: ='Statement Y'!C38 -> 0 | D35: ='Statement Y'!D38 -> 0 | E35: ='Statement Y'!E38 -> 0 | F35: ='Statement Y'!F38 -> 0 | G35: ='Statement Y'!G38 -> 0 | H35: ='Statement Y'!H38 -> 0 | J35: ='Statement Q'!C38 -> 0 | K35: ='Statement Q'!D38 -> 0 | L35: ='Statement Q'!E38 -> 0 | M35: ='Statement Q'!F38 -> 0 | N35: ='Statement Q'!G38 -> 0 | O35: ='Statement Q'!H38 -> 0 | P35: ='Statement Q'!I38 -> 0 | Q35: ='Statement Q'!J38 -> 0 | S35: =Q35 -> 0
... B52: Total liabilities and equity | C52: ='Statement Y'!C55 -> 0 | D52: ='Statement Y'!D55 -> 0 | E52: ='Statement Y'!E55 -> 0 | F52: ='Statement Y'!F55 -> 0 | G52: ='Statement Y'!G55 -> 0 | H52: ='Statement Y'!H55 -> 0 | J52: ='Statement Q'!C55 -> 0 | K52: ='Statement Q'!D55 -> 0 | L52: ='Statement Q'!E55 -> 0 | M52: ='Statement Q'!F55 -> 0 | N52: ='Statement Q'!G55 -> 0 | O52: ='Statement Q'!H55 -> 0 | P52: ='Statement Q'!I55 -> 0 | Q52: ='Statement Q'!J55 -> 0 | S52: =Q52 -> 0
B54: Cashflow statement
B55: Net income | C55: ='Statement Y'!C58 -> 0 | D55: ='Statement Y'!D58 -> 0 | E55: ='Statement Y'!E58 -> 0 | F55: ='Statement Y'!F58 -> 0 | G55: ='Statement Y'!G58 -> 0 | H55: ='Statement Y'!H58 -> 0 | J55: ='Statement Q'!C58 -> 0 | K55: ='Statement Q'!D58 -> 0 | L55: ='Statement Q'!E58 -> 0 | M55: ='Statement Q'!F58 -> 0 | N55: ='Statement Q'!G58 -> 0 | O55: ='Statement Q'!H58 -> 0 | P55: ='Statement Q'!I58 -> 0 | Q55: ='Statement Q'!J58 -> 0 | S55: =SUM(N55:Q55) -> 0
B56: D&A | C56: ='Statement Y'!C59 -> 0 | D56: ='Statement Y'!D59 -> 0 | E56: ='Statement Y'!E59 -> 0 | F56: ='Statement Y'!F59 -> 0 | G56: ='Statement Y'!G59 -> 0 | H56: ='Statement Y'!H59 -> 0 | J56: ='Statement Q'!C59 -> 0 | K56: ='Statement Q'!D59 -> 0 | L56: ='Statement Q'!E59 -> 0 | M56: ='Statement Q'!F59 -> 0 | N56: ='Statement Q'!G59 -> 0 | O56: ='Statement Q'!H59 -> 0 | P56: ='Statement Q'!I59 -> 0 | Q56: ='Statement Q'!J59 -> 0 | S56: =SUM(N56:Q56) -> 0
B57: Deferred income taxes | C57: ='Statement Y'!C60 -> 0 | D57: ='Statement Y'!D60 -> 0 | E57: ='Statement Y'!E60 -> 0 | F57: ='Statement Y'!F60 -> 0 | G57: ='Statement Y'!G60 -> 0 | H57: ='Statement Y'!H60 -> 0 | J57: ='Statement Q'!C60 -> 0 | K57: ='Statement Q'!D60 -> 0 | L57: ='Statement Q'!E60 -> 0 | M57: ='Statement Q'!F60 -> 0 | N57: ='Statement Q'!G60 -> 0 | O57: ='Statement Q'!H60 -> 0 | P57: ='Statement Q'!I60 -> 0 | Q57: ='Statement Q'!J60 -> 0 | S57: =SUM(N57:Q57) -> 0
B58: Stock-based compensation | C58: ='Statement Y'!C61 -> 0 | D58: ='Statement Y'!D61 -> 0 | E58: ='Statement Y'!E61 -> 0 | F58: ='Statement Y'!F61 -> 0 | G58: ='Statement Y'!G61 -> 0 | H58: ='Statement Y'!H61 -> 0 | J58: ='Statement Q'!C61 -> 0 | K58: ='Statement Q'!D61 -> 0 | L58: ='Statement Q'!E61 -> 0 | M58: ='Statement Q'!F61 -> 0 | N58: ='Statement Q'!G61 -> 0 | O58: ='Statement Q'!H61 -> 0 | P58: ='Statement Q'!I61 -> 0 | Q58: ='Statement Q'!J61 -> 0 | S58: =SUM(N58:Q58) -> 0
B59: Accretion on marketable securitirs | C59: ='Statement Y'!C62 -> 0 | D59: ='Statement Y'!D62 -> 0 | E59: ='Statement Y'!E62 -> 0 | F59: ='Statement Y'!F62 -> 0 | G59: ='Statement Y'!G62 -> 0 | H59: ='Statement Y'!H62 -> 0 | J59: ='Statement Q'!C62 -> 0 | K59: ='Statement Q'!D62 -> 0 | L59: ='Statement Q'!E62 -> 0 | M59: ='Statement Q'!F62 -> 0 | N59: ='Statement Q'!G62 -> 0 | O59: ='Statement Q'!H62 -> 0 | P59: ='Statement Q'!I62 -> 0 | Q59: ='Statement Q'!J62 -> 0 | S59: =SUM(N59:Q59) -> 0
...

Sheet Forecast ->
B13: Forecast ->

Sheet Revenue
B1: Revenue forecast
C2: History | H2: Forecast | S2: History | AA2: Forecast | AE2: TTM
C4: Revenues | S4: Revenues | AE4: Q1-Q2-Q3
B5: Revenues (thousand) | C5: ='Statement Y'!D3 -> 2021 | D5: ='Statement Y'!E3 -> 2022 | E5: ='Statement Y'!F3 -> 2023 | F5: ='Statement Y'!G3 -> 2024 | G5: ='Statement Y'!H3 -> 2025 | H5: =G5+1 -> 2026 | I5: =H5+1 -> 2027 | J5: =I5+1 -> 2028 | K5: =J5+1 -> 2029 | L5: =K5+1 -> 2030 | R5: Revenues (thousand) | S5: ='Statement Q'!C3 -> Q1 2024 | T5: ='Statement Q'!D3 -> Q2 2024 | U5: ='Statement Q'!E3 -> Q3 2024 | V5: ='Statement Q'!F3 -> Q4 2024 | W5: ='Statement Q'!G3 -> Q1 2025 | X5: ='Statement Q'!H3 -> Q2 2025 | Y5: ='Statement Q'!I3 -> Q3 2025 | Z5: ='Statement Q'!J3 -> Q4 2025 | AA5: FQ1 | AB5: FQ2 | AC5: FQ3 | AE5: FQ1
B6: ='Statement Y'!#REF! -> #REF! | C6: ='Statement Y'!#REF! -> #REF! | D6: ='Statement Y'!#REF! -> #REF! | E6: ='Statement Y'!#REF! -> #REF! | F6: ='Statement Y'!#REF! -> #REF! | G6: ='Statement Y'!#REF! -> #REF! | H6: =H39*H36 -> #REF! | I6: =I39*I36 -> #REF! | J6: =J39*J36 -> #REF! | K6: =K39*K36 -> #REF! | L6: =L39*L36 -> #REF! | N6: Avg revenue/Paid user * Paid subscribers | Q6: Avg revenue/Paid user * Paid subscribers | R6: ='Statement Q'!#REF! -> #REF! | S6: ='Statement Q'!#REF! -> #REF! | T6: ='Statement Q'!#REF! -> #REF! | U6: ='Statement Q'!#REF! -> #REF! | V6: ='Statement Q'!#REF! -> #REF! | W6: ='Statement Q'!#REF! -> #REF! | X6: ='Statement Q'!#REF! -> #REF! | Y6: ='Statement Q'!#REF! -> #REF! | Z6: ='Statement Q'!#REF! -> #REF! | AA6: =AA39*AA36 -> #REF! | AE6: =SUM(X6:AA6) -> #REF!
B7: ='Statement Y'!#REF! -> #REF! | C7: ='Statement Y'!#REF! -> #REF! | D7: ='Statement Y'!#REF! -> #REF! | E7: ='Statement Y'!#REF! -> #REF! | F7: ='Statement Y'!#REF! -> #REF! | G7: ='Statement Y'!#REF! -> #REF! | H7: =H37*H33 -> #REF! | I7: =I37*I33 -> #REF! | J7: =J37*J33 -> #REF! | K7: =K37*K33 -> #REF! | L7: =L37*L33 -> #REF! | N7: Free users * Ad revenue/Free user | Q7: Free users * Ad revenue/Free user | R7: ='Statement Q'!#REF! -> #REF! | S7: ='Statement Q'!#REF! -> #REF! | T7: ='Statement Q'!#REF! -> #REF! | U7: ='Statement Q'!#REF! -> #REF! | V7: ='Statement Q'!#REF! -> #REF! | W7: ='Statement Q'!#REF! -> #REF! | X7: ='Statement Q'!#REF! -> #REF! | Y7: ='Statement Q'!#REF! -> #REF! | Z7: ='Statement Q'!#REF! -> #REF! | AA7: =AA37*AA33 -> #REF! | AE7: =SUM(X7:AA7) -> #REF!
B8: ='Statement Y'!#REF! -> #REF! | C8: ='Statement Y'!#REF! -> #REF! | D8: ='Statement Y'!#REF! -> #REF! | E8: ='Statement Y'!#REF! -> #REF! | F8: ='Statement Y'!#REF! -> #REF! | G8: ='Statement Y'!#REF! -> #REF! | H8: =G8*(1+H27) -> #REF! | I8: =H8*(1+I27) -> #REF! | J8: =I8*(1+J27) -> #REF! | K8: =J8*(1+K27) -> #REF! | L8: =K8*(1+L27) -> #REF! | N8: English test growth rate | Q8: English test growth rate | R8: ='Statement Q'!#REF! -> #REF! | S8: ='Statement Q'!#REF! -> #REF! | T8: ='Statement Q'!#REF! -> #REF! | U8: ='Statement Q'!#REF! -> #REF! | V8: ='Statement Q'!#REF! -> #REF! | W8: ='Statement Q'!#REF! -> #REF! | X8: ='Statement Q'!#REF! -> #REF! | Y8: ='Statement Q'!#REF! -> #REF! | Z8: ='Statement Q'!#REF! -> #REF! | AA8: =Z8*(1+AA27) -> #REF! | AE8: =SUM(X8:AA8) -> #REF!
B9: ='Statement Y'!#REF! -> #REF! | C9: ='Statement Y'!#REF! -> #REF! | D9: ='Statement Y'!#REF! -> #REF! | E9: ='Statement Y'!#REF! -> #REF! | F9: ='Statement Y'!#REF! -> #REF! | G9: ='Statement Y'!#REF! -> #REF! | H9: =H29*H38 -> #REF! | I9: =I29*I38 -> #REF! | J9: =J29*J38 -> #REF! | K9: =K29*K38 -> #REF! | L9: =L29*L38 -> #REF! | N9: DAU * In-app purchases % of DAU | Q9: DAU * In-app purchases % of DAU | R9: ='Statement Q'!#REF! -> #REF! | S9: ='Statement Q'!#REF! -> #REF! | T9: ='Statement Q'!#REF! -> #REF! | U9: ='Statement Q'!#REF! -> #REF! | V9: ='Statement Q'!#REF! -> #REF! | W9: ='Statement Q'!#REF! -> #REF! | X9: ='Statement Q'!#REF! -> #REF! | Y9: ='Statement Q'!#REF! -> #REF! | Z9: ='Statement Q'!#REF! -> #REF! | AA9: =AA29*AA38 -> #REF! | AE9: =SUM(X9:AA9) -> #REF!
B10: ='Statement Y'!#REF! -> #REF! | C10: ='Statement Y'!#REF! -> #REF! | D10: ='Statement Y'!#REF! -> #REF! | E10: ='Statement Y'!#REF! -> #REF! | F10: ='Statement Y'!#REF! -> #REF! | G10: ='Statement Y'!#REF! -> #REF! | H10: =G10*(1+H28) -> #REF! | I10: =H10*(1+I28) -> #REF! | J10: =I10*(1+J28) -> #REF! | K10: =J10*(1+K28) -> #REF! | L10: =K10*(1+L28) -> #REF! | N10: Other growth rate | Q10: Other growth rate | R10: ='Statement Q'!#REF! -> #REF! | S10: ='Statement Q'!#REF! -> #REF! | T10: ='Statement Q'!#REF! -> #REF! | U10: ='Statement Q'!#REF! -> #REF! | V10: ='Statement Q'!#REF! -> #REF! | W10: ='Statement Q'!#REF! -> #REF! | X10: ='Statement Q'!#REF! -> #REF! | Y10: ='Statement Q'!#REF! -> #REF! | Z10: ='Statement Q'!#REF! -> #REF! | AA10: =Z10*(1+AA28) -> #REF! | AE10: =SUM(X10:AA10) -> #REF!
B11: ='Statement Y'!#REF! -> #REF! | C11: ='Statement Y'!#REF! -> #REF! | D11: ='Statement Y'!#REF! -> #REF! | E11: ='Statement Y'!#REF! -> #REF! | F11: ='Statement Y'!#REF! -> #REF! | G11: ='Statement Y'!#REF! -> #REF! | H11: =SUM(H7:H10) -> #REF! | I11: =SUM(I7:I10) -> #REF! | J11: =SUM(J7:J10) -> #REF! | K11: =SUM(K7:K10) -> #REF! | L11: =SUM(L7:L10) -> #REF! | R11: ='Statement Q'!#REF! -> #REF! | S11: ='Statement Q'!#REF! -> #REF! | T11: ='Statement Q'!#REF! -> #REF! | U11: ='Statement Q'!#REF! -> #REF! | V11: ='Statement Q'!#REF! -> #REF! | W11: ='Statement Q'!#REF! -> #REF! | X11: ='Statement Q'!#REF! -> #REF! | Y11: ='Statement Q'!#REF! -> #REF! | Z11: ='Statement Q'!#REF! -> #REF! | AA11: =SUM(AA7:AA10) -> #REF! | AB11: =SUM(AB7:AB10) -> 0 | AC11: =SUM(AC7:AC10) -> 0 | AE11: =SUM(AE7:AE10) -> #REF!
B12: Total | C12: ='Statement Y'!D5 -> 0 | D12: ='Statement Y'!E5 -> 0 | E12: ='Statement Y'!F5 -> 0 | F12: ='Statement Y'!G5 -> 0 | G12: ='Statement Y'!H5 -> 0 | H12: =H6+H11 -> #REF! | I12: =I6+I11 -> #REF! | J12: =J6+J11 -> #REF! | K12: =K6+K11 -> #REF! | L12: =L6+L11 -> #REF! | R12: Total | S12: ='Statement Q'!C5 -> 0 | T12: ='Statement Q'!D5 -> 0 | U12: ='Statement Q'!E5 -> 0 | V12: ='Statement Q'!F5 -> 0 | W12: ='Statement Q'!G5 -> 0 | X12: ='Statement Q'!H5 -> 0 | Y12: ='Statement Q'!I5 -> 0 | Z12: ='Statement Q'!J5 -> 0 | AA12: =AA6+AA11 -> #REF! | AB12: =AB6+AB11 -> 0 | AC12: =AC6+AC11 -> 0 | AE12: =AE6+AE11 -> #REF!
C14: Growth rates | S14: Growth rates
B15: Revenue growth % | C15: =C5 -> 2021 | D15: =D5 -> 2022 | E15: =E5 -> 2023 | F15: =F5 -> 2024 | G15: =G5 -> 2025 | H15: =H5 -> 2026 | I15: =I5 -> 2027 | J15: =J5 -> 2028 | ... L15: =L5 -> 2030 | R15: Revenue growth % | S15: =S5 -> Q1 2024 | T15: =T5 -> Q2 2024 | U15: =U5 -> Q3 2024 | V15: =V5 -> Q4 2024 | W15: =W5 -> Q1 2025 | X15: =X5 -> Q2 2025 | Y15: =Y5 -> Q3 2025 | Z15: =Z5 -> Q4 2025 | ... AC15: =AC5 -> FQ3
B16: =B6 -> #REF! | D16: =D6/C6-1 -> #REF! | E16: =E6/D6-1 -> #REF! | F16: =F6/E6-1 -> #REF! | G16: =G6/F6-1 -> #REF! | H16: =H6/G6-1 -> #REF! | I16: =I6/H6-1 -> #REF! | J16: =J6/I6-1 -> #REF! | K16: =K6/J6-1 -> #REF! | L16: =L6/K6-1 -> #REF! | R16: =R6 -> #REF! | T16: =T6/S6-1 -> #REF! | U16: =U6/T6-1 -> #REF! | V16: =V6/U6-1 -> #REF! | W16: =W6/V6-1 -> #REF! | X16: =X6/W6-1 -> #REF! | Y16: =Y6/X6-1 -> #REF! | Z16: =Z6/Y6-1 -> #REF! | AA16: =AA6/Z6-1 -> #REF!
B17: =B7 -> #REF! | D17: =D7/C7-1 -> #REF! | E17: =E7/D7-1 -> #REF! | F17: =F7/E7-1 -> #REF! | G17: =G7/F7-1 -> #REF! | H17: =H7/G7-1 -> #REF! | I17: =I7/H7-1 -> #REF! | J17: =J7/I7-1 -> #REF! | K17: =K7/J7-1 -> #REF! | L17: =L7/K7-1 -> #REF! | R17: =R7 -> #REF! | T17: =T7/S7-1 -> #REF! | U17: =U7/T7-1 -> #REF! | V17: =V7/U7-1 -> #REF! | W17: =W7/V7-1 -> #REF! | X17: =X7/W7-1 -> #REF! | Y17: =Y7/X7-1 -> #REF! | Z17: =Z7/Y7-1 -> #REF! | AA17: =AA7/Z7-1 -> #REF!
B18: =B8 -> #REF! | D18: =D8/C8-1 -> #REF! | E18: =E8/D8-1 -> #REF! | F18: =F8/E8-1 -> #REF! | G18: =G8/F8-1 -> #REF! | H18: =H8/G8-1 -> #REF! | I18: =I8/H8-1 -> #REF! | J18: =J8/I8-1 -> #REF! | K18: =K8/J8-1 -> #REF! | L18: =L8/K8-1 -> #REF! | R18: =R8 -> #REF! | T18: =T8/S8-1 -> #REF! | U18: =U8/T8-1 -> #REF! | V18: =V8/U8-1 -> #REF! | W18: =W8/V8-1 -> #REF! | X18: =X8/W8-1 -> #REF! | Y18: =Y8/X8-1 -> #REF! | Z18: =Z8/Y8-1 -> #REF! | AA18: =AA8/Z8-1 -> #REF!
B19: =B9 -> #REF! | D19: =D9/C9-1 -> #REF! | E19: =E9/D9-1 -> #REF! | F19: =F9/E9-1 -> #REF! | G19: =G9/F9-1 -> #REF! | H19: =H9/G9-1 -> #REF! | I19: =I9/H9-1 -> #REF! | J19: =J9/I9-1 -> #REF! | K19: =K9/J9-1 -> #REF! | L19: =L9/K9-1 -> #REF! | R19: =R9 -> #REF! | T19: =T9/S9-1 -> #REF! | U19: =U9/T9-1 -> #REF! | V19: =V9/U9-1 -> #REF! | W19: =W9/V9-1 -> #REF! | X19: =X9/W9-1 -> #REF! | Y19: =Y9/X9-1 -> #REF! | Z19: =Z9/Y9-1 -> #REF! | AA19: =AA9/Z9-1 -> #REF!
B20: =B10 -> #REF! | D20: =D10/C10-1 -> #REF! | E20: =E10/D10-1 -> #REF! | F20: =F10/E10-1 -> #REF! | G20: =G10/F10-1 -> #REF! | H20: =H10/G10-1 -> #REF! | I20: =I10/H10-1 -> #REF! | J20: =J10/I10-1 -> #REF! | K20: =K10/J10-1 -> #REF! | L20: =L10/K10-1 -> #REF! | R20: =R10 -> #REF! | T20: =T10/S10-1 -> #REF! | U20: =U10/T10-1 -> #REF! | V20: =V10/U10-1 -> #REF! | W20: =W10/V10-1 -> #REF! | X20: =X10/W10-1 -> #REF! | Y20: =Y10/X10-1 -> #REF! | Z20: =Z10/Y10-1 -> #REF! | AA20: =AA10/Z10-1 -> #REF!
B21: =B11 -> #REF! | D21: =D11/C11-1 -> #REF! | E21: =E11/D11-1 -> #REF! | F21: =F11/E11-1 -> #REF! | G21: =G11/F11-1 -> #REF! | H21: =H11/G11-1 -> #REF! | I21: =I11/H11-1 -> #REF! | J21: =J11/I11-1 -> #REF! | K21: =K11/J11-1 -> #REF! | L21: =L11/K11-1 -> #REF! | R21: =R11 -> #REF! | T21: =T11/S11-1 -> #REF! | U21: =U11/T11-1 -> #REF! | V21: =V11/U11-1 -> #REF! | W21: =W11/V11-1 -> #REF! | X21: =X11/W11-1 -> #REF! | Y21: =Y11/X11-1 -> #REF! | Z21: =Z11/Y11-1 -> #REF! | AA21: =AA11/Z11-1 -> #REF!
B22: =B12 -> Total | D22: =D12/C12-1 -> #DIV/0! | E22: =E12/D12-1 -> #DIV/0! | F22: =F12/E12-1 -> #DIV/0! | G22: =G12/F12-1 -> #DIV/0! | H22: =H12/G12-1 -> #REF! | I22: =I12/H12-1 -> #REF! | J22: =J12/I12-1 -> #REF! | K22: =K12/J12-1 -> #REF! | L22: =L12/K12-1 -> #REF! | R22: =R12 -> Total | T22: =T12/S12-1 -> #DIV/0! | U22: =U12/T12-1 -> #DIV/0! | V22: =V12/U12-1 -> #DIV/0! | W22: =W12/V12-1 -> #DIV/0! | X22: =X12/W12-1 -> #DIV/0! | Y22: =Y12/X12-1 -> #DIV/0! | Z22: =Z12/Y12-1 -> #DIV/0! | AA22: =AA12/Z12-1 -> #REF!
C25: Drivers and metrics | S25: Drivers and metrics | AE25: =AE4 -> Q1-Q2-Q3
B26: Metric (thousand) | C26: =C5 -> 2021 | D26: =D5 -> 2022 | E26: =E5 -> 2023 | F26: =F5 -> 2024 | G26: =G5 -> 2025 | H26: =H5 -> 2026 | I26: =I5 -> 2027 | J26: =J5 -> 2028 | ... L26: =L5 -> 2030 | R26: Metric (thousand) | S26: =S5 -> Q1 2024 | T26: =T5 -> Q2 2024 | U26: =U5 -> Q3 2024 | V26: =V5 -> Q4 2024 | W26: =W5 -> Q1 2025 | X26: =X5 -> Q2 2025 | Y26: =Y5 -> Q3 2025 | Z26: =Z5 -> Q4 2025 | ... AC26: =AC5 -> FQ3 | AE26: =AE5 -> FQ1
B27: English test growth rate | D27: =D18 -> #REF! | E27: =E18 -> #REF! | F27: =F18 -> #REF! | G27: =G18 -> #REF! | H27: -0.05 | I27: -0.02 | J27: 0.03 | K27: 0.06 | L27: 0.08 | R27: English test growth rate | T27: =T18 -> #REF! | U27: =U18 -> #REF! | V27: =V18 -> #REF! | W27: =W18 -> #REF! | X27: =X18 -> #REF! | Y27: =Y18 -> #REF! | Z27: =Z18 -> #REF! | AA27: 0.01
B28: Other growth rate | D28: =D20 -> #REF! | E28: =E20 -> #REF! | F28: =F20 -> #REF! | G28: =G20 -> #REF! | H28: 0.45 | I28: 0.35 | J28: 0.3 | K28: 0.25 | L28: 0.2 | R28: Other growth rate | T28: =T19 -> #REF! | U28: =U19 -> #REF! | V28: =V19 -> #REF! | W28: =W19 -> #REF! | X28: =X19 -> #REF! | Y28: =Y19 -> #REF! | Z28: =Z19 -> #REF! | AA28: 0.04
B29: DAU | C29: ='Statement Y'!#REF! -> #REF! | D29: ='Statement Y'!#REF! -> #REF! | E29: ='Statement Y'!#REF! -> #REF! | F29: ='Statement Y'!#REF! -> #REF! | G29: ='Statement Y'!#REF! -> #REF! | H29: =G29*(1+H31) -> #REF! | I29: =H29*(1+I31) -> #REF! | J29: =I29*(1+J31) -> #REF! | K29: =J29*(1+K31) -> #REF! | L29: =K29*(1+L31) -> #REF! | N29: DAU growth rate | Q29: DAU growth rate | R29: DAU | S29: ='Statement Q'!#REF! -> #REF! | T29: ='Statement Q'!#REF! -> #REF! | U29: ='Statement Q'!#REF! -> #REF! | V29: ='Statement Q'!#REF! -> #REF! | W29: ='Statement Q'!#REF! -> #REF! | X29: ='Statement Q'!#REF! -> #REF! | Y29: ='Statement Q'!#REF! -> #REF! | Z29: ='Statement Q'!#REF! -> #REF! | AA29: =Z29*(1+AA31) -> #REF! | AE29: =AA29 -> #REF!
B30: MAU | C30: ='Statement Y'!#REF! -> #REF! | D30: ='Statement Y'!#REF! -> #REF! | E30: ='Statement Y'!#REF! -> #REF! | F30: ='Statement Y'!#REF! -> #REF! | G30: ='Statement Y'!#REF! -> #REF! | H30: =G30*(1+H32) -> #REF! | I30: =H30*(1+I32) -> #REF! | J30: =I30*(1+J32) -> #REF! | K30: =J30*(1+K32) -> #REF! | L30: =K30*(1+L32) -> #REF! | N30: MAU growth rate | Q30: MAU growth rate | R30: MAU | S30: ='Statement Q'!#REF! -> #REF! | T30: ='Statement Q'!#REF! -> #REF! | U30: ='Statement Q'!#REF! -> #REF! | V30: ='Statement Q'!#REF! -> #REF! | W30: ='Statement Q'!#REF! -> #REF! | X30: ='Statement Q'!#REF! -> #REF! | Y30: ='Statement Q'!#REF! -> #REF! | Z30: ='Statement Q'!#REF! -> #REF! | AA30: =Z30*(1+AA32) -> #REF! | AE30: =AA30 -> #REF!
B31: DAU growth rate | D31: =D29/C29-1 -> #REF! | E31: =E29/D29-1 -> #REF! | F31: =F29/E29-1 -> #REF! | G31: =G29/F29-1 -> #REF! | H31: 0.35 | I31: 0.37 | J31: 0.39 | K31: 0.41 | L31: 0.39 | R31: DAU growth rate | T31: =T29/S29-1 -> #REF! | U31: =U29/T29-1 -> #REF! | V31: =V29/U29-1 -> #REF! | W31: =W29/V29-1 -> #REF! | X31: =X29/W29-1 -> #REF! | Y31: =Y29/X29-1 -> #REF! | Z31: =Z29/Y29-1 -> #REF! | AA31: 0.06
B32: MAU growth rate | D32: =D30/C30-1 -> #REF! | E32: =E30/D30-1 -> #REF! | F32: =F30/E30-1 -> #REF! | G32: =G30/F30-1 -> #REF! | H32: 0.19 | I32: 0.26 | J32: 0.24 | K32: 0.28 | L32: 0.31 | R32: MAU growth rate | T32: =T30/S30-1 -> #REF! | U32: =U30/T30-1 -> #REF! | V32: =V30/U30-1 -> #REF! | W32: =W30/V30-1 -> #REF! | X32: =X30/W30-1 -> #REF! | Y32: =Y30/X30-1 -> #REF! | Z32: =Z30/Y30-1 -> #REF! | AA32: 0.03
B33: Ad revenue/Free user | C33: ='Statement Y'!#REF! -> #REF! | D33: ='Statement Y'!#REF! -> #REF! | E33: ='Statement Y'!#REF! -> #REF! | F33: ='Statement Y'!#REF! -> #REF! | G33: ='Statement Y'!#REF! -> #REF! | H33: 0.73 | I33: 0.75 | J33: 0.7 | K33: 0.75 | L33: 0.8 | R33: Ad revenue/Free user | S33: ='Statement Q'!#REF! -> #REF! | T33: ='Statement Q'!#REF! -> #REF! | U33: ='Statement Q'!#REF! -> #REF! | V33: ='Statement Q'!#REF! -> #REF! | W33: ='Statement Q'!#REF! -> #REF! | X33: ='Statement Q'!#REF! -> #REF! | Y33: ='Statement Q'!#REF! -> #REF! | Z33: ='Statement Q'!#REF! -> #REF! | AA33: 0.18 | AE33: =AE7/AE37 -> #REF!
B34: Subscribers to MAU ratio | C34: ='Statement Y'!#REF! -> #REF! | D34: ='Statement Y'!#REF! -> #REF! | E34: ='Statement Y'!#REF! -> #REF! | F34: ='Statement Y'!#REF! -> #REF! | G34: ='Statement Y'!#REF! -> #REF! | H34: =G34*(1+H35) -> #REF! | I34: =H34*(1+I35) -> #REF! | J34: =I34*(1+J35) -> #REF! | K34: =J34*(1+K35) -> #REF! | L34: =K34*(1+L35) -> #REF! | N34: Subscribers to MAU growth | Q34: Subscribers to MAU growth | R34: Subscribers to MAU ratio | S34: ='Statement Q'!#REF! -> #REF! | T34: ='Statement Q'!#REF! -> #REF! | U34: ='Statement Q'!#REF! -> #REF! | V34: ='Statement Q'!#REF! -> #REF! | W34: ='Statement Q'!#REF! -> #REF! | X34: ='Statement Q'!#REF! -> #REF! | Y34: ='Statement Q'!#REF! -> #REF! | Z34: ='Statement Q'!#REF! -> #REF! | AA34: =Z34*(1+AA35) -> #REF!
B35: Subscribers to MAU growth | D35: =D34/C34-1 -> #REF! | E35: =E34/D34-1 -> #REF! | F35: =F34/E34-1 -> #REF! | G35: =G34/F34-1 -> #REF! | H35: -0.06 | I35: -0.06 | J35: 0.05 | K35: 0.08 | L35: 0.11 | R35: Subscribers to MAU growth | T35: =T34/S34-1 -> #REF! | U35: =U34/T34-1 -> #REF! | V35: =V34/U34-1 -> #REF! | W35: =W34/V34-1 -> #REF! | X35: =X34/W34-1 -> #REF! | Y35: =Y34/X34-1 -> #REF! | Z35: =Z34/Y34-1 -> #REF! | AA35: -0.02
B36: Paid subscribers | C36: ='Statement Y'!#REF! -> #REF! | D36: ='Statement Y'!#REF! -> #REF! | E36: ='Statement Y'!#REF! -> #REF! | F36: ='Statement Y'!#REF! -> #REF! | G36: ='Statement Y'!#REF! -> #REF! | H36: =H34*H30 -> #REF! | I36: =I34*I30 -> #REF! | J36: =J34*J30 -> #REF! | K36: =K34*K30 -> #REF! | L36: =L34*L30 -> #REF! | N36: Subscribers to MAU ratio * MAU | Q36: Subscribers to MAU ratio * MAU | R36: Paid subscribers | S36: ='Statement Q'!#REF! -> #REF! | T36: ='Statement Q'!#REF! -> #REF! | U36: ='Statement Q'!#REF! -> #REF! | V36: ='Statement Q'!#REF! -> #REF! | W36: ='Statement Q'!#REF! -> #REF! | X36: ='Statement Q'!#REF! -> #REF! | Y36: ='Statement Q'!#REF! -> #REF! | Z36: ='Statement Q'!#REF! -> #REF! | AA36: =AA34*AA30 -> #REF! | AE36: =AA36 -> #REF!
B37: Free users | C37: ='Statement Y'!#REF! -> #REF! | D37: ='Statement Y'!#REF! -> #REF! | E37: ='Statement Y'!#REF! -> #REF! | F37: ='Statement Y'!#REF! -> #REF! | G37: ='Statement Y'!#REF! -> #REF! | H37: =H30-H36 -> #REF! | I37: =I30-I36 -> #REF! | J37: =J30-J36 -> #REF! | K37: =K30-K36 -> #REF! | L37: =L30-L36 -> #REF! | N37: MAU - Paid subscribers | Q37: MAU - Paid subscribers | R37: Free users | S37: ='Statement Q'!#REF! -> #REF! | T37: ='Statement Q'!#REF! -> #REF! | U37: ='Statement Q'!#REF! -> #REF! | V37: ='Statement Q'!#REF! -> #REF! | W37: ='Statement Q'!#REF! -> #REF! | X37: ='Statement Q'!#REF! -> #REF! | Y37: ='Statement Q'!#REF! -> #REF! | Z37: ='Statement Q'!#REF! -> #REF! | AA37: =AA30-AA36 -> #REF! | AE37: =AA37 -> #REF!
B38: In-App purchases % of DAU | C38: ='Statement Y'!#REF! -> #REF! | D38: ='Statement Y'!#REF! -> #REF! | E38: ='Statement Y'!#REF! -> #REF! | F38: ='Statement Y'!#REF! -> #REF! | G38: ='Statement Y'!#REF! -> #REF! | H38: 0.7 | I38: 0.65 | J38: 0.6 | K38: 0.65 | L38: 0.65 | R38: In-App purchases % of DAU | S38: ='Statement Q'!#REF! -> #REF! | T38: ='Statement Q'!#REF! -> #REF! | U38: ='Statement Q'!#REF! -> #REF! | V38: ='Statement Q'!#REF! -> #REF! | W38: ='Statement Q'!#REF! -> #REF! | X38: ='Statement Q'!#REF! -> #REF! | Y38: ='Statement Q'!#REF! -> #REF! | Z38: ='Statement Q'!#REF! -> #REF! | AA38: 0.16
B39: Avg revenue/Paid user | C39: ='Statement Y'!#REF! -> #REF! | D39: ='Statement Y'!#REF! -> #REF! | E39: ='Statement Y'!#REF! -> #REF! | F39: ='Statement Y'!#REF! -> #REF! | G39: ='Statement Y'!#REF! -> #REF! | H39: 73.5 | I39: 75 | J39: 73 | K39: 76 | L39: 78 | R39: Avg revenue/Paid user | S39: ='Statement Q'!#REF! -> #REF! | T39: ='Statement Q'!#REF! -> #REF! | U39: ='Statement Q'!#REF! -> #REF! | V39: ='Statement Q'!#REF! -> #REF! | W39: ='Statement Q'!#REF! -> #REF! | X39: ='Statement Q'!#REF! -> #REF! | Y39: ='Statement Q'!#REF! -> #REF! | Z39: ='Statement Q'!#REF! -> #REF! | AA39: 20
B40: DAU to MAU ratio | C40: ='Statement Y'!#REF! -> #REF! | D40: ='Statement Y'!#REF! -> #REF! | E40: ='Statement Y'!#REF! -> #REF! | F40: ='Statement Y'!#REF! -> #REF! | G40: ='Statement Y'!#REF! -> #REF! | H40: 0.44 | I40: =I29/I30 -> #REF! | J40: =J29/J30 -> #REF! | K40: =K29/K30 -> #REF! | L40: =L29/L30 -> #REF! | R40: DAU to MAU ratio | S40: ='Statement Q'!#REF! -> #REF! | T40: ='Statement Q'!#REF! -> #REF! | U40: ='Statement Q'!#REF! -> #REF! | V40: ='Statement Q'!#REF! -> #REF! | W40: ='Statement Q'!#REF! -> #REF! | X40: ='Statement Q'!#REF! -> #REF! | Y40: ='Statement Q'!#REF! -> #REF! | Z40: ='Statement Q'!#REF! -> #REF! | AA40: =AA29/AA30 -> #REF!
C43: Growth rates for metrics | S43: Growth rates for metrics
B44: Metrics growth % | C44: =C5 -> 2021 | D44: =D5 -> 2022 | E44: =E5 -> 2023 | F44: =F5 -> 2024 | G44: =G5 -> 2025 | H44: =H5 -> 2026 | I44: =I5 -> 2027 | J44: =J5 -> 2028 | ... L44: =L5 -> 2030 | R44: Metrics growth % | S44: =S5 -> Q1 2024 | T44: =T5 -> Q2 2024 | U44: =U5 -> Q3 2024 | V44: =V5 -> Q4 2024 | W44: =W5 -> Q1 2025 | X44: =X5 -> Q2 2025 | Y44: =Y5 -> Q3 2025 | Z44: =Z5 -> Q4 2025 | ... AC44: =AC5 -> FQ3
B45: Ad revenue/Free user | D45: =D33/C33-1 -> #REF! | E45: =E33/D33-1 -> #REF! | F45: =F33/E33-1 -> #REF! | G45: =G33/F33-1 -> #REF! | H45: =H33/G33-1 -> #REF! | I45: =I33/H33-1 -> 0.02739726 | J45: =J33/I33-1 -> -0.066666667 | K45: =K33/J33-1 -> 0.071428571 | L45: =L33/K33-1 -> 0.066666667 | R45: Ad revenue/Free user | T45: =T33/S33-1 -> #REF! | U45: =U33/T33-1 -> #REF! | V45: =V33/U33-1 -> #REF! | W45: =W33/V33-1 -> #REF! | X45: =X33/W33-1 -> #REF! | Y45: =Y33/X33-1 -> #REF! | Z45: =Z33/Y33-1 -> #REF! | AA45: =AA33/Z33-1 -> #REF!
B46: Paid subscribers | D46: =D36/C36-1 -> #REF! | E46: =E36/D36-1 -> #REF! | F46: =F36/E36-1 -> #REF! | G46: =G36/F36-1 -> #REF! | H46: =H36/G36-1 -> #REF! | I46: =I36/H36-1 -> #REF! | J46: =J36/I36-1 -> #REF! | K46: =K36/J36-1 -> #REF! | L46: =L36/K36-1 -> #REF! | R46: Paid subscribers | T46: =T36/S36-1 -> #REF! | U46: =U36/T36-1 -> #REF! | V46: =V36/U36-1 -> #REF! | W46: =W36/V36-1 -> #REF! | X46: =X36/W36-1 -> #REF! | Y46: =Y36/X36-1 -> #REF! | Z46: =Z36/Y36-1 -> #REF! | AA46: =AA36/Z36-1 -> #REF!
...

Sheet COGS & OpEx
B1: COGS & OpEx forecast
C2: History | H2: Forecast | P2: History | X2: Forecast | AB2: TTM
C4: Revenues | P4: Revenues | AB4: Q1-Q2-Q3
B5: Revenues (thousand) | C5: ='Statement Y'!D3 -> 2021 | D5: ='Statement Y'!E3 -> 2022 | E5: ='Statement Y'!F3 -> 2023 | F5: ='Statement Y'!G3 -> 2024 | G5: ='Statement Y'!H3 -> 2025 | H5: =G5+1 -> 2026 | I5: =H5+1 -> 2027 | J5: =I5+1 -> 2028 | K5: =J5+1 -> 2029 | L5: =K5+1 -> 2030 | O5: Revenues (thousand) | P5: ='Statement Q'!C3 -> Q1 2024 | Q5: ='Statement Q'!D3 -> Q2 2024 | R5: ='Statement Q'!E3 -> Q3 2024 | S5: ='Statement Q'!F3 -> Q4 2024 | T5: ='Statement Q'!G3 -> Q1 2025 | U5: ='Statement Q'!H3 -> Q2 2025 | V5: ='Statement Q'!I3 -> Q3 2025 | W5: ='Statement Q'!J3 -> Q4 2025 | X5: FQ1 | Y5: FQ2 | Z5: FQ3 | AB5: FQ1
B6: Revenue | C6: ='Statement Y'!D5 -> 0 | D6: ='Statement Y'!E5 -> 0 | E6: ='Statement Y'!F5 -> 0 | F6: ='Statement Y'!G5 -> 0 | G6: ='Statement Y'!H5 -> 0 | H6: =Revenue!H12 -> #REF! | I6: =Revenue!I12 -> #REF! | J6: =Revenue!J12 -> #REF! | K6: =Revenue!K12 -> #REF! | L6: =Revenue!L12 -> #REF! | O6: Revenue | P6: ='Statement Q'!C5 -> 0 | Q6: ='Statement Q'!D5 -> 0 | R6: ='Statement Q'!E5 -> 0 | S6: ='Statement Q'!F5 -> 0 | T6: ='Statement Q'!G5 -> 0 | U6: ='Statement Q'!H5 -> 0 | V6: ='Statement Q'!I5 -> 0 | W6: ='Statement Q'!J5 -> 0 | X6: =Revenue!AA12 -> #REF! | Y6: =Revenue!AB12 -> 0 | Z6: =Revenue!AC12 -> 0 | AB6: =SUM(U6:X6) -> #REF!
C9: COGS and OpEx | P9: COGS & OpEx | AB9: =AB4 -> Q1-Q2-Q3
B10: Expenses (thousand) | C10: =C5 -> 2021 | D10: =D5 -> 2022 | E10: =E5 -> 2023 | F10: =F5 -> 2024 | G10: =G5 -> 2025 | H10: =H5 -> 2026 | I10: =I5 -> 2027 | J10: =J5 -> 2028 | ... L10: =L5 -> 2030 | O10: Expenses (thousand) | P10: =P5 -> Q1 2024 | Q10: =Q5 -> Q2 2024 | R10: =R5 -> Q3 2024 | S10: =S5 -> Q4 2024 | T10: =T5 -> Q1 2025 | U10: =U5 -> Q2 2025 | V10: =V5 -> Q3 2025 | W10: =W5 -> Q4 2025 | ... Z10: =Z5 -> FQ3 | AB10: =AB5 -> FQ1
B11: COGS | C11: ='Statement Y'!D6 -> 0 | D11: ='Statement Y'!E6 -> 0 | E11: ='Statement Y'!F6 -> 0 | F11: ='Statement Y'!G6 -> 0 | G11: ='Statement Y'!H6 -> 0 | H11: =H20*H$6 -> #REF! | I11: =I20*I$6 -> #REF! | J11: =J20*J$6 -> #REF! | K11: =K20*K$6 -> #REF! | L11: =L20*L$6 -> #REF! | O11: COGS | P11: ='Statement Q'!C6 -> 0 | Q11: ='Statement Q'!D6 -> 0 | R11: ='Statement Q'!E6 -> 0 | S11: ='Statement Q'!F6 -> 0 | T11: ='Statement Q'!G6 -> 0 | U11: ='Statement Q'!H6 -> 0 | V11: ='Statement Q'!I6 -> 0 | W11: ='Statement Q'!J6 -> 0 | X11: =X20*X$6 -> #REF! | AB11: =SUM(U11:X11) -> #REF!
B12: R&D | C12: ='Statement Y'!D8 -> 0 | D12: ='Statement Y'!E8 -> 0 | E12: ='Statement Y'!F8 -> 0 | F12: ='Statement Y'!G8 -> 0 | G12: ='Statement Y'!H8 -> 0 | H12: =H21*H$6 -> #REF! | I12: =I21*I$6 -> #REF! | J12: =J21*J$6 -> #REF! | K12: =K21*K$6 -> #REF! | L12: =L21*L$6 -> #REF! | O12: R&D | P12: ='Statement Q'!C8 -> 0 | Q12: ='Statement Q'!D8 -> 0 | R12: ='Statement Q'!E8 -> 0 | S12: ='Statement Q'!F8 -> 0 | T12: ='Statement Q'!G8 -> 0 | U12: ='Statement Q'!H8 -> 0 | V12: ='Statement Q'!I8 -> 0 | W12: ='Statement Q'!J8 -> 0 | X12: =X21*X$6 -> #REF! | AB12: =SUM(U12:X12) -> #REF!
B13: Sales and marketing | C13: ='Statement Y'!D9 -> 0 | D13: ='Statement Y'!E9 -> 0 | E13: ='Statement Y'!F9 -> 0 | F13: ='Statement Y'!G9 -> 0 | G13: ='Statement Y'!H9 -> 0 | H13: =H22*H$6 -> #REF! | I13: =I22*I$6 -> #REF! | J13: =J22*J$6 -> #REF! | K13: =K22*K$6 -> #REF! | L13: =L22*L$6 -> #REF! | O13: Sales and marketing | P13: ='Statement Q'!C9 -> 0 | Q13: ='Statement Q'!D9 -> 0 | R13: ='Statement Q'!E9 -> 0 | S13: ='Statement Q'!F9 -> 0 | T13: ='Statement Q'!G9 -> 0 | U13: ='Statement Q'!H9 -> 0 | V13: ='Statement Q'!I9 -> 0 | W13: ='Statement Q'!J9 -> 0 | X13: =X22*X$6 -> #REF! | AB13: =SUM(U13:X13) -> #REF!
B14: General & administrative | C14: ='Statement Y'!D10 -> 0 | D14: ='Statement Y'!E10 -> 0 | E14: ='Statement Y'!F10 -> 0 | F14: ='Statement Y'!G10 -> 0 | G14: ='Statement Y'!H10 -> 0 | H14: =H23*H$6 -> #REF! | I14: =I23*I$6 -> #REF! | J14: =J23*J$6 -> #REF! | K14: =K23*K$6 -> #REF! | L14: =L23*L$6 -> #REF! | O14: General & administrative | P14: ='Statement Q'!C10 -> 0 | Q14: ='Statement Q'!D10 -> 0 | R14: ='Statement Q'!E10 -> 0 | S14: ='Statement Q'!F10 -> 0 | T14: ='Statement Q'!G10 -> 0 | U14: ='Statement Q'!H10 -> 0 | V14: ='Statement Q'!I10 -> 0 | W14: ='Statement Q'!J10 -> 0 | X14: =X23*X$6 -> #REF! | AB14: =SUM(U14:X14) -> #REF!
B15: OpEx | C15: ='Statement Y'!D11 -> 0 | D15: ='Statement Y'!E11 -> 0 | E15: ='Statement Y'!F11 -> 0 | F15: ='Statement Y'!G11 -> 0 | G15: ='Statement Y'!H11 -> 0 | H15: =SUM(H12:H14) -> #REF! | I15: =SUM(I12:I14) -> #REF! | J15: =SUM(J12:J14) -> #REF! | K15: =SUM(K12:K14) -> #REF! | L15: =SUM(L12:L14) -> #REF! | O15: OpEx | P15: ='Statement Q'!C11 -> 0 | Q15: ='Statement Q'!D11 -> 0 | R15: ='Statement Q'!E11 -> 0 | S15: ='Statement Q'!F11 -> 0 | T15: ='Statement Q'!G11 -> 0 | U15: ='Statement Q'!H11 -> 0 | V15: ='Statement Q'!I11 -> 0 | W15: ='Statement Q'!J11 -> 0 | X15: =SUM(X12:X14) -> #REF! | AB15: =SUM(U15:X15) -> #REF!
C18: Expenses % of Revenue | P18: Expenses % of Revenue
B19: % of revenue | C19: =C5 -> 2021 | D19: =D5 -> 2022 | E19: =E5 -> 2023 | F19: =F5 -> 2024 | G19: =G5 -> 2025 | H19: =H5 -> 2026 | I19: =I5 -> 2027 | J19: =J5 -> 2028 | ... L19: =L5 -> 2030 | O19: % of revenue | P19: =P5 -> Q1 2024 | Q19: =Q5 -> Q2 2024 | R19: =R5 -> Q3 2024 | S19: =S5 -> Q4 2024 | T19: =T5 -> Q1 2025 | U19: =U5 -> Q2 2025 | V19: =V5 -> Q3 2025 | W19: =W5 -> Q4 2025 | ... Z19: =Z5 -> FQ3
B20: =B11 -> COGS | C20: =C11/C$6 -> #DIV/0! | D20: =D11/D$6 -> #DIV/0! | E20: =E11/E$6 -> #DIV/0! | F20: =F11/F$6 -> #DIV/0! | G20: =G11/G$6 -> #DIV/0! | H20: 0.28 | I20: 0.275 | J20: 0.28 | K20: 0.268 | L20: 0.276 | O20: =O11 -> COGS | P20: =P11/P$6 -> #DIV/0! | Q20: =Q11/Q$6 -> #DIV/0! | R20: =R11/R$6 -> #DIV/0! | S20: =S11/S$6 -> #DIV/0! | T20: =T11/T$6 -> #DIV/0! | U20: =U11/U$6 -> #DIV/0! | V20: =V11/V$6 -> #DIV/0! | W20: =W11/W$6 -> #DIV/0! | X20: 0.28
B21: =B12 -> R&D | C21: =C12/C$6 -> #DIV/0! | D21: =D12/D$6 -> #DIV/0! | E21: =E12/E$6 -> #DIV/0! | F21: =F12/F$6 -> #DIV/0! | G21: =G12/G$6 -> #DIV/0! | H21: 0.35 | I21: 0.3 | J21: 0.3 | K21: 0.31 | L21: 0.29 | O21: =O12 -> R&D | P21: =P12/P$6 -> #DIV/0! | Q21: =Q12/Q$6 -> #DIV/0! | R21: =R12/R$6 -> #DIV/0! | S21: =S12/S$6 -> #DIV/0! | T21: =T12/T$6 -> #DIV/0! | U21: =U12/U$6 -> #DIV/0! | V21: =V12/V$6 -> #DIV/0! | W21: =W12/W$6 -> #DIV/0! | X21: 0.296
B22: =B13 -> Sales and marketing | C22: =C13/C$6 -> #DIV/0! | D22: =D13/D$6 -> #DIV/0! | E22: =E13/E$6 -> #DIV/0! | F22: =F13/F$6 -> #DIV/0! | G22: =G13/G$6 -> #DIV/0! | H22: 0.13 | I22: 0.125 | J22: 0.12 | K22: 0.115 | L22: 0.11 | O22: =O13 -> Sales and marketing | P22: =P13/P$6 -> #DIV/0! | Q22: =Q13/Q$6 -> #DIV/0! | R22: =R13/R$6 -> #DIV/0! | S22: =S13/S$6 -> #DIV/0! | T22: =T13/T$6 -> #DIV/0! | U22: =U13/U$6 -> #DIV/0! | V22: =V13/V$6 -> #DIV/0! | W22: =W13/W$6 -> #DIV/0! | X22: 0.115
B23: =B14 -> General & administrative | C23: =C14/C$6 -> #DIV/0! | D23: =D14/D$6 -> #DIV/0! | E23: =E14/E$6 -> #DIV/0! | F23: =F14/F$6 -> #DIV/0! | G23: =G14/G$6 -> #DIV/0! | H23: 0.18 | I23: 0.17 | J23: 0.16 | K23: 0.175 | L23: 0.17 | O23: =O14 -> General & administrative | P23: =P14/P$6 -> #DIV/0! | Q23: =Q14/Q$6 -> #DIV/0! | R23: =R14/R$6 -> #DIV/0! | S23: =S14/S$6 -> #DIV/0! | T23: =T14/T$6 -> #DIV/0! | U23: =U14/U$6 -> #DIV/0! | V23: =V14/V$6 -> #DIV/0! | W23: =W14/W$6 -> #DIV/0! | X23: 0.185

Sheet PP&E
B1: PP&E, D&A and CapEx
B3: ="CapEx:"&CHOOSE(C3," as a % of PP&E"," as a % of revenue") -> CapEx: as a % of revenue | C3: 2
C5: History | H5: Forecast
C7: Revenues
B8: Revenues (thousand) | C8: ='Statement Y'!D3 -> 2021 | D8: ='Statement Y'!E3 -> 2022 | E8: ='Statement Y'!F3 -> 2023 | F8: ='Statement Y'!G3 -> 2024 | G8: ='Statement Y'!H3 -> 2025 | H8: =G8+1 -> 2026 | I8: =H8+1 -> 2027 | J8: =I8+1 -> 2028 | K8: =J8+1 -> 2029 | L8: =K8+1 -> 2030
B9: Revenue | C9: ='Statement Y'!D5 -> 0 | D9: ='Statement Y'!E5 -> 0 | E9: ='Statement Y'!F5 -> 0 | F9: ='Statement Y'!G5 -> 0 | G9: ='Statement Y'!H5 -> 0 | H9: =Revenue!H12 -> #REF! | I9: =Revenue!I12 -> #REF! | J9: =Revenue!J12 -> #REF! | K9: =Revenue!K12 -> #REF! | L9: =Revenue!L12 -> #REF!
C12: PP&E
B13: $ (thousand) | C13: =C8 -> 2021 | D13: =D8 -> 2022 | E13: =E8 -> 2023 | F13: =F8 -> 2024 | G13: =G8 -> 2025 | H13: =H8 -> 2026 | I13: =I8 -> 2027 | J13: =J8 -> 2028 | ... L13: =L8 -> 2030
B14: Beginning PP&E | C14: ='Statement Y'!C32 -> 0 | D14: =C17 -> 0 | E14: =D17 -> 0 | F14: =E17 -> 0 | G14: =F17 -> 0 | H14: =G17 -> 0 | I14: =H17 -> #DIV/0! | J14: =I17 -> #DIV/0! | K14: =J17 -> #DIV/0! | L14: =K17 -> #DIV/0!
B15: CapEx | C15: =-'Statement Y'!D74 -> 0 | D15: =-'Statement Y'!E74 -> 0 | E15: =-'Statement Y'!F74 -> 0 | F15: =-'Statement Y'!G74 -> 0 | G15: =-'Statement Y'!H74 -> 0 | H15: =CHOOSE($C$3,H34*H14,H35*H9) -> #DIV/0! | I15: =CHOOSE($C$3,I34*I14,I35*I9) -> #DIV/0! | J15: =CHOOSE($C$3,J34*J14,J35*J9) -> #DIV/0! | K15: =CHOOSE($C$3,K34*K14,K35*K9) -> #DIV/0! | L15: =CHOOSE($C$3,L34*L14,L35*L9) -> #DIV/0!
B16: Depreciation | C16: ='Statement Y'!D115 -> 0 | D16: ='Statement Y'!E115 -> 0 | E16: ='Statement Y'!F115 -> 0 | F16: ='Statement Y'!G115 -> 0 | G16: ='Statement Y'!H115 -> 0 | H16: =H27 -> #DIV/0! | I16: =I27 -> #DIV/0! | J16: =J27 -> #DIV/0! | K16: =K27 -> #DIV/0! | L16: =L27 -> #DIV/0!
B17: Ending PP&E | C17: ='Statement Y'!D32 -> 0 | D17: ='Statement Y'!E32 -> 0 | E17: ='Statement Y'!F32 -> 0 | F17: ='Statement Y'!G32 -> 0 | G17: ='Statement Y'!H32 -> 0 | H17: =H14+H15-H16 -> #DIV/0! | I17: =I14+I15-I16 -> #DIV/0! | J17: =J14+J15-J16 -> #DIV/0! | K17: =K14+K15-K16 -> #DIV/0! | L17: =L14+L15-L16 -> #DIV/0!
C20: Depreciation schedule
B21: $ (thousand) | C21: =C8 -> 2021 | D21: =D8 -> 2022 | E21: =E8 -> 2023 | F21: =F8 -> 2024 | G21: =G8 -> 2025 | H21: =H8 -> 2026 | I21: =I8 -> 2027 | J21: =J8 -> 2028 | ... L21: =L8 -> 2030
B22: =H8 -> 2026 | H22: =IF(COUNT($H$22:H22) <= $C$39, $H$14/$C$39+$H$15/$C$38, 0) -> #DIV/0! | I22: =IF(COUNT($H$22:I22) <= $C$39, $H$14/$C$39+$H$15/$C$38, 0) -> #DIV/0! | J22: =IF(COUNT($H$22:J22) <= $C$39, $H$14/$C$39+$H$15/$C$38, 0) -> #DIV/0! | K22: =IF(COUNT($H$22:K22) <= $C$39, $H$14/$C$39+$H$15/$C$38, 0) -> #DIV/0! | L22: =IF(COUNT($H$22:L22) <= $C$39, $H$14/$C$39+$H$15/$C$38, 0) -> #DIV/0!
B23: =I8 -> 2027 | I23: =$I$15/$C$38 -> #DIV/0! | J23: =$I$15/$C$38 -> #DIV/0! | K23: =$I$15/$C$38 -> #DIV/0! | L23: =$I$15/$C$38 -> #DIV/0!
B24: =J8 -> 2028 | J24: =$J$15/$C$38 -> #DIV/0! | K24: =$J$15/$C$38 -> #DIV/0! | L24: =$J$15/$C$38 -> #DIV/0!
B25: =K8 -> 2029 | K25: =$K$15/$C$38 -> #DIV/0! | L25: =$K$15/$C$38 -> #DIV/0!
B26: =L8 -> 2030 | L26: =L15/C38 -> #DIV/0!
B27: Total | H27: =SUM(H22:H26) -> #DIV/0! | I27: =SUM(I22:I26) -> #DIV/0! | J27: =SUM(J22:J26) -> #DIV/0! | K27: =SUM(K22:K26) -> #DIV/0! | L27: =SUM(L22:L26) -> #DIV/0!
C30: CapEx Drivers
B31: % of | C31: =C8 -> 2021 | D31: =D8 -> 2022 | E31: =E8 -> 2023 | F31: =F8 -> 2024 | G31: =G8 -> 2025 | H31: =H8 -> 2026 | I31: =I8 -> 2027 | J31: =J8 -> 2028 | ... L31: =L8 -> 2030
B32: D&A % of PP&E | C32: =C16/C14 -> #DIV/0! | D32: =D16/D14 -> #DIV/0! | E32: =E16/E14 -> #DIV/0! | F32: =F16/F14 -> #DIV/0! | G32: =G16/G14 -> #DIV/0! | H32: =H16/H14 -> #DIV/0! | I32: =I16/I14 -> #DIV/0! | J32: =J16/J14 -> #DIV/0! | ... L32: =L16/L14 -> #DIV/0!
B33: D&A % of revenue | C33: =C16/C9 -> #DIV/0! | D33: =D16/D9 -> #DIV/0! | E33: =E16/E9 -> #DIV/0! | F33: =F16/F9 -> #DIV/0! | G33: =G16/G9 -> #DIV/0! | H33: =H16/H9 -> #DIV/0! | I33: =I16/I9 -> #DIV/0! | J33: =J16/J9 -> #DIV/0! | ... L33: =L16/L9 -> #DIV/0!
B34: CapEx % of PP&E | C34: =C15/C14 -> #DIV/0! | D34: =D15/D14 -> #DIV/0! | E34: =E15/E14 -> #DIV/0! | F34: =F15/F14 -> #DIV/0! | G34: =G15/G14 -> #DIV/0! | H34: =AVERAGE(D34:G34) -> #DIV/0! | I34: =$H$34 -> #DIV/0! | J34: =$H$34 -> #DIV/0! | K34: =$H$34 -> #DIV/0! | L34: =$H$34 -> #DIV/0!
B35: CapEx % of revenue | C35: =C15/C9 -> #DIV/0! | D35: =D15/D9 -> #DIV/0! | E35: =E15/E9 -> #DIV/0! | F35: =F15/F9 -> #DIV/0! | G35: =G15/G9 -> #DIV/0! | H35: =AVERAGE(D35:G35) -> #DIV/0! | I35: =$H$35 -> #DIV/0! | J35: =$H$35 -> #DIV/0! | K35: =$H$35 -> #DIV/0! | L35: =$H$35 -> #DIV/0!
B37: PP&E and CapEx useful life
B38: Useful life CapEx | C38: 7
B39: Useful life historical PP&E | C39: 6
C42: Historical PP&E data
B43: $ (thousands) | C43: =C8 -> 2021 | D43: =D8 -> 2022 | E43: =E8 -> 2023 | F43: =F8 -> 2024 | G43: =G8 -> 2025
B44: ='Statement Y'!B119 -> Gross PP&E | C44: ='Statement Y'!C119 -> 0 | D44: ='Statement Y'!D119 -> 0 | E44: ='Statement Y'!E119 -> 0 | F44: ='Statement Y'!F119 -> 0 | G44: ='Statement Y'!G119 -> 0
B45: ='Statement Y'!B120 -> Accumulated depreciation | C45: ='Statement Y'!C120 -> 0 | D45: ='Statement Y'!D120 -> 0 | E45: ='Statement Y'!E120 -> 0 | F45: ='Statement Y'!F120 -> 0 | G45: ='Statement Y'!G120 -> 0
B46: Remaining useful life years | C46: =C17/C16 -> #DIV/0! | D46: =D17/D16 -> #DIV/0! | E46: =E17/E16 -> #DIV/0! | F46: =F17/F16 -> #DIV/0! | G46: =G17/G16 -> #DIV/0!
B47: Percent depreciated | C47: =C45/C44 -> #DIV/0! | D47: =D45/D44 -> #DIV/0! | E47: =E45/E44 -> #DIV/0! | F47: =F45/F44 -> #DIV/0! | G47: =G45/G44 -> #DIV/0!
B50: Average useful life PP&E
B51: Avg Gross PP&E | C51: =AVERAGE(C44:G44) -> 0
