Workbook

Sheet Overview
B2: Automatic Data | E2: At a glance | H2: Valuation | K2: Links
B3: Company | C3: #VALUE! | E3: Market capitalization | F3: =Statement!AC154 -> 49043.4 | H3: ='AVG target price'!B5 -> DCF price | I3: ='AVG target price'!C5 -> 117.44825 | K3: Financials ->'!B13
B4: Ticker | C4: {=_FV(C3,"Ticker symbol",TRUE)} -> ADSK | E4: Enterprise value | F4: =Statement!AC155 -> 48164.4 | H4: ='AVG target price'!B6 -> EV/EBIT price | I4: ='AVG target price'!C6 -> 346.52062 | K4: Analysis ->'!B13
B5: Price | C5: {=_FV(C3,"Price",TRUE)} -> 233.54 | E5: EPS | F5: =Statement!AC27 -> 7.73 | H5: ='AVG target price'!B7 -> PS price | I5: ='AVG target price'!C7 -> 188.26132 | K5: Forecast ->'!B13
B6: Price Extended Hours | C6: {=_FV(C3,"Price (Extended hours)",TRUE)} -> 233.65 | E6: PE | F6: =Statement!AC151 -> 30.21216 | H6: ='AVG target price'!B8 -> EV/FCFF price | I6: ='AVG target price'!C8 -> 344.98288 | K6: Valuation ->'!B13
B7: Day change | C7: {=_FV(C3,"Change")} -> -1.81 | E7: PS | F7: =Statement!AC152 -> 6.3856252 | H7: ='AVG target price'!B9 -> EV/Sales price | I7: ='AVG target price'!C9 -> 219.72591
B8: Day change extended | C8: {=_FV(C3,"Change (extended hours)",TRUE)} -> 0.11 | E8: FCF Yield | F8: =Statement!AC162 -> 0.042778437 | H8: ='AVG target price'!B10 -> AVG price | I8: ='AVG target price'!C10 -> 243.3878
B9: Day change % | C9: {=_FV(C3,"Change (%)",TRUE)} -> -0.007691 | E9: Earnings Yield | F9: =Statement!AC163 -> 0.033099255 | H9: ='AVG target price'!B12 -> Upside/Downside | I9: ='AVG target price'!C12 -> 0.042167502
B10: Day change extended % | C10: {=_FV(C3,"Change % (extended hours)",TRUE)} -> 0.000471 | E10: Buyback Yield | F10: =Statement!AC165 -> 0.032440655
B11: 52 week high | C11: {=_FV(C3,"52 week high",TRUE)} -> 320 | E11: Dividend Yield | F11: =Statement!AC164 -> 0 | H11: DDM price | I11: =DDM!C26 -> 0
B12: 52 week low | C12: {=_FV(C3,"52 week low",TRUE)} -> 185.5 | E12: ROA | F12: =Statement!AC124 -> 0.12647308
B13: Beta | C13: {=_FV(C3,"Beta")} -> 1.3195 | E13: ROE | F13: =Statement!AC126 -> 0.48536802 | H13: Reverse DCF rate | I13: ='Reverse DCF'!C17 -> 0.465
B14: Avg volume | C14: {=_FV(C3,"Volume average",TRUE)} -> 2316106 | E14: ROIC | F14: =Statement!AC141 -> 0.63581348
E15: Net Cash/Market Cap | F15: =Statement!AC177 -> 0.017922901
E16: Net Cash/Share | F16: =Statement!AC176 -> 4.2057416 | H16: Discount rates used
B17: Unit data and other info | E17: Insider Ownership | F17: =Statement!AC172 -> 0.0047619048 | H17: WACC | I17: =DCF!C15 -> 0.10760405
B18: Units | C18: M | E18: Net Trade Cycle | F18: =Statement!AC145 -> -212.53333 | H18: Cost of Equity | I18: =Multiples!C54 -> 0.1118175
B19: Units conversion | C19: 1000000 | E19: Net Debt/Equity | F19: =Statement!AC147 -> -0.25982855
B20: Has operating lease | C20: Yes | E20: Quick Ratio | F20: =Statement!AC148 -> 0.76056126
B21: Has finance lease | C21: No
B22: Has debt | C22: Yes
B25: Constants | E25: 10 Year Bond Yield
B26: Default tax rate | C26: 0.21 | E26: #VALUE! | F26: {=_FV(E26,"Price")} -> 52.44
B27: Cost of debt | C27: 0.061 | E27: Percentage | F27: =F26/1000 -> 0.05244
B28: Manual WACC | C28: 0
B29: Manual Cost of Equity | C29: 0
B33: Info
B35: Mission: | C35: Empower everyone, everywhere, to design and make anything
B36: Auditor: | C36: Ernst & Young LLP
B37: Business units: | C37: AECO has the Architecure, Engineering and Construction Collection, AutoCAD Civil 3D, Building Connected and other related products
C38: AutoCAD and AutoCAD LT
C39: Manufacturing Fusion, Inventor, Vault and other related software
C40: Media and Entertainment contains Maya, 3ds Max plus other related programs
B41: Competitors: | C41: Adobe
C42: Bentley Systems
C43: Dassault Systemes
C44: MSC Software Corporation
C45: Oracle
C46: PTC
C47: Siemens
...

Sheet Financials ->
H5: Links
H6: Overview'!B3
H7: Financials ->'!B13
H8: Analysis ->'!B13
H9: Forecast ->'!B13
H10: Valuation ->'!B13
B13: Financials ->

Sheet Statement
B2: Date | M2: 31.01.2022 | N2: 31.01.2023 | O2: 31.01.2024 | P2: 31.01.2025 | Q2: 31.01.2026 | T2: 31.10.2024 | U2: 31.01.2025 | V2: 30.04.2025 | W2: 31.07.2025 | X2: 31.10.2025 | Y2: 31.01.2026 | Z2: 30.04.2026 | AA2: 31.07.2026
B3: FY | M3: 2022 | N3: 2023 | O3: 2024 | P3: 2025 | Q3: 2026 | T3: Q3 2025 | U3: Q4 2025 | V3: Q1 2026 | W3: Q2 2026 | X3: Q3 2026 | Y3: Q4 2026 | Z3: Q1 2027 | AA3: Q2 2027 | AC3: TTM/YTD
B4: Income statement
B5: Revenue | M5: 4386 | N5: 5005 | O5: 5497 | P5: 6131 | Q5: 7206 | T5: 1570 | U5: 1639 | V5: 1633 | W5: 1763 | X5: 1853 | Y5: 1957 | Z5: 1934 | AA5: 2046 | AC5: =SUM(X5:AA5) -> 7790
B6: COGS | M6: 418 | N6: 480 | O6: 511 | P6: 578 | Q6: 650 | T6: 147 | U6: 154 | V6: 160 | W6: 159 | X6: 165 | Y6: 166 | Z6: 175 | AA6: 176 | AC6: =SUM(X6:AA6) -> 682
B7: Gross Profit | C7: =C5-C6 -> 0 | D7: =D5-D6 -> 0 | E7: =E5-E6 -> 0 | F7: =F5-F6 -> 0 | G7: =G5-G6 -> 0 | H7: =H5-H6 -> 0 | I7: =I5-I6 -> 0 | J7: =J5-J6 -> 0 | ... Q7: =Q5-Q6 -> 6556 | T7: =T5-T6 -> 1423 | U7: =U5-U6 -> 1485 | V7: =V5-V6 -> 1473 | W7: =W5-W6 -> 1604 | X7: =X5-X6 -> 1688 | Y7: =Y5-Y6 -> 1791 | Z7: =Z5-Z6 -> 1759 | AA7: =AA5-AA6 -> 1870 | AC7: =SUM(X7:AA7) -> 7108
B8: Sales and marketing | M8: 1623 | N8: 1745 | O8: 1823 | P8: 2000 | Q8: 2373 | T8: 525 | U8: 526 | V8: 566 | W8: 559 | X8: 612 | Y8: 636 | Z8: 593 | AA8: 616 | AC8: =SUM(X8:AA8) -> 2457
B9: R&D | M9: 1115 | N9: 1219 | O9: 1373 | P9: 1485 | Q9: 1643 | T9: 378 | U9: 393 | V9: 394 | W9: 413 | X9: 416 | Y9: 420 | Z9: 421 | AA9: 464 | AC9: =SUM(X9:AA9) -> 1721
B10: General and administrative | M10: 572 | N10: 532 | O10: 620 | P10: 650 | Q10: 693 | T10: 161 | U10: 173 | V10: 162 | W10: 168 | X10: 172 | Y10: 191 | Z10: 162 | AA10: 179 | AC10: =SUM(X10:AA10) -> 704
B11: Amortization purchased intangibles | M11: 40 | N11: 40 | O11: 42 | P11: 49 | Q11: 53 | T11: 13 | U11: 12 | V11: 13 | W11: 14 | X11: 13 | Y11: 13 | Z11: 12 | AA11: 13 | AC11: =SUM(X11:AA11) -> 51
B12: OpEx | M12: 3350 | N12: 3536 | O12: 3858 | P12: 4199 | Q12: 4978 | T12: 1077 | U12: 1119 | V12: 1240 | W12: 1160 | X12: 1218 | Y12: 1360 | Z12: 1218 | AA12: 1271 | AC12: =SUM(X12:AA12) -> 5067
B13: Operating income | M13: 618 | N13: 989 | O13: 1128 | P13: 1354 | Q13: 1578 | T13: 346 | U13: 366 | V13: 233 | W13: 444 | X13: 470 | Y13: 431 | Z13: 541 | AA13: 599 | AC13: =SUM(X13:AA13) -> 2041
B14: Interest income/expense | M14: -53 | N14: -43 | O14: 8 | P14: 30 | Q14: 25 | T14: 5 | U14: 6 | V14: 1 | W14: 12 | X14: -2 | Y14: 14 | Z14: 58 | AA14: -6 | AC14: =SUM(X14:AA14) -> 64
B15: Other income/expense | M15: 0 | N15: 0 | O15: 0 | P15: 0 | Q15: 0 | T15: 0 | U15: 0 | V15: 0 | W15: 0 | X15: 0 | Y15: 0 | Z15: 0 | AA15: 0 | AC15: =SUM(X15:AA15) -> 0
B16: Income before taxes | M16: 565 | N16: 946 | O16: 1136 | P16: 1384 | Q16: 1603 | T16: 351 | U16: 372 | V16: 234 | W16: 456 | X16: 468 | Y16: 445 | Z16: 599 | AA16: 593 | AC16: =SUM(X16:AA16) -> 2105
B17: Income tax expense/benefit | M17: -68 | N17: -123 | O17: -230 | P17: -272 | Q17: -479 | T17: -76 | U17: -69 | V17: -82 | W17: -143 | X17: -125 | Y17: -129 | Z17: -108 | AA17: -101 | AC17: =SUM(X17:AA17) -> -463
B18: Non-controlling interest | M18: 0 | N18: 0 | O18: 0 | P18: 0 | Q18: 0 | T18: 0 | U18: 0 | V18: 0 | W18: 0 | X18: 0 | Y18: 0 | Z18: 0 | AA18: 0 | AC18: =SUM(X18:AA18) -> 0
B19: Net income | M19: 497 | N19: 823 | O19: 906 | P19: 1112 | Q19: 1124 | T19: 275 | U19: 303 | V19: 152 | W19: 313 | X19: 343 | Y19: 316 | Z19: 491 | AA19: 492 | AC19: =SUM(X19:AA19) -> 1642
B20: Basic Shares outstanding avg | M20: 220 | N20: 216 | O20: 214 | P20: 215 | Q20: 213 | T20: 215 | U20: 214 | V20: 214 | W20: 213 | X20: 213 | Y20: 212 | Z20: 211 | AA20: 210 | AC20: =AVERAGE(X20:AA20) -> 211.5
B21: Basic Shares outstanding avg adjusted | C21: =C20*C$86 -> 0 | D21: =D20*D$86 -> 0 | E21: =E20*E$86 -> 0 | F21: =F20*F$86 -> 0 | G21: =G20*G$86 -> 0 | H21: =H20*H$86 -> 0 | I21: =I20*I$86 -> 0 | J21: =J20*J$86 -> 0 | ... Q21: =Q20*Q$86 -> 213 | T21: =T20*T$86 -> 215 | U21: =U20*U$86 -> 214 | V21: =V20*V$86 -> 214 | W21: =W20*W$86 -> 213 | X21: =X20*X$86 -> 213 | Y21: =Y20*Y$86 -> 212 | Z21: =Z20*Z$86 -> 211 | AA21: =AA20*AA$86 -> 210 | AC21: =AC20*AC$86 -> 211.5
B22: Diluted Shares outstanding avg | M22: 222 | N22: 218 | O22: 216 | P22: 217 | Q22: 215 | T22: 217 | U22: 217 | V22: 216 | W22: 215 | X22: 215 | Y22: 214 | Z22: 212 | AA22: 211 | AC22: =AVERAGE(X22:AA22) -> 213
B23: Diluted Shares outstanding avg adjusted | C23: =C22*C$86 -> 0 | D23: =D22*D$86 -> 0 | E23: =E22*E$86 -> 0 | F23: =F22*F$86 -> 0 | G23: =G22*G$86 -> 0 | H23: =H22*H$86 -> 0 | I23: =I22*I$86 -> 0 | J23: =J22*J$86 -> 0 | ... Q23: =Q22*Q$86 -> 215 | T23: =T22*T$86 -> 217 | U23: =U22*U$86 -> 217 | V23: =V22*V$86 -> 216 | W23: =W22*W$86 -> 215 | X23: =X22*X$86 -> 215 | Y23: =Y22*Y$86 -> 214 | Z23: =Z22*Z$86 -> 212 | AA23: =AA22*AA$86 -> 211 | AC23: =AC22*AC$86 -> 213
B24: Basic EPS | M24: 2.26 | N24: 3.81 | O24: 4.23 | P24: 5.17 | Q24: 5.28 | T24: 1.28 | U24: 1.42 | V24: 0.71 | W24: 1.47 | X24: 1.61 | Y24: 1.49 | Z24: 2.33 | AA24: 2.34 | AC24: =SUM(X24:AA24) -> 7.77
B25: Basic EPS adjusted | M25: =M24/M$86 -> 2.26 | N25: =N24/N$86 -> 3.81 | O25: =O24/O$86 -> 4.23 | P25: =P24/P$86 -> 5.17 | Q25: =Q24/Q$86 -> 5.28 | T25: =T24/T$86 -> 1.28 | U25: =U24/U$86 -> 1.42 | V25: =V24/V$86 -> 0.71 | W25: =W24/W$86 -> 1.47 | X25: =X24/X$86 -> 1.61 | Y25: =Y24/Y$86 -> 1.49 | Z25: =Z24/Z$86 -> 2.33 | AA25: =AA24/AA$86 -> 2.34 | AC25: =AC24/AC$86 -> 7.77
B26: Diluted EPS | M26: 2.24 | N26: 3.78 | O26: 4.19 | P26: 5.12 | Q26: 5.23 | T26: 1.27 | U26: 1.4 | V26: 0.7 | W26: 1.46 | X26: 1.6 | Y26: 1.48 | Z26: 2.32 | AA26: 2.33 | AC26: =SUM(X26:AA26) -> 7.73
B27: Diluted EPS adjusted | M27: =M26/M$86 -> 2.24 | N27: =N26/N$86 -> 3.78 | O27: =O26/O$86 -> 4.19 | P27: =P26/P$86 -> 5.12 | Q27: =Q26/Q$86 -> 5.23 | T27: =T26/T$86 -> 1.27 | U27: =U26/U$86 -> 1.4 | V27: =V26/V$86 -> 0.7 | W27: =W26/W$86 -> 1.46 | X27: =X26/X$86 -> 1.6 | Y27: =Y26/Y$86 -> 1.48 | Z27: =Z26/Z$86 -> 2.32 | AA27: =AA26/AA$86 -> 2.33 | AC27: =AC26/AC$86 -> 7.73
B29: Balance sheet
B30: Cash and cash equivalents | M30: =1528+236 -> 1764 | N30: =1947+125 -> 2072 | O30: =1892+354 -> 2246 | P30: =1599+287 -> 1886 | Q30: =2249+348 -> 2597 | T30: =1437+276 -> 1713 | U30: =1599+287 -> 1886 | V30: =1816+224 -> 2040 | W30: =2003+233 -> 2236 | X30: =1989+300 -> 2289 | Y30: =2249+348 -> 2597 | Z30: =2671+253 -> 2924 | AA30: =4098+57 -> 4155 | AC30: =AA30 -> 4155
B31: Acc receivable | M31: 716 | N31: 961 | O31: 876 | P31: 1008 | Q31: 1439 | T31: 702 | U31: 1008 | V31: 494 | W31: 532 | X31: 806 | Y31: 1439 | Z31: 579 | AA31: 684 | AC31: =AA31 -> 684
B32: Inventory | M32: 0 | N32: 0 | O32: 0 | P32: 0 | Q32: 0 | T32: 0 | U32: 0 | V32: 0 | W32: 0 | X32: 0 | Y32: 0 | Z32: 0 | AA32: 0 | AC32: =AA32 -> 0
B33: Current assets | M33: 2764 | N33: 3341 | O33: 3579 | P33: 3482 | Q33: 4942 | T33: 2899 | U33: 3482 | V33: 3215 | W33: 3489 | X33: 3895 | Y33: 4942 | Z33: 4374 | AA33: 5670 | AC33: =AA33 -> 5670
B34: PP&E | M34: 163 | N34: 144 | O34: 121 | P34: 117 | Q34: 121 | T34: 116 | U34: 117 | V34: 111 | W34: 109 | X34: 118 | Y34: 121 | Z34: 122 | AA34: 124 | AC34: =AA34 -> 124
B35: Marketable securities and investments | M35: 45 | N35: 102 | O35: 234 | P35: 267 | Q35: 376 | T35: 264 | U35: 267 | V35: 261 | W35: 282 | X35: 302 | Y35: 376 | Z35: 385 | AA35: 202 | AC35: =AA35 -> 202
B36: Goodwill | M36: 3604 | N36: 3625 | O36: 3653 | P36: 4242 | Q36: 4295 | T36: 4256 | U36: 4242 | V36: 4275 | W36: 4275 | X36: 4278 | Y36: 4295 | Z36: 4337 | AA36: 4331 | AC36: =AA36 -> 4331
B37: Long term assets | M37: =M38-M33 -> 5843 | N37: =N38-N33 -> 6097 | O37: =O38-O33 -> 6333 | P37: =P38-P33 -> 7351 | Q37: =Q38-Q33 -> 7525 | T37: =T38-T33 -> 7234 | U37: =U38-U33 -> 7351 | V37: =V38-V33 -> 7370 | W37: =W38-W33 -> 7367 | X37: =X38-X33 -> 7303 | Y37: =Y38-Y33 -> 7525 | Z37: =Z38-Z33 -> 7558 | AA37: =AA38-AA33 -> 7313 | AC37: =AA37 -> 7313
B38: Total assets | M38: 8607 | N38: 9438 | O38: 9912 | P38: 10833 | Q38: 12467 | T38: 10133 | U38: 10833 | V38: 10585 | W38: 10856 | X38: 11198 | Y38: 12467 | Z38: 11932 | AA38: 12983 | AC38: =AA38 -> 12983
B39: Acc payable | M39: 121 | N39: 102 | O39: 100 | P39: 242 | Q39: 422 | T39: 217 | U39: 242 | V39: 277 | W39: 324 | X39: 384 | Y39: 422 | Z39: 403 | AA39: 457 | AC39: =AA39 -> 457
B40: Debt | M40: 0 | N40: 0 | O40: 0 | P40: 300 | Q40: 0 | T40: 300 | U40: 300 | V40: 300 | W40: 0 | X40: 0 | Y40: 0 | Z40: 0 | AA40: =994+499 -> 1493 | AC40: =AA40 -> 1493
B41: Current liabilities | M41: 4009 | N41: 4000 | O41: 4351 | P41: 5151 | Q41: 5808 | T41: 4468 | U41: 5151 | V41: 4919 | W41: 4566 | X41: 4735 | Y41: 5808 | Z41: 5240 | AA41: 6628 | AC41: =AA41 -> 6628
B42: Debt | M42: 2280 | N42: 2281 | O42: 2284 | P42: 1987 | Q42: 2483 | T42: 1986 | U42: 1987 | V42: 1988 | W42: 2481 | X42: 2482 | Y42: 2483 | Z42: 2484 | AA42: 1985 | AC42: =AA42 -> 1985
...

Sheet Analysis ->
H5: Links
H6: Overview'!B3
H7: Financials ->'!B13
H8: Analysis ->'!B13
H9: Forecast ->'!B13
H10: Valuation ->'!B13
B13: Analysis ->

Sheet Basic
B1: TTM/YTD data
B4: Overview | E4: CAGR
B5: Price | C5: =Overview!C5 -> 233.54 | F5: 5Y | G5: 10Y
B6: Market capitalization | C6: =Statement!AC154 -> 49043.4 | E6: Revenue | F6: =IF(Statement!M5<=0,"N/A",_xlfn.RRI(4,Statement!M5,Statement!Q5)) -> 0.13215635 | G6: =IF(Statement!H5<=0,"N/A",_xlfn.RRI(9,Statement!H5,Statement!Q5)) -> N/A
B7: Enterprise value | C7: =Statement!AC155 -> 48164.4 | E7: Net income | F7: =IF(OR(Statement!M19<=0, Statement!Q19<=0), "N/A", _xlfn.RRI(4, Statement!M19, Statement!Q19)) -> 0.22631624 | G7: =IF(OR(Statement!H19<=0, Statement!Q19<=0), "N/A", _xlfn.RRI(9, Statement!H19, Statement!Q19)) -> N/A
B8: PE | C8: =Statement!AC151 -> 30.21216 | E8: EPS | F8: =IF(OR(Statement!M27<=0, Statement!Q27<=0), "N/A", _xlfn.RRI(4, Statement!M27, Statement!Q27)) -> 0.23612793 | G8: =IF(OR(Statement!H27<=0, Statement!Q27<=0), "N/A", _xlfn.RRI(9, Statement!H27, Statement!Q27)) -> N/A
B9: PS | C9: =Statement!AC152 -> 6.3856252 | E9: Dividend | F9: =IF(Statement!M83<=0,"N/A",_xlfn.RRI(4,Statement!M83,Statement!Q83)) -> N/A | G9: =IF(Statement!H83<=0,"N/A",_xlfn.RRI(9,Statement!H83,Statement!Q83)) -> N/A
B10: PB | C10: =Statement!AC153 -> 14.427981 | E10: Price | F10: =IF(Statement!M118<=0,"N/A",_xlfn.RRI(4,Statement!M118,Statement!Q118)) -> 0.0030684375 | G10: =IF(Statement!H118<=0,"N/A",_xlfn.RRI(9,Statement!H118,Statement!Q118)) -> N/A
B11: EV/Revenue | C11: =Statement!AC156 -> 6.1828498
B12: EV/EBIT | C12: =Statement!AC157 -> 23.598432
B15: Margins | E15: Earnings quality
B16: Gross margin | C16: =Statement!AC102 -> 0.91245186 | E16: Net income | F16: =Statement!AC19 -> 1642
B17: Operating margin | C17: =Statement!AC103 -> 0.26200257 | E17: Operating cash | F17: =Statement!AC60 -> 2896
B18: Net margin | C18: =Statement!AC104 -> 0.21078306 | E18: Cash accruals | F18: =IF(OR(F16<=0, F17<=0),"N/A",F16-F17) -> -1254
B21: DuPont Identity | E21: Performance indicators
B22: Profit Margin (Earnings/Revenue) | C22: =Statement!AC122 -> 0.21078306 | E22: ROA | F22: =C24 -> 0.12647308
B23: Asset Turnover (Revenue/Total assets) | C23: =Statement!AC123 -> 0.6000154 | E23: ROE | F23: =C26 -> 0.48536802
B24: ROA | C24: =Statement!AC124 -> 0.12647308 | E24: ROIC | F24: =Statement!AC141 -> 0.63581348
B25: Equity Multiplier (Total assets/Equity) | C25: =Statement!AC125 -> 3.837718
B26: ROE | C26: =Statement!AC126 -> 0.48536802
B29: Cash conversion cycle | E29: Liquidity ratios
B30: DSO | C30: =Statement!AC142 -> 32.04878 | E30: Debt/Equity | F30: =Statement!AC146 -> 1.0280816
B31: DIO | C31: =Statement!AC143 -> 0 | E31: Net Debt/Equity | F31: =Statement!AC147 -> -0.25982855
B32: DPO | C32: =Statement!AC144 -> 244.58211 | E32: Current ratio | F32: =Statement!AC149 -> 0.85546168
B33: Net trade cycle | C33: =Statement!AC145 -> -212.53333 | E33: Quick ratio | F33: =Statement!AC148 -> 0.76056126
E34: Interest coverage | F34: =Statement!AC150 -> N/A
B37: Earnings yields | E37: Payout ratios
B38: Earnings yield | C38: =Statement!AC163 -> 0.033099255 | E38: Dividend payout ratio | F38: =Statement!AC169 -> 0
B39: FCF yield | C39: =Statement!AC162 -> 0.042778437 | E39: Buyback payout ratio | F39: =Statement!AC170 -> 0.75834128
B40: Dividend yield | C40: =Statement!AC164 -> 0 | E40: Full payout ratio | F40: =Statement!AC171 -> 0.75834128
B41: Buyback yield | C41: =Statement!AC165 -> 0.032440655
B42: Total shareholder yield | C42: =Statement!AC166 -> 0.032440655
B45: Ownership | E45: Cash holdings
B46: Insider ownership | C46: =Statement!AC172 -> 0.0047619048 | E46: Cash per share | F46: =Statement!AC173 -> 20.84689
E47: Net cash per share | F47: =Statement!AC176 -> 4.2057416
E48: Net cash to market cap | F48: =Statement!AC177 -> 0.017922901
B51: Stock based compensation | E51: CapEx usage
B52: Stock based compensation % OCF | C52: =Statement!AC174 -> 0.24378453 | E52: Capex to Revenue | F52: =Statement!AC178 -> 0.011810013
B53: Stock based compensation % Revenue | C53: =Statement!AC175 -> 0.090629012 | E53: CapEx to OCF | F53: =Statement!AC179 -> 0.031767956
E54: CapEx to D&A | F54: =Statement!AC180 -> 0.45771144

Sheet Yearly Analysis
C2: =Statement!M2 -> 31.01.2022 | D2: =Statement!N2 -> 31.01.2023 | E2: =Statement!O2 -> 31.01.2024 | F2: =Statement!P2 -> 31.01.2025 | G2: =Statement!Q2 -> 31.01.2026
C3: =Statement!M3 -> 2022 | D3: =Statement!N3 -> 2023 | E3: =Statement!O3 -> 2024 | F3: =Statement!P3 -> 2025 | G3: =Statement!Q3 -> 2026 | I3: =Statement!AC3 -> TTM/YTD
B5: Overview
B6: Price | C6: =Statement!M117 -> 249.79 | D6: =Statement!N117 -> 215.16 | E6: =Statement!O117 -> 253.81 | F6: =Statement!P117 -> 311.21 | G6: =Statement!Q117 -> 252.87 | I6: =Statement!AC117 -> 233.54
B7: Market capitalization | C7: =Statement!M154 -> 54704.01 | D7: =Statement!N154 -> 46904.88 | E7: =Statement!O154 -> 54822.96 | F7: =Statement!P154 -> 67532.57 | G7: =Statement!Q154 -> 54367.05 | I7: =Statement!AC154 -> 49043.4
B8: Enterprise value | C8: =Statement!M155 -> 55175.01 | D8: =Statement!N155 -> 47011.88 | E8: =Statement!O155 -> 54626.96 | F8: =Statement!P155 -> 67666.57 | G8: =Statement!Q155 -> 53877.05 | I8: =Statement!AC155 -> 48164.4
B9: PE | C9: =Statement!M151 -> 111.51339 | D9: =Statement!N151 -> 56.920635 | E9: =Statement!O151 -> 60.575179 | F9: =Statement!P151 -> 60.783203 | G9: =Statement!Q151 -> 48.349904 | I9: =Statement!AC151 -> 30.21216
B10: PS | C10: =Statement!M152 -> 12.643269 | D10: =Statement!N152 -> 9.3716044 | E10: =Statement!O152 -> 9.9732509 | F10: =Statement!P152 -> 11.014936 | G10: =Statement!Q152 -> 7.5446919 | I10: =Statement!AC152 -> 6.3856252
B11: PB | C11: =Statement!M153 -> 63.845029 | D11: =Statement!N153 -> 40.589135 | E11: =Statement!O153 -> 29.280507 | F11: =Statement!P153 -> 25.528481 | G11: =Statement!Q153 -> 17.688443 | I11: =Statement!AC153 -> 14.427981
B12: EV/Revenue | C12: =Statement!M156 -> 12.579802 | D12: =Statement!N156 -> 9.392983 | E12: =Statement!O156 -> 9.9375951 | F12: =Statement!P156 -> 11.036792 | G12: =Statement!Q156 -> 7.476693 | I12: =Statement!AC156 -> 6.1828498
B13: EV/EBIT | C13: =Statement!M157 -> 89.279951 | D13: =Statement!N157 -> 47.534762 | E13: =Statement!O157 -> 48.428156 | F13: =Statement!P157 -> 49.97531 | G13: =Statement!Q157 -> 34.142617 | I13: =Statement!AC157 -> 23.598432
B15: Margins
B16: Gross margin | C16: =Statement!M102 -> 0.90469676 | D16: =Statement!N102 -> 0.9040959 | E16: =Statement!O102 -> 0.9070402 | F16: =Statement!P102 -> 0.905725 | G16: =Statement!Q102 -> 0.90979739 | I16: =Statement!AC102 -> 0.91245186
B17: Operating margin | C17: =Statement!M103 -> 0.14090287 | D17: =Statement!N103 -> 0.1976024 | E17: =Statement!O103 -> 0.20520284 | F17: =Statement!P103 -> 0.22084489 | G17: =Statement!Q103 -> 0.21898418 | I17: =Statement!AC103 -> 0.26200257
B18: Net margin | C18: =Statement!M104 -> 0.11331509 | D18: =Statement!N104 -> 0.16443556 | E18: =Statement!O104 -> 0.16481717 | F18: =Statement!P104 -> 0.18137335 | G18: =Statement!Q104 -> 0.15598113 | I18: =Statement!AC104 -> 0.21078306
B20: Earnings quality
B21: Net income | C21: =Statement!M19 -> 497 | D21: =Statement!N19 -> 823 | E21: =Statement!O19 -> 906 | F21: =Statement!P19 -> 1112 | G21: =Statement!Q19 -> 1124 | I21: =Statement!AC19 -> 1642
B22: Operating cash | C22: =Statement!M60 -> 1531 | D22: =Statement!N60 -> 2071 | E22: =Statement!O60 -> 1313 | F22: =Statement!P60 -> 1607 | G22: =Statement!Q60 -> 2452 | I22: =Statement!AC60 -> 2896
B23: Cash accruals | C23: =IF(OR(C21<=0, C22<=0),"N/A",C21-C22) -> -1034 | D23: =IF(OR(D21<=0, D22<=0),"N/A",D21-D22) -> -1248 | E23: =IF(OR(E21<=0, E22<=0),"N/A",E21-E22) -> -407 | F23: =IF(OR(F21<=0, F22<=0),"N/A",F21-F22) -> -495 | G23: =IF(OR(G21<=0, G22<=0),"N/A",G21-G22) -> -1328 | I23: =IF(OR(I21<=0, I22<=0),"N/A",I21-I22) -> -1254
B25: DuPont Identity
B26: Profit Margin (Earnings/Revenue) | C26: =Statement!M122 -> 0.11331509 | D26: =Statement!N122 -> 0.16443556 | E26: =Statement!O122 -> 0.16481717 | F26: =Statement!P122 -> 0.18137335 | G26: =Statement!Q122 -> 0.15598113 | I26: =Statement!AC122 -> 0.21078306
B27: Asset Turnover (Revenue/Total assets) | C27: =Statement!M123 -> 0.50958522 | D27: =Statement!N123 -> 0.53030303 | E27: =Statement!O123 -> 0.55458031 | F27: =Statement!P123 -> 0.56595588 | G27: =Statement!Q123 -> 0.57800594 | I27: =Statement!AC123 -> 0.6000154
B28: ROA | C28: =Statement!M124 -> 0.057743697 | D28: =Statement!N124 -> 0.087200678 | E28: =Statement!O124 -> 0.091404358 | F28: =Statement!P124 -> 0.10264931 | G28: =Statement!Q124 -> 0.090158017 | I28: =Statement!AC124 -> 0.12647308
B29: Equity Multiplier (Total assets/Equity) | C29: =Statement!M125 -> 10.137809 | D29: =Statement!N125 -> 8.2427948 | E29: =Statement!O125 -> 5.3433962 | F29: =Statement!P125 -> 4.1331553 | G29: =Statement!Q125 -> 4.0942529 | I29: =Statement!AC125 -> 3.837718
B30: ROE | C30: =Statement!M126 -> 0.58539458 | D30: =Statement!N126 -> 0.71877729 | E30: =Statement!O126 -> 0.4884097 | F30: =Statement!P126 -> 0.42426555 | G30: =Statement!Q126 -> 0.36912972 | I30: =Statement!AC126 -> 0.48536802
B32: Performance Indicators
B33: ROA | C33: =C28 -> 0.057743697 | D33: =D28 -> 0.087200678 | E33: =E28 -> 0.091404358 | F33: =F28 -> 0.10264931 | G33: =G28 -> 0.090158017 | I33: =I28 -> 0.12647308
B34: ROE | C34: =C30 -> 0.58539458 | D34: =D30 -> 0.71877729 | E34: =E30 -> 0.4884097 | F34: =F30 -> 0.42426555 | G34: =G30 -> 0.36912972 | I34: =I30 -> 0.48536802
B35: ROIC | C35: =Statement!M141 -> 0.41183427 | D35: =Statement!N141 -> 0.68722771 | E35: =Statement!O141 -> 0.54226626 | F35: =Statement!P141 -> 0.39488056 | G35: =Statement!Q141 -> 0.43306081 | I35: =Statement!AC141 -> 0.63581348
B37: Cash conversion cycle
B38: DSO | C38: =Statement!M142 -> 59.585043 | D38: =Statement!N142 -> 70.082917 | E38: =Statement!O142 -> 58.166273 | F38: =Statement!P142 -> 60.009786 | G38: =Statement!Q142 -> 72.888565 | I38: =Statement!AC142 -> 32.04878
B39: DIO | C39: =Statement!M143 -> 0 | D39: =Statement!N143 -> 0 | E39: =Statement!O143 -> 0 | F39: =Statement!P143 -> 0 | G39: =Statement!Q143 -> 0 | I39: =Statement!AC143 -> 0
B40: DPO | C40: =Statement!M144 -> 105.65789 | D40: =Statement!N144 -> 77.5625 | E40: =Statement!O144 -> 71.428571 | F40: =Statement!P144 -> 152.82007 | G40: =Statement!Q144 -> 236.96923 | I40: =Statement!AC144 -> 244.58211
B41: Net trade cycle | C41: =Statement!M145 -> -46.072851 | D41: =Statement!N145 -> -7.4795829 | E41: =Statement!O145 -> -13.262299 | F41: =Statement!P145 -> -92.810283 | G41: =Statement!Q145 -> -164.08067 | I41: =Statement!AC145 -> -212.53333
B43: Liquidity ratios
B44: Debt/Equity | C44: =Statement!M146 -> 2.6855124 | D44: =Statement!N146 -> 1.9921397 | E44: =Statement!O146 -> 1.2312668 | F44: =Statement!P146 -> 0.87256772 | G44: =Statement!Q146 -> 0.81543514 | I44: =Statement!AC146 -> 1.0280816
B45: Net Debt/Equity | C45: =Statement!M147 -> 0.55477032 | D45: =Statement!N147 -> 0.093449782 | E45: =Statement!O147 -> -0.10566038 | F45: =Statement!P147 -> 0.051125525 | G45: =Statement!Q147 -> -0.16091954 | I45: =Statement!AC147 -> -0.25982855
B46: Quick ratio | C46: =Statement!M148 -> 0.62983288 | D46: =Statement!N148 -> 0.78375 | E46: =Statement!O148 -> 0.77131694 | F46: =Statement!P148 -> 0.61366725 | G46: =Statement!Q148 -> 0.75964187 | I46: =Statement!AC148 -> 0.76056126
B47: Current ratio | C47: =Statement!M149 -> 0.68944874 | D47: =Statement!N149 -> 0.83525 | E47: =Statement!O149 -> 0.82256952 | F47: =Statement!P149 -> 0.67598525 | G47: =Statement!Q149 -> 0.85089532 | I47: =Statement!AC149 -> 0.85546168
B48: Interest coverage | C48: =Statement!M150 -> 11.660377 | D48: =Statement!N150 -> 23 | E48: =Statement!O150 -> N/A | F48: =Statement!P150 -> N/A | G48: =Statement!Q150 -> N/A | I48: =Statement!AC150 -> N/A
...

Sheet Quarter analysis
C3: Latest 2 quarters | F3: YoY
C4: =Statement!Z2 -> 30.04.2026 | D4: =Statement!AA2 -> 31.07.2026 | F4: =Statement!W2 -> 31.07.2025 | G4: =Statement!AA2 -> 31.07.2026
B5: Income statement growth | C5: =Statement!Z3 -> Q1 2027 | D5: =Statement!AA3 -> Q2 2027 | F5: =Statement!W3 -> Q2 2026 | G5: =Statement!AA3 -> Q2 2027
B6: Revenue | C6: =Statement!Z5 -> 1934 | D6: =Statement!AA5 -> 2046 | F6: =Statement!W5 -> 1763 | G6: =Statement!AA5 -> 2046
B7: Growth | C7: =Statement!AA90 -> 0.057911065 | F7: =IF(F6=0, IF(G6=0,0,IF(G6>0,1,-1)), (G6-F6)/ABS(F6) ) -> 0.16052184
B8: COGS | C8: =Statement!Z6 -> 175 | D8: =Statement!AA6 -> 176 | F8: =Statement!W6 -> 159 | G8: =Statement!AA6 -> 176
B9: Growth | C9: =Statement!AA91 -> 0.0057142857 | F9: =IF(F8=0, IF(G8=0,0,IF(G8>0,1,-1)), (G8-F8)/ABS(F8) ) -> 0.10691824
B10: Gross Profit | C10: =Statement!Z7 -> 1759 | D10: =Statement!AA7 -> 1870 | F10: =Statement!W7 -> 1604 | G10: =Statement!AA7 -> 1870
B11: Growth | C11: =Statement!AA92 -> 0.063104036 | F11: =IF(F10=0, IF(G10=0,0,IF(G10>0,1,-1)), (G10-F10)/ABS(F10) ) -> 0.16583541
B12: OpEx | C12: =Statement!Z12 -> 1218 | D12: =Statement!AA12 -> 1271 | F12: =Statement!W12 -> 1160 | G12: =Statement!AA12 -> 1271
B13: Growth | C13: =Statement!AA96 -> 0.043513957 | F13: =IF(F12=0, IF(G12=0,0,IF(G12>0,1,-1)), (G12-F12)/ABS(F12) ) -> 0.095689655
B14: Operating profit | C14: =Statement!Z13 -> 541 | D14: =Statement!AA13 -> 599 | F14: =Statement!W13 -> 444 | G14: =Statement!AA13 -> 599
B15: Growth | C15: =Statement!AA97 -> 0.10720887 | F15: =IF(F14=0, IF(G14=0,0,IF(G14>0,1,-1)), (G14-F14)/ABS(F14) ) -> 0.3490991
B16: Net income | C16: =Statement!Z19 -> 491 | D16: =Statement!AA19 -> 492 | F16: =Statement!W19 -> 313 | G16: =Statement!AA19 -> 492
B17: Growth | C17: =Statement!AA99 -> 0.0020366599 | F17: =IF(F16=0, IF(G16=0,0,IF(G16>0,1,-1)), (G16-F16)/ABS(F16) ) -> 0.57188498
B18: Diluted shares outstanding | C18: =Statement!Z23 -> 212 | D18: =Statement!AA23 -> 211 | F18: =Statement!W23 -> 215 | G18: =Statement!AA23 -> 211
B19: Growth | C19: =IF(C18=0, IF(D18=0,0,IF(D18>0,1,-1)), (D18-C18)/ABS(C18) ) -> -0.0047169811 | F19: =IF(F18=0, IF(G18=0,0,IF(G18>0,1,-1)), (G18-F18)/ABS(F18) ) -> -0.018604651
B20: Diluted EPS | C20: =Statement!Z27 -> 2.32 | D20: =Statement!AA27 -> 2.33 | F20: =Statement!W27 -> 1.46 | G20: =Statement!AA27 -> 2.33
B21: Growth | C21: =IF(C20=0, IF(D20=0,0,IF(D20>0,1,-1)), (D20-C20)/ABS(C20) ) -> 0.0043103448 | F21: =IF(F20=0, IF(G20=0,0,IF(G20>0,1,-1)), (G20-F20)/ABS(F20) ) -> 0.59589041
B23: Revenue breakdown | C23: =C5 -> Q1 2027 | D23: =D5 -> Q2 2027 | F23: =F5 -> Q2 2026 | G23: =G5 -> Q2 2027
B24: =Statement!B188 -> Subscription | C24: =Statement!Z188 -> 1836 | D24: =Statement!AA188 -> 1952 | F24: =Statement!W188 -> 1667 | G24: =Statement!AA188 -> 1952
B25: Growth | C25: =IF(C24=0, IF(D24=0,0,IF(D24>0,1,-1)), (D24-C24)/ABS(C24) ) -> 0.063180828 | F25: =IF(F24=0, IF(G24=0,0,IF(G24>0,1,-1)), (G24-F24)/ABS(F24) ) -> 0.17096581
B26: =Statement!B189 -> Other | C26: =Statement!Z189 -> 98 | D26: =Statement!AA189 -> 94 | F26: =Statement!W189 -> 96 | G26: =Statement!AA189 -> 94
B27: Growth | C27: =IF(C26=0, IF(D26=0,0,IF(D26>0,1,-1)), (D26-C26)/ABS(C26) ) -> -0.040816327 | F27: =IF(F26=0, IF(G26=0,0,IF(G26>0,1,-1)), (G26-F26)/ABS(F26) ) -> -0.020833333
B29: =Statement!B195 -> AECO | C29: =Statement!Z195 -> 970 | D29: =Statement!AA195 -> 1029 | F29: =Statement!W195 -> 878 | G29: =Statement!AA195 -> 1029
B30: Growth | C30: =IF(C29=0, IF(D29=0,0,IF(D29>0,1,-1)), (D29-C29)/ABS(C29) ) -> 0.060824742 | F30: =IF(F29=0, IF(G29=0,0,IF(G29>0,1,-1)), (G29-F29)/ABS(F29) ) -> 0.17198178
B31: =Statement!B196 -> AutoCAD and AutoCAD LT | C31: =Statement!Z196 -> 474 | D31: =Statement!AA196 -> 500 | F31: =Statement!W196 -> 440 | G31: =Statement!AA196 -> 500
B32: Growth | C32: =IF(C31=0, IF(D31=0,0,IF(D31>0,1,-1)), (D31-C31)/ABS(C31) ) -> 0.054852321 | F32: =IF(F31=0, IF(G31=0,0,IF(G31>0,1,-1)), (G31-F31)/ABS(F31) ) -> 0.13636364
B33: =Statement!B197 -> Manufacturing | C33: =Statement!Z197 -> 367 | D33: =Statement!AA197 -> 385 | F33: =Statement!W197 -> 334 | G33: =Statement!AA197 -> 385
B34: Growth | C34: =IF(C33=0, IF(D33=0,0,IF(D33>0,1,-1)), (D33-C33)/ABS(C33) ) -> 0.049046322 | F34: =IF(F33=0, IF(G33=0,0,IF(G33>0,1,-1)), (G33-F33)/ABS(F33) ) -> 0.15269461
B35: =Statement!B198 -> Media and Entertainment | C35: =Statement!Z198 -> 86 | D35: =Statement!AA198 -> 92 | F35: =Statement!W198 -> 80 | G35: =Statement!AA198 -> 92
B36: Growth | C36: =IF(C35=0, IF(D35=0,0,IF(D35>0,1,-1)), (D35-C35)/ABS(C35) ) -> 0.069767442 | F36: =IF(F35=0, IF(G35=0,0,IF(G35>0,1,-1)), (G35-F35)/ABS(F35) ) -> 0.15
B37: =Statement!B199 -> Other | C37: =Statement!Z199 -> 37 | D37: =Statement!AA199 -> 40 | F37: =Statement!W199 -> 31 | G37: =Statement!AA199 -> 40
B38: Growth | C38: =IF(C37=0, IF(D37=0,0,IF(D37>0,1,-1)), (D37-C37)/ABS(C37) ) -> 0.081081081 | F38: =IF(F37=0, IF(G37=0,0,IF(G37>0,1,-1)), (G37-F37)/ABS(F37) ) -> 0.29032258

Sheet Graphs Year
C66: =Statement!H2 -> 0 | D66: =Statement!I2 -> 0 | E66: =Statement!J2 -> 0 | F66: =Statement!K2 -> 0 | G66: =Statement!L2 -> 0 | H66: =Statement!M2 -> 31.01.2022 | I66: =Statement!N2 -> 31.01.2023 | J66: =Statement!O2 -> 31.01.2024 | ... L66: =Statement!Q2 -> 31.01.2026
C67: =Statement!H3 -> 0 | D67: =Statement!I3 -> 0 | E67: =Statement!J3 -> 0 | F67: =Statement!K3 -> 0 | G67: =Statement!L3 -> 0 | H67: =Statement!M3 -> 2022 | I67: =Statement!N3 -> 2023 | J67: =Statement!O3 -> 2024 | ... L67: =Statement!Q3 -> 2026
B68: Revenue | C68: =Statement!H5 -> 0 | D68: =Statement!I5 -> 0 | E68: =Statement!J5 -> 0 | F68: =Statement!K5 -> 0 | G68: =Statement!L5 -> 0 | H68: =Statement!M5 -> 4386 | I68: =Statement!N5 -> 5005 | J68: =Statement!O5 -> 5497 | ... L68: =Statement!Q5 -> 7206
B69: Operating income | C69: =Statement!H13 -> 0 | D69: =Statement!I13 -> 0 | E69: =Statement!J13 -> 0 | F69: =Statement!K13 -> 0 | G69: =Statement!L13 -> 0 | H69: =Statement!M13 -> 618 | I69: =Statement!N13 -> 989 | J69: =Statement!O13 -> 1128 | ... L69: =Statement!Q13 -> 1578
B70: Net income | C70: =Statement!H19 -> 0 | D70: =Statement!I19 -> 0 | E70: =Statement!J19 -> 0 | F70: =Statement!K19 -> 0 | G70: =Statement!L19 -> 0 | H70: =Statement!M19 -> 497 | I70: =Statement!N19 -> 823 | J70: =Statement!O19 -> 906 | ... L70: =Statement!Q19 -> 1124
B71: FCFE | C71: =Statement!H158 -> 0 | D71: =Statement!I158 -> 0 | E71: =Statement!J158 -> 0 | F71: =Statement!K158 -> 0 | G71: =Statement!L158 -> 0 | H71: =Statement!M158 -> 909 | I71: =Statement!N158 -> 1368 | J71: =Statement!O158 -> 549 | ... L71: =Statement!Q158 -> 1588
B72: FCFF | C72: =Statement!H159 -> 0 | D72: =Statement!I159 -> 0 | E72: =Statement!J159 -> 0 | F72: =Statement!K159 -> 0 | G72: =Statement!L159 -> 0 | H72: =Statement!M159 -> 841.62124 | I72: =Statement!N159 -> 1656.4091 | J72: =Statement!O159 -> 526.61972 | ... L72: =Statement!Q159 -> 724.47037
B73: Gross margin | C73: =Statement!H102 -> 0 | D73: =Statement!I102 -> 0 | E73: =Statement!J102 -> 0 | F73: =Statement!K102 -> 0 | G73: =Statement!L102 -> 0 | H73: =Statement!M102 -> 0.90469676 | I73: =Statement!N102 -> 0.9040959 | J73: =Statement!O102 -> 0.9070402 | ... L73: =Statement!Q102 -> 0.90979739
B74: Operating margin | C74: =Statement!H103 -> 0 | D74: =Statement!I103 -> 0 | E74: =Statement!J103 -> 0 | F74: =Statement!K103 -> 0 | G74: =Statement!L103 -> 0 | H74: =Statement!M103 -> 0.14090287 | I74: =Statement!N103 -> 0.1976024 | J74: =Statement!O103 -> 0.20520284 | ... L74: =Statement!Q103 -> 0.21898418
B75: Net margin | C75: =Statement!H104 -> 0 | D75: =Statement!I104 -> 0 | E75: =Statement!J104 -> 0 | F75: =Statement!K104 -> 0 | G75: =Statement!L104 -> 0 | H75: =Statement!M104 -> 0.11331509 | I75: =Statement!N104 -> 0.16443556 | J75: =Statement!O104 -> 0.16481717 | ... L75: =Statement!Q104 -> 0.15598113
B76: ="Revenue "&Statement!B188 -> Revenue Subscription | C76: =Statement!H188 -> 0 | D76: =Statement!I188 -> 0 | E76: =Statement!J188 -> 0 | F76: =Statement!K188 -> 0 | G76: =Statement!L188 -> 0 | H76: =Statement!M188 -> 4136 | I76: =Statement!N188 -> 4716 | J76: =Statement!O188 -> 5170 | ... L76: =Statement!Q188 -> 6776
B77: ="Revenue "&Statement!B189 -> Revenue Other | C77: =Statement!H189 -> 0 | D77: =Statement!I189 -> 0 | E77: =Statement!J189 -> 0 | F77: =Statement!K189 -> 0 | G77: =Statement!L189 -> 0 | H77: =Statement!M189 -> 250 | I77: =Statement!N189 -> 289 | J77: =Statement!O189 -> 327 | ... L77: =Statement!Q189 -> 430
B78: ="Revenue "&Statement!B195 -> Revenue AECO | C78: =Statement!H195 -> 0 | D78: =Statement!I195 -> 0 | E78: =Statement!J195 -> 0 | F78: =Statement!K195 -> 0 | G78: =Statement!L195 -> 0 | H78: =Statement!M195 -> 1969 | I78: =Statement!N195 -> 2278 | J78: =Statement!O195 -> 2580 | ... L78: =Statement!Q195 -> 3583
B79: ="Revenue "&Statement!B196 -> Revenue AutoCAD and AutoCAD LT | C79: =Statement!H196 -> 0 | D79: =Statement!I196 -> 0 | E79: =Statement!J196 -> 0 | F79: =Statement!K196 -> 0 | G79: =Statement!L196 -> 0 | H79: =Statement!M196 -> 1244 | I79: =Statement!N196 -> 1387 | J79: =Statement!O196 -> 1462 | ... L79: =Statement!Q196 -> 1787
B80: ="Revenue "&Statement!B197 -> Revenue Manufacturing | C80: =Statement!H197 -> 0 | D80: =Statement!I197 -> 0 | E80: =Statement!J197 -> 0 | F80: =Statement!K197 -> 0 | G80: =Statement!L197 -> 0 | H80: =Statement!M197 -> 876 | I80: =Statement!N197 -> 978 | J80: =Statement!O197 -> 1063 | ... L80: =Statement!Q197 -> 1379
B81: ="Revenue "&Statement!B198 -> Revenue Media and Entertainment | C81: =Statement!H198 -> 0 | D81: =Statement!I198 -> 0 | E81: =Statement!J198 -> 0 | F81: =Statement!K198 -> 0 | G81: =Statement!L198 -> 0 | H81: =Statement!M198 -> 259 | I81: =Statement!N198 -> 291 | J81: =Statement!O198 -> 295 | ... L81: =Statement!Q198 -> 332
B82: ="Revenue "&Statement!B199 -> Revenue Other | C82: =Statement!H199 -> 0 | D82: =Statement!I199 -> 0 | E82: =Statement!J199 -> 0 | F82: =Statement!K199 -> 0 | G82: =Statement!L199 -> 0 | H82: =Statement!M199 -> 38 | I82: =Statement!N199 -> 71 | J82: =Statement!O199 -> 97 | ... L82: =Statement!Q199 -> 125
B83: ROA | C83: =Statement!H124 -> 0 | D83: =Statement!I124 -> 0 | E83: =Statement!J124 -> 0 | F83: =Statement!K124 -> 0 | G83: =Statement!L124 -> 0 | H83: =Statement!M124 -> 0.057743697 | I83: =Statement!N124 -> 0.087200678 | J83: =Statement!O124 -> 0.091404358 | ... L83: =Statement!Q124 -> 0.090158017
B84: ROE | C84: =Statement!H126 -> 0 | D84: =Statement!I126 -> 0 | E84: =Statement!J126 -> 0 | F84: =Statement!K126 -> 0 | G84: =Statement!L126 -> 0 | H84: =Statement!M126 -> 0.58539458 | I84: =Statement!N126 -> 0.71877729 | J84: =Statement!O126 -> 0.4884097 | ... L84: =Statement!Q126 -> 0.36912972
B85: ROIC | C85: =Statement!H141 -> 0 | D85: =Statement!I141 -> 0 | E85: =Statement!J141 -> 0 | F85: =Statement!K141 -> 0 | G85: =Statement!L141 -> 0 | H85: =Statement!M141 -> 0.41183427 | I85: =Statement!N141 -> 0.68722771 | J85: =Statement!O141 -> 0.54226626 | ... L85: =Statement!Q141 -> 0.43306081
B86: Price 5y | C86: =Statement!H218 -> 0 | D86: =Statement!I218 -> 0 | E86: =Statement!J218 -> 0 | F86: =Statement!K218 -> 0 | G86: =Statement!L218 -> 0 | H86: =Statement!M218 -> 100 | I86: =Statement!N218 -> 86.136355 | J86: =Statement!O218 -> 101.60935 | ... L86: =Statement!Q218 -> 101.23304
B87: Revenue 5y | C87: =Statement!H219 -> 0 | D87: =Statement!I219 -> 0 | E87: =Statement!J219 -> 0 | F87: =Statement!K219 -> 0 | G87: =Statement!L219 -> 0 | H87: =Statement!M219 -> 100 | I87: =Statement!N219 -> 114.11309 | J87: =Statement!O219 -> 125.3306 | ... L87: =Statement!Q219 -> 164.29549
B88: EPS 5y | C88: =Statement!H220 -> 0 | D88: =Statement!I220 -> 0 | E88: =Statement!J220 -> 0 | F88: =Statement!K220 -> 0 | G88: =Statement!L220 -> 0 | H88: =Statement!M220 -> 100 | I88: =Statement!N220 -> 168.75 | J88: =Statement!O220 -> 187.05357 | ... L88: =Statement!Q220 -> 233.48214

Sheet Graphs Quarter
C55: =Statement!T2 -> 31.10.2024 | D55: =Statement!U2 -> 31.01.2025 | E55: =Statement!V2 -> 30.04.2025 | F55: =Statement!W2 -> 31.07.2025 | G55: =Statement!X2 -> 31.10.2025 | H55: =Statement!Y2 -> 31.01.2026 | I55: =Statement!Z2 -> 30.04.2026 | J55: =Statement!AA2 -> 31.07.2026
C56: =Statement!T3 -> Q3 2025 | D56: =Statement!U3 -> Q4 2025 | E56: =Statement!V3 -> Q1 2026 | F56: =Statement!W3 -> Q2 2026 | G56: =Statement!X3 -> Q3 2026 | H56: =Statement!Y3 -> Q4 2026 | I56: =Statement!Z3 -> Q1 2027 | J56: =Statement!AA3 -> Q2 2027
B57: Revenue | C57: =Statement!T5 -> 1570 | D57: =Statement!U5 -> 1639 | E57: =Statement!V5 -> 1633 | F57: =Statement!W5 -> 1763 | G57: =Statement!X5 -> 1853 | H57: =Statement!Y5 -> 1957 | I57: =Statement!Z5 -> 1934 | J57: =Statement!AA5 -> 2046
B58: Operating income | C58: =Statement!T13 -> 346 | D58: =Statement!U13 -> 366 | E58: =Statement!V13 -> 233 | F58: =Statement!W13 -> 444 | G58: =Statement!X13 -> 470 | H58: =Statement!Y13 -> 431 | I58: =Statement!Z13 -> 541 | J58: =Statement!AA13 -> 599
B59: Net income | C59: =Statement!T19 -> 275 | D59: =Statement!U19 -> 303 | E59: =Statement!V19 -> 152 | F59: =Statement!W19 -> 313 | G59: =Statement!X19 -> 343 | H59: =Statement!Y19 -> 316 | I59: =Statement!Z19 -> 491 | J59: =Statement!AA19 -> 492
B60: Gross margin | C60: =Statement!T102 -> 0.90636943 | D60: =Statement!U102 -> 0.90604027 | E60: =Statement!V102 -> 0.90202082 | F60: =Statement!W102 -> 0.90981282 | G60: =Statement!X102 -> 0.91095521 | H60: =Statement!Y102 -> 0.91517629 | I60: =Statement!Z102 -> 0.90951396 | J60: =Statement!AA102 -> 0.91397849
B61: Operating margin | C61: =Statement!T103 -> 0.22038217 | D61: =Statement!U103 -> 0.22330689 | E61: =Statement!V103 -> 0.14268218 | F61: =Statement!W103 -> 0.25184345 | G61: =Statement!X103 -> 0.25364274 | H61: =Statement!Y103 -> 0.22023505 | I61: =Statement!Z103 -> 0.27973113 | J61: =Statement!AA103 -> 0.29276637
B62: Net margin | C62: =Statement!T104 -> 0.17515924 | D62: =Statement!U104 -> 0.18486882 | E62: =Statement!V104 -> 0.09308022 | F62: =Statement!W104 -> 0.17753829 | G62: =Statement!X104 -> 0.18510523 | H62: =Statement!Y104 -> 0.16147164 | I62: =Statement!Z104 -> 0.25387797 | J62: =Statement!AA104 -> 0.24046921
B63: ="Revenue "&Statement!B188 -> Revenue Subscription | C63: =Statement!T188 -> 1466 | D63: =Statement!U188 -> 1532 | E63: =Statement!V188 -> 1540 | F63: =Statement!W188 -> 1667 | G63: =Statement!X188 -> 1742 | H63: =Statement!Y188 -> 1827 | I63: =Statement!Z188 -> 1836 | J63: =Statement!AA188 -> 1952
B64: ="Revenue "&Statement!B189 -> Revenue Other | C64: =Statement!T189 -> 104 | D64: =Statement!U189 -> 107 | E64: =Statement!V189 -> 93 | F64: =Statement!W189 -> 96 | G64: =Statement!X189 -> 111 | H64: =Statement!Y189 -> 130 | I64: =Statement!Z189 -> 98 | J64: =Statement!AA189 -> 94
B65: ="Revenue "&Statement!B195 -> Revenue AECO | C65: =Statement!T195 -> 751 | D65: =Statement!U195 -> 799 | E65: =Statement!V195 -> 809 | F65: =Statement!W195 -> 878 | G65: =Statement!X195 -> 921 | H65: =Statement!Y195 -> 975 | I65: =Statement!Z195 -> 970 | J65: =Statement!AA195 -> 1029
B66: ="Revenue "&Statement!B196 -> Revenue AutoCAD and AutoCAD LT | C66: =Statement!T196 -> 398 | D66: =Statement!U196 -> 409 | E66: =Statement!V196 -> 411 | F66: =Statement!W196 -> 440 | G66: =Statement!X196 -> 458 | H66: =Statement!Y196 -> 478 | I66: =Statement!Z196 -> 474 | J66: =Statement!AA196 -> 500
B67: ="Revenue "&Statement!B197 -> Revenue Manufacturing | C67: =Statement!T197 -> 307 | D67: =Statement!U197 -> 318 | E67: =Statement!V197 -> 309 | F67: =Statement!W197 -> 334 | G67: =Statement!X197 -> 355 | H67: =Statement!Y197 -> 381 | I67: =Statement!Z197 -> 367 | J67: =Statement!AA197 -> 385
B68: ="Revenue "&Statement!B198 -> Revenue Media and Entertainment | C68: =Statement!T198 -> 83 | D68: =Statement!U198 -> 84 | E68: =Statement!V198 -> 76 | F68: =Statement!W198 -> 80 | G68: =Statement!X198 -> 86 | H68: =Statement!Y198 -> 90 | I68: =Statement!Z198 -> 86 | J68: =Statement!AA198 -> 92
B69: ="Revenue "&Statement!B199 -> Revenue Other | C69: =Statement!T199 -> 31 | D69: =Statement!U199 -> 29 | E69: =Statement!V199 -> 28 | F69: =Statement!W199 -> 31 | G69: =Statement!X199 -> 33 | H69: =Statement!Y199 -> 33 | I69: =Statement!Z199 -> 37 | J69: =Statement!AA199 -> 40
B70: FCFE | C70: =Statement!T158 -> 0 | D70: =Statement!U158 -> 0 | E70: =Statement!V158 -> 319 | F70: =Statement!W158 -> 253 | G70: =Statement!X158 -> 231 | H70: =Statement!Y158 -> 785 | I70: =Statement!Z158 -> 712 | J70: =Statement!AA158 -> 370

Sheet Forecast ->
H5: Links
H6: Overview'!B3
H7: Financials ->'!B13
H8: Analysis ->'!B13
H9: Forecast ->'!B13
H10: Valuation ->'!B13
B13: Forecast ->

Sheet Revenue
B1: Revenue forecast
C2: History | H2: Forecast | S2: History | AA2: Forecast | AE2: TTM
C4: Revenues | S4: Revenues
B5: Revenues (thousand) | C5: =Statement!M3 -> 2022 | D5: =Statement!N3 -> 2023 | E5: =Statement!O3 -> 2024 | F5: =Statement!P3 -> 2025 | G5: =Statement!Q3 -> 2026 | H5: =G5+1 -> 2027 | I5: =H5+1 -> 2028 | J5: =I5+1 -> 2029 | K5: =J5+1 -> 2030 | L5: =K5+1 -> 2031 | R5: =B5 -> Revenues (thousand) | S5: =Statement!T3 -> Q3 2025 | T5: =Statement!U3 -> Q4 2025 | U5: =Statement!V3 -> Q1 2026 | V5: =Statement!W3 -> Q2 2026 | W5: =Statement!X3 -> Q3 2026 | X5: =Statement!Y3 -> Q4 2026 | Y5: =Statement!Z3 -> Q1 2027 | Z5: =Statement!AA3 -> Q2 2027 | AA5: FQ1 | AB5: FQ2 | AC5: FQ3 | AE5: FQ1
B6: =Statement!B188 -> Subscription | C6: =Statement!M188 -> 4136 | D6: =Statement!N188 -> 4716 | E6: =Statement!O188 -> 5170 | F6: =Statement!P188 -> 5758 | G6: =Statement!Q188 -> 6776 | H6: =H14-H7 -> 7878.2949 | I6: =I14-I7 -> 9167.4253 | J6: =J14-J7 -> 10360.902 | K6: =K14-K7 -> 11639.445 | L6: =L14-L7 -> 12716.049 | N6: Revenue - Other | Q6: Revenue - Other | R6: =B6 -> Subscription | S6: =Statement!T188 -> 1466 | T6: =Statement!U188 -> 1532 | U6: =Statement!V188 -> 1540 | V6: =Statement!W188 -> 1667 | W6: =Statement!X188 -> 1742 | X6: =Statement!Y188 -> 1827 | Y6: =Statement!Z188 -> 1836 | Z6: =Statement!AA188 -> 1952 | AA6: =AA14-AA7 -> 2030.5585 | AE6: =SUM(X6:AA6) -> 7645.5585
B7: =Statement!B189 -> Other | C7: =Statement!M189 -> 250 | D7: =Statement!N189 -> 289 | E7: =Statement!O189 -> 327 | F7: =Statement!P189 -> 373 | G7: =Statement!Q189 -> 430 | H7: =H14*H30 -> 458.5251 | I7: =I14*I30 -> 533.55386 | J7: =J14*J30 -> 556.80293 | K7: =K14*K30 -> 612.60235 | L7: =L14*L30 -> 669.26571 | N7: Other % of Revenue | Q7: Other % of Revenue | R7: =B7 -> Other | S7: =Statement!T189 -> 104 | T7: =Statement!U189 -> 107 | U7: =Statement!V189 -> 93 | V7: =Statement!W189 -> 96 | W7: =Statement!X189 -> 111 | X7: =Statement!Y189 -> 130 | Y7: =Statement!Z189 -> 98 | Z7: =Statement!AA189 -> 94 | AA7: =AA14*AA30 -> 106.8715 | AE7: =SUM(X7:AA7) -> 428.8715
B9: =Statement!B195 -> AECO | C9: =Statement!M195 -> 1969 | D9: =Statement!N195 -> 2278 | E9: =Statement!O195 -> 2580 | F9: =Statement!P195 -> 2937 | G9: =Statement!Q195 -> 3583 | H9: =G9*(1+H21) -> 4299.6 | I9: =H9*(1+I21) -> 5159.52 | J9: =I9*(1+J21) -> 5933.448 | K9: =J9*(1+K21) -> 6823.4652 | L9: =K9*(1+L21) -> 7505.8117 | N9: AECO Growth Rate | Q9: AECO Growth Rate | R9: =B9 -> AECO | S9: =Statement!T195 -> 751 | T9: =Statement!U195 -> 799 | U9: =Statement!V195 -> 809 | V9: =Statement!W195 -> 878 | W9: =Statement!X195 -> 921 | X9: =Statement!Y195 -> 975 | Y9: =Statement!Z195 -> 970 | Z9: =Statement!AA195 -> 1029 | AA9: =Z9*(1+AA21) -> 1075.305 | AE9: =SUM(X9:AA9) -> 4049.305
B10: =Statement!B196 -> AutoCAD and AutoCAD LT | C10: =Statement!M196 -> 1244 | D10: =Statement!N196 -> 1387 | E10: =Statement!O196 -> 1462 | F10: =Statement!P196 -> 1572 | G10: =Statement!Q196 -> 1787 | H10: =G10*(1+H22) -> 1965.7 | I10: =H10*(1+I22) -> 2201.584 | J10: =I10*(1+J22) -> 2399.7266 | K10: =J10*(1+K22) -> 2615.702 | L10: =K10*(1+L22) -> 2824.9581 | N10: AutoCAD Growth Rate | Q10: AutoCAD Growth Rate | R10: =B10 -> AutoCAD and AutoCAD LT | S10: =Statement!T196 -> 398 | T10: =Statement!U196 -> 409 | U10: =Statement!V196 -> 411 | V10: =Statement!W196 -> 440 | W10: =Statement!X196 -> 458 | X10: =Statement!Y196 -> 478 | Y10: =Statement!Z196 -> 474 | Z10: =Statement!AA196 -> 500 | AA10: =Z10*(1+AA22) -> 520 | AE10: =SUM(X10:AA10) -> 1972
B11: =Statement!B197 -> Manufacturing | C11: =Statement!M197 -> 876 | D11: =Statement!N197 -> 978 | E11: =Statement!O197 -> 1063 | F11: =Statement!P197 -> 1189 | G11: =Statement!Q197 -> 1379 | H11: =G11*(1+H23) -> 1585.85 | I11: =H11*(1+I23) -> 1823.7275 | J11: =I11*(1+J23) -> 2042.5748 | K11: =J11*(1+K23) -> 2246.8323 | L11: =K11*(1+L23) -> 2471.5155 | N11: Manufacturing Growth Rate | Q11: Manufacturing Growth Rate | R11: =B11 -> Manufacturing | S11: =Statement!T197 -> 307 | T11: =Statement!U197 -> 318 | U11: =Statement!V197 -> 309 | V11: =Statement!W197 -> 334 | W11: =Statement!X197 -> 355 | X11: =Statement!Y197 -> 381 | Y11: =Statement!Z197 -> 367 | Z11: =Statement!AA197 -> 385 | AA11: =Z11*(1+AA23) -> 402.325 | AE11: =SUM(X11:AA11) -> 1535.325
B12: =Statement!B198 -> Media and Entertainment | C12: =Statement!M198 -> 259 | D12: =Statement!N198 -> 291 | E12: =Statement!O198 -> 295 | F12: =Statement!P198 -> 315 | G12: =Statement!Q198 -> 332 | H12: =G12*(1+H24) -> 351.92 | I12: =H12*(1+I24) -> 373.0352 | J12: =I12*(1+J24) -> 391.68696 | K12: =J12*(1+K24) -> 411.27131 | L12: =K12*(1+L24) -> 423.60945 | N12: Media Growth Rate | Q12: Media Growth Rate | R12: =B12 -> Media and Entertainment | S12: =Statement!T198 -> 83 | T12: =Statement!U198 -> 84 | U12: =Statement!V198 -> 76 | V12: =Statement!W198 -> 80 | W12: =Statement!X198 -> 86 | X12: =Statement!Y198 -> 90 | Y12: =Statement!Z198 -> 86 | Z12: =Statement!AA198 -> 92 | AA12: =Z12*(1+AA24) -> 96.6 | AE12: =SUM(X12:AA12) -> 364.6
B13: =Statement!B199 -> Other | C13: =Statement!M199 -> 38 | D13: =Statement!N199 -> 71 | E13: =Statement!O199 -> 97 | F13: =Statement!P199 -> 118 | G13: =Statement!Q199 -> 125 | H13: =G13*(1+H25) -> 133.75 | I13: =H13*(1+I25) -> 143.1125 | J13: =I13*(1+J25) -> 150.26813 | K13: =J13*(1+K25) -> 154.77617 | L13: =K13*(1+L25) -> 159.41945 | N13: Other Growth Rate | Q13: Other Growth Rate | R13: =B13 -> Other | S13: =Statement!T199 -> 31 | T13: =Statement!U199 -> 29 | U13: =Statement!V199 -> 28 | V13: =Statement!W199 -> 31 | W13: =Statement!X199 -> 33 | X13: =Statement!Y199 -> 33 | Y13: =Statement!Z199 -> 37 | Z13: =Statement!AA199 -> 40 | AA13: =Z13*(1+AA25) -> 43.2 | AE13: =SUM(X13:AA13) -> 153.2
B14: Total | C14: =Statement!M5 -> 4386 | D14: =Statement!N5 -> 5005 | E14: =Statement!O5 -> 5497 | F14: =Statement!P5 -> 6131 | G14: =Statement!Q5 -> 7206 | H14: =SUM(H9:H13) -> 8336.82 | I14: =SUM(I9:I13) -> 9700.9792 | J14: =SUM(J9:J13) -> 10917.704 | K14: =SUM(K9:K13) -> 12252.047 | L14: =SUM(L9:L13) -> 13385.314 | R14: Total | S14: =Statement!T5 -> 1570 | T14: =Statement!U5 -> 1639 | U14: =Statement!V5 -> 1633 | V14: =Statement!W5 -> 1763 | W14: =Statement!X5 -> 1853 | X14: =Statement!Y5 -> 1957 | Y14: =Statement!Z5 -> 1934 | Z14: =Statement!AA5 -> 2046 | AA14: =SUM(AA9:AA13) -> 2137.43 | AE14: =SUM(X14:AA14) -> 8074.43
C16: Growth rates | S16: Growth rates
B17: Revenue growth % | C17: =C5 -> 2022 | D17: =D5 -> 2023 | E17: =E5 -> 2024 | F17: =F5 -> 2025 | G17: =G5 -> 2026 | H17: =H5 -> 2027 | I17: =I5 -> 2028 | J17: =J5 -> 2029 | ... L17: =L5 -> 2031 | R17: Revenue growth % | S17: =S5 -> Q3 2025 | T17: =T5 -> Q4 2025 | U17: =U5 -> Q1 2026 | V17: =V5 -> Q2 2026 | W17: =W5 -> Q3 2026 | X17: =X5 -> Q4 2026 | Y17: =Y5 -> Q1 2027 | Z17: =Z5 -> Q2 2027 | ... AC17: =AC5 -> FQ3
B18: =B6 -> Subscription | D18: =D6/C6-1 -> 0.14023211 | E18: =E6/D6-1 -> 0.096268024 | F18: =F6/E6-1 -> 0.11373308 | G18: =G6/F6-1 -> 0.1767975 | H18: =H6/G6-1 -> 0.16267634 | I18: =I6/H6-1 -> 0.16363064 | J18: =J6/I6-1 -> 0.13018663 | K18: =K6/J6-1 -> 0.12340075 | L18: =L6/K6-1 -> 0.092496163 | R18: =R6 -> Subscription | T18: =T6/S6-1 -> 0.045020464 | U18: =U6/T6-1 -> 0.0052219321 | V18: =V6/U6-1 -> 0.082467532 | W18: =W6/V6-1 -> 0.044991002 | X18: =X6/W6-1 -> 0.048794489 | Y18: =Y6/X6-1 -> 0.0049261084 | Z18: =Z6/Y6-1 -> 0.063180828 | AA18: =AA6/Z6-1 -> 0.040245133
B19: =B7 -> Other | D19: =D7/C7-1 -> 0.156 | E19: =E7/D7-1 -> 0.13148789 | F19: =F7/E7-1 -> 0.14067278 | G19: =G7/F7-1 -> 0.15281501 | H19: =H7/G7-1 -> 0.066337442 | I19: =I7/H7-1 -> 0.16363064 | J19: =J7/I7-1 -> 0.043573991 | K19: =K7/J7-1 -> 0.10021395 | L19: =L7/K7-1 -> 0.092496163 | R19: =R7 -> Other | T19: =T7/S7-1 -> 0.028846154 | U19: =U7/T7-1 -> -0.13084112 | V19: =V7/U7-1 -> 0.032258065 | W19: =W7/V7-1 -> 0.15625 | X19: =X7/W7-1 -> 0.17117117 | Y19: =Y7/X7-1 -> -0.24615385 | Z19: =Z7/Y7-1 -> -0.040816327 | AA19: =AA7/Z7-1 -> 0.13693085
B21: =B9 -> AECO | D21: =D9/C9-1 -> 0.15693245 | E21: =E9/D9-1 -> 0.13257243 | F21: =F9/E9-1 -> 0.13837209 | G21: =G9/F9-1 -> 0.21995233 | H21: 0.2 | I21: 0.2 | J21: 0.15 | K21: 0.15 | L21: 0.1 | R21: =R9 -> AECO | T21: =T9/S9-1 -> 0.06391478 | U21: =U9/T9-1 -> 0.012515645 | V21: =V9/U9-1 -> 0.085290482 | W21: =W9/V9-1 -> 0.048974943 | X21: =X9/W9-1 -> 0.058631922 | Y21: =Y9/X9-1 -> -0.0051282051 | Z21: =Z9/Y9-1 -> 0.060824742 | AA21: 0.045
B22: =B10 -> AutoCAD and AutoCAD LT | D22: =D10/C10-1 -> 0.11495177 | E22: =E10/D10-1 -> 0.05407354 | F22: =F10/E10-1 -> 0.075239398 | G22: =G10/F10-1 -> 0.13676845 | H22: 0.1 | I22: 0.12 | J22: 0.09 | K22: 0.09 | L22: 0.08 | R22: =R10 -> AutoCAD and AutoCAD LT | T22: =T10/S10-1 -> 0.027638191 | U22: =U10/T10-1 -> 0.0048899756 | V22: =V10/U10-1 -> 0.070559611 | W22: =W10/V10-1 -> 0.040909091 | X22: =X10/W10-1 -> 0.043668122 | Y22: =Y10/X10-1 -> -0.0083682008 | Z22: =Z10/Y10-1 -> 0.054852321 | AA22: 0.04
B23: =B11 -> Manufacturing | D23: =D11/C11-1 -> 0.11643836 | E23: =E11/D11-1 -> 0.086912065 | F23: =F11/E11-1 -> 0.11853246 | G23: =G11/F11-1 -> 0.15979815 | H23: 0.15 | I23: 0.15 | J23: 0.12 | K23: 0.1 | L23: 0.1 | R23: =R11 -> Manufacturing | T23: =T11/S11-1 -> 0.035830619 | U23: =U11/T11-1 -> -0.028301887 | V23: =V11/U11-1 -> 0.080906149 | W23: =W11/V11-1 -> 0.062874251 | X23: =X11/W11-1 -> 0.073239437 | Y23: =Y11/X11-1 -> -0.036745407 | Z23: =Z11/Y11-1 -> 0.049046322 | AA23: 0.045
B24: =B12 -> Media and Entertainment | D24: =D12/C12-1 -> 0.12355212 | E24: =E12/D12-1 -> 0.013745704 | F24: =F12/E12-1 -> 0.06779661 | G24: =G12/F12-1 -> 0.053968254 | H24: 0.06 | I24: 0.06 | J24: 0.05 | K24: 0.05 | L24: 0.03 | R24: =R12 -> Media and Entertainment | T24: =T12/S12-1 -> 0.012048193 | U24: =U12/T12-1 -> -0.095238095 | V24: =V12/U12-1 -> 0.052631579 | W24: =W12/V12-1 -> 0.075 | X24: =X12/W12-1 -> 0.046511628 | Y24: =Y12/X12-1 -> -0.044444444 | Z24: =Z12/Y12-1 -> 0.069767442 | AA24: 0.05
B25: =B13 -> Other | D25: =D13/C13-1 -> 0.86842105 | E25: =E13/D13-1 -> 0.36619718 | F25: =F13/E13-1 -> 0.21649485 | G25: =G13/F13-1 -> 0.059322034 | H25: 0.07 | I25: 0.07 | J25: 0.05 | K25: 0.03 | L25: 0.03 | R25: =R13 -> Other | T25: =T13/S13-1 -> -0.064516129 | U25: =U13/T13-1 -> -0.034482759 | V25: =V13/U13-1 -> 0.10714286 | W25: =W13/V13-1 -> 0.064516129 | X25: =X13/W13-1 -> 0 | Y25: =Y13/X13-1 -> 0.12121212 | Z25: =Z13/Y13-1 -> 0.081081081 | AA25: 0.08
B26: =B14 -> Total | D26: =D14/C14-1 -> 0.14113087 | E26: =E14/D14-1 -> 0.098301698 | F26: =F14/E14-1 -> 0.11533564 | G26: =G14/F14-1 -> 0.17533844 | H26: =H14/G14-1 -> 0.15692756 | I26: =I14/H14-1 -> 0.16363064 | J26: =J14/I14-1 -> 0.12542293 | K26: =K14/J14-1 -> 0.12221823 | L26: =L14/K14-1 -> 0.092496163 | R26: =R14 -> Total | T26: =T14/S14-1 -> 0.043949045 | U26: =U14/T14-1 -> -0.0036607688 | V26: =V14/U14-1 -> 0.079608083 | W26: =W14/V14-1 -> 0.051049348 | X26: =X14/W14-1 -> 0.056125202 | Y26: =Y14/X14-1 -> -0.011752683 | Z26: =Z14/Y14-1 -> 0.057911065 | AA26: =AA14/Z14-1 -> 0.044687195
C28: Metrics | S28: Metrics
C29: =C17 -> 2022 | D29: =D17 -> 2023 | E29: =E17 -> 2024 | F29: =F17 -> 2025 | G29: =G17 -> 2026 | H29: =H17 -> 2027 | I29: =I17 -> 2028 | J29: =J17 -> 2029 | ... L29: =L17 -> 2031 | S29: =S17 -> Q3 2025 | T29: =T17 -> Q4 2025 | U29: =U17 -> Q1 2026 | V29: =V17 -> Q2 2026 | W29: =W17 -> Q3 2026 | X29: =X17 -> Q4 2026 | Y29: =Y17 -> Q1 2027 | Z29: =Z17 -> Q2 2027 | ... AC29: =AC17 -> FQ3 | AE29: FQ1
B30: =B7&" % of revenue" -> Other % of revenue | C30: =C7/C14 -> 0.056999544 | D30: =D7/D14 -> 0.057742258 | E30: =E7/E14 -> 0.059486993 | F30: =F7/F14 -> 0.060838362 | G30: =G7/G14 -> 0.059672495 | H30: 0.055 | I30: 0.055 | J30: 0.051 | K30: 0.05 | L30: 0.05 | R30: =R7&" % of revenue" -> Other % of revenue | S30: =S7/S14 -> 0.066242038 | T30: =T7/T14 -> 0.06528371 | U30: =U7/U14 -> 0.056950398 | V30: =V7/V14 -> 0.054452638 | W30: =W7/W14 -> 0.05990286 | X30: =X7/X14 -> 0.066428206 | Y30: =Y7/Y14 -> 0.050672182 | Z30: =Z7/Z14 -> 0.045943304 | AA30: 0.05 | AE30: =AE7/AE14 -> 0.053114771

Sheet COGS & OpEx
B1: COGS & OpEx forecast
C2: History | H2: Forecast | P2: History | X2: Forecast | AB2: TTM
C4: Revenues | P4: Revenues
B5: =Revenue!B5 -> Revenues (thousand) | C5: =Revenue!C5 -> 2022 | D5: =Revenue!D5 -> 2023 | E5: =Revenue!E5 -> 2024 | F5: =Revenue!F5 -> 2025 | G5: =Revenue!G5 -> 2026 | H5: =G5+1 -> 2027 | I5: =H5+1 -> 2028 | J5: =I5+1 -> 2029 | K5: =J5+1 -> 2030 | L5: =K5+1 -> 2031 | O5: Revenues (thousand) | P5: =Revenue!S5 -> Q3 2025 | Q5: =Revenue!T5 -> Q4 2025 | R5: =Revenue!U5 -> Q1 2026 | S5: =Revenue!V5 -> Q2 2026 | T5: =Revenue!W5 -> Q3 2026 | U5: =Revenue!X5 -> Q4 2026 | V5: =Revenue!Y5 -> Q1 2027 | W5: =Revenue!Z5 -> Q2 2027 | X5: FQ1 | Y5: FQ2 | Z5: FQ3 | AB5: =Revenue!AE5 -> FQ1
B6: Revenue | C6: =Revenue!C14 -> 4386 | D6: =Revenue!D14 -> 5005 | E6: =Revenue!E14 -> 5497 | F6: =Revenue!F14 -> 6131 | G6: =Revenue!G14 -> 7206 | H6: =Revenue!H14 -> 8336.82 | I6: =Revenue!I14 -> 9700.9792 | J6: =Revenue!J14 -> 10917.704 | ... L6: =Revenue!L14 -> 13385.314 | O6: Revenue | P6: =Revenue!S14 -> 1570 | Q6: =Revenue!T14 -> 1639 | R6: =Revenue!U14 -> 1633 | S6: =Revenue!V14 -> 1763 | T6: =Revenue!W14 -> 1853 | U6: =Revenue!X14 -> 1957 | V6: =Revenue!Y14 -> 1934 | W6: =Revenue!Z14 -> 2046 | X6: =Revenue!AA14 -> 2137.43 | AB6: =Revenue!AE14 -> 8074.43
C9: COGS and OpEx | P9: COGS & OpEx
B10: Expenses (tnousand) | C10: =C5 -> 2022 | D10: =D5 -> 2023 | E10: =E5 -> 2024 | F10: =F5 -> 2025 | G10: =G5 -> 2026 | H10: =H5 -> 2027 | I10: =I5 -> 2028 | J10: =J5 -> 2029 | ... L10: =L5 -> 2031 | O10: Expenses (thousand) | P10: =P5 -> Q3 2025 | Q10: =Q5 -> Q4 2025 | R10: =R5 -> Q1 2026 | S10: =S5 -> Q2 2026 | T10: =T5 -> Q3 2026 | U10: =U5 -> Q4 2026 | V10: =V5 -> Q1 2027 | W10: =W5 -> Q2 2027 | ... Z10: =Z5 -> FQ3 | AB10: =AB5 -> FQ1
B11: =Statement!B191 -> Subscription COGS | C11: =Statement!M191 -> 299 | D11: =Statement!N191 -> 343 | E11: =Statement!O191 -> 381 | F11: =Statement!P191 -> 413 | G11: =Statement!Q191 -> 463 | H11: =H6*H23 -> 516.88284 | I11: =I6*I23 -> 582.05875 | J11: =J6*J23 -> 655.06227 | K11: =K6*K23 -> 735.12281 | L11: =L6*L23 -> 803.11885 | O11: =B11 -> Subscription COGS | P11: =Statement!T191 -> 105 | Q11: =Statement!U191 -> 108 | R11: =Statement!V191 -> 111 | S11: =Statement!W191 -> 114 | T11: =Statement!X191 -> 118 | U11: =Statement!Y191 -> 120 | V11: =Statement!Z191 -> 129 | W11: =Statement!AA191 -> 130 | X11: =X23*X$6 -> 192.3687 | AB11: =SUM(U11:X11) -> 571.3687
B12: =Statement!B192 -> Other COGS | C12: =Statement!M192 -> 67 | D12: =Statement!N192 -> 79 | E12: =Statement!O192 -> 82 | F12: =Statement!P192 -> 80 | G12: =Statement!Q192 -> 90 | H12: =H6*H24 -> 100.04184 | I12: =I6*I24 -> 116.41175 | J12: =J6*J24 -> 131.01245 | K12: =K6*K24 -> 147.02456 | L12: =L6*L24 -> 160.62377 | O12: =B12 -> Other COGS | P12: =Statement!T192 -> 19 | Q12: =Statement!U192 -> 23 | R12: =Statement!V192 -> 24 | S12: =Statement!W192 -> 22 | T12: =Statement!X192 -> 22 | U12: =Statement!Y192 -> 22 | V12: =Statement!Z192 -> 21 | W12: =Statement!AA192 -> 22 | X12: =X24*X$6 -> 2.13743 | AB12: =SUM(U12:X12) -> 67.13743
B13: =Statement!B193 -> Amortization of developed tech COGS | C13: =Statement!M193 -> 52 | D13: =Statement!N193 -> 58 | E13: =Statement!O193 -> 48 | F13: =Statement!P193 -> 85 | G13: =Statement!Q193 -> 97 | H13: =H6*H25 -> 100.04184 | I13: =I6*I25 -> 106.71077 | J13: =J6*J25 -> 120.09475 | K13: =K6*K25 -> 134.77252 | L13: =L6*L25 -> 147.23846 | O13: =B13 -> Amortization of developed tech COGS | P13: =Statement!T193 -> 23 | Q13: =Statement!U193 -> 23 | R13: =Statement!V193 -> 25 | S13: =Statement!W193 -> 23 | T13: =Statement!X193 -> 25 | U13: =Statement!Y193 -> 24 | V13: =Statement!Z193 -> 25 | W13: =Statement!AA193 -> 24 | X13: =X25*X$6 -> 38.47374 | AB13: =SUM(U13:X13) -> 111.47374
B14: COGS | C14: =Statement!M6 -> 418 | D14: =Statement!N6 -> 480 | E14: =Statement!O6 -> 511 | F14: =Statement!P6 -> 578 | G14: =Statement!Q6 -> 650 | H14: =SUM(H11:H13) -> 716.96652 | I14: =SUM(I11:I13) -> 805.18127 | J14: =SUM(J11:J13) -> 906.16947 | K14: =SUM(K11:K13) -> 1016.9199 | L14: =SUM(L11:L13) -> 1110.9811 | O14: =B14 -> COGS | P14: =Statement!T6 -> 147 | Q14: =Statement!U6 -> 154 | R14: =Statement!V6 -> 160 | S14: =Statement!W6 -> 159 | T14: =Statement!X6 -> 165 | U14: =Statement!Y6 -> 166 | V14: =Statement!Z6 -> 175 | W14: =Statement!AA6 -> 176 | X14: =SUM(X11:X13) -> 232.97987 | AB14: =SUM(AB11:AB13) -> 749.97987
B15: =Statement!B8 -> Sales and marketing | C15: =Statement!M8 -> 1623 | D15: =Statement!N8 -> 1745 | E15: =Statement!O8 -> 1823 | F15: =Statement!P8 -> 2000 | G15: =Statement!Q8 -> 2373 | H15: =H6*H27 -> 2709.4665 | I15: =I6*I27 -> 3104.3133 | J15: =J6*J27 -> 3493.6654 | K15: =K6*K27 -> 3798.1345 | L15: =L6*L27 -> 4149.4474 | O15: =B15 -> Sales and marketing | P15: =Statement!T8 -> 525 | Q15: =Statement!U8 -> 526 | R15: =Statement!V8 -> 566 | S15: =Statement!W8 -> 559 | T15: =Statement!X8 -> 612 | U15: =Statement!Y8 -> 636 | V15: =Statement!Z8 -> 593 | W15: =Statement!AA8 -> 616 | X15: =X27*X$6 -> 384.7374 | AB15: =SUM(U15:X15) -> 2229.7374
B16: =Statement!B9 -> R&D | C16: =Statement!M9 -> 1115 | D16: =Statement!N9 -> 1219 | E16: =Statement!O9 -> 1373 | F16: =Statement!P9 -> 1485 | G16: =Statement!Q9 -> 1643 | H16: =H6*H28 -> 1834.1004 | I16: =I6*I28 -> 2134.2154 | J16: =J6*J28 -> 2292.7179 | K16: =K6*K28 -> 2572.9299 | L16: =L6*L28 -> 2810.916 | O16: =B16 -> R&D | P16: =Statement!T9 -> 378 | Q16: =Statement!U9 -> 393 | R16: =Statement!V9 -> 394 | S16: =Statement!W9 -> 413 | T16: =Statement!X9 -> 416 | U16: =Statement!Y9 -> 420 | V16: =Statement!Z9 -> 421 | W16: =Statement!AA9 -> 464 | X16: =X28*X$6 -> 577.1061 | AB16: =SUM(U16:X16) -> 1882.1061
B17: =Statement!B10 -> General and administrative | C17: =Statement!M10 -> 572 | D17: =Statement!N10 -> 532 | E17: =Statement!O10 -> 620 | F17: =Statement!P10 -> 650 | G17: =Statement!Q10 -> 693 | H17: =H6*H29 -> 875.3661 | I17: =I6*I29 -> 1067.1077 | J17: =J6*J29 -> 1200.9475 | K17: =K6*K29 -> 1225.2047 | L17: =L6*L29 -> 1338.5314 | O17: =B17 -> General and administrative | P17: =Statement!T10 -> 161 | Q17: =Statement!U10 -> 173 | R17: =Statement!V10 -> 162 | S17: =Statement!W10 -> 168 | T17: =Statement!X10 -> 172 | U17: =Statement!Y10 -> 191 | V17: =Statement!Z10 -> 162 | W17: =Statement!AA10 -> 179 | X17: =X29*X$6 -> 168.85697 | AB17: =SUM(U17:X17) -> 700.85697
