Workbook

Sheet Overview
B2: Automatic Data | E2: At a glance | H2: Valuation | K2: Links
B3: Company | C3: #VALUE! | E3: Market capitalization | F3: =Statement!AC154 -> 2662186.8 | H3: ='AVG target price'!B5 -> DCF price | I3: ='AVG target price'!C5 -> 93.81546 | K3: Financials ->'!B13
B4: Ticker | C4: {=_FV(C3,"Ticker symbol",TRUE)} -> AMZN | E4: Enterprise value | F4: =Statement!AC155 -> 2721085.8 | H4: ='AVG target price'!B6 -> EV/EBIT price | I4: ='AVG target price'!C6 -> 385.51692 | K4: Analysis ->'!B13
B5: Price | C5: {=_FV(C3,"Price",TRUE)} -> 243.79 | E5: EPS | F5: =Statement!AC27 -> 6.6066633 | H5: ='AVG target price'!B7 -> PS price | I5: ='AVG target price'!C7 -> 284.18338 | K5: Forecast ->'!B13
B6: Price Extended Hours | C6: {=_FV(C3,"Price (Extended hours)",TRUE)} -> 231.2492 | E6: PE | F6: =Statement!AC151 -> 36.900624 | H6: ='AVG target price'!B8 -> EV/FCFF price | I6: ='AVG target price'!C8 -> 278.1761 | K6: Valuation ->'!B13
B7: Day change | C7: {=_FV(C3,"Change")} -> -10.81 | E7: PS | F7: =Statement!AC152 -> 3.3298702 | H7: ='AVG target price'!B9 -> EV/Sales price | I7: ='AVG target price'!C9 -> 282.71146
B8: Day change extended | C8: {=_FV(C3,"Change (extended hours)",TRUE)} -> -12.5408 | E8: FCF Yield | F8: =Statement!AC162 -> -0.025079006 | H8: ='AVG target price'!B10 -> AVG price | I8: ='AVG target price'!C10 -> 264.88067
B9: Day change % | C9: {=_FV(C3,"Change (%)",TRUE)} -> -0.042459 | E9: Earnings Yield | F9: =Statement!AC163 -> 0.027099813 | H9: ='AVG target price'!B12 -> Upside/Downside | I9: ='AVG target price'!C12 -> 0.086511614
B10: Day change extended % | C10: {=_FV(C3,"Change % (extended hours)",TRUE)} -> -0.051441 | E10: Buyback Yield | F10: =Statement!AC165 -> 0
B11: 52 week high | C11: {=_FV(C3,"52 week high",TRUE)} -> 287.2 | E11: Dividend Yield | F11: =Statement!AC164 -> 0 | H11: DDM price | I11: =DDM!C26 -> 0
B12: 52 week low | C12: {=_FV(C3,"52 week low",TRUE)} -> 196 | E12: ROA | F12: =Statement!AC124 -> 0.057878059
B13: Beta | C13: {=_FV(C3,"Beta")} -> 1.4919 | E13: ROE | F13: =Statement!AC126 -> 0.11728306 | H13: Reverse DCF rate | I13: ='Reverse DCF'!C17 -> 0.03
B14: Avg volume | C14: {=_FV(C3,"Volume average",TRUE)} -> 35430230 | E14: ROIC | F14: =Statement!AC141 -> 0.10099664 | H14: Reverse DCF price | I14: ='Reverse DCF'!C16 -> -30.998311
E15: Net Cash/Market Cap | F15: =Statement!AC177 -> -0.022124293
E16: Net Cash/Share | F16: =Statement!AC176 -> -5.4606898 | H16: Discount rates used
B17: Unit data and other info | E17: Insider Ownership | F17: =Statement!AC172 -> 0.093864469 | H17: WACC | I17: =DCF!C15 -> 0.11325171
B18: Units | C18: M | E18: Net Trade Cycle | F18: =Statement!AC145 -> -38.849641 | H18: Cost of Equity | I18: =Multiples!C54 -> 0.1175855
B19: Units conversion | C19: 1000000 | E19: Net Debt/Equity | F19: =Statement!AC147 -> 0.095989087
B20: Has operating lease | C20: Yes | E20: Quick Ratio | F20: =Statement!AC148 -> 0.82357684
B21: Has finance lease | C21: No
B22: Has debt | C22: Yes
B25: Constants | E25: 10 Year Bond Yield
B26: Default tax rate | C26: 0.21 | E26: #VALUE! | F26: {=_FV(E26,"Price")} -> 50.45
B27: Cost of debt | C27: 0.059 | E27: Percentage | F27: =F26/1000 -> 0.05045
B28: Manual WACC | C28: 0
B29: Manual Cost of Equity | C29: 0
B33: Info
B35: Mission: | C35: Be Earth's most customer-centric company
B36: Auditor: | C36: Ernst & Young
B42: Notes
B44: Date: | C44: 18.09.2026 | E44: Q3 2026
B45: -
B52: Adjustments
B54: Date: | C54: 30.06.2026 | E54: Q2 2026
B55: - | C55: Other income/expense | E55: Taken out 50486 due to paper gains from Anthropic
B57: Date: | C57: 31.03.2026 | E57: Q1 2026
B58: - | C58: Other income/expense | E58: Taken out 12328 due to paper gains from Anthropic
B60: Date: | C60: 30.09.2025 | E60: Q3 2025
B61: - | C61: Other income/expense | E61: Taken out 9000 due to paper gains from Anthropic
B63: Date: | C63: 31.12.2025 | E63: FY 2025
...

Sheet Financials ->
H5: Links
H6: Overview'!B3
H7: Financials ->'!B13
H8: Analysis ->'!B13
H9: Forecast ->'!B13
H10: Valuation ->'!B13
B13: Financials ->

Sheet Statement
B2: Date | M2: 31.12.2021 | N2: 31.12.2022 | O2: 31.12.2023 | P2: 31.12.2024 | Q2: 31.12.2025 | T2: 31.12.2024 | U2: 31.03.2025 | V2: 30.06.2025 | W2: 30.09.2025 | X2: 31.12.2025 | Y2: 31.03.2026 | Z2: 30.06.2026 | AA2: 30.09.2026
B3: FY | M3: 2021 | N3: 2022 | O3: 2023 | P3: 2024 | Q3: 2025 | T3: Q4 2024 | U3: Q1 2025 | V3: Q2 2025 | W3: Q3 2025 | X3: Q4 2025 | Y3: Q1 2026 | Z3: Q2 2026 | AA3: Q3 2026 | AC3: TTM/YTD
B4: Income statement
B5: Revenue | M5: 469822 | N5: 513983 | O5: 574785 | P5: 637959 | Q5: 716924 | T5: 187792 | U5: 155667 | V5: 167702 | W5: 180169 | X5: 213386 | Y5: 181519 | Z5: 200606 | AA5: 201944 | AC5: =SUM(X5:AA5) -> 797455
B6: COGS | M6: =272344+75111 -> 347455 | N6: =288831+84299 -> 373130 | O6: =304739+90619 -> 395358 | P6: =326288+98505 -> 424793 | Q6: =356414+109074 -> 465488 | T6: =98893+27962 -> 126855 | U6: =76976+24593 -> 101569 | V6: =80809+25976 -> 106785 | W6: =88670+27679 -> 116349 | X6: =109959+30826 -> 140785 | Y6: =87463+27289 -> 114752 | Z6: =95778+29633 -> 125411 | AA6: =94573+29997 -> 124570 | AC6: =SUM(X6:AA6) -> 505518
B7: Gross Profit | C7: =C5-C6 -> 0 | D7: =D5-D6 -> 0 | E7: =E5-E6 -> 0 | F7: =F5-F6 -> 0 | G7: =G5-G6 -> 0 | H7: =H5-H6 -> 0 | I7: =I5-I6 -> 0 | J7: =J5-J6 -> 0 | ... Q7: =Q5-Q6 -> 251436 | T7: =T5-T6 -> 60937 | U7: =U5-U6 -> 54098 | V7: =V5-V6 -> 60917 | W7: =W5-W6 -> 63820 | X7: =X5-X6 -> 72601 | Y7: =Y5-Y6 -> 66767 | Z7: =Z5-Z6 -> 75195 | AA7: =AA5-AA6 -> 77374 | AC7: =SUM(X7:AA7) -> 291937
B8: Tech and infra | M8: 56052 | N8: 73213 | O8: 85622 | P8: 88544 | Q8: 108521 | T8: 23571 | U8: 22994 | V8: 27166 | W8: 28962 | X8: 29399 | Y8: 29567 | Z8: 33158 | AA8: 34814 | AC8: =SUM(X8:AA8) -> 126938
B9: Sales and marketing | M9: 32551 | N9: 42238 | O9: 44370 | P9: 43907 | Q9: 47129 | T9: 13124 | U9: 9763 | V9: 11416 | W9: 11686 | X9: 14264 | Y9: 10314 | Z9: 11698 | AA9: 11649 | AC9: =SUM(X9:AA9) -> 47925
B10: General and administrative | M10: 8823 | N10: 11891 | O10: 11816 | P10: 11359 | Q10: 11172 | T10: 2863 | U10: 2628 | V10: 2965 | W10: 2875 | X10: 2704 | Y10: 2587 | Z10: 2788 | AA10: 2701 | AC10: =SUM(X10:AA10) -> 10780
B11: Other expenses/income | M11: 62 | N11: 1263 | O11: 767 | P11: 763 | Q11: 4639 | T11: 176 | U11: 308 | V11: 199 | W11: 2875 | X11: 1257 | Y11: 447 | Z11: 90 | AA11: 134 | AC11: =SUM(X11:AA11) -> 1928
B12: OpEx | M12: =SUM(M8:M11) -> 97488 | N12: =SUM(N8:N11) -> 128605 | O12: =SUM(O8:O11) -> 142575 | P12: =SUM(P8:P11) -> 144573 | Q12: =SUM(Q8:Q11) -> 171461 | T12: =SUM(T8:T11) -> 39734 | U12: =SUM(U8:U11) -> 35693 | V12: =SUM(V8:V11) -> 41746 | W12: =SUM(W8:W11) -> 46398 | X12: =SUM(X8:X11) -> 47624 | Y12: =SUM(Y8:Y11) -> 42915 | Z12: =SUM(Z8:Z11) -> 47734 | AA12: =SUM(AA8:AA11) -> 49298 | AC12: =SUM(X12:AA12) -> 187571
B13: Operating income | M13: 24879 | N13: 12248 | O13: 36852 | P13: 68593 | Q13: 79975 | T13: 21203 | U13: 18405 | V13: 19171 | W13: 17422 | X13: 24977 | Y13: 23852 | Z13: 27461 | AA13: 28076 | AC13: =SUM(X13:AA13) -> 104366
B14: Interest income/expense | M14: =448-1809 -> -1361 | N14: =989-2367 -> -1378 | O14: =2949-3182 -> -233 | P14: =4677-2406 -> 2271 | Q14: =4381-2274 -> 2107 | T14: =1248-570 -> 678 | U14: =1066-541 -> 525 | V14: =1085-516 -> 569 | W14: =1100-538 -> 562 | X14: =1130-679 -> 451 | Y14: =1135-800 -> 335 | Z14: =1295-1314 -> -19 | AA14: =1187-1691 -> -504 | AC14: =SUM(X14:AA14) -> 263
B15: Other income/expense | M15: =14633-11526 -> 3107 | N15: =-16806+13870 -> -2936 | O15: 938 | P15: -2250 | Q15: 2229 | T15: 468 | U15: 2749 | V15: 1117 | W15: =10186-9000 -> 1186 | X15: 1177 | Y15: =15647-12328 -> 3319 | Z15: =53415-50486 -> 2929 | AA15: -703 | AC15: =SUM(X15:AA15) -> 6722
B16: Income before taxes | M16: =38151-11526 -> 26625 | N16: =-5936+13870 -> 7934 | O16: 37557 | P16: 68614 | Q16: 84311 | T16: 22349 | U16: 21679 | V16: 20857 | W16: =28170-9000 -> 19170 | X16: 26605 | Y16: =39834-12328 -> 27506 | Z16: =80857-50486 -> 30371 | AA16: 26869 | AC16: =SUM(X16:AA16) -> 111351
B17: Income tax expense/benefit | M17: -4791 | N17: 3217 | O17: -7120 | P17: -9265 | Q17: -19087 | T17: -2325 | U17: -4553 | V17: -2678 | W17: -6910 | X17: -4946 | Y17: -9560 | Z17: -18199 | AA17: -6180 | AC17: =SUM(X17:AA17) -> -38885
B18: Non-controlling interest | M18: 0 | N18: 0 | O18: 0 | P18: 0 | Q18: 0 | T18: 0 | U18: 0 | V18: 0 | W18: 0 | X18: 0 | Y18: 0 | Z18: 0 | AA18: 0 | AC18: =SUM(X18:AA18) -> 0
B19: Net income | M19: =33364-11526 -> 21838 | N19: =-2722+13870 -> 11148 | O19: 30425 | P19: 59248 | Q19: 64670 | T19: 20004 | U19: 17127 | V19: 18164 | W19: =21187-9000 -> 12187 | X19: 21192 | Y19: =30255-12328 -> 17927 | Z19: =62647-50486 -> 12161 | AA19: 20685 | AC19: =SUM(X19:AA19) -> 71965
B20: Basic Shares outstanding avg | M20: 10117 | N20: 10189 | O20: 10304 | P20: 10473 | Q20: 10656 | T20: 10552 | U20: 10603 | V20: 10637 | W20: 10674 | X20: 10709 | Y20: 10743 | Z20: 10769 | AA20: 10797 | AC20: =AVERAGE(X20:AA20) -> 10754.5
B21: Basic Shares outstanding avg adjusted | C21: =C20*C$86 -> 0 | D21: =D20*D$86 -> 0 | E21: =E20*E$86 -> 0 | F21: =F20*F$86 -> 0 | G21: =G20*G$86 -> 0 | H21: =H20*H$86 -> 0 | I21: =I20*I$86 -> 0 | J21: =J20*J$86 -> 0 | ... Q21: =Q20*Q$86 -> 10656 | T21: =T20*T$86 -> 10552 | U21: =U20*U$86 -> 10603 | V21: =V20*V$86 -> 10637 | W21: =W20*W$86 -> 10674 | X21: =X20*X$86 -> 10709 | Y21: =Y20*Y$86 -> 10743 | Z21: =Z20*Z$86 -> 10769 | AA21: =AA20*AA$86 -> 10797 | AC21: =AC20*AC$86 -> 10754.5
B22: Diluted Shares outstanding avg | M22: 10296 | N22: 10189 | O22: 10492 | P22: 10721 | Q22: 10827 | T22: 10771 | U22: 10793 | V22: 10806 | W22: 10845 | X22: 10863 | Y22: 10874 | Z22: 10903 | AA22: 10929 | AC22: =AVERAGE(X22:AA22) -> 10892.25
B23: Diluted Shares outstanding avg adjusted | C23: =C22*C$86 -> 0 | D23: =D22*D$86 -> 0 | E23: =E22*E$86 -> 0 | F23: =F22*F$86 -> 0 | G23: =G22*G$86 -> 0 | H23: =H22*H$86 -> 0 | I23: =I22*I$86 -> 0 | J23: =J22*J$86 -> 0 | ... Q23: =Q22*Q$86 -> 10827 | T23: =T22*T$86 -> 10771 | U23: =U22*U$86 -> 10793 | V23: =V22*V$86 -> 10806 | W23: =W22*W$86 -> 10845 | X23: =X22*X$86 -> 10863 | Y23: =Y22*Y$86 -> 10874 | Z23: =Z22*Z$86 -> 10903 | AA23: =AA22*AA$86 -> 10929 | AC23: =AC22*AC$86 -> 10892.25
B24: Basic EPS | M24: =M19/M20 -> 2.158545 | N24: =N19/N20 -> 1.0941211 | O24: 2.95 | P24: 5.66 | Q24: =Q19/Q20 -> 6.0688814 | T24: 1.9 | U24: 1.62 | V24: 1.71 | W24: =W19/W20 -> 1.1417463 | X24: 1.98 | Y24: =Y19/Y20 -> 1.6687145 | Z24: =Z19/Z20 -> 1.1292599 | AA24: =AA19/AA20 -> 1.9158099 | AC24: =SUM(X24:AA24) -> 6.6937844
B25: Basic EPS adjusted | M25: =M24/M$86 -> 2.158545 | N25: =N24/N$86 -> 1.0941211 | O25: =O24/O$86 -> 2.95 | P25: =P24/P$86 -> 5.66 | Q25: =Q24/Q$86 -> 6.0688814 | T25: =T24/T$86 -> 1.9 | U25: =U24/U$86 -> 1.62 | V25: =V24/V$86 -> 1.71 | W25: =W24/W$86 -> 1.1417463 | X25: =X24/X$86 -> 1.98 | Y25: =Y24/Y$86 -> 1.6687145 | Z25: =Z24/Z$86 -> 1.1292599 | AA25: =AA24/AA$86 -> 1.9158099 | AC25: =AC24/AC$86 -> 6.6937844
B26: Diluted EPS | M26: =M19/M22 -> 2.1210179 | N26: =N19/N22 -> 1.0941211 | O26: 2.9 | P26: 5.53 | Q26: =Q19/Q22 -> 5.9730304 | T26: 1.86 | U26: 1.59 | V26: 1.68 | W26: =W19/W22 -> 1.1237437 | X26: 1.95 | Y26: =Y19/Y22 -> 1.6486114 | Z26: =Z19/Z22 -> 1.1153811 | AA26: =AA19/AA22 -> 1.8926709 | AC26: =SUM(X26:AA26) -> 6.6066633
B27: Diluted EPS adjusted | M27: =M26/M$86 -> 2.1210179 | N27: =N26/N$86 -> 1.0941211 | O27: =O26/O$86 -> 2.9 | P27: =P26/P$86 -> 5.53 | Q27: =Q26/Q$86 -> 5.9730304 | T27: =T26/T$86 -> 1.86 | U27: =U26/U$86 -> 1.59 | V27: =V26/V$86 -> 1.68 | W27: =W26/W$86 -> 1.1237437 | X27: =X26/X$86 -> 1.95 | Y27: =Y26/Y$86 -> 1.6486114 | Z27: =Z26/Z$86 -> 1.1153811 | AA27: =AA26/AA$86 -> 1.8926709 | AC27: =AC26/AC$86 -> 6.6066633
B29: Balance sheet
B30: Cash and cash equivalents | M30: =36220+59829 -> 96049 | N30: =53888+16138 -> 70026 | O30: =73387+13393 -> 86780 | P30: =78779+22423 -> 101202 | Q30: =86810+36219 -> 123029 | T30: =78779+22423 -> 101202 | U30: =66207+28358 -> 94565 | V30: =57741+35439 -> 93180 | W30: =66922+27275 -> 94197 | X30: =86810+36219 -> 123029 | Y30: =101816+41273 -> 143089 | Z30: =78213+44775 -> 122988 | AA30: =55783+58443 -> 114226 | AC30: =AA30 -> 114226
B31: Acc receivable | M31: 32891 | N31: 42360 | O31: 52253 | P31: 55451 | Q31: 67729 | T31: 55451 | U31: 54216 | V31: 57415 | W31: 61175 | X31: 67729 | Y31: 75532 | Z31: 88092 | AA31: 98242 | AC31: =AA31 -> 98242
B32: Inventory | M32: 32640 | N32: 34405 | O32: 33318 | P32: 34214 | Q32: 38325 | T32: 34214 | U32: 35864 | V32: 40825 | W32: 41494 | X32: 38325 | Y32: 36534 | Z32: 38184 | AA32: 42632 | AC32: =AA32 -> 42632
B33: Current assets | M33: 161580 | N33: 146791 | O33: 172351 | P33: 190867 | Q33: 229083 | T33: 190867 | U33: 184645 | V33: 191420 | W33: 196866 | X33: 229083 | Y33: 255155 | Z33: 249264 | AA33: 255100 | AC33: =AA33 -> 255100
B34: PP&E | M34: 160281 | N34: 186715 | O34: 204177 | P34: 252665 | Q34: 357025 | T34: 252665 | U34: 272781 | V34: 297616 | W34: 324435 | X34: 357025 | Y34: 397458 | Z34: 446046 | AA34: 508862 | AC34: =AA34 -> 508862
B35: Marketable securities and investments | M35: 0 | N35: 0 | O35: 0 | P35: 0 | Q35: 0 | T35: 0 | U35: 0 | V35: 0 | W35: 0 | X35: 0 | Y35: 0 | Z35: 0 | AA35: 0 | AC35: =AA35 -> 0
B36: Goodwill | M36: 15371 | N36: 20288 | O36: 22789 | P36: 23074 | Q36: 23273 | T36: 23074 | U36: 23089 | V36: 23155 | W36: 23260 | X36: 23273 | Y36: 23449 | Z36: 23504 | AA36: 23743 | AC36: =AA36 -> 23743
B37: Long term assets | M37: =M38-M33 -> 258969 | N37: =N38-N33 -> 315884 | O37: =O38-O33 -> 355503 | P37: =P38-P33 -> 434027 | Q37: =Q38-Q33 -> 588959 | T37: =T38-T33 -> 434027 | U37: =U38-U33 -> 458611 | V37: =V38-V33 -> 490750 | W37: =W38-W33 -> 531055 | X37: =X38-X33 -> 588959 | Y37: =Y38-Y33 -> 661475 | Z37: =Z38-Z33 -> 846425 | AA37: =AA38-AA33 -> 988290 | AC37: =AA37 -> 988290
B38: Total assets | M38: 420549 | N38: 462675 | O38: 527854 | P38: 624894 | Q38: 818042 | T38: 624894 | U38: 643256 | V38: 682170 | W38: 727921 | X38: 818042 | Y38: 916630 | Z38: 1095689 | AA38: 1243390 | AC38: =AA38 -> 1243390
B39: Acc payable | M39: 78664 | N39: 79600 | O39: 84981 | P39: 94363 | Q39: 121909 | T39: 94363 | U39: 89241 | V39: 98285 | W39: 106032 | X39: 121909 | Y39: 124749 | Z39: 147440 | AA39: 158715 | AC39: =AA39 -> 158715
B40: Debt | M40: 0 | N40: 0 | O40: 0 | P40: 0 | Q40: 0 | T40: 0 | U40: 0 | V40: 0 | W40: 0 | X40: 0 | Y40: 0 | Z40: 0 | AA40: 0 | AC40: =AA40 -> 0
B41: Current liabilities | M41: 142266 | N41: 155393 | O41: 164917 | P41: 179431 | Q41: 218005 | T41: 179431 | U41: 176171 | V41: 186921 | W41: 195196 | X41: 218005 | Y41: 216756 | Z41: 241274 | AA41: 257982 | AC41: =AA41 -> 257982
B42: Debt | M42: 48744 | N42: 67150 | O42: 58314 | P42: 52623 | Q42: 65648 | T42: 52623 | U42: 53374 | V42: 50718 | W42: 50742 | X42: 65648 | Y42: 119074 | Z42: 128894 | AA42: 173125 | AC42: =AA42 -> 173125
...

Sheet Analysis ->
H5: Links
H6: Overview'!B3
H7: Financials ->'!B13
H8: Analysis ->'!B13
H9: Forecast ->'!B13
H10: Valuation ->'!B13
B13: Analysis ->

Sheet Basic
B1: TTM/YTD data
B4: Overview | E4: CAGR
B5: Price | C5: =Overview!C5 -> 243.79 | F5: 5Y | G5: 10Y
B6: Market capitalization | C6: =Statement!AC154 -> 2662186.8 | E6: Revenue | F6: =IF(Statement!M5<=0,"N/A",_xlfn.RRI(4,Statement!M5,Statement!Q5)) -> 0.11143724 | G6: =IF(Statement!H5<=0,"N/A",_xlfn.RRI(9,Statement!H5,Statement!Q5)) -> N/A
B7: Enterprise value | C7: =Statement!AC155 -> 2721085.8 | E7: Net income | F7: =IF(OR(Statement!M19<=0, Statement!Q19<=0), "N/A", _xlfn.RRI(4, Statement!M19, Statement!Q19)) -> 0.31181472 | G7: =IF(OR(Statement!H19<=0, Statement!Q19<=0), "N/A", _xlfn.RRI(9, Statement!H19, Statement!Q19)) -> N/A
B8: PE | C8: =Statement!AC151 -> 36.900624 | E8: EPS | F8: =IF(OR(Statement!M27<=0, Statement!Q27<=0), "N/A", _xlfn.RRI(4, Statement!M27, Statement!Q27)) -> 0.29542597 | G8: =IF(OR(Statement!H27<=0, Statement!Q27<=0), "N/A", _xlfn.RRI(9, Statement!H27, Statement!Q27)) -> N/A
B9: PS | C9: =Statement!AC152 -> 3.3298702 | E9: Dividend | F9: =IF(Statement!M83<=0,"N/A",_xlfn.RRI(4,Statement!M83,Statement!Q83)) -> N/A | G9: =IF(Statement!H83<=0,"N/A",_xlfn.RRI(9,Statement!H83,Statement!Q83)) -> N/A
B10: PB | C10: =Statement!AC153 -> 4.2853889 | E10: Price | F10: =IF(Statement!M118<=0,"N/A",_xlfn.RRI(4,Statement!M118,Statement!Q118)) -> 0.084729456 | G10: =IF(Statement!H118<=0,"N/A",_xlfn.RRI(9,Statement!H118,Statement!Q118)) -> N/A
B11: EV/Revenue | C11: =Statement!AC156 -> 3.4122124
B12: EV/EBIT | C12: =Statement!AC157 -> 26.072531
B15: Margins | E15: Earnings quality
B16: Gross margin | C16: =Statement!AC102 -> 0.36608586 | E16: Net income | F16: =Statement!AC19 -> 71965
B17: Operating margin | C17: =Statement!AC103 -> 0.13087384 | E17: Operating cash | F17: =Statement!AC60 -> 168300
B18: Net margin | C18: =Statement!AC104 -> 0.090243337 | E18: Cash accruals | F18: =IF(OR(F16<=0, F17<=0),"N/A",F16-F17) -> -96335
B21: DuPont Identity | E21: Performance indicators
B22: Profit Margin (Earnings/Revenue) | C22: =Statement!AC122 -> 0.090243337 | E22: ROA | F22: =C24 -> 0.057878059
B23: Asset Turnover (Revenue/Total assets) | C23: =Statement!AC123 -> 0.64135549 | E23: ROE | F23: =C26 -> 0.11728306
B24: ROA | C24: =Statement!AC124 -> 0.057878059 | E24: ROIC | F24: =Statement!AC141 -> 0.10099664
B25: Equity Multiplier (Total assets/Equity) | C25: =Statement!AC125 -> 2.026382
B26: ROE | C26: =Statement!AC126 -> 0.11728306
B29: Cash conversion cycle | E29: Liquidity ratios
B30: DSO | C30: =Statement!AC142 -> 44.96596 | E30: Debt/Equity | F30: =Statement!AC146 -> 0.28214589
B31: DIO | C31: =Statement!AC143 -> 30.781654 | E31: Net Debt/Equity | F31: =Statement!AC147 -> 0.095989087
B32: DPO | C32: =Statement!AC144 -> 114.59725 | E32: Current ratio | F32: =Statement!AC149 -> 0.98882868
B33: Net trade cycle | C33: =Statement!AC145 -> -38.849641 | E33: Quick ratio | F33: =Statement!AC148 -> 0.82357684
E34: Interest coverage | F34: =Statement!AC150 -> N/A
B37: Earnings yields | E37: Payout ratios
B38: Earnings yield | C38: =Statement!AC163 -> 0.027099813 | E38: Dividend payout ratio | F38: =Statement!AC169 -> 0
B39: FCF yield | C39: =Statement!AC162 -> -0.025079006 | E39: Buyback payout ratio | F39: =Statement!AC170 -> 0
B40: Dividend yield | C40: =Statement!AC164 -> 0 | E40: Full payout ratio | F40: =Statement!AC171 -> 0
B41: Buyback yield | C41: =Statement!AC165 -> 0
B42: Total shareholder yield | C42: =Statement!AC166 -> 0
B45: Ownership | E45: Cash holdings
B46: Insider ownership | C46: =Statement!AC172 -> 0.093864469 | E46: Cash per share | F46: =Statement!AC173 -> 10.59021
E47: Net cash per share | F47: =Statement!AC176 -> -5.4606898
E48: Net cash to market cap | F48: =Statement!AC177 -> -0.022124293
B51: Stock based compensation | E51: CapEx usage
B52: Stock based compensation % OCF | C52: =Statement!AC174 -> 0.11808081 | E52: Capex to Revenue | F52: =Statement!AC178 -> 0.26984846
B53: Stock based compensation % Revenue | C53: =Statement!AC175 -> 0.024920528 | E53: CapEx to OCF | F53: =Statement!AC179 -> 1.2786215
E54: CapEx to D&A | F54: =Statement!AC180 -> 2.7118319
...

Sheet Yearly Analysis
C2: =Statement!M2 -> 31.12.2021 | D2: =Statement!N2 -> 31.12.2022 | E2: =Statement!O2 -> 31.12.2023 | F2: =Statement!P2 -> 31.12.2024 | G2: =Statement!Q2 -> 31.12.2025
C3: =Statement!M3 -> 2021 | D3: =Statement!N3 -> 2022 | E3: =Statement!O3 -> 2023 | F3: =Statement!P3 -> 2024 | G3: =Statement!Q3 -> 2025 | I3: =Statement!AC3 -> TTM/YTD
B5: Overview
B6: Price | C6: =Statement!M117 -> 166.72 | D6: =Statement!N117 -> 83.99 | E6: =Statement!O117 -> 151.94 | F6: =Statement!P117 -> 219.39 | G6: =Statement!Q117 -> 230.82 | I6: =Statement!AC117 -> 243.79
B7: Market capitalization | C7: =Statement!M154 -> 1726552.3 | D7: =Statement!N154 -> 860645.53 | E7: =Statement!O154 -> 1606917.4 | F7: =Statement!P154 -> 2379503.9 | G7: =Statement!Q154 -> 2517322.9 | I7: =Statement!AC154 -> 2662186.8
B8: Enterprise value | C8: =Statement!M155 -> 1679247.3 | D8: =Statement!N155 -> 857769.53 | E8: =Statement!O155 -> 1578451.4 | F8: =Statement!P155 -> 2330924.9 | G8: =Statement!Q155 -> 2459941.9 | I8: =Statement!AC155 -> 2721085.8
B9: PE | C9: =Statement!M151 -> 78.60377 | D9: =Statement!N151 -> 76.764811 | E9: =Statement!O151 -> 52.393103 | F9: =Statement!P151 -> 39.672694 | G9: =Statement!Q151 -> 38.643701 | I9: =Statement!AC151 -> 36.900624
B10: PS | C10: =Statement!M152 -> 3.6536159 | D10: =Statement!N152 -> 1.6649852 | E10: =Statement!O152 -> 2.7734796 | F10: =Statement!P152 -> 3.686883 | G10: =Statement!Q152 -> 3.4858481 | I10: =Statement!AC152 -> 3.3298702
B11: PB | C11: =Statement!M153 -> 12.273207 | D11: =Statement!N153 -> 5.8930968 | E11: =Statement!O153 -> 7.8184655 | F11: =Statement!P153 -> 8.1305564 | G11: =Statement!Q153 -> 6.0278854 | I11: =Statement!AC153 -> 4.2853889
B12: EV/Revenue | C12: =Statement!M156 -> 3.5742203 | D12: =Statement!N156 -> 1.6688675 | E12: =Statement!O156 -> 2.7461598 | F12: =Statement!P156 -> 3.6537222 | G12: =Statement!Q156 -> 3.431245 | I12: =Statement!AC156 -> 3.4122124
B13: EV/EBIT | C13: =Statement!M157 -> 67.496576 | D13: =Statement!N157 -> 70.033436 | E13: =Statement!O157 -> 42.832178 | F13: =Statement!P157 -> 33.981965 | G13: =Statement!Q157 -> 30.758886 | I13: =Statement!AC157 -> 26.072531
B15: Margins
B16: Gross margin | C16: =Statement!M102 -> 0.26045396 | D16: =Statement!N102 -> 0.27404214 | E16: =Statement!O102 -> 0.31216368 | F16: =Statement!P102 -> 0.33413746 | G16: =Statement!Q102 -> 0.350715 | I16: =Statement!AC102 -> 0.36608586
B17: Operating margin | C17: =Statement!M103 -> 0.052954098 | D17: =Statement!N103 -> 0.023829582 | E17: =Statement!O103 -> 0.064114408 | F17: =Statement!P103 -> 0.10751945 | G17: =Statement!Q103 -> 0.11155297 | I17: =Statement!AC103 -> 0.13087384
B18: Net margin | C18: =Statement!M104 -> 0.046481433 | D18: =Statement!N104 -> 0.021689433 | E18: =Statement!O104 -> 0.052932836 | F18: =Statement!P104 -> 0.092871172 | G18: =Statement!Q104 -> 0.090204819 | I18: =Statement!AC104 -> 0.090243337
B20: Earnings quality
B21: Net income | C21: =Statement!M19 -> 21838 | D21: =Statement!N19 -> 11148 | E21: =Statement!O19 -> 30425 | F21: =Statement!P19 -> 59248 | G21: =Statement!Q19 -> 64670 | I21: =Statement!AC19 -> 71965
B22: Operating cash | C22: =Statement!M60 -> 46327 | D22: =Statement!N60 -> 46752 | E22: =Statement!O60 -> 84946 | F22: =Statement!P60 -> 115877 | G22: =Statement!Q60 -> 139514 | I22: =Statement!AC60 -> 168300
B23: Cash accruals | C23: =IF(OR(C21<=0, C22<=0),"N/A",C21-C22) -> -24489 | D23: =IF(OR(D21<=0, D22<=0),"N/A",D21-D22) -> -35604 | E23: =IF(OR(E21<=0, E22<=0),"N/A",E21-E22) -> -54521 | F23: =IF(OR(F21<=0, F22<=0),"N/A",F21-F22) -> -56629 | G23: =IF(OR(G21<=0, G22<=0),"N/A",G21-G22) -> -74844 | I23: =IF(OR(I21<=0, I22<=0),"N/A",I21-I22) -> -96335
B25: DuPont Identity
B26: Profit Margin (Earnings/Revenue) | C26: =Statement!M122 -> 0.046481433 | D26: =Statement!N122 -> 0.021689433 | E26: =Statement!O122 -> 0.052932836 | F26: =Statement!P122 -> 0.092871172 | G26: =Statement!Q122 -> 0.090204819 | I26: =Statement!AC122 -> 0.090243337
B27: Asset Turnover (Revenue/Total assets) | C27: =Statement!M123 -> 1.1171635 | D27: =Statement!N123 -> 1.1108943 | E27: =Statement!O123 -> 1.0889091 | F27: =Statement!P123 -> 1.0209075 | G27: =Statement!Q123 -> 0.87639021 | I27: =Statement!AC123 -> 0.64135549
B28: ROA | C28: =Statement!M124 -> 0.051927362 | D28: =Statement!N124 -> 0.024094667 | E28: =Statement!O124 -> 0.057639044 | F28: =Statement!P124 -> 0.09481288 | G28: =Statement!Q124 -> 0.079054621 | I28: =Statement!AC124 -> 0.057878059
B29: Equity Multiplier (Total assets/Equity) | C29: =Statement!M125 -> 3.0420558 | D29: =Statement!N125 -> 3.1680738 | E29: =Statement!O125 -> 2.6147567 | F29: =Statement!P125 -> 2.1851733 | G29: =Statement!Q125 -> 1.9900551 | I29: =Statement!AC125 -> 2.026382
B30: ROE | C30: =Statement!M126 -> 0.15796593 | D30: =Statement!N126 -> 0.076333683 | E30: =Statement!O126 -> 0.15071207 | F30: =Statement!P126 -> 0.20718257 | G30: =Statement!Q126 -> 0.15732305 | I30: =Statement!AC126 -> 0.11728306
B32: Performance Indicators
B33: ROA | C33: =C28 -> 0.051927362 | D33: =D28 -> 0.024094667 | E33: =E28 -> 0.057639044 | F33: =F28 -> 0.09481288 | G33: =G28 -> 0.079054621 | I33: =I28 -> 0.057878059
B34: ROE | C34: =C30 -> 0.15796593 | D34: =D30 -> 0.076333683 | E34: =E30 -> 0.15071207 | F34: =F30 -> 0.20718257 | G34: =G30 -> 0.15732305 | I34: =I30 -> 0.11728306
B35: ROIC | C35: =Statement!M141 -> 0.22434772 | D35: =Statement!N141 -> 0.085550441 | E35: =Statement!O141 -> 0.17222666 | F35: =Statement!P141 -> 0.24992875 | G35: =Statement!Q141 -> 0.17492908 | I35: =Statement!AC141 -> 0.10099664
B37: Cash conversion cycle
B38: DSO | C38: =Statement!M142 -> 25.552688 | D38: =Statement!N142 -> 30.08154 | E38: =Statement!O142 -> 33.181703 | F38: =Statement!P142 -> 31.725573 | G38: =Statement!Q142 -> 34.482156 | I38: =Statement!AC142 -> 44.96596
B39: DIO | C39: =Statement!M143 -> 34.288181 | D39: =Statement!N143 -> 33.655361 | E39: =Statement!O143 -> 30.759641 | F39: =Statement!P143 -> 29.398107 | G39: =Statement!Q143 -> 30.051527 | I39: =Statement!AC143 -> 30.781654
B40: DPO | C40: =Statement!M144 -> 82.636197 | D40: =Statement!N144 -> 77.865623 | E40: =Statement!O144 -> 78.45564 | F40: =Statement!P144 -> 81.080656 | G40: =Statement!Q144 -> 95.591691 | I40: =Statement!AC144 -> 114.59725
B41: Net trade cycle | C41: =Statement!M145 -> -22.795328 | D41: =Statement!N145 -> -14.128722 | E41: =Statement!O145 -> -14.514297 | F41: =Statement!P145 -> -19.956976 | G41: =Statement!Q145 -> -31.058009 | I41: =Statement!AC145 -> -38.849641
B43: Liquidity ratios
B44: Debt/Equity | C44: =Statement!M146 -> 0.35259141 | D44: =Statement!N146 -> 0.45979609 | E44: =Statement!O146 -> 0.28886192 | F44: =Statement!P146 -> 0.18401581 | G44: =Statement!Q146 -> 0.15970224 | I44: =Statement!AC146 -> 0.28214589
B45: Net Debt/Equity | C45: =Statement!M147 -> -0.34218236 | D45: =Statement!N147 -> -0.01969283 | E45: =Statement!O147 -> -0.14100805 | F45: =Statement!P147 -> -0.16987446 | G45: =Statement!Q147 -> -0.13959106 | I45: =Statement!AC147 -> 0.095989087
B46: Quick ratio | C46: =Statement!M148 -> 0.9063304 | D46: =Statement!N148 -> 0.72323721 | E46: =Statement!O148 -> 0.84304832 | F46: =Statement!P148 -> 0.87305427 | G46: =Statement!Q148 -> 0.87501663 | I46: =Statement!AC148 -> 0.82357684
B47: Current ratio | C47: =Statement!M149 -> 1.1357598 | D47: =Statement!N149 -> 0.94464358 | E47: =Statement!O149 -> 1.0450772 | F47: =Statement!P149 -> 1.0637348 | G47: =Statement!Q149 -> 1.0508153 | I47: =Statement!AC149 -> 0.98882868
B48: Interest coverage | C48: =Statement!M150 -> 18.279941 | D48: =Statement!N150 -> 8.8882438 | E48: =Statement!O150 -> 158.16309 | F48: =Statement!P150 -> N/A | G48: =Statement!Q150 -> N/A | I48: =Statement!AC150 -> N/A
...

Sheet Quarter analysis
C3: Latest 2 quarters | F3: YoY
C4: =Statement!Z2 -> 30.06.2026 | D4: =Statement!AA2 -> 30.09.2026 | F4: =Statement!W2 -> 30.09.2025 | G4: =Statement!AA2 -> 30.09.2026
B5: Income statement growth | C5: =Statement!Z3 -> Q2 2026 | D5: =Statement!AA3 -> Q3 2026 | F5: =Statement!W3 -> Q3 2025 | G5: =Statement!AA3 -> Q3 2026
B6: Revenue | C6: =Statement!Z5 -> 200606 | D6: =Statement!AA5 -> 201944 | F6: =Statement!W5 -> 180169 | G6: =Statement!AA5 -> 201944
B7: Growth | C7: =Statement!AA90 -> 0.0066697905 | F7: =IF(F6=0, IF(G6=0,0,IF(G6>0,1,-1)), (G6-F6)/ABS(F6) ) -> 0.12085875
B8: COGS | C8: =Statement!Z6 -> 125411 | D8: =Statement!AA6 -> 124570 | F8: =Statement!W6 -> 116349 | G8: =Statement!AA6 -> 124570
B9: Growth | C9: =Statement!AA91 -> -0.0067059508 | F9: =IF(F8=0, IF(G8=0,0,IF(G8>0,1,-1)), (G8-F8)/ABS(F8) ) -> 0.070658106
B10: Gross Profit | C10: =Statement!Z7 -> 75195 | D10: =Statement!AA7 -> 77374 | F10: =Statement!W7 -> 63820 | G10: =Statement!AA7 -> 77374
B11: Growth | C11: =Statement!AA92 -> 0.028977991 | F11: =IF(F10=0, IF(G10=0,0,IF(G10>0,1,-1)), (G10-F10)/ABS(F10) ) -> 0.21237856
B12: OpEx | C12: =Statement!Z12 -> 47734 | D12: =Statement!AA12 -> 49298 | F12: =Statement!W12 -> 46398 | G12: =Statement!AA12 -> 49298
B13: Growth | C13: =Statement!AA96 -> 0.032764906 | F13: =IF(F12=0, IF(G12=0,0,IF(G12>0,1,-1)), (G12-F12)/ABS(F12) ) -> 0.062502694
B14: Operating profit | C14: =Statement!Z13 -> 27461 | D14: =Statement!AA13 -> 28076 | F14: =Statement!W13 -> 17422 | G14: =Statement!AA13 -> 28076
B15: Growth | C15: =Statement!AA97 -> 0.022395397 | F15: =IF(F14=0, IF(G14=0,0,IF(G14>0,1,-1)), (G14-F14)/ABS(F14) ) -> 0.61152566
B16: Net income | C16: =Statement!Z19 -> 12161 | D16: =Statement!AA19 -> 20685 | F16: =Statement!W19 -> 12187 | G16: =Statement!AA19 -> 20685
B17: Growth | C17: =Statement!AA99 -> 0.7009292 | F17: =IF(F16=0, IF(G16=0,0,IF(G16>0,1,-1)), (G16-F16)/ABS(F16) ) -> 0.6973004
B18: Diluted shares outstanding | C18: =Statement!Z23 -> 10903 | D18: =Statement!AA23 -> 10929 | F18: =Statement!W23 -> 10845 | G18: =Statement!AA23 -> 10929
B19: Growth | C19: =IF(C18=0, IF(D18=0,0,IF(D18>0,1,-1)), (D18-C18)/ABS(C18) ) -> 0.0023846648 | F19: =IF(F18=0, IF(G18=0,0,IF(G18>0,1,-1)), (G18-F18)/ABS(F18) ) -> 0.0077455048
B20: Diluted EPS | C20: =Statement!Z27 -> 1.1153811 | D20: =Statement!AA27 -> 1.8926709 | F20: =Statement!W27 -> 1.1237437 | G20: =Statement!AA27 -> 1.8926709
B21: Growth | C21: =IF(C20=0, IF(D20=0,0,IF(D20>0,1,-1)), (D20-C20)/ABS(C20) ) -> 0.6968827 | F21: =IF(F20=0, IF(G20=0,0,IF(G20>0,1,-1)), (G20-F20)/ABS(F20) ) -> 0.684255
B23: Revenue breakdown | C23: =C5 -> Q2 2026 | D23: =D5 -> Q3 2026 | F23: =F5 -> Q3 2025 | G23: =G5 -> Q3 2026
B24: =Statement!B202 -> Online Stores | C24: =Statement!Z188 -> 70432 | D24: =Statement!AA188 -> 68470 | F24: =Statement!W188 -> 67407 | G24: =Statement!AA188 -> 68470
B25: Growth | C25: =IF(C24=0, IF(D24=0,0,IF(D24>0,1,-1)), (D24-C24)/ABS(C24) ) -> -0.027856656 | F25: =IF(F24=0, IF(G24=0,0,IF(G24>0,1,-1)), (G24-F24)/ABS(F24) ) -> 0.015769876
B26: =Statement!B203 -> Physical Stores | C26: =Statement!Z189 -> 5794 | D26: =Statement!AA189 -> 5710 | F26: =Statement!W189 -> 5578 | G26: =Statement!AA189 -> 5710
B27: Growth | C27: =IF(C26=0, IF(D26=0,0,IF(D26>0,1,-1)), (D26-C26)/ABS(C26) ) -> -0.014497756 | F27: =IF(F26=0, IF(G26=0,0,IF(G26>0,1,-1)), (G26-F26)/ABS(F26) ) -> 0.023664396
B28: =Statement!B204 -> Third party seller services | C28: =Statement!Z190 -> 46780 | D28: =Statement!AA190 -> 46492 | F28: =Statement!W190 -> 42486 | G28: =Statement!AA190 -> 46492
B29: Growth | C29: =IF(C28=0, IF(D28=0,0,IF(D28>0,1,-1)), (D28-C28)/ABS(C28) ) -> -0.0061564771 | F29: =IF(F28=0, IF(G28=0,0,IF(G28>0,1,-1)), (G28-F28)/ABS(F28) ) -> 0.094289884
B30: =Statement!B205 -> Advertising services | C30: =Statement!Z191 -> 19809 | D30: =Statement!AA191 -> 19637 | F30: =Statement!W191 -> 17703 | G30: =Statement!AA191 -> 19637
B31: Growth | C31: =IF(C30=0, IF(D30=0,0,IF(D30>0,1,-1)), (D30-C30)/ABS(C30) ) -> -0.0086829219 | F31: =IF(F30=0, IF(G30=0,0,IF(G30>0,1,-1)), (G30-F30)/ABS(F30) ) -> 0.10924702
B32: =Statement!B206 -> Subscription services | C32: =Statement!Z192 -> 13730 | D32: =Statement!AA192 -> 14006 | F32: =Statement!W192 -> 12574 | G32: =Statement!AA192 -> 14006
B33: Growth | C33: =IF(C32=0, IF(D32=0,0,IF(D32>0,1,-1)), (D32-C32)/ABS(C32) ) -> 0.020101966 | F33: =IF(F32=0, IF(G32=0,0,IF(G32>0,1,-1)), (G32-F32)/ABS(F32) ) -> 0.1138858
B34: =Statement!B207 -> Other | C34: =Statement!Z193 -> 1829 | D34: =Statement!AA193 -> 1645 | F34: =Statement!W193 -> 1415 | G34: =Statement!AA193 -> 1645
B35: Growth | C35: =IF(C34=0, IF(D34=0,0,IF(D34>0,1,-1)), (D34-C34)/ABS(C34) ) -> -0.10060142 | F35: =IF(F34=0, IF(G34=0,0,IF(G34>0,1,-1)), (G34-F34)/ABS(F34) ) -> 0.16254417
B36: =Statement!B208 -> Retail | C36: =Statement!Z194 -> 158374 | D36: =Statement!AA194 -> 155960 | F36: =Statement!W194 -> 147163 | G36: =Statement!AA194 -> 155960
B37: Growth | C37: =IF(C36=0, IF(D36=0,0,IF(D36>0,1,-1)), (D36-C36)/ABS(C36) ) -> -0.015242401 | F37: =IF(F36=0, IF(G36=0,0,IF(G36>0,1,-1)), (G36-F36)/ABS(F36) ) -> 0.059777254
B38: =Statement!B209 -> AWS | C38: =Statement!Z195 -> 42232 | D38: =Statement!AA195 -> 45984 | F38: =Statement!W195 -> 33006 | G38: =Statement!AA195 -> 45984
B39: Growth | C39: =IF(C38=0, IF(D38=0,0,IF(D38>0,1,-1)), (D38-C38)/ABS(C38) ) -> 0.088842584 | F39: =IF(F38=0, IF(G38=0,0,IF(G38>0,1,-1)), (G38-F38)/ABS(F38) ) -> 0.39320124

Sheet Graphs Year
C63: =Statement!H2 -> 0 | D63: =Statement!I2 -> 0 | E63: =Statement!J2 -> 0 | F63: =Statement!K2 -> 0 | G63: =Statement!L2 -> 0 | H63: =Statement!M2 -> 31.12.2021 | I63: =Statement!N2 -> 31.12.2022 | J63: =Statement!O2 -> 31.12.2023 | ... L63: =Statement!Q2 -> 31.12.2025
C64: =Statement!H3 -> 0 | D64: =Statement!I3 -> 0 | E64: =Statement!J3 -> 0 | F64: =Statement!K3 -> 0 | G64: =Statement!L3 -> 0 | H64: =Statement!M3 -> 2021 | I64: =Statement!N3 -> 2022 | J64: =Statement!O3 -> 2023 | ... L64: =Statement!Q3 -> 2025
B65: Revenue | C65: =Statement!H5 -> 0 | D65: =Statement!I5 -> 0 | E65: =Statement!J5 -> 0 | F65: =Statement!K5 -> 0 | G65: =Statement!L5 -> 0 | H65: =Statement!M5 -> 469822 | I65: =Statement!N5 -> 513983 | J65: =Statement!O5 -> 574785 | ... L65: =Statement!Q5 -> 716924
B66: Operating income | C66: =Statement!H13 -> 0 | D66: =Statement!I13 -> 0 | E66: =Statement!J13 -> 0 | F66: =Statement!K13 -> 0 | G66: =Statement!L13 -> 0 | H66: =Statement!M13 -> 24879 | I66: =Statement!N13 -> 12248 | J66: =Statement!O13 -> 36852 | ... L66: =Statement!Q13 -> 79975
B67: Net income | C67: =Statement!H19 -> 0 | D67: =Statement!I19 -> 0 | E67: =Statement!J19 -> 0 | F67: =Statement!K19 -> 0 | G67: =Statement!L19 -> 0 | H67: =Statement!M19 -> 21838 | I67: =Statement!N19 -> 11148 | J67: =Statement!O19 -> 30425 | ... L67: =Statement!Q19 -> 64670
B68: FCFE | C68: =Statement!H158 -> 0 | D68: =Statement!I158 -> 0 | E68: =Statement!J158 -> 0 | F68: =Statement!K158 -> 0 | G68: =Statement!L158 -> 0 | H68: =Statement!M158 -> -27483 | I68: =Statement!N158 -> -36514 | J68: =Statement!O158 -> 8194 | ... L68: =Statement!Q158 -> -11772
B69: FCFF | C69: =Statement!H159 -> 0 | D69: =Statement!I159 -> 0 | E69: =Statement!J159 -> 0 | F69: =Statement!K159 -> 0 | G69: =Statement!L159 -> 0 | H69: =Statement!M159 -> -25828.818 | I69: =Statement!N159 -> -30362 | J69: =Statement!O159 -> 14258.653 | ... L69: =Statement!Q159 -> -24162.382
B70: Gross margin | C70: =Statement!H102 -> 0 | D70: =Statement!I102 -> 0 | E70: =Statement!J102 -> 0 | F70: =Statement!K102 -> 0 | G70: =Statement!L102 -> 0 | H70: =Statement!M102 -> 0.26045396 | I70: =Statement!N102 -> 0.27404214 | J70: =Statement!O102 -> 0.31216368 | ... L70: =Statement!Q102 -> 0.350715
B71: Operating margin | C71: =Statement!H103 -> 0 | D71: =Statement!I103 -> 0 | E71: =Statement!J103 -> 0 | F71: =Statement!K103 -> 0 | G71: =Statement!L103 -> 0 | H71: =Statement!M103 -> 0.052954098 | I71: =Statement!N103 -> 0.023829582 | J71: =Statement!O103 -> 0.064114408 | ... L71: =Statement!Q103 -> 0.11155297
B72: Net margin | C72: =Statement!H104 -> 0 | D72: =Statement!I104 -> 0 | E72: =Statement!J104 -> 0 | F72: =Statement!K104 -> 0 | G72: =Statement!L104 -> 0 | H72: =Statement!M104 -> 0.046481433 | I72: =Statement!N104 -> 0.021689433 | J72: =Statement!O104 -> 0.052932836 | ... L72: =Statement!Q104 -> 0.090204819
B73: ="Revenue "&Statement!B188 -> Revenue Online Stores | C73: =Statement!H188 -> 0 | D73: =Statement!I188 -> 0 | E73: =Statement!J188 -> 0 | F73: =Statement!K188 -> 0 | G73: =Statement!L188 -> 0 | H73: =Statement!M188 -> 222075 | I73: =Statement!N188 -> 220004 | J73: =Statement!O188 -> 231872 | ... L73: =Statement!Q188 -> 269287
B74: ="Revenue "&Statement!B189 -> Revenue Physical Stores | C74: =Statement!H189 -> 0 | D74: =Statement!I189 -> 0 | E74: =Statement!J189 -> 0 | F74: =Statement!K189 -> 0 | G74: =Statement!L189 -> 0 | H74: =Statement!M189 -> 17075 | I74: =Statement!N189 -> 18963 | J74: =Statement!O189 -> 20030 | ... L74: =Statement!Q189 -> 22561
B75: ="Revenue "&Statement!B190 -> Revenue Third party seller services | C75: =Statement!H190 -> 0 | D75: =Statement!I190 -> 0 | E75: =Statement!J190 -> 0 | F75: =Statement!K190 -> 0 | G75: =Statement!L190 -> 0 | H75: =Statement!M190 -> 103366 | I75: =Statement!N190 -> 117716 | J75: =Statement!O190 -> 140053 | ... L75: =Statement!Q190 -> 172162
B76: ="Revenue "&Statement!B191 -> Revenue Advertising services | C76: =Statement!H191 -> 0 | D76: =Statement!I191 -> 0 | E76: =Statement!J191 -> 0 | F76: =Statement!K191 -> 0 | G76: =Statement!L191 -> 0 | H76: =Statement!M191 -> 31160 | I76: =Statement!N191 -> 37739 | J76: =Statement!O191 -> 46906 | ... L76: =Statement!Q191 -> 68635
B77: ="Revenue "&Statement!B192 -> Revenue Subscription services | C77: =Statement!H192 -> 0 | D77: =Statement!I192 -> 0 | E77: =Statement!J192 -> 0 | F77: =Statement!K192 -> 0 | G77: =Statement!L192 -> 0 | H77: =Statement!M192 -> 31768 | I77: =Statement!N192 -> 35218 | J77: =Statement!O192 -> 40209 | ... L77: =Statement!Q192 -> 49619
B78: ="Revenue "&Statement!B193 -> Revenue Other | C78: =Statement!H193 -> 0 | D78: =Statement!I193 -> 0 | E78: =Statement!J193 -> 0 | F78: =Statement!K193 -> 0 | G78: =Statement!L193 -> 0 | H78: =Statement!M193 -> 2176 | I78: =Statement!N193 -> 4247 | J78: =Statement!O193 -> 4958 | ... L78: =Statement!Q193 -> 5935
B79: ="Revenue "&Statement!B194 -> Revenue Retail | C79: =Statement!H194 -> 0 | D79: =Statement!I194 -> 0 | E79: =Statement!J194 -> 0 | F79: =Statement!K194 -> 0 | G79: =Statement!L194 -> 0 | H79: =Statement!M194 -> 407620 | I79: =Statement!N194 -> 433887 | J79: =Statement!O194 -> 484028 | ... L79: =Statement!Q194 -> 588199
B80: ="Revenue "&Statement!B195 -> Revenue AWS | C80: =Statement!H195 -> 0 | D80: =Statement!I195 -> 0 | E80: =Statement!J195 -> 0 | F80: =Statement!K195 -> 0 | G80: =Statement!L195 -> 0 | H80: =Statement!M195 -> 62202 | I80: =Statement!N195 -> 80096 | J80: =Statement!O195 -> 90757 | ... L80: =Statement!Q195 -> 128725
B81: ROA | C81: =Statement!H124 -> 0 | D81: =Statement!I124 -> 0 | E81: =Statement!J124 -> 0 | F81: =Statement!K124 -> 0 | G81: =Statement!L124 -> 0 | H81: =Statement!M124 -> 0.051927362 | I81: =Statement!N124 -> 0.024094667 | J81: =Statement!O124 -> 0.057639044 | ... L81: =Statement!Q124 -> 0.079054621
B82: ROE | C82: =Statement!H126 -> 0 | D82: =Statement!I126 -> 0 | E82: =Statement!J126 -> 0 | F82: =Statement!K126 -> 0 | G82: =Statement!L126 -> 0 | H82: =Statement!M126 -> 0.15796593 | I82: =Statement!N126 -> 0.076333683 | J82: =Statement!O126 -> 0.15071207 | ... L82: =Statement!Q126 -> 0.15732305
B83: ROIC | C83: =Statement!H141 -> 0 | D83: =Statement!I141 -> 0 | E83: =Statement!J141 -> 0 | F83: =Statement!K141 -> 0 | G83: =Statement!L141 -> 0 | H83: =Statement!M141 -> 0.22434772 | I83: =Statement!N141 -> 0.085550441 | J83: =Statement!O141 -> 0.17222666 | ... L83: =Statement!Q141 -> 0.17492908
B84: Price 5y | C84: =Statement!H220 -> 0 | D84: =Statement!I220 -> 0 | E84: =Statement!J220 -> 0 | F84: =Statement!K220 -> 0 | G84: =Statement!L220 -> 0 | H84: =Statement!M220 -> 100 | I84: =Statement!N220 -> 50.377879 | J84: =Statement!O220 -> 91.134837 | ... L84: =Statement!Q220 -> 138.4477
B85: Revenue 5y | C85: =Statement!H221 -> 0 | D85: =Statement!I221 -> 0 | E85: =Statement!J221 -> 0 | F85: =Statement!K221 -> 0 | G85: =Statement!L221 -> 0 | H85: =Statement!M221 -> 100 | I85: =Statement!N221 -> 109.39952 | J85: =Statement!O221 -> 122.34101 | ... L85: =Statement!Q221 -> 152.59481
B86: EPS 5y | C86: =Statement!H222 -> 0 | D86: =Statement!I222 -> 0 | E86: =Statement!J222 -> 0 | F86: =Statement!K222 -> 0 | G86: =Statement!L222 -> 0 | H86: =Statement!M222 -> 100 | I86: =Statement!N222 -> 51.584719 | J86: =Statement!O222 -> 136.72681 | ... L86: =Statement!Q222 -> 281.61151

Sheet Graphs Quarter
C55: =Statement!T2 -> 31.12.2024 | D55: =Statement!U2 -> 31.03.2025 | E55: =Statement!V2 -> 30.06.2025 | F55: =Statement!W2 -> 30.09.2025 | G55: =Statement!X2 -> 31.12.2025 | H55: =Statement!Y2 -> 31.03.2026 | I55: =Statement!Z2 -> 30.06.2026 | J55: =Statement!AA2 -> 30.09.2026
C56: =Statement!T3 -> Q4 2024 | D56: =Statement!U3 -> Q1 2025 | E56: =Statement!V3 -> Q2 2025 | F56: =Statement!W3 -> Q3 2025 | G56: =Statement!X3 -> Q4 2025 | H56: =Statement!Y3 -> Q1 2026 | I56: =Statement!Z3 -> Q2 2026 | J56: =Statement!AA3 -> Q3 2026
B57: Revenue | C57: =Statement!T5 -> 187792 | D57: =Statement!U5 -> 155667 | E57: =Statement!V5 -> 167702 | F57: =Statement!W5 -> 180169 | G57: =Statement!X5 -> 213386 | H57: =Statement!Y5 -> 181519 | I57: =Statement!Z5 -> 200606 | J57: =Statement!AA5 -> 201944
B58: Operating income | C58: =Statement!T13 -> 21203 | D58: =Statement!U13 -> 18405 | E58: =Statement!V13 -> 19171 | F58: =Statement!W13 -> 17422 | G58: =Statement!X13 -> 24977 | H58: =Statement!Y13 -> 23852 | I58: =Statement!Z13 -> 27461 | J58: =Statement!AA13 -> 28076
B59: Net income | C59: =Statement!T19 -> 20004 | D59: =Statement!U19 -> 17127 | E59: =Statement!V19 -> 18164 | F59: =Statement!W19 -> 12187 | G59: =Statement!X19 -> 21192 | H59: =Statement!Y19 -> 17927 | I59: =Statement!Z19 -> 12161 | J59: =Statement!AA19 -> 20685
B60: Gross margin | C60: =Statement!T102 -> 0.32449199 | D60: =Statement!U102 -> 0.34752388 | E60: =Statement!V102 -> 0.36324552 | F60: =Statement!W102 -> 0.35422298 | G60: =Statement!X102 -> 0.34023319 | H60: =Statement!Y102 -> 0.36782375 | I60: =Statement!Z102 -> 0.37483924 | J60: =Statement!AA102 -> 0.38314582
B61: Operating margin | C61: =Statement!T103 -> 0.11290683 | D61: =Statement!U103 -> 0.11823315 | E61: =Statement!V103 -> 0.11431587 | F61: =Statement!W103 -> 0.0966981 | G61: =Statement!X103 -> 0.11705079 | H61: =Statement!Y103 -> 0.13140222 | I61: =Statement!Z103 -> 0.13689022 | J61: =Statement!AA103 -> 0.13902864
B62: Net margin | C62: =Statement!T104 -> 0.10652211 | D62: =Statement!U104 -> 0.11002332 | E62: =Statement!V104 -> 0.10831117 | F62: =Statement!W104 -> 0.067642047 | G62: =Statement!X104 -> 0.099312982 | H62: =Statement!Y104 -> 0.098761011 | I62: =Statement!Z104 -> 0.060621317 | J62: =Statement!AA104 -> 0.10242939
B63: ="Revenue "&Statement!B188 -> Revenue Online Stores | C63: =Statement!T188 -> 0 | D63: =Statement!U188 -> 57407 | E63: =Statement!V188 -> 61485 | F63: =Statement!W188 -> 67407 | G63: =Statement!X188 -> 82988 | H63: =Statement!Y188 -> 64254 | I63: =Statement!Z188 -> 70432 | J63: =Statement!AA188 -> 68470
B64: ="Revenue "&Statement!B189 -> Revenue Physical Stores | C64: =Statement!T189 -> 0 | D64: =Statement!U189 -> 5533 | E64: =Statement!V189 -> 5595 | F64: =Statement!W189 -> 5578 | G64: =Statement!X189 -> 5855 | H64: =Statement!Y189 -> 5785 | I64: =Statement!Z189 -> 5794 | J64: =Statement!AA189 -> 5710
B65: ="Revenue "&Statement!B190 -> Revenue Third party seller services | C65: =Statement!T190 -> 0 | D65: =Statement!U190 -> 36512 | E65: =Statement!V190 -> 40348 | F65: =Statement!W190 -> 42486 | G65: =Statement!X190 -> 52816 | H65: =Statement!Y190 -> 41578 | I65: =Statement!Z190 -> 46780 | J65: =Statement!AA190 -> 46492
B66: ="Revenue "&Statement!B191 -> Revenue Advertising services | C66: =Statement!T191 -> 0 | D66: =Statement!U191 -> 13921 | E66: =Statement!V191 -> 15694 | F66: =Statement!W191 -> 17703 | G66: =Statement!X191 -> 21317 | H66: =Statement!Y191 -> 17243 | I66: =Statement!Z191 -> 19809 | J66: =Statement!AA191 -> 19637
B67: ="Revenue "&Statement!B192 -> Revenue Subscription services | C67: =Statement!T192 -> 0 | D67: =Statement!U192 -> 11715 | E67: =Statement!V192 -> 12208 | F67: =Statement!W192 -> 12574 | G67: =Statement!X192 -> 13122 | H67: =Statement!Y192 -> 13427 | I67: =Statement!Z192 -> 13730 | J67: =Statement!AA192 -> 14006
B68: ="Revenue "&Statement!B193 -> Revenue Other | C68: =Statement!T193 -> 0 | D68: =Statement!U193 -> 1312 | E68: =Statement!V193 -> 1499 | F68: =Statement!W193 -> 1415 | G68: =Statement!X193 -> 1709 | H68: =Statement!Y193 -> 1645 | I68: =Statement!Z193 -> 1829 | J68: =Statement!AA193 -> 1645
B69: ="Revenue "&Statement!B194 -> Revenue Retail | C69: =Statement!T194 -> 0 | D69: =Statement!U194 -> 126400 | E69: =Statement!V194 -> 136829 | F69: =Statement!W194 -> 147163 | G69: =Statement!X194 -> 177807 | H69: =Statement!Y194 -> 143932 | I69: =Statement!Z194 -> 158374 | J69: =Statement!AA194 -> 155960
B70: ="Revenue "&Statement!B195 -> Revenue AWS | C70: =Statement!T195 -> 0 | D70: =Statement!U195 -> 29267 | E70: =Statement!V195 -> 30837 | F70: =Statement!W195 -> 33006 | G70: =Statement!X195 -> 35615 | H70: =Statement!Y195 -> 37587 | I70: =Statement!Z195 -> 42232 | J70: =Statement!AA195 -> 45984
B71: FCFE | C71: =Statement!T158 -> 12807 | D71: =Statement!U158 -> -11693 | E71: =Statement!V158 -> -6202 | F71: =Statement!W158 -> -4417 | G71: =Statement!X158 -> 10540 | H71: =Statement!Y158 -> -22203 | I71: =Statement!Z158 -> -14859 | J71: =Statement!AA158 -> -40243

Sheet Forecast ->
H5: Links
H6: Overview'!B3
H7: Financials ->'!B13
H8: Analysis ->'!B13
H9: Forecast ->'!B13
H10: Valuation ->'!B13
B13: Forecast ->

Sheet Revenue
B1: Revenue forecast
C2: History | H2: Forecast | S2: History | AA2: Forecast | AE2: TTM
C4: Revenues | S4: Revenues
B5: Revenues (thousand) | C5: =Statement!M3 -> 2021 | D5: =Statement!N3 -> 2022 | E5: =Statement!O3 -> 2023 | F5: =Statement!P3 -> 2024 | G5: =Statement!Q3 -> 2025 | H5: =G5+1 -> 2026 | I5: =H5+1 -> 2027 | J5: =I5+1 -> 2028 | K5: =J5+1 -> 2029 | L5: =K5+1 -> 2030 | R5: =B5 -> Revenues (thousand) | S5: =Statement!T3 -> Q4 2024 | T5: =Statement!U3 -> Q1 2025 | U5: =Statement!V3 -> Q2 2025 | V5: =Statement!W3 -> Q3 2025 | W5: =Statement!X3 -> Q4 2025 | X5: =Statement!Y3 -> Q1 2026 | Y5: =Statement!Z3 -> Q2 2026 | Z5: =Statement!AA3 -> Q3 2026 | AA5: FQ1 | AB5: FQ2 | AC5: FQ3 | AE5: FQ1
B6: =Statement!B188 -> Online Stores | C6: =Statement!M188 -> 222075 | D6: =Statement!N188 -> 220004 | E6: =Statement!O188 -> 231872 | F6: =Statement!P188 -> 247029 | G6: =Statement!Q188 -> 269287 | H6: =G6*(1+H18) -> 292176.4 | I6: =H6*(1+I18) -> 312628.74 | J6: =I6*(1+J18) -> 334512.75 | K6: =J6*(1+K18) -> 357928.65 | L6: =K6*(1+L18) -> 382983.65 | N6: Online Stores Growth Rate | Q6: Online Stores Growth Rate | R6: =B6 -> Online Stores | S6: =Statement!T188 -> 0 | T6: =Statement!U188 -> 57407 | U6: =Statement!V188 -> 61485 | V6: =Statement!W188 -> 67407 | W6: =Statement!X188 -> 82988 | X6: =Statement!Y188 -> 64254 | Y6: =Statement!Z188 -> 70432 | Z6: =Statement!AA188 -> 68470 | AA6: =Z6*(1+AA18) -> 89011 | AE6: =SUM(X6:AA6) -> 292167
B7: =Statement!B189 -> Physical Stores | C7: =Statement!M189 -> 17075 | D7: =Statement!N189 -> 18963 | E7: =Statement!O189 -> 20030 | F7: =Statement!P189 -> 21215 | G7: =Statement!Q189 -> 22561 | H7: =G7*(1+H19) -> 23576.245 | I7: =H7*(1+I19) -> 24566.447 | J7: =I7*(1+J19) -> 25549.105 | K7: =J7*(1+K19) -> 26571.069 | L7: =K7*(1+L19) -> 27633.912 | N7: Physical Stores Growth Rate | Q7: Physical Stores Growth Rate | R7: =B7 -> Physical Stores | S7: =Statement!T189 -> 0 | T7: =Statement!U189 -> 5533 | U7: =Statement!V189 -> 5595 | V7: =Statement!W189 -> 5578 | W7: =Statement!X189 -> 5855 | X7: =Statement!Y189 -> 5785 | Y7: =Statement!Z189 -> 5794 | Z7: =Statement!AA189 -> 5710 | AA7: =Z7*(1+AA19) -> 6566.5 | AE7: =SUM(X7:AA7) -> 23855.5
B8: =Statement!B190 -> Third party seller services | C8: =Statement!M190 -> 103366 | D8: =Statement!N190 -> 117716 | E8: =Statement!O190 -> 140053 | F8: =Statement!P190 -> 156146 | G8: =Statement!Q190 -> 172162 | H8: =G8*(1+H20) -> 189378.2 | I8: =H8*(1+I20) -> 208316.02 | J8: =I8*(1+J20) -> 229147.62 | K8: =J8*(1+K20) -> 249770.91 | L8: =K8*(1+L20) -> 272250.29 | N8: Third party Growth Rate | Q8: Third party Growth Rate | R8: =B8 -> Third party seller services | S8: =Statement!T190 -> 0 | T8: =Statement!U190 -> 36512 | U8: =Statement!V190 -> 40348 | V8: =Statement!W190 -> 42486 | W8: =Statement!X190 -> 52816 | X8: =Statement!Y190 -> 41578 | Y8: =Statement!Z190 -> 46780 | Z8: =Statement!AA190 -> 46492 | AA8: =Z8*(1+AA20) -> 55790.4 | AE8: =SUM(X8:AA8) -> 190640.4
B9: =Statement!B191 -> Advertising services | C9: =Statement!M191 -> 31160 | D9: =Statement!N191 -> 37739 | E9: =Statement!O191 -> 46906 | F9: =Statement!P191 -> 56214 | G9: =Statement!Q191 -> 68635 | H9: =G9*(1+H21) -> 78930.25 | I9: =H9*(1+I21) -> 93137.695 | J9: =I9*(1+J21) -> 110833.86 | K9: =J9*(1+K21) -> 129675.61 | L9: =K9*(1+L21) -> 149126.95 | N9: Advertising Growth Rate | Q9: Advertising Growth Rate | R9: =B9 -> Advertising services | S9: =Statement!T191 -> 0 | T9: =Statement!U191 -> 13921 | U9: =Statement!V191 -> 15694 | V9: =Statement!W191 -> 17703 | W9: =Statement!X191 -> 21317 | X9: =Statement!Y191 -> 17243 | Y9: =Statement!Z191 -> 19809 | Z9: =Statement!AA191 -> 19637 | AA9: =Z9*(1+AA21) -> 20618.85 | AE9: =SUM(X9:AA9) -> 77307.85
B10: =Statement!B192 -> Subscription services | C10: =Statement!M192 -> 31768 | D10: =Statement!N192 -> 35218 | E10: =Statement!O192 -> 40209 | F10: =Statement!P192 -> 44374 | G10: =Statement!Q192 -> 49619 | H10: =G10*(1+H22) -> 54580.9 | I10: =H10*(1+I22) -> 60584.799 | J10: =I10*(1+J22) -> 67854.975 | K10: =J10*(1+K22) -> 74640.472 | L10: =K10*(1+L22) -> 81358.115 | N10: Subscription Growth Rate | Q10: Subscription Growth Rate | R10: =B10 -> Subscription services | S10: =Statement!T192 -> 0 | T10: =Statement!U192 -> 11715 | U10: =Statement!V192 -> 12208 | V10: =Statement!W192 -> 12574 | W10: =Statement!X192 -> 13122 | X10: =Statement!Y192 -> 13427 | Y10: =Statement!Z192 -> 13730 | Z10: =Statement!AA192 -> 14006 | AA10: =Z10*(1+AA22) -> 14706.3 | AE10: =SUM(X10:AA10) -> 55869.3
B11: =Statement!B193 -> Other | C11: =Statement!M193 -> 2176 | D11: =Statement!N193 -> 4247 | E11: =Statement!O193 -> 4958 | F11: =Statement!P193 -> 5425 | G11: =Statement!Q193 -> 5935 | H11: =G11*(1+H23) -> 6409.8 | I11: =H11*(1+I23) -> 6858.486 | J11: =I11*(1+J23) -> 7407.1649 | K11: =J11*(1+K23) -> 7925.6664 | L11: =K11*(1+L23) -> 8480.4631 | N11: Other Growth Rate | Q11: Other Growth Rate | R11: =B11 -> Other | S11: =Statement!T193 -> 0 | T11: =Statement!U193 -> 1312 | U11: =Statement!V193 -> 1499 | V11: =Statement!W193 -> 1415 | W11: =Statement!X193 -> 1709 | X11: =Statement!Y193 -> 1645 | Y11: =Statement!Z193 -> 1829 | Z11: =Statement!AA193 -> 1645 | AA11: =Z11*(1+AA23) -> 1809.5 | AE11: =SUM(X11:AA11) -> 6928.5
B12: =Statement!B194 -> Retail | C12: =Statement!M194 -> 407620 | D12: =Statement!N194 -> 433887 | E12: =Statement!O194 -> 484028 | F12: =Statement!P194 -> 530403 | G12: =Statement!Q194 -> 588199 | H12: =SUM(H6:H11) -> 645051.79 | I12: =SUM(I6:I11) -> 706092.19 | J12: =SUM(J6:J11) -> 775305.48 | K12: =SUM(K6:K11) -> 846512.38 | L12: =SUM(L6:L11) -> 921833.39 | N12: SUM of all the above | Q12: SUM of all the above | R12: =B12 -> Retail | S12: =Statement!T194 -> 0 | T12: =Statement!U194 -> 126400 | U12: =Statement!V194 -> 136829 | V12: =Statement!W194 -> 147163 | W12: =Statement!X194 -> 177807 | X12: =Statement!Y194 -> 143932 | Y12: =Statement!Z194 -> 158374 | Z12: =Statement!AA194 -> 155960 | AA12: =SUM(AA6:AA11) -> 188502.55 | AE12: =SUM(X12:AA12) -> 646768.55
B13: =Statement!B195 -> AWS | C13: =Statement!M195 -> 62202 | D13: =Statement!N195 -> 80096 | E13: =Statement!O195 -> 90757 | F13: =Statement!P195 -> 107556 | G13: =Statement!Q195 -> 128725 | H13: =G13*(1+H25) -> 181502.25 | I13: =H13*(1+I25) -> 245028.04 | J13: =I13*(1+J25) -> 301384.49 | K13: =J13*(1+K25) -> 355633.69 | L13: =K13*(1+L25) -> 405422.41 | N13: AWS Growth Rate | Q13: AWS Growth Rate | R13: =B13 -> AWS | S13: =Statement!T195 -> 0 | T13: =Statement!U195 -> 29267 | U13: =Statement!V195 -> 30837 | V13: =Statement!W195 -> 33006 | W13: =Statement!X195 -> 35615 | X13: =Statement!Y195 -> 37587 | Y13: =Statement!Z195 -> 42232 | Z13: =Statement!AA195 -> 45984 | AA13: =Z13*(1+AA25) -> 55180.8 | AE13: =SUM(X13:AA13) -> 180983.8
B14: Total | C14: =Statement!M5 -> 469822 | D14: =Statement!N5 -> 513983 | E14: =Statement!O5 -> 574785 | F14: =Statement!P5 -> 637959 | G14: =Statement!Q5 -> 716924 | H14: =SUM(H12:H13) -> 826554.04 | I14: =SUM(I12:I13) -> 951120.23 | J14: =SUM(J12:J13) -> 1076690 | K14: =SUM(K12:K13) -> 1202146.1 | L14: =SUM(L12:L13) -> 1327255.8 | N14: SUM of Retail and AWS | Q14: SUM of Retail and AWS | R14: Total | S14: =Statement!T5 -> 187792 | T14: =Statement!U5 -> 155667 | U14: =Statement!V5 -> 167702 | V14: =Statement!W5 -> 180169 | W14: =Statement!X5 -> 213386 | X14: =Statement!Y5 -> 181519 | Y14: =Statement!Z5 -> 200606 | Z14: =Statement!AA5 -> 201944 | AA14: =SUM(AA12:AA13) -> 243683.35 | AE14: =SUM(X14:AA14) -> 827752.35
C16: Growth rates | S16: Growth rates
B17: Revenue growth % | C17: =C5 -> 2021 | D17: =D5 -> 2022 | E17: =E5 -> 2023 | F17: =F5 -> 2024 | G17: =G5 -> 2025 | H17: =H5 -> 2026 | I17: =I5 -> 2027 | J17: =J5 -> 2028 | ... L17: =L5 -> 2030 | R17: Revenue growth % | S17: =S5 -> Q4 2024 | T17: =T5 -> Q1 2025 | U17: =U5 -> Q2 2025 | V17: =V5 -> Q3 2025 | W17: =W5 -> Q4 2025 | X17: =X5 -> Q1 2026 | Y17: =Y5 -> Q2 2026 | Z17: =Z5 -> Q3 2026 | ... AC17: =AC5 -> FQ3
B18: =B6 -> Online Stores | D18: =D6/C6-1 -> -0.0093256783 | E18: =E6/D6-1 -> 0.053944474 | F18: =F6/E6-1 -> 0.065367962 | G18: =G6/F6-1 -> 0.090102781 | H18: 0.085 | I18: 0.07 | J18: 0.07 | K18: 0.07 | L18: 0.07 | R18: =R6 -> Online Stores | T18: =T6/S6-1 -> #DIV/0! | U18: =U6/T6-1 -> 0.071036633 | V18: =V6/U6-1 -> 0.096316175 | W18: =W6/V6-1 -> 0.2311481 | X18: =X6/W6-1 -> -0.22574348 | Y18: =Y6/X6-1 -> 0.096149656 | Z18: =Z6/Y6-1 -> -0.027856656 | AA18: 0.3
B19: =B7 -> Physical Stores | D19: =D7/C7-1 -> 0.11057101 | E19: =E7/D7-1 -> 0.056267468 | F19: =F7/E7-1 -> 0.059161258 | G19: =G7/F7-1 -> 0.063445675 | H19: 0.045 | I19: 0.042 | J19: 0.04 | K19: 0.04 | L19: 0.04 | R19: =R7 -> Physical Stores | T19: =T7/S7-1 -> #DIV/0! | U19: =U7/T7-1 -> 0.011205494 | V19: =V7/U7-1 -> -0.0030384272 | W19: =W7/V7-1 -> 0.049659376 | X19: =X7/W7-1 -> -0.011955594 | Y19: =Y7/X7-1 -> 0.0015557476 | Z19: =Z7/Y7-1 -> -0.014497756 | AA19: 0.15
B20: =B8 -> Third party seller services | D20: =D8/C8-1 -> 0.13882708 | E20: =E8/D8-1 -> 0.1897533 | F20: =F8/E8-1 -> 0.1149065 | G20: =G8/F8-1 -> 0.10257067 | H20: 0.1 | I20: 0.1 | J20: 0.1 | K20: 0.09 | L20: 0.09 | R20: =R8 -> Third party seller services | T20: =T8/S8-1 -> #DIV/0! | U20: =U8/T8-1 -> 0.10506135 | V20: =V8/U8-1 -> 0.052988996 | W20: =W8/V8-1 -> 0.24313892 | X20: =X8/W8-1 -> -0.21277643 | Y20: =Y8/X8-1 -> 0.12511424 | Z20: =Z8/Y8-1 -> -0.0061564771 | AA20: 0.2
B21: =B9 -> Advertising services | D21: =D9/C9-1 -> 0.21113607 | E21: =E9/D9-1 -> 0.24290522 | F21: =F9/E9-1 -> 0.19843943 | G21: =G9/F9-1 -> 0.22095919 | H21: 0.15 | I21: 0.18 | J21: 0.19 | K21: 0.17 | L21: 0.15 | R21: =R9 -> Advertising services | T21: =T9/S9-1 -> #DIV/0! | U21: =U9/T9-1 -> 0.12736154 | V21: =V9/U9-1 -> 0.1280107 | W21: =W9/V9-1 -> 0.20414619 | X21: =X9/W9-1 -> -0.19111507 | Y21: =Y9/X9-1 -> 0.14881401 | Z21: =Z9/Y9-1 -> -0.0086829219 | AA21: 0.05
B22: =B10 -> Subscription services | D22: =D10/C10-1 -> 0.10859985 | E22: =E10/D10-1 -> 0.1417173 | F22: =F10/E10-1 -> 0.10358377 | G22: =G10/F10-1 -> 0.11819985 | H22: 0.1 | I22: 0.11 | J22: 0.12 | K22: 0.1 | L22: 0.09 | R22: =R10 -> Subscription services | T22: =T10/S10-1 -> #DIV/0! | U22: =U10/T10-1 -> 0.0420828 | V22: =V10/U10-1 -> 0.029980341 | W22: =W10/V10-1 -> 0.043581995 | X22: =X10/W10-1 -> 0.023243408 | Y22: =Y10/X10-1 -> 0.022566471 | Z22: =Z10/Y10-1 -> 0.020101966 | AA22: 0.05
B23: =B11 -> Other | D23: =D11/C11-1 -> 0.95174632 | E23: =E11/D11-1 -> 0.16741229 | F23: =F11/E11-1 -> 0.094191206 | G23: =G11/F11-1 -> 0.094009217 | H23: 0.08 | I23: 0.07 | J23: 0.08 | K23: 0.07 | L23: 0.07 | R23: =R11 -> Other | T23: =T11/S11-1 -> #DIV/0! | U23: =U11/T11-1 -> 0.14253049 | V23: =V11/U11-1 -> -0.056037358 | W23: =W11/V11-1 -> 0.20777385 | X23: =X11/W11-1 -> -0.0374488 | Y23: =Y11/X11-1 -> 0.1118541 | Z23: =Z11/Y11-1 -> -0.10060142 | AA23: 0.1
B24: =B12 -> Retail | D24: =D12/C12-1 -> 0.06443992 | E24: =E12/D12-1 -> 0.11556235 | F24: =F12/E12-1 -> 0.095810573 | G24: =G12/F12-1 -> 0.1089662 | H24: =H12/G12-1 -> 0.096655707 | I24: =I12/H12-1 -> 0.094628681 | J24: =J12/I12-1 -> 0.09802302 | K24: =K12/J12-1 -> 0.091843666 | L24: =L12/K12-1 -> 0.088978039 | R24: =R12 -> Retail | T24: =T12/S12-1 -> #DIV/0! | U24: =U12/T12-1 -> 0.082507911 | V24: =V12/U12-1 -> 0.075524925 | W24: =W12/V12-1 -> 0.20823169 | X24: =X12/W12-1 -> -0.19051556 | Y24: =Y12/X12-1 -> 0.10033905 | Z24: =Z12/Y12-1 -> -0.015242401 | AA24: =AA12/Z12-1 -> 0.20865959
B25: =B13 -> AWS | D25: =D13/C13-1 -> 0.28767564 | E25: =E13/D13-1 -> 0.13310278 | F25: =F13/E13-1 -> 0.18509867 | G25: =G13/F13-1 -> 0.1968184 | H25: 0.41 | I25: 0.35 | J25: 0.23 | K25: 0.18 | L25: 0.14 | R25: =R13 -> AWS | T25: =T13/S13-1 -> #DIV/0! | U25: =U13/T13-1 -> 0.053644036 | V25: =V13/U13-1 -> 0.070337581 | W25: =W13/V13-1 -> 0.079046234 | X25: =X13/W13-1 -> 0.055369928 | Y25: =Y13/X13-1 -> 0.12357996 | Z25: =Z13/Y13-1 -> 0.088842584 | AA25: 0.2
B26: =B14 -> Total | D26: =D14/C14-1 -> 0.093995173 | E26: =E14/D14-1 -> 0.11829574 | F26: =F14/E14-1 -> 0.10990892 | G26: =G14/F14-1 -> 0.12377755 | H26: =H14/G14-1 -> 0.15291724 | I26: =I14/H14-1 -> 0.15070544 | J26: =J14/I14-1 -> 0.13202299 | K26: =K14/J14-1 -> 0.11652018 | L26: =L14/K14-1 -> 0.10407199 | R26: =R14 -> Total | T26: =T14/S14-1 -> -0.17106693 | U26: =U14/T14-1 -> 0.077312468 | V26: =V14/U14-1 -> 0.074340199 | W26: =W14/V14-1 -> 0.18436579 | X26: =X14/W14-1 -> -0.14933969 | Y26: =Y14/X14-1 -> 0.10515153 | Z26: =Z14/Y14-1 -> 0.0066697905 | AA26: =AA14/Z14-1 -> 0.20668775

Sheet COGS & OpEx
B1: COGS & OpEx forecast
C2: History | H2: Forecast | P2: History | X2: Forecast | AB2: TTM
C4: Revenues | P4: Revenues
B5: =Revenue!B5 -> Revenues (thousand) | C5: =Revenue!C5 -> 2021 | D5: =Revenue!D5 -> 2022 | E5: =Revenue!E5 -> 2023 | F5: =Revenue!F5 -> 2024 | G5: =Revenue!G5 -> 2025 | H5: =G5+1 -> 2026 | I5: =H5+1 -> 2027 | J5: =I5+1 -> 2028 | K5: =J5+1 -> 2029 | L5: =K5+1 -> 2030 | O5: Revenues (thousand) | P5: =Revenue!S5 -> Q4 2024 | Q5: =Revenue!T5 -> Q1 2025 | R5: =Revenue!U5 -> Q2 2025 | S5: =Revenue!V5 -> Q3 2025 | T5: =Revenue!W5 -> Q4 2025 | U5: =Revenue!X5 -> Q1 2026 | V5: =Revenue!Y5 -> Q2 2026 | W5: =Revenue!Z5 -> Q3 2026 | X5: FQ1 | Y5: FQ2 | Z5: FQ3 | AB5: =Revenue!AE5 -> FQ1
B6: Revenue | C6: =Revenue!C14 -> 469822 | D6: =Revenue!D14 -> 513983 | E6: =Revenue!E14 -> 574785 | F6: =Revenue!F14 -> 637959 | G6: =Revenue!G14 -> 716924 | H6: =Revenue!H14 -> 826554.04 | I6: =Revenue!I14 -> 951120.23 | J6: =Revenue!J14 -> 1076690 | ... L6: =Revenue!L14 -> 1327255.8 | O6: Revenue | P6: =Revenue!S14 -> 187792 | Q6: =Revenue!T14 -> 155667 | R6: =Revenue!U14 -> 167702 | S6: =Revenue!V14 -> 180169 | T6: =Revenue!W14 -> 213386 | U6: =Revenue!X14 -> 181519 | V6: =Revenue!Y14 -> 200606 | W6: =Revenue!Z14 -> 201944 | X6: =Revenue!AA14 -> 243683.35 | AB6: =Revenue!AE14 -> 827752.35
B7: Retail | C7: =Revenue!C12 -> 407620 | D7: =Revenue!D12 -> 433887 | E7: =Revenue!E12 -> 484028 | F7: =Revenue!F12 -> 530403 | G7: =Revenue!G12 -> 588199 | H7: =Revenue!H12 -> 645051.79 | I7: =Revenue!I12 -> 706092.19 | J7: =Revenue!J12 -> 775305.48 | ... L7: =Revenue!L12 -> 921833.39 | O7: Retail | P7: =Revenue!S12 -> 0 | Q7: =Revenue!T12 -> 126400 | R7: =Revenue!U12 -> 136829 | S7: =Revenue!V12 -> 147163 | T7: =Revenue!W12 -> 177807 | U7: =Revenue!X12 -> 143932 | V7: =Revenue!Y12 -> 158374 | W7: =Revenue!Z12 -> 155960 | X7: =Revenue!AA12 -> 188502.55 | AB7: =Revenue!AE12 -> 646768.55
B8: Retail Store | C8: =SUM(Revenue!C6:C8) -> 342516 | D8: =SUM(Revenue!D6:D8) -> 356683 | E8: =SUM(Revenue!E6:E8) -> 391955 | F8: =SUM(Revenue!F6:F8) -> 424390 | G8: =SUM(Revenue!G6:G8) -> 464010 | H8: =SUM(Revenue!H6:H8) -> 505130.84 | I8: =SUM(Revenue!I6:I8) -> 545511.21 | J8: =SUM(Revenue!J6:J8) -> 589209.48 | ... L8: =SUM(Revenue!L6:L8) -> 682867.85 | O8: Retail Store | P8: =SUM(Revenue!S6:S8) -> 0 | Q8: =SUM(Revenue!T6:T8) -> 99452 | R8: =SUM(Revenue!U6:U8) -> 107428 | S8: =SUM(Revenue!V6:V8) -> 115471 | T8: =SUM(Revenue!W6:W8) -> 141659 | U8: =SUM(Revenue!X6:X8) -> 111617 | V8: =SUM(Revenue!Y6:Y8) -> 123006 | W8: =SUM(Revenue!Z6:Z8) -> 120672 | X8: =SUM(Revenue!AA6:AA8) -> 151367.9 | AB8: =SUM(Revenue!AE6:AE8) -> 506662.9
C12: COGS and OpEx | P12: COGS & OpEx | AB12: =AB4 -> 0
