Workbook

Sheet Overview
B2: Ticker | C2: PHR
B3: Price | C3: =[1]Sheet1!$C$7 -> 9.05
B4: Cost of operating lease debt | C4: 0.075
B5: Cost of financial lease debt | C5: 0.078
B8: Units | C8: K
B10: Market cap | C10: =C3*'Statement Q'!J147 -> 549905.15
B11: Net debt | C11: =(Statements!S48+Statements!S49+Statements!S56+Statements!S57)-Statements!S26 -> 28619
B12: EV | C12: =C10+C11 -> 578524.15
B14: PE | C14: =C3/'Statement Q'!N25 -> 239.06756
B15: PS | C15: =$C$3/('Statement Q'!$N$5/'Statement Q'!$N$23) -> 1.147108
B19: Shares held by insiders | C19: 3302
B20: Total shares | C20: ='Statement Q'!J147 -> 60763
B21: Insider % | C21: =C19/C20 -> 0.054342281
B23: ROIC = NOPAT/Invested capital
B24: NOPAT = EBIT * (1-tax rate)
B25: Invested capital = (Total assets - Cash and equivalents) -non-interest bearing current liabilities
B26: NIBCL usually are accounts payable and accrued expenses and other operating items that do not have interest attached
B27: NIBCL does not include any sort of debt
B29: NOPAT | C29: =Statements!S14*(1-'Statement Y'!G151) -> -6290.232
B30: Assets les cash | C30: =Statements!S46-Statements!S26-Statements!S27 -> 556961
B31: NIBCL | C31: =SUM(Statements!S50:S54)+Statements!S47 -> 174016
B32: Invested capital | C32: =C30-C31 -> 382945
B33: ROIC | C33: =C29/C32 -> -0.016425941
A37: Info
A39: Mission: | B39: Address 3 challenges in healthcare: access to care, affordability of care, health patient outcomes
A40: Auditor: | B40: KPMG
A44: Notes
A46: Date: | B46: 30.03.2026 | C46: Q4 2026
B47: Revenue outlook for FY 2027 will be in the range 510-520 million
B48: Network solution clients commiting lower spend levels for second half of fiscal 2027
B49: AccessOne will contribute about 37 million to the total revenue range
B50: Adjusted EBITDA in the range 125 to 135 million
B51: AHSC growth in the mid single digit percentage range
B52: Total revenue per AHSC in low single digit percentage range
B53: TAM of 24B
B54: It is expected that subscription growth will be slower than the other 2 revenue streams
B55: Got a $250k revolving credit maturing on 13.03.2031

Sheet Financials ->
B13: Financials ->

Sheet Statement Y
B2: Date | C2: 31.01.2021 | D2: 31.01.2022 | E2: 31.01.2023 | F2: 31.01.2024 | G2: 31.01.2025 | H2: 31.01.2026
B3: FY | C3: =2021 -> 2021 | D3: =C3+1 -> 2022 | E3: =D3+1 -> 2023 | F3: =E3+1 -> 2024 | G3: =F3+1 -> 2025 | H3: =G3+1 -> 2026 | I3: =H3+1 -> 2027 | J3: =I3+1 -> 2028 | K3: =J3+1 -> 2029
B4: Income statement
B5: Revenue | C5: 148677 | D5: 213233 | E5: 280910 | F5: 356299 | G5: 419813 | H5: 480591
B6: COGS | C6: 52386 | D6: 81388 | E6: 109267 | F6: 124011 | G6: 134934 | H6: 154123
B7: Gross Profit | C7: =C5-C6 -> 96291 | D7: =D5-D6 -> 131845 | E7: =E5-E6 -> 171643 | F7: =F5-F6 -> 232288 | G7: =G5-G6 -> 284879 | H7: =H5-H6 -> 326468 | I7: =I5-I6 -> 0 | J7: =J5-J6 -> 0 | K7: =K5-K6 -> 0
B8: Sales and marketing | C8: 42972 | D8: 106421 | E8: 151263 | F8: 147008 | G8: 121129 | H8: 100243
B9: R&D | C9: 22622 | D9: 52265 | E9: 91244 | F9: 112346 | G9: 117364 | H9: 121481
B10: General and administrative | C10: 40460 | D10: 68674 | E10: 80384 | F10: 79926 | G10: 76597 | H10: 79903
B11: Depreciation | C11: 9770 | D11: 14985 | E11: 17988 | F11: 17584 | G11: 14183 | H11: 12972
B12: Amortization | C12: 6138 | D12: 6317 | E12: 7316 | F12: 11903 | G12: 13703 | H12: 18481
B13: OpEx | C13: =SUM(C8:C12) -> 121962 | D13: =SUM(D8:D12) -> 248662 | E13: =SUM(E8:E12) -> 348195 | F13: =SUM(F8:F12) -> 368767 | G13: =SUM(G8:G12) -> 342976 | H13: =SUM(H8:H12) -> 333080 | I13: =SUM(I8:I12) -> 0 | J13: =SUM(J8:J12) -> 0 | K13: =SUM(K8:K12) -> 0
B14: Operating income | C14: -25671 | D14: -116817 | E14: -176552 | F14: -136479 | G14: -58097 | H14: -6612
B15: Other income/expense | C15: 1 | D15: -78 | E15: -175 | F15: 44 | G15: 1956 | H15: 2953
B16: Extinguishment of debt | C16: 0 | D16: 0 | E16: 0 | F16: -1118 | G16: 0 | H16: -501
B17: Interest expense | C17: 0 | D17: 0 | E17: 0 | F17: 0 | G17: 0 | H17: -6953
B18: Interest income | C18: -1573 | D18: -1084 | E18: 1064 | F18: 2211 | G18: 330 | H18: 2173
B19: Income before taxes | C19: -27243 | D19: -117979 | E19: -175663 | F19: -135342 | G19: -55811 | H19: -8940
B20: Income tax expense/benefit | C20: -49 | D20: -182 | E20: -483 | F20: -1543 | G20: -2716 | H20: 11246
B21: Net income | C21: -27292 | D21: -118161 | E21: -176146 | F21: -136885 | G21: -58527 | H21: 2306
B22: Basic Shares outstanding avg | C22: 39520 | D22: 49888 | E22: 52440 | F22: 54561 | G22: 57590 | H22: 59738
B23: Diluted Shares outstanding avg | C23: 39520 | D23: 49888 | E23: 52440 | F23: 54561 | G23: 57590 | H23: 61495
B24: Basic EPS | C24: -0.69 | D24: -2.37 | E24: -3.36 | F24: -2.51 | G24: -1.02 | H24: 0.04
B25: Diluted EPS | C25: -0.69 | D25: -2.37 | E25: -3.36 | F25: -2.51 | G25: -1.02 | H25: 0.04
B27: Balance sheet
B28: Cash and cash equivalents | C28: 218781 | D28: 313812 | E28: 176683 | F28: 87520 | G28: 84220 | H28: 73830
B29: Settlement assets | C29: 15488 | D29: 19590 | E29: 22599 | F29: 28072 | G29: 29176 | H29: 32999
B30: Acc receivable | C30: 29052 | D30: 40262 | E30: 51394 | F30: 64863 | G30: 73617 | H30: 97453
B31: Cardholder receivables | C31: 0 | D31: 0 | E31: 0 | F31: 0 | G31: 0 | H31: 38330
B32: Deferred purchase receivables | C32: 0 | D32: 0 | E32: 0 | F32: 0 | G32: 0 | H32: 18003
B33: Accrued interest receivables | C33: 0 | D33: 0 | E33: 0 | F33: 0 | G33: 0 | H33: 840
B34: Deferred contract acquisition costs | C34: 1693 | D34: 1642 | E34: 1056 | F34: 768 | G34: 401 | H34: 410
B35: Prepaid expenses & Other current | C35: 7254 | D35: 11043 | E35: 10709 | F35: 14461 | G35: 15871 | H35: 17978
B36: Current assets | C36: 272268 | D36: 386349 | E36: 262441 | F36: 195684 | G36: 203285 | H36: 279843
B37: PP&E | C37: 26660 | D37: 34645 | E37: 21670 | F37: 16902 | G37: 23651 | H37: 20332
B38: Capitalized internal use software | C38: 10476 | D38: 17643 | E38: 35150 | F38: 46139 | G38: 52763 | H38: 54270
B39: Operating lease right of use | C39: 2654 | D39: 2337 | E39: 569 | F39: 266 | G39: 1477 | H39: 2002
... B46: Deferred purchase receivables | C46: 0 | D46: 0 | E46: 0 | F46: 0 | G46: 0 | H46: 5422
B47: Long term assets | C47: =SUM(C37:C44) -> 54398 | D47: =SUM(D37:D44) -> 108127 | E47: =SUM(E37:E44) -> 107616 | F47: =SUM(F37:F44) -> 174642 | G47: =SUM(G37:G44) -> 185130 | H47: =SUM(H37:H44) -> 330802 | I47: =SUM(I37:I44) -> 0 | J47: =SUM(J37:J44) -> 0 | K47: =SUM(K37:K44) -> 0
B48: Total assets | C48: 326666 | D48: 494476 | E48: 370057 | F48: 370326 | G48: 388415 | H48: 663790
...

Sheet Statement Q
B2: Date | C2: 30.04.2024 | D2: 31.07.2024 | E2: 31.10.2024 | F2: 31.01.2025 | G2: 30.04.2025 | H2: 31.07.2025 | I2: 31.10.2025 | J2: 31.01.2026
B3: Q | C3: Q1 2025 | D3: Q2 2025 | E3: Q3 2025 | F3: Q4 2025 | G3: Q1 2026 | H3: Q2 2026 | I3: Q3 2026 | J3: Q4 2026 | P3: =I3 -> Q3 2026 | Q3: =J3 -> Q4 2026 | R3: Growth Rate
B4: Income statement | N4: TTM | P4: Quarter compare
B5: Revenue | C5: 101217 | D5: 102115 | E5: 106800 | F5: 109681 | G5: 115936 | H5: 117255 | I5: 120333 | J5: 127067 | N5: =SUM(G5:J5) -> 480591 | P5: =I5 -> 120333 | Q5: =J5 -> 127067 | R5: =IF(P5=0, IF(Q5=0,0,IF(Q5>0,1,-1)), (Q5-P5)/ABS(P5) ) -> 0.055961374
B6: COGS | C6: 34020 | D6: 32811 | E6: 34537 | F6: 33566 | G6: 38065 | H6: 37641 | I6: 38027 | J6: 40390 | N6: =SUM(G6:J6) -> 154123 | P6: =I6 -> 38027 | Q6: =J6 -> 40390 | R6: =IF(P6=0, IF(Q6=0,0,IF(Q6>0,1,-1)), (Q6-P6)/ABS(P6) ) -> 0.062140058
B7: Gross Profit | C7: =C5-C6 -> 67197 | D7: =D5-D6 -> 69304 | E7: =E5-E6 -> 72263 | F7: =F5-F6 -> 76115 | G7: =G5-G6 -> 77871 | H7: =H5-H6 -> 79614 | I7: =I5-I6 -> 82306 | J7: =J5-J6 -> 86677 | N7: =SUM(G7:J7) -> 326468 | P7: =I7 -> 82306 | Q7: =J7 -> 86677 | R7: =IF(P7=0, IF(Q7=0,0,IF(Q7>0,1,-1)), (Q7-P7)/ABS(P7) ) -> 0.053106699
B8: Sales and marketing | C8: 32011 | D8: 30184 | E8: 30071 | F8: 28863 | G8: 26043 | H8: 25396 | I8: 24148 | J8: 24656 | N8: =SUM(G8:J8) -> 100243 | P8: =I8 -> 24148 | Q8: =J8 -> 24656 | R8: =IF(P8=0, IF(Q8=0,0,IF(Q8>0,1,-1)), (Q8-P8)/ABS(P8) ) -> 0.021036939
B9: R&D | C9: 28881 | D9: 29542 | E9: 29315 | F9: 29626 | G9: 31829 | H9: 29274 | I9: 29453 | J9: 30925 | N9: =SUM(G9:J9) -> 121481 | P9: =I9 -> 29453 | Q9: =J9 -> 30925 | R9: =IF(P9=0, IF(Q9=0,0,IF(Q9>0,1,-1)), (Q9-P9)/ABS(P9) ) -> 0.049977931
B10: General and administrative | C10: 19052 | D10: 19497 | E10: 19633 | F10: 18415 | G10: 16408 | H10: 19042 | I10: 17488 | J10: 26965 | N10: =SUM(G10:J10) -> 79903 | P10: =I10 -> 17488 | Q10: =J10 -> 26965 | R10: =IF(P10=0, IF(Q10=0,0,IF(Q10>0,1,-1)), (Q10-P10)/ABS(P10) ) -> 0.54191446
B11: Depreciation | C11: 3524 | D11: 3921 | E11: 3566 | F11: 3172 | G11: 2986 | H11: 3279 | I11: 3199 | J11: 3508 | N11: =SUM(G11:J11) -> 12972 | P11: =I11 -> 3199 | Q11: =J11 -> 3508 | R11: =IF(P11=0, IF(Q11=0,0,IF(Q11>0,1,-1)), (Q11-P11)/ABS(P11) ) -> 0.096592685
B12: Amortization | C12: 3149 | D12: 3382 | E12: 3521 | F12: 3651 | G12: 3892 | H12: 4130 | I12: 4279 | J12: 6180 | N12: =SUM(G12:J12) -> 18481 | P12: =I12 -> 4279 | Q12: =J12 -> 6180 | R12: =IF(P12=0, IF(Q12=0,0,IF(Q12>0,1,-1)), (Q12-P12)/ABS(P12) ) -> 0.44426268
B13: OpEx | C13: =SUM(C8:C12) -> 86617 | D13: =SUM(D8:D12) -> 86526 | E13: =SUM(E8:E12) -> 86106 | F13: =SUM(F8:F12) -> 83727 | G13: =SUM(G8:G12) -> 81158 | H13: =SUM(H8:H12) -> 81121 | I13: =SUM(I8:I12) -> 78567 | J13: =SUM(J8:J12) -> 92234 | N13: =SUM(G13:J13) -> 333080 | P13: =I13 -> 78567 | Q13: =J13 -> 92234 | R13: =IF(P13=0, IF(Q13=0,0,IF(Q13>0,1,-1)), (Q13-P13)/ABS(P13) ) -> 0.17395344
B14: Operating income | C14: -19420 | D14: -17222 | E14: -13843 | F14: -7612 | G14: -3287 | H14: -1507 | I14: 3739 | J14: -5557 | N14: =SUM(G14:J14) -> -6612 | P14: =I14 -> 3739 | Q14: =J14 -> -5557 | R14: =IF(P14=0, IF(Q14=0,0,IF(Q14>0,1,-1)), (Q14-P14)/ABS(P14) ) -> -2.4862263
B15: Other income/expense | C15: -31 | D15: -86 | E15: -144 | F15: 2217 | G15: 338 | H15: 336 | I15: 1006 | J15: 1273 | N15: =SUM(G15:J15) -> 2953 | P15: =I15 -> 1006 | Q15: =J15 -> 1273 | R15: =IF(P15=0, IF(Q15=0,0,IF(Q15>0,1,-1)), (Q15-P15)/ABS(P15) ) -> 0.26540755
B16: Extinguishment of debt | C16: 0 | D16: 0 | E16: 0 | F16: 0 | G16: 0 | H16: 0 | I16: 0 | J16: -501 | N16: =SUM(G16:J16) -> -501 | P16: =I16 -> 0 | Q16: =J16 -> -501 | R16: =IF(P16=0, IF(Q16=0,0,IF(Q16>0,1,-1)), (Q16-P16)/ABS(P16) ) -> -1
B17: Interest expense | C17: 0 | D17: 0 | E17: 0 | F17: 0 | G17: 0 | H17: 0 | I17: 0 | J17: -5807 | N17: =SUM(G17:J17) -> -5807 | P17: =I17 -> 0 | Q17: =J17 -> -5807 | R17: =IF(P17=0, IF(Q17=0,0,IF(Q17>0,1,-1)), (Q17-P17)/ABS(P17) ) -> -1
B18: Interest income | C18: 239 | D18: 46 | E18: 26 | F18: 19 | G18: -230 | H18: 608 | I18: 380 | J18: 269 | N18: =SUM(G18:J18) -> 1027 | P18: =I18 -> 380 | Q18: =J18 -> 269 | R18: =IF(P18=0, IF(Q18=0,0,IF(Q18>0,1,-1)), (Q18-P18)/ABS(P18) ) -> -0.29210526
B19: Income before taxes | C19: -19212 | D19: -17262 | E19: -13961 | F19: -5376 | G19: -3179 | H19: -563 | I19: 5125 | J19: -10323 | N19: =SUM(G19:J19) -> -8940 | P19: =I19 -> 5125 | Q19: =J19 -> -10323 | R19: =IF(P19=0, IF(Q19=0,0,IF(Q19>0,1,-1)), (Q19-P19)/ABS(P19) ) -> -3.0142439
B20: Income tax expense/benefit | C20: -510 | D20: -750 | E20: -442 | F20: -1014 | G20: -735 | H20: 1217 | I20: -854 | J20: 11618 | N20: =SUM(G20:J20) -> 11246 | P20: =I20 -> -854 | Q20: =J20 -> 11618 | R20: =IF(P20=0, IF(Q20=0,0,IF(Q20>0,1,-1)), (Q20-P20)/ABS(P20) ) -> 14.604215
B21: Net income | C21: -19722 | D21: -18012 | E21: -14403 | F21: -6390 | G21: -3914 | H21: 654 | I21: 4271 | J21: 1295 | N21: =SUM(G21:J21) -> 2306 | P21: =I21 -> 4271 | Q21: =J21 -> 1295 | R21: =IF(P21=0, IF(Q21=0,0,IF(Q21>0,1,-1)), (Q21-P21)/ABS(P21) ) -> -0.69679232
B22: Basic Shares outstanding avg | C22: 56666 | D22: 57503 | E22: 57892 | F22: 58278 | G22: 58921 | H22: 59592 | I22: 60009 | J22: 60404 | N22: =AVERAGE(G22:J22) -> 59731.5 | P22: =I22 -> 60009 | Q22: =J22 -> 60404 | R22: =IF(P22=0, IF(Q22=0,0,IF(Q22>0,1,-1)), (Q22-P22)/ABS(P22) ) -> 0.006582346
B23: Diluted Shares outstanding avg | C23: 56666 | D23: 57503 | E23: 57892 | F23: 58278 | G23: 58921 | H23: 61686 | I23: 61560 | J23: 61497 | N23: =AVERAGE((G23:J23)) -> 60916 | P23: =I23 -> 61560 | Q23: =J23 -> 61497 | R23: =IF(P23=0, IF(Q23=0,0,IF(Q23>0,1,-1)), (Q23-P23)/ABS(P23) ) -> -0.0010233918
B24: Basic EPS | C24: -0.35 | D24: -0.31 | E24: -0.25 | F24: -0.11 | G24: -0.07 | H24: 0.01 | I24: 0.07 | J24: 0.02 | N24: =N21/N22 -> 0.038606096 | P24: =I24 -> 0.07 | Q24: =J24 -> 0.02 | R24: =IF(P24=0, IF(Q24=0,0,IF(Q24>0,1,-1)), (Q24-P24)/ABS(P24) ) -> -0.71428571
B25: Diluted EPS | C25: -0.35 | D25: -0.31 | E25: -0.25 | F25: -0.11 | G25: -0.07 | H25: 0.01 | I25: 0.07 | J25: 0.02 | N25: =N21/N23 -> 0.037855407 | P25: =I25 -> 0.07 | Q25: =J25 -> 0.02 | R25: =IF(P25=0, IF(Q25=0,0,IF(Q25>0,1,-1)), (Q25-P25)/ABS(P25) ) -> -0.71428571
B27: Balance sheet
B28: Cash and cash equivalents | G28: 90871 | H28: 98266 | I28: 106371 | J28: 73830
B29: Settlement assets | G29: 33006 | H29: 28875 | I29: 25391 | J29: 32999
B30: Acc receivable | G30: 75099 | H30: 76842 | I30: 88257 | J30: 97453
B31: Cardholder receivables | G31: 0 | H31: 0 | I31: 0 | J31: 38330
B32: Deferred purchase receivables | G32: 0 | H32: 0 | I32: 0 | J32: 18003
B33: Accrued interest receivables | G33: 0 | H33: 0 | I33: 0 | J33: 840
B34: Deferred contract acquisition costs | G34: 414 | H34: 431 | I34: 427 | J34: 410
B35: Prepaid expenses & Other current | G35: 16019 | H35: 18227 | I35: 20460 | J35: 17978
B36: Current assets | G36: 215409 | H36: 222641 | I36: 240906 | J36: 279843
B37: PP&E | G37: 23492 | H37: 22769 | I37: 21111 | J37: 20332
B38: Capitalized internal use software | G38: 53531 | H38: 53881 | I38: 54093 | J38: 54270
B39: Operating lease right of use | G39: 1262 | H39: 1043 | I39: 820 | J39: 2002
... B46: Deferred purchase receivables | G46: 0 | H46: 0 | I46: 0 | J46: 5422
B47: Long term assets | C47: =SUM(C37:C44) -> 0 | D47: =SUM(D37:D44) -> 0 | E47: =SUM(E37:E44) -> 0 | F47: =SUM(F37:F44) -> 0 | G47: =SUM(G37:G44) -> 184986 | H47: =SUM(H37:H44) -> 185988 | I47: =SUM(I37:I44) -> 182566 | J47: =SUM(J37:J44) -> 330802
B48: Total assets | G48: 400395 | H48: 408629 | I48: 423472 | J48: 663790
...

Sheet Statements
B2: Date | C2: ='Statement Y'!C2 -> 31.01.2021 | D2: ='Statement Y'!D2 -> 31.01.2022 | E2: ='Statement Y'!E2 -> 31.01.2023 | F2: ='Statement Y'!F2 -> 31.01.2024 | G2: ='Statement Y'!G2 -> 31.01.2025 | H2: ='Statement Y'!H2 -> 31.01.2026 | J2: ='Statement Q'!C2 -> 30.04.2024 | K2: ='Statement Q'!D2 -> 31.07.2024 | L2: ='Statement Q'!E2 -> 31.10.2024 | M2: ='Statement Q'!F2 -> 31.01.2025 | N2: ='Statement Q'!G2 -> 30.04.2025 | O2: ='Statement Q'!H2 -> 31.07.2025 | P2: ='Statement Q'!I2 -> 31.10.2025 | Q2: ='Statement Q'!J2 -> 31.01.2026
B3: FY | C3: ='Statement Y'!C3 -> 2021 | D3: ='Statement Y'!D3 -> 2022 | E3: ='Statement Y'!E3 -> 2023 | F3: ='Statement Y'!F3 -> 2024 | G3: ='Statement Y'!G3 -> 2025 | H3: ='Statement Y'!H3 -> 2026 | J3: ='Statement Q'!C3 -> Q1 2025 | K3: ='Statement Q'!D3 -> Q2 2025 | L3: ='Statement Q'!E3 -> Q3 2025 | M3: ='Statement Q'!F3 -> Q4 2025 | N3: ='Statement Q'!G3 -> Q1 2026 | O3: ='Statement Q'!H3 -> Q2 2026 | P3: ='Statement Q'!I3 -> Q3 2026 | Q3: ='Statement Q'!J3 -> Q4 2026 | S3: TTM
B4: Income statement
B5: Revenue | C5: ='Statement Y'!C5 -> 148677 | D5: ='Statement Y'!D5 -> 213233 | E5: ='Statement Y'!E5 -> 280910 | F5: ='Statement Y'!F5 -> 356299 | G5: ='Statement Y'!G5 -> 419813 | H5: ='Statement Y'!H5 -> 480591 | J5: ='Statement Q'!C5 -> 101217 | K5: ='Statement Q'!D5 -> 102115 | L5: ='Statement Q'!E5 -> 106800 | M5: ='Statement Q'!F5 -> 109681 | N5: ='Statement Q'!G5 -> 115936 | O5: ='Statement Q'!H5 -> 117255 | P5: ='Statement Q'!I5 -> 120333 | Q5: ='Statement Q'!J5 -> 127067 | S5: =SUM(N5:Q5) -> 480591
B6: COGS | C6: ='Statement Y'!C6 -> 52386 | D6: ='Statement Y'!D6 -> 81388 | E6: ='Statement Y'!E6 -> 109267 | F6: ='Statement Y'!F6 -> 124011 | G6: ='Statement Y'!G6 -> 134934 | H6: ='Statement Y'!H6 -> 154123 | J6: ='Statement Q'!C6 -> 34020 | K6: ='Statement Q'!D6 -> 32811 | L6: ='Statement Q'!E6 -> 34537 | M6: ='Statement Q'!F6 -> 33566 | N6: ='Statement Q'!G6 -> 38065 | O6: ='Statement Q'!H6 -> 37641 | P6: ='Statement Q'!I6 -> 38027 | Q6: ='Statement Q'!J6 -> 40390 | S6: =SUM(N6:Q6) -> 154123
B7: Gross Profit | C7: ='Statement Y'!C7 -> 96291 | D7: ='Statement Y'!D7 -> 131845 | E7: ='Statement Y'!E7 -> 171643 | F7: ='Statement Y'!F7 -> 232288 | G7: ='Statement Y'!G7 -> 284879 | H7: ='Statement Y'!H7 -> 326468 | J7: ='Statement Q'!C7 -> 67197 | K7: ='Statement Q'!D7 -> 69304 | L7: ='Statement Q'!E7 -> 72263 | M7: ='Statement Q'!F7 -> 76115 | N7: ='Statement Q'!G7 -> 77871 | O7: ='Statement Q'!H7 -> 79614 | P7: ='Statement Q'!I7 -> 82306 | Q7: ='Statement Q'!J7 -> 86677 | S7: =SUM(N7:Q7) -> 326468
B8: Sales and marketing | C8: ='Statement Y'!C8 -> 42972 | D8: ='Statement Y'!D8 -> 106421 | E8: ='Statement Y'!E8 -> 151263 | F8: ='Statement Y'!F8 -> 147008 | G8: ='Statement Y'!G8 -> 121129 | H8: ='Statement Y'!H8 -> 100243 | J8: ='Statement Q'!C8 -> 32011 | K8: ='Statement Q'!D8 -> 30184 | L8: ='Statement Q'!E8 -> 30071 | M8: ='Statement Q'!F8 -> 28863 | N8: ='Statement Q'!G8 -> 26043 | O8: ='Statement Q'!H8 -> 25396 | P8: ='Statement Q'!I8 -> 24148 | Q8: ='Statement Q'!J8 -> 24656 | S8: =SUM(N8:Q8) -> 100243
B9: R&D | C9: ='Statement Y'!C9 -> 22622 | D9: ='Statement Y'!D9 -> 52265 | E9: ='Statement Y'!E9 -> 91244 | F9: ='Statement Y'!F9 -> 112346 | G9: ='Statement Y'!G9 -> 117364 | H9: ='Statement Y'!H9 -> 121481 | J9: ='Statement Q'!C9 -> 28881 | K9: ='Statement Q'!D9 -> 29542 | L9: ='Statement Q'!E9 -> 29315 | M9: ='Statement Q'!F9 -> 29626 | N9: ='Statement Q'!G9 -> 31829 | O9: ='Statement Q'!H9 -> 29274 | P9: ='Statement Q'!I9 -> 29453 | Q9: ='Statement Q'!J9 -> 30925 | S9: =SUM(N9:Q9) -> 121481
B10: General and administrative | C10: ='Statement Y'!C10 -> 40460 | D10: ='Statement Y'!D10 -> 68674 | E10: ='Statement Y'!E10 -> 80384 | F10: ='Statement Y'!F10 -> 79926 | G10: ='Statement Y'!G10 -> 76597 | H10: ='Statement Y'!H10 -> 79903 | J10: ='Statement Q'!C10 -> 19052 | K10: ='Statement Q'!D10 -> 19497 | L10: ='Statement Q'!E10 -> 19633 | M10: ='Statement Q'!F10 -> 18415 | N10: ='Statement Q'!G10 -> 16408 | O10: ='Statement Q'!H10 -> 19042 | P10: ='Statement Q'!I10 -> 17488 | Q10: ='Statement Q'!J10 -> 26965 | S10: =SUM(N10:Q10) -> 79903
B11: Depreciation | C11: ='Statement Y'!C11 -> 9770 | D11: ='Statement Y'!D11 -> 14985 | E11: ='Statement Y'!E11 -> 17988 | F11: ='Statement Y'!F11 -> 17584 | G11: ='Statement Y'!G11 -> 14183 | H11: ='Statement Y'!H11 -> 12972 | J11: ='Statement Q'!C11 -> 3524 | K11: ='Statement Q'!D11 -> 3921 | L11: ='Statement Q'!E11 -> 3566 | M11: ='Statement Q'!F11 -> 3172 | N11: ='Statement Q'!G11 -> 2986 | O11: ='Statement Q'!H11 -> 3279 | P11: ='Statement Q'!I11 -> 3199 | Q11: ='Statement Q'!J11 -> 3508 | S11: =SUM(N11:Q11) -> 12972
B12: Amortization | C12: ='Statement Y'!C12 -> 6138 | D12: ='Statement Y'!D12 -> 6317 | E12: ='Statement Y'!E12 -> 7316 | F12: ='Statement Y'!F12 -> 11903 | G12: ='Statement Y'!G12 -> 13703 | H12: ='Statement Y'!H12 -> 18481 | J12: ='Statement Q'!C12 -> 3149 | K12: ='Statement Q'!D12 -> 3382 | L12: ='Statement Q'!E12 -> 3521 | M12: ='Statement Q'!F12 -> 3651 | N12: ='Statement Q'!G12 -> 3892 | O12: ='Statement Q'!H12 -> 4130 | P12: ='Statement Q'!I12 -> 4279 | Q12: ='Statement Q'!J12 -> 6180 | S12: =SUM(N12:Q12) -> 18481
B13: OpEx | C13: ='Statement Y'!C13 -> 121962 | D13: ='Statement Y'!D13 -> 248662 | E13: ='Statement Y'!E13 -> 348195 | F13: ='Statement Y'!F13 -> 368767 | G13: ='Statement Y'!G13 -> 342976 | H13: ='Statement Y'!H13 -> 333080 | J13: ='Statement Q'!C13 -> 86617 | K13: ='Statement Q'!D13 -> 86526 | L13: ='Statement Q'!E13 -> 86106 | M13: ='Statement Q'!F13 -> 83727 | N13: ='Statement Q'!G13 -> 81158 | O13: ='Statement Q'!H13 -> 81121 | P13: ='Statement Q'!I13 -> 78567 | Q13: ='Statement Q'!J13 -> 92234 | S13: =SUM(N13:Q13) -> 333080
B14: Operating income | C14: ='Statement Y'!C14 -> -25671 | D14: ='Statement Y'!D14 -> -116817 | E14: ='Statement Y'!E14 -> -176552 | F14: ='Statement Y'!F14 -> -136479 | G14: ='Statement Y'!G14 -> -58097 | H14: ='Statement Y'!H14 -> -6612 | J14: ='Statement Q'!C14 -> -19420 | K14: ='Statement Q'!D14 -> -17222 | L14: ='Statement Q'!E14 -> -13843 | M14: ='Statement Q'!F14 -> -7612 | N14: ='Statement Q'!G14 -> -3287 | O14: ='Statement Q'!H14 -> -1507 | P14: ='Statement Q'!I14 -> 3739 | Q14: ='Statement Q'!J14 -> -5557 | S14: =SUM(N14:Q14) -> -6612
B15: EBITDA | C15: =C14+C73 -> -9763 | D15: =D14+D73 -> -95515 | E15: =E14+E73 -> -151248 | F15: =F14+F73 -> -106992 | G15: =G14+G73 -> -30211 | H15: =H14+H73 -> 24841 | J15: =J14+J73 -> -12747 | K15: =K14+K73 -> -9919 | L15: =L14+L73 -> -6756 | M15: =M14+M73 -> -789 | N15: =N14+N73 -> 3591 | O15: =O14+O73 -> 5902 | P15: =P14+P73 -> 11217 | Q15: =Q14+Q73 -> 4131 | S15: =SUM(N15:Q15) -> 24841
B16: Other income/expense | C16: ='Statement Y'!C15 -> 1 | D16: ='Statement Y'!D15 -> -78 | E16: ='Statement Y'!E15 -> -175 | F16: ='Statement Y'!F15 -> 44 | G16: ='Statement Y'!G15 -> 1956 | H16: ='Statement Y'!H15 -> 2953 | J16: ='Statement Q'!C15 -> -31 | K16: ='Statement Q'!D15 -> -86 | L16: ='Statement Q'!E15 -> -144 | M16: ='Statement Q'!F15 -> 2217 | N16: ='Statement Q'!G15 -> 338 | O16: ='Statement Q'!H15 -> 336 | P16: ='Statement Q'!I15 -> 1006 | Q16: ='Statement Q'!J15 -> 1273 | S16: =SUM(N16:Q16) -> 2953
B17: Extinguishment of debt | C17: ='Statement Y'!C16 -> 0 | D17: ='Statement Y'!D16 -> 0 | E17: ='Statement Y'!E16 -> 0 | F17: ='Statement Y'!F16 -> -1118 | G17: ='Statement Y'!G16 -> 0 | H17: ='Statement Y'!H16 -> -501 | J17: ='Statement Q'!C16 -> 0 | K17: ='Statement Q'!D16 -> 0 | L17: ='Statement Q'!E16 -> 0 | M17: ='Statement Q'!F16 -> 0 | N17: ='Statement Q'!G16 -> 0 | O17: ='Statement Q'!H16 -> 0 | P17: ='Statement Q'!I16 -> 0 | Q17: ='Statement Q'!J16 -> -501 | S17: =SUM(N17:Q17) -> -501
B18: Interest income | C18: ='Statement Y'!C18+'Statement Y'!C17 -> -1573 | D18: ='Statement Y'!D18+'Statement Y'!D17 -> -1084 | E18: ='Statement Y'!E18+'Statement Y'!E17 -> 1064 | F18: ='Statement Y'!F18+'Statement Y'!F17 -> 2211 | G18: ='Statement Y'!G18+'Statement Y'!G17 -> 330 | H18: ='Statement Y'!H18+'Statement Y'!H17 -> -4780 | J18: ='Statement Q'!C18+'Statement Q'!C17 -> 239 | K18: ='Statement Q'!D18+'Statement Q'!D17 -> 46 | L18: ='Statement Q'!E18+'Statement Q'!E17 -> 26 | M18: ='Statement Q'!F18+'Statement Q'!F17 -> 19 | N18: ='Statement Q'!G18+'Statement Q'!G17 -> -230 | O18: ='Statement Q'!H18+'Statement Q'!H17 -> 608 | P18: ='Statement Q'!I18+'Statement Q'!I17 -> 380 | Q18: ='Statement Q'!J18+'Statement Q'!J17 -> -5538 | S18: =SUM(N18:Q18) -> -4780
B19: Income before taxes | C19: ='Statement Y'!C19 -> -27243 | D19: ='Statement Y'!D19 -> -117979 | E19: ='Statement Y'!E19 -> -175663 | F19: ='Statement Y'!F19 -> -135342 | G19: ='Statement Y'!G19 -> -55811 | H19: ='Statement Y'!H19 -> -8940 | J19: ='Statement Q'!C19 -> -19212 | K19: ='Statement Q'!D19 -> -17262 | L19: ='Statement Q'!E19 -> -13961 | M19: ='Statement Q'!F19 -> -5376 | N19: ='Statement Q'!G19 -> -3179 | O19: ='Statement Q'!H19 -> -563 | P19: ='Statement Q'!I19 -> 5125 | Q19: ='Statement Q'!J19 -> -10323 | S19: =SUM(N19:Q19) -> -8940
B20: Income tax expense/benefit | C20: ='Statement Y'!C20 -> -49 | D20: ='Statement Y'!D20 -> -182 | E20: ='Statement Y'!E20 -> -483 | F20: ='Statement Y'!F20 -> -1543 | G20: ='Statement Y'!G20 -> -2716 | H20: ='Statement Y'!H20 -> 11246 | J20: ='Statement Q'!C20 -> -510 | K20: ='Statement Q'!D20 -> -750 | L20: ='Statement Q'!E20 -> -442 | M20: ='Statement Q'!F20 -> -1014 | N20: ='Statement Q'!G20 -> -735 | O20: ='Statement Q'!H20 -> 1217 | P20: ='Statement Q'!I20 -> -854 | Q20: ='Statement Q'!J20 -> 11618 | S20: =SUM(N20:Q20) -> 11246
B21: Net income | C21: ='Statement Y'!C21 -> -27292 | D21: ='Statement Y'!D21 -> -118161 | E21: ='Statement Y'!E21 -> -176146 | F21: ='Statement Y'!F21 -> -136885 | G21: ='Statement Y'!G21 -> -58527 | H21: ='Statement Y'!H21 -> 2306 | J21: ='Statement Q'!C21 -> -19722 | K21: ='Statement Q'!D21 -> -18012 | L21: ='Statement Q'!E21 -> -14403 | M21: ='Statement Q'!F21 -> -6390 | N21: ='Statement Q'!G21 -> -3914 | O21: ='Statement Q'!H21 -> 654 | P21: ='Statement Q'!I21 -> 4271 | Q21: ='Statement Q'!J21 -> 1295 | S21: =SUM(N21:Q21) -> 2306
B22: Diluted Shares outstanding avg | C22: ='Statement Y'!C23 -> 39520 | D22: ='Statement Y'!D23 -> 49888 | E22: ='Statement Y'!E23 -> 52440 | F22: ='Statement Y'!F23 -> 54561 | G22: ='Statement Y'!G23 -> 57590 | H22: ='Statement Y'!H23 -> 61495 | J22: ='Statement Q'!C23 -> 56666 | K22: ='Statement Q'!D23 -> 57503 | L22: ='Statement Q'!E23 -> 57892 | M22: ='Statement Q'!F23 -> 58278 | N22: ='Statement Q'!G23 -> 58921 | O22: ='Statement Q'!H23 -> 61686 | P22: ='Statement Q'!I23 -> 61560 | Q22: ='Statement Q'!J23 -> 61497 | S22: =AVERAGE(N22:Q22) -> 60916
B23: Diluted EPS | C23: ='Statement Y'!C25 -> -0.69 | D23: ='Statement Y'!D25 -> -2.37 | E23: ='Statement Y'!E25 -> -3.36 | F23: ='Statement Y'!F25 -> -2.51 | G23: ='Statement Y'!G25 -> -1.02 | H23: ='Statement Y'!H25 -> 0.04 | J23: ='Statement Q'!C25 -> -0.35 | K23: ='Statement Q'!D25 -> -0.31 | L23: ='Statement Q'!E25 -> -0.25 | M23: ='Statement Q'!F25 -> -0.11 | N23: ='Statement Q'!G25 -> -0.07 | O23: ='Statement Q'!H25 -> 0.01 | P23: ='Statement Q'!I25 -> 0.07 | Q23: ='Statement Q'!J25 -> 0.02 | S23: =S21/S22 -> 0.037855407
B25: Balance sheet
B26: Cash and cash equivalents | C26: ='Statement Y'!C28 -> 218781 | D26: ='Statement Y'!D28 -> 313812 | E26: ='Statement Y'!E28 -> 176683 | F26: ='Statement Y'!F28 -> 87520 | G26: ='Statement Y'!G28 -> 84220 | H26: ='Statement Y'!H28 -> 73830 | J26: ='Statement Q'!C28 -> 0 | K26: ='Statement Q'!D28 -> 0 | L26: ='Statement Q'!E28 -> 0 | M26: ='Statement Q'!F28 -> 0 | N26: ='Statement Q'!G28 -> 90871 | O26: ='Statement Q'!H28 -> 98266 | P26: ='Statement Q'!I28 -> 106371 | Q26: ='Statement Q'!J28 -> 73830 | S26: =Q26 -> 73830
B27: Settlement assets | C27: ='Statement Y'!C29 -> 15488 | D27: ='Statement Y'!D29 -> 19590 | E27: ='Statement Y'!E29 -> 22599 | F27: ='Statement Y'!F29 -> 28072 | G27: ='Statement Y'!G29 -> 29176 | H27: ='Statement Y'!H29 -> 32999 | J27: ='Statement Q'!C29 -> 0 | K27: ='Statement Q'!D29 -> 0 | L27: ='Statement Q'!E29 -> 0 | M27: ='Statement Q'!F29 -> 0 | N27: ='Statement Q'!G29 -> 33006 | O27: ='Statement Q'!H29 -> 28875 | P27: ='Statement Q'!I29 -> 25391 | Q27: ='Statement Q'!J29 -> 32999 | S27: =Q27 -> 32999
B28: Acc receivable | C28: ='Statement Y'!C30 -> 29052 | D28: ='Statement Y'!D30 -> 40262 | E28: ='Statement Y'!E30 -> 51394 | F28: ='Statement Y'!F30 -> 64863 | G28: ='Statement Y'!G30 -> 73617 | H28: ='Statement Y'!H30 -> 97453 | J28: ='Statement Q'!C30 -> 0 | K28: ='Statement Q'!D30 -> 0 | L28: ='Statement Q'!E30 -> 0 | M28: ='Statement Q'!F30 -> 0 | N28: ='Statement Q'!G30 -> 75099 | O28: ='Statement Q'!H30 -> 76842 | P28: ='Statement Q'!I30 -> 88257 | Q28: ='Statement Q'!J30 -> 97453 | S28: =Q28 -> 97453
B29: Cardholder receivables | C29: ='Statement Y'!C31 -> 0 | D29: ='Statement Y'!D31 -> 0 | E29: ='Statement Y'!E31 -> 0 | F29: ='Statement Y'!F31 -> 0 | G29: ='Statement Y'!G31 -> 0 | H29: ='Statement Y'!H31 -> 38330 | J29: ='Statement Q'!C31 -> 0 | K29: ='Statement Q'!D31 -> 0 | L29: ='Statement Q'!E31 -> 0 | M29: ='Statement Q'!F31 -> 0 | N29: ='Statement Q'!G31 -> 0 | O29: ='Statement Q'!H31 -> 0 | P29: ='Statement Q'!I31 -> 0 | Q29: ='Statement Q'!J31 -> 38330 | S29: =Q29 -> 38330
B30: Deferred purchase receivables | C30: ='Statement Y'!C32 -> 0 | D30: ='Statement Y'!D32 -> 0 | E30: ='Statement Y'!E32 -> 0 | F30: ='Statement Y'!F32 -> 0 | G30: ='Statement Y'!G32 -> 0 | H30: ='Statement Y'!H32 -> 18003 | J30: ='Statement Q'!C32 -> 0 | K30: ='Statement Q'!D32 -> 0 | L30: ='Statement Q'!E32 -> 0 | M30: ='Statement Q'!F32 -> 0 | N30: ='Statement Q'!G32 -> 0 | O30: ='Statement Q'!H32 -> 0 | P30: ='Statement Q'!I32 -> 0 | Q30: ='Statement Q'!J32 -> 18003 | S30: =Q30 -> 18003
B31: Accrued interest receivables | C31: ='Statement Y'!C33 -> 0 | D31: ='Statement Y'!D33 -> 0 | E31: ='Statement Y'!E33 -> 0 | F31: ='Statement Y'!F33 -> 0 | G31: ='Statement Y'!G33 -> 0 | H31: ='Statement Y'!H33 -> 840 | J31: ='Statement Q'!C33 -> 0 | K31: ='Statement Q'!D33 -> 0 | L31: ='Statement Q'!E33 -> 0 | M31: ='Statement Q'!F33 -> 0 | N31: ='Statement Q'!G33 -> 0 | O31: ='Statement Q'!H33 -> 0 | P31: ='Statement Q'!I33 -> 0 | Q31: ='Statement Q'!J33 -> 840 | S31: =Q31 -> 840
B32: Deferred contract acquisition costs | C32: ='Statement Y'!C34 -> 1693 | D32: ='Statement Y'!D34 -> 1642 | E32: ='Statement Y'!E34 -> 1056 | F32: ='Statement Y'!F34 -> 768 | G32: ='Statement Y'!G34 -> 401 | H32: ='Statement Y'!H34 -> 410 | J32: ='Statement Q'!C34 -> 0 | K32: ='Statement Q'!D34 -> 0 | L32: ='Statement Q'!E34 -> 0 | M32: ='Statement Q'!F34 -> 0 | N32: ='Statement Q'!G34 -> 414 | O32: ='Statement Q'!H34 -> 431 | P32: ='Statement Q'!I34 -> 427 | Q32: ='Statement Q'!J34 -> 410 | S32: =Q32 -> 410
B33: Prepaid expenses & Other current | C33: ='Statement Y'!C35 -> 7254 | D33: ='Statement Y'!D35 -> 11043 | E33: ='Statement Y'!E35 -> 10709 | F33: ='Statement Y'!F35 -> 14461 | G33: ='Statement Y'!G35 -> 15871 | H33: ='Statement Y'!H35 -> 17978 | J33: ='Statement Q'!C35 -> 0 | K33: ='Statement Q'!D35 -> 0 | L33: ='Statement Q'!E35 -> 0 | M33: ='Statement Q'!F35 -> 0 | N33: ='Statement Q'!G35 -> 16019 | O33: ='Statement Q'!H35 -> 18227 | P33: ='Statement Q'!I35 -> 20460 | Q33: ='Statement Q'!J35 -> 17978 | S33: =Q33 -> 17978
B34: Current assets | C34: ='Statement Y'!C36 -> 272268 | D34: ='Statement Y'!D36 -> 386349 | E34: ='Statement Y'!E36 -> 262441 | F34: ='Statement Y'!F36 -> 195684 | G34: ='Statement Y'!G36 -> 203285 | H34: ='Statement Y'!H36 -> 279843 | J34: ='Statement Q'!C36 -> 0 | K34: ='Statement Q'!D36 -> 0 | L34: ='Statement Q'!E36 -> 0 | M34: ='Statement Q'!F36 -> 0 | N34: ='Statement Q'!G36 -> 215409 | O34: ='Statement Q'!H36 -> 222641 | P34: ='Statement Q'!I36 -> 240906 | Q34: ='Statement Q'!J36 -> 279843 | S34: =Q34 -> 279843
B35: PP&E | C35: ='Statement Y'!C37 -> 26660 | D35: ='Statement Y'!D37 -> 34645 | E35: ='Statement Y'!E37 -> 21670 | F35: ='Statement Y'!F37 -> 16902 | G35: ='Statement Y'!G37 -> 23651 | H35: ='Statement Y'!H37 -> 20332 | J35: ='Statement Q'!C37 -> 0 | K35: ='Statement Q'!D37 -> 0 | L35: ='Statement Q'!E37 -> 0 | M35: ='Statement Q'!F37 -> 0 | N35: ='Statement Q'!G37 -> 23492 | O35: ='Statement Q'!H37 -> 22769 | P35: ='Statement Q'!I37 -> 21111 | Q35: ='Statement Q'!J37 -> 20332 | S35: =Q35 -> 20332
B36: Capitalized internal use software | C36: ='Statement Y'!C38 -> 10476 | D36: ='Statement Y'!D38 -> 17643 | E36: ='Statement Y'!E38 -> 35150 | F36: ='Statement Y'!F38 -> 46139 | G36: ='Statement Y'!G38 -> 52763 | H36: ='Statement Y'!H38 -> 54270 | J36: ='Statement Q'!C38 -> 0 | K36: ='Statement Q'!D38 -> 0 | L36: ='Statement Q'!E38 -> 0 | M36: ='Statement Q'!F38 -> 0 | N36: ='Statement Q'!G38 -> 53531 | O36: ='Statement Q'!H38 -> 53881 | P36: ='Statement Q'!I38 -> 54093 | Q36: ='Statement Q'!J38 -> 54270 | S36: =Q36 -> 54270
B37: Operating lease right of use | C37: ='Statement Y'!C39 -> 2654 | D37: ='Statement Y'!D39 -> 2337 | E37: ='Statement Y'!E39 -> 569 | F37: ='Statement Y'!F39 -> 266 | G37: ='Statement Y'!G39 -> 1477 | H37: ='Statement Y'!H39 -> 2002 | J37: ='Statement Q'!C39 -> 0 | K37: ='Statement Q'!D39 -> 0 | L37: ='Statement Q'!E39 -> 0 | M37: ='Statement Q'!F39 -> 0 | N37: ='Statement Q'!G39 -> 1262 | O37: ='Statement Q'!H39 -> 1043 | P37: ='Statement Q'!I39 -> 820 | Q37: ='Statement Q'!J39 -> 2002 | S37: =Q37 -> 2002
... B63: Total liabilities | C63: ='Statement Y'!C65 -> 63360 | D63: ='Statement Y'!D65 -> 77196 | E63: ='Statement Y'!E65 -> 82238 | F63: ='Statement Y'!F65 -> 118877 | G63: ='Statement Y'!G65 -> 123607 | H63: ='Statement Y'!H65 -> 326583 | J63: ='Statement Q'!C65 -> 0 | K63: ='Statement Q'!D65 -> 0 | L63: ='Statement Q'!E65 -> 0 | M63: ='Statement Q'!F65 -> 0 | N63: ='Statement Q'!G65 -> 118209 | O63: ='Statement Q'!H65 -> 110642 | P63: ='Statement Q'!I65 -> 103143 | Q63: ='Statement Q'!J65 -> 326583 | S63: =Q63 -> 326583
B64: Common stock par value | C64: ='Statement Y'!C67 -> 449 | D64: ='Statement Y'!D67 -> 521 | E64: ='Statement Y'!E67 -> 542 | F64: ='Statement Y'!F67 -> 577 | G64: ='Statement Y'!G67 -> 601 | H64: ='Statement Y'!H67 -> 620 | J64: ='Statement Q'!C67 -> 0 | K64: ='Statement Q'!D67 -> 0 | L64: ='Statement Q'!E67 -> 0 | M64: ='Statement Q'!F67 -> 0 | N64: ='Statement Q'!G67 -> 608 | O64: ='Statement Q'!H67 -> 611 | P64: ='Statement Q'!I67 -> 616 | Q64: ='Statement Q'!J67 -> 620 | S64: =Q64 -> 620
B65: Additional paid-in capital | C65: ='Statement Y'!C68 -> 579599 | D65: ='Statement Y'!D68 -> 860657 | E65: ='Statement Y'!E68 -> 926957 | F65: ='Statement Y'!F68 -> 1039361 | G65: ='Statement Y'!G68 -> 1111274 | H65: ='Statement Y'!H68 -> 1181679 | J65: ='Statement Q'!C68 -> 0 | K65: ='Statement Q'!D68 -> 0 | L65: ='Statement Q'!E68 -> 0 | M65: ='Statement Q'!F68 -> 0 | N65: ='Statement Q'!G68 -> 1132124 | O65: ='Statement Q'!H68 -> 1147540 | P65: ='Statement Q'!I68 -> 1166078 | Q65: ='Statement Q'!J68 -> 1181679 | S65: =Q65 -> 1181679
B66: Retained earnings | C66: ='Statement Y'!C69 -> -311777 | D66: ='Statement Y'!D69 -> -429938 | E66: ='Statement Y'!E69 -> -606084 | F66: ='Statement Y'!F69 -> -742969 | G66: ='Statement Y'!G69 -> -801496 | H66: ='Statement Y'!H69 -> -799190 | J66: ='Statement Q'!C69 -> 0 | K66: ='Statement Q'!D69 -> 0 | L66: ='Statement Q'!E69 -> 0 | M66: ='Statement Q'!F69 -> 0 | N66: ='Statement Q'!G69 -> -805410 | O66: ='Statement Q'!H69 -> -804756 | P66: ='Statement Q'!I69 -> -800485 | Q66: ='Statement Q'!J69 -> -799190 | S66: =Q66 -> -799190
B67: Treasury stock par value | C67: ='Statement Y'!C71 -> -4965 | D67: ='Statement Y'!D71 -> -13960 | E67: ='Statement Y'!E71 -> -33596 | F67: ='Statement Y'!F71 -> -45520 | G67: ='Statement Y'!G71 -> -45520 | H67: ='Statement Y'!H71 -> -45520 | J67: ='Statement Q'!C71 -> 0 | K67: ='Statement Q'!D71 -> 0 | L67: ='Statement Q'!E71 -> 0 | M67: ='Statement Q'!F71 -> 0 | N67: ='Statement Q'!G71 -> -45520 | O67: ='Statement Q'!H71 -> -45520 | P67: ='Statement Q'!I71 -> -45520 | Q67: ='Statement Q'!J71 -> -45520 | S67: =Q67 -> -45520
...

Sheet Forecast ->
B13: Forecast ->

Sheet Revenue
B1: Revenue forecast
C2: History | H2: Forecast | S2: History | AA2: Forecast | AE2: TTM
C4: Revenues | S4: Revenues | AE4: Q2-Q3-Q4
B5: Revenues (million) | C5: ='Statement Y'!D3 -> 2022 | D5: ='Statement Y'!E3 -> 2023 | E5: ='Statement Y'!F3 -> 2024 | F5: ='Statement Y'!G3 -> 2025 | G5: ='Statement Y'!H3 -> 2026 | H5: =G5+1 -> 2027 | I5: =H5+1 -> 2028 | J5: =I5+1 -> 2029 | K5: =J5+1 -> 2030 | L5: =K5+1 -> 2031 | R5: Revenues (thousand) | S5: ='Statement Q'!C3 -> Q1 2025 | T5: ='Statement Q'!D3 -> Q2 2025 | U5: ='Statement Q'!E3 -> Q3 2025 | V5: ='Statement Q'!F3 -> Q4 2025 | W5: ='Statement Q'!G3 -> Q1 2026 | X5: ='Statement Q'!H3 -> Q2 2026 | Y5: ='Statement Q'!I3 -> Q3 2026 | Z5: ='Statement Q'!J3 -> Q4 2026 | AA5: FQ1 | AB5: FQ2 | AC5: FQ3 | AE5: FQ1
B6: ='Statement Y'!B182 -> Subscription and related services | C6: ='Statement Y'!D182 -> 95514 | D6: ='Statement Y'!E182 -> 128975 | E6: ='Statement Y'!F182 -> 165436 | F6: ='Statement Y'!G182 -> 196510 | G6: ='Statement Y'!H182 -> 219461 | H6: =H24*H26 -> 236161.98 | I6: =I24*I26 -> 255285.2 | J6: =J24*J26 -> 274214.6 | K6: =K24*K26 -> 304652.42 | L6: =L24*L26 -> 346328.87 | N6: AHSC * avg sub revenue per AHSC | Q6: AHSC * avg sub revenue per AHSC | R6: ='Statement Q'!B172 -> Subscription and related services | S6: ='Statement Q'!C172 -> 46742 | T6: ='Statement Q'!D172 -> 48612 | U6: ='Statement Q'!E172 -> 49363 | V6: ='Statement Q'!F172 -> 51793 | W6: ='Statement Q'!G172 -> 54355 | X6: ='Statement Q'!H172 -> 53702 | Y6: ='Statement Q'!I172 -> 55480 | Z6: ='Statement Q'!J172 -> 55924 | AA6: =AA24*AA26 -> 57025.703 | AE6: =SUM(X6:AA6) -> 222131.7
B7: ='Statement Y'!B183 -> Payment solutions | C7: ='Statement Y'!D183 -> 65201 | D7: ='Statement Y'!E183 -> 78368 | E7: ='Statement Y'!F183 -> 94610 | F7: ='Statement Y'!G183 -> 101740 | G7: ='Statement Y'!H183 -> 121459 | H7: =H20*H22*H23 -> 132935.44 | I7: =I20*I22*I23 -> 139763.93 | J7: =J20*J22*J23 -> 148905.4 | K7: =K20*K22*K23 -> 159800.92 | L7: =L20*L22*L23 -> 171621.91 | N7: pacient payment volume * facilitator * take rate | Q7: pacient payment volume * facilitator * take rate | R7: ='Statement Q'!B173 -> Payment solutions | S7: ='Statement Q'!C173 -> 27060 | T7: ='Statement Q'!D173 -> 25300 | U7: ='Statement Q'!E173 -> 24704 | V7: ='Statement Q'!F173 -> 24676 | W7: ='Statement Q'!G173 -> 29925 | X7: ='Statement Q'!H173 -> 28392 | Y7: ='Statement Q'!I173 -> 27422 | Z7: ='Statement Q'!J173 -> 35720 | AA7: =AA20*AA22*AA23 -> 44008.92 | AE7: =SUM(X7:AA7) -> 135542.92
B8: ='Statement Y'!B184 -> Network solutions | C8: ='Statement Y'!D184 -> 52518 | D8: ='Statement Y'!E184 -> 73567 | E8: ='Statement Y'!F184 -> 96253 | F8: ='Statement Y'!G184 -> 121563 | G8: ='Statement Y'!H184 -> 139671 | H8: =H28*H32 -> 142906.53 | I8: =I28*I32 -> 149029.79 | J8: =J28*J32 -> 168084.37 | K8: =K28*K32 -> 205674.75 | L8: =L28*L32 -> 268479.6 | N8: annual patient visits * revenue per visit | Q8: network solutions per AHSC * AHSC | R8: ='Statement Q'!B174 -> Network solutions | S8: ='Statement Q'!C174 -> 27415 | T8: ='Statement Q'!D174 -> 28203 | U8: ='Statement Q'!E174 -> 32733 | V8: ='Statement Q'!F174 -> 33212 | W8: ='Statement Q'!G174 -> 31656 | X8: ='Statement Q'!H174 -> 35161 | Y8: ='Statement Q'!I174 -> 37431 | Z8: ='Statement Q'!J174 -> 35423 | AA8: =AA24*AA28 -> 35391.119 | AE8: =SUM(X8:AA8) -> 143406.12
B9: Total | C9: ='Statement Y'!D5 -> 213233 | D9: ='Statement Y'!E5 -> 280910 | E9: ='Statement Y'!F5 -> 356299 | F9: ='Statement Y'!G5 -> 419813 | G9: ='Statement Y'!H5 -> 480591 | H9: =SUM(H6:H8) -> 512003.95 | I9: =SUM(I6:I8) -> 544078.91 | J9: =SUM(J6:J8) -> 591204.37 | K9: =SUM(K6:K8) -> 670128.09 | L9: =SUM(L6:L8) -> 786430.37 | N9: annual patient visits = ahsc * visit per ahsc | R9: Total | S9: ='Statement Q'!C5 -> 101217 | T9: ='Statement Q'!D5 -> 102115 | U9: ='Statement Q'!E5 -> 106800 | V9: ='Statement Q'!F5 -> 109681 | W9: ='Statement Q'!G5 -> 115936 | X9: ='Statement Q'!H5 -> 117255 | Y9: ='Statement Q'!I5 -> 120333 | Z9: ='Statement Q'!J5 -> 127067 | AA9: =SUM(AA6:AA8) -> 136425.74 | AE9: =SUM(X9:AA9) -> 501080.74
C11: Growth rates | S11: Growth rates
B12: Revenue growth % | C12: =C5 -> 2022 | D12: =D5 -> 2023 | E12: =E5 -> 2024 | F12: =F5 -> 2025 | G12: =G5 -> 2026 | H12: =H5 -> 2027 | I12: =I5 -> 2028 | J12: =J5 -> 2029 | ... L12: =L5 -> 2031 | R12: Revenue growth % | S12: =S5 -> Q1 2025 | T12: =T5 -> Q2 2025 | U12: =U5 -> Q3 2025 | V12: =V5 -> Q4 2025 | W12: =W5 -> Q1 2026 | X12: =X5 -> Q2 2026 | Y12: =Y5 -> Q3 2026 | Z12: =Z5 -> Q4 2026 | ... AC12: =AC5 -> FQ3
B13: =B6 -> Subscription and related services | D13: =D6/C6-1 -> 0.35032561 | E13: =E6/D6-1 -> 0.2826982 | F13: =F6/E6-1 -> 0.18783094 | G13: =G6/F6-1 -> 0.11679304 | H13: =H6/G6-1 -> 0.0761 | I13: =I6/H6-1 -> 0.080975 | J13: =J6/I6-1 -> 0.07415 | K13: =K6/J6-1 -> 0.111 | L13: =L6/K6-1 -> 0.1368 | R13: =R6 -> Subscription and related services | T13: =T6/S6-1 -> 0.040006846 | U13: =U6/T6-1 -> 0.01544886 | V13: =V6/U6-1 -> 0.049227154 | W13: =W6/V6-1 -> 0.049466144 | X13: =X6/W6-1 -> -0.012013614 | Y13: =Y6/X6-1 -> 0.033108637 | Z13: =Z6/Y6-1 -> 0.0080028839 | AA13: =AA6/Z6-1 -> 0.0197
B14: =B7 -> Payment solutions | D14: =D7/C7-1 -> 0.20194476 | E14: =E7/D7-1 -> 0.20725296 | F14: =F7/E7-1 -> 0.075362012 | G14: =G7/F7-1 -> 0.19381757 | H14: =H7/G7-1 -> 0.094488181 | I14: =I7/H7-1 -> 0.051366935 | J14: =J7/I7-1 -> 0.065406556 | K14: =K7/J7-1 -> 0.073170732 | L14: =L7/K7-1 -> 0.073973214 | R14: =R7 -> Payment solutions | T14: =T7/S7-1 -> -0.06504065 | U14: =U7/T7-1 -> -0.023557312 | V14: =V7/U7-1 -> -0.0011334197 | W14: =W7/V7-1 -> 0.21271681 | X14: =X7/W7-1 -> -0.05122807 | Y14: =Y7/X7-1 -> -0.034164553 | Z14: =Z7/Y7-1 -> 0.30260375 | AA14: =AA7/Z7-1 -> 0.23205263
B15: =B8 -> Network solutions | D15: =D8/C8-1 -> 0.40079592 | E15: =E8/D8-1 -> 0.30837196 | F15: =F8/E8-1 -> 0.26295284 | G15: =G8/F8-1 -> 0.1489598 | H15: =H8/G8-1 -> 0.023165375 | I15: =I8/H8-1 -> 0.042848 | J15: =J8/I8-1 -> 0.1278575 | K15: =K8/J8-1 -> 0.22364 | L15: =L8/K8-1 -> 0.30536 | R15: =R8 -> Network solutions | T15: =T8/S8-1 -> 0.028743389 | U15: =U8/T8-1 -> 0.16062121 | V15: =V8/U8-1 -> 0.01463355 | W15: =W8/V8-1 -> -0.046850536 | X15: =X8/W8-1 -> 0.11072151 | Y15: =Y8/X8-1 -> 0.064560166 | Z15: =Z8/Y8-1 -> -0.053645374 | AA15: =AA8/Z8-1 -> -0.0009
B16: Total | D16: =D9/C9-1 -> 0.31738521 | E16: =E9/D9-1 -> 0.26837421 | F16: =F9/E9-1 -> 0.17826039 | G16: =G9/F9-1 -> 0.14477398 | H16: =H9/G9-1 -> 0.065363174 | I16: =I9/H9-1 -> 0.062645926 | J16: =J9/I9-1 -> 0.086615102 | K16: =K9/J9-1 -> 0.13349652 | L16: =L9/K9-1 -> 0.17355231 | R16: Total | T16: =T9/S9-1 -> 0.0088720274 | U16: =U9/T9-1 -> 0.045879645 | V16: =V9/U9-1 -> 0.026975655 | W16: =W9/V9-1 -> 0.057029021 | X16: =X9/W9-1 -> 0.011376967 | Y16: =Y9/X9-1 -> 0.02625048 | Z16: =Z9/Y9-1 -> 0.055961374 | AA16: =AA9/Z9-1 -> 0.073652027
C18: Revenue drivers | S18: Growth rates
C19: =C12 -> 2022 | D19: =D12 -> 2023 | E19: =E12 -> 2024 | F19: =F12 -> 2025 | G19: =G12 -> 2026 | H19: =H12 -> 2027 | I19: =I12 -> 2028 | J19: =J12 -> 2029 | ... L19: =L12 -> 2031 | S19: =S12 -> Q1 2025 | T19: =T12 -> Q2 2025 | U19: =U12 -> Q3 2025 | V19: =V12 -> Q4 2025 | W19: =W12 -> Q1 2026 | X19: =X12 -> Q2 2026 | Y19: =Y12 -> Q3 2026 | Z19: =Z12 -> Q4 2026 | ... AC19: =AC12 -> FQ3
B20: ='Statement Y'!B175 -> Patient payment volume | C20: ='Statement Y'!D175 -> 2768000 | D20: ='Statement Y'!E175 -> 3284000 | E20: ='Statement Y'!F175 -> 3947000 | F20: ='Statement Y'!G175 -> 4420000 | G20: ='Statement Y'!H175 -> 4873000 | H20: =G20*(1+H21) -> 5360300 | I20: =H20*(1+I21) -> 5949933 | J20: =I20*(1+J21) -> 6485427 | K20: =J20*(1+K21) -> 7133969.7 | L20: =K20*(1+L21) -> 7847366.6 | R20: ='Statement Q'!B165 -> Patient payment volume | S20: ='Statement Q'!C165 -> 1166000 | T20: ='Statement Q'!D165 -> 1093000 | U20: ='Statement Q'!E165 -> 1081000 | V20: ='Statement Q'!F165 -> 1080000 | W20: ='Statement Q'!G165 -> 1314000 | X20: ='Statement Q'!H165 -> 1250000 | Y20: ='Statement Q'!I165 -> 1181000 | Z20: ='Statement Q'!J165 -> 1128000 | AA20: =Z20*(1+AA21) -> 1150560 | AE20: =SUM(X20:AA20) -> 4709560
B21: Patient payment volume growth | D21: =(D20-C20)/C20 -> 0.18641618 | E21: =(E20-D20)/D20 -> 0.20188794 | F21: =(F20-E20)/E20 -> 0.11983785 | G21: =(G20-F20)/F20 -> 0.10248869 | H21: 0.1 | I21: 0.11 | J21: 0.09 | K21: 0.1 | L21: 0.1 | R21: Patient payment volume growth | T21: =(T20-S20)/S20 -> -0.062607204 | U21: =(U20-T20)/T20 -> -0.010978957 | V21: =(V20-U20)/U20 -> -0.00092506938 | W21: =(W20-V20)/V20 -> 0.21666667 | X21: =(X20-W20)/W20 -> -0.04870624 | Y21: =(Y20-X20)/X20 -> -0.0552 | Z21: =(Z20-Y20)/Y20 -> -0.044877223 | AA21: 0.02
B22: ='Statement Y'!B176 -> Payment facilitator volume | C22: ='Statement Y'!D176 -> 0.79 | D22: ='Statement Y'!E176 -> 0.8 | E22: ='Statement Y'!F176 -> 0.82 | F22: ='Statement Y'!G176 -> 0.81 | G22: ='Statement Y'!H176 -> 0.83 | H22: 0.8 | I22: 0.81 | J22: 0.82 | K22: 0.8 | L22: 0.81 | R22: ='Statement Q'!B166 -> Payment facilitator volume | S22: ='Statement Q'!C166 -> 0.81 | T22: ='Statement Q'!D166 -> 0.81 | U22: ='Statement Q'!E166 -> 0.81 | V22: ='Statement Q'!F166 -> 0.82 | W22: ='Statement Q'!G166 -> 0.82 | X22: ='Statement Q'!H166 -> 0.82 | Y22: ='Statement Q'!I166 -> 0.85 | Z22: ='Statement Q'!J166 -> 0.84 | AA22: 0.85
B23: ='Statement Y'!B177 -> Take rate | C23: ='Statement Y'!D177 -> 0.0298 | D23: ='Statement Y'!E177 -> 0.0298 | E23: ='Statement Y'!F177 -> 0.0292 | F23: ='Statement Y'!G177 -> 0.0283 | G23: ='Statement Y'!H177 -> 0.030029991 | H23: 0.031 | I23: 0.029 | J23: 0.028 | K23: 0.028 | L23: 0.027 | R23: ='Statement Q'!B167 -> Take rate | S23: ='Statement Q'!C167 -> 0.029 | T23: ='Statement Q'!D167 -> 0.029 | U23: ='Statement Q'!E167 -> 0.028 | V23: ='Statement Q'!F167 -> 0.028 | W23: ='Statement Q'!G167 -> 0.028 | X23: ='Statement Q'!H167 -> 0.028 | Y23: ='Statement Q'!I167 -> 0.027 | Z23: ='Statement Q'!J167 -> 0.037698413 | AA23: 0.045
B24: ='Statement Y'!B173 -> AHSC | C24: ='Statement Y'!D173 -> 2074 | D24: ='Statement Y'!E173 -> 2856 | E24: ='Statement Y'!F173 -> 3601 | F24: ='Statement Y'!G173 -> 4203 | G24: ='Statement Y'!H173 -> 4514 | H24: =G24*(1+H25) -> 4762.27 | I24: =H24*(1+I25) -> 5071.8175 | J24: =I24*(1+J25) -> 5502.922 | K24: =J24*(1+K25) -> 6053.2142 | L24: =K24*(1+L25) -> 6779.6 | R24: ='Statement Q'!B163 -> AHSC | S24: ='Statement Q'!C163 -> 4065 | T24: ='Statement Q'!D163 -> 4169 | U24: ='Statement Q'!E163 -> 4237 | V24: ='Statement Q'!F163 -> 4341 | W24: ='Statement Q'!G163 -> 4411 | X24: ='Statement Q'!H163 -> 4467 | Y24: ='Statement Q'!I163 -> 4520 | Z24: ='Statement Q'!J163 -> 4658 | AA24: =Z24*(1+AA25) -> 4797.74 | AE24: =AVERAGE(X24:AA24) -> 4610.685
B25: AHSC Growth | D25: =(D24-C24)/C24 -> 0.37704918 | E25: =(E24-D24)/D24 -> 0.26085434 | F25: =(F24-E24)/E24 -> 0.16717578 | G25: =(G24-F24)/F24 -> 0.073994766 | H25: 0.055 | I25: 0.065 | J25: 0.085 | K25: 0.1 | L25: 0.12 | R25: AHSC Growth | T25: =(T24-S24)/S24 -> 0.025584256 | U25: =(U24-T24)/T24 -> 0.016310866 | V25: =(V24-U24)/U24 -> 0.024545669 | W25: =(W24-V24)/V24 -> 0.016125317 | X25: =(X24-W24)/W24 -> 0.012695534 | Y25: =(Y24-X24)/X24 -> 0.011864786 | Z25: =(Z24-Y24)/Y24 -> 0.030530973 | AA25: 0.03
B26: ='Statement Y'!B174 -> Avg subscription revenue per AHSC | C26: ='Statement Y'!D174 -> 46.053038 | D26: ='Statement Y'!E174 -> 45.159314 | E26: ='Statement Y'!F174 -> 45.941683 | F26: ='Statement Y'!G174 -> 46.754699 | G26: ='Statement Y'!H174 -> 48.617856 | H26: =G26*(1+H27) -> 49.590213 | I26: =H26*(1+I27) -> 50.334066 | J26: =I26*(1+J27) -> 49.830725 | K26: =J26*(1+K27) -> 50.329032 | L26: =K26*(1+L27) -> 51.083968 | R26: ='Statement Q'!B164 -> Avg subscription revenue per AHSC | S26: ='Statement Q'!C164 -> 11.498647 | T26: ='Statement Q'!D164 -> 11.66035 | U26: ='Statement Q'!E164 -> 11.65046 | V26: ='Statement Q'!F164 -> 11.931122 | W26: ='Statement Q'!G164 -> 12.322603 | X26: ='Statement Q'!H164 -> 12.021939 | Y26: ='Statement Q'!I164 -> 12.274336 | Z26: ='Statement Q'!J164 -> 12.006011 | AA26: =Z26*(1+AA27) -> 11.885951 | AE26: =SUM(X26:AA26) -> 48.188237
B27: Avg revenue AHSC growth | D27: =(D26-C26)/C26 -> -0.019406405 | E27: =(E26-D26)/D26 -> 0.017324646 | F27: =(F26-E26)/E26 -> 0.0176967 | G27: =(G26-F26)/F26 -> 0.03984961 | H27: 0.02 | I27: 0.015 | J27: -0.01 | K27: 0.01 | L27: 0.015 | R27: Avg revenue AHSC growth | T27: =(T26-S26)/S26 -> 0.014062804 | U27: =(U26-T26)/T26 -> -0.00084817115 | V27: =(V26-U26)/U26 -> 0.024090175 | W27: =(W26-V26)/V26 -> 0.032811728 | X27: =(X26-W26)/W26 -> -0.024399385 | Y27: =(Y26-X26)/X26 -> 0.020994752 | Z27: =(Z26-Y26)/Y26 -> -0.021860662 | AA27: -0.01
B28: ='Statement Y'!B178 -> Annual patient visits | D28: ='Statement Y'!E178 -> 120000 | E28: ='Statement Y'!F178 -> 150000 | F28: ='Statement Y'!G178 -> 170000 | G28: ='Statement Y'!H178 -> 180000 | H28: =H24*H30 -> 183253.5 | I28: =I24*I30 -> 187358.38 | J28: =J24*J30 -> 201251 | K28: =K24*K30 -> 228017.39 | L28: =L24*L30 -> 268148.45 | R28: ='Statement Q'!B168 -> Network solutions revenue per AHSC | S28: ='Statement Q'!C168 -> 6.7441574 | T28: ='Statement Q'!D168 -> 6.7649316 | U28: ='Statement Q'!E168 -> 7.7255133 | V28: ='Statement Q'!F168 -> 7.6507717 | W28: ='Statement Q'!G168 -> 7.1766039 | X28: ='Statement Q'!H168 -> 7.8712783 | Y28: ='Statement Q'!I168 -> 8.2811947 | Z28: ='Statement Q'!J168 -> 7.604766 | AA28: =Z28*(1+AA29) -> 7.376623 | AE28: =SUM(X28:AA28) -> 31.133862
B29: Annual patient visits growth | E29: =(E28-D28)/D28 -> 0.25 | F29: =(F28-E28)/E28 -> 0.13333333 | G29: =(G28-F28)/F28 -> 0.058823529 | H29: =(H28-G28)/G28 -> 0.018075 | I29: =(I28-H28)/H28 -> 0.0224 | J29: =(J28-I28)/I28 -> 0.07415 | K29: =(K28-J28)/J28 -> 0.133 | L29: =(L28-K28)/K28 -> 0.176 | R29: Nw solutions revenue growth | T29: =(T28-S28)/S28 -> 0.003080325 | U29: =(U28-T28)/T28 -> 0.14199429 | V29: =(V28-U28)/U28 -> -0.0096746482 | W29: =(W28-V28)/V28 -> -0.061976463 | X29: =(X28-W28)/W28 -> 0.096797082 | Y29: =(Y28-X28)/X28 -> 0.052077492 | Z29: =(Z28-Y28)/Y28 -> -0.081682501 | AA29: -0.03
B30: ='Statement Y'!B188 -> Patient visit per AHSC | D30: ='Statement Y'!E188 -> 42.016807 | E30: ='Statement Y'!F188 -> 41.655096 | F30: ='Statement Y'!G188 -> 40.4473 | G30: ='Statement Y'!H188 -> 39.875942 | H30: =G30*(1+H31) -> 38.480284 | I30: =H30*(1+I31) -> 36.941072 | J30: =I30*(1+J31) -> 36.571661 | K30: =J30*(1+K31) -> 37.668811 | L30: =K30*(1+L31) -> 39.552252
B31: Patient visit per AHSC growth | E31: =(E30-D30)/D30 -> -0.0086087198 | F31: =(F30-E30)/E30 -> -0.028995162 | G31: =(G30-F30)/F30 -> -0.014125987 | H31: -0.035 | I31: -0.04 | J31: -0.01 | K31: 0.03 | L31: 0.05
B32: ='Statement Y'!B189 -> Revenue per visit | D32: ='Statement Y'!E189 -> 0.61305833 | E32: ='Statement Y'!F189 -> 0.64168667 | F32: ='Statement Y'!G189 -> 0.71507647 | G32: ='Statement Y'!H189 -> 0.77595 | H32: =G32*(1+H33) -> 0.77982975 | I32: =H32*(1+I33) -> 0.79542634 | J32: =I32*(1+J33) -> 0.83519766 | K32: =J32*(1+K33) -> 0.90201348 | L32: =K32*(1+L33) -> 1.001235
B33: Revenue per visit growth | E33: =(E32-D32)/D32 -> 0.046697568 | F33: =(F32-E32)/E32 -> 0.11437016 | G33: =(G32-F32)/F32 -> 0.085128699 | H33: 0.005 | I33: 0.02 | J33: 0.05 | K33: 0.08 | L33: 0.11

Sheet COGS & OpEx
B1: COGS & OpEx forecast
C2: History | H2: Forecast | P2: History | X2: Forecast | AB2: TTM
C4: Revenues | P4: Revenues | AB4: =Revenue!AE4 -> Q2-Q3-Q4
B5: Revenues (million) | C5: =Revenue!C5 -> 2022 | D5: =Revenue!D5 -> 2023 | E5: =Revenue!E5 -> 2024 | F5: =Revenue!F5 -> 2025 | G5: =Revenue!G5 -> 2026 | H5: =Revenue!H5 -> 2027 | I5: =Revenue!I5 -> 2028 | J5: =Revenue!J5 -> 2029 | ... L5: =Revenue!L5 -> 2031 | O5: Revenues (thousand) | P5: =Revenue!S5 -> Q1 2025 | Q5: =Revenue!T5 -> Q2 2025 | R5: =Revenue!U5 -> Q3 2025 | S5: =Revenue!V5 -> Q4 2025 | T5: =Revenue!W5 -> Q1 2026 | U5: =Revenue!X5 -> Q2 2026 | V5: =Revenue!Y5 -> Q3 2026 | W5: =Revenue!Z5 -> Q4 2026 | X5: FQ1 | Y5: FQ2 | Z5: FQ3 | AB5: =Revenue!AE5 -> FQ1
B6: Revenue | C6: =Revenue!C9 -> 213233 | D6: =Revenue!D9 -> 280910 | E6: =Revenue!E9 -> 356299 | F6: =Revenue!F9 -> 419813 | G6: =Revenue!G9 -> 480591 | H6: =Revenue!H9 -> 512003.95 | I6: =Revenue!I9 -> 544078.91 | J6: =Revenue!J9 -> 591204.37 | ... L6: =Revenue!L9 -> 786430.37 | O6: Revenue | P6: =Revenue!S9 -> 101217 | Q6: =Revenue!T9 -> 102115 | R6: =Revenue!U9 -> 106800 | S6: =Revenue!V9 -> 109681 | T6: =Revenue!W9 -> 115936 | U6: =Revenue!X9 -> 117255 | V6: =Revenue!Y9 -> 120333 | W6: =Revenue!Z9 -> 127067 | X6: =Revenue!AA9 -> 136425.74 | Y6: =[2]Revenue!AB11 -> 0 | Z6: =[2]Revenue!AC11 -> 0 | AB6: =SUM(U6:X6) -> 501080.74
C9: COGS and OpEx | P9: COGS & OpEx | AB9: =AB4 -> Q2-Q3-Q4
B10: Expenses (million) | C10: =C5 -> 2022 | D10: =D5 -> 2023 | E10: =E5 -> 2024 | F10: =F5 -> 2025 | G10: =G5 -> 2026 | H10: =H5 -> 2027 | I10: =I5 -> 2028 | J10: =J5 -> 2029 | ... L10: =L5 -> 2031 | O10: Expenses (thousand) | P10: =P5 -> Q1 2025 | Q10: =Q5 -> Q2 2025 | R10: =R5 -> Q3 2025 | S10: =S5 -> Q4 2025 | T10: =T5 -> Q1 2026 | U10: =U5 -> Q2 2026 | V10: =V5 -> Q3 2026 | W10: =W5 -> Q4 2026 | ... Z10: =Z5 -> FQ3 | AB10: =AB5 -> FQ1
B11: COGS | C11: ='Statement Y'!D6 -> 81388 | D11: ='Statement Y'!E6 -> 109267 | E11: ='Statement Y'!F6 -> 124011 | F11: ='Statement Y'!G6 -> 134934 | G11: ='Statement Y'!H6 -> 154123 | H11: =H22*H$6 -> 158721.23 | I11: =I22*I$6 -> 157782.89 | J11: =J22*J$6 -> 165537.22 | K11: =K22*K$6 -> 187635.87 | L11: =L22*L$6 -> 228064.81 | O11: COGS | P11: ='Statement Q'!C6 -> 34020 | Q11: ='Statement Q'!D6 -> 32811 | R11: ='Statement Q'!E6 -> 34537 | S11: ='Statement Q'!F6 -> 33566 | T11: ='Statement Q'!G6 -> 38065 | U11: ='Statement Q'!H6 -> 37641 | V11: ='Statement Q'!I6 -> 38027 | W11: ='Statement Q'!J6 -> 40390 | X11: =X22*X$6 -> 43656.237 | AB11: =SUM(U11:X11) -> 159714.24
B12: ='Statement Y'!B8 -> Sales and marketing | C12: ='Statement Y'!D8 -> 106421 | D12: ='Statement Y'!E8 -> 151263 | E12: ='Statement Y'!F8 -> 147008 | F12: ='Statement Y'!G8 -> 121129 | G12: ='Statement Y'!H8 -> 100243 | H12: =H23*H$6 -> 107520.83 | I12: =I23*I$6 -> 119697.36 | J12: =J23*J$6 -> 124152.92 | K12: =K23*K$6 -> 134025.62 | L12: =L23*L$6 -> 157286.07 | O12: ='Statement Q'!B8 -> Sales and marketing | P12: ='Statement Q'!C8 -> 32011 | Q12: ='Statement Q'!D8 -> 30184 | R12: ='Statement Q'!E8 -> 30071 | S12: ='Statement Q'!F8 -> 28863 | T12: ='Statement Q'!G8 -> 26043 | U12: ='Statement Q'!H8 -> 25396 | V12: ='Statement Q'!I8 -> 24148 | W12: ='Statement Q'!J8 -> 24656 | X12: =X23*X$6 -> 25920.891 | AB12: =SUM(U12:X12) -> 100120.89
B13: ='Statement Y'!B9 -> R&D | C13: ='Statement Y'!D9 -> 52265 | D13: ='Statement Y'!E9 -> 91244 | E13: ='Statement Y'!F9 -> 112346 | F13: ='Statement Y'!G9 -> 117364 | G13: ='Statement Y'!H9 -> 121481 | H13: =H24*H$6 -> 133121.03 | I13: =I24*I$6 -> 141460.52 | J13: =J24*J$6 -> 147801.09 | K13: =K24*K$6 -> 147428.18 | L13: =L24*L$6 -> 165150.38 | O13: ='Statement Q'!B9 -> R&D | P13: ='Statement Q'!C9 -> 28881 | Q13: ='Statement Q'!D9 -> 29542 | R13: ='Statement Q'!E9 -> 29315 | S13: ='Statement Q'!F9 -> 29626 | T13: ='Statement Q'!G9 -> 31829 | U13: ='Statement Q'!H9 -> 29274 | V13: ='Statement Q'!I9 -> 29453 | W13: ='Statement Q'!J9 -> 30925 | X13: =X24*X$6 -> 32742.178 | AB13: =SUM(U13:X13) -> 122394.18
B14: ='Statement Y'!B10 -> General and administrative | C14: ='Statement Y'!D10 -> 68674 | D14: ='Statement Y'!E10 -> 80384 | E14: ='Statement Y'!F10 -> 79926 | F14: ='Statement Y'!G10 -> 76597 | G14: ='Statement Y'!H10 -> 79903 | H14: =H25*H$6 -> 79360.613 | I14: =I25*I$6 -> 89228.942 | J14: =J25*J$6 -> 94592.699 | K14: =K25*K$6 -> 113921.78 | L14: =L25*L$6 -> 125828.86 | O14: ='Statement Q'!B10 -> General and administrative | P14: ='Statement Q'!C10 -> 19052 | Q14: ='Statement Q'!D10 -> 19497 | R14: ='Statement Q'!E10 -> 19633 | S14: ='Statement Q'!F10 -> 18415 | T14: ='Statement Q'!G10 -> 16408 | U14: ='Statement Q'!H10 -> 19042 | V14: ='Statement Q'!I10 -> 17488 | W14: ='Statement Q'!J10 -> 26965 | X14: =X25*X$6 -> 25920.891 | AB14: =SUM(U14:X14) -> 89415.891
B15: ='Statement Y'!B11 -> Depreciation | C15: ='Statement Y'!D11 -> 14985 | D15: ='Statement Y'!E11 -> 17988 | E15: ='Statement Y'!F11 -> 17584 | F15: ='Statement Y'!G11 -> 14183 | G15: ='Statement Y'!H11 -> 12972 | H15: =H26*H$6 -> 12288.095 | I15: =I26*I$6 -> 13601.973 | J15: =J26*J$6 -> 13597.7 | K15: =K26*K$6 -> 13402.562 | L15: =L26*L$6 -> 13369.316 | O15: ='Statement Q'!B11 -> Depreciation | P15: ='Statement Q'!C11 -> 3524 | Q15: ='Statement Q'!D11 -> 3921 | R15: ='Statement Q'!E11 -> 3566 | S15: ='Statement Q'!F11 -> 3172 | T15: ='Statement Q'!G11 -> 2986 | U15: ='Statement Q'!H11 -> 3279 | V15: ='Statement Q'!I11 -> 3199 | W15: ='Statement Q'!J11 -> 3508 | X15: =X26*X$6 -> 4092.7723 | AB15: =SUM(U15:X15) -> 14078.772
B16: ='Statement Y'!B12 -> Amortization | C16: ='Statement Y'!D12 -> 6317 | D16: ='Statement Y'!E12 -> 7316 | E16: ='Statement Y'!F12 -> 11903 | F16: ='Statement Y'!G12 -> 13703 | G16: ='Statement Y'!H12 -> 18481 | H16: =H27*H$6 -> 20480.158 | I16: =I27*I$6 -> 20674.999 | J16: =J27*J$6 -> 18918.54 | K16: =K27*K$6 -> 17423.33 | L16: =L27*L$6 -> 17301.468 | O16: ='Statement Q'!B12 -> Amortization | P16: ='Statement Q'!C12 -> 3149 | Q16: ='Statement Q'!D12 -> 3382 | R16: ='Statement Q'!E12 -> 3521 | S16: ='Statement Q'!F12 -> 3651 | T16: ='Statement Q'!G12 -> 3892 | U16: ='Statement Q'!H12 -> 4130 | V16: ='Statement Q'!I12 -> 4279 | W16: ='Statement Q'!J12 -> 6180 | X16: =X27*X$6 -> 6821.2871 | AB16: =SUM(U16:X16) -> 21410.287
B17: OpEx | C17: ='Statement Y'!D13 -> 248662 | D17: ='Statement Y'!E13 -> 348195 | E17: ='Statement Y'!F13 -> 368767 | F17: ='Statement Y'!G13 -> 342976 | G17: ='Statement Y'!H13 -> 333080 | H17: =SUM(H12:H16) -> 352770.72 | I17: =SUM(I12:I16) -> 384663.79 | J17: =SUM(J12:J16) -> 399062.95 | K17: =SUM(K12:K16) -> 426201.47 | L17: =SUM(L12:L16) -> 478936.1 | O17: OpEx | P17: ='Statement Q'!C13 -> 86617 | Q17: ='Statement Q'!D13 -> 86526 | R17: ='Statement Q'!E13 -> 86106 | S17: ='Statement Q'!F13 -> 83727 | T17: ='Statement Q'!G13 -> 81158 | U17: ='Statement Q'!H13 -> 81121 | V17: ='Statement Q'!I13 -> 78567 | W17: ='Statement Q'!J13 -> 92234 | X17: =SUM(X12:X16) -> 95498.019 | AB17: =SUM(U17:X17) -> 347420.02
C20: Expenses % of Revenue | P20: Expenses % of Revenue
B21: % of revenue | C21: =C5 -> 2022 | D21: =D5 -> 2023 | E21: =E5 -> 2024 | F21: =F5 -> 2025 | G21: =G5 -> 2026 | H21: =H5 -> 2027 | I21: =I5 -> 2028 | J21: =J5 -> 2029 | ... L21: =L5 -> 2031 | O21: % of revenue | P21: =P5 -> Q1 2025 | Q21: =Q5 -> Q2 2025 | R21: =R5 -> Q3 2025 | S21: =S5 -> Q4 2025 | T21: =T5 -> Q1 2026 | U21: =U5 -> Q2 2026 | V21: =V5 -> Q3 2026 | W21: =W5 -> Q4 2026 | ... Z21: =Z5 -> FQ3
B22: =B11 -> COGS | C22: =C11/C$6 -> 0.38168576 | D22: =D11/D$6 -> 0.38897512 | E22: =E11/E$6 -> 0.34805318 | F22: =F11/F$6 -> 0.32141453 | G22: =G11/G$6 -> 0.32069473 | H22: 0.31 | I22: 0.29 | J22: 0.28 | K22: 0.28 | L22: 0.29 | O22: =O11 -> COGS | P22: =P11/P$6 -> 0.33610955 | Q22: =Q11/Q$6 -> 0.3213142 | R22: =R11/R$6 -> 0.32338015 | S22: =S11/S$6 -> 0.30603295 | T22: =T11/T$6 -> 0.3283277 | U22: =U11/U$6 -> 0.32101829 | V22: =V11/V$6 -> 0.31601473 | W22: =W11/W$6 -> 0.3178638 | X22: 0.32
B23: =B12 -> Sales and marketing | C23: =C12/C$6 -> 0.49908316 | D23: =D12/D$6 -> 0.53847496 | E23: =E12/E$6 -> 0.41259728 | F23: =F12/F$6 -> 0.28853085 | G23: =G12/G$6 -> 0.20858277 | H23: 0.21 | I23: 0.22 | J23: 0.21 | K23: 0.2 | L23: 0.2 | O23: =O12 -> Sales and marketing | P23: =P12/P$6 -> 0.3162611 | Q23: =Q12/Q$6 -> 0.29558831 | R23: =R12/R$6 -> 0.28156367 | S23: =S12/S$6 -> 0.26315406 | T23: =T12/T$6 -> 0.22463256 | U23: =U12/U$6 -> 0.21658778 | V23: =V12/V$6 -> 0.20067646 | W23: =W12/W$6 -> 0.19403937 | X23: 0.19
B24: =B13 -> R&D | C24: =C13/C$6 -> 0.24510746 | D24: =D13/D$6 -> 0.32481578 | E24: =E13/E$6 -> 0.31531382 | F24: =F13/F$6 -> 0.27956257 | G24: =G13/G$6 -> 0.25277419 | H24: 0.26 | I24: 0.26 | J24: 0.25 | K24: 0.22 | L24: 0.21 | O24: =O13 -> R&D | P24: =P13/P$6 -> 0.28533744 | Q24: =Q13/Q$6 -> 0.28930128 | R24: =R13/R$6 -> 0.27448502 | S24: =S13/S$6 -> 0.27011059 | T24: =T13/T$6 -> 0.2745394 | U24: =U13/U$6 -> 0.249661 | V24: =V13/V$6 -> 0.24476245 | W24: =W13/W$6 -> 0.24337554 | X24: 0.24
B25: =B14 -> General and administrative | C25: =C14/C$6 -> 0.32206084 | D25: =D14/D$6 -> 0.28615571 | E25: =E14/E$6 -> 0.22432283 | F25: =F14/F$6 -> 0.18245505 | G25: =G14/G$6 -> 0.16625988 | H25: 0.155 | I25: 0.164 | J25: 0.16 | K25: 0.17 | L25: 0.16 | O25: =O14 -> General and administrative | P25: =P14/P$6 -> 0.18822925 | Q25: =Q14/Q$6 -> 0.19093179 | R25: =R14/R$6 -> 0.18382959 | S25: =S14/S$6 -> 0.16789599 | T25: =T14/T$6 -> 0.14152636 | U25: =U14/U$6 -> 0.16239819 | V25: =V14/V$6 -> 0.14533004 | W25: =W14/W$6 -> 0.21221088 | X25: 0.19
B26: =B15 -> Depreciation | C26: =C15/C$6 -> 0.070275239 | D26: =D15/D$6 -> 0.064034744 | E26: =E15/E$6 -> 0.049351808 | F26: =F15/F$6 -> 0.03378409 | G26: =G15/G$6 -> 0.026991766 | H26: 0.024 | I26: 0.025 | J26: 0.023 | K26: 0.02 | L26: 0.017 | O26: =O15 -> Depreciation | P26: =P15/P$6 -> 0.034816286 | Q26: =Q15/Q$6 -> 0.038397885 | R26: =R15/R$6 -> 0.033389513 | S26: =S15/S$6 -> 0.028920232 | T26: =T15/T$6 -> 0.025755589 | U26: =U15/U$6 -> 0.027964692 | V26: =V15/V$6 -> 0.026584561 | W26: =W15/W$6 -> 0.027607483 | X26: 0.03
