Workbook

Sheet Overview
B2: Automatic Data | E2: At a glance | H2: Valuation | K2: Links
B3: Company | C3: #VALUE! | E3: Market capitalization | F3: =Statement!AC149 -> 7169450.9 | H3: ='AVG target price'!B5 -> DCF price | I3: ='AVG target price'!C5 -> 147.1741 | K3: Financials ->'!B13
B4: Ticker | C4: {=_FV(C3,"Ticker symbol",TRUE)} -> DUOL | E4: Enterprise value | F4: =Statement!AC150 -> 5752891.9 | H4: ='AVG target price'!B6 -> EV/EBIT price | I4: ='AVG target price'!C6 -> 198.02442 | K4: Analysis ->'!B13
B5: Price | C5: {=_FV(C3,"Price",TRUE)} -> 143.04 | E5: EPS | F5: =Statement!AC26 -> 3.1405969 | H5: ='AVG target price'!B7 -> PS price | I5: ='AVG target price'!C7 -> 159.74574 | K5: Forecast ->'!B13
B6: Price Extended Hours | C6: {=_FV(C3,"Price (Extended hours)",TRUE)} -> 142.69 | E6: PE | F6: =Statement!AC146 -> 45.545482 | H6: ='AVG target price'!B8 -> EV/FCFF price | I6: ='AVG target price'!C8 -> 203.55142 | K6: Valuation ->'!B13
B7: Day change | C7: {=_FV(C3,"Change")} -> 1.65 | E7: PS | F7: =Statement!AC147 -> 6.1427774 | H7: ='AVG target price'!B9 -> EV/Sales | I7: ='AVG target price'!C9 -> 203.9738
B8: Day change extended | C8: {=_FV(C3,"Change (extended hours)",TRUE)} -> -0.35 | E8: FCF Yield | F8: =Statement!AC157 -> 0.03526351 | H8: ='AVG target price'!B10 -> AVG price | I8: ='AVG target price'!C10 -> 182.4939
B9: Day change % | C9: {=_FV(C3,"Change (%)",TRUE)} -> 0.01167 | E9: Earnings Yield | F9: =Statement!AC158 -> 0.021956075 | H9: ='AVG target price'!B12 -> Upside/Downside | I9: ='AVG target price'!C12 -> 0.27582424
B10: Day change extended % | C10: {=_FV(C3,"Change % (extended hours)",TRUE)} -> -0.002447 | E10: Buyback Yield | F10: =Statement!AC160 -> 0.0097082749
B11: 52 week high | C11: {=_FV(C3,"52 week high",TRUE)} -> 322.09 | E11: Dividend Yield | F11: =Statement!AC159 -> 0 | H11: DDM price | I11: =DDM!C26 -> 0
B12: 52 week low | C12: {=_FV(C3,"52 week low",TRUE)} -> 87.89 | E12: ROA | F12: =Statement!AC123 -> 0.07428664
B13: Beta | C13: {=_FV(C3,"Beta")} -> 1.066 | E13: ROE | F13: =Statement!AC125 -> 0.10928737 | H13: Reverse DCF rate | I13: ='Reverse DCF'!C17 -> 0.29
B14: Avg volume | C14: {=_FV(C3,"Volume average",TRUE)} -> 930380 | E14: ROIC | F14: =Statement!AC136 -> -17.586668 | H14: Reverse DCF price | I14: ='Reverse DCF'!C16 -> 154.01938
E15: Net Cash/Market Cap | F15: =Statement!AC172 -> 0.19758264
E16: Net Cash/Share | F16: =Statement!AC171 -> 30.277412 | H16: Discount rates used
B17: Unit data and other info | E17: Insider Ownership | F17: =Statement!AC167 -> 0.1452057 | H17: WACC | I17: =DCF!C15 -> 0.0975
B18: Units | C18: K | E18: Net Trade Cycle | F18: =Statement!AC140 -> 22.829227 | H18: Cost of Equity | I18: =Multiples!C54 -> 0.0975
B19: Units conversion | C19: 1000 | E19: Net Debt/Equity | F19: =Statement!AC142 -> -1.0048356
B20: Has operating lease | C20: Yes | E20: Quick Ratio | F20: =Statement!AC143 -> 2.6781752
B21: Has finance lease | C21: No
B22: Has debt | C22: No
B25: Constants | E25: 10 Year Bond Yield
B26: Default tax rate | C26: 0.21 | E26: #VALUE! | F26: {=_FV(E26,"Price")} -> 49.53
B27: Cost of debt | C27: 0 | E27: Percentage | F27: =F26/1000 -> 0.04953
B28: Manual WACC | C28: 0
B29: Manual Cost of Equity | C29: 0
B33: Info
B35: Mission: | C35: Develop the best education in the world and make it universally available
B36: Auditor: | C36: Deloitte
B42: Notes
B44: Date: | C44: 04.08.2026 | E44: Q2 2027
B45: - | C45: FY2027 revenue expected as 1285
B46: - | C46: Gross margin expected at 71% in Q3 and 71.6% in FY2027
B47: - | C47: Stock based compensation expected at about 15% of revenue
B53: Adjustments
B58: Date: | C58: 31.12.2025 | E58: FY 2025
B59: - | C59: Tax expense/benefit | E59: Taken out 256.7M to account for a big tax benefit
B60: - | C60: Net income, both EPS | E60: Adjusted these values to account for the tax change
B62: Date: | C62: 30.09.2025 | E62: Q3 2025
B63: - | C63: Tax expense/benefit | E63: Taken out 256.7M to account for a big tax benefit
...

Sheet Financials ->
H5: Links
H6: Overview'!B3
H7: Financials ->'!B13
H8: Analysis ->'!B13
H9: Forecast ->'!B13
H10: Valuation ->'!B13
B13: Financials ->

Sheet Statement
B2: Date | M2: 31.12.2021 | N2: 30.09.2022 | O2: 31.12.2023 | P2: 31.12.2024 | Q2: 31.12.2025 | T2: 30.09.2024 | U2: 31.12.2024 | V2: 31.03.2025 | W2: 30.06.2025 | X2: 30.09.2025 | Y2: 31.12.2025 | Z2: 31.03.2026 | AA2: 30.06.2026
B3: FY | M3: 2021 | N3: 2022 | O3: 2023 | P3: 2024 | Q3: 2025 | T3: Q3 2024 | U3: Q4 2024 | V3: Q1 2025 | W3: Q2 2025 | X3: Q3 2025 | Y3: Q4 2025 | Z3: Q1 2026 | AA3: Q2 2026 | AC3: TTM/YTD
B4: Income statement
B5: Revenue | M5: 250772 | N5: 369495 | O5: 531109 | P5: 748024 | Q5: 1037589 | T5: 192594 | U5: 209550 | V5: 230743 | W5: 252265 | X5: 271713 | Y5: 282868 | Z5: 291967 | AA5: 298454 | AC5: =SUM(X5:AA5) -> 1145002
B6: COGS | M6: 69186 | N6: 99431 | O6: 142105 | P6: 203645 | Q6: 288132 | T6: 52180 | U6: 58925 | V6: 66647 | W6: 69684 | X6: 74802 | Y6: 76999 | Z6: 78871 | AA6: 81714 | AC6: =SUM(X6:AA6) -> 312386
B7: Gross Profit | C7: =C5-C6 -> 0 | D7: =D5-D6 -> 0 | E7: =E5-E6 -> 0 | F7: =F5-F6 -> 0 | G7: =G5-G6 -> 0 | H7: =H5-H6 -> 0 | I7: =I5-I6 -> 0 | J7: =J5-J6 -> 0 | ... Q7: =Q5-Q6 -> 749457 | T7: =T5-T6 -> 140414 | U7: =U5-U6 -> 150625 | V7: =V5-V6 -> 164096 | W7: =W5-W6 -> 182581 | X7: =X5-X6 -> 196911 | Y7: =Y5-Y6 -> 205869 | Z7: =Z5-Z6 -> 213096 | AA7: =AA5-AA6 -> 216740 | AC7: =SUM(X7:AA7) -> 832616
B8: R&D | M8: 103833 | N8: 150444 | O8: 194352 | P8: 235298 | Q8: 306323 | T8: 62878 | U8: 66395 | V8: 70390 | W8: 73670 | X8: 82707 | Y8: 79556 | Z8: 82974 | AA8: 92195 | AC8: =SUM(X8:AA8) -> 337432
B9: Sales and marketing | M9: 59170 | N9: 66967 | O9: 75788 | P9: 90494 | Q9: 125677 | T9: 25574 | U9: 24815 | V9: 26662 | W9: 29563 | X9: 35081 | Y9: 34371 | Z9: 39249 | AA9: 40007 | AC9: =SUM(X9:AA9) -> 148708
B10: General and administrative | M10: 78590 | N10: 117848 | O10: 132123 | P10: 155992 | Q10: 181887 | T10: 38388 | U10: 45533 | V10: 43450 | W10: 45985 | X10: 43964 | Y10: 48488 | Z10: 46346 | AA10: 50593 | AC10: =SUM(X10:AA10) -> 189391
B11: OpEx | C11: =SUM(C8:C10) -> 0 | D11: =SUM(D8:D10) -> 0 | E11: =SUM(E8:E10) -> 0 | F11: =SUM(F8:F10) -> 0 | G11: =SUM(G8:G10) -> 0 | H11: =SUM(H8:H10) -> 0 | I11: =SUM(I8:I10) -> 0 | J11: =SUM(J8:J10) -> 0 | ... Q11: =SUM(Q8:Q10) -> 613887 | T11: =SUM(T8:T10) -> 126840 | U11: =SUM(U8:U10) -> 136743 | V11: =SUM(V8:V10) -> 140502 | W11: =SUM(W8:W10) -> 149218 | X11: =SUM(X8:X10) -> 161752 | Y11: =SUM(Y8:Y10) -> 162415 | Z11: =SUM(Z8:Z10) -> 168569 | AA11: =SUM(AA8:AA10) -> 182795 | AC11: =SUM(X11:AA11) -> 675531
B12: Operating income | M12: -60007 | N12: -65195 | O12: -13259 | P12: 62595 | Q12: 135570 | T12: 13574 | U12: 13882 | V12: 23594 | W12: 33363 | X12: 35159 | Y12: 43454 | Z12: 44527 | AA12: 33945 | AC12: =SUM(X12:AA12) -> 157085
B13: Interest income/expense | M13: 19 | N13: 7235 | O13: 31091 | P13: 42697 | Q13: 45231 | T13: 11246 | U13: 10697 | V13: 10415 | W13: 11427 | X13: 11793 | Y13: 11596 | Z13: 11811 | AA13: 11831 | AC13: =SUM(X13:AA13) -> 47031
B14: Other income/expense | M14: =318-288 -> 30 | N14: =131-807 -> -676 | O14: =590-645 -> -55 | P14: =1267-4253 -> -2986 | Q14: =3382-1773 -> 1609 | T14: 569 | U14: -2227 | V14: 1001 | W14: 1660 | X14: -503 | Y14: -549 | Z14: -786 | AA14: -410 | AC14: =SUM(X14:AA14) -> -2248
B15: Income before taxes | M15: -59958 | N15: 58636 | O15: 17777 | P15: 102306 | Q15: 182410 | T15: 25389 | U15: 22352 | V15: 35010 | W15: 46450 | X15: 46449 | Y15: 54501 | Z15: 55552 | AA15: 45366 | AC15: =SUM(X15:AA15) -> 201868
B16: Income tax expense/benefit | M16: -177 | N16: -938 | O16: -1710 | P16: -13732 | Q16: -25045 | T16: -2029 | U16: -8445 | V16: 125 | W16: -1669 | X16: =245746-256700 -> -10954 | Y16: -12547 | Z16: -12092 | AA16: -12208 | AC16: =SUM(X16:AA16) -> -47801
B17: Non-controlling interest | M17: 0 | N17: 0 | O17: 0 | P17: 0 | Q17: 0 | T17: 0 | U17: 0 | V17: 0 | W17: 0 | X17: 0 | Y17: 0 | Z17: 0 | AA17: 0 | AC17: =SUM(X17:AA17) -> 0
B18: Net income | M18: -60135 | N18: -59574 | O18: 16067 | P18: 88574 | Q18: 157365 | T18: 23360 | U18: 13907 | V18: 35135 | W18: 44781 | X18: 35495 | Y18: 41954 | Z18: 43460 | AA18: 33158 | AC18: =SUM(X18:AA18) -> 154067
B19: Basic Shares outstanding avg | M19: 23433 | N19: 39470 | O19: 41451 | P19: 43504 | Q19: 45753.039 | T19: 43707 | U19: 43504 | V19: 45148 | W19: 45610 | X19: 45950 | Y19: 45753.039 | Z19: 46793 | AA19: 46701.408 | AC19: =AVERAGE(X19:AA19) -> 46299.362
B20: Basic Shares outstanding avg adjusted | C20: =C19*C$85 -> 0 | D20: =D19*D$85 -> 0 | E20: =E19*E$85 -> 0 | F20: =F19*F$85 -> 0 | G20: =G19*G$85 -> 0 | H20: =H19*H$85 -> 0 | I20: =I19*I$85 -> 0 | J20: =J19*J$85 -> 0 | ... Q20: =Q19*Q$85 -> 45753.039 | T20: =T19*T$85 -> 43707 | U20: =U19*U$85 -> 43504 | V20: =V19*V$85 -> 45148 | W20: =W19*W$85 -> 45610 | X20: =X19*X$85 -> 45950 | Y20: =Y19*Y$85 -> 45753.039 | Z20: =Z19*Z$85 -> 46793 | AA20: =AA19*AA$85 -> 46701.408 | AC20: =AC19*AC$85 -> 46299.362
B21: Diluted Shares outstanding avg | M21: 23433 | N21: 39470 | O21: 46522 | P21: 47101 | Q21: 48315.636 | T21: 47969 | U21: 47101 | V21: 48497 | W21: 49000 | X21: 49144 | Y21: 48315.636 | Z21: 48987 | AA21: 50239.394 | AC21: =AVERAGE(X21:AA21) -> 49171.507
B22: Diluted Shares outstanding avg adjusted | C22: =C21*C$85 -> 0 | D22: =D21*D$85 -> 0 | E22: =E21*E$85 -> 0 | F22: =F21*F$85 -> 0 | G22: =G21*G$85 -> 0 | H22: =H21*H$85 -> 0 | I22: =I21*I$85 -> 0 | J22: =J21*J$85 -> 0 | ... Q22: =Q21*Q$85 -> 48315.636 | T22: =T21*T$85 -> 47969 | U22: =U21*U$85 -> 47101 | V22: =V21*V$85 -> 48497 | W22: =W21*W$85 -> 49000 | X22: =X21*X$85 -> 49144 | Y22: =Y21*Y$85 -> 48315.636 | Z22: =Z21*Z$85 -> 48987 | AA22: =AA21*AA$85 -> 50239.394 | AC22: =AC21*AC$85 -> 49171.507
B23: Basic EPS | M23: -2.57 | N23: -1.51 | O23: 0.39 | P23: 2.04 | Q23: 3.4394437 | T23: 0.53 | U23: 0.31967175 | V23: 0.78 | W23: 0.98 | X23: 0.77247008 | Y23: 0.91696642 | Z23: 0.93 | AA23: 0.71 | AC23: =SUM(X23:AA23) -> 3.3294365
B24: Basic EPS adjusted | M24: =M23/M$85 -> -2.57 | N24: =N23/N$85 -> -1.51 | O24: =O23/O$85 -> 0.39 | P24: =P23/P$85 -> 2.04 | Q24: =Q23/Q$85 -> 3.4394437 | T24: =T23/T$85 -> 0.53 | U24: =U23/U$85 -> 0.31967175 | V24: =V23/V$85 -> 0.78 | W24: =W23/W$85 -> 0.98 | X24: =X23/X$85 -> 0.77247008 | Y24: =Y23/Y$85 -> 0.91696642 | Z24: =Z23/Z$85 -> 0.93 | AA24: =AA23/AA$85 -> 0.71 | AC24: =AC23/AC$85 -> 3.3294365
B25: Diluted EPS | M25: -2.57 | N25: -1.51 | O25: 0.35 | P25: 1.88 | Q25: 3.2570202 | T25: 0.49 | U25: 0.29525912 | V25: 0.72 | W25: 0.91 | X25: 0.72226518 | Y25: 0.86833174 | Z25: 0.89 | AA25: 0.66 | AC25: =SUM(X25:AA25) -> 3.1405969
B26: Diluted EPS adjusted | M26: =M25/M$85 -> -2.57 | N26: =N25/N$85 -> -1.51 | O26: =O25/O$85 -> 0.35 | P26: =P25/P$85 -> 1.88 | Q26: =Q25/Q$85 -> 3.2570202 | T26: =T25/T$85 -> 0.49 | U26: =U25/U$85 -> 0.29525912 | V26: =V25/V$85 -> 0.72 | W26: =W25/W$85 -> 0.91 | X26: =X25/X$85 -> 0.72226518 | Y26: =Y25/Y$85 -> 0.86833174 | Z26: =Z25/Z$85 -> 0.89 | AA26: =AA25/AA$85 -> 0.66 | AC26: =AC25/AC$85 -> 3.1405969
B28: Balance sheet
B29: Cash and cash equivalents | M29: 553922 | N29: 608180 | O29: 747610 | P29: =785791+91854 -> 877645 | Q29: =1036389+104078 -> 1140467 | T29: =854409+26354 -> 880763 | U29: =785791+91854 -> 877645 | V29: =883996+115284 -> 999280 | W29: =976231+121652 -> 1097883 | X29: =1011542+109912 -> 1121454 | Y29: =1036389+104078 -> 1140467 | Z29: =1138561+113049 -> 1251610 | AA29: =1180887+132979 -> 1313866 | AC29: =AA29 -> 1313866
B30: Acc receivable | M30: 33163 | N30: 46728 | O30: 88975 | P30: 128923 | Q30: 162827 | T30: 94215 | U30: 128923 | V30: 114183 | W30: 112919 | X30: 124489 | Y30: 162827 | Z30: 125086 | AA30: 130979 | AC30: =AA30 -> 130979
B31: Inventory | M31: 0 | N31: 0 | O31: 0 | P31: 0 | Q31: 0 | T31: 0 | U31: 0 | V31: 0 | W31: 0 | X31: 0 | Y31: 0 | Z31: 0 | AA31: 0 | AC31: =AA31 -> 0
B32: Current assets | M32: 619271 | N32: 697183 | O32: 897798 | P32: 1101588 | Q32: 1436606 | T32: 1058437 | U32: 1101588 | V32: 1219657 | W32: 1323990 | X32: 1367105 | Y32: 1436606 | Z32: 1505959 | AA32: 1671114 | AC32: =AA32 -> 1671114
B33: PP&E | M33: 8211 | N33: 12969 | O33: 11792 | P33: 18943 | Q33: 36297 | T33: 19495 | U33: 18943 | V33: 19161 | W33: 19685 | X33: 24626 | Y33: 36297 | Z33: 36966 | AA33: 42619 | AC33: =AA33 -> 42619
B34: Marketable securities and investments | M34: 0 | N34: 0 | O34: 0 | P34: 98292 | Q34: 135098 | T34: 55328 | U34: 98292 | V34: 83342 | W34: 75362 | X34: 98735 | Y34: 135098 | Z34: 140211 | AA34: 102693 | AC34: =AA34 -> 102693
B35: Goodwill | M35: 0 | N35: 4050 | O35: 4050 | P35: 10538 | Q35: 35335 | T35: 10538 | U35: 10538 | V35: 10538 | W35: 10538 | X35: 35335 | Y35: 35335 | Z35: 35335 | AA35: 35335 | AC35: =AA35 -> 35335
B36: Long term assets | M36: =M37-M32 -> 42040 | N36: =N37-N32 -> 50164 | O36: =O37-O32 -> 56159 | P36: =P37-P32 -> 200140 | Q36: =Q37-Q32 -> 555576 | T36: =T37-T32 -> 161112 | U36: =U37-U32 -> 200140 | V36: =V37-V32 -> 183489 | W36: =W37-W32 -> 218569 | X36: =X37-X32 -> 518533 | Y36: =Y37-Y32 -> 555576 | Z36: =Z37-Z32 -> 552035 | AA36: =AA37-AA32 -> 402839 | AC36: =AA36 -> 402839
B37: Total assets | M37: 661311 | N37: 747347 | O37: 953957 | P37: 1301728 | Q37: 1992182 | T37: 1219549 | U37: 1301728 | V37: 1403146 | W37: 1542559 | X37: 1885638 | Y37: 1992182 | Z37: 2057994 | AA37: 2073953 | AC37: =AA37 -> 2073953
B38: Acc payable | M38: 7818 | N38: 1177 | O38: 2447 | P38: 6381 | Q38: 7998 | T38: 3649 | U38: 6381 | V38: 2546 | W38: 7729 | X38: 3568 | Y38: 7998 | Z38: 7486 | AA38: 16196 | AC38: =AA38 -> 16196
B39: Debt | M39: 0 | N39: 0 | O39: 0 | P39: 0 | Q39: 0 | T39: 0 | U39: 0 | V39: 0 | W39: 0 | X39: 0 | Y39: 0 | Z39: 0 | AA39: 0 | AC39: =AA39 -> 0
B40: Current liabilities | M40: 119131 | N40: 181766 | O40: 277362 | P40: 422231 | Q40: 551148 | T40: 342133 | U40: 422231 | V40: 454485 | W40: 471383 | X40: 484540 | Y40: 551148 | Z40: 574114 | AA40: 577833 | AC40: =AA40 -> 577833
B41: Debt | M41: 0 | N41: 0 | O41: 0 | P41: 0 | Q41: 0 | T41: 0 | U41: 0 | V41: 0 | W41: 0 | X41: 0 | Y41: 0 | Z41: 0 | AA41: 0 | AC41: =AA41 -> 0
B42: Long term liabilities | M42: =M43-M40 -> 29124 | N42: =N43-N40 -> 23503 | O42: =O43-O40 -> 21094 | P42: =P43-P40 -> 54947 | Q42: =Q43-Q40 -> 94028 | T42: =T43-T40 -> 54963 | U42: =U43-U40 -> 54947 | V42: =V43-V40 -> 54835 | W42: =W43-W40 -> 94145 | X42: =X43-X40 -> 93559 | Y42: =Y43-Y40 -> 94028 | Z42: =Z43-Z40 -> 92116 | AA42: =AA43-AA40 -> 86378 | AC42: =AA42 -> 86378
...

Sheet Analysis ->
H5: Links
H6: Overview'!B3
H7: Financials ->'!B13
H8: Analysis ->'!B13
H9: Forecast ->'!B13
H10: Valuation ->'!B13
B13: Analysis ->

Sheet Basic
B1: TTM/YTD data
B4: Overview | E4: CAGR
B5: Price | C5: =Overview!C5 -> 143.04 | F5: 5Y | G5: 10Y
B6: Market capitalization | C6: =Statement!AC149 -> 7169450.9 | E6: Revenue | F6: =IF(Statement!M5<=0,"N/A",_xlfn.RRI(4,Statement!M5,Statement!Q5)) -> 0.42622019 | G6: =IF(Statement!H5<=0,"N/A",_xlfn.RRI(9,Statement!H5,Statement!Q5)) -> N/A
B7: Enterprise value | C7: =Statement!AC150 -> 5752891.9 | E7: Net income | F7: =IF(OR(Statement!M18<=0, Statement!Q18<=0), "N/A", _xlfn.RRI(4, Statement!M18, Statement!Q18)) -> N/A | G7: =IF(OR(Statement!H18<=0, Statement!Q18<=0), "N/A", _xlfn.RRI(9, Statement!H18, Statement!Q18)) -> N/A
B8: PE | C8: =Statement!AC146 -> 45.545482 | E8: EPS | F8: =IF(OR(Statement!M26<=0, Statement!Q26<=0), "N/A", _xlfn.RRI(4, Statement!M26, Statement!Q26)) -> N/A | G8: =IF(OR(Statement!H26<=0, Statement!Q26<=0), "N/A", _xlfn.RRI(9, Statement!H26, Statement!Q26)) -> N/A
B9: PS | C9: =Statement!AC147 -> 6.1427774 | E9: Dividend | F9: =IF(Statement!M82<=0,"N/A",_xlfn.RRI(4,Statement!M82,Statement!Q82)) -> N/A | G9: =IF(Statement!H82<=0,"N/A",_xlfn.RRI(9,Statement!H82,Statement!Q82)) -> N/A
B10: PB | C10: =Statement!AC148 -> 4.747159 | E10: Price | F10: =IF(Statement!M117<=0,"N/A",_xlfn.RRI(4,Statement!M117,Statement!Q117)) -> 0.12501941 | G10: =IF(Statement!H117<=0,"N/A",_xlfn.RRI(9,Statement!H117,Statement!Q117)) -> N/A
B11: EV/Revenue | C11: =Statement!AC151 -> 5.0243509
B12: EV/EBIT | C12: =Statement!AC152 -> 36.622796
B15: Margins | E15: Earnings quality
B16: Gross margin | C16: =Statement!AC101 -> 0.72717428 | E16: Net income | F16: =Statement!AC18 -> 154067
B17: Operating margin | C17: =Statement!AC102 -> 0.1371919 | E17: Operating cash | F17: =Statement!AC59 -> 430548
B18: Net margin | C18: =Statement!AC103 -> 0.1345561 | E18: Cash accruals | F18: =IF(OR(F16<=0, F17<=0),"N/A",F16-F17) -> -276481
B21: DuPont Identity | E21: Performance indicators
B22: Profit Margin (Earnings/Revenue) | C22: =Statement!AC121 -> 0.1345561 | E22: ROA | F22: =C24 -> 0.07428664
B23: Asset Turnover (Revenue/Total assets) | C23: =Statement!AC122 -> 0.55208676 | E23: ROE | F23: =C26 -> 0.10928737
B24: ROA | C24: =Statement!AC123 -> 0.07428664 | E24: ROIC | F24: =Statement!AC136 -> -17.586668
B25: Equity Multiplier (Total assets/Equity) | C25: =Statement!AC124 -> 1.4711578
B26: ROE | C26: =Statement!AC125 -> 0.10928737
B29: Cash conversion cycle | E29: Liquidity ratios
B30: DSO | C30: =Statement!AC137 -> 41.753058 | E30: Debt/Equity | F30: =Statement!AC141 -> 0
B31: DIO | C31: =Statement!AC138 -> 0 | E31: Net Debt/Equity | F31: =Statement!AC142 -> -1.0048356
B32: DPO | C32: =Statement!AC139 -> 18.923831 | E32: Current ratio | F32: =Statement!AC144 -> 2.8920363
B33: Net trade cycle | C33: =Statement!AC140 -> 22.829227 | E33: Quick ratio | F33: =Statement!AC143 -> 2.6781752
E34: Interest coverage | F34: =Statement!AC145 -> N/A
B37: Earnings yields | E37: Payout ratios
B38: Earnings yield | C38: =Statement!AC158 -> 0.021956075 | E38: Dividend payout ratio | F38: =Statement!AC164 -> 0
B39: FCF yield | C39: =Statement!AC157 -> 0.03526351 | E39: Buyback payout ratio | F39: =Statement!AC165 -> 0.27530654
B40: Dividend yield | C40: =Statement!AC159 -> 0 | E40: Full payout ratio | F40: =Statement!AC166 -> 0.27530654
B41: Buyback yield | C41: =Statement!AC160 -> 0.0097082749
B42: Total shareholder yield | C42: =Statement!AC161 -> 0.0097082749
B45: Ownership | E45: Cash holdings
B46: Insider ownership | C46: =Statement!AC167 -> 0.1452057 | E46: Cash per share | F46: =Statement!AC168 -> 30.277412
E47: Net cash per share | F47: =Statement!AC171 -> 30.277412
E48: Net cash to market cap | F48: =Statement!AC172 -> 0.19758264
B51: Stock based compensation | E51: CapEx usage
B52: Stock based compensation % OCF | C52: =Statement!AC169 -> 0.33604616 | E52: Capex to Revenue | F52: =Statement!AC173 -> 0.028859338
B53: Stock based compensation % Revenue | C53: =Statement!AC170 -> 0.12636135 | E53: CapEx to OCF | F53: =Statement!AC174 -> 0.076748702
E54: CapEx to D&A | F54: =Statement!AC175 -> 2.0915248

Sheet Yearly Analysis
C2: =Statement!M2 -> 31.12.2021 | D2: =Statement!N2 -> 30.09.2022 | E2: =Statement!O2 -> 31.12.2023 | F2: =Statement!P2 -> 31.12.2024 | G2: =Statement!Q2 -> 31.12.2025
C3: =Statement!M3 -> 2021 | D3: =Statement!N3 -> 2022 | E3: =Statement!O3 -> 2023 | F3: =Statement!P3 -> 2024 | G3: =Statement!Q3 -> 2025 | I3: =Statement!AC3 -> TTM/YTD
B5: Overview
B6: Price | C6: =Statement!M116 -> 110.58 | D6: =Statement!N116 -> 71.13 | E6: =Statement!O116 -> 226.85 | F6: =Statement!P116 -> 325.2 | G6: =Statement!Q116 -> 177.14 | I6: =Statement!AC116 -> 143.04
B7: Market capitalization | C7: =Statement!M149 -> 4271152.5 | D7: =Statement!N149 -> 2890438.7 | E7: =Statement!O149 -> 10876777 | F7: =Statement!P149 -> 15882768 | G7: =Statement!Q149 -> 8845485.9 | I7: =Statement!AC149 -> 7169450.9
B8: Enterprise value | C8: =Statement!M150 -> 3717230.5 | D8: =Statement!N150 -> 2282258.7 | E8: =Statement!O150 -> 10129167 | F8: =Statement!P150 -> 14906831 | G8: =Statement!Q150 -> 7569920.9 | I8: =Statement!AC150 -> 5752891.9
B9: PE | C9: =Statement!M146 -> -43.027237 | D9: =Statement!N146 -> -47.10596 | E9: =Statement!O146 -> 648.14286 | F9: =Statement!P146 -> 172.97872 | G9: =Statement!Q146 -> 54.387137 | I9: =Statement!AC146 -> 45.545482
B10: PS | C10: =Statement!M147 -> 10.332976 | D10: =Statement!N147 -> 7.5982113 | E10: =Statement!O147 -> 19.870715 | F10: =Statement!P147 -> 20.476944 | G10: =Statement!Q147 -> 8.248576 | I10: =Statement!AC147 -> 6.1427774
B11: PB | C11: =Statement!M148 -> 8.3249246 | D11: =Statement!N148 -> 5.3321453 | E11: =Statement!O148 -> 14.838148 | F11: =Statement!P148 -> 17.843701 | G11: =Statement!Q148 -> 6.2334065 | I11: =Statement!AC148 -> 4.747159
B12: EV/Revenue | C12: =Statement!M151 -> 14.823148 | D12: =Statement!N151 -> 6.1766971 | E12: =Statement!O151 -> 19.071729 | F12: =Statement!P151 -> 19.928279 | G12: =Statement!Q151 -> 7.2956835 | I12: =Statement!AC151 -> 5.0243509
B13: EV/EBIT | C13: =Statement!M152 -> -61.946615 | D13: =Statement!N152 -> -35.006652 | E13: =Statement!O152 -> -763.94652 | F13: =Statement!P152 -> 238.14731 | G13: =Statement!Q152 -> 55.837729 | I13: =Statement!AC152 -> 36.622796
B15: Margins
B16: Gross margin | C16: =Statement!M101 -> 0.72410795 | D16: =Statement!N101 -> 0.73090028 | E16: =Statement!O101 -> 0.73243722 | F16: =Statement!P101 -> 0.72775606 | G16: =Statement!Q101 -> 0.72230623 | I16: =Statement!AC101 -> 0.72717428
B17: Operating margin | C17: =Statement!M102 -> -0.23928908 | D17: =Statement!N102 -> -0.17644352 | E17: =Statement!O102 -> -0.024964744 | F17: =Statement!P102 -> 0.08368047 | G17: =Statement!Q102 -> 0.13065867 | I17: =Statement!AC102 -> 0.1371919
B18: Net margin | C18: =Statement!M103 -> -0.2397995 | D18: =Statement!N103 -> -0.16123087 | E18: =Statement!O103 -> 0.030251794 | F18: =Statement!P103 -> 0.11841064 | G18: =Statement!Q103 -> 0.1516641 | I18: =Statement!AC103 -> 0.1345561
B20: Earnings quality
B21: Net income | C21: =Statement!M18 -> -60135 | D21: =Statement!N18 -> -59574 | E21: =Statement!O18 -> 16067 | F21: =Statement!P18 -> 88574 | G21: =Statement!Q18 -> 157365 | I21: =Statement!AC18 -> 154067
B22: Operating cash | C22: =Statement!M59 -> 9170 | D22: =Statement!N59 -> 53656 | E22: =Statement!O59 -> 153614 | F22: =Statement!P59 -> 285513 | G22: =Statement!Q59 -> 387823 | I22: =Statement!AC59 -> 430548
B23: Cash accruals | C23: =IF(OR(C21<=0, C22<=0),"N/A",C21-C22) -> N/A | D23: =IF(OR(D21<=0, D22<=0),"N/A",D21-D22) -> N/A | E23: =IF(OR(E21<=0, E22<=0),"N/A",E21-E22) -> -137547 | F23: =IF(OR(F21<=0, F22<=0),"N/A",F21-F22) -> -196939 | G23: =IF(OR(G21<=0, G22<=0),"N/A",G21-G22) -> -230458 | I23: =IF(OR(I21<=0, I22<=0),"N/A",I21-I22) -> -276481
B25: DuPont Identity
B26: Profit Margin (Earnings/Revenue) | C26: =Statement!M121 -> -0.2397995 | D26: =Statement!N121 -> -0.16123087 | E26: =Statement!O121 -> 0.030251794 | F26: =Statement!P121 -> 0.11841064 | G26: =Statement!Q121 -> 0.1516641 | I26: =Statement!AC121 -> 0.1345561
B27: Asset Turnover (Revenue/Total assets) | C27: =Statement!M122 -> 0.37920434 | D27: =Statement!N122 -> 0.49440889 | E27: =Statement!O122 -> 0.55674312 | F27: =Statement!P122 -> 0.57463925 | G27: =Statement!Q122 -> 0.52083043 | I27: =Statement!AC122 -> 0.55208676
B28: ROA | C28: =Statement!M123 -> -0.09093301 | D28: =Statement!N123 -> -0.079713975 | E28: =Statement!O123 -> 0.016842478 | F28: =Statement!P123 -> 0.068043401 | G28: =Statement!Q123 -> 0.078991277 | I28: =Statement!AC123 -> 0.07428664
B29: Equity Multiplier (Total assets/Equity) | C29: =Statement!M124 -> 1.2889646 | D29: =Statement!N124 -> 1.3786706 | E29: =Statement!O124 -> 1.4553098 | F29: =Statement!P124 -> 1.5787132 | G29: =Statement!Q124 -> 1.4789704 | I29: =Statement!AC124 -> 1.4711578
B30: ROE | C30: =Statement!M125 -> -0.11720943 | D30: =Statement!N125 -> -0.10989931 | E30: =Statement!O125 -> 0.024511023 | F30: =Statement!P125 -> 0.10742102 | G30: =Statement!Q125 -> 0.11682576 | I30: =Statement!AC125 -> 0.10928737
B32: Performance Indicators
B33: ROA | C33: =C28 -> -0.09093301 | D33: =D28 -> -0.079713975 | E33: =E28 -> 0.016842478 | F33: =F28 -> 0.068043401 | G33: =G28 -> 0.078991277 | I33: =I28 -> 0.07428664
B34: ROE | C34: =C30 -> -0.11720943 | D34: =D30 -> -0.10989931 | E34: =E30 -> 0.024511023 | F34: =F30 -> 0.10742102 | G34: =G30 -> 0.11682576 | I34: =I30 -> 0.10928737
B35: ROIC | C35: =Statement!M136 -> 1.4683845 | D35: =Statement!N136 -> 0.98627878 | E35: =Statement!O136 -> 0.14394902 | F35: =Statement!P136 -> -0.3579779 | G35: =Statement!Q136 -> 1.6371014 | I35: =Statement!AC136 -> -17.586668
B37: Cash conversion cycle
B38: DSO | C38: =Statement!M137 -> 48.268926 | D38: =Statement!N137 -> 46.159542 | E38: =Statement!O137 -> 61.147288 | F38: =Statement!P137 -> 62.908269 | G38: =Statement!Q137 -> 57.278802 | I38: =Statement!AC137 -> 41.753058
B39: DIO | C39: =Statement!M138 -> 0 | D39: =Statement!N138 -> 0 | E39: =Statement!O138 -> 0 | F39: =Statement!P138 -> 0 | G39: =Statement!Q138 -> 0 | I39: =Statement!AC138 -> 0
B40: DPO | C40: =Statement!M139 -> 41.244905 | D40: =Statement!N139 -> 4.3206344 | E40: =Statement!O139 -> 6.2851765 | F40: =Statement!P139 -> 11.436888 | G40: =Statement!Q139 -> 10.13171 | I40: =Statement!AC139 -> 18.923831
B41: Net trade cycle | C41: =Statement!M140 -> 7.0240205 | D41: =Statement!N140 -> 41.838908 | E41: =Statement!O140 -> 54.862112 | F41: =Statement!P140 -> 51.471381 | G41: =Statement!Q140 -> 47.147092 | I41: =Statement!AC140 -> 22.829227
B43: Liquidity ratios
B44: Debt/Equity | C44: =Statement!M141 -> 0 | D44: =Statement!N141 -> 0 | E44: =Statement!O141 -> 0 | F44: =Statement!P141 -> 0 | G44: =Statement!Q141 -> 0 | I44: =Statement!AC141 -> 0
B45: Net Debt/Equity | C45: =Statement!M142 -> -1.0796521 | D45: =Statement!N142 -> -1.1219419 | E45: =Statement!O142 -> -1.1405169 | F45: =Statement!P142 -> -1.1835995 | G45: =Statement!Q142 -> -0.94696312 | I45: =Statement!AC142 -> -1.0048356
B46: Quick ratio | C46: =Statement!M143 -> 4.9280624 | D46: =Statement!N143 -> 3.6030281 | E46: =Statement!O143 -> 3.0162207 | F46: =Statement!P143 -> 2.6167193 | G46: =Statement!Q143 -> 2.6098108 | I46: =Statement!AC143 -> 2.6781752
B47: Current ratio | C47: =Statement!M144 -> 5.1982356 | D47: =Statement!N144 -> 3.8356073 | E47: =Statement!O144 -> 3.2369178 | F47: =Statement!P144 -> 2.60897 | G47: =Statement!Q144 -> 2.6065703 | I47: =Statement!AC144 -> 2.8920363
B48: Interest coverage | C48: =Statement!M145 -> N/A | D48: =Statement!N145 -> N/A | E48: =Statement!O145 -> N/A | F48: =Statement!P145 -> N/A | G48: =Statement!Q145 -> N/A | I48: =Statement!AC145 -> N/A
...

Sheet Quarter analysis
C3: Latest 2 quarters | F3: YoY
C4: =Statement!Z2 -> 31.03.2026 | D4: =Statement!AA2 -> 30.06.2026 | F4: =Statement!W2 -> 30.06.2025 | G4: =Statement!AA2 -> 30.06.2026
B5: Income statement growth | C5: =Statement!Z3 -> Q1 2026 | D5: =Statement!AA3 -> Q2 2026 | F5: =Statement!W3 -> Q2 2025 | G5: =Statement!AA3 -> Q2 2026
B6: Revenue | C6: =Statement!Z5 -> 291967 | D6: =Statement!AA5 -> 298454 | F6: =Statement!W5 -> 252265 | G6: =Statement!AA5 -> 298454
B7: Growth | C7: =Statement!AA89 -> 0.022218264 | F7: =IF(F6=0, IF(G6=0,0,IF(G6>0,1,-1)), (G6-F6)/ABS(F6) ) -> 0.18309714
B8: COGS | C8: =Statement!Z6 -> 78871 | D8: =Statement!AA6 -> 81714 | F8: =Statement!W6 -> 69684 | G8: =Statement!AA6 -> 81714
B9: Growth | C9: =Statement!AA90 -> 0.036046202 | F9: =IF(F8=0, IF(G8=0,0,IF(G8>0,1,-1)), (G8-F8)/ABS(F8) ) -> 0.17263647
B10: Gross Profit | C10: =Statement!Z7 -> 213096 | D10: =Statement!AA7 -> 216740 | F10: =Statement!W7 -> 182581 | G10: =Statement!AA7 -> 216740
B11: Growth | C11: =Statement!AA91 -> 0.017100274 | F11: =IF(F10=0, IF(G10=0,0,IF(G10>0,1,-1)), (G10-F10)/ABS(F10) ) -> 0.18708957
B12: OpEx | C12: =Statement!Z11 -> 168569 | D12: =Statement!AA11 -> 182795 | F12: =Statement!W11 -> 149218 | G12: =Statement!AA11 -> 182795
B13: Growth | C13: =Statement!AA95 -> 0.084392741 | F13: =IF(F12=0, IF(G12=0,0,IF(G12>0,1,-1)), (G12-F12)/ABS(F12) ) -> 0.22501977
B14: Operating profit | C14: =Statement!Z12 -> 44527 | D14: =Statement!AA12 -> 33945 | F14: =Statement!W12 -> 33363 | G14: =Statement!AA12 -> 33945
B15: Growth | C15: =Statement!AA96 -> -0.23765356 | F15: =IF(F14=0, IF(G14=0,0,IF(G14>0,1,-1)), (G14-F14)/ABS(F14) ) -> 0.017444474
B16: Net income | C16: =Statement!Z18 -> 43460 | D16: =Statement!AA18 -> 33158 | F16: =Statement!W18 -> 44781 | G16: =Statement!AA18 -> 33158
B17: Growth | C17: =Statement!AA98 -> -0.23704556 | F17: =IF(F16=0, IF(G16=0,0,IF(G16>0,1,-1)), (G16-F16)/ABS(F16) ) -> -0.25955204
B18: Diluted shares outstanding | C18: =Statement!Z22 -> 48987 | D18: =Statement!AA22 -> 50239.394 | F18: =Statement!W22 -> 49000 | G18: =Statement!AA22 -> 50239.394
B19: Growth | C19: =IF(C18=0, IF(D18=0,0,IF(D18>0,1,-1)), (D18-C18)/ABS(C18) ) -> 0.025565843 | F19: =IF(F18=0, IF(G18=0,0,IF(G18>0,1,-1)), (G18-F18)/ABS(F18) ) -> 0.025293754
B20: Diluted EPS | C20: =Statement!Z26 -> 0.89 | D20: =Statement!AA26 -> 0.66 | F20: =Statement!W26 -> 0.91 | G20: =Statement!AA26 -> 0.66
B21: Growth | C21: =IF(C20=0, IF(D20=0,0,IF(D20>0,1,-1)), (D20-C20)/ABS(C20) ) -> -0.25842697 | F21: =IF(F20=0, IF(G20=0,0,IF(G20>0,1,-1)), (G20-F20)/ABS(F20) ) -> -0.27472527
B23: Revenue breakdown | C23: =C5 -> Q1 2026 | D23: =D5 -> Q2 2026 | F23: =F5 -> Q2 2025 | G23: =G5 -> Q2 2026
B24: =Statement!B183 -> Subscription | C24: =Statement!Z183 -> 250908 | D24: =Statement!AA183 -> 258035 | F24: =Statement!W183 -> 210678 | G24: =Statement!AA183 -> 258035
B25: Growth | C25: =IF(C24=0, IF(D24=0,0,IF(D24>0,1,-1)), (D24-C24)/ABS(C24) ) -> 0.028404834 | F25: =IF(F24=0, IF(G24=0,0,IF(G24>0,1,-1)), (G24-F24)/ABS(F24) ) -> 0.22478379
B26: =Statement!B184 -> Advertising | C26: =Statement!Z184 -> 20614 | D26: =Statement!AA184 -> 21052 | F26: =Statement!W184 -> 20603 | G26: =Statement!AA184 -> 21052
B27: Growth | C27: =IF(C26=0, IF(D26=0,0,IF(D26>0,1,-1)), (D26-C26)/ABS(C26) ) -> 0.021247696 | F27: =IF(F26=0, IF(G26=0,0,IF(G26>0,1,-1)), (G26-F26)/ABS(F26) ) -> 0.021792943
B28: =Statement!B185 -> English test | C28: =Statement!Z185 -> 11317 | D28: =Statement!AA185 -> 10109 | F28: =Statement!W185 -> 10088 | G28: =Statement!AA185 -> 10109
B29: Growth | C29: =IF(C28=0, IF(D28=0,0,IF(D28>0,1,-1)), (D28-C28)/ABS(C28) ) -> -0.10674207 | F29: =IF(F28=0, IF(G28=0,0,IF(G28>0,1,-1)), (G28-F28)/ABS(F28) ) -> 0.0020816812
B30: =Statement!B186 -> In-App purchases | C30: =Statement!Z186 -> 8446 | D30: =Statement!AA186 -> 8002 | F30: =Statement!W186 -> 10390 | G30: =Statement!AA186 -> 8002
B31: Growth | C31: =IF(C30=0, IF(D30=0,0,IF(D30>0,1,-1)), (D30-C30)/ABS(C30) ) -> -0.052569264 | F31: =IF(F30=0, IF(G30=0,0,IF(G30>0,1,-1)), (G30-F30)/ABS(F30) ) -> -0.22983638
B32: =Statement!B187 -> Other | C32: =Statement!Z187 -> 682 | D32: =Statement!AA187 -> 1256 | F32: =Statement!W187 -> 506 | G32: =Statement!AA187 -> 1256
B33: Growth | C33: =IF(C32=0, IF(D32=0,0,IF(D32>0,1,-1)), (D32-C32)/ABS(C32) ) -> 0.84164223 | F33: =IF(F32=0, IF(G32=0,0,IF(G32>0,1,-1)), (G32-F32)/ABS(F32) ) -> 1.4822134
B35: Metrics growth | C35: =C5 -> Q1 2026 | D35: =D5 -> Q2 2026 | F35: =F5 -> Q2 2025 | G35: =G5 -> Q2 2026
B36: =Statement!B209 -> DAU | C36: =Statement!Z209 -> 56500 | D36: =Statement!AA209 -> 58700 | F36: =Statement!W209 -> 47700 | G36: =Statement!AA209 -> 58700
B37: Growth | C37: =IF(C36=0, IF(D36=0,0,IF(D36>0,1,-1)), (D36-C36)/ABS(C36) ) -> 0.038938053 | F37: =IF(F36=0, IF(G36=0,0,IF(G36>0,1,-1)), (G36-F36)/ABS(F36) ) -> 0.23060797
B38: =Statement!B210 -> MAU | C38: =Statement!Z210 -> 137800 | D38: =Statement!AA210 -> 140600 | F38: =Statement!W210 -> 128300 | G38: =Statement!AA210 -> 140600
B39: Growth | C39: =IF(C38=0, IF(D38=0,0,IF(D38>0,1,-1)), (D38-C38)/ABS(C38) ) -> 0.020319303 | F39: =IF(F38=0, IF(G38=0,0,IF(G38>0,1,-1)), (G38-F38)/ABS(F38) ) -> 0.095869057
B40: =Statement!B211 -> Paid subscriberrs | C40: =Statement!Z211 -> 12500 | D40: =Statement!AA211 -> 12700 | F40: =Statement!W211 -> 10900 | G40: =Statement!AA211 -> 12700
B41: Growth | C41: =IF(C40=0, IF(D40=0,0,IF(D40>0,1,-1)), (D40-C40)/ABS(C40) ) -> 0.016 | F41: =IF(F40=0, IF(G40=0,0,IF(G40>0,1,-1)), (G40-F40)/ABS(F40) ) -> 0.16513761
B42: =Statement!B212 -> Free users | C42: =Statement!Z212 -> 125300 | D42: =Statement!AA212 -> 127900 | F42: =Statement!W212 -> 117400 | G42: =Statement!AA212 -> 127900
B43: Growth | C43: =IF(C42=0, IF(D42=0,0,IF(D42>0,1,-1)), (D42-C42)/ABS(C42) ) -> 0.0207502 | F43: =IF(F42=0, IF(G42=0,0,IF(G42>0,1,-1)), (G42-F42)/ABS(F42) ) -> 0.089437819
B44: =Statement!B213 -> Average revenue per paid user | C44: =Statement!Z213 -> 20.07264 | D44: =Statement!AA213 -> 20.317717 | F44: =Statement!W213 -> 19.328257 | G44: =Statement!AA213 -> 20.317717
...

Sheet Graphs Year
C55: =Statement!H2 -> 0 | D55: =Statement!I2 -> 0 | E55: =Statement!J2 -> 0 | F55: =Statement!K2 -> 0 | G55: =Statement!L2 -> 0 | H55: =Statement!M2 -> 31.12.2021 | I55: =Statement!N2 -> 30.09.2022 | J55: =Statement!O2 -> 31.12.2023 | ... L55: =Statement!Q2 -> 31.12.2025
C56: =Statement!H3 -> 0 | D56: =Statement!I3 -> 0 | E56: =Statement!J3 -> 0 | F56: =Statement!K3 -> 0 | G56: =Statement!L3 -> 0 | H56: =Statement!M3 -> 2021 | I56: =Statement!N3 -> 2022 | J56: =Statement!O3 -> 2023 | ... L56: =Statement!Q3 -> 2025
B57: Revenue | C57: =Statement!H5 -> 0 | D57: =Statement!I5 -> 0 | E57: =Statement!J5 -> 0 | F57: =Statement!K5 -> 0 | G57: =Statement!L5 -> 0 | H57: =Statement!M5 -> 250772 | I57: =Statement!N5 -> 369495 | J57: =Statement!O5 -> 531109 | ... L57: =Statement!Q5 -> 1037589
B58: Operating income | C58: =Statement!H12 -> 0 | D58: =Statement!I12 -> 0 | E58: =Statement!J12 -> 0 | F58: =Statement!K12 -> 0 | G58: =Statement!L12 -> 0 | H58: =Statement!M12 -> -60007 | I58: =Statement!N12 -> -65195 | J58: =Statement!O12 -> -13259 | ... L58: =Statement!Q12 -> 135570
B59: Net income | C59: =Statement!H18 -> 0 | D59: =Statement!I18 -> 0 | E59: =Statement!J18 -> 0 | F59: =Statement!K18 -> 0 | G59: =Statement!L18 -> 0 | H59: =Statement!M18 -> -60135 | I59: =Statement!N18 -> -59574 | J59: =Statement!O18 -> 16067 | ... L59: =Statement!Q18 -> 157365
B60: FCFE | C60: =Statement!H153 -> 0 | D60: =Statement!I153 -> 0 | E60: =Statement!J153 -> 0 | F60: =Statement!K153 -> 0 | G60: =Statement!L153 -> 0 | H60: =Statement!M153 -> -37840 | I60: =Statement!N153 -> -30288 | J60: =Statement!O153 -> 44709 | ... L60: =Statement!Q153 -> 222987
B61: FCFF | C61: =Statement!H154 -> 0 | D61: =Statement!I154 -> 0 | E61: =Statement!J154 -> 0 | F61: =Statement!K154 -> 0 | G61: =Statement!L154 -> 0 | H61: =Statement!M154 -> -37712 | I61: =Statement!N154 -> -35909 | J61: =Statement!O154 -> 15050 | ... L61: =Statement!Q154 -> 152914.16
B62: Gross margin | C62: =Statement!H101 -> 0 | D62: =Statement!I101 -> 0 | E62: =Statement!J101 -> 0 | F62: =Statement!K101 -> 0 | G62: =Statement!L101 -> 0 | H62: =Statement!M101 -> 0.72410795 | I62: =Statement!N101 -> 0.73090028 | J62: =Statement!O101 -> 0.73243722 | ... L62: =Statement!Q101 -> 0.72230623
B63: Operating margin | C63: =Statement!H102 -> 0 | D63: =Statement!I102 -> 0 | E63: =Statement!J102 -> 0 | F63: =Statement!K102 -> 0 | G63: =Statement!L102 -> 0 | H63: =Statement!M102 -> -0.23928908 | I63: =Statement!N102 -> -0.17644352 | J63: =Statement!O102 -> -0.024964744 | ... L63: =Statement!Q102 -> 0.13065867
B64: Net margin | C64: =Statement!H103 -> 0 | D64: =Statement!I103 -> 0 | E64: =Statement!J103 -> 0 | F64: =Statement!K103 -> 0 | G64: =Statement!L103 -> 0 | H64: =Statement!M103 -> -0.2397995 | I64: =Statement!N103 -> -0.16123087 | J64: =Statement!O103 -> 0.030251794 | ... L64: =Statement!Q103 -> 0.1516641
B65: ="Revenue "&Statement!B183 -> Revenue Subscription | C65: =Statement!H183 -> 0 | D65: =Statement!I183 -> 0 | E65: =Statement!J183 -> 0 | F65: =Statement!K183 -> 0 | G65: =Statement!L183 -> 0 | H65: =Statement!M183 -> 180698 | I65: =Statement!N183 -> 273507 | J65: =Statement!O183 -> 404684 | ... L65: =Statement!Q183 -> 873442
B66: ="Revenue "&Statement!B184 -> Revenue Advertising | C66: =Statement!H184 -> 0 | D66: =Statement!I184 -> 0 | E66: =Statement!J184 -> 0 | F66: =Statement!K184 -> 0 | G66: =Statement!L184 -> 0 | H66: =Statement!M184 -> 38501 | I66: =Statement!N184 -> 44731 | J66: =Statement!O184 -> 49858 | ... L66: =Statement!Q184 -> 79725
B67: ="Revenue "&Statement!B185 -> Revenue English test | C67: =Statement!H185 -> 0 | D67: =Statement!I185 -> 0 | E67: =Statement!J185 -> 0 | F67: =Statement!K185 -> 0 | G67: =Statement!L185 -> 0 | H67: =Statement!M185 -> 24658 | I67: =Statement!N185 -> 32718 | J67: =Statement!O185 -> 41212 | ... L67: =Statement!Q185 -> 42006
B68: ="Revenue "&Statement!B186 -> Revenue In-App purchases | C68: =Statement!H186 -> 0 | D68: =Statement!I186 -> 0 | E68: =Statement!J186 -> 0 | F68: =Statement!K186 -> 0 | G68: =Statement!L186 -> 0 | H68: =Statement!M186 -> 6915 | I68: =Statement!N186 -> 18539 | J68: =Statement!O186 -> 34673 | ... L68: =Statement!Q186 -> 40479
B69: ="Revenue "&Statement!B187 -> Revenue Other | C69: =Statement!H187 -> 0 | D69: =Statement!I187 -> 0 | E69: =Statement!J187 -> 0 | F69: =Statement!K187 -> 0 | G69: =Statement!L187 -> 0 | H69: =Statement!M187 -> 79 | I69: =Statement!N187 -> 625 | J69: =Statement!O187 -> 682 | ... L69: =Statement!Q187 -> 1937
B70: ROA | C70: =Statement!H123 -> 0 | D70: =Statement!I123 -> 0 | E70: =Statement!J123 -> 0 | F70: =Statement!K123 -> 0 | G70: =Statement!L123 -> 0 | H70: =Statement!M123 -> -0.09093301 | I70: =Statement!N123 -> -0.079713975 | J70: =Statement!O123 -> 0.016842478 | ... L70: =Statement!Q123 -> 0.078991277
B71: ROE | C71: =Statement!H125 -> 0 | D71: =Statement!I125 -> 0 | E71: =Statement!J125 -> 0 | F71: =Statement!K125 -> 0 | G71: =Statement!L125 -> 0 | H71: =Statement!M125 -> -0.11720943 | I71: =Statement!N125 -> -0.10989931 | J71: =Statement!O125 -> 0.024511023 | ... L71: =Statement!Q125 -> 0.11682576
B72: ROIC | C72: =Statement!H136 -> 0 | D72: =Statement!I136 -> 0 | E72: =Statement!J136 -> 0 | F72: =Statement!K136 -> 0 | G72: =Statement!L136 -> 0 | H72: =Statement!M136 -> 1.4683845 | I72: =Statement!N136 -> 0.98627878 | J72: =Statement!O136 -> 0.14394902 | ... L72: =Statement!Q136 -> 1.6371014
B73: Price 5y | C73: =Statement!H203 -> 0 | D73: =Statement!I203 -> 0 | E73: =Statement!J203 -> 0 | F73: =Statement!K203 -> 0 | G73: =Statement!L203 -> 0 | H73: =Statement!M203 -> 100 | I73: =Statement!N203 -> 64.324471 | J73: =Statement!O203 -> 205.1456 | ... L73: =Statement!Q203 -> 160.19172
B74: Revenue 5y | C74: =Statement!H204 -> 0 | D74: =Statement!I204 -> 0 | E74: =Statement!J204 -> 0 | F74: =Statement!K204 -> 0 | G74: =Statement!L204 -> 0 | H74: =Statement!M204 -> 100 | I74: =Statement!N204 -> 147.343 | J74: =Statement!O204 -> 211.78959 | ... L74: =Statement!Q204 -> 413.75792
B75: EPS 5y | C75: =Statement!H205 -> 0 | D75: =Statement!I205 -> 0 | E75: =Statement!J205 -> 0 | F75: =Statement!K205 -> 0 | G75: =Statement!L205 -> 0 | H75: =Statement!M205 -> 100 | I75: =Statement!N205 -> 141.24514 | J75: =Statement!O205 -> 213.61868 | ... L75: =Statement!Q205 -> 326.7323

Sheet Graphs Quarter
C55: =Statement!T2 -> 30.09.2024 | D55: =Statement!U2 -> 31.12.2024 | E55: =Statement!V2 -> 31.03.2025 | F55: =Statement!W2 -> 30.06.2025 | G55: =Statement!X2 -> 30.09.2025 | H55: =Statement!Y2 -> 31.12.2025 | I55: =Statement!Z2 -> 31.03.2026 | J55: =Statement!AA2 -> 30.06.2026
C56: =Statement!T3 -> Q3 2024 | D56: =Statement!U3 -> Q4 2024 | E56: =Statement!V3 -> Q1 2025 | F56: =Statement!W3 -> Q2 2025 | G56: =Statement!X3 -> Q3 2025 | H56: =Statement!Y3 -> Q4 2025 | I56: =Statement!Z3 -> Q1 2026 | J56: =Statement!AA3 -> Q2 2026
B57: Revenue | C57: =Statement!T5 -> 192594 | D57: =Statement!U5 -> 209550 | E57: =Statement!V5 -> 230743 | F57: =Statement!W5 -> 252265 | G57: =Statement!X5 -> 271713 | H57: =Statement!Y5 -> 282868 | I57: =Statement!Z5 -> 291967 | J57: =Statement!AA5 -> 298454
B58: Operating income | C58: =Statement!T12 -> 13574 | D58: =Statement!U12 -> 13882 | E58: =Statement!V12 -> 23594 | F58: =Statement!W12 -> 33363 | G58: =Statement!X12 -> 35159 | H58: =Statement!Y12 -> 43454 | I58: =Statement!Z12 -> 44527 | J58: =Statement!AA12 -> 33945
B59: Net income | C59: =Statement!T18 -> 23360 | D59: =Statement!U18 -> 13907 | E59: =Statement!V18 -> 35135 | F59: =Statement!W18 -> 44781 | G59: =Statement!X18 -> 35495 | H59: =Statement!Y18 -> 41954 | I59: =Statement!Z18 -> 43460 | J59: =Statement!AA18 -> 33158
B60: Gross margin | C60: =Statement!T101 -> 0.72906736 | D60: =Statement!U101 -> 0.7188022 | E60: =Statement!V101 -> 0.7111635 | F60: =Statement!W101 -> 0.72376667 | G60: =Statement!X101 -> 0.72470217 | H60: =Statement!Y101 -> 0.72779176 | I60: =Statement!Z101 -> 0.72986331 | J60: =Statement!AA101 -> 0.72620906
B61: Operating margin | C61: =Statement!T102 -> 0.07047987 | D61: =Statement!U102 -> 0.066246719 | E61: =Statement!V102 -> 0.10225229 | F61: =Statement!W102 -> 0.13225378 | G61: =Statement!X102 -> 0.12939756 | H61: =Statement!Y102 -> 0.15361936 | I61: =Statement!Z102 -> 0.15250696 | J61: =Statement!AA102 -> 0.11373612
B62: Net margin | C62: =Statement!T103 -> 0.12129142 | D62: =Statement!U103 -> 0.066366022 | E62: =Statement!V103 -> 0.15226897 | F62: =Statement!W103 -> 0.17751571 | G62: =Statement!X103 -> 0.13063416 | H62: =Statement!Y103 -> 0.14831653 | I62: =Statement!Z103 -> 0.14885244 | J62: =Statement!AA103 -> 0.1110992
B63: ="Revenue "&Statement!B183 -> Revenue Subscription | C63: =Statement!T183 -> 157617 | D63: =Statement!U183 -> 174317 | E63: =Statement!V183 -> 190987 | F63: =Statement!W183 -> 210678 | G63: =Statement!X183 -> 229491 | H63: =Statement!Y183 -> 242286 | I63: =Statement!Z183 -> 250908 | J63: =Statement!AA183 -> 258035
B64: ="Revenue "&Statement!B184 -> Revenue Advertising | C64: =Statement!T184 -> 14405 | D64: =Statement!U184 -> 14292 | E64: =Statement!V184 -> 17882 | F64: =Statement!W184 -> 20603 | G64: =Statement!X184 -> 21019 | H64: =Statement!Y184 -> 20221 | I64: =Statement!Z184 -> 20614 | J64: =Statement!AA184 -> 21052
B65: ="Revenue "&Statement!B185 -> Revenue English test | C65: =Statement!T185 -> 10772 | D65: =Statement!U185 -> 11415 | E65: =Statement!V185 -> 11986 | F65: =Statement!W185 -> 10088 | G65: =Statement!X185 -> 9649 | H65: =Statement!Y185 -> 10283 | I65: =Statement!Z185 -> 11317 | J65: =Statement!AA185 -> 10109
B66: ="Revenue "&Statement!B186 -> Revenue In-App purchases | C66: =Statement!T186 -> 9411 | D66: =Statement!U186 -> 9142 | E66: =Statement!V186 -> 9442 | F66: =Statement!W186 -> 10390 | G66: =Statement!X186 -> 11096 | H66: =Statement!Y186 -> 9551 | I66: =Statement!Z186 -> 8446 | J66: =Statement!AA186 -> 8002
B67: ="Revenue "&Statement!B187 -> Revenue Other | C67: =Statement!T187 -> 389 | D67: =Statement!U187 -> 384 | E67: =Statement!V187 -> 446 | F67: =Statement!W187 -> 506 | G67: =Statement!X187 -> 458 | H67: =Statement!Y187 -> 527 | I67: =Statement!Z187 -> 682 | J67: =Statement!AA187 -> 1256
B68: FCFE | C68: =Statement!T153 -> 22285 | D68: =Statement!U153 -> 51117 | E68: =Statement!V153 -> 71994 | F68: =Statement!W153 -> 51732 | G68: =Statement!X153 -> 41791 | H68: =Statement!Y153 -> 57470 | I68: =Statement!Z153 -> 113139 | J68: =Statement!AA153 -> 40420

Sheet Forecast ->
H5: Links
H6: Overview'!B3
H7: Financials ->'!B13
H8: Analysis ->'!B13
H9: Forecast ->'!B13
H10: Valuation ->'!B13
B13: Forecast ->

Sheet Revenue
B1: Revenue forecast
C2: History | H2: Forecast | S2: History | AA2: Forecast | AE2: TTM/YTD
C4: Revenues | S4: Revenues
B5: Revenues (thousand) | C5: =Statement!M3 -> 2021 | D5: =Statement!N3 -> 2022 | E5: =Statement!O3 -> 2023 | F5: =Statement!P3 -> 2024 | G5: =Statement!Q3 -> 2025 | H5: =G5+1 -> 2026 | I5: =H5+1 -> 2027 | J5: =I5+1 -> 2028 | K5: =J5+1 -> 2029 | L5: =K5+1 -> 2030 | R5: =B5 -> Revenues (thousand) | S5: =Statement!T3 -> Q3 2024 | T5: =Statement!U3 -> Q4 2024 | U5: =Statement!V3 -> Q1 2025 | V5: =Statement!W3 -> Q2 2025 | W5: =Statement!X3 -> Q3 2025 | X5: =Statement!Y3 -> Q4 2025 | Y5: =Statement!Z3 -> Q1 2026 | Z5: =Statement!AA3 -> Q2 2026 | AA5: FQ1 | AB5: FQ2 | AC5: FQ3 | AE5: FQ1
B6: =Statement!B183 -> Subscription | C6: =Statement!M183 -> 180698 | D6: =Statement!N183 -> 273507 | E6: =Statement!O183 -> 404684 | F6: =Statement!P183 -> 607531 | G6: =Statement!Q183 -> 873442 | H6: =H37*H34 -> 1024390.1 | I6: =I37*I34 -> 1165141.3 | J6: =J37*J34 -> 1488468 | K6: =K37*K34 -> 2031452.9 | L6: =L37*L34 -> 2773542.7 | N6: Avg revenue/Paid user * Paid subscribers | Q6: Avg revenue/Paid user * Paid subscribers | R6: =B6 -> Subscription | S6: =Statement!T183 -> 157617 | T6: =Statement!U183 -> 174317 | U6: =Statement!V183 -> 190987 | V6: =Statement!W183 -> 210678 | W6: =Statement!X183 -> 229491 | X6: =Statement!Y183 -> 242286 | Y6: =Statement!Z183 -> 250908 | Z6: =Statement!AA183 -> 258035 | AA6: =AA37*AA34 -> 258876.8 | AE6: =SUM(X6:AA6) -> 1010105.8
B7: =Statement!B184 -> Advertising | C7: =Statement!M184 -> 38501 | D7: =Statement!N184 -> 44731 | E7: =Statement!O184 -> 49858 | F7: =Statement!P184 -> 54907 | G7: =Statement!Q184 -> 79725 | H7: =H35*H31 -> 101116.2 | I7: =I35*I31 -> 124816.88 | J7: =J35*J31 -> 150067.49 | K7: =K35*K31 -> 188412.22 | L7: =L35*L31 -> 232290.48 | N7: Free users * Ad revenue/Free user | Q7: Free users * Ad revenue/Free user | R7: =B7 -> Advertising | S7: =Statement!T184 -> 14405 | T7: =Statement!U184 -> 14292 | U7: =Statement!V184 -> 17882 | V7: =Statement!W184 -> 20603 | W7: =Statement!X184 -> 21019 | X7: =Statement!Y184 -> 20221 | Y7: =Statement!Z184 -> 20614 | Z7: =Statement!AA184 -> 21052 | AA7: =AA35*AA31 -> 22657.627 | AE7: =SUM(X7:AA7) -> 84544.627
B8: =Statement!B185 -> English test | C8: =Statement!M185 -> 24658 | D8: =Statement!N185 -> 32718 | E8: =Statement!O185 -> 41212 | F8: =Statement!P185 -> 45640 | G8: =Statement!Q185 -> 42006 | H8: =G8*(1+H25) -> 39905.7 | I8: =H8*(1+I25) -> 39107.586 | J8: =I8*(1+J25) -> 40280.814 | K8: =J8*(1+K25) -> 42697.662 | L8: =K8*(1+L25) -> 46113.475 | N8: English test growth rate | Q8: English test growth rate | R8: =B8 -> English test | S8: =Statement!T185 -> 10772 | T8: =Statement!U185 -> 11415 | U8: =Statement!V185 -> 11986 | V8: =Statement!W185 -> 10088 | W8: =Statement!X185 -> 9649 | X8: =Statement!Y185 -> 10283 | Y8: =Statement!Z185 -> 11317 | Z8: =Statement!AA185 -> 10109 | AA8: =Z8*(1+AA25) -> 10614.45 | AE8: =SUM(X8:AA8) -> 42323.45
B9: =Statement!B186 -> In-App purchases | C9: =Statement!M186 -> 6915 | D9: =Statement!N186 -> 18539 | E9: =Statement!O186 -> 34673 | F9: =Statement!P186 -> 38653 | G9: =Statement!Q186 -> 40479 | H9: =H27*H36 -> 44900.4 | I9: =I27*I36 -> 51382.5 | J9: =J27*J36 -> 60236.1 | K9: =K27*K36 -> 82874.834 | L9: =L27*L36 -> 106079.79 | N9: DAU * In-app purchases % of DAU | Q9: DAU * In-app purchases % of DAU | R9: =B9 -> In-App purchases | S9: =Statement!T186 -> 9411 | T9: =Statement!U186 -> 9142 | U9: =Statement!V186 -> 9442 | V9: =Statement!W186 -> 10390 | W9: =Statement!X186 -> 11096 | X9: =Statement!Y186 -> 9551 | Y9: =Statement!Z186 -> 8446 | Z9: =Statement!AA186 -> 8002 | AA9: =AA27*AA36 -> 7607.52 | AE9: =SUM(X9:AA9) -> 33606.52
B10: =Statement!B187 -> Other | C10: =Statement!M187 -> 79 | D10: =Statement!N187 -> 625 | E10: =Statement!O187 -> 682 | F10: =Statement!P187 -> 1293 | G10: =Statement!Q187 -> 1937 | H10: =G10*(1+H26) -> 2808.65 | I10: =H10*(1+I26) -> 3791.6775 | J10: =I10*(1+J26) -> 4929.1808 | K10: =J10*(1+K26) -> 6161.4759 | L10: =K10*(1+L26) -> 7393.7711 | N10: Other growth rate | Q10: Other growth rate | R10: =B10 -> Other | S10: =Statement!T187 -> 389 | T10: =Statement!U187 -> 384 | U10: =Statement!V187 -> 446 | V10: =Statement!W187 -> 506 | W10: =Statement!X187 -> 458 | X10: =Statement!Y187 -> 527 | Y10: =Statement!Z187 -> 682 | Z10: =Statement!AA187 -> 1256 | AA10: =Z10*(1+AA26) -> 1142.96 | AE10: =SUM(X10:AA10) -> 3607.96
B11: Total | C11: =Statement!M5 -> 250772 | D11: =Statement!N5 -> 369495 | E11: =Statement!O5 -> 531109 | F11: =Statement!P5 -> 748024 | G11: =Statement!Q5 -> 1037589 | H11: =SUM(H6:H10) -> 1213121 | I11: =SUM(I6:I10) -> 1384239.9 | J11: =SUM(J6:J10) -> 1743981.6 | K11: =SUM(K6:K10) -> 2351599.1 | L11: =SUM(L6:L10) -> 3165420.2 | R11: Total | S11: =Statement!T5 -> 192594 | T11: =Statement!U5 -> 209550 | U11: =Statement!V5 -> 230743 | V11: =Statement!W5 -> 252265 | W11: =Statement!X5 -> 271713 | X11: =Statement!Y5 -> 282868 | Y11: =Statement!Z5 -> 291967 | Z11: =Statement!AA5 -> 298454 | AA11: =SUM(AA6:AA10) -> 300899.36 | AE11: =SUM(X11:AA11) -> 1174188.4
C13: Growth rates | S13: Growth rates
B14: Revenue growth % | C14: =C5 -> 2021 | D14: =D5 -> 2022 | E14: =E5 -> 2023 | F14: =F5 -> 2024 | G14: =G5 -> 2025 | H14: =H5 -> 2026 | I14: =I5 -> 2027 | J14: =J5 -> 2028 | ... L14: =L5 -> 2030 | R14: Revenue growth % | S14: =S5 -> Q3 2024 | T14: =T5 -> Q4 2024 | U14: =U5 -> Q1 2025 | V14: =V5 -> Q2 2025 | W14: =W5 -> Q3 2025 | X14: =X5 -> Q4 2025 | Y14: =Y5 -> Q1 2026 | Z14: =Z5 -> Q2 2026 | ... AC14: =AC5 -> FQ3
B15: =B6 -> Subscription | D15: =D6/C6-1 -> 0.51361388 | E15: =E6/D6-1 -> 0.47961113 | F15: =F6/E6-1 -> 0.50124789 | G15: =G6/F6-1 -> 0.43769125 | H15: =H6/G6-1 -> 0.17281981 | I15: =I6/H6-1 -> 0.1374 | J15: =J6/I6-1 -> 0.2775 | K15: =K6/J6-1 -> 0.36479452 | L15: =L6/K6-1 -> 0.3653 | R15: =R6 -> Subscription | T15: =T6/S6-1 -> 0.10595304 | U15: =U6/T6-1 -> 0.095630375 | V15: =V6/U6-1 -> 0.10310126 | W15: =W6/V6-1 -> 0.089297411 | X15: =X6/W6-1 -> 0.05575382 | Y15: =Y6/X6-1 -> 0.035586043 | Z15: =Z6/Y6-1 -> 0.028404834 | AA15: =AA6/Z6-1 -> 0.0032623481
B16: =B7 -> Advertising | D16: =D7/C7-1 -> 0.16181398 | E16: =E7/D7-1 -> 0.1146185 | F16: =F7/E7-1 -> 0.1012676 | G16: =G7/F7-1 -> 0.45200066 | H16: =H7/G7-1 -> 0.26831237 | I16: =I7/H7-1 -> 0.23439052 | J16: =J7/I7-1 -> 0.20230118 | K16: =K7/J7-1 -> 0.2555166 | L16: =L7/K7-1 -> 0.23288436 | R16: =R7 -> Advertising | T16: =T7/S7-1 -> -0.0078444984 | U16: =U7/T7-1 -> 0.25118948 | V16: =V7/U7-1 -> 0.15216419 | W16: =W7/V7-1 -> 0.020191234 | X16: =X7/W7-1 -> -0.03796565 | Y16: =Y7/X7-1 -> 0.019435241 | Z16: =Z7/Y7-1 -> 0.021247696 | AA16: =AA7/Z7-1 -> 0.07626958
B17: =B8 -> English test | D17: =D8/C8-1 -> 0.3268716 | E17: =E8/D8-1 -> 0.25961245 | F17: =F8/E8-1 -> 0.10744443 | G17: =G8/F8-1 -> -0.079623138 | H17: =H8/G8-1 -> -0.05 | I17: =I8/H8-1 -> -0.02 | J17: =J8/I8-1 -> 0.03 | K17: =K8/J8-1 -> 0.06 | L17: =L8/K8-1 -> 0.08 | R17: =R8 -> English test | T17: =T8/S8-1 -> 0.059691794 | U17: =U8/T8-1 -> 0.050021901 | V17: =V8/U8-1 -> -0.15835141 | W17: =W8/V8-1 -> -0.04351705 | X17: =X8/W8-1 -> 0.065706291 | Y17: =Y8/X8-1 -> 0.10055431 | Z17: =Z8/Y8-1 -> -0.10674207 | AA17: =AA8/Z8-1 -> 0.05
B18: =B9 -> In-App purchases | D18: =D9/C9-1 -> 1.6809834 | E18: =E9/D9-1 -> 0.87027348 | F18: =F9/E9-1 -> 0.11478672 | G18: =G9/F9-1 -> 0.047240835 | H18: =H9/G9-1 -> 0.10922701 | I18: =I9/H9-1 -> 0.1443662 | J18: =J9/I9-1 -> 0.17230769 | K18: =K9/J9-1 -> 0.37583333 | L18: =L9/K9-1 -> 0.28 | R18: =R9 -> In-App purchases | T18: =T9/S9-1 -> -0.028583572 | U18: =U9/T9-1 -> 0.032815576 | V18: =V9/U9-1 -> 0.10040246 | W18: =W9/V9-1 -> 0.067949952 | X18: =X9/W9-1 -> -0.13923937 | Y18: =Y9/X9-1 -> -0.11569469 | Z18: =Z9/Y9-1 -> -0.052569264 | AA18: =AA9/Z9-1 -> -0.049297676
B19: =B10 -> Other | D19: =D10/C10-1 -> 6.9113924 | E19: =E10/D10-1 -> 0.0912 | F19: =F10/E10-1 -> 0.89589443 | G19: =G10/F10-1 -> 0.49806651 | H19: =H10/G10-1 -> 0.45 | I19: =I10/H10-1 -> 0.35 | J19: =J10/I10-1 -> 0.3 | K19: =K10/J10-1 -> 0.25 | L19: =L10/K10-1 -> 0.2 | R19: =R10 -> Other | T19: =T10/S10-1 -> -0.01285347 | U19: =U10/T10-1 -> 0.16145833 | V19: =V10/U10-1 -> 0.13452915 | W19: =W10/V10-1 -> -0.09486166 | X19: =X10/W10-1 -> 0.15065502 | Y19: =Y10/X10-1 -> 0.29411765 | Z19: =Z10/Y10-1 -> 0.84164223 | AA19: =AA10/Z10-1 -> -0.09
B20: =B11 -> Total | D20: =D11/C11-1 -> 0.47343005 | E20: =E11/D11-1 -> 0.43739157 | F20: =F11/E11-1 -> 0.40841899 | G20: =G11/F11-1 -> 0.38710656 | H20: =H11/G11-1 -> 0.16917299 | I20: =I11/H11-1 -> 0.14105673 | J20: =J11/I11-1 -> 0.25988388 | K20: =K11/J11-1 -> 0.34840826 | L20: =L11/K11-1 -> 0.34607135 | R20: =R11 -> Total | T20: =T11/S11-1 -> 0.088040126 | U20: =U11/T11-1 -> 0.10113577 | V20: =V11/U11-1 -> 0.093272602 | W20: =W11/V11-1 -> 0.077093533 | X20: =X11/W11-1 -> 0.041054348 | Y20: =Y11/X11-1 -> 0.032166947 | Z20: =Z11/Y11-1 -> 0.022218264 | AA20: =AA11/Z11-1 -> 0.0081934141
C23: Drivers and metrics | S23: Drivers and metrics | AE23: =AE2 -> TTM/YTD
B24: Metric (thousand) | C24: =C5 -> 2021 | D24: =D5 -> 2022 | E24: =E5 -> 2023 | F24: =F5 -> 2024 | G24: =G5 -> 2025 | H24: =H5 -> 2026 | I24: =I5 -> 2027 | J24: =J5 -> 2028 | ... L24: =L5 -> 2030 | R24: Metric (thousand) | S24: =S5 -> Q3 2024 | T24: =T5 -> Q4 2024 | U24: =U5 -> Q1 2025 | V24: =V5 -> Q2 2025 | W24: =W5 -> Q3 2025 | X24: =X5 -> Q4 2025 | Y24: =Y5 -> Q1 2026 | Z24: =Z5 -> Q2 2026 | ... AC24: =AC5 -> FQ3 | AE24: =AE5 -> FQ1
B25: English test growth rate | D25: =D17 -> 0.3268716 | E25: =E17 -> 0.25961245 | F25: =F17 -> 0.10744443 | G25: =G17 -> -0.079623138 | H25: -0.05 | I25: -0.02 | J25: 0.03 | K25: 0.06 | L25: 0.08 | R25: English test growth rate | T25: =T17 -> 0.059691794 | U25: =U17 -> 0.050021901 | V25: =V17 -> -0.15835141 | W25: =W17 -> -0.04351705 | X25: =X17 -> 0.065706291 | Y25: =Y17 -> 0.10055431 | Z25: =Z17 -> -0.10674207 | AA25: 0.05
B26: Other growth rate | D26: =D19 -> 6.9113924 | E26: =E19 -> 0.0912 | F26: =F19 -> 0.89589443 | G26: =G19 -> 0.49806651 | H26: 0.45 | I26: 0.35 | J26: 0.3 | K26: 0.25 | L26: 0.2 | R26: Other growth rate | T26: =T19 -> -0.01285347 | U26: =U19 -> 0.16145833 | V26: =V19 -> 0.13452915 | W26: =W19 -> -0.09486166 | X26: =X19 -> 0.15065502 | Y26: =Y19 -> 0.29411765 | Z26: =Z19 -> 0.84164223 | AA26: -0.09
B27: DAU | C27: =Statement!M209 -> 9600 | D27: =Statement!N209 -> 16300 | E27: =Statement!O209 -> 26900 | F27: =Statement!P209 -> 40500 | G27: =Statement!Q209 -> 52700 | H27: =G27*(1+H29) -> 63240 | I27: =H27*(1+I29) -> 79050 | J27: =I27*(1+J29) -> 100393.5 | K27: =J27*(1+K29) -> 127499.74 | L27: =K27*(1+L29) -> 163199.67 | N27: DAU growth rate | Q27: DAU growth rate | R27: DAU | S27: =Statement!T209 -> 37200 | T27: =Statement!U209 -> 40500 | U27: =Statement!V209 -> 46600 | V27: =Statement!W209 -> 47700 | W27: =Statement!X209 -> 50500 | X27: =Statement!Y209 -> 52700 | Y27: =Statement!Z209 -> 56500 | Z27: =Statement!AA209 -> 58700 | AA27: =Z27*(1+AA29) -> 63396 | AE27: =AA27 -> 63396
B28: MAU | C28: =Statement!M210 -> 40500 | D28: =Statement!N210 -> 60700 | E28: =Statement!O210 -> 88400 | F28: =Statement!P210 -> 116700 | G28: =Statement!Q210 -> 133100 | H28: =G28*(1+H30) -> 158389 | I28: =H28*(1+I30) -> 191650.69 | J28: =I28*(1+J30) -> 234772.1 | K28: =J28*(1+K30) -> 288769.68 | L28: =K28*(1+L30) -> 355186.7 | N28: MAU growth rate | Q28: MAU growth rate | R28: MAU | S28: =Statement!T210 -> 113100 | T28: =Statement!U210 -> 116700 | U28: =Statement!V210 -> 130200 | V28: =Statement!W210 -> 128300 | W28: =Statement!X210 -> 135300 | X28: =Statement!Y210 -> 133100 | Y28: =Statement!Z210 -> 137800 | Z28: =Statement!AA210 -> 140600 | AA28: =Z28*(1+AA30) -> 146224 | AE28: =AA28 -> 146224
B29: DAU growth rate | D29: =D27/C27-1 -> 0.69791667 | E29: =E27/D27-1 -> 0.65030675 | F29: =F27/E27-1 -> 0.50557621 | G29: =G27/F27-1 -> 0.30123457 | H29: 0.2 | I29: 0.25 | J29: 0.27 | K29: 0.27 | L29: 0.28 | R29: DAU growth rate | T29: =T27/S27-1 -> 0.088709677 | U29: =U27/T27-1 -> 0.15061728 | V29: =V27/U27-1 -> 0.02360515 | W29: =W27/V27-1 -> 0.05870021 | X29: =X27/W27-1 -> 0.043564356 | Y29: =Y27/X27-1 -> 0.072106262 | Z29: =Z27/Y27-1 -> 0.038938053 | AA29: 0.08
B30: MAU growth rate | D30: =D28/C28-1 -> 0.49876543 | E30: =E28/D28-1 -> 0.45634267 | F30: =F28/E28-1 -> 0.32013575 | G30: =G28/F28-1 -> 0.14053128 | H30: 0.19 | I30: 0.21 | J30: 0.225 | K30: 0.23 | L30: 0.23 | R30: MAU growth rate | T30: =T28/S28-1 -> 0.031830239 | U30: =U28/T28-1 -> 0.11568123 | V30: =V28/U28-1 -> -0.014592934 | W30: =W28/V28-1 -> 0.054559626 | X30: =X28/W28-1 -> -0.016260163 | Y30: =Y28/X28-1 -> 0.035311796 | Z30: =Z28/Y28-1 -> 0.020319303 | AA30: 0.04
B31: Ad revenue/Free user | C31: =Statement!M216 -> 1.0131842 | D31: =Statement!N216 -> 0.79169912 | E31: =Statement!O216 -> 0.609511 | F31: =Statement!P216 -> 0.51219216 | G31: =Statement!Q216 -> 0.65942928 | H31: 0.7 | I31: 0.71 | J31: 0.7 | K31: 0.72 | L31: 0.73 | R31: Ad revenue/Free user | S31: =Statement!T216 -> 0.13784689 | T31: =Statement!U216 -> 0.1333209 | U31: =Statement!V216 -> 0.14914095 | V31: =Statement!W216 -> 0.17549404 | W31: =Statement!X216 -> 0.16978191 | X31: =Statement!Y216 -> 0.16725393 | Y31: =Statement!Z216 -> 0.16451716 | Z31: =Statement!AA216 -> 0.16459734 | AA31: 0.17 | AE31: =AE7/AE35 -> 0.63433768
B32: Subscribers to MAU ratio | C32: =Statement!M215 -> 0.061728395 | D32: =Statement!N215 -> 0.069192751 | E32: =Statement!O215 -> 0.074660633 | F32: =Statement!P215 -> 0.081405313 | G32: =Statement!Q215 -> 0.091660406 | H32: =G32*(1+H33) -> 0.087993989 | I32: =H32*(1+I33) -> 0.08271435 | J32: =I32*(1+J33) -> 0.086850068 | K32: =J32*(1+K33) -> 0.093798073 | L32: =K32*(1+L33) -> 0.10411586 | N32: Subscribers to MAU growth | Q32: Subscribers to MAU growth | R32: Subscribers to MAU ratio | S32: =Statement!T215 -> 0.076038904 | T32: =Statement!U215 -> 0.081405313 | U32: =Statement!V215 -> 0.079109063 | V32: =Statement!W215 -> 0.084957132 | W32: =Statement!X215 -> 0.084996305 | X32: =Statement!Y215 -> 0.091660406 | Y32: =Statement!Z215 -> 0.090711176 | Z32: =Statement!AA215 -> 0.090327169 | AA32: =Z32*(1+AA33) -> 0.088520626
B33: Subscribers to MAU growth | D33: =D32/C32-1 -> 0.12092257 | E33: =E32/D32-1 -> 0.079023917 | F33: =F32/E32-1 -> 0.090337826 | G33: =G32/F32-1 -> 0.12597572 | H33: -0.04 | I33: -0.06 | J33: 0.05 | K33: 0.08 | L33: 0.11 | R33: Subscribers to MAU growth | T33: -1 | U33: =U32/T32-1 -> -0.028207616 | V33: =V32/U32-1 -> 0.073924131 | W33: =W32/V32-1 -> 0.00046108885 | X33: =X32/W32-1 -> 0.078404599 | Y33: =Y32/X32-1 -> -0.010355945 | Z33: =Z32/Y32-1 -> -0.0042332859 | AA33: -0.02
B34: Paid subscribers | C34: =Statement!M211 -> 2500 | D34: =Statement!N211 -> 4200 | E34: =Statement!O211 -> 6600 | F34: =Statement!P211 -> 9500 | G34: =Statement!Q211 -> 12200 | H34: =H32*H28 -> 13937.28 | I34: =I32*I28 -> 15852.262 | J34: =J32*J28 -> 20389.972 | K34: =K32*K28 -> 27086.039 | L34: =L32*L28 -> 36980.569 | N34: Subscribers to MAU ratio * MAU | Q34: Subscribers to MAU ratio * MAU | R34: Paid subscribers | S34: =Statement!T211 -> 8600 | T34: =Statement!U211 -> 9500 | U34: =Statement!V211 -> 10300 | V34: =Statement!W211 -> 10900 | W34: =Statement!X211 -> 11500 | X34: =Statement!Y211 -> 12200 | Y34: =Statement!Z211 -> 12500 | Z34: =Statement!AA211 -> 12700 | AA34: =AA32*AA28 -> 12943.84 | AE34: =AA34 -> 12943.84
B35: Free users | C35: =Statement!M212 -> 38000 | D35: =Statement!N212 -> 56500 | E35: =Statement!O212 -> 81800 | F35: =Statement!P212 -> 107200 | G35: =Statement!Q212 -> 120900 | H35: =H28-H34 -> 144451.72 | I35: =I28-I34 -> 175798.43 | J35: =J28-J34 -> 214382.12 | K35: =K28-K34 -> 261683.64 | L35: =L28-L34 -> 318206.13 | N35: MAU - Paid subscribers | Q35: MAU - Paid subscribers | R35: Free users | S35: =Statement!T212 -> 104500 | T35: =Statement!U212 -> 107200 | U35: =Statement!V212 -> 119900 | V35: =Statement!W212 -> 117400 | W35: =Statement!X212 -> 123800 | X35: =Statement!Y212 -> 120900 | Y35: =Statement!Z212 -> 125300 | Z35: =Statement!AA212 -> 127900 | AA35: =AA28-AA34 -> 133280.16 | AE35: =AA35 -> 133280.16
B36: In-App purchases % of DAU | C36: =Statement!M217 -> 0.7203125 | D36: =Statement!N217 -> 1.137362 | E36: =Statement!O217 -> 1.2889591 | F36: =Statement!P217 -> 0.95439506 | G36: =Statement!Q217 -> 0.76810247 | H36: 0.71 | I36: 0.65 | J36: 0.6 | K36: 0.65 | L36: 0.65 | R36: In-App purchases % of DAU | S36: =Statement!T217 -> 0.25298387 | T36: =Statement!U217 -> 0.2257284 | U36: =Statement!V217 -> 0.20261803 | V36: =Statement!W217 -> 0.21781971 | W36: =Statement!X217 -> 0.21972277 | X36: =Statement!Y217 -> 0.1812334 | Y36: =Statement!Z217 -> 0.14948673 | Z36: =Statement!AA217 -> 0.13632027 | AA36: 0.12
