Workbook

Sheet Overview
B2: Automatic Data | E2: At a glance | H2: Valuation | K2: Links
B3: Company | C3: #VALUE! | E3: Market capitalization | F3: =Statement!AC153 -> 1035640.2 | H3: ='AVG target price'!B5 -> DCF price | I3: ='AVG target price'!C5 -> 928.67184 | K3: Financials ->'!B13
B4: Ticker | C4: {=_FV(C3,"Ticker symbol",TRUE)} -> MU | E4: Enterprise value | F4: =Statement!AC154 -> 967366.2 | H4: ='AVG target price'!B6 -> EV/EBIT price | I4: ='AVG target price'!C6 -> 1281.1934 | K4: Analysis ->'!B13
B5: Price | C5: {=_FV(C3,"Price",TRUE)} -> 903.7 | E5: EPS | F5: =Statement!AC26 -> 74.21 | H5: ='AVG target price'!B7 -> PS price | I5: ='AVG target price'!C7 -> 567.445 | K5: Forecast ->'!B13
B6: Price Extended Hours | C6: {=_FV(C3,"Price (Extended hours)",TRUE)} -> 904.75 | E6: PE | F6: =Statement!AC150 -> 12.177604 | H6: ='AVG target price'!B8 -> EV/FCFF price | I6: ='AVG target price'!C8 -> 1729.7038 | K6: Valuation ->'!B13
B7: Day change | C7: {=_FV(C3,"Change")} -> 26.15 | E7: PS | F7: =Statement!AC151 -> 7.7554217 | H7: ='AVG target price'!B9 -> EV/Sales price | I7: ='AVG target price'!C9 -> 912.37103
B8: Day change extended | C8: {=_FV(C3,"Change (extended hours)",TRUE)} -> 1.05 | E8: FCF Yield | F8: =Statement!AC161 -> 0.055646739 | H8: ='AVG target price'!B10 -> AVG price | I8: ='AVG target price'!C10 -> 1083.877
B9: Day change % | C9: {=_FV(C3,"Change (%)",TRUE)} -> 0.029799 | E9: Earnings Yield | F9: =Statement!AC162 -> 0.082117959 | H9: ='AVG target price'!B12 -> Upside/Downside | I9: ='AVG target price'!C12 -> 0.19937703
B10: Day change extended % | C10: {=_FV(C3,"Change % (extended hours)",TRUE)} -> 0.001162 | E10: Buyback Yield | F10: =Statement!AC164 -> 0.0006276311
B11: 52 week high | C11: {=_FV(C3,"52 week high",TRUE)} -> 1255 | E11: Dividend Yield | F11: =Statement!AC163 -> 0.00062520748 | H11: DDM price | I11: =DDM!C26 -> 5.1961126
B12: 52 week low | C12: {=_FV(C3,"52 week low",TRUE)} -> 192.59 | E12: ROA | F12: =Statement!AC123 -> 0.43376317
B13: Beta | C13: {=_FV(C3,"Beta")} -> 2.3616 | E13: ROE | F13: =Statement!AC125 -> 0.61403547 | H13: Reverse DCF rate | I13: ='Reverse DCF'!C17 -> 0.24
B14: Avg volume | C14: {=_FV(C3,"Volume average",TRUE)} -> 26399323 | E14: ROIC | F14: =Statement!AC140 -> 1.2071782 | H14: Reverse DCF price | I14: ='Reverse DCF'!C16 -> 881.76467
E15: Net Cash/Market Cap | F15: =Statement!AC176 -> 0.06592444
E16: Net Cash/Share | F16: =Statement!AC175 -> 60.472985 | H16: Discount rates used
B17: Unit data and other info | E17: Insider Ownership | F17: =Statement!AC171 -> 0.002617801 | H17: WACC | I17: =DCF!C15 -> 0.15559907
B18: Units | C18: M | E18: Net Trade Cycle | F18: =Statement!AC144 -> -74.647977 | H18: Cost of Equity | I18: =Multiples!C54 -> 0.156152
B19: Units conversion | C19: 1000000 | E19: Net Debt/Equity | F19: =Statement!AC146 -> -0.49338768
B20: Has operating lease | C20: Yes | E20: Quick Ratio | F20: =Statement!AC147 -> 3.9898843
B21: Has finance lease | C21: No
B22: Has debt | C22: Yes
B25: Constants | E25: 10 Year Bond Yield
B26: Default tax rate | C26: 0.21 | E26: #VALUE! | F26: {=_FV(E26,"Price")} -> 49.88
B27: Cost of debt | C27: 0.057 | E27: Percentage | F27: =F26/1000 -> 0.04988
B28: Manual WACC | C28: 0
B29: Manual Cost of Equity | C29: 0
B33: Info
B35: Mission: | C35: Transform how the world uses information to enrich life for all
B36: Auditor: | C36: PwC
B37: Business units: | C37: Cloud memory business unit (CMBU) - memory for large hyperscalers and HBM for datacenter customers
C38: Core datacenter business unit (CDBU) - memory for mid-tier cloud, enterprise and OEM datacenter customers and storage for all datacenter customers
C39: Mobile and client business unit (MCBU) - memory and storage for mobile and client
C40: Automotive and embedded business unit (AEBU) - memory and storage for automotive, industrial and consumer
B46: Notes
B48: Date: | C48: 30.09.2026 | E48: Q4 2026
B49: - | C49: In Q1 2027 gross margin will be 85.95% and Opex $2.35B
B50: - | C50: 26 signed agreements with customers in datacenter consumer and automotive fields representing more than 35% of revenue through 2030
B51: - | C51: Cloud memory revenue increased because of higher pricing and higher bit shipments
B52: - | C52: Datacenter revenue increased because of higher pricing and higher bit shipments
B53: - | C53: Mobile and client revenue increased because of higher pricing though they had lower bit shipments
...

Sheet Financials ->
H5: Links
H6: Overview'!B3
H7: Financials ->'!B13
H8: Analysis ->'!B13
H9: Forecast ->'!B13
H10: Valuation ->'!B13
B13: Financials ->

Sheet Statement
B2: Date | L2: 02.09.2021 | M2: 01.09.2022 | N2: 31.08.2023 | O2: 29.08.2024 | P2: 28.08.2025 | Q2: 03.09.2025 | T2: 28.11.2024 | U2: 27.02.2025 | V2: 29.05.2025 | W2: 28.08.2025 | X2: 27.11.2025 | Y2: 26.02.2026 | Z2: 28.05.2026 | AA2: 03.09.2026
B3: FY | L3: 2021 | M3: 2022 | N3: 2023 | O3: 2024 | P3: 2025 | Q3: 2026 | T3: Q1 2025 | U3: Q2 2025 | V3: Q3 2025 | W3: Q4 2025 | X3: Q1 2026 | Y3: Q2 2026 | Z3: Q3 2026 | AA3: Q4 2026 | AC3: TTM/YTD
B4: Income statement
B5: Revenue | L5: 27705 | M5: 30758 | N5: 15540 | O5: 25111 | P5: 37378 | Q5: 133188 | T5: 8709 | U5: 8053 | V5: 9301 | W5: 11315 | X5: 13643 | Y5: 23860 | Z5: 41456 | AA5: 54229 | AC5: =SUM(X5:AA5) -> 133188
B6: COGS | L6: 17282 | M6: 16860 | N6: 16956 | O6: 19498 | P6: 22505 | Q6: 25684 | T6: 5361 | U6: 5090 | V6: 5793 | W6: 6261 | X6: 5997 | Y6: 6105 | Z6: 6400 | AA6: 7182 | AC6: =SUM(X6:AA6) -> 25684
B7: Gross Profit | C7: =C5-C6 -> 0 | D7: =D5-D6 -> 0 | E7: =E5-E6 -> 0 | F7: =F5-F6 -> 0 | G7: =G5-G6 -> 0 | H7: =H5-H6 -> 0 | I7: =I5-I6 -> 0 | J7: =J5-J6 -> 0 | ... Q7: =Q5-Q6 -> 107504 | T7: =T5-T6 -> 3348 | U7: =U5-U6 -> 2963 | V7: =V5-V6 -> 3508 | W7: =W5-W6 -> 5054 | X7: =X5-X6 -> 7646 | Y7: =Y5-Y6 -> 17755 | Z7: =Z5-Z6 -> 35056 | AA7: =AA5-AA6 -> 47047 | AC7: =SUM(X7:AA7) -> 107504
B8: R&D | L8: 2663 | M8: 3116 | N8: 3114 | O8: 3430 | P8: 3798 | Q8: 5650 | T8: 888 | U8: 898 | V8: 965 | W8: 1047 | X8: 1171 | Y8: 1250 | Z8: 1316 | AA8: 1913 | AC8: =SUM(X8:AA8) -> 5650
B9: Sales and marketing | L9: 894 | M9: 1066 | N9: 920 | O9: 1129 | P9: 1205 | Q9: 1947 | T9: 288 | U9: 285 | V9: 318 | W9: 314 | X9: 337 | Y9: 344 | Z9: 407 | AA9: 859 | AC9: =SUM(X9:AA9) -> 1947
B10: Other income/expense | L10: =488+95 -> 583 | M10: =48-34 -> 14 | N10: =171+124 -> 295 | O10: -250 | P10: 100 | Q10: 567 | T10: -2 | U10: 7 | V10: 56 | W10: 39 | X10: 2 | Y10: 26 | Z10: 15 | AA10: 524 | AC10: =SUM(X10:AA10) -> 567
B11: OpEx | C11: =SUM(C8:C10) -> 0 | D11: =SUM(D8:D10) -> 0 | E11: =SUM(E8:E10) -> 0 | F11: =SUM(F8:F10) -> 0 | G11: =SUM(G8:G10) -> 0 | H11: =SUM(H8:H10) -> 0 | I11: =SUM(I8:I10) -> 0 | J11: =SUM(J8:J10) -> 0 | ... Q11: =SUM(Q8:Q10) -> 8164 | T11: =SUM(T8:T10) -> 1174 | U11: =SUM(U8:U10) -> 1190 | V11: =SUM(V8:V10) -> 1339 | W11: =SUM(W8:W10) -> 1400 | X11: =SUM(X8:X10) -> 1510 | Y11: =SUM(Y8:Y10) -> 1620 | Z11: =SUM(Z8:Z10) -> 1738 | AA11: =SUM(AA8:AA10) -> 3296 | AC11: =SUM(X11:AA11) -> 8164
B12: Operating income | L12: 6283 | M12: 9702 | N12: -5745 | O12: 1304 | P12: 9770 | Q12: 99340 | T12: 2174 | U12: 1773 | V12: 2169 | W12: 3654 | X12: 6136 | Y12: 16135 | Z12: 33318 | AA12: 43751 | AC12: =SUM(X12:AA12) -> 99340
B13: Interest income/expense | L13: =37-183 -> -146 | M13: =96-189 -> -93 | N13: =468-388 -> 80 | O13: =529-562 -> -33 | P13: =496-477 -> 19 | Q13: =1084-106 -> 978 | T13: =107-118 -> -11 | U13: =108-112 -> -4 | V13: =135-123 -> 12 | W13: =146-124 -> 22 | X13: =139-74 -> 65 | Y13: =155-32 -> 123 | Z13: 215 | AA13: 575 | AC13: =SUM(X13:AA13) -> 978
B14: Other income/expense | L14: 81 | M14: -38 | N14: 7 | O14: -31 | P14: -135 | Q14: -647 | T14: -11 | U14: -11 | V14: -68 | W14: -45 | X14: -140 | Y14: -98 | Z14: -321 | AA14: -88 | AC14: =SUM(X14:AA14) -> -647
B15: Income before taxes | L15: 6218 | M15: 9571 | N15: -5658 | O15: 1240 | P15: 9654 | Q15: 99671 | T15: 2152 | U15: 1758 | V15: 2113 | W15: 3631 | X15: 6061 | Y15: 16160 | Z15: 33212 | AA15: 44238 | AC15: =SUM(X15:AA15) -> 99671
B16: Income tax expense/benefit | L16: -394 | M16: -888 | N16: -177 | O16: -451 | P16: -1124 | Q16: -14761 | T16: -283 | U16: -177 | V16: -235 | W16: -429 | X16: -829 | Y16: -2371 | Z16: -4978 | AA16: -6583 | AC16: =SUM(X16:AA16) -> -14761
B17: Non-controlling interest | L17: 0 | M17: 0 | N17: 0 | O17: 0 | P17: 0 | Q17: 0 | T17: 0 | U17: 0 | V17: 0 | W17: 0 | X17: 0 | Y17: 0 | Z17: 0 | AA17: 0 | AC17: =SUM(X17:AA17) -> 0
B18: Net income | L18: 5861 | M18: 8687 | N18: -5833 | O18: 778 | P18: 8539 | Q18: 84969 | T18: 1870 | U18: 1583 | V18: 1885 | W18: 3201 | X18: 5240 | Y18: 13785 | Z18: 28243 | AA18: 37701 | AC18: =SUM(X18:AA18) -> 84969
B19: Basic Shares outstanding avg | L19: 1120 | M19: 1112 | N19: 1093 | O19: 1105 | P19: 1116 | Q19: 1127 | T19: 1111 | U19: 1115 | V19: 1118 | W19: 1120 | X19: 1125 | Y19: 1126 | Z19: 1128 | AA19: 1130 | AC19: =AVERAGE(X19:AA19) -> 1127.25
B20: Basic Shares outstanding avg adjusted | C20: =C19*C$85 -> 0 | D20: =D19*D$85 -> 0 | E20: =E19*E$85 -> 0 | F20: =F19*F$85 -> 0 | G20: =G19*G$85 -> 0 | H20: =H19*H$85 -> 0 | I20: =I19*I$85 -> 0 | J20: =J19*J$85 -> 0 | ... Q20: =Q19*Q$85 -> 1127 | T20: =T19*T$85 -> 1111 | U20: =U19*U$85 -> 1115 | V20: =V19*V$85 -> 1118 | W20: =W19*W$85 -> 1120 | X20: =X19*X$85 -> 1125 | Y20: =Y19*Y$85 -> 1126 | Z20: =Z19*Z$85 -> 1128 | AA20: =AA19*AA$85 -> 1130 | AC20: =AC19*AC$85 -> 1127.25
B21: Diluted Shares outstanding avg | L21: 1141 | M21: 1122 | N21: 1093 | O21: 1118 | P21: 1125 | Q21: 1143 | T21: 1122 | U21: 1123 | V21: 1125 | W21: 1131 | X21: 1138 | Y21: 1142 | Z21: 1145 | AA21: 1147 | AC21: =AVERAGE(X21:AA21) -> 1143
B22: Diluted Shares outstanding avg adjusted | C22: =C21*C$85 -> 0 | D22: =D21*D$85 -> 0 | E22: =E21*E$85 -> 0 | F22: =F21*F$85 -> 0 | G22: =G21*G$85 -> 0 | H22: =H21*H$85 -> 0 | I22: =I21*I$85 -> 0 | J22: =J21*J$85 -> 0 | ... Q22: =Q21*Q$85 -> 1143 | T22: =T21*T$85 -> 1122 | U22: =U21*U$85 -> 1123 | V22: =V21*V$85 -> 1125 | W22: =W21*W$85 -> 1131 | X22: =X21*X$85 -> 1138 | Y22: =Y21*Y$85 -> 1142 | Z22: =Z21*Z$85 -> 1145 | AA22: =AA21*AA$85 -> 1147 | AC22: =AC21*AC$85 -> 1143
B23: Basic EPS | L23: 5.23 | M23: 7.81 | N23: -5.34 | O23: 0.7 | P23: 7.65 | Q23: 75.38 | T23: 1.68 | U23: 1.42 | V23: 1.69 | W23: 2.86 | X23: 4.66 | Y23: 12.25 | Z23: 25.03 | AA23: 33.36 | AC23: =SUM(X23:AA23) -> 75.3
B24: Basic EPS adjusted | L24: =L23/L$85 -> 5.23 | M24: =M23/M$85 -> 7.81 | N24: =N23/N$85 -> -5.34 | O24: =O23/O$85 -> 0.7 | P24: =P23/P$85 -> 7.65 | Q24: =Q23/Q$85 -> 75.38 | T24: =T23/T$85 -> 1.68 | U24: =U23/U$85 -> 1.42 | V24: =V23/V$85 -> 1.69 | W24: =W23/W$85 -> 2.86 | X24: =X23/X$85 -> 4.66 | Y24: =Y23/Y$85 -> 12.25 | Z24: =Z23/Z$85 -> 25.03 | AA24: =AA23/AA$85 -> 33.36 | AC24: =AC23/AC$85 -> 75.3
B25: Diluted EPS | L25: 5.14 | M25: 7.75 | N25: -5.34 | O25: 0.7 | P25: 7.59 | Q25: 74.33 | T25: 1.67 | U25: 1.41 | V25: 1.68 | W25: 2.83 | X25: 4.6 | Y25: 12.07 | Z25: 24.67 | AA25: 32.87 | AC25: =SUM(X25:AA25) -> 74.21
B26: Diluted EPS adjusted | L26: =L25/L$85 -> 5.14 | M26: =M25/M$85 -> 7.75 | N26: =N25/N$85 -> -5.34 | O26: =O25/O$85 -> 0.7 | P26: =P25/P$85 -> 7.59 | Q26: =Q25/Q$85 -> 74.33 | T26: =T25/T$85 -> 1.67 | U26: =U25/U$85 -> 1.41 | V26: =V25/V$85 -> 1.68 | W26: =W25/W$85 -> 2.83 | X26: =X25/X$85 -> 4.6 | Y26: =Y25/Y$85 -> 12.07 | Z26: =Z25/Z$85 -> 24.67 | AA26: =AA25/AA$85 -> 32.87 | AC26: =AC25/AC$85 -> 74.21
B28: Balance sheet
B29: Cash and cash equivalents | L29: =7763+870 -> 8633 | M29: =8262+1069 -> 9331 | N29: =8577+1017 -> 9594 | O29: =7041+1065 -> 8106 | P29: =9642+665 -> 10307 | Q29: =38364+5070 -> 43434 | T29: =6693+895 -> 7588 | U29: =7552+663 -> 8215 | V29: =10163+648 -> 10811 | W29: =9642+665 -> 10307 | X29: =9731+587 -> 10318 | Y29: =13908+681 -> 14589 | Z29: =24995+1027 -> 26022 | AA29: =38364+5070 -> 43434 | AC29: =AA29 -> 43434
B30: Acc receivable | L30: 5311 | M30: 5130 | N30: 2443 | O30: 6615 | P30: 9265 | Q30: 36197 | T30: 7423 | U30: 6504 | V30: 7436 | W30: 9265 | X30: 10184 | Y30: 17314 | Z30: 31025 | AA30: 36197 | AC30: =AA30 -> 36197
B31: Inventory | L31: 4487 | M31: 6663 | N31: 8387 | O31: 8875 | P31: 8355 | Q31: 10372 | T31: 8705 | U31: 9007 | V31: 8727 | W31: 8355 | X31: 8205 | Y31: 8267 | Z31: 8567 | AA31: 10372 | AC31: =AA31 -> 10372
B32: Current assets | L32: 19907 | M32: 21781 | N32: 21244 | O32: 24372 | P32: 28841 | Q32: 91070 | T32: 24493 | U32: 24689 | V32: 27919 | W32: 28841 | X32: 29665 | Y32: 41413 | Z32: 66737 | AA32: 91070 | AC32: =AA32 -> 91070
B33: PP&E | L33: 33213 | M33: 38549 | N33: 37928 | O33: 39749 | P33: 46590 | Q33: 63310 | T33: 41476 | U33: 42528 | V33: 44773 | W33: 46590 | X33: 48477 | Y33: 51408 | Z33: 56426 | AA33: 63310 | AC33: =AA33 -> 63310
B34: Marketable securities and investments | L34: 1765 | M34: 1647 | N34: 844 | O34: 1046 | P34: 1629 | Q34: 30019 | T34: 1156 | U34: 1375 | V34: 1402 | W34: 1629 | X34: 1697 | Y34: 2038 | Z34: 4106 | AA34: 30019 | AC34: =AA34 -> 30019
B35: Goodwill | L35: 1228 | M35: 1228 | N35: 1150 | O35: 1150 | P35: 1150 | Q35: 1150 | T35: 1150 | U35: 1150 | V35: 1150 | W35: 1150 | X35: 1150 | Y35: 1150 | Z35: 1150 | AA35: 1150 | AC35: =AA35 -> 1150
B36: Long term assets | L36: =L37-L32 -> 38942 | M36: =M37-M32 -> 44502 | N36: =N37-N32 -> 43010 | O36: =O37-O32 -> 45044 | P36: =P37-P32 -> 53957 | Q36: =Q37-Q32 -> 104818 | T36: =T37-T32 -> 46968 | U36: =U37-U32 -> 48364 | V36: =V37-V32 -> 50478 | W36: =W37-W32 -> 53957 | X36: =X37-X32 -> 56306 | Y36: =Y37-Y32 -> 60096 | Z36: =Z37-Z32 -> 67375 | AA36: =AA37-AA32 -> 104818 | AC36: =AA36 -> 104818
B37: Total assets | L37: 58849 | M37: 66283 | N37: 64254 | O37: 69416 | P37: 82798 | Q37: 195888 | T37: 71461 | U37: 73053 | V37: 78397 | W37: 82798 | X37: 85971 | Y37: 101509 | Z37: 134112 | AA37: 195888 | AC37: =AA37 -> 195888
B38: Acc payable | L38: 5325 | M38: 6090 | N38: 3958 | O38: 7299 | P38: 9649 | Q38: 22605 | T38: 7126 | U38: 6176 | V38: 8761 | W38: 9649 | X38: 9769 | Y38: 10997 | Z38: 15521 | AA38: 22605 | AC38: =AA38 -> 22605
B39: Debt | L39: 155 | M39: 103 | N39: 278 | O39: 431 | P39: 560 | Q39: 491 | T39: 533 | U39: 504 | V39: 538 | W39: 560 | X39: 569 | Y39: 585 | Z39: 582 | AA39: 491 | AC39: =AA39 -> 491
B40: Current liabilities | L40: 6424 | M40: 7539 | N40: 4765 | O40: 9248 | P40: 11454 | Q40: 27482 | T40: 9015 | U40: 7877 | V40: 10135 | W40: 11454 | X40: 12060 | Y40: 14296 | Z40: 19488 | AA40: 27482 | AC40: =AA40 -> 27482
B41: Debt | L41: 6621 | M41: 6803 | N41: 13052 | O41: 12966 | P41: 14017 | Q41: 4688 | T41: 13252 | U41: 13851 | V41: 15003 | W41: 14017 | X41: 11187 | Y41: 9557 | Z41: 5140 | AA41: 4688 | AC41: =AA41 -> 4688
B42: Long term liabilities | L42: =L43-L40 -> 8492 | M42: =M43-M40 -> 8837 | N42: =N43-N40 -> 15369 | O42: =O43-O40 -> 15037 | P42: =P43-P40 -> 17179 | Q42: =Q43-Q40 -> 30028 | T42: =T43-T40 -> 15649 | U42: =U43-U40 -> 16543 | V42: =V43-V40 -> 17514 | W42: =W43-W40 -> 17179 | X42: =X43-X40 -> 15105 | Y42: =Y43-Y40 -> 14754 | Z42: =Z43-Z40 -> 13900 | AA42: =AA43-AA40 -> 30028 | AC42: =AA42 -> 30028
...

Sheet Analysis ->
H5: Links
H6: Overview'!B3
H7: Financials ->'!B13
H8: Analysis ->'!B13
H9: Forecast ->'!B13
H10: Valuation ->'!B13
B13: Analysis ->

Sheet Basic
B1: TTM/YTD data
B4: Overview | E4: CAGR
B5: Price | C5: =Overview!C5 -> 903.7 | F5: 5Y | G5: 10Y
B6: Market capitalization | C6: =Statement!AC153 -> 1035640.2 | E6: Revenue | F6: =IF(Statement!M5<=0,"N/A",_xlfn.RRI(4,Statement!M5,Statement!Q5)) -> 0.4425363 | G6: =IF(Statement!H5<=0,"N/A",_xlfn.RRI(9,Statement!H5,Statement!Q5)) -> N/A
B7: Enterprise value | C7: =Statement!AC154 -> 967366.2 | E7: Net income | F7: =IF(OR(Statement!M18<=0, Statement!Q18<=0), "N/A", _xlfn.RRI(4, Statement!M18, Statement!Q18)) -> 0.7684699 | G7: =IF(OR(Statement!H18<=0, Statement!Q18<=0), "N/A", _xlfn.RRI(9, Statement!H18, Statement!Q18)) -> N/A
B8: PE | C8: =Statement!AC150 -> 12.177604 | E8: EPS | F8: =IF(OR(Statement!M26<=0, Statement!Q26<=0), "N/A", _xlfn.RRI(4, Statement!M26, Statement!Q26)) -> 0.7598093 | G8: =IF(OR(Statement!H26<=0, Statement!Q26<=0), "N/A", _xlfn.RRI(9, Statement!H26, Statement!Q26)) -> N/A
B9: PS | C9: =Statement!AC151 -> 7.7554217 | E9: Dividend | F9: =IF(Statement!M82<=0,"N/A",_xlfn.RRI(4,Statement!M82,Statement!Q82)) -> 0.15982129 | G9: =IF(Statement!H82<=0,"N/A",_xlfn.RRI(9,Statement!H82,Statement!Q82)) -> N/A
B10: PB | C10: =Statement!AC152 -> 7.3731178 | E10: Price | F10: =IF(Statement!M117<=0,"N/A",_xlfn.RRI(4,Statement!M117,Statement!Q117)) -> 1.0220966 | G10: =IF(Statement!H117<=0,"N/A",_xlfn.RRI(9,Statement!H117,Statement!Q117)) -> N/A
B11: EV/Revenue | C11: =Statement!AC155 -> 7.2631633
B12: EV/EBIT | C12: =Statement!AC156 -> 9.7379324
B15: Margins | E15: Earnings quality
B16: Gross margin | C16: =Statement!AC101 -> 0.8071598 | E16: Net income | F16: =Statement!AC18 -> 84969
B17: Operating margin | C17: =Statement!AC102 -> 0.74586299 | E17: Operating cash | F17: =Statement!AC59 -> 89675
B18: Net margin | C18: =Statement!AC103 -> 0.63796288 | E18: Cash accruals | F18: =IF(OR(F16<=0, F17<=0),"N/A",F16-F17) -> -4706
B21: DuPont Identity | E21: Performance indicators
B22: Profit Margin (Earnings/Revenue) | C22: =Statement!AC121 -> 0.63796288 | E22: ROA | F22: =C24 -> 0.43376317
B23: Asset Turnover (Revenue/Total assets) | C23: =Statement!AC122 -> 0.67991914 | E23: ROE | F23: =C26 -> 0.61403547
B24: ROA | C24: =Statement!AC123 -> 0.43376317 | E24: ROIC | F24: =Statement!AC140 -> 1.2071782
B25: Equity Multiplier (Total assets/Equity) | C25: =Statement!AC124 -> 1.4156007
B26: ROE | C26: =Statement!AC125 -> 0.61403547
B29: Cash conversion cycle | E29: Liquidity ratios
B30: DSO | C30: =Statement!AC141 -> 99.197413 | E30: Debt/Equity | F30: =Statement!AC145 -> 0.03742647
B31: DIO | C31: =Statement!AC142 -> 147.39838 | E31: Net Debt/Equity | F31: =Statement!AC146 -> -0.49338768
B32: DPO | C32: =Statement!AC143 -> 321.24377 | E32: Current ratio | F32: =Statement!AC148 -> 3.3138054
B33: Net trade cycle | C33: =Statement!AC144 -> -74.647977 | E33: Quick ratio | F33: =Statement!AC147 -> 3.9898843
E34: Interest coverage | F34: =Statement!AC149 -> N/A
B37: Earnings yields | E37: Payout ratios
B38: Earnings yield | C38: =Statement!AC162 -> 0.082117959 | E38: Dividend payout ratio | F38: =Statement!AC168 -> 0.010584765
B39: FCF yield | C39: =Statement!AC161 -> 0.055646739 | E39: Buyback payout ratio | F39: =Statement!AC169 -> 0.011278848
B40: Dividend yield | C40: =Statement!AC163 -> 0.00062520748 | E40: Full payout ratio | F40: =Statement!AC170 -> 0.021863613
B41: Buyback yield | C41: =Statement!AC164 -> 0.0006276311
B42: Total shareholder yield | C42: =Statement!AC165 -> 0.0012166388
B45: Ownership | E45: Cash holdings
B46: Insider ownership | C46: =Statement!AC171 -> 0.002617801 | E46: Cash per share | F46: =Statement!AC172 -> 65.06023
E47: Net cash per share | F47: =Statement!AC175 -> 60.472985
E48: Net cash to market cap | F48: =Statement!AC176 -> 0.06592444
B51: Stock based compensation | E51: CapEx usage
B52: Stock based compensation % OCF | C52: =Statement!AC173 -> 0.01486479 | E52: Capex to Revenue | F52: =Statement!AC177 -> 0.23059134
B53: Stock based compensation % Revenue | C53: =Statement!AC174 -> 0.010008409 | E53: CapEx to OCF | F53: =Statement!AC178 -> 0.34248118
E54: CapEx to D&A | F54: =Statement!AC179 -> 3.2318215

Sheet Yearly Analysis
C2: =Statement!M2 -> 01.09.2022 | D2: =Statement!N2 -> 31.08.2023 | E2: =Statement!O2 -> 29.08.2024 | F2: =Statement!P2 -> 28.08.2025 | G2: =Statement!Q2 -> 03.09.2025
C3: =Statement!M3 -> 2022 | D3: =Statement!N3 -> 2023 | E3: =Statement!O3 -> 2024 | F3: =Statement!P3 -> 2025 | G3: =Statement!Q3 -> 2026 | I3: =Statement!AC3 -> TTM/YTD
B5: Overview
B6: Price | C6: =Statement!M116 -> 57.31 | D6: =Statement!N116 -> 68.09 | E6: =Statement!O116 -> 95.57 | F6: =Statement!P116 -> 122 | G6: =Statement!Q116 -> 958.16 | I6: =Statement!AC116 -> 903.7
B7: Market capitalization | C7: =Statement!M153 -> 62869.07 | D7: =Statement!N153 -> 74762.82 | E7: =Statement!O153 -> 107229.54 | F7: =Statement!P153 -> 137982 | G7: =Statement!Q153 -> 1098051.4 | I7: =Statement!AC153 -> 1035640.2
B8: Enterprise value | C8: =Statement!M154 -> 58797.07 | D8: =Statement!N154 -> 77654.82 | E8: =Statement!O154 -> 111474.54 | F8: =Statement!P154 -> 140623 | G8: =Statement!Q154 -> 1029777.4 | I8: =Statement!AC154 -> 967366.2
B9: PE | C9: =Statement!M150 -> 7.3948387 | D9: =Statement!N150 -> -12.750936 | E9: =Statement!O150 -> 136.52857 | F9: =Statement!P150 -> 16.073781 | G9: =Statement!Q150 -> 12.890623 | I9: =Statement!AC150 -> 12.177604
B10: PS | C10: =Statement!M151 -> 2.0905722 | D10: =Statement!N151 -> 4.7890843 | E10: =Statement!O151 -> 4.2549982 | F10: =Statement!P151 -> 3.6719461 | G10: =Statement!Q151 -> 8.2227894 | I10: =Statement!AC151 -> 7.7554217
B11: PB | C11: =Statement!M152 -> 1.2482411 | D11: =Statement!N152 -> 1.6945335 | E11: =Statement!O152 -> 2.348433 | F11: =Statement!P152 -> 2.527167 | G11: =Statement!Q152 -> 7.8174467 | I11: =Statement!AC152 -> 7.3731178
B12: EV/Revenue | C12: =Statement!M155 -> 1.9116025 | D12: =Statement!N155 -> 4.9970927 | E12: =Statement!O155 -> 4.4392712 | F12: =Statement!P155 -> 3.7621863 | G12: =Statement!Q155 -> 7.7317578 | I12: =Statement!AC155 -> 7.2631633
B13: EV/EBIT | C13: =Statement!M156 -> 6.0603041 | D13: =Statement!N156 -> -13.51694 | E13: =Statement!O156 -> 85.48661 | F13: =Statement!P156 -> 14.393347 | G13: =Statement!Q156 -> 10.36619 | I13: =Statement!AC156 -> 9.7379324
B15: Margins
B16: Gross margin | C16: =Statement!M101 -> 0.45184993 | D16: =Statement!N101 -> -0.091119691 | E16: =Statement!O101 -> 0.22352754 | F16: =Statement!P101 -> 0.39790786 | G16: =Statement!Q101 -> 0.8071598 | I16: =Statement!AC101 -> 0.8071598
B17: Operating margin | C17: =Statement!M102 -> 0.31543013 | D17: =Statement!N102 -> -0.36969112 | E17: =Statement!O102 -> 0.051929433 | F17: =Statement!P102 -> 0.2613837 | G17: =Statement!Q102 -> 0.74586299 | I17: =Statement!AC102 -> 0.74586299
B18: Net margin | C18: =Statement!M103 -> 0.28243059 | D18: =Statement!N103 -> -0.37535393 | E18: =Statement!O103 -> 0.030982438 | F18: =Statement!P103 -> 0.22844989 | G18: =Statement!Q103 -> 0.63796288 | I18: =Statement!AC103 -> 0.63796288
B20: Earnings quality
B21: Net income | C21: =Statement!M18 -> 8687 | D21: =Statement!N18 -> -5833 | E21: =Statement!O18 -> 778 | F21: =Statement!P18 -> 8539 | G21: =Statement!Q18 -> 84969 | I21: =Statement!AC18 -> 84969
B22: Operating cash | C22: =Statement!M59 -> 15181 | D22: =Statement!N59 -> 1559 | E22: =Statement!O59 -> 8507 | F22: =Statement!P59 -> 17525 | G22: =Statement!Q59 -> 89675 | I22: =Statement!AC59 -> 89675
B23: Cash accruals | C23: =IF(OR(C21<=0, C22<=0),"N/A",C21-C22) -> -6494 | D23: =IF(OR(D21<=0, D22<=0),"N/A",D21-D22) -> N/A | E23: =IF(OR(E21<=0, E22<=0),"N/A",E21-E22) -> -7729 | F23: =IF(OR(F21<=0, F22<=0),"N/A",F21-F22) -> -8986 | G23: =IF(OR(G21<=0, G22<=0),"N/A",G21-G22) -> -4706 | I23: =IF(OR(I21<=0, I22<=0),"N/A",I21-I22) -> -4706
B25: DuPont Identity
B26: Profit Margin (Earnings/Revenue) | C26: =Statement!M121 -> 0.28243059 | D26: =Statement!N121 -> -0.37535393 | E26: =Statement!O121 -> 0.030982438 | F26: =Statement!P121 -> 0.22844989 | G26: =Statement!Q121 -> 0.63796288 | I26: =Statement!AC121 -> 0.63796288
B27: Asset Turnover (Revenue/Total assets) | C27: =Statement!M122 -> 0.46404055 | D27: =Statement!N122 -> 0.24185265 | E27: =Statement!O122 -> 0.36174657 | F27: =Statement!P122 -> 0.45143603 | G27: =Statement!Q122 -> 0.67991914 | I27: =Statement!AC122 -> 0.67991914
B28: ROA | C28: =Statement!M123 -> 0.13105925 | D28: =Statement!N123 -> -0.090780341 | E28: =Statement!O123 -> 0.011207791 | F28: =Statement!P123 -> 0.10313051 | G28: =Statement!Q123 -> 0.43376317 | I28: =Statement!AC123 -> 0.43376317
B29: Equity Multiplier (Total assets/Equity) | C29: =Statement!M124 -> 1.3281303 | D29: =Statement!N124 -> 1.4563463 | E29: =Statement!O124 -> 1.5381002 | F29: =Statement!P124 -> 1.5286255 | G29: =Statement!Q124 -> 1.4156007 | I29: =Statement!AC124 -> 1.4156007
B30: ROE | C30: =Statement!M125 -> 0.17406376 | D30: =Statement!N125 -> -0.13220762 | E30: =Statement!O125 -> 0.017238705 | F30: =Statement!P125 -> 0.15764793 | G30: =Statement!Q125 -> 0.61403547 | I30: =Statement!AC125 -> 0.61403547
B32: Performance Indicators
B33: ROA | C33: =C28 -> 0.13105925 | D33: =D28 -> -0.090780341 | E33: =E28 -> 0.011207791 | F33: =F28 -> 0.10313051 | G33: =G28 -> 0.43376317 | I33: =I28 -> 0.43376317
B34: ROE | C34: =C30 -> 0.17406376 | D34: =D30 -> -0.13220762 | E34: =E30 -> 0.017238705 | F34: =F30 -> 0.15764793 | G34: =G30 -> 0.61403547 | I34: =I30 -> 0.61403547
B35: ROIC | C35: =Statement!M140 -> 0.19203329 | D35: =Statement!N140 -> -0.12220284 | E35: =Statement!O140 -> 0.016804168 | F35: =Statement!P140 -> 0.15196448 | G35: =Statement!Q140 -> 1.2071782 | I35: =Statement!AC140 -> 1.2071782
B37: Cash conversion cycle
B38: DSO | C38: =Statement!M141 -> 60.876845 | D38: =Statement!N141 -> 57.380631 | E38: =Statement!O141 -> 96.152085 | F38: =Statement!P141 -> 90.473674 | G38: =Statement!Q141 -> 99.197413 | I38: =Statement!AC141 -> 99.197413
B39: DIO | C39: =Statement!M142 -> 144.24644 | D39: =Statement!N142 -> 180.54111 | E39: =Statement!O142 -> 166.13883 | F39: =Statement!P142 -> 135.50655 | G39: =Statement!Q142 -> 147.39838 | I39: =Statement!AC142 -> 147.39838
B40: DPO | C40: =Statement!M143 -> 131.84164 | D40: =Statement!N143 -> 85.201109 | E40: =Statement!O143 -> 136.63632 | F40: =Statement!P143 -> 156.49345 | G40: =Statement!Q143 -> 321.24377 | I40: =Statement!AC143 -> 321.24377
B41: Net trade cycle | C41: =Statement!M144 -> 73.281649 | D41: =Statement!N144 -> 152.72063 | E41: =Statement!O144 -> 125.6546 | F41: =Statement!P144 -> 69.486783 | G41: =Statement!Q144 -> -74.647977 | I41: =Statement!AC144 -> -74.647977
B43: Liquidity ratios
B44: Debt/Equity | C44: =Statement!M145 -> 0.13837738 | D44: =Statement!N145 -> 0.30213055 | E44: =Statement!O145 -> 0.29684696 | F44: =Statement!P145 -> 0.26912213 | G44: =Statement!Q145 -> 0.03742647 | I44: =Statement!AC145 -> 0.03742647
B45: Net Debt/Equity | C45: =Statement!M146 -> -0.081591761 | D45: =Statement!N146 -> 0.065548504 | E45: =Statement!O146 -> 0.094059516 | F45: =Statement!P146 -> 0.048758423 | G45: =Statement!Q146 -> -0.49338768 | I45: =Statement!AC146 -> -0.49338768
B46: Quick ratio | C46: =Statement!M147 -> 2.1366229 | D46: =Statement!N147 -> 2.7032529 | E46: =Statement!O147 -> 1.7049092 | F46: =Statement!P147 -> 1.8509691 | G46: =Statement!Q147 -> 3.9898843 | I46: =Statement!AC147 -> 3.9898843
B47: Current ratio | C47: =Statement!M148 -> 2.88911 | D47: =Statement!N148 -> 4.4583421 | E47: =Statement!O148 -> 2.6353806 | F47: =Statement!P148 -> 2.517985 | G47: =Statement!Q148 -> 3.3138054 | I47: =Statement!AC148 -> 3.3138054
B48: Interest coverage | C48: =Statement!M149 -> 104.32258 | D48: =Statement!N149 -> N/A | E48: =Statement!O149 -> 39.515152 | F48: =Statement!P149 -> N/A | G48: =Statement!Q149 -> N/A | I48: =Statement!AC149 -> N/A
...

Sheet Quarter analysis
C3: Latest 2 quarters | F3: YoY
C4: =Statement!Z2 -> 28.05.2026 | D4: =Statement!AA2 -> 03.09.2026 | F4: =Statement!W2 -> 28.08.2025 | G4: =Statement!AA2 -> 03.09.2026
B5: Income statement growth | C5: =Statement!Z3 -> Q3 2026 | D5: =Statement!AA3 -> Q4 2026 | F5: =Statement!W3 -> Q4 2025 | G5: =Statement!AA3 -> Q4 2026
B6: Revenue | C6: =Statement!Z5 -> 41456 | D6: =Statement!AA5 -> 54229 | F6: =Statement!W5 -> 11315 | G6: =Statement!AA5 -> 54229
B7: Growth | C7: =Statement!AA89 -> 0.3081098 | F7: =IF(F6=0, IF(G6=0,0,IF(G6>0,1,-1)), (G6-F6)/ABS(F6) ) -> 3.7926646
B8: COGS | C8: =Statement!Z6 -> 6400 | D8: =Statement!AA6 -> 7182 | F8: =Statement!W6 -> 6261 | G8: =Statement!AA6 -> 7182
B9: Growth | C9: =Statement!AA90 -> 0.1221875 | F9: =IF(F8=0, IF(G8=0,0,IF(G8>0,1,-1)), (G8-F8)/ABS(F8) ) -> 0.1471011
B10: Gross Profit | C10: =Statement!Z7 -> 35056 | D10: =Statement!AA7 -> 47047 | F10: =Statement!W7 -> 5054 | G10: =Statement!AA7 -> 47047
B11: Growth | C11: =Statement!AA91 -> 0.34205272 | F11: =IF(F10=0, IF(G10=0,0,IF(G10>0,1,-1)), (G10-F10)/ABS(F10) ) -> 8.3088643
B12: OpEx | C12: =Statement!Z11 -> 1738 | D12: =Statement!AA11 -> 3296 | F12: =Statement!W11 -> 1400 | G12: =Statement!AA11 -> 3296
B13: Growth | C13: =Statement!AA95 -> 0.89643268 | F13: =IF(F12=0, IF(G12=0,0,IF(G12>0,1,-1)), (G12-F12)/ABS(F12) ) -> 1.3542857
B14: Operating profit | C14: =Statement!Z12 -> 33318 | D14: =Statement!AA12 -> 43751 | F14: =Statement!W12 -> 3654 | G14: =Statement!AA12 -> 43751
B15: Growth | C15: =Statement!AA96 -> 0.31313404 | F15: =IF(F14=0, IF(G14=0,0,IF(G14>0,1,-1)), (G14-F14)/ABS(F14) ) -> 10.973454
B16: Net income | C16: =Statement!Z18 -> 28243 | D16: =Statement!AA18 -> 37701 | F16: =Statement!W18 -> 3201 | G16: =Statement!AA18 -> 37701
B17: Growth | C17: =Statement!AA98 -> 0.33487944 | F17: =IF(F16=0, IF(G16=0,0,IF(G16>0,1,-1)), (G16-F16)/ABS(F16) ) -> 10.777882
B18: Diluted shares outstanding | C18: =Statement!Z22 -> 1145 | D18: =Statement!AA22 -> 1147 | F18: =Statement!W22 -> 1131 | G18: =Statement!AA22 -> 1147
B19: Growth | C19: =IF(C18=0, IF(D18=0,0,IF(D18>0,1,-1)), (D18-C18)/ABS(C18) ) -> 0.0017467249 | F19: =IF(F18=0, IF(G18=0,0,IF(G18>0,1,-1)), (G18-F18)/ABS(F18) ) -> 0.014146773
B20: Diluted EPS | C20: =Statement!Z26 -> 24.67 | D20: =Statement!AA26 -> 32.87 | F20: =Statement!W26 -> 2.83 | G20: =Statement!AA26 -> 32.87
B21: Growth | C21: =IF(C20=0, IF(D20=0,0,IF(D20>0,1,-1)), (D20-C20)/ABS(C20) ) -> 0.33238752 | F21: =IF(F20=0, IF(G20=0,0,IF(G20>0,1,-1)), (G20-F20)/ABS(F20) ) -> 10.614841
B23: Revenue breakdown | C23: =C5 -> Q3 2026 | D23: =D5 -> Q4 2026 | F23: =F5 -> Q4 2025 | G23: =G5 -> Q4 2026
B24: =Statement!B187 -> DRAM | C24: =Statement!Z187 -> 31328 | D24: =Statement!AA187 -> 39771 | F24: =Statement!W187 -> 22178 | G24: =Statement!AA187 -> 39771
B25: Growth | C25: =IF(C24=0, IF(D24=0,0,IF(D24>0,1,-1)), (D24-C24)/ABS(C24) ) -> 0.26950332 | F25: =IF(F24=0, IF(G24=0,0,IF(G24>0,1,-1)), (G24-F24)/ABS(F24) ) -> 0.79326359
B26: =Statement!B188 -> NAND | C26: =Statement!Z188 -> 9943 | D26: =Statement!AA188 -> 14102 | F26: =Statement!W188 -> 6262 | G26: =Statement!AA188 -> 14102
B27: Growth | C27: =IF(C26=0, IF(D26=0,0,IF(D26>0,1,-1)), (D26-C26)/ABS(C26) ) -> 0.41828422 | F27: =IF(F26=0, IF(G26=0,0,IF(G26>0,1,-1)), (G26-F26)/ABS(F26) ) -> 1.2519962
B28: =Statement!B189 -> Other | C28: =Statement!Z189 -> 185 | D28: =Statement!AA189 -> 356 | F28: =Statement!W189 -> 229 | G28: =Statement!AA189 -> 356
B29: Growth | C29: =IF(C28=0, IF(D28=0,0,IF(D28>0,1,-1)), (D28-C28)/ABS(C28) ) -> 0.92432432 | F29: =IF(F28=0, IF(G28=0,0,IF(G28>0,1,-1)), (G28-F28)/ABS(F28) ) -> 0.55458515
B31: =Statement!B191 -> Cloud Memory | C31: =Statement!Z191 -> 13769 | D31: =Statement!AA191 -> 16283 | F31: =Statement!W191 -> 4543 | G31: =Statement!AA191 -> 16283
B32: Growth | C32: =IF(C31=0, IF(D31=0,0,IF(D31>0,1,-1)), (D31-C31)/ABS(C31) ) -> 0.18258407 | F32: =IF(F31=0, IF(G31=0,0,IF(G31>0,1,-1)), (G31-F31)/ABS(F31) ) -> 2.5841955
B33: =Statement!B192 -> Core Data Center | C33: =Statement!Z192 -> 11524 | D33: =Statement!AA192 -> 18002 | F33: =Statement!W192 -> 1577 | G33: =Statement!AA192 -> 18002
B34: Growth | C34: =IF(C33=0, IF(D33=0,0,IF(D33>0,1,-1)), (D33-C33)/ABS(C33) ) -> 0.5621312 | F34: =IF(F33=0, IF(G33=0,0,IF(G33>0,1,-1)), (G33-F33)/ABS(F33) ) -> 10.415346
B35: =Statement!B193 -> Mobile and Client | C35: =Statement!Z193 -> 11521 | D35: =Statement!AA193 -> 13114 | F35: =Statement!W193 -> 3760 | G35: =Statement!AA193 -> 13114
B36: Growth | C36: =IF(C35=0, IF(D35=0,0,IF(D35>0,1,-1)), (D35-C35)/ABS(C35) ) -> 0.13826925 | F36: =IF(F35=0, IF(G35=0,0,IF(G35>0,1,-1)), (G35-F35)/ABS(F35) ) -> 2.487766
B37: =Statement!B194 -> Automotive and Embedded | C37: =Statement!Z194 -> 4634 | D37: =Statement!AA194 -> 6824 | F37: =Statement!W194 -> 1434 | G37: =Statement!AA194 -> 6824
B38: Growth | C38: =IF(C37=0, IF(D37=0,0,IF(D37>0,1,-1)), (D37-C37)/ABS(C37) ) -> 0.47259387 | F38: =IF(F37=0, IF(G37=0,0,IF(G37>0,1,-1)), (G37-F37)/ABS(F37) ) -> 3.7587169

Sheet Graphs Year
C62: =Statement!H2 -> 0 | D62: =Statement!I2 -> 0 | E62: =Statement!J2 -> 0 | F62: =Statement!K2 -> 0 | G62: =Statement!L2 -> 02.09.2021 | H62: =Statement!M2 -> 01.09.2022 | I62: =Statement!N2 -> 31.08.2023 | J62: =Statement!O2 -> 29.08.2024 | ... L62: =Statement!Q2 -> 03.09.2025
C63: =Statement!H3 -> 0 | D63: =Statement!I3 -> 0 | E63: =Statement!J3 -> 0 | F63: =Statement!K3 -> 0 | G63: =Statement!L3 -> 2021 | H63: =Statement!M3 -> 2022 | I63: =Statement!N3 -> 2023 | J63: =Statement!O3 -> 2024 | ... L63: =Statement!Q3 -> 2026
B64: Revenue | C64: =Statement!H5 -> 0 | D64: =Statement!I5 -> 0 | E64: =Statement!J5 -> 0 | F64: =Statement!K5 -> 0 | G64: =Statement!L5 -> 27705 | H64: =Statement!M5 -> 30758 | I64: =Statement!N5 -> 15540 | J64: =Statement!O5 -> 25111 | ... L64: =Statement!Q5 -> 133188
B65: Operating income | C65: =Statement!H12 -> 0 | D65: =Statement!I12 -> 0 | E65: =Statement!J12 -> 0 | F65: =Statement!K12 -> 0 | G65: =Statement!L12 -> 6283 | H65: =Statement!M12 -> 9702 | I65: =Statement!N12 -> -5745 | J65: =Statement!O12 -> 1304 | ... L65: =Statement!Q12 -> 99340
B66: Net income | C66: =Statement!H18 -> 0 | D66: =Statement!I18 -> 0 | E66: =Statement!J18 -> 0 | F66: =Statement!K18 -> 0 | G66: =Statement!L18 -> 5861 | H66: =Statement!M18 -> 8687 | I66: =Statement!N18 -> -5833 | J66: =Statement!O18 -> 778 | ... L66: =Statement!Q18 -> 84969
B67: FCFE | C67: =Statement!H157 -> 0 | D67: =Statement!I157 -> 0 | E67: =Statement!J157 -> 0 | F67: =Statement!K157 -> 0 | G67: =Statement!L157 -> 2060 | H67: =Statement!M157 -> 2600 | I67: =Statement!N157 -> -6713 | J67: =Statement!O157 -> -712 | ... L67: =Statement!Q157 -> 57630
B68: FCFF | C68: =Statement!H158 -> 0 | D68: =Statement!I158 -> 0 | E68: =Statement!J158 -> 0 | F68: =Statement!K158 -> 0 | G68: =Statement!L158 -> 1698.8813 | H68: =Statement!M158 -> 2605.8458 | I68: =Statement!N158 -> -8557 | J68: =Statement!O158 -> -660.27742 | ... L68: =Statement!Q158 -> 57677.02
B69: Gross margin | C69: =Statement!H101 -> 0 | D69: =Statement!I101 -> 0 | E69: =Statement!J101 -> 0 | F69: =Statement!K101 -> 0 | G69: =Statement!L101 -> 0.37621368 | H69: =Statement!M101 -> 0.45184993 | I69: =Statement!N101 -> -0.091119691 | J69: =Statement!O101 -> 0.22352754 | ... L69: =Statement!Q101 -> 0.8071598
B70: Operating margin | C70: =Statement!H102 -> 0 | D70: =Statement!I102 -> 0 | E70: =Statement!J102 -> 0 | F70: =Statement!K102 -> 0 | G70: =Statement!L102 -> 0.22678217 | H70: =Statement!M102 -> 0.31543013 | I70: =Statement!N102 -> -0.36969112 | J70: =Statement!O102 -> 0.051929433 | ... L70: =Statement!Q102 -> 0.74586299
B71: Net margin | C71: =Statement!H103 -> 0 | D71: =Statement!I103 -> 0 | E71: =Statement!J103 -> 0 | F71: =Statement!K103 -> 0 | G71: =Statement!L103 -> 0.21155026 | H71: =Statement!M103 -> 0.28243059 | I71: =Statement!N103 -> -0.37535393 | J71: =Statement!O103 -> 0.030982438 | ... L71: =Statement!Q103 -> 0.63796288
B72: ="Revenue "&Statement!B187 -> Revenue DRAM | C72: =Statement!H187 -> 0 | D72: =Statement!I187 -> 0 | E72: =Statement!J187 -> 0 | F72: =Statement!K187 -> 0 | G72: =Statement!L187 -> 20039 | H72: =Statement!M187 -> 22386 | I72: =Statement!N187 -> 10978 | J72: =Statement!O187 -> 17603 | ... L72: =Statement!Q187 -> 100679
B73: ="Revenue "&Statement!B188 -> Revenue NAND | C73: =Statement!H188 -> 0 | D73: =Statement!I188 -> 0 | E73: =Statement!J188 -> 0 | F73: =Statement!K188 -> 0 | G73: =Statement!L188 -> 7007 | H73: =Statement!M188 -> 7811 | I73: =Statement!N188 -> 4206 | J73: =Statement!O188 -> 7227 | ... L73: =Statement!Q188 -> 31785
B74: ="Revenue "&Statement!B189 -> Revenue Other | C74: =Statement!H189 -> 0 | D74: =Statement!I189 -> 0 | E74: =Statement!J189 -> 0 | F74: =Statement!K189 -> 0 | G74: =Statement!L189 -> 659 | H74: =Statement!M189 -> 561 | I74: =Statement!N189 -> 356 | J74: =Statement!O189 -> 281 | ... L74: =Statement!Q189 -> 724
B75: ="Revenue "&Statement!B191 -> Revenue Cloud Memory | C75: =Statement!H191 -> 0 | D75: =Statement!I191 -> 0 | E75: =Statement!J191 -> 0 | F75: =Statement!K191 -> 0 | G75: =Statement!L191 -> 0 | H75: =Statement!M191 -> 0 | I75: =Statement!N191 -> 1872 | J75: =Statement!O191 -> 3792 | ... L75: =Statement!Q191 -> 43085
B76: ="Revenue "&Statement!B192 -> Revenue Core Data Center | C76: =Statement!H192 -> 0 | D76: =Statement!I192 -> 0 | E76: =Statement!J192 -> 0 | F76: =Statement!K192 -> 0 | G76: =Statement!L192 -> 0 | H76: =Statement!M192 -> 0 | I76: =Statement!N192 -> 2124 | J76: =Statement!O192 -> 4984 | ... L76: =Statement!Q192 -> 37592
B77: ="Revenue "&Statement!B193 -> Revenue Mobile and Client | C77: =Statement!H193 -> 0 | D77: =Statement!I193 -> 0 | E77: =Statement!J193 -> 0 | F77: =Statement!K193 -> 0 | G77: =Statement!L193 -> 0 | H77: =Statement!M193 -> 0 | I77: =Statement!N193 -> 7394 | J77: =Statement!O193 -> 11667 | ... L77: =Statement!Q193 -> 36601
B78: ="Revenue "&Statement!B194 -> Revenue Automotive and Embedded | C78: =Statement!H194 -> 0 | D78: =Statement!I194 -> 0 | E78: =Statement!J194 -> 0 | F78: =Statement!K194 -> 0 | G78: =Statement!L194 -> 0 | H78: =Statement!M194 -> 0 | I78: =Statement!N194 -> 4139 | J78: =Statement!O194 -> 4631 | ... L78: =Statement!Q194 -> 15886
B79: ROA | C79: =Statement!H123 -> 0 | D79: =Statement!I123 -> 0 | E79: =Statement!J123 -> 0 | F79: =Statement!K123 -> 0 | G79: =Statement!L123 -> 0.099593876 | H79: =Statement!M123 -> 0.13105925 | I79: =Statement!N123 -> -0.090780341 | J79: =Statement!O123 -> 0.011207791 | ... L79: =Statement!Q123 -> 0.43376317
B80: ROE | C80: =Statement!H125 -> 0 | D80: =Statement!I125 -> 0 | E80: =Statement!J125 -> 0 | F80: =Statement!K125 -> 0 | G80: =Statement!L125 -> 0.13340769 | H80: =Statement!M125 -> 0.17406376 | I80: =Statement!N125 -> -0.13220762 | J80: =Statement!O125 -> 0.017238705 | ... L80: =Statement!Q125 -> 0.61403547
B81: ROIC | C81: =Statement!H140 -> 0 | D81: =Statement!I140 -> 0 | E81: =Statement!J140 -> 0 | F81: =Statement!K140 -> 0 | G81: =Statement!L140 -> 0.14598698 | H81: =Statement!M140 -> 0.19203329 | I81: =Statement!N140 -> -0.12220284 | J81: =Statement!O140 -> 0.016804168 | ... L81: =Statement!Q140 -> 1.2071782
B82: Price 5y | C82: =Statement!H218 -> 0 | D82: =Statement!I218 -> 0 | E82: =Statement!J218 -> 0 | F82: =Statement!K218 -> 0 | G82: =Statement!L218 -> 100 | H82: =Statement!M218 -> 100 | I82: =Statement!N218 -> 118.80998 | J82: =Statement!O218 -> 166.75973 | ... L82: =Statement!Q218 -> 1671.8897
B83: Revenue 5y | C83: =Statement!H219 -> 0 | D83: =Statement!I219 -> 0 | E83: =Statement!J219 -> 0 | F83: =Statement!K219 -> 0 | G83: =Statement!L219 -> 100 | H83: =Statement!M219 -> 100 | I83: =Statement!N219 -> 50.523441 | J83: =Statement!O219 -> 81.640549 | ... L83: =Statement!Q219 -> 433.01905
B84: EPS 5y | C84: =Statement!H220 -> 0 | D84: =Statement!I220 -> 0 | E84: =Statement!J220 -> 0 | F84: =Statement!K220 -> 0 | G84: =Statement!L220 -> 100 | H84: =Statement!M220 -> 100 | I84: =Statement!N220 -> -68.903226 | J84: =Statement!O220 -> 9.0322581 | ... L84: =Statement!Q220 -> 959.09677

Sheet Graphs Quarter
C55: =Statement!T2 -> 28.11.2024 | D55: =Statement!U2 -> 27.02.2025 | E55: =Statement!V2 -> 29.05.2025 | F55: =Statement!W2 -> 28.08.2025 | G55: =Statement!X2 -> 27.11.2025 | H55: =Statement!Y2 -> 26.02.2026 | I55: =Statement!Z2 -> 28.05.2026 | J55: =Statement!AA2 -> 03.09.2026
C56: =Statement!T3 -> Q1 2025 | D56: =Statement!U3 -> Q2 2025 | E56: =Statement!V3 -> Q3 2025 | F56: =Statement!W3 -> Q4 2025 | G56: =Statement!X3 -> Q1 2026 | H56: =Statement!Y3 -> Q2 2026 | I56: =Statement!Z3 -> Q3 2026 | J56: =Statement!AA3 -> Q4 2026
B57: Revenue | C57: =Statement!T5 -> 8709 | D57: =Statement!U5 -> 8053 | E57: =Statement!V5 -> 9301 | F57: =Statement!W5 -> 11315 | G57: =Statement!X5 -> 13643 | H57: =Statement!Y5 -> 23860 | I57: =Statement!Z5 -> 41456 | J57: =Statement!AA5 -> 54229
B58: Operating income | C58: =Statement!T12 -> 2174 | D58: =Statement!U12 -> 1773 | E58: =Statement!V12 -> 2169 | F58: =Statement!W12 -> 3654 | G58: =Statement!X12 -> 6136 | H58: =Statement!Y12 -> 16135 | I58: =Statement!Z12 -> 33318 | J58: =Statement!AA12 -> 43751
B59: Net income | C59: =Statement!T18 -> 1870 | D59: =Statement!U18 -> 1583 | E59: =Statement!V18 -> 1885 | F59: =Statement!W18 -> 3201 | G59: =Statement!X18 -> 5240 | H59: =Statement!Y18 -> 13785 | I59: =Statement!Z18 -> 28243 | J59: =Statement!AA18 -> 37701
B60: Gross margin | C60: =Statement!T101 -> 0.3844299 | D60: =Statement!U101 -> 0.36793741 | E60: =Statement!V101 -> 0.37716375 | F60: =Statement!W101 -> 0.44666372 | G60: =Statement!X101 -> 0.56043392 | H60: =Statement!Y101 -> 0.74413244 | I60: =Statement!Z101 -> 0.84561945 | J60: =Statement!AA101 -> 0.86756164
B61: Operating margin | C61: =Statement!T102 -> 0.24962682 | D61: =Statement!U102 -> 0.2201664 | E61: =Statement!V102 -> 0.23320073 | F61: =Statement!W102 -> 0.32293416 | G61: =Statement!X102 -> 0.44975445 | H61: =Statement!Y102 -> 0.67623638 | I61: =Statement!Z102 -> 0.80369548 | J61: =Statement!AA102 -> 0.80678235
B62: Net margin | C62: =Statement!T103 -> 0.2147204 | D62: =Statement!U103 -> 0.19657271 | E62: =Statement!V103 -> 0.20266638 | F62: =Statement!W103 -> 0.28289881 | G62: =Statement!X103 -> 0.38407975 | H62: =Statement!Y103 -> 0.57774518 | I62: =Statement!Z103 -> 0.68127653 | J62: =Statement!AA103 -> 0.69521843
B63: ="Revenue "&Statement!B187 -> Revenue DRAM | C63: =Statement!T187 -> 6400 | D63: =Statement!U187 -> 6123 | E63: =Statement!V187 -> 7071 | F63: =Statement!W187 -> 22178 | G63: =Statement!X187 -> 10812 | H63: =Statement!Y187 -> 18768 | I63: =Statement!Z187 -> 31328 | J63: =Statement!AA187 -> 39771
B64: ="Revenue "&Statement!B188 -> Revenue NAND | C64: =Statement!T188 -> 2241 | D64: =Statement!U188 -> 1855 | E64: =Statement!V188 -> 2155 | F64: =Statement!W188 -> 6262 | G64: =Statement!X188 -> 2743 | H64: =Statement!Y188 -> 4997 | I64: =Statement!Z188 -> 9943 | J64: =Statement!AA188 -> 14102
B65: ="Revenue "&Statement!B189 -> Revenue Other | C65: =Statement!T189 -> 68 | D65: =Statement!U189 -> 75 | E65: =Statement!V189 -> 75 | F65: =Statement!W189 -> 229 | G65: =Statement!X189 -> 88 | H65: =Statement!Y189 -> 95 | I65: =Statement!Z189 -> 185 | J65: =Statement!AA189 -> 356
B66: ="Revenue "&Statement!B191 -> Revenue Cloud Memory | C66: =Statement!T191 -> 2658 | D66: =Statement!U191 -> 2947 | E66: =Statement!V191 -> 3386 | F66: =Statement!W191 -> 4543 | G66: =Statement!X191 -> 5284 | H66: =Statement!Y191 -> 7749 | I66: =Statement!Z191 -> 13769 | J66: =Statement!AA191 -> 16283
B67: ="Revenue "&Statement!B192 -> Revenue Core Data Center | C67: =Statement!T192 -> 2292 | D67: =Statement!U192 -> 1830 | E67: =Statement!V192 -> 1530 | F67: =Statement!W192 -> 1577 | G67: =Statement!X192 -> 2379 | H67: =Statement!Y192 -> 5687 | I67: =Statement!Z192 -> 11524 | J67: =Statement!AA192 -> 18002
B68: ="Revenue "&Statement!B193 -> Revenue Mobile and Client | C68: =Statement!T193 -> 2608 | D68: =Statement!U193 -> 2236 | E68: =Statement!V193 -> 3255 | F68: =Statement!W193 -> 3760 | G68: =Statement!X193 -> 4255 | H68: =Statement!Y193 -> 7711 | I68: =Statement!Z193 -> 11521 | J68: =Statement!AA193 -> 13114
B69: ="Revenue "&Statement!B194 -> Revenue Automotive and Embedded | C69: =Statement!T194 -> 1158 | D69: =Statement!U194 -> 1034 | E69: =Statement!V194 -> 1127 | F69: =Statement!W194 -> 1434 | G69: =Statement!X194 -> 1720 | H69: =Statement!Y194 -> 2708 | I69: =Statement!Z194 -> 4634 | J69: =Statement!AA194 -> 6824
B70: FCFE | C70: =Statement!T157 -> -182 | D70: =Statement!U157 -> -362 | E70: =Statement!V157 -> 1418 | F70: =Statement!W157 -> -178 | G70: =Statement!X157 -> 2732 | H70: =Statement!Y157 -> 5207 | I70: =Statement!Z157 -> 17207 | J70: =Statement!AA157 -> 32484

Sheet Forecast ->
H5: Links
H6: Overview'!B3
H7: Financials ->'!B13
H8: Analysis ->'!B13
H9: Forecast ->'!B13
H10: Valuation ->'!B13
B13: Forecast ->

Sheet Revenue
B1: Revenue forecast
C2: History | H2: Forecast | S2: History | AA2: Forecast | AE2: TTM
C4: Revenues | S4: Revenues
B5: Revenues (thousand) | C5: =Statement!M3 -> 2022 | D5: =Statement!N3 -> 2023 | E5: =Statement!O3 -> 2024 | F5: =Statement!P3 -> 2025 | G5: =Statement!Q3 -> 2026 | H5: =G5+1 -> 2027 | I5: =H5+1 -> 2028 | J5: =I5+1 -> 2029 | K5: =J5+1 -> 2030 | L5: =K5+1 -> 2031 | R5: =B5 -> Revenues (thousand) | S5: =Statement!T3 -> Q1 2025 | T5: =Statement!U3 -> Q2 2025 | U5: =Statement!V3 -> Q3 2025 | V5: =Statement!W3 -> Q4 2025 | W5: =Statement!X3 -> Q1 2026 | X5: =Statement!Y3 -> Q2 2026 | Y5: =Statement!Z3 -> Q3 2026 | Z5: =Statement!AA3 -> Q4 2026 | AA5: FQ1 | AB5: FQ2 | AC5: FQ3 | AE5: FQ1
B6: =Statement!B191 -> Cloud Memory | C6: =Statement!M191 -> 0 | D6: =Statement!N191 -> 1872 | E6: =Statement!O191 -> 3792 | F6: =Statement!P191 -> 13524 | G6: =Statement!Q191 -> 43085 | H6: =G6*(1+H14) -> 62473.25 | I6: =H6*(1+I14) -> 87462.55 | J6: =I6*(1+J14) -> 96208.805 | K6: =J6*(1+K14) -> 86587.924 | L6: =K6*(1+L14) -> 51952.755 | N6: Cloud growth rate | Q6: =N6 -> Cloud growth rate | R6: =B6 -> Cloud Memory | S6: =Statement!T191 -> 2658 | T6: =Statement!U191 -> 2947 | U6: =Statement!V191 -> 3386 | V6: =Statement!W191 -> 4543 | W6: =Statement!X191 -> 5284 | X6: =Statement!Y191 -> 7749 | Y6: =Statement!Z191 -> 13769 | Z6: =Statement!AA191 -> 16283 | AA6: =Z6*(1+AA14) -> 18725.45 | AE6: =SUM(X6:AA6) -> 56526.45
B7: =Statement!B192 -> Core Data Center | C7: =Statement!M192 -> 0 | D7: =Statement!N192 -> 2124 | E7: =Statement!O192 -> 4984 | F7: =Statement!P192 -> 7229 | G7: =Statement!Q192 -> 37592 | H7: =G7*(1+H15) -> 63906.4 | I7: =H7*(1+I15) -> 83078.32 | J7: =I7*(1+J15) -> 95540.068 | K7: =J7*(1+K15) -> 81209.058 | L7: =K7*(1+L15) -> 40604.529 | N7: Datacenter growth rate | Q7: =N7 -> Datacenter growth rate | R7: =B7 -> Core Data Center | S7: =Statement!T192 -> 2292 | T7: =Statement!U192 -> 1830 | U7: =Statement!V192 -> 1530 | V7: =Statement!W192 -> 1577 | W7: =Statement!X192 -> 2379 | X7: =Statement!Y192 -> 5687 | Y7: =Statement!Z192 -> 11524 | Z7: =Statement!AA192 -> 18002 | AA7: =Z7*(1+AA15) -> 19802.2 | AE7: =SUM(X7:AA7) -> 55015.2
B8: =Statement!B193 -> Mobile and Client | C8: =Statement!M193 -> 0 | D8: =Statement!N193 -> 7394 | E8: =Statement!O193 -> 11667 | F8: =Statement!P193 -> 11859 | G8: =Statement!Q193 -> 36601 | H8: =G8*(1+H16) -> 73202 | I8: =H8*(1+I16) -> 102482.8 | J8: =I8*(1+J16) -> 133227.64 | K8: =J8*(1+K16) -> 106582.11 | L8: =K8*(1+L16) -> 95923.901 | N8: Mobile growth rate | Q8: =N8 -> Mobile growth rate | R8: =B8 -> Mobile and Client | S8: =Statement!T193 -> 2608 | T8: =Statement!U193 -> 2236 | U8: =Statement!V193 -> 3255 | V8: =Statement!W193 -> 3760 | W8: =Statement!X193 -> 4255 | X8: =Statement!Y193 -> 7711 | Y8: =Statement!Z193 -> 11521 | Z8: =Statement!AA193 -> 13114 | AA8: =Z8*(1+AA16) -> 15736.8 | AE8: =SUM(X8:AA8) -> 48082.8
B9: =Statement!B194 -> Automotive and Embedded | C9: =Statement!M194 -> 0 | D9: =Statement!N194 -> 4139 | E9: =Statement!O194 -> 4631 | F9: =Statement!P194 -> 4753 | G9: =Statement!Q194 -> 15886 | H9: =G9*(1+H17) -> 31772 | I9: =H9*(1+I17) -> 44480.8 | J9: =I9*(1+J17) -> 48928.88 | K9: =J9*(1+K17) -> 44035.992 | L9: =K9*(1+L17) -> 30825.194 | N9: Automotive growth rate | Q9: =N9 -> Automotive growth rate | R9: =B9 -> Automotive and Embedded | S9: =Statement!T194 -> 1158 | T9: =Statement!U194 -> 1034 | U9: =Statement!V194 -> 1127 | V9: =Statement!W194 -> 1434 | W9: =Statement!X194 -> 1720 | X9: =Statement!Y194 -> 2708 | Y9: =Statement!Z194 -> 4634 | Z9: =Statement!AA194 -> 6824 | AA9: =Z9*(1+AA17) -> 7506.4 | AE9: =SUM(X9:AA9) -> 21672.4
B10: Total | C10: =Statement!M5 -> 30758 | D10: =Statement!N5 -> 15540 | E10: =Statement!O5 -> 25111 | F10: =Statement!P5 -> 37378 | G10: =Statement!Q5 -> 133188 | H10: =SUM(H6:H9) -> 231353.65 | I10: =SUM(I6:I9) -> 317504.47 | J10: =SUM(J6:J9) -> 373905.39 | K10: =SUM(K6:K9) -> 318415.09 | L10: =SUM(L6:L9) -> 219306.38 | R10: Total | S10: =Statement!T5 -> 8709 | T10: =Statement!U5 -> 8053 | U10: =Statement!V5 -> 9301 | V10: =Statement!W5 -> 11315 | W10: =Statement!X5 -> 13643 | X10: =Statement!Y5 -> 23860 | Y10: =Statement!Z5 -> 41456 | Z10: =Statement!AA5 -> 54229 | AA10: =SUM(AA6:AA9) -> 61770.85 | AE10: =SUM(X10:AA10) -> 181315.85
C12: Growth rates | S12: Growth rates
B13: Revenue growth % | C13: =C5 -> 2022 | D13: =D5 -> 2023 | E13: =E5 -> 2024 | F13: =F5 -> 2025 | G13: =G5 -> 2026 | H13: =H5 -> 2027 | I13: =I5 -> 2028 | J13: =J5 -> 2029 | ... L13: =L5 -> 2031 | R13: Revenue growth % | S13: =S5 -> Q1 2025 | T13: =T5 -> Q2 2025 | U13: =U5 -> Q3 2025 | V13: =V5 -> Q4 2025 | W13: =W5 -> Q1 2026 | X13: =X5 -> Q2 2026 | Y13: =Y5 -> Q3 2026 | Z13: =Z5 -> Q4 2026 | ... AC13: =AC5 -> FQ3
B14: =B6 -> Cloud Memory | D14: =D6/C6-1 -> #DIV/0! | E14: =E6/D6-1 -> 1.025641 | F14: =F6/E6-1 -> 2.5664557 | G14: =G6/F6-1 -> 2.1858178 | H14: 0.45 | I14: 0.4 | J14: 0.1 | K14: -0.1 | L14: -0.4 | R14: =R6 -> Cloud Memory | T14: =T6/S6-1 -> 0.10872837 | U14: =U6/T6-1 -> 0.14896505 | V14: =V6/U6-1 -> 0.34170112 | W14: =W6/V6-1 -> 0.16310808 | X14: =X6/W6-1 -> 0.46650265 | Y14: =Y6/X6-1 -> 0.77687444 | Z14: =Z6/Y6-1 -> 0.18258407 | AA14: 0.15
B15: =B7 -> Core Data Center | D15: =D7/C7-1 -> #DIV/0! | E15: =E7/D7-1 -> 1.346516 | F15: =F7/E7-1 -> 0.45044141 | G15: =G7/F7-1 -> 4.200166 | H15: 0.7 | I15: 0.3 | J15: 0.15 | K15: -0.15 | L15: -0.5 | R15: =R7 -> Core Data Center | T15: =T7/S7-1 -> -0.20157068 | U15: =U7/T7-1 -> -0.16393443 | V15: =V7/U7-1 -> 0.030718954 | W15: =W7/V7-1 -> 0.50856056 | X15: =X7/W7-1 -> 1.3905002 | Y15: =Y7/X7-1 -> 1.0263759 | Z15: =Z7/Y7-1 -> 0.5621312 | AA15: 0.1
B16: =B8 -> Mobile and Client | D16: =D8/C8-1 -> #DIV/0! | E16: =E8/D8-1 -> 0.577901 | F16: =F8/E8-1 -> 0.016456673 | G16: =G8/F8-1 -> 2.0863479 | H16: 1 | I16: 0.4 | J16: 0.3 | K16: -0.2 | L16: -0.1 | R16: =R8 -> Mobile and Client | T16: =T8/S8-1 -> -0.14263804 | U16: =U8/T8-1 -> 0.45572451 | V16: =V8/U8-1 -> 0.15514593 | W16: =W8/V8-1 -> 0.13164894 | X16: =X8/W8-1 -> 0.81222092 | Y16: =Y8/X8-1 -> 0.49409934 | Z16: =Z8/Y8-1 -> 0.13826925 | AA16: 0.2
B17: =B9 -> Automotive and Embedded | D17: =D9/C9-1 -> #DIV/0! | E17: =E9/D9-1 -> 0.11886929 | F17: =F9/E9-1 -> 0.026344202 | G17: =G9/F9-1 -> 2.3423101 | H17: 1 | I17: 0.4 | J17: 0.1 | K17: -0.1 | L17: -0.3 | R17: =R9 -> Automotive and Embedded | T17: =T9/S9-1 -> -0.10708117 | U17: =U9/T9-1 -> 0.089941973 | V17: =V9/U9-1 -> 0.27240461 | W17: =W9/V9-1 -> 0.19944212 | X17: =X9/W9-1 -> 0.5744186 | Y17: =Y9/X9-1 -> 0.711226 | Z17: =Z9/Y9-1 -> 0.47259387 | AA17: 0.1
B18: =B10 -> Total | D18: =D10/C10-1 -> -0.49476559 | E18: =E10/D10-1 -> 0.61589447 | F18: =F10/E10-1 -> 0.48851101 | G18: =G10/F10-1 -> 2.5632725 | H18: =H10/G10-1 -> 0.73704575 | I18: =I10/H10-1 -> 0.37237718 | J18: =J10/I10-1 -> 0.1776382 | K18: =K10/J10-1 -> -0.14840735 | L18: =L10/K10-1 -> -0.31125632 | R18: =R10 -> Total | T18: =T10/S10-1 -> -0.075324377 | U18: =U10/T10-1 -> 0.1549733 | V18: =V10/U10-1 -> 0.21653586 | W18: =W10/V10-1 -> 0.20574459 | X18: =X10/W10-1 -> 0.74888221 | Y18: =Y10/X10-1 -> 0.73746857 | Z18: =Z10/Y10-1 -> 0.3081098 | AA18: =AA10/Z10-1 -> 0.13907411

Sheet COGS & OpEx
B1: COGS & OpEx forecast
C2: History | H2: Forecast | P2: History | X2: Forecast | AB2: TTM
C4: Revenues | P4: Revenues
B5: =Revenue!B5 -> Revenues (thousand) | C5: =Revenue!C5 -> 2022 | D5: =Revenue!D5 -> 2023 | E5: =Revenue!E5 -> 2024 | F5: =Revenue!F5 -> 2025 | G5: =Revenue!G5 -> 2026 | H5: =G5+1 -> 2027 | I5: =H5+1 -> 2028 | J5: =I5+1 -> 2029 | K5: =J5+1 -> 2030 | L5: =K5+1 -> 2031 | O5: Revenues (thousand) | P5: =Revenue!S5 -> Q1 2025 | Q5: =Revenue!T5 -> Q2 2025 | R5: =Revenue!U5 -> Q3 2025 | S5: =Revenue!V5 -> Q4 2025 | T5: =Revenue!W5 -> Q1 2026 | U5: =Revenue!X5 -> Q2 2026 | V5: =Revenue!Y5 -> Q3 2026 | W5: =Revenue!Z5 -> Q4 2026 | X5: FQ1 | Y5: FQ2 | Z5: FQ3 | AB5: =Revenue!AE5 -> FQ1
B6: Revenue | C6: =Revenue!C10 -> 30758 | D6: =Revenue!D10 -> 15540 | E6: =Revenue!E10 -> 25111 | F6: =Revenue!F10 -> 37378 | G6: =Revenue!G10 -> 133188 | H6: =Revenue!H10 -> 231353.65 | I6: =Revenue!I10 -> 317504.47 | J6: =Revenue!J10 -> 373905.39 | ... L6: =Revenue!L10 -> 219306.38 | O6: Revenue | P6: =Revenue!S10 -> 8709 | Q6: =Revenue!T10 -> 8053 | R6: =Revenue!U10 -> 9301 | S6: =Revenue!V10 -> 11315 | T6: =Revenue!W10 -> 13643 | U6: =Revenue!X10 -> 23860 | V6: =Revenue!Y10 -> 41456 | W6: =Revenue!Z10 -> 54229 | X6: =Revenue!AA10 -> 61770.85 | AB6: =Revenue!AE10 -> 181315.85
C9: COGS and OpEx | P9: COGS & OpEx | AB9: =AB4 -> 0
B10: Expenses (tnousand) | C10: =C5 -> 2022 | D10: =D5 -> 2023 | E10: =E5 -> 2024 | F10: =F5 -> 2025 | G10: =G5 -> 2026 | H10: =H5 -> 2027 | I10: =I5 -> 2028 | J10: =J5 -> 2029 | ... L10: =L5 -> 2031 | O10: Expenses (thousand) | P10: =P5 -> Q1 2025 | Q10: =Q5 -> Q2 2025 | R10: =R5 -> Q3 2025 | S10: =S5 -> Q4 2025 | T10: =T5 -> Q1 2026 | U10: =U5 -> Q2 2026 | V10: =V5 -> Q3 2026 | W10: =W5 -> Q4 2026 | ... Z10: =Z5 -> FQ3 | AB10: =AB5 -> FQ1
B11: =Statement!B191 -> Cloud Memory | C11: =Statement!M196 -> 0 | D11: =Statement!N196 -> 1801 | E11: =Statement!O196 -> 2677 | F11: =Statement!P196 -> 5867 | G11: =Statement!Q196 -> 8865.11 | H11: =H6*H24 -> 11567.683 | I11: =I6*I24 -> 12700.179 | J11: =J6*J24 -> 14956.216 | K11: =K6*K24 -> 14328.679 | L11: =L6*L24 -> 9868.787 | O11: =B11 -> Cloud Memory | P11: =Statement!T196 -> 1293 | Q11: =Statement!U196 -> 1317 | R11: =Statement!V196 -> 1415 | S11: =Statement!W196 -> 1842 | T11: =Statement!X196 -> 1817 | U11: =Statement!Y196 -> 2002 | V11: =Statement!Z196 -> 2278 | W11: =Statement!AA196 -> 2768.11 | X11: =X24*X$6 -> 3088.5425 | AB11: =SUM(U11:X11) -> 10136.653
B12: =Statement!B192 -> Core Data Center | C12: =Statement!M197 -> 0 | D12: =Statement!N197 -> 1967 | E12: =Statement!O197 -> 3638 | F12: =Statement!P197 -> 3995 | G12: =Statement!Q197 -> 5955.2 | H12: =H6*H25 -> 9254.146 | I12: =I6*I25 -> 9525.1341 | J12: =J6*J25 -> 11217.162 | K12: =K6*K25 -> 11144.528 | L12: =L6*L25 -> 7675.7233 | O12: =B12 -> Core Data Center | P12: =Statement!T197 -> 1149 | Q12: =Statement!U197 -> 967 | R12: =Statement!V197 -> 956 | S12: =Statement!W197 -> 923 | T12: =Statement!X197 -> 1157 | U12: =Statement!Y197 -> 1461 | V12: =Statement!Z197 -> 1537 | W12: =Statement!AA197 -> 1800.2 | X12: =X25*X$6 -> 2161.9797 | AB12: =SUM(U12:X12) -> 6960.1797
B13: =Statement!B193 -> Mobile and Client | C13: =Statement!M198 -> 0 | D13: =Statement!N198 -> 9072 | E13: =Statement!O198 -> 10222 | F13: =Statement!P198 -> 8650 | G13: =Statement!Q198 -> 6401.4 | H13: =H6*H26 -> 10410.914 | I13: =I6*I26 -> 11112.656 | J13: =J6*J26 -> 13086.689 | K13: =K6*K26 -> 12736.603 | L13: =L6*L26 -> 8772.2552 | O13: =B13 -> Mobile and Client | P13: =Statement!T198 -> 1899 | Q13: =Statement!U198 -> 1894 | R13: =Statement!V198 -> 2467 | S13: =Statement!W198 -> 2390 | T13: =Statement!X198 -> 1970 | U13: =Statement!Y198 -> 1657 | V13: =Statement!Z198 -> 1463 | W13: =Statement!AA198 -> 1311.4 | X13: =X26*X$6 -> 1853.1255 | AB13: =SUM(U13:X13) -> 6284.5255
B14: =Statement!B194 -> Automotive and Embedded | C14: =Statement!M199 -> 0 | D14: =Statement!N199 -> 2905 | E14: =Statement!O199 -> 3598 | F14: =Statement!P199 -> 3566 | G14: =Statement!Q199 -> 3867.84 | H14: =H6*H27 -> 5783.8413 | I14: =I6*I27 -> 6350.0894 | J14: =J6*J27 -> 7478.1079 | K14: =K6*K27 -> 9552.4526 | L14: =L6*L27 -> 6579.1914 | O14: =B14 -> Automotive and Embedded | P14: =Statement!T199 -> 922 | Q14: =Statement!U199 -> 820 | R14: =Statement!V199 -> 837 | S14: =Statement!W199 -> 987 | T14: =Statement!X199 -> 942 | U14: =Statement!Y199 -> 859 | V14: =Statement!Z199 -> 975 | W14: =Statement!AA199 -> 1091.84 | X14: =X27*X$6 -> 1420.7296 | AB14: =SUM(U14:X14) -> 4346.5696
B15: COGS | C15: =Statement!M6 -> 16860 | D15: =Statement!N6 -> 16956 | E15: =Statement!O6 -> 19498 | F15: =Statement!P6 -> 22505 | G15: =Statement!Q6 -> 25684 | H15: =SUM(H11:H14) -> 37016.584 | I15: =SUM(I11:I14) -> 39688.059 | J15: =SUM(J11:J14) -> 46738.174 | K15: =SUM(K11:K14) -> 47762.263 | L15: =SUM(L11:L14) -> 32895.957 | O15: =B15 -> COGS | P15: =Statement!T6 -> 5361 | Q15: =Statement!U6 -> 5090 | R15: =Statement!V6 -> 5793 | S15: =Statement!W6 -> 6261 | T15: =Statement!X6 -> 5997 | U15: =Statement!Y6 -> 6105 | V15: =Statement!Z6 -> 6400 | W15: =Statement!AA6 -> 7182 | X15: =SUM(X11:X14) -> 8524.3773 | AB15: =SUM(AB11:AB14) -> 27727.927
B16: =Statement!B8 -> R&D | C16: =Statement!M8 -> 3116 | D16: =Statement!N8 -> 3114 | E16: =Statement!O8 -> 3430 | F16: =Statement!P8 -> 3798 | G16: =Statement!Q8 -> 5650 | H16: =H6*H29 -> 9716.8533 | I16: =I6*I29 -> 12700.179 | J16: =J6*J29 -> 14956.216 | K16: =K6*K29 -> 11144.528 | L16: =L6*L29 -> 6579.1914 | O16: =B16 -> R&D | P16: =Statement!T8 -> 888 | Q16: =Statement!U8 -> 898 | R16: =Statement!V8 -> 965 | S16: =Statement!W8 -> 1047 | T16: =Statement!X8 -> 1171 | U16: =Statement!Y8 -> 1250 | V16: =Statement!Z8 -> 1316 | W16: =Statement!AA8 -> 1913 | X16: =X29*X$6 -> 1482.5004 | AB16: =SUM(U16:X16) -> 5961.5004
B17: =Statement!B9 -> Sales and marketing | C17: =Statement!M9 -> 1066 | D17: =Statement!N9 -> 920 | E17: =Statement!O9 -> 1129 | F17: =Statement!P9 -> 1205 | G17: =Statement!Q9 -> 1947 | H17: =H6*H30 -> 3470.3047 | I17: =I6*I30 -> 6350.0894 | J17: =J6*J30 -> 7478.1079 | K17: =K6*K30 -> 4776.2263 | L17: =L6*L30 -> 6579.1914 | O17: =B17 -> Sales and marketing | P17: =Statement!T9 -> 288 | Q17: =Statement!U9 -> 285 | R17: =Statement!V9 -> 318 | S17: =Statement!W9 -> 314 | T17: =Statement!X9 -> 337 | U17: =Statement!Y9 -> 344 | V17: =Statement!Z9 -> 407 | W17: =Statement!AA9 -> 859 | X17: =X30*X$6 -> 803.02105 | AB17: =SUM(U17:X17) -> 2413.021
B18: =Statement!B10 -> Other income/expense | C18: =Statement!M10 -> 14 | D18: =Statement!N10 -> 295 | E18: =Statement!O10 -> -250 | F18: =Statement!P10 -> 100 | G18: =Statement!Q10 -> 567 | H18: 150 | I18: 150 | J18: 150 | K18: 150 | L18: 150 | O18: =B18 -> Other income/expense | P18: =Statement!T10 -> -2 | Q18: =Statement!U10 -> 7 | R18: =Statement!V10 -> 56 | S18: =Statement!W10 -> 39 | T18: =Statement!X10 -> 2 | U18: =Statement!Y10 -> 26 | V18: =Statement!Z10 -> 15 | W18: =Statement!AA10 -> 524 | X18: 150 | AB18: =SUM(U18:X18) -> 715
B19: OpEx | C19: =Statement!M11 -> 4196 | D19: =Statement!N11 -> 4329 | E19: =Statement!O11 -> 4309 | F19: =Statement!P11 -> 5103 | G19: =Statement!Q11 -> 8164 | H19: =SUM(H16:H18) -> 13337.158 | I19: =SUM(I16:I18) -> 19200.268 | J19: =SUM(J16:J18) -> 22584.324 | K19: =SUM(K16:K18) -> 16070.754 | L19: =SUM(L16:L18) -> 13308.383 | O19: =B19 -> OpEx | P19: =Statement!T11 -> 1174 | Q19: =Statement!U11 -> 1190 | R19: =Statement!V11 -> 1339 | S19: =Statement!W11 -> 1400 | T19: =Statement!X11 -> 1510 | U19: =Statement!Y11 -> 1620 | V19: =Statement!Z11 -> 1738 | W19: =Statement!AA11 -> 3296 | X19: =SUM(X16:X18) -> 2435.5214 | AB19: =SUM(U19:X19) -> 9089.5215
C22: Expenses % of Revenue | P22: Expenses % of Revenue
B23: % of revenue | C23: =C5 -> 2022 | D23: =D5 -> 2023 | E23: =E5 -> 2024 | F23: =F5 -> 2025 | G23: =G5 -> 2026 | H23: =H5 -> 2027 | I23: =I5 -> 2028 | J23: =J5 -> 2029 | ... L23: =L5 -> 2031 | O23: % of revenue | P23: =P5 -> Q1 2025 | Q23: =Q5 -> Q2 2025 | R23: =R5 -> Q3 2025 | S23: =S5 -> Q4 2025 | T23: =T5 -> Q1 2026 | U23: =U5 -> Q2 2026 | V23: =V5 -> Q3 2026 | W23: =W5 -> Q4 2026 | ... Z23: =Z5 -> FQ3
B24: =B11 -> Cloud Memory | C24: =C11/C$6 -> 0 | D24: =D11/D$6 -> 0.11589447 | E24: =E11/E$6 -> 0.10660667 | F24: =F11/F$6 -> 0.15696399 | G24: =G11/G$6 -> 0.066560876 | H24: 0.05 | I24: 0.04 | J24: 0.04 | K24: 0.045 | L24: 0.045 | O24: =O11 -> Cloud Memory | P24: =P11/P$6 -> 0.1484671 | Q24: =Q11/Q$6 -> 0.16354154 | R24: =R11/R$6 -> 0.15213418 | S24: =S11/S$6 -> 0.16279275 | T24: =T11/T$6 -> 0.13318185 | U24: =U11/U$6 -> 0.083906119 | V24: =V11/V$6 -> 0.054949826 | W24: =W11/W$6 -> 0.051044828 | X24: 0.05
