Workbook

Sheet Overview
B2: Automatic Data | E2: At a glance | H2: Valuation | K2: Links
B3: Company | C3: #VALUE! | E3: Market capitalization | F3: =Statement!AC155 -> 5104177.2 | H3: ='AVG target price'!B5 -> DCF price | I3: ='AVG target price'!C5 -> 205.87576 | K3: Financials ->'!B13
B4: Ticker | C4: {=_FV(C3,"Ticker symbol",TRUE)} -> NVDA | E4: Enterprise value | F4: =Statement!AC156 -> 5038074.2 | H4: ='AVG target price'!B6 -> EV/EBIT price | I4: ='AVG target price'!C6 -> 439.1811 | K4: Analysis ->'!B13
B5: Price | C5: {=_FV(C3,"Price",TRUE)} -> 210.96 | E5: EPS | F5: =Statement!AC25 -> 7.91 | H5: ='AVG target price'!B7 -> PS price | I5: ='AVG target price'!C7 -> 372.92429 | K5: Forecast ->'!B13
B6: Price Extended Hours | C6: {=_FV(C3,"Price (Extended hours)",TRUE)} -> 211.1155 | E6: PE | F6: =Statement!AC152 -> 26.670038 | H6: ='AVG target price'!B8 -> EV/FCFF price | I6: ='AVG target price'!C8 -> 456.30962 | K6: Valuation ->'!B13
B7: Day change | C7: {=_FV(C3,"Change")} -> -1.25 | E7: PS | F7: =Statement!AC153 -> 16.98837 | H7: ='AVG target price'!B9 -> EV/Sales price | I7: ='AVG target price'!C9 -> 404.87388
B8: Day change extended | C8: {=_FV(C3,"Change (extended hours)",TRUE)} -> 0.1555 | E8: FCF Yield | F8: =Statement!AC163 -> 0.023463919 | H8: ='AVG target price'!B10 -> AVG price | I8: ='AVG target price'!C10 -> 375.83293
B9: Day change % | C9: {=_FV(C3,"Change (%)",TRUE)} -> -0.00589 | E9: Earnings Yield | F9: =Statement!AC164 -> 0.03749526 | H9: ='AVG target price'!B12 -> Upside/Downside | I9: ='AVG target price'!C12 -> 0.78153645
B10: Day change extended % | C10: {=_FV(C3,"Change % (extended hours)",TRUE)} -> 0.0007371 | E10: Buyback Yield | F10: =Statement!AC166 -> 0.010837202
B11: 52 week high | C11: {=_FV(C3,"52 week high",TRUE)} -> 243.37 | E11: Dividend Yield | F11: =Statement!AC165 -> 0.0013272658 | H11: DDM price | I11: =DDM!C26 -> 1.6842105
B12: 52 week low | C12: {=_FV(C3,"52 week low",TRUE)} -> 164.27 | E12: ROA | F12: =Statement!AC121 -> 0.60223498
B13: Beta | C13: {=_FV(C3,"Beta")} -> 2.1957 | E13: ROE | F13: =Statement!AC123 -> 0.84232523 | H13: Reverse DCF rate | I13: ='Reverse DCF'!C17 -> 0.5
B14: Avg volume | C14: {=_FV(C3,"Volume average",TRUE)} -> 107148374 | E14: ROIC | F14: =Statement!AC142 -> 1.0183874 | H14: Reverse DCF price | I14: ='Reverse DCF'!C16 -> 228.84689
E15: Net Cash/Market Cap | F15: =Statement!AC178 -> 0.012950765
E16: Net Cash/Share | F16: =Statement!AC177 -> 2.7428631 | H16: Discount rates used
B17: Unit data and other info | E17: Insider Ownership | F17: =Statement!AC173 -> 0.039553627 | H17: WACC | I17: =DCF!C15 -> 0.12
B18: Units | C18: M | E18: Net Trade Cycle | F18: =Statement!AC146 -> 154.5376 | H18: Cost of Equity | I18: =Multiples!C54 -> 0.12
B19: Units conversion | C19: 1000000 | E19: Net Debt/Equity | F19: =Statement!AC148 -> -0.28867956
B20: Has operating lease | C20: Yes | E20: Quick Ratio | F20: =Statement!AC149 -> 3.775727
B21: Has finance lease | C21: No
B22: Has debt | C22: Yes
B25: Constants | E25: 10 Year Bond Yield
B26: Default tax rate | C26: 0.21 | E26: #VALUE! | F26: {=_FV(E26,"Price")} -> 49.53
B27: Cost of debt | C27: 0.05 | E27: Percentage | F27: =F26/1000 -> 0.04953
B28: Manual WACC | C28: 0.12
B29: Manual Cost of Equity | C29: 0.12
B33: Info
B35: Mission: | C35: Pioneered accelerated computing to help solve the most challanging computational problems
B36: Auditor: | C36: PwC
B42: Notes
B44: Date: | C44: 21.08.2026 | E44: Q2 2027
B45: - | C45: Revenue expected to grow by 70% in FY 2028
B46: - | C46: CapEx by top 5 hyperscalers expected to reach $800B in 2026 and $1.3T in 2027
B47: - | C47: Gross margins will bottom in Q4 2027 to 71%-72% and will settle at 72%-73 in FY 2028
B48: - | C48: Opex for the full year expected to be in the low 50s
B54: Adjustments
B56: Date: | C56: 21.08.2026 | E56: Q2 2027

Sheet Financials ->
H5: Links
H6: Overview'!B3
H7: Financials ->'!B13
H8: Analysis ->'!B13
H9: Forecast ->'!B13
H10: Valuation ->'!B13
B13: Financials ->

Sheet Statement
B2: Date | M2: 30.01.2022 | N2: 29.01.2023 | O2: 28.01.2024 | P2: 26.01.2025 | Q2: 25.01.2026 | T2: 27.10.2024 | U2: 26.01.2025 | V2: 27.04.2025 | W2: 27.07.2025 | X2: 26.10.2025 | Y2: 25.01.2026 | Z2: 26.04.2026 | AA2: 26.07.2026
B3: FY | M3: 2022 | N3: 2023 | O3: 2024 | P3: 2025 | Q3: 2026 | T3: Q3 2025 | U3: Q4 2025 | V3: Q1 2026 | W3: Q2 2026 | X3: Q3 2026 | Y3: Q4 2026 | Z3: Q1 2027 | AA3: Q2 2027 | AC3: TTM/YTD
B4: Income statement
B5: Revenue | M5: 26914 | N5: 26974 | O5: 60922 | P5: 130497 | Q5: 215938 | T5: 35082 | U5: 39331 | V5: 44062 | W5: 46743 | X5: 57006 | Y5: 68127 | Z5: 81615 | AA5: 96221 | AC5: =SUM(X5:AA5) -> 302969
B6: COGS | M6: 9439 | N6: 11618 | O6: 16621 | P6: 32639 | Q6: 62475 | T6: 8926 | U6: 10608 | V6: 17394 | W6: 12890 | X6: 15157 | Y6: 17034 | Z6: 20458 | AA6: 24079 | AC6: =SUM(X6:AA6) -> 76728
B7: Gross Profit | C7: =C5-C6 -> 0 | D7: =D5-D6 -> 0 | E7: =E5-E6 -> 0 | F7: =F5-F6 -> 0 | G7: =G5-G6 -> 0 | H7: =H5-H6 -> 0 | I7: =I5-I6 -> 0 | J7: =J5-J6 -> 0 | ... Q7: =Q5-Q6 -> 153463 | T7: =T5-T6 -> 26156 | U7: =U5-U6 -> 28723 | V7: =V5-V6 -> 26668 | W7: =W5-W6 -> 33853 | X7: =X5-X6 -> 41849 | Y7: =Y5-Y6 -> 51093 | Z7: =Z5-Z6 -> 61157 | AA7: =AA5-AA6 -> 72142 | AC7: =SUM(X7:AA7) -> 226241
B8: R&D | M8: 5268 | N8: 7339 | O8: 8675 | P8: 12914 | Q8: 18497 | T8: 3390 | U8: 3714 | V8: 3989 | W8: 4291 | X8: 4705 | Y8: 5512 | Z8: 6321 | AA8: 7054 | AC8: =SUM(X8:AA8) -> 23592
B9: SG&A | M9: 2166 | N9: 2440 | O9: 2654 | P9: 3491 | Q9: 4579 | T9: 897 | U9: 975 | V9: 1041 | W9: 1122 | X9: 1134 | Y9: 1282 | Z9: 1300 | AA9: 1354 | AC9: =SUM(X9:AA9) -> 5070
B10: OpEx | C10: =SUM(C8:C9) -> 0 | D10: =SUM(D8:D9) -> 0 | E10: =SUM(E8:E9) -> 0 | F10: =SUM(F8:F9) -> 0 | G10: =SUM(G8:G9) -> 0 | H10: =SUM(H8:H9) -> 0 | I10: =SUM(I8:I9) -> 0 | J10: =SUM(J8:J9) -> 0 | ... M10: =SUM(M8:M9) -> 7434 | N10: =SUM(N8:N9)+1353 -> 11132 | O10: =SUM(O8:O9) -> 11329 | P10: =SUM(P8:P9) -> 16405 | Q10: =SUM(Q8:Q9) -> 23076 | T10: =SUM(T8:T9) -> 4287 | U10: =SUM(U8:U9) -> 4689 | V10: =SUM(V8:V9) -> 5030 | W10: =SUM(W8:W9) -> 5413 | X10: =SUM(X8:X9) -> 5839 | Y10: =SUM(Y8:Y9) -> 6794 | Z10: =SUM(Z8:Z9) -> 7621 | AA10: =SUM(AA8:AA9) -> 8408 | AC10: =SUM(X10:AA10) -> 28662
B11: Operating income | M11: 10041 | N11: 4224 | O11: 32972 | P11: 81453 | Q11: 130387 | T11: 21869 | U11: 24034 | V11: 21638 | W11: 28440 | X11: 36010 | Y11: 44299 | Z11: 53536 | AA11: 63734 | AC11: =SUM(X11:AA11) -> 197579
B12: Interest income/expense | M12: =29-236 -> -207 | N12: 5 | O12: =866-257 -> 609 | P12: =1786-247 -> 1539 | Q12: =2300-259 -> 2041 | T12: =472-61 -> 411 | U12: =511-61 -> 450 | V12: =515-63 -> 452 | W12: =592-62 -> 530 | X12: =624-61 -> 563 | Y12: =568-74 -> 494 | Z12: =540-102 -> 438 | AA12: 0 | AC12: =SUM(X12:AA12) -> 1495
B13: Other income/expense | M13: 107 | N13: -48 | O13: 237 | P13: 1034 | Q13: 9022 | T13: 36 | U13: 733 | V13: -180 | W13: 2236 | X13: 1363 | Y13: 5604 | Z13: 15939 | AA13: 7773 | AC13: =SUM(X13:AA13) -> 30679
B14: Income before taxes | M14: 9941 | N14: 4181 | O14: 33818 | P14: 84026 | Q14: 141450 | T14: 22316 | U14: 25217 | V14: 21910 | W14: 31206 | X14: 37936 | Y14: 50397 | Z14: 69903 | AA14: 71507 | AC14: =SUM(X14:AA14) -> 229743
B15: Income tax expense/benefit | M15: -189 | N15: 187 | O15: -4058 | P15: -11146 | Q15: -21383 | T15: -3007 | U15: -3126 | V15: -3135 | W15: -4784 | X15: -6026 | Y15: -7437 | Z15: -11582 | AA15: -11819 | AC15: =SUM(X15:AA15) -> -36864
B16: Non-controlling interest | M16: 0 | N16: 0 | O16: 0 | P16: 0 | Q16: 0 | T16: 0 | U16: 0 | V16: 0 | W16: 0 | X16: 0 | Y16: 0 | Z16: 0 | AA16: 0 | AC16: =SUM(X16:AA16) -> 0
B17: Net income | M17: 9752 | N17: 4368 | O17: 29760 | P17: 72880 | Q17: 120067 | T17: 19309 | U17: 22091 | V17: 18775 | W17: 26422 | X17: 31910 | Y17: 42960 | Z17: 58321 | AA17: 59688 | AC17: =SUM(X17:AA17) -> 192879
B18: Basic Shares outstanding avg | M18: 2496 | N18: 2487 | O18: 2469 | P18: 24555 | Q18: 24359 | T18: 24533 | U18: 24489 | V18: 24441 | W18: 24366 | X18: 24327 | Y18: 24304 | Z18: 24286 | AA18: 24190 | AC18: =AVERAGE(X18:AA18) -> 24276.75
B19: Basic Shares outstanding avg adjusted | C19: =C18*C$84 -> 0 | D19: =D18*D$84 -> 0 | E19: =E18*E$84 -> 0 | F19: =F18*F$84 -> 0 | G19: =G18*G$84 -> 0 | H19: =H18*H$84 -> 0 | I19: =I18*I$84 -> 0 | J19: =J18*J$84 -> 0 | ... Q19: =Q18*Q$84 -> 24359 | T19: =T18*T$84 -> 24533 | U19: =U18*U$84 -> 24489 | V19: =V18*V$84 -> 24441 | W19: =W18*W$84 -> 24366 | X19: =X18*X$84 -> 24327 | Y19: =Y18*Y$84 -> 24304 | Z19: =Z18*Z$84 -> 24286 | AA19: =AA18*AA$84 -> 24190 | AC19: =AC18*AC$84 -> 24276.75
B20: Diluted Shares outstanding avg | M20: 2535 | N20: 2507 | O20: 2494 | P20: 24804 | Q20: 24514 | T20: 24774 | U20: 24706 | V20: 24611 | W20: 24532 | X20: 24483 | Y20: 24432 | Z20: 24391 | AA20: 24285 | AC20: =AVERAGE(X20:AA20) -> 24397.75
B21: Diluted Shares outstanding avg adjusted | C21: =C20*C$84 -> 0 | D21: =D20*D$84 -> 0 | E21: =E20*E$84 -> 0 | F21: =F20*F$84 -> 0 | G21: =G20*G$84 -> 0 | H21: =H20*H$84 -> 0 | I21: =I20*I$84 -> 0 | J21: =J20*J$84 -> 0 | ... Q21: =Q20*Q$84 -> 24514 | T21: =T20*T$84 -> 24774 | U21: =U20*U$84 -> 24706 | V21: =V20*V$84 -> 24611 | W21: =W20*W$84 -> 24532 | X21: =X20*X$84 -> 24483 | Y21: =Y20*Y$84 -> 24432 | Z21: =Z20*Z$84 -> 24391 | AA21: =AA20*AA$84 -> 24285 | AC21: =AC20*AC$84 -> 24397.75
B22: Basic EPS | M22: 3.91 | N22: 1.76 | O22: 12.05 | P22: 2.97 | Q22: 4.93 | T22: 0.79 | U22: 0.9 | V22: 0.77 | W22: 1.08 | X22: 1.31 | Y22: 1.77 | Z22: 2.4 | AA22: 2.47 | AC22: =SUM(X22:AA22) -> 7.95
B23: Basic EPS adjusted | M23: =M22/M$84 -> 0.391 | N23: =N22/N$84 -> 0.176 | O23: =O22/O$84 -> 1.205 | P23: =P22/P$84 -> 2.97 | Q23: =Q22/Q$84 -> 4.93 | T23: =T22/T$84 -> 0.79 | U23: =U22/U$84 -> 0.9 | V23: =V22/V$84 -> 0.77 | W23: =W22/W$84 -> 1.08 | X23: =X22/X$84 -> 1.31 | Y23: =Y22/Y$84 -> 1.77 | Z23: =Z22/Z$84 -> 2.4 | AA23: =AA22/AA$84 -> 2.47 | AC23: =AC22/AC$84 -> 7.95
B24: Diluted EPS | M24: 3.85 | N24: 1.74 | O24: 11.93 | P24: 2.94 | Q24: 4.9 | T24: 0.78 | U24: 0.89 | V24: 0.76 | W24: 1.08 | X24: 1.3 | Y24: 1.76 | Z24: 2.39 | AA24: 2.46 | AC24: =SUM(X24:AA24) -> 7.91
B25: Diluted EPS adjusted | M25: =M24/M$84 -> 0.385 | N25: =N24/N$84 -> 0.174 | O25: =O24/O$84 -> 1.193 | P25: =P24/P$84 -> 2.94 | Q25: =Q24/Q$84 -> 4.9 | T25: =T24/T$84 -> 0.78 | U25: =U24/U$84 -> 0.89 | V25: =V24/V$84 -> 0.76 | W25: =W24/W$84 -> 1.08 | X25: =X24/X$84 -> 1.3 | Y25: =Y24/Y$84 -> 1.76 | Z25: =Z24/Z$84 -> 2.39 | AA25: =AA24/AA$84 -> 2.46 | AC25: =AC24/AC$84 -> 7.91
B27: Balance sheet
B28: Cash and cash equivalents | M28: =1990+19218 -> 21208 | N28: =3389+9907 -> 13296 | O28: =7280+18704 -> 25984 | P28: =8589+34621 -> 43210 | Q28: =10605+51951 -> 62556 | T28: =9107+29380 -> 38487 | U28: =8589+34621 -> 43210 | V28: =15234+38457 -> 53691 | W28: =11639+45152 -> 56791 | X28: =11486+49122 -> 60608 | Y28: =10605+39065+12886 -> 62556 | Z28: =13237+37098+30237 -> 80572 | AA28: =22443+34143+42783 -> 99369 | AC28: =AA28 -> 99369
B29: Acc receivable | M29: 4650 | N29: 3827 | O29: 9999 | P29: 23065 | Q29: 38466 | T29: 17693 | U29: 23065 | V29: 22132 | W29: 27808 | X29: 33391 | Y29: 38466 | Z29: 40710 | AA29: 63059 | AC29: =AA29 -> 63059
B30: Inventory | M30: 2605 | N30: 5159 | O30: 5282 | P30: 10080 | Q30: 21403 | T30: 7654 | U30: 10080 | V30: 11333 | W30: 14962 | X30: 19784 | Y30: 21403 | Z30: 25797 | AA30: 31575 | AC30: =AA30 -> 31575
B31: Current assets | M31: 28829 | N31: 23073 | O31: 44345 | P31: 80126 | Q31: 125605 | T31: 67640 | U31: 80126 | V31: 89935 | W31: 102219 | X31: 116492 | Y31: 125605 | Z31: 150995 | AA31: 197412 | AC31: =AA31 -> 197412
B32: PP&E | M32: 2778 | N32: 3807 | O32: 3914 | P32: 6283 | Q32: 10383 | T32: 5343 | U32: 6283 | V32: 7136 | W32: 9141 | X32: 9780 | Y32: 10383 | Z32: 12403 | AA32: 14285 | AC32: =AA32 -> 14285
B33: Marketable securities and investments | M33: 0 | N33: 0 | O33: 0 | P33: 0 | Q33: 0 | T33: 0 | U33: 0 | V33: 0 | W33: 0 | X33: 0 | Y33: 0 | Z33: 0 | AA33: 0 | AC33: =AA33 -> 0
B34: Goodwill | M34: 4349 | N34: 4372 | O34: 4430 | P34: 5188 | Q34: 20832 | T34: 4724 | U34: 5188 | V34: 5498 | W34: 5755 | X34: 6261 | Y34: 20832 | Z34: 20894 | AA34: 21125 | AC34: =AA34 -> 21125
B35: Long term assets | M35: =M36-M31 -> 15358 | N35: =N36-N31 -> 18109 | O35: =O36-O31 -> 21383 | P35: =P36-P31 -> 31475 | Q35: =Q36-Q31 -> 81198 | T35: =T36-T31 -> 28373 | U35: =U36-U31 -> 31475 | V35: =V36-V31 -> 35319 | W35: =W36-W31 -> 38521 | X35: =X36-X31 -> 44656 | Y35: =Y36-Y31 -> 81198 | Z35: =Z36-Z31 -> 108479 | AA35: =AA36-AA31 -> 122860 | AC35: =AA35 -> 122860
B36: Total assets | M36: 44187 | N36: 41182 | O36: 65728 | P36: 111601 | Q36: 206803 | T36: 96013 | U36: 111601 | V36: 125254 | W36: 140740 | X36: 161148 | Y36: 206803 | Z36: 259474 | AA36: 320272 | AC36: =AA36 -> 320272
B37: Acc payable | M37: 1783 | N37: 1193 | O37: 2699 | P37: 6310 | Q37: 9812 | T37: 5353 | U37: 6310 | V37: 7331 | W37: 9064 | X37: 8624 | Y37: 9812 | Z37: 13097 | AA37: 15059 | AC37: =AA37 -> 15059
B38: Debt | M38: 0 | N38: 1250 | O38: 1250 | P38: 0 | Q38: 999 | T38: 0 | U38: 0 | V38: 0 | W38: 0 | X38: 999 | Y38: 999 | Z38: 1000 | AA38: 1000 | AC38: =AA38 -> 1000
B39: Current liabilities | M39: 4335 | N39: 6563 | O39: 10631 | P39: 18047 | Q39: 32163 | T39: 16479 | U39: 18047 | V39: 26542 | W39: 24257 | X39: 26075 | Y39: 32163 | Z39: 43884 | AA39: 43019 | AC39: =AA39 -> 43019
B40: Debt | M40: 10946 | N40: 9703 | O40: 8459 | P40: 8463 | Q40: 7469 | T40: 8462 | U40: 8463 | V40: 8464 | W40: 8466 | X40: 7468 | Y40: 7569 | Z40: 7470 | AA40: 32266 | AC40: =AA40 -> 32266
B41: Long term liabilities | M41: =M42-M39 -> 13240 | N41: =N42-N39 -> 12518 | O41: =O42-O39 -> 12119 | P41: =P42-P39 -> 14227 | Q41: =Q42-Q39 -> 17347 | T41: =T42-T39 -> 13635 | U41: =U42-U39 -> 14227 | V41: =V42-V39 -> 14869 | W41: =W42-W39 -> 16352 | X41: =X42-X39 -> 16176 | Y41: =Y42-Y39 -> 17347 | Z41: =Z42-Z39 -> 20116 | AA41: =AA42-AA39 -> 48269 | AC41: =AA41 -> 48269
B42: Total liabilities | M42: 17575 | N42: 19081 | O42: 22750 | P42: 32274 | Q42: 49510 | T42: 30114 | U42: 32274 | V42: 41411 | W42: 40609 | X42: 42251 | Y42: 49510 | Z42: 64000 | AA42: 91288 | AC42: =AA42 -> 91288
...

Sheet Analysis ->
H5: Links
H6: Overview'!B3
H7: Financials ->'!B13
H8: Analysis ->'!B13
H9: Forecast ->'!B13
H10: Valuation ->'!B13
B13: Analysis ->

Sheet Basic
B1: TTM/YTD data
B4: Overview | E4: CAGR
B5: Price | C5: =Overview!C5 -> 210.96 | F5: 5Y | G5: 10Y
B6: Market capitalization | C6: =Statement!AC155 -> 5104177.2 | E6: Revenue | F6: =IF(Statement!M5<=0,"N/A",_xlfn.RRI(4,Statement!M5,Statement!Q5)) -> 0.68301391 | G6: =IF(Statement!H5<=0,"N/A",_xlfn.RRI(9,Statement!H5,Statement!Q5)) -> N/A
B7: Enterprise value | C7: =Statement!AC156 -> 5038074.2 | E7: Net income | F7: =IF(OR(Statement!M17<=0, Statement!Q17<=0), "N/A", _xlfn.RRI(4, Statement!M17, Statement!Q17)) -> 0.87319285 | G7: =IF(OR(Statement!H17<=0, Statement!Q17<=0), "N/A", _xlfn.RRI(9, Statement!H17, Statement!Q17)) -> N/A
B8: PE | C8: =Statement!AC152 -> 26.670038 | E8: EPS | F8: =IF(OR(Statement!M25<=0, Statement!Q25<=0), "N/A", _xlfn.RRI(4, Statement!M25, Statement!Q25)) -> 0.88879071 | G8: =IF(OR(Statement!H25<=0, Statement!Q25<=0), "N/A", _xlfn.RRI(9, Statement!H25, Statement!Q25)) -> N/A
B9: PS | C9: =Statement!AC153 -> 16.98837 | E9: Dividend | F9: =IF(Statement!M81<=0,"N/A",_xlfn.RRI(4,Statement!M81,Statement!Q81)) -> 0.25743343 | G9: =IF(Statement!H81<=0,"N/A",_xlfn.RRI(9,Statement!H81,Statement!Q81)) -> N/A
B10: PB | C10: =Statement!AC154 -> 22.203019 | E10: Price | F10: =IF(Statement!M115<=0,"N/A",_xlfn.RRI(4,Statement!M115,Statement!Q115)) -> 0.69306912 | G10: =IF(Statement!H115<=0,"N/A",_xlfn.RRI(9,Statement!H115,Statement!Q115)) -> N/A
B11: EV/Revenue | C11: =Statement!AC157 -> 16.629009
B12: EV/EBIT | C12: =Statement!AC158 -> 25.499037
B15: Margins | E15: Earnings quality
B16: Gross margin | C16: =Statement!AC99 -> 0.74674637 | E16: Net income | F16: =Statement!AC17 -> 192879
B17: Operating margin | C17: =Statement!AC100 -> 0.65214263 | E17: Operating cash | F17: =Statement!AC58 -> 134361
B18: Net margin | C18: =Statement!AC101 -> 0.63662949 | E18: Cash accruals | F18: =IF(OR(F16<=0, F17<=0),"N/A",F16-F17) -> 58518
B21: DuPont Identity | E21: Performance indicators
B22: Profit Margin (Earnings/Revenue) | C22: =Statement!AC119 -> 0.63662949 | E22: ROA | F22: =C24 -> 0.60223498
B23: Asset Turnover (Revenue/Total assets) | C23: =Statement!AC120 -> 0.94597405 | E23: ROE | F23: =C26 -> 0.84232523
B24: ROA | C24: =Statement!AC121 -> 0.60223498 | E24: ROIC | F24: =Statement!AC142 -> 1.0183874
B25: Equity Multiplier (Total assets/Equity) | C25: =Statement!AC122 -> 1.3986654
B26: ROE | C26: =Statement!AC123 -> 0.84232523
B29: Cash conversion cycle | E29: Liquidity ratios
B30: DSO | C30: =Statement!AC143 -> 75.969934 | E30: Debt/Equity | F30: =Statement!AC147 -> 0.14527653
B31: DIO | C31: =Statement!AC144 -> 150.20429 | E31: Net Debt/Equity | F31: =Statement!AC148 -> -0.28867956
B32: DPO | C32: =Statement!AC145 -> 71.636625 | E32: Current ratio | F32: =Statement!AC150 -> 4.5889491
B33: Net trade cycle | C33: =Statement!AC146 -> 154.5376 | E33: Quick ratio | F33: =Statement!AC149 -> 3.775727
E34: Interest coverage | F34: =Statement!AC151 -> N/A
B37: Earnings yields | E37: Payout ratios
B38: Earnings yield | C38: =Statement!AC164 -> 0.03749526 | E38: Dividend payout ratio | F38: =Statement!AC170 -> 0.056577937
B39: FCF yield | C39: =Statement!AC163 -> 0.023463919 | E39: Buyback payout ratio | F39: =Statement!AC171 -> 0.46186667
B40: Dividend yield | C40: =Statement!AC165 -> 0.0013272658 | E40: Full payout ratio | F40: =Statement!AC172 -> 0.51844461
B41: Buyback yield | C41: =Statement!AC166 -> 0.010837202
B42: Total shareholder yield | C42: =Statement!AC167 -> 0.012164742
B45: Ownership | E45: Cash holdings
B46: Insider ownership | C46: =Statement!AC173 -> 0.039553627 | E46: Cash per share | F46: =Statement!AC174 -> 4.123195
E47: Net cash per share | F47: =Statement!AC177 -> 2.7428631
E48: Net cash to market cap | F48: =Statement!AC178 -> 0.012950765
B51: Stock based compensation | E51: CapEx usage
B52: Stock based compensation % OCF | C52: =Statement!AC175 -> 0.053899569 | E52: Capex to Revenue | F52: =Statement!AC179 -> 0.024276411
B53: Stock based compensation % Revenue | C53: =Statement!AC176 -> 0.023903436 | E53: CapEx to OCF | F53: =Statement!AC180 -> 0.054740587
E54: CapEx to D&A | F54: =Statement!AC181 -> 1.9948468

Sheet Yearly Analysis
C2: =Statement!M2 -> 30.01.2022 | D2: =Statement!N2 -> 29.01.2023 | E2: =Statement!O2 -> 28.01.2024 | F2: =Statement!P2 -> 26.01.2025 | G2: =Statement!Q2 -> 25.01.2026
C3: =Statement!M3 -> 2022 | D3: =Statement!N3 -> 2023 | E3: =Statement!O3 -> 2024 | F3: =Statement!P3 -> 2025 | G3: =Statement!Q3 -> 2026 | I3: =Statement!AC3 -> TTM/YTD
B5: Overview
B6: Price | C6: =Statement!M114 -> 228.4 | D6: =Statement!N114 -> 203.6 | E6: =Statement!O114 -> 610.3 | F6: =Statement!P114 -> 142.62 | G6: =Statement!Q114 -> 187.67 | I6: =Statement!AC114 -> 210.96
B7: Market capitalization | C7: =Statement!M155 -> 582191.6 | D7: =Statement!N155 -> 506964 | E7: =Statement!O155 -> 1541007.5 | F7: =Statement!P155 -> 3515440.4 | G7: =Statement!Q155 -> 4589469.8 | I7: =Statement!AC155 -> 5104177.2
B8: Enterprise value | C8: =Statement!M156 -> 571929.6 | D8: =Statement!N156 -> 504621 | E8: =Statement!O156 -> 1524732.5 | F8: =Statement!P156 -> 3480693.4 | G8: =Statement!Q156 -> 4535381.8 | I8: =Statement!AC156 -> 5038074.2
B9: PE | C9: =Statement!M152 -> 59.324675 | D9: =Statement!N152 -> 117.01149 | E9: =Statement!O152 -> 51.156748 | F9: =Statement!P152 -> 48.510204 | G9: =Statement!Q152 -> 38.3 | I9: =Statement!AC152 -> 26.670038
B10: PS | C10: =Statement!M153 -> 21.512744 | D10: =Statement!N153 -> 18.922859 | E10: =Statement!O153 -> 24.984213 | F10: =Statement!P153 -> 27.108259 | G10: =Statement!Q153 -> 21.304923 | I10: =Statement!AC153 -> 16.98837
B11: PB | C11: =Statement!M154 -> 21.542312 | D11: =Statement!N154 -> 22.754265 | E11: =Statement!O154 -> 35.500721 | F11: =Statement!P154 -> 43.868141 | G11: =Statement!Q154 -> 28.992905 | I11: =Statement!AC154 -> 22.203019
B12: EV/Revenue | C12: =Statement!M157 -> 21.250264 | D12: =Statement!N157 -> 18.707681 | E12: =Statement!O157 -> 25.027617 | F12: =Statement!P157 -> 26.672593 | G12: =Statement!Q157 -> 21.003167 | I12: =Statement!AC157 -> 16.629009
B13: EV/EBIT | C13: =Statement!M158 -> 56.959426 | D13: =Statement!N158 -> 119.4652 | E13: =Statement!O158 -> 46.243252 | F13: =Statement!P158 -> 42.732538 | G13: =Statement!Q158 -> 34.784003 | I13: =Statement!AC158 -> 25.499037
B15: Margins
B16: Gross margin | C16: =Statement!M99 -> 0.64929033 | D16: =Statement!N99 -> 0.56928894 | E16: =Statement!O99 -> 0.72717573 | F16: =Statement!P99 -> 0.74988697 | G16: =Statement!Q99 -> 0.71068084 | I16: =Statement!AC99 -> 0.74674637
B17: Operating margin | C17: =Statement!M100 -> 0.37307721 | D17: =Statement!N100 -> 0.15659524 | E17: =Statement!O100 -> 0.54121664 | F17: =Statement!P100 -> 0.62417527 | G17: =Statement!Q100 -> 0.60381684 | I17: =Statement!AC100 -> 0.65214263
B18: Net margin | C18: =Statement!M101 -> 0.3623393 | D18: =Statement!N101 -> 0.16193371 | E18: =Statement!O101 -> 0.48849348 | F18: =Statement!P101 -> 0.55848027 | G18: =Statement!Q101 -> 0.55602534 | I18: =Statement!AC101 -> 0.63662949
B20: Earnings quality
B21: Net income | C21: =Statement!M17 -> 9752 | D21: =Statement!N17 -> 4368 | E21: =Statement!O17 -> 29760 | F21: =Statement!P17 -> 72880 | G21: =Statement!Q17 -> 120067 | I21: =Statement!AC17 -> 192879
B22: Operating cash | C22: =Statement!M58 -> 9108 | D22: =Statement!N58 -> 5641 | E22: =Statement!O58 -> 28090 | F22: =Statement!P58 -> 64089 | G22: =Statement!Q58 -> 102718 | I22: =Statement!AC58 -> 134361
B23: Cash accruals | C23: =IF(OR(C21<=0, C22<=0),"N/A",C21-C22) -> 644 | D23: =IF(OR(D21<=0, D22<=0),"N/A",D21-D22) -> -1273 | E23: =IF(OR(E21<=0, E22<=0),"N/A",E21-E22) -> 1670 | F23: =IF(OR(F21<=0, F22<=0),"N/A",F21-F22) -> 8791 | G23: =IF(OR(G21<=0, G22<=0),"N/A",G21-G22) -> 17349 | I23: =IF(OR(I21<=0, I22<=0),"N/A",I21-I22) -> 58518
B25: DuPont Identity
B26: Profit Margin (Earnings/Revenue) | C26: =Statement!M119 -> 0.3623393 | D26: =Statement!N119 -> 0.16193371 | E26: =Statement!O119 -> 0.48849348 | F26: =Statement!P119 -> 0.55848027 | G26: =Statement!Q119 -> 0.55602534 | I26: =Statement!AC119 -> 0.63662949
B27: Asset Turnover (Revenue/Total assets) | C27: =Statement!M120 -> 0.60909317 | D27: =Statement!N120 -> 0.6549949 | E27: =Statement!O120 -> 0.92688048 | F27: =Statement!P120 -> 1.1693175 | G27: =Statement!Q120 -> 1.0441725 | I27: =Statement!AC120 -> 0.94597405
B28: ROA | C28: =Statement!M121 -> 0.2206984 | D28: =Statement!N121 -> 0.10606576 | E28: =Statement!O121 -> 0.45277507 | F28: =Statement!P121 -> 0.65304074 | G28: =Statement!Q121 -> 0.58058636 | I28: =Statement!AC121 -> 0.60223498
B29: Equity Multiplier (Total assets/Equity) | C29: =Statement!M122 -> 1.6604164 | D29: =Statement!N122 -> 1.8633546 | E29: =Statement!O122 -> 1.5293406 | F29: =Statement!P122 -> 1.4068476 | G29: =Statement!Q122 -> 1.3147629 | I29: =Statement!AC122 -> 1.3986654
B30: ROE | C30: =Statement!M123 -> 0.36645123 | D30: =Statement!N123 -> 0.19763812 | E30: =Statement!O123 -> 0.6924473 | F30: =Statement!P123 -> 0.91872881 | G30: =Statement!Q123 -> 0.7633334 | I30: =Statement!AC123 -> 0.84232523
B32: Performance Indicators
B33: ROA | C33: =C28 -> 0.2206984 | D33: =D28 -> 0.10606576 | E33: =E28 -> 0.45277507 | F33: =F28 -> 0.65304074 | G33: =G28 -> 0.58058636 | I33: =I28 -> 0.60223498
B34: ROE | C34: =C30 -> 0.36645123 | D34: =D30 -> 0.19763812 | E34: =E30 -> 0.6924473 | F34: =F30 -> 0.91872881 | G34: =G30 -> 0.7633334 | I34: =I30 -> 0.84232523
B35: ROIC | C35: =Statement!M142 -> 0.60245252 | D35: =Statement!N142 -> 0.21378682 | E35: =Statement!O142 -> 1.0866014 | F35: =Statement!P142 -> 1.5847534 | G35: =Statement!Q142 -> 1.0723937 | I35: =Statement!AC142 -> 1.0183874
B37: Cash conversion cycle
B38: DSO | C38: =Statement!M143 -> 63.061975 | D38: =Statement!N143 -> 51.785238 | E38: =Statement!O143 -> 59.906684 | F38: =Statement!P143 -> 64.512786 | G38: =Statement!Q143 -> 65.01908 | I38: =Statement!AC143 -> 75.969934
B39: DIO | C39: =Statement!M144 -> 100.73366 | D39: =Statement!N144 -> 162.0791 | E39: =Statement!O144 -> 115.99362 | F39: =Statement!P144 -> 112.72404 | G39: =Statement!Q144 -> 125.04354 | I39: =Statement!AC144 -> 150.20429
B40: DPO | C40: =Statement!M145 -> 68.947452 | D40: =Statement!N145 -> 37.480203 | E40: =Statement!O145 -> 59.270501 | F40: =Statement!P145 -> 70.564356 | G40: =Statement!Q145 -> 57.32501 | I40: =Statement!AC145 -> 71.636625
B41: Net trade cycle | C41: =Statement!M146 -> 94.848181 | D41: =Statement!N146 -> 176.38414 | E41: =Statement!O146 -> 116.62981 | F41: =Statement!P146 -> 106.67247 | G41: =Statement!Q146 -> 132.73761 | I41: =Statement!AC146 -> 154.5376
B43: Liquidity ratios
B44: Debt/Equity | C44: =Statement!M147 -> 0.4113182 | D44: =Statement!N147 -> 0.49558843 | E44: =Statement!O147 -> 0.22590628 | F44: =Statement!P147 -> 0.10668499 | G44: =Statement!Q147 -> 0.053835835 | I44: =Statement!AC147 -> 0.14527653
B45: Net Debt/Equity | C45: =Statement!M148 -> -0.38561551 | D45: =Statement!N148 -> -0.1060133 | E45: =Statement!O148 -> -0.37868212 | F45: =Statement!P148 -> -0.43802236 | G45: =Statement!Q148 -> -0.34386781 | I45: =Statement!AC148 -> -0.28867956
B46: Quick ratio | C46: =Statement!M149 -> 5.9649366 | D46: =Statement!N149 -> 2.6090203 | E46: =Statement!O149 -> 3.3847239 | F46: =Statement!P149 -> 3.6723555 | G46: =Statement!Q149 -> 3.1409383 | I46: =Statement!AC149 -> 3.775727
B47: Current ratio | C47: =Statement!M150 -> 6.6502884 | D47: =Statement!N150 -> 3.5156179 | E47: =Statement!O150 -> 4.1712915 | F47: =Statement!P150 -> 4.4398515 | G47: =Statement!Q150 -> 3.9052638 | I47: =Statement!AC150 -> 4.5889491
B48: Interest coverage | C48: =Statement!M151 -> 48.507246 | D48: =Statement!N151 -> N/A | E48: =Statement!O151 -> N/A | F48: =Statement!P151 -> N/A | G48: =Statement!Q151 -> N/A | I48: =Statement!AC151 -> N/A
...

Sheet Quarter analysis
C3: Latest 2 quarters | F3: YoY
C4: =Statement!Z2 -> 26.04.2026 | D4: =Statement!AA2 -> 26.07.2026 | F4: =Statement!W2 -> 27.07.2025 | G4: =Statement!AA2 -> 26.07.2026
B5: Income statement growth | C5: =Statement!Z3 -> Q1 2027 | D5: =Statement!AA3 -> Q2 2027 | F5: =Statement!W3 -> Q2 2026 | G5: =Statement!AA3 -> Q2 2027
B6: Revenue | C6: =Statement!Z5 -> 81615 | D6: =Statement!AA5 -> 96221 | F6: =Statement!W5 -> 46743 | G6: =Statement!AA5 -> 96221
B7: Growth | C7: =Statement!AA88 -> 0.1789622 | F7: =IF(F6=0, IF(G6=0,0,IF(G6>0,1,-1)), (G6-F6)/ABS(F6) ) -> 1.0585114
B8: COGS | C8: =Statement!Z6 -> 20458 | D8: =Statement!AA6 -> 24079 | F8: =Statement!W6 -> 12890 | G8: =Statement!AA6 -> 24079
B9: Growth | C9: =Statement!AA89 -> 0.17699677 | F9: =IF(F8=0, IF(G8=0,0,IF(G8>0,1,-1)), (G8-F8)/ABS(F8) ) -> 0.86803724
B10: Gross Profit | C10: =Statement!Z7 -> 61157 | D10: =Statement!AA7 -> 72142 | F10: =Statement!W7 -> 33853 | G10: =Statement!AA7 -> 72142
B11: Growth | C11: =Statement!AA90 -> 0.17961967 | F11: =IF(F10=0, IF(G10=0,0,IF(G10>0,1,-1)), (G10-F10)/ABS(F10) ) -> 1.1310371
B12: OpEx | C12: =Statement!Z10 -> 7621 | D12: =Statement!AA10 -> 8408 | F12: =Statement!W10 -> 5413 | G12: =Statement!AA10 -> 8408
B13: Growth | C13: =Statement!AA93 -> 0.10326729 | F13: =IF(F12=0, IF(G12=0,0,IF(G12>0,1,-1)), (G12-F12)/ABS(F12) ) -> 0.55329762
B14: Operating profit | C14: =Statement!Z11 -> 53536 | D14: =Statement!AA11 -> 63734 | F14: =Statement!W11 -> 28440 | G14: =Statement!AA11 -> 63734
B15: Growth | C15: =Statement!AA94 -> 0.19048864 | F15: =IF(F14=0, IF(G14=0,0,IF(G14>0,1,-1)), (G14-F14)/ABS(F14) ) -> 1.2409986
B16: Net income | C16: =Statement!Z17 -> 58321 | D16: =Statement!AA17 -> 59688 | F16: =Statement!W17 -> 26422 | G16: =Statement!AA17 -> 59688
B17: Growth | C17: =Statement!AA96 -> 0.023439241 | F17: =IF(F16=0, IF(G16=0,0,IF(G16>0,1,-1)), (G16-F16)/ABS(F16) ) -> 1.2590266
B18: Diluted shares outstanding | C18: =Statement!Z21 -> 24391 | D18: =Statement!AA21 -> 24285 | F18: =Statement!W21 -> 24532 | G18: =Statement!AA21 -> 24285
B19: Growth | C19: =IF(C18=0, IF(D18=0,0,IF(D18>0,1,-1)), (D18-C18)/ABS(C18) ) -> -0.0043458653 | F19: =IF(F18=0, IF(G18=0,0,IF(G18>0,1,-1)), (G18-F18)/ABS(F18) ) -> -0.010068482
B20: Diluted EPS | C20: =Statement!Z25 -> 2.39 | D20: =Statement!AA25 -> 2.46 | F20: =Statement!W25 -> 1.08 | G20: =Statement!AA25 -> 2.46
B21: Growth | C21: =IF(C20=0, IF(D20=0,0,IF(D20>0,1,-1)), (D20-C20)/ABS(C20) ) -> 0.029288703 | F21: =IF(F20=0, IF(G20=0,0,IF(G20>0,1,-1)), (G20-F20)/ABS(F20) ) -> 1.2777778
B23: Revenue breakdown | C23: =C5 -> Q1 2027 | D23: =D5 -> Q2 2027 | F23: =F5 -> Q2 2026 | G23: =G5 -> Q2 2027
B24: HyperScale | C24: =Statement!Z189 -> 37869 | D24: =Statement!AA189 -> 48710 | F24: =Statement!W189 -> 23883 | G24: =Statement!AA189 -> 48710
B25: Growth | C25: =IF(C24=0, IF(D24=0,0,IF(D24>0,1,-1)), (D24-C24)/ABS(C24) ) -> 0.28627637 | F25: =IF(F24=0, IF(G24=0,0,IF(G24>0,1,-1)), (G24-F24)/ABS(F24) ) -> 1.039526
B26: AI Clouds | C26: =Statement!Z190 -> 37377 | D26: =Statement!AA190 -> 40313 | F26: =Statement!W190 -> 17213 | G26: =Statement!AA190 -> 40313
B27: Growth | C27: =IF(C26=0, IF(D26=0,0,IF(D26>0,1,-1)), (D26-C26)/ABS(C26) ) -> 0.078550981 | F27: =IF(F26=0, IF(G26=0,0,IF(G26>0,1,-1)), (G26-F26)/ABS(F26) ) -> 1.3420089
B28: Data Center | C28: =Statement!Z191 -> 75246 | D28: =Statement!AA191 -> 89023 | F28: =Statement!W191 -> 41096 | G28: =Statement!AA191 -> 89023
B29: Growth | C29: =IF(C28=0, IF(D28=0,0,IF(D28>0,1,-1)), (D28-C28)/ABS(C28) ) -> 0.18309279 | F29: =IF(F28=0, IF(G28=0,0,IF(G28>0,1,-1)), (G28-F28)/ABS(F28) ) -> 1.1662206
B30: Edge Computing | C30: =Statement!Z192 -> 6369 | D30: =Statement!AA192 -> 7198 | F30: =Statement!W192 -> 5647 | G30: =Statement!AA192 -> 7198
B31: Growth | C31: =IF(C30=0, IF(D30=0,0,IF(D30>0,1,-1)), (D30-C30)/ABS(C30) ) -> 0.13016172 | F31: =IF(F30=0, IF(G30=0,0,IF(G30>0,1,-1)), (G30-F30)/ABS(F30) ) -> 0.27465911

Sheet Graphs Year
C55: =Statement!H2 -> 0 | D55: =Statement!I2 -> 0 | E55: =Statement!J2 -> 0 | F55: =Statement!K2 -> 0 | G55: =Statement!L2 -> 0 | H55: =Statement!M2 -> 30.01.2022 | I55: =Statement!N2 -> 29.01.2023 | J55: =Statement!O2 -> 28.01.2024 | ... L55: =Statement!Q2 -> 25.01.2026
C56: =Statement!H3 -> 0 | D56: =Statement!I3 -> 0 | E56: =Statement!J3 -> 0 | F56: =Statement!K3 -> 0 | G56: =Statement!L3 -> 0 | H56: =Statement!M3 -> 2022 | I56: =Statement!N3 -> 2023 | J56: =Statement!O3 -> 2024 | ... L56: =Statement!Q3 -> 2026
B57: Revenue | C57: =Statement!H5 -> 0 | D57: =Statement!I5 -> 0 | E57: =Statement!J5 -> 0 | F57: =Statement!K5 -> 0 | G57: =Statement!L5 -> 0 | H57: =Statement!M5 -> 26914 | I57: =Statement!N5 -> 26974 | J57: =Statement!O5 -> 60922 | ... L57: =Statement!Q5 -> 215938
B58: Operating income | C58: =Statement!H11 -> 0 | D58: =Statement!I11 -> 0 | E58: =Statement!J11 -> 0 | F58: =Statement!K11 -> 0 | G58: =Statement!L11 -> 0 | H58: =Statement!M11 -> 10041 | I58: =Statement!N11 -> 4224 | J58: =Statement!O11 -> 32972 | ... L58: =Statement!Q11 -> 130387
B59: Net income | C59: =Statement!H17 -> 0 | D59: =Statement!I17 -> 0 | E59: =Statement!J17 -> 0 | F59: =Statement!K17 -> 0 | G59: =Statement!L17 -> 0 | H59: =Statement!M17 -> 9752 | I59: =Statement!N17 -> 4368 | J59: =Statement!O17 -> 29760 | ... L59: =Statement!Q17 -> 120067
B60: FCFE | C60: =Statement!H159 -> 0 | D60: =Statement!I159 -> 0 | E60: =Statement!J159 -> 0 | F60: =Statement!K159 -> 0 | G60: =Statement!L159 -> 0 | H60: =Statement!M159 -> 6128 | I60: =Statement!N159 -> 1099 | J60: =Statement!O159 -> 23472 | ... L60: =Statement!Q159 -> 90290
B61: FCFF | C61: =Statement!H160 -> 0 | D61: =Statement!I160 -> 0 | E61: =Statement!J160 -> 0 | F61: =Statement!K160 -> 0 | G61: =Statement!L160 -> 0 | H61: =Statement!M160 -> 6685.0988 | I61: =Statement!N160 -> 1728 | J61: =Statement!O160 -> 25732.516 | ... L61: =Statement!Q160 -> 91501.394
B62: Gross margin | C62: =Statement!H99 -> 0 | D62: =Statement!I99 -> 0 | E62: =Statement!J99 -> 0 | F62: =Statement!K99 -> 0 | G62: =Statement!L99 -> 0 | H62: =Statement!M99 -> 0.64929033 | I62: =Statement!N99 -> 0.56928894 | J62: =Statement!O99 -> 0.72717573 | ... L62: =Statement!Q99 -> 0.71068084
B63: Operating margin | C63: =Statement!H100 -> 0 | D63: =Statement!I100 -> 0 | E63: =Statement!J100 -> 0 | F63: =Statement!K100 -> 0 | G63: =Statement!L100 -> 0 | H63: =Statement!M100 -> 0.37307721 | I63: =Statement!N100 -> 0.15659524 | J63: =Statement!O100 -> 0.54121664 | ... L63: =Statement!Q100 -> 0.60381684
B64: Net margin | C64: =Statement!H101 -> 0 | D64: =Statement!I101 -> 0 | E64: =Statement!J101 -> 0 | F64: =Statement!K101 -> 0 | G64: =Statement!L101 -> 0 | H64: =Statement!M101 -> 0.3623393 | I64: =Statement!N101 -> 0.16193371 | J64: =Statement!O101 -> 0.48849348 | ... L64: =Statement!Q101 -> 0.55602534
B65: Revenue HyperScale | C65: =Statement!H189 -> 0 | D65: =Statement!I189 -> 0 | E65: =Statement!J189 -> 0 | F65: =Statement!K189 -> 0 | G65: =Statement!L189 -> 0 | H65: =Statement!M189 -> 0 | I65: =Statement!N189 -> 0 | J65: =Statement!O189 -> 0 | ... L65: =Statement!Q189 -> 105636
B66: Revenue AI Clouds | C66: =Statement!H190 -> 0 | D66: =Statement!I190 -> 0 | E66: =Statement!J190 -> 0 | F66: =Statement!K190 -> 0 | G66: =Statement!L190 -> 0 | H66: =Statement!M190 -> 0 | I66: =Statement!N190 -> 0 | J66: =Statement!O190 -> 0 | ... L66: =Statement!Q190 -> 88101
B67: Revenue Edge Computing | C67: =Statement!H192 -> 0 | D67: =Statement!I192 -> 0 | E67: =Statement!J192 -> 0 | F67: =Statement!K192 -> 0 | G67: =Statement!L192 -> 0 | H67: =Statement!M192 -> 0 | I67: =Statement!N192 -> 0 | J67: =Statement!O192 -> 0 | ... L67: =Statement!Q192 -> 22201
B68: ROA | C68: =Statement!H121 -> 0 | D68: =Statement!I121 -> 0 | E68: =Statement!J121 -> 0 | F68: =Statement!K121 -> 0 | G68: =Statement!L121 -> 0 | H68: =Statement!M121 -> 0.2206984 | I68: =Statement!N121 -> 0.10606576 | J68: =Statement!O121 -> 0.45277507 | ... L68: =Statement!Q121 -> 0.58058636
B69: ROE | C69: =Statement!H123 -> 0 | D69: =Statement!I123 -> 0 | E69: =Statement!J123 -> 0 | F69: =Statement!K123 -> 0 | G69: =Statement!L123 -> 0 | H69: =Statement!M123 -> 0.36645123 | I69: =Statement!N123 -> 0.19763812 | J69: =Statement!O123 -> 0.6924473 | ... L69: =Statement!Q123 -> 0.7633334
B70: ROIC | C70: =Statement!H142 -> 0 | D70: =Statement!I142 -> 0 | E70: =Statement!J142 -> 0 | F70: =Statement!K142 -> 0 | G70: =Statement!L142 -> 0 | H70: =Statement!M142 -> 0.60245252 | I70: =Statement!N142 -> 0.21378682 | J70: =Statement!O142 -> 1.0866014 | ... L70: =Statement!Q142 -> 1.0723937
B71: Price 5y | C71: =Statement!H207 -> 0 | D71: =Statement!I207 -> 0 | E71: =Statement!J207 -> 0 | F71: =Statement!K207 -> 0 | G71: =Statement!L207 -> 0 | H71: =Statement!M207 -> 100 | I71: =Statement!N207 -> 89.141856 | J71: =Statement!O207 -> 267.20665 | ... L71: =Statement!Q207 -> 821.6725
B72: Revenue 5y | C72: =Statement!H208 -> 0 | D72: =Statement!I208 -> 0 | E72: =Statement!J208 -> 0 | F72: =Statement!K208 -> 0 | G72: =Statement!L208 -> 0 | H72: =Statement!M208 -> 100 | I72: =Statement!N208 -> 100.22293 | J72: =Statement!O208 -> 226.35803 | ... L72: =Statement!Q208 -> 802.32593
B73: EPS 5y | C73: =Statement!H209 -> 0 | D73: =Statement!I209 -> 0 | E73: =Statement!J209 -> 0 | F73: =Statement!K209 -> 0 | G73: =Statement!L209 -> 0 | H73: =Statement!M209 -> 100 | I73: =Statement!N209 -> 45.194805 | J73: =Statement!O209 -> 309.87013 | ... L73: =Statement!Q209 -> 1272.7273

Sheet Graphs Quarter
C55: =Statement!T2 -> 27.10.2024 | D55: =Statement!U2 -> 26.01.2025 | E55: =Statement!V2 -> 27.04.2025 | F55: =Statement!W2 -> 27.07.2025 | G55: =Statement!X2 -> 26.10.2025 | H55: =Statement!Y2 -> 25.01.2026 | I55: =Statement!Z2 -> 26.04.2026 | J55: =Statement!AA2 -> 26.07.2026
C56: =Statement!T3 -> Q3 2025 | D56: =Statement!U3 -> Q4 2025 | E56: =Statement!V3 -> Q1 2026 | F56: =Statement!W3 -> Q2 2026 | G56: =Statement!X3 -> Q3 2026 | H56: =Statement!Y3 -> Q4 2026 | I56: =Statement!Z3 -> Q1 2027 | J56: =Statement!AA3 -> Q2 2027
B57: Revenue | C57: =Statement!T5 -> 35082 | D57: =Statement!U5 -> 39331 | E57: =Statement!V5 -> 44062 | F57: =Statement!W5 -> 46743 | G57: =Statement!X5 -> 57006 | H57: =Statement!Y5 -> 68127 | I57: =Statement!Z5 -> 81615 | J57: =Statement!AA5 -> 96221
B58: Operating income | C58: =Statement!T11 -> 21869 | D58: =Statement!U11 -> 24034 | E58: =Statement!V11 -> 21638 | F58: =Statement!W11 -> 28440 | G58: =Statement!X11 -> 36010 | H58: =Statement!Y11 -> 44299 | I58: =Statement!Z11 -> 53536 | J58: =Statement!AA11 -> 63734
B59: Net income | C59: =Statement!T17 -> 19309 | D59: =Statement!U17 -> 22091 | E59: =Statement!V17 -> 18775 | F59: =Statement!W17 -> 26422 | G59: =Statement!X17 -> 31910 | H59: =Statement!Y17 -> 42960 | I59: =Statement!Z17 -> 58321 | J59: =Statement!AA17 -> 59688
B60: Gross margin | C60: =Statement!T99 -> 0.74556753 | D60: =Statement!U99 -> 0.73028908 | E60: =Statement!V99 -> 0.60523807 | F60: =Statement!W99 -> 0.72423678 | G60: =Statement!X99 -> 0.73411571 | H60: =Statement!Y99 -> 0.74996697 | I60: =Statement!Z99 -> 0.74933529 | J60: =Statement!AA99 -> 0.74975317
B61: Operating margin | C61: =Statement!T100 -> 0.62336811 | D61: =Statement!U100 -> 0.61107015 | E61: =Statement!V100 -> 0.49108075 | F61: =Statement!W100 -> 0.60843335 | G61: =Statement!X100 -> 0.63168789 | H61: =Statement!Y100 -> 0.65024146 | I61: =Statement!Z100 -> 0.65595785 | J61: =Statement!AA100 -> 0.662371
B62: Net margin | C62: =Statement!T101 -> 0.55039621 | D62: =Statement!U101 -> 0.56166891 | E62: =Statement!V101 -> 0.42610413 | F62: =Statement!W101 -> 0.56526111 | G62: =Statement!X101 -> 0.55976564 | H62: =Statement!Y101 -> 0.63058699 | I62: =Statement!Z101 -> 0.71458678 | J62: =Statement!AA101 -> 0.62032197
B63: Revenue HyperScale | C63: =Statement!T189 -> 13390 | D63: =Statement!U189 -> 19094 | E63: =Statement!V189 -> 17599 | F63: =Statement!W189 -> 23883 | G63: =Statement!X189 -> 30340 | H63: =Statement!Y189 -> 33814 | I63: =Statement!Z189 -> 37869 | J63: =Statement!AA189 -> 48710
B64: Revenue AI | C64: =Statement!T190 -> 17381 | D64: =Statement!U190 -> 16486 | E64: =Statement!V190 -> 21513 | F64: =Statement!W190 -> 17213 | G64: =Statement!X190 -> 20875 | H64: =Statement!Y190 -> 28500 | I64: =Statement!Z190 -> 37377 | J64: =Statement!AA190 -> 40313
B65: Revenue Edge | C65: =Statement!T192 -> 4311 | D65: =Statement!U192 -> 3751 | E65: =Statement!V192 -> 4950 | F65: =Statement!W192 -> 5647 | G65: =Statement!X192 -> 5791 | H65: =Statement!Y192 -> 5813 | I65: =Statement!Z192 -> 6369 | J65: =Statement!AA192 -> 7198
B66: FCFE | C66: =Statement!T159 -> 15564 | D66: =Statement!U159 -> 14230 | E66: =Statement!V159 -> 24713 | F66: =Statement!W159 -> 11847 | G66: =Statement!X159 -> 20458 | H66: =Statement!Y159 -> 33273 | I66: =Statement!Z159 -> 46659 | J66: =Statement!AA159 -> 19374

Sheet Forecast ->
H5: Links
H6: Overview'!B3
H7: Financials ->'!B13
H8: Analysis ->'!B13
H9: Forecast ->'!B13
H10: Valuation ->'!B13
B13: Forecast ->

Sheet Revenue
B1: Revenue forecast
C2: History | H2: Forecast | S2: History | AA2: Forecast | AE2: TTM
C4: Revenues | S4: Revenues
B5: Revenues (thousand) | C5: =Statement!M3 -> 2022 | D5: =Statement!N3 -> 2023 | E5: =Statement!O3 -> 2024 | F5: =Statement!P3 -> 2025 | G5: =Statement!Q3 -> 2026 | H5: =G5+1 -> 2027 | I5: =H5+1 -> 2028 | J5: =I5+1 -> 2029 | K5: =J5+1 -> 2030 | L5: =K5+1 -> 2031 | R5: =B5 -> Revenues (thousand) | S5: =Statement!T3 -> Q3 2025 | T5: =Statement!U3 -> Q4 2025 | U5: =Statement!V3 -> Q1 2026 | V5: =Statement!W3 -> Q2 2026 | W5: =Statement!X3 -> Q3 2026 | X5: =Statement!Y3 -> Q4 2026 | Y5: =Statement!Z3 -> Q1 2027 | Z5: =Statement!AA3 -> Q2 2027 | AA5: FQ1 | AB5: FQ2 | AC5: FQ3 | AE5: FQ1
B6: =Statement!B189 -> HyperScale | C6: =Statement!M189 -> 0 | D6: =Statement!N189 -> 0 | E6: =Statement!O189 -> 0 | F6: =Statement!P189 -> 53796 | G6: =Statement!Q189 -> 105636 | H6: =G6+G6*H14 -> 205990.2 | I6: =H6+H6*I14 -> 360482.85 | J6: =I6+I6*J14 -> 558748.42 | K6: =J6+J6*K14 -> 698435.52 | L6: =K6+K6*L14 -> 768279.07 | N6: HyperScale Growth Rate | Q6: HyperScale Growth Rate | R6: =B6 -> HyperScale | S6: =Statement!T189 -> 13390 | T6: =Statement!U189 -> 19094 | U6: =Statement!V189 -> 17599 | V6: =Statement!W189 -> 23883 | W6: =Statement!X189 -> 30340 | X6: =Statement!Y189 -> 33814 | Y6: =Statement!Z189 -> 37869 | Z6: =Statement!AA189 -> 48710 | AA6: =Z6+Z6*AA14 -> 53581 | AE6: =SUM(X6:AA6) -> 173974
B7: =Statement!B190 -> AI Clouds | C7: =Statement!M190 -> 0 | D7: =Statement!N190 -> 0 | E7: =Statement!O190 -> 0 | F7: =Statement!P190 -> 61390 | G7: =Statement!Q190 -> 88101 | H7: =G7+G7*H15 -> 154176.75 | I7: =H7+H7*I15 -> 254391.64 | J7: =I7+I7*J15 -> 356148.29 | K7: =J7+J7*K15 -> 391763.12 | L7: =K7+K7*L15 -> 411351.28 | N7: AI Growth Rate | Q7: AI Growth Rate | R7: =B7 -> AI Clouds | S7: =Statement!T190 -> 17381 | T7: =Statement!U190 -> 16486 | U7: =Statement!V190 -> 21513 | V7: =Statement!W190 -> 17213 | W7: =Statement!X190 -> 20875 | X7: =Statement!Y190 -> 28500 | Y7: =Statement!Z190 -> 37377 | Z7: =Statement!AA190 -> 40313 | AA7: =Z7+Z7*AA15 -> 47569.34 | AE7: =SUM(X7:AA7) -> 153759.34
B8: =Statement!B191 -> Data Center | C8: =Statement!M191 -> 0 | D8: =Statement!N191 -> 0 | E8: =Statement!O191 -> 0 | F8: =Statement!P191 -> 115186 | G8: =Statement!Q191 -> 193737 | H8: =SUM(H6:H7) -> 360166.95 | I8: =SUM(I6:I7) -> 614874.49 | J8: =SUM(J6:J7) -> 914896.71 | K8: =SUM(K6:K7) -> 1090198.6 | L8: =SUM(L6:L7) -> 1179630.4 | R8: =B8 -> Data Center | S8: =Statement!T191 -> 30771 | T8: =Statement!U191 -> 35580 | U8: =Statement!V191 -> 39112 | V8: =Statement!W191 -> 41096 | W8: =Statement!X191 -> 51215 | X8: =Statement!Y191 -> 62314 | Y8: =Statement!Z191 -> 75246 | Z8: =Statement!AA191 -> 89023 | AA8: =SUM(AA6:AA7) -> 101150.34 | AE8: =SUM(X8:AA8) -> 327733.34
B9: =Statement!B192 -> Edge Computing | C9: =Statement!M192 -> 0 | D9: =Statement!N192 -> 0 | E9: =Statement!O192 -> 0 | F9: =Statement!P192 -> 15311 | G9: =Statement!Q192 -> 22201 | H9: =G9+G9*H17 -> 33301.5 | I9: =H9+H9*I17 -> 49952.25 | J9: =I9+I9*J17 -> 72430.762 | K9: =J9+J9*K17 -> 94159.991 | L9: =K9+K9*L17 -> 103575.99 | N9: Edge Growth Rate | Q9: Edge Growth Rate | R9: =B9 -> Edge Computing | S9: =Statement!T192 -> 4311 | T9: =Statement!U192 -> 3751 | U9: =Statement!V192 -> 4950 | V9: =Statement!W192 -> 5647 | W9: =Statement!X192 -> 5791 | X9: =Statement!Y192 -> 5813 | Y9: =Statement!Z192 -> 6369 | Z9: =Statement!AA192 -> 7198 | AA9: =Z9+Z9*AA17 -> 7845.82 | AE9: =SUM(X9:AA9) -> 27225.82
B10: Total | C10: =Statement!M5 -> 26914 | D10: =Statement!N5 -> 26974 | E10: =Statement!O5 -> 60922 | F10: =Statement!P5 -> 130497 | G10: =Statement!Q5 -> 215938 | H10: =SUM(H8:H9) -> 393468.45 | I10: =SUM(I8:I9) -> 664826.74 | J10: =SUM(J8:J9) -> 987327.47 | K10: =SUM(K8:K9) -> 1184358.6 | L10: =SUM(L8:L9) -> 1283206.3 | R10: Total | S10: =Statement!T5 -> 35082 | T10: =Statement!U5 -> 39331 | U10: =Statement!V5 -> 44062 | V10: =Statement!W5 -> 46743 | W10: =Statement!X5 -> 57006 | X10: =Statement!Y5 -> 68127 | Y10: =Statement!Z5 -> 81615 | Z10: =Statement!AA5 -> 96221 | AA10: =SUM(AA8:AA9) -> 108996.16 | AE10: =SUM(X10:AA10) -> 354959.16
C12: Growth rates | S12: Growth rates
B13: Revenue growth % | C13: =C5 -> 2022 | D13: =D5 -> 2023 | E13: =E5 -> 2024 | F13: =F5 -> 2025 | G13: =G5 -> 2026 | H13: =H5 -> 2027 | I13: =I5 -> 2028 | J13: =J5 -> 2029 | ... L13: =L5 -> 2031 | R13: Revenue growth % | S13: =S5 -> Q3 2025 | T13: =T5 -> Q4 2025 | U13: =U5 -> Q1 2026 | V13: =V5 -> Q2 2026 | W13: =W5 -> Q3 2026 | X13: =X5 -> Q4 2026 | Y13: =Y5 -> Q1 2027 | Z13: =Z5 -> Q2 2027 | ... AC13: =AC5 -> FQ3
B14: =B6 -> HyperScale | D14: =D6/C6-1 -> #DIV/0! | E14: =E6/D6-1 -> #DIV/0! | F14: =F6/E6-1 -> #DIV/0! | G14: =G6/F6-1 -> 0.96364042 | H14: 0.95 | I14: 0.75 | J14: 0.55 | K14: 0.25 | L14: 0.1 | R14: =R6 -> HyperScale | T14: =T6/S6-1 -> 0.42598954 | U14: =U6/T6-1 -> -0.078296847 | V14: =V6/U6-1 -> 0.35706574 | W14: =W6/V6-1 -> 0.27035967 | X14: =X6/W6-1 -> 0.11450231 | Y14: =Y6/X6-1 -> 0.11992074 | Z14: =Z6/Y6-1 -> 0.28627637 | AA14: 0.1
B15: =B7 -> AI Clouds | D15: =D7/C7-1 -> #DIV/0! | E15: =E7/D7-1 -> #DIV/0! | F15: =F7/E7-1 -> #DIV/0! | G15: =G7/F7-1 -> 0.43510344 | H15: 0.75 | I15: 0.65 | J15: 0.4 | K15: 0.1 | L15: 0.05 | R15: =R7 -> AI Clouds | T15: =T7/S7-1 -> -0.05149301 | U15: =U7/T7-1 -> 0.30492539 | V15: =V7/U7-1 -> -0.19987914 | W15: =W7/V7-1 -> 0.21274618 | X15: =X7/W7-1 -> 0.36526946 | Y15: =Y7/X7-1 -> 0.31147368 | Z15: =Z7/Y7-1 -> 0.078550981 | AA15: 0.18
B16: =B8 -> Data Center | D16: =D8/C8-1 -> #DIV/0! | E16: =E8/D8-1 -> #DIV/0! | F16: =F8/E8-1 -> #DIV/0! | G16: =G8/F8-1 -> 0.6819492 | H16: =H8/G8-1 -> 0.85905093 | I16: =I8/H8-1 -> 0.70719298 | J16: =J8/I8-1 -> 0.48794059 | K16: =K8/J8-1 -> 0.19160844 | L16: =L8/K8-1 -> 0.082032489 | R16: =R8 -> Data Center | T16: =T8/S8-1 -> 0.15628351 | U16: =U8/T8-1 -> 0.099269252 | V16: =V8/U8-1 -> 0.05072612 | W16: =W8/V8-1 -> 0.24622834 | X16: =X8/W8-1 -> 0.21671385 | Y16: =Y8/X8-1 -> 0.20752961 | Z16: =Z8/Y8-1 -> 0.18309279 | AA16: =AA8/Z8-1 -> 0.13622704
B17: =B9 -> Edge Computing | D17: =D9/C9-1 -> #DIV/0! | E17: =E9/D9-1 -> #DIV/0! | F17: =F9/E9-1 -> #DIV/0! | G17: =G9/F9-1 -> 0.45000327 | H17: 0.5 | I17: 0.5 | J17: 0.45 | K17: 0.3 | L17: 0.1 | R17: =R9 -> Edge Computing | T17: =T9/S9-1 -> -0.12990026 | U17: =U9/T9-1 -> 0.31964809 | V17: =V9/U9-1 -> 0.14080808 | W17: =W9/V9-1 -> 0.025500266 | X17: =X9/W9-1 -> 0.0037989984 | Y17: =Y9/X9-1 -> 0.095647686 | Z17: =Z9/Y9-1 -> 0.13016172 | AA17: 0.09
B18: =B10 -> Total | D18: =D10/C10-1 -> 0.002229323 | E18: =E10/D10-1 -> 1.2585453 | F18: =F10/E10-1 -> 1.1420341 | G18: =G10/F10-1 -> 0.65473536 | H18: =H10/G10-1 -> 0.82213622 | I18: =I10/H10-1 -> 0.68965704 | J18: =J10/I10-1 -> 0.4850899 | K18: =K10/J10-1 -> 0.19956009 | L18: =L10/K10-1 -> 0.083460959 | R18: =R10 -> Total | T18: =T10/S10-1 -> 0.12111624 | U18: =U10/T10-1 -> 0.1202868 | V18: =V10/U10-1 -> 0.060846081 | W18: =W10/V10-1 -> 0.21956229 | X18: =X10/W10-1 -> 0.19508473 | Y18: =Y10/X10-1 -> 0.19798318 | Z18: =Z10/Y10-1 -> 0.1789622 | AA18: =AA10/Z10-1 -> 0.13276894

Sheet COGS & OpEx
B1: COGS & OpEx forecast
C2: History | H2: Forecast | P2: History | X2: Forecast | AB2: TTM
C4: Revenues | P4: Revenues
B5: =Revenue!B5 -> Revenues (thousand) | C5: =Revenue!C5 -> 2022 | D5: =Revenue!D5 -> 2023 | E5: =Revenue!E5 -> 2024 | F5: =Revenue!F5 -> 2025 | G5: =Revenue!G5 -> 2026 | H5: =G5+1 -> 2027 | I5: =H5+1 -> 2028 | J5: =I5+1 -> 2029 | K5: =J5+1 -> 2030 | L5: =K5+1 -> 2031 | O5: Revenues (thousand) | P5: =Revenue!S5 -> Q3 2025 | Q5: =Revenue!T5 -> Q4 2025 | R5: =Revenue!U5 -> Q1 2026 | S5: =Revenue!V5 -> Q2 2026 | T5: =Revenue!W5 -> Q3 2026 | U5: =Revenue!X5 -> Q4 2026 | V5: =Revenue!Y5 -> Q1 2027 | W5: =Revenue!Z5 -> Q2 2027 | X5: FQ1 | Y5: FQ2 | Z5: FQ3 | AB5: =Revenue!AE5 -> FQ1
B6: Revenue | C6: =Revenue!C10 -> 26914 | D6: =Revenue!D10 -> 26974 | E6: =Revenue!E10 -> 60922 | F6: =Revenue!F10 -> 130497 | G6: =Revenue!G10 -> 215938 | H6: =Revenue!H10 -> 393468.45 | I6: =Revenue!I10 -> 664826.74 | J6: =Revenue!J10 -> 987327.47 | ... L6: =Revenue!L10 -> 1283206.3 | O6: Revenue | P6: =Revenue!S10 -> 35082 | Q6: =Revenue!T10 -> 39331 | R6: =Revenue!U10 -> 44062 | S6: =Revenue!V10 -> 46743 | T6: =Revenue!W10 -> 57006 | U6: =Revenue!X10 -> 68127 | V6: =Revenue!Y10 -> 81615 | W6: =Revenue!Z10 -> 96221 | X6: =Revenue!AA10 -> 108996.16 | AB6: =Revenue!AE10 -> 354959.16
C9: COGS and OpEx | P9: COGS & OpEx | AB9: =AB4 -> 0
B10: Expenses (tnousand) | C10: =C5 -> 2022 | D10: =D5 -> 2023 | E10: =E5 -> 2024 | F10: =F5 -> 2025 | G10: =G5 -> 2026 | H10: =H5 -> 2027 | I10: =I5 -> 2028 | J10: =J5 -> 2029 | ... L10: =L5 -> 2031 | O10: Expenses (thousand) | P10: =P5 -> Q3 2025 | Q10: =Q5 -> Q4 2025 | R10: =R5 -> Q1 2026 | S10: =S5 -> Q2 2026 | T10: =T5 -> Q3 2026 | U10: =U5 -> Q4 2026 | V10: =V5 -> Q1 2027 | W10: =W5 -> Q2 2027 | ... Z10: =Z5 -> FQ3 | AB10: =AB5 -> FQ1
B11: COGS | C11: =Statement!M6 -> 9439 | D11: =Statement!N6 -> 11618 | E11: =Statement!O6 -> 16621 | F11: =Statement!P6 -> 32639 | G11: =Statement!Q6 -> 62475 | H11: =H6*H19 -> 110171.17 | I11: =I6*I19 -> 179503.22 | J11: =J6*J19 -> 266578.42 | K11: =K6*K19 -> 296089.66 | L11: =L6*L19 -> 307969.52 | O11: =B11 -> COGS | P11: =Statement!T6 -> 8926 | Q11: =Statement!U6 -> 10608 | R11: =Statement!V6 -> 17394 | S11: =Statement!W6 -> 12890 | T11: =Statement!X6 -> 15157 | U11: =Statement!Y6 -> 17034 | V11: =Statement!Z6 -> 20458 | W11: =Statement!AA6 -> 24079 | X11: =X6*X19 -> 26159.078 | AB11: =SUM(U11:X11) -> 87730.078
B12: =Statement!B8 -> R&D | C12: =Statement!M8 -> 5268 | D12: =Statement!N8 -> 7339 | E12: =Statement!O8 -> 8675 | F12: =Statement!P8 -> 12914 | G12: =Statement!Q8 -> 18497 | H12: =H6*H20 -> 39346.845 | I12: =I6*I20 -> 59834.406 | J12: =J6*J20 -> 88859.473 | K12: =K6*K20 -> 94748.691 | L12: =L6*L20 -> 102656.51 | O12: =B12 -> R&D | P12: =Statement!T8 -> 3390 | Q12: =Statement!U8 -> 3714 | R12: =Statement!V8 -> 3989 | S12: =Statement!W8 -> 4291 | T12: =Statement!X8 -> 4705 | U12: =Statement!Y8 -> 5512 | V12: =Statement!Z8 -> 6321 | W12: =Statement!AA8 -> 7054 | X12: =X20*X$6 -> 10899.616 | AB12: =SUM(U12:X12) -> 29786.616
B13: =Statement!B9 -> SG&A | C13: =Statement!M9 -> 2166 | D13: =Statement!N9 -> 2440 | E13: =Statement!O9 -> 2654 | F13: =Statement!P9 -> 3491 | G13: =Statement!Q9 -> 4579 | H13: =H6*H21 -> 11804.053 | I13: =I6*I21 -> 16620.668 | J13: =J6*J21 -> 24683.187 | K13: =K6*K21 -> 27240.249 | L13: =L6*L21 -> 29513.746 | O13: =B13 -> SG&A | P13: =Statement!T9 -> 897 | Q13: =Statement!U9 -> 975 | R13: =Statement!V9 -> 1041 | S13: =Statement!W9 -> 1122 | T13: =Statement!X9 -> 1134 | U13: =Statement!Y9 -> 1282 | V13: =Statement!Z9 -> 1300 | W13: =Statement!AA9 -> 1354 | X13: =X21*X$6 -> 3269.8848 | AB13: =SUM(U13:X13) -> 7205.8848
B14: OpEx | C14: =Statement!M10 -> 7434 | D14: =Statement!N10 -> 11132 | E14: =Statement!O10 -> 11329 | F14: =Statement!P10 -> 16405 | G14: =Statement!Q10 -> 23076 | H14: =SUM(H12:H13) -> 51150.899 | I14: =SUM(I12:I13) -> 76455.075 | J14: =SUM(J12:J13) -> 113542.66 | K14: =SUM(K12:K13) -> 121988.94 | L14: =SUM(L12:L13) -> 132170.25 | O14: =B14 -> OpEx | P14: =Statement!T10 -> 4287 | Q14: =Statement!U10 -> 4689 | R14: =Statement!V10 -> 5030 | S14: =Statement!W10 -> 5413 | T14: =Statement!X10 -> 5839 | U14: =Statement!Y10 -> 6794 | V14: =Statement!Z10 -> 7621 | W14: =Statement!AA10 -> 8408 | X14: =SUM(X12:X13) -> 14169.501 | AB14: =SUM(U14:X14) -> 36992.501
C17: Expenses % of Revenue | P17: Expenses % of Revenue
B18: % of revenue | C18: =C5 -> 2022 | D18: =D5 -> 2023 | E18: =E5 -> 2024 | F18: =F5 -> 2025 | G18: =G5 -> 2026 | H18: =H5 -> 2027 | I18: =I5 -> 2028 | J18: =J5 -> 2029 | ... L18: =L5 -> 2031 | O18: % of revenue | P18: =P5 -> Q3 2025 | Q18: =Q5 -> Q4 2025 | R18: =R5 -> Q1 2026 | S18: =S5 -> Q2 2026 | T18: =T5 -> Q3 2026 | U18: =U5 -> Q4 2026 | V18: =V5 -> Q1 2027 | W18: =W5 -> Q2 2027 | ... Z18: =Z5 -> FQ3
B19: =B11 -> COGS | C19: =C11/C$6 -> 0.35070967 | D19: =D11/D$6 -> 0.43071106 | E19: =E11/E$6 -> 0.27282427 | F19: =F11/F$6 -> 0.25011303 | G19: =G11/G$6 -> 0.28931916 | H19: 0.28 | I19: 0.27 | J19: 0.27 | K19: 0.25 | L19: 0.24 | O19: =O11 -> COGS | P19: =P11/P$6 -> 0.25443247 | Q19: =Q11/Q$6 -> 0.26971092 | R19: =R11/R$6 -> 0.39476193 | S19: =S11/S$6 -> 0.27576322 | T19: =T11/T$6 -> 0.26588429 | U19: =U11/U$6 -> 0.25003303 | V19: =V11/V$6 -> 0.25066471 | W19: =W11/W$6 -> 0.25024683 | X19: 0.24
B20: =B12 -> R&D | C20: =C12/C$6 -> 0.19573456 | D20: =D12/D$6 -> 0.27207681 | E20: =E12/E$6 -> 0.14239519 | F20: =F12/F$6 -> 0.098960129 | G20: =G12/G$6 -> 0.085658847 | H20: 0.1 | I20: 0.09 | J20: 0.09 | K20: 0.08 | L20: 0.08 | O20: =O12 -> R&D | P20: =P12/P$6 -> 0.096630751 | Q20: =Q12/Q$6 -> 0.094429331 | R20: =R12/R$6 -> 0.090531524 | S20: =S12/S$6 -> 0.091799842 | T20: =T12/T$6 -> 0.082535172 | U20: =U12/U$6 -> 0.080907716 | V20: =V12/V$6 -> 0.077448998 | W20: =W12/W$6 -> 0.0733104 | X20: 0.1
B21: =B13 -> SG&A | C21: =C13/C$6 -> 0.080478561 | D21: =D13/D$6 -> 0.090457478 | E21: =E13/E$6 -> 0.043563901 | F21: =F13/F$6 -> 0.026751573 | G21: =G13/G$6 -> 0.021205161 | H21: 0.03 | I21: 0.025 | J21: 0.025 | K21: 0.023 | L21: 0.023 | O21: =O13 -> SG&A | P21: =P13/P$6 -> 0.025568668 | Q21: =Q13/Q$6 -> 0.024789606 | R21: =R13/R$6 -> 0.0236258 | S21: =S13/S$6 -> 0.024003594 | T21: =T13/T$6 -> 0.019892643 | U21: =U13/U$6 -> 0.018817796 | V21: =V13/V$6 -> 0.015928445 | W21: =W13/W$6 -> 0.014071772 | X21: 0.03
B22: =B14 -> OpEx | C22: =C14/C$6 -> 0.27621312 | D22: =D14/D$6 -> 0.41269371 | E22: =E14/E$6 -> 0.1859591 | F22: =F14/F$6 -> 0.1257117 | G22: =G14/G$6 -> 0.10686401 | H22: =H14/H$6 -> 0.13 | I22: =I14/I$6 -> 0.115 | J22: =J14/J$6 -> 0.115 | ... L22: =L14/L$6 -> 0.103 | O22: =O14 -> OpEx | P22: =P14/P$6 -> 0.12219942 | Q22: =Q14/Q$6 -> 0.11921894 | R22: =R14/R$6 -> 0.11415732 | S22: =S14/S$6 -> 0.11580344 | T22: =T14/T$6 -> 0.10242781 | U22: =U14/U$6 -> 0.099725513 | V22: =V14/V$6 -> 0.093377443 | W22: =W14/W$6 -> 0.087382172 | X22: =X14/X$6 -> 0.13

Sheet WC & Investments
B1: Working Capital, Capex, D&A
C3: History | H3: Forecast
C5: Revenues
B6: Revenues (thousand) | C6: =Revenue!C5 -> 2022 | D6: =Revenue!D5 -> 2023 | E6: =Revenue!E5 -> 2024 | F6: =Revenue!F5 -> 2025 | G6: =Revenue!G5 -> 2026 | H6: =G6+1 -> 2027 | I6: =H6+1 -> 2028 | J6: =I6+1 -> 2029 | K6: =J6+1 -> 2030 | L6: =K6+1 -> 2031
B7: Revenue | C7: =Revenue!C10 -> 26914 | D7: =Revenue!D10 -> 26974 | E7: =Revenue!E10 -> 60922 | F7: =Revenue!F10 -> 130497 | G7: =Revenue!G10 -> 215938 | H7: =Revenue!H10 -> 393468.45 | I7: =Revenue!I10 -> 664826.74 | J7: =Revenue!J10 -> 987327.47 | ... L7: =Revenue!L10 -> 1283206.3
B8: COGS | C8: ='COGS & OpEx'!C11 -> 9439 | D8: ='COGS & OpEx'!D11 -> 11618 | E8: ='COGS & OpEx'!E11 -> 16621 | F8: ='COGS & OpEx'!F11 -> 32639 | G8: ='COGS & OpEx'!G11 -> 62475 | H8: ='COGS & OpEx'!H11 -> 110171.17 | I8: ='COGS & OpEx'!I11 -> 179503.22 | J8: ='COGS & OpEx'!J11 -> 266578.42 | ... L8: ='COGS & OpEx'!L11 -> 307969.52
C11: Working Capital
B12: $ (thousand) | C12: =C6 -> 2022 | D12: =D6 -> 2023 | E12: =E6 -> 2024 | F12: =F6 -> 2025 | G12: =G6 -> 2026 | H12: =H6 -> 2027 | I12: =I6 -> 2028 | J12: =J6 -> 2029 | ... L12: =L6 -> 2031
B13: Accounts receivable | C13: =Statement!M29 -> 4650 | D13: =Statement!N29 -> 3827 | E13: =Statement!O29 -> 9999 | F13: =Statement!P29 -> 23065 | G13: =Statement!Q29 -> 38466 | H13: =H20*H7/365 -> 75459.703 | I13: =I20*I7/365 -> 123858.13 | J13: =J20*J7/365 -> 162300.41 | K13: =K20*K7/365 -> 194689.09 | L13: =L20*L7/365 -> 210938.03
B14: Inventory | C14: =Statement!M30 -> 2605 | D14: =Statement!N30 -> 5159 | E14: =Statement!O30 -> 5282 | F14: =Statement!P30 -> 10080 | G14: =Statement!Q30 -> 21403 | H14: =H21*H8/365 -> 41653.756 | I14: =I21*I8/365 -> 66391.602 | J14: =J21*J8/365 -> 87642.219 | K14: =K21*K8/365 -> 97344.545 | L14: =L21*L8/365 -> 101250.25
B15: Accounts payable | C15: =Statement!M37 -> 1783 | D15: =Statement!N37 -> 1193 | E15: =Statement!O37 -> 2699 | F15: =Statement!P37 -> 6310 | G15: =Statement!Q37 -> 9812 | H15: =H22*H8/365 -> 20525.039 | I15: =I22*I8/365 -> 32949.906 | J15: =J22*J8/365 -> 47472.869 | K15: =K22*K8/365 -> 52728.295 | L15: =L22*L8/365 -> 54843.888
C18: WC metrics and drivers
B19: Days | C19: =C6 -> 2022 | D19: =D6 -> 2023 | E19: =E6 -> 2024 | F19: =F6 -> 2025 | G19: =G6 -> 2026 | H19: =H6 -> 2027 | I19: =I6 -> 2028 | J19: =J6 -> 2029 | ... L19: =L6 -> 2031
B20: DSO | C20: =C13/C7*365 -> 63.061975 | D20: =D13/D7*365 -> 51.785238 | E20: =E13/E7*365 -> 59.906684 | F20: =F13/F7*365 -> 64.512786 | G20: =G13/G7*365 -> 65.01908 | H20: 70 | I20: 68 | J20: 60 | K20: 60 | L20: 60
B21: DIO | C21: =C14/C8*365 -> 100.73366 | D21: =D14/D8*365 -> 162.0791 | E21: =E14/E8*365 -> 115.99362 | F21: =F14/F8*365 -> 112.72404 | G21: =G14/G8*365 -> 125.04354 | H21: 138 | I21: 135 | J21: 120 | K21: 120 | L21: 120
B22: DPO | C22: =C15/C8*365 -> 68.947452 | D22: =D15/D8*365 -> 37.480203 | E22: =E15/E8*365 -> 59.270501 | F22: =F15/F8*365 -> 70.564356 | G22: =G15/G8*365 -> 57.32501 | H22: 68 | I22: 67 | J22: 65 | K22: 65 | L22: 65
B23: Net trade cycle | C23: =C20+C21-C22 -> 94.848181 | D23: =D20+D21-D22 -> 176.38414 | E23: =E20+E21-E22 -> 116.62981 | F23: =F20+F21-F22 -> 106.67247 | G23: =G20+G21-G22 -> 132.73761 | H23: =H20+H21-H22 -> 140 | I23: =I20+I21-I22 -> 136 | J23: =J20+J21-J22 -> 115 | ... L23: =L20+L21-L22 -> 115
C26: Change in SIP NWC
B27: $ (thousand) | C27: =C6 -> 2022 | D27: =D6 -> 2023 | E27: =E6 -> 2024 | F27: =F6 -> 2025 | G27: =G6 -> 2026 | H27: =H6 -> 2027 | I27: =I6 -> 2028 | J27: =J6 -> 2029 | ... L27: =L6 -> 2031
B28: Change in acc receivable | C28: =Statement!M54 -> -2215 | D28: =Statement!N54 -> 822 | E28: =Statement!O54 -> -6172 | F28: =Statement!P54 -> -13063 | G28: =Statement!Q54 -> -15399 | H28: =-(H13-G13) -> -36993.703 | I28: =-(I13-H13) -> -48398.429 | J28: =-(J13-I13) -> -38442.275 | K28: =-(K13-J13) -> -32388.684 | L28: =-(L13-K13) -> -16248.938
B29: Change in inventory | C29: =Statement!M55 -> -774 | D29: =Statement!N55 -> -2554 | E29: =Statement!O55 -> -98 | F29: =Statement!P55 -> -4781 | G29: =Statement!Q55 -> -11324 | H29: =-(H14-G14) -> -20250.756 | I29: =-(I14-H14) -> -24737.846 | J29: =-(J14-I14) -> -21250.618 | K29: =-(K14-J14) -> -9702.3259 | L29: =-(L14-K14) -> -3905.7085
B30: Change in acc payable | C30: =Statement!M56 -> 568 | D30: =Statement!N56 -> -551 | E30: =Statement!O56 -> 1531 | F30: =Statement!P56 -> 3357 | G30: =Statement!Q56 -> 3069 | H30: =H15-G15 -> 10713.039 | I30: =I15-H15 -> 12424.867 | J30: =J15-I15 -> 14522.963 | K30: =K15-J15 -> 5255.4265 | L30: =L15-K15 -> 2115.5921
C33: Total change in NWC and less SIP
B34: $ (thousand) | C34: =C6 -> 2022 | D34: =D6 -> 2023 | E34: =E6 -> 2024 | F34: =F6 -> 2025 | G34: =G6 -> 2026 | H34: =H6 -> 2027 | I34: =I6 -> 2028 | J34: =J6 -> 2029 | ... L34: =L6 -> 2031
B35: Total change in NWC | C35: =Statement!M54+Statement!M55+Statement!M56+Statement!M57 -> -3363 | D35: =Statement!N54+Statement!N55+Statement!N56+Statement!N57 -> -2207 | E35: =Statement!O54+Statement!O55+Statement!O56+Statement!O57 -> -3722 | F35: =Statement!P54+Statement!P55+Statement!P56+Statement!P57 -> -9383 | G35: =Statement!Q54+Statement!Q55+Statement!Q56+Statement!Q57 -> -15976 | H35: =H36+H28+H29+H30 -> -34727.366 | I35: =I36+I28+I29+I30 -> -40766.606 | J35: =J36+J28+J29+J30 -> -25423.38 | K35: =K36+K28+K29+K30 -> -60522.756 | L35: =L36+L28+L29+L30 -> -56535.245
B36: Change in NWC less SIP | C36: =C35-C28-C29-C30 -> -942 | D36: =D35-D28-D29-D30 -> 76 | E36: =E35-E28-E29-E30 -> 1017 | F36: =F35-F28-F29-F30 -> 5104 | G36: =G35-G28-G29-G30 -> 7678 | H36: =H7*H37 -> 11804.053 | I36: =I7*I37 -> 19944.802 | J36: =J7*J37 -> 19746.549 | K36: =K7*K37 -> -23687.173 | L36: =L7*L37 -> -38496.19
B37: % of revenue | C37: =C36/C7 -> -0.035000372 | D37: =D36/D7 -> 0.002817528 | E37: =E36/E7 -> 0.016693477 | F37: =F36/F7 -> 0.03911201 | G37: =G36/G7 -> 0.035556502 | H37: 0.03 | I37: 0.03 | J37: 0.02 | K37: -0.02 | L37: -0.03
C40: Investments
B41: $ (thousand) | C41: =C6 -> 2022 | D41: =D6 -> 2023 | E41: =E6 -> 2024 | F41: =F6 -> 2025 | G41: =G6 -> 2026 | H41: =H6 -> 2027 | I41: =I6 -> 2028 | J41: =J6 -> 2029 | ... L41: =L6 -> 2031
B42: D&A | C42: =Statement!M52 -> 1174 | D42: =Statement!N52 -> 1544 | E42: =Statement!O52 -> 1508 | F42: =Statement!P52 -> 1864 | G42: =Statement!Q52 -> 2843 | H42: =H7*H43 -> 4328.1529 | I42: =I7*I43 -> 7313.0941 | J42: =J7*J43 -> 11847.93 | K42: =K7*K43 -> 14212.304 | L42: =L7*L43 -> 15398.476
B43: % of Revenue | C43: =C42/C7 -> 0.043620421 | D43: =D42/D7 -> 0.057240305 | E43: =E42/E7 -> 0.024752963 | F43: =F42/F7 -> 0.014283853 | G43: =G42/G7 -> 0.013165816 | H43: 0.011 | I43: 0.011 | J43: 0.012 | K43: 0.012 | L43: 0.012
B44: % of CapEx | C44: =C42/C45 -> 1.2028689 | D44: =D42/D45 -> 0.84233497 | E44: =E42/E45 -> 1.4106642 | F44: =F42/F45 -> 0.57601978 | G44: =G42/G45 -> 0.47053956 | H44: =H42/H45 -> 0.44 | I44: =I42/I45 -> 0.44 | J44: =J42/J45 -> 0.48 | ... L44: =L42/L45 -> 0.4
