Workbook

Sheet Overview
B2: Automatic Data | E2: At a glance | H2: Valuation | K2: Links
B3: Company | C3: #VALUE! | E3: Market capitalization | F3: =Statement!AC153 -> 6989162.4 | H3: ='AVG target price'!B5 -> DCF price | I3: ='AVG target price'!C5 -> 6.0868928 | K3: Financials ->'!B13
B4: Ticker | C4: {=_FV(C3,"Ticker symbol",TRUE)} -> PATH | E4: Enterprise value | F4: =Statement!AC154 -> 5584137.4 | H4: ='AVG target price'!B6 -> EV/EBIT price | I4: ='AVG target price'!C6 -> 15.500001 | K4: Analysis ->'!B13
B5: Price | C5: {=_FV(C3,"Price",TRUE)} -> 13.325 | E5: EPS | F5: =Statement!AC26 -> 0.67 | H5: ='AVG target price'!B7 -> PS price | I5: ='AVG target price'!C7 -> 11.635364 | K5: Forecast ->'!B13
B6: Price Extended Hours | C6: {=_FV(C3,"Price (Extended hours)",TRUE)} -> 13.32 | E6: PE | F6: =Statement!AC150 -> 19.88806 | H6: ='AVG target price'!B8 -> EV/FCFF price | I6: ='AVG target price'!C8 -> 9.9292211 | K6: Valuation ->'!B13
B7: Day change | C7: {=_FV(C3,"Change")} -> -0.155 | E7: PS | F7: =Statement!AC151 -> 4.1332067 | H7: ='AVG target price'!B9 -> EV/Sales | I7: ='AVG target price'!C9 -> 11.620184
B8: Day change extended | C8: {=_FV(C3,"Change (extended hours)",TRUE)} -> 0 | E8: FCF Yield | F8: =Statement!AC161 -> 0.018367866 | H8: ='AVG target price'!B10 -> AVG price | I8: ='AVG target price'!C10 -> 10.954333
B9: Day change % | C9: {=_FV(C3,"Change (%)",TRUE)} -> -0.011499 | E9: Earnings Yield | F9: =Statement!AC162 -> 0.050281426 | H9: ='AVG target price'!B12 -> Upside/Downside | I9: ='AVG target price'!C12 -> -0.17791124
B10: Day change extended % | C10: {=_FV(C3,"Change % (extended hours)",TRUE)} -> 0 | E10: Buyback Yield | F10: =Statement!AC164 -> 0.038423488
B11: 52 week high | C11: {=_FV(C3,"52 week high",TRUE)} -> 19.84 | E11: Dividend Yield | F11: =Statement!AC163 -> 0 | H11: DDM price | I11: =DDM!C26 -> 0
B12: 52 week low | C12: {=_FV(C3,"52 week low",TRUE)} -> 9.2002 | E12: ROA | F12: =Statement!AC123 -> 0.12448205
B13: Beta | C13: {=_FV(C3,"Beta")} -> 1.063 | E13: ROE | F13: =Statement!AC125 -> 0.18573545 | H13: Reverse DCF rate | I13: ='Reverse DCF'!C17 -> 1.4
B14: Avg volume | C14: {=_FV(C3,"Volume average",TRUE)} -> 46968664 | E14: ROIC | F14: =Statement!AC140 -> 0.2813996
E15: Net Cash/Market Cap | F15: =Statement!AC176 -> 0.2010291
E16: Net Cash/Share | F16: =Statement!AC175 -> 2.6959778 | H16: Discount rates used
B17: Unit data and other info | E17: Insider Ownership | F17: =Statement!AC171 -> 0.22269906 | H17: WACC | I17: =DCF!C15 -> 0.1
B18: Units | C18: K | E18: Net Trade Cycle | F18: =Statement!AC144 -> 45.101496 | H18: Cost of Equity | I18: =Multiples!C54 -> 0.12
B19: Units conversion | C19: 1000 | E19: Net Debt/Equity | F19: =Statement!AC146 -> -0.72106145
B20: Has operating lease | C20: Yes | E20: Quick Ratio | F20: =Statement!AC147 -> 2.1209291
B21: Has finance lease | C21: No
B22: Has debt | C22: No
B25: Constants | E25: 10 Year Bond Yield
B26: Default tax rate | C26: 0.21 | E26: #VALUE! | F26: {=_FV(E26,"Price")} -> 52.44
B27: Cost of debt | C27: 0 | E27: Percentage | F27: =F26/1000 -> 0.05244
B28: Manual WACC | C28: 0.1
B29: Manual Cost of Equity | C29: 0.12
B33: Info
B35: Mission: | C35: Empower customers to combine automation, AI agents and people, devilering end to end process orchestration that drives innovation
B36: Auditor: | C36: KPMG
B42: Notes
B44: Date: | C44: 03.09.2026 | E44: Q2 2027
B45: - | C45: Revenue and ARR for FY 2027 are 1789M-1794M and 2065B-2070B
B46: - | C46: Non GAAP EBIT for Q3 2027 and FY 2027 are 100M and 445M
B52: Adjustments
B54: Date: | C54: 30.04.2026 | E54: Q1 2027

Sheet Financials ->
H5: Links
H6: Overview'!B3
H7: Financials ->'!B13
H8: Analysis ->'!B13
H9: Forecast ->'!B13
H10: Valuation ->'!B13
B13: Financials ->

Sheet Statement
B2: Date | M2: 31.01.2022 | N2: 31.01.2023 | O2: 31.01.2024 | P2: 31.01.2025 | Q2: 31.01.2026 | T2: 31.10.2024 | U2: 31.01.2025 | V2: 30.04.2025 | W2: 31.07.2025 | X2: 31.10.2025 | Y2: 31.01.2026 | Z2: 30.04.2026 | AA2: 31.07.2026
B3: FY | M3: 2022 | N3: 2023 | O3: 2024 | P3: 2025 | Q3: 2026 | T3: Q3 2025 | U3: Q4 2025 | V3: Q1 2026 | W3: Q2 2026 | X3: Q3 2026 | Y3: Q4 2026 | Z3: Q1 2027 | AA3: Q2 2027 | AC3: TTM/YTD
B4: Income statement
B5: Revenue | M5: 892252 | N5: 1058581 | O5: 1308072 | P5: 1429664 | Q5: 1610572 | T5: 354653 | U5: 423646 | V5: 356624 | W5: 361728 | X5: 411113 | Y5: 481107 | Z5: 418382 | AA5: 410256 | AC5: =SUM(X5:AA5) -> 1720858
B6: COGS | M6: 168868 | N6: 180051 | O6: 195924 | P6: 246942 | Q6: 270984 | T6: 63763 | U6: 64534 | V6: 63857 | W6: 64380 | X6: 68812 | Y6: 73935 | Z6: 76928 | AA6: 80587 | AC6: =SUM(X6:AA6) -> 300262
B7: Gross Profit | C7: =C5-C6 -> 0 | D7: =D5-D6 -> 0 | E7: =E5-E6 -> 0 | F7: =F5-F6 -> 0 | G7: =G5-G6 -> 0 | H7: =H5-H6 -> 0 | I7: =I5-I6 -> 0 | J7: =J5-J6 -> 0 | ... Q7: =Q5-Q6 -> 1339588 | T7: =T5-T6 -> 290890 | U7: =U5-U6 -> 359112 | V7: =V5-V6 -> 292767 | W7: =W5-W6 -> 297348 | X7: =X5-X6 -> 342301 | Y7: =Y5-Y6 -> 407172 | Z7: =Z5-Z6 -> 341454 | AA7: =AA5-AA6 -> 329669 | AC7: =SUM(X7:AA7) -> 1420596
B8: Sales and marketing | M8: 697682 | N8: 701558 | O8: 713130 | P8: 738493 | Q8: 683329 | T8: 187188 | U8: 176836 | V8: 159661 | W8: 166303 | X8: 179186 | Y8: 178179 | Z8: 167859 | AA8: 164606 | AC8: =SUM(X8:AA8) -> 689830
B9: R&D | M9: 276657 | N9: 285750 | O9: 332101 | P9: 380682 | Q9: 385208 | T9: 96976 | U9: 99670 | V9: 94839 | W9: 98341 | X9: 96869 | Y9: 95159 | Z9: 92902 | AA9: 83393 | AC9: =SUM(X9:AA9) -> 368323
B10: General and administrative | M10: 249991 | N10: 239505 | O10: 231637 | P10: 226116 | Q10: 214291 | T10: 50090 | U10: 48997 | V10: 54679 | W10: 52889 | X10: 53175 | Y10: 53548 | Z10: 52706 | AA10: 50066 | AC10: =SUM(X10:AA10) -> 209495
B11: OpEx | C11: =SUM(C8:C10) -> 0 | D11: =SUM(D8:D10) -> 0 | E11: =SUM(E8:E10) -> 0 | F11: =SUM(F8:F10) -> 0 | G11: =SUM(G8:G10) -> 0 | H11: =SUM(H8:H10) -> 0 | I11: =SUM(I8:I10) -> 0 | J11: =SUM(J8:J10) -> 0 | ... Q11: =SUM(Q8:Q10) -> 1282828 | T11: =SUM(T8:T10) -> 334254 | U11: =SUM(U8:U10) -> 325503 | V11: =SUM(V8:V10) -> 309179 | W11: =SUM(W8:W10) -> 317533 | X11: =SUM(X8:X10) -> 329230 | Y11: =SUM(Y8:Y10) -> 326886 | Z11: =SUM(Z8:Z10) -> 313467 | AA11: =SUM(AA8:AA10) -> 298065 | AC11: =SUM(X11:AA11) -> 1267648
B12: Operating income | M12: -500946 | N12: -348283 | O12: -164720 | P12: -162569 | Q12: 56760 | T12: -43364 | U12: 33609 | V12: -16412 | W12: -20185 | X12: 13071 | Y12: 80286 | Z12: 27987 | AA12: 31604 | AC12: =SUM(X12:AA12) -> 152948
B13: Interest income/expense | M13: 3551 | N13: 27955 | O13: 57130 | P13: 49422 | Q13: 48023 | T13: 10055 | U13: 12167 | V13: 12648 | W13: 12004 | X13: 11701 | Y13: 11670 | Z13: 10401 | AA13: 10769 | AC13: =SUM(X13:AA13) -> 44541
B14: Other income/expense | M14: -13488 | N14: 2767 | O14: 31775 | P14: 35047 | Q14: -4155 | T14: 7810 | U14: 8848 | V14: -15964 | W14: 11508 | X14: -180 | Y14: 481 | Z14: 2580 | AA14: 10482 | AC14: =SUM(X14:AA14) -> 13363
B15: Income before taxes | M15: -510883 | N15: -317561 | O15: -75815 | P15: -78100 | Q15: 100628 | T15: -25499 | U15: 54624 | V15: -19728 | W15: 3327 | X15: 24592 | Y15: 92437 | Z15: 40968 | AA15: 52855 | AC15: =SUM(X15:AA15) -> 210852
B16: Income tax expense/benefit | M16: -14703 | N16: -10791 | O16: -14068 | P16: 4406 | Q16: 181702 | T16: 14844 | U16: -2830 | V16: -2827 | W16: -1743 | X16: 174247 | Y16: 12025 | Z16: -18443 | AA16: -16766 | AC16: =SUM(X16:AA16) -> 151063
B17: Non-controlling interest | M17: 0 | N17: 0 | O17: 0 | P17: 0 | Q17: 0 | T17: 0 | U17: 0 | V17: 0 | W17: 0 | X17: 0 | Y17: 0 | Z17: 0 | AA17: 0 | AC17: =SUM(X17:AA17) -> 0
B18: Net income | M18: -525586 | N18: -328352 | O18: -89883 | P18: -73694 | Q18: 282330 | T18: -10655 | U18: 51794 | V18: -22555 | W18: 1584 | X18: 198839 | Y18: 104462 | Z18: 22525 | AA18: 36089 | AC18: =SUM(X18:AA18) -> 361915
B19: Basic Shares outstanding avg | M19: 454625 | N19: 548022 | O19: 563855 | P19: 559933 | Q19: 538125 | T19: 551036 | U19: 550948 | V19: 548451 | W19: 536169 | X19: 532255 | Y19: 535962 | Z19: 523584 | AA19: 519654 | AC19: =AVERAGE(X19:AA19) -> 527863.75
B20: Basic Shares outstanding avg adjusted | C20: =C19*C$85 -> 0 | D20: =D19*D$85 -> 0 | E20: =E19*E$85 -> 0 | F20: =F19*F$85 -> 0 | G20: =G19*G$85 -> 0 | H20: =H19*H$85 -> 0 | I20: =I19*I$85 -> 0 | J20: =J19*J$85 -> 0 | ... Q20: =Q19*Q$85 -> 538125 | T20: =T19*T$85 -> 551036 | U20: =U19*U$85 -> 550948 | V20: =V19*V$85 -> 548451 | W20: =W19*W$85 -> 536169 | X20: =X19*X$85 -> 532255 | Y20: =Y19*Y$85 -> 535962 | Z20: =Z19*Z$85 -> 523584 | AA20: =AA19*AA$85 -> 519654 | AC20: =AC19*AC$85 -> 527863.75
B21: Diluted Shares outstanding avg | M21: 454625 | N21: 548022 | O21: 653855 | P21: 559933 | Q21: 544860 | T21: 551036 | U21: 555373 | V21: 548451 | W21: 542865 | X21: 539018 | Y21: 545284 | Z21: 527818 | AA21: 523013 | AC21: =AVERAGE(X21:AA21) -> 533783.25
B22: Diluted Shares outstanding avg adjusted | C22: =C21*C$85 -> 0 | D22: =D21*D$85 -> 0 | E22: =E21*E$85 -> 0 | F22: =F21*F$85 -> 0 | G22: =G21*G$85 -> 0 | H22: =H21*H$85 -> 0 | I22: =I21*I$85 -> 0 | J22: =J21*J$85 -> 0 | ... Q22: =Q21*Q$85 -> 544860 | T22: =T21*T$85 -> 551036 | U22: =U21*U$85 -> 555373 | V22: =V21*V$85 -> 548451 | W22: =W21*W$85 -> 542865 | X22: =X21*X$85 -> 539018 | Y22: =Y21*Y$85 -> 545284 | Z22: =Z21*Z$85 -> 527818 | AA22: =AA21*AA$85 -> 523013 | AC22: =AC21*AC$85 -> 533783.25
B23: Basic EPS | M23: -1.16 | N23: -0.6 | O23: -0.16 | P23: -0.13 | Q23: 0.52 | T23: -0.02 | U23: 0.09 | V23: -0.04 | W23: 0 | X23: 0.37 | Y23: 0.19 | Z23: 0.04 | AA23: 0.07 | AC23: =SUM(X23:AA23) -> 0.67
B24: Basic EPS adjusted | M24: =M23/M$85 -> -1.16 | N24: =N23/N$85 -> -0.6 | O24: =O23/O$85 -> -0.16 | P24: =P23/P$85 -> -0.13 | Q24: =Q23/Q$85 -> 0.52 | T24: =T23/T$85 -> -0.02 | U24: =U23/U$85 -> 0.09 | V24: =V23/V$85 -> -0.04 | W24: =W23/W$85 -> 0 | X24: =X23/X$85 -> 0.37 | Y24: =Y23/Y$85 -> 0.19 | Z24: =Z23/Z$85 -> 0.04 | AA24: =AA23/AA$85 -> 0.07 | AC24: =AC23/AC$85 -> 0.67
B25: Diluted EPS | M25: -1.16 | N25: -0.6 | O25: -0.16 | P25: -0.13 | Q25: 0.52 | T25: -0.02 | U25: 0.09 | V25: -0.04 | W25: 0 | X25: 0.37 | Y25: 0.19 | Z25: 0.04 | AA25: 0.07 | AC25: =SUM(X25:AA25) -> 0.67
B26: Diluted EPS adjusted | M26: =M25/M$85 -> -1.16 | N26: =N25/N$85 -> -0.6 | O26: =O25/O$85 -> -0.16 | P26: =P25/P$85 -> -0.13 | Q26: =Q25/Q$85 -> 0.52 | T26: =T25/T$85 -> -0.02 | U26: =U25/U$85 -> 0.09 | V26: =V25/V$85 -> -0.04 | W26: =W25/W$85 -> 0 | X26: =X25/X$85 -> 0.37 | Y26: =Y25/Y$85 -> 0.19 | Z26: =Z25/Z$85 -> 0.04 | AA26: =AA25/AA$85 -> 0.07 | AC26: =AC25/AC$85 -> 0.67
B28: Balance sheet
B29: Cash and cash equivalents | M29: =1768723+96417 -> 1865140 | N29: =1402119+354774 -> 1756893 | O29: =1061678+818145 -> 1879823 | P29: =879196+750322 -> 1629518 | Q29: =871157+601329 -> 1472486 | T29: =773630+795411 -> 1569041 | U29: =879196+750322 -> 1629518 | V29: =700641+854392 -> 1555033 | W29: =628617+818870 -> 1447487 | X29: =743660+654526 -> 1398186 | Y29: =871157+601329 -> 1472486 | Z29: =632195+675049 -> 1307244 | AA29: =607414+676576 -> 1283990 | AC29: =AA29 -> 1283990
B30: Acc receivable | M30: =251988+74831 -> 326819 | N30: =374217+69260 -> 443477 | O30: =436296+84197 -> 520493 | P30: =451131+88735 -> 539866 | Q30: =488265+92440 -> 580705 | T30: =336137+109918 -> 446055 | U30: =451131+88735 -> 539866 | V30: =266619+103150 -> 369769 | W30: =269810+117418 -> 387228 | X30: =366757+129335 -> 496092 | Y30: =488265+92440 -> 580705 | Z30: 299999 | AA30: 307112 | AC30: =AA30 -> 307112
B31: Inventory | M31: 0 | N31: 0 | O31: 0 | P31: 0 | Q31: 0 | T31: 0 | U31: 0 | V31: 0 | W31: 0 | X31: 0 | Y31: 0 | Z31: 0 | AA31: 0 | AC31: =AA31 -> 0
B32: Current assets | M32: 2277301 | N32: 2344407 | O32: 2580412 | P32: 2338559 | Q32: 2243945 | T32: 2176478 | U32: 2338559 | V32: 2109669 | W32: 2030736 | X32: 2093343 | Y32: 2243945 | Z32: 1918362 | AA32: 1926630 | AC32: =AA32 -> 1926630
B33: PP&E | M33: 17176 | N33: 29045 | O33: 23982 | P33: 32740 | Q33: 46014 | T33: 25132 | U33: 32740 | V33: 41964 | W33: 41545 | X33: 44604 | Y33: 46014 | Z33: 45585 | AA33: 46436 | AC33: =AA33 -> 46436
B34: Marketable securities and investments | M34: 19523 | N34: 2942 | O34: 0 | P34: 94113 | Q34: 216990 | T34: 34397 | U34: 94113 | V34: 36467 | W34: 75151 | X34: 121609 | Y34: 216990 | Z34: 108502 | AA34: 121035 | AC34: =AA34 -> 121035
B35: Goodwill | M35: 53564 | N35: 88010 | O35: 89026 | P35: 87304 | Q35: 125310 | T35: 89864 | U35: 87304 | V35: 121371 | W35: 120800 | X35: 120625 | Y35: 125310 | Z35: 185695 | AA35: 179481 | AC35: =AA35 -> 179481
B36: Long term assets | M36: =M37-M32 -> 295149 | N36: =N37-N32 -> 390799 | O36: =O37-O32 -> 374346 | P36: =P37-P32 -> 526711 | Q36: =Q37-Q32 -> 935255 | T36: =T37-T32 -> 486813 | U36: =U37-U32 -> 526711 | V36: =V37-V32 -> 534773 | W36: =W37-W32 -> 561581 | X36: =X37-X32 -> 802633 | Y36: =Y37-Y32 -> 935255 | Z36: =Z37-Z32 -> 986338 | AA36: =AA37-AA32 -> 980737 | AC36: =AA36 -> 980737
B37: Total assets | M37: 2572450 | N37: 2735206 | O37: 2954758 | P37: 2865270 | Q37: 3179200 | T37: 2663291 | U37: 2865270 | V37: 2644442 | W37: 2592317 | X37: 2895976 | Y37: 3179200 | Z37: 2904700 | AA37: 2907367 | AC37: =AA37 -> 2907367
B38: Acc payable | M38: 11515 | N38: 8891 | O38: 3447 | P38: 33178 | Q38: 10161 | T38: 18426 | U38: 33178 | V38: 16885 | W38: 19743 | X38: 14280 | Y38: 10161 | Z38: 19699 | AA38: 16484 | AC38: =AA38 -> 16484
B39: Debt | M39: 0 | N39: 0 | O39: 0 | P39: 0 | Q39: 0 | T39: 0 | U39: 0 | V39: 0 | W39: 0 | X39: 0 | Y39: 0 | Z39: 0 | AA39: 0 | AC39: =AA39 -> 0
B40: Current liabilities | M40: 527501 | N40: 626452 | O40: 711691 | P40: 798920 | Q40: 905423 | T40: 695473 | U40: 798920 | V40: 715867 | W40: 738417 | X40: 788700 | Y40: 905423 | Z40: 831666 | AA40: 807258 | AC40: =AA40 -> 807258
B41: Debt | M41: 0 | N41: 0 | O41: 0 | P41: 0 | Q41: 0 | T41: 0 | U41: 0 | V41: 0 | W41: 0 | X41: 0 | Y41: 0 | Z41: 0 | AA41: 0 | AC41: =AA41 -> 0
B42: Long term liabilities | M42: =M43-M40 -> 123032 | N42: =N43-N40 -> 188596 | O42: =O43-O40 -> 226953 | P42: =P43-P40 -> 220588 | Q42: =Q43-Q40 -> 191190 | T42: =T43-T40 -> 235973 | U42: =U43-U40 -> 220588 | V42: =V43-V40 -> 230114 | W42: =W43-W40 -> 188197 | X42: =X43-X40 -> 182659 | Y42: =Y43-Y40 -> 191190 | Z42: =Z43-Z40 -> 170069 | AA42: =AA43-AA40 -> 151558 | AC42: =AA42 -> 151558
...

Sheet Analysis ->
H5: Links
H6: Overview'!B3
H7: Financials ->'!B13
H8: Analysis ->'!B13
H9: Forecast ->'!B13
H10: Valuation ->'!B13
B13: Analysis ->

Sheet Basic
B1: TTM/YTD data
B4: Overview | E4: CAGR
B5: Price | C5: =Overview!C5 -> 13.325 | F5: 5Y | G5: 10Y
B6: Market capitalization | C6: =Statement!AC153 -> 6989162.4 | E6: Revenue | F6: =IF(Statement!M5<=0,"N/A",_xlfn.RRI(4,Statement!M5,Statement!Q5)) -> 0.159106 | G6: =IF(Statement!H5<=0,"N/A",_xlfn.RRI(9,Statement!H5,Statement!Q5)) -> N/A
B7: Enterprise value | C7: =Statement!AC154 -> 5584137.4 | E7: Net income | F7: =IF(OR(Statement!M18<=0, Statement!Q18<=0), "N/A", _xlfn.RRI(4, Statement!M18, Statement!Q18)) -> N/A | G7: =IF(OR(Statement!H18<=0, Statement!Q18<=0), "N/A", _xlfn.RRI(9, Statement!H18, Statement!Q18)) -> N/A
B8: PE | C8: =Statement!AC150 -> 19.88806 | E8: EPS | F8: =IF(OR(Statement!M26<=0, Statement!Q26<=0), "N/A", _xlfn.RRI(4, Statement!M26, Statement!Q26)) -> N/A | G8: =IF(OR(Statement!H26<=0, Statement!Q26<=0), "N/A", _xlfn.RRI(9, Statement!H26, Statement!Q26)) -> N/A
B9: PS | C9: =Statement!AC151 -> 4.1332067 | E9: Dividend | F9: =IF(Statement!M82<=0,"N/A",_xlfn.RRI(4,Statement!M82,Statement!Q82)) -> N/A | G9: =IF(Statement!H82<=0,"N/A",_xlfn.RRI(9,Statement!H82,Statement!Q82)) -> N/A
B10: PB | C10: =Statement!AC152 -> 3.5638809 | E10: Price | F10: =IF(Statement!M117<=0,"N/A",_xlfn.RRI(4,Statement!M117,Statement!Q117)) -> -0.21662025 | G10: =IF(Statement!H117<=0,"N/A",_xlfn.RRI(9,Statement!H117,Statement!Q117)) -> N/A
B11: EV/Revenue | C11: =Statement!AC155 -> 3.2449728
B12: EV/EBIT | C12: =Statement!AC156 -> 36.510039
B15: Margins | E15: Earnings quality
B16: Gross margin | C16: =Statement!AC101 -> 0.82551611 | E16: Net income | F16: =Statement!AC18 -> 361915
B17: Operating margin | C17: =Statement!AC102 -> 0.08887892 | E17: Operating cash | F17: =Statement!AC59 -> 373246
B18: Net margin | C18: =Statement!AC103 -> 0.21031079 | E18: Cash accruals | F18: =IF(OR(F16<=0, F17<=0),"N/A",F16-F17) -> -11331
B21: DuPont Identity | E21: Performance indicators
B22: Profit Margin (Earnings/Revenue) | C22: =Statement!AC121 -> 0.21031079 | E22: ROA | F22: =C24 -> 0.12448205
B23: Asset Turnover (Revenue/Total assets) | C23: =Statement!AC122 -> 0.59189569 | E23: ROE | F23: =C26 -> 0.18573545
B24: ROA | C24: =Statement!AC123 -> 0.12448205 | E24: ROIC | F24: =Statement!AC140 -> 0.2813996
B25: Equity Multiplier (Total assets/Equity) | C25: =Statement!AC124 -> 1.4920662
B26: ROE | C26: =Statement!AC125 -> 0.18573545
B29: Cash conversion cycle | E29: Liquidity ratios
B30: DSO | C30: =Statement!AC141 -> 65.139529 | E30: Debt/Equity | F30: =Statement!AC145 -> 0
B31: DIO | C31: =Statement!AC142 -> 0 | E31: Net Debt/Equity | F31: =Statement!AC146 -> -0.72106145
B32: DPO | C32: =Statement!AC143 -> 20.038033 | E32: Current ratio | F32: =Statement!AC148 -> 2.3866348
B33: Net trade cycle | C33: =Statement!AC144 -> 45.101496 | E33: Quick ratio | F33: =Statement!AC147 -> 2.1209291
E34: Interest coverage | F34: =Statement!AC149 -> N/A
B37: Earnings yields | E37: Payout ratios
B38: Earnings yield | C38: =Statement!AC162 -> 0.050281426 | E38: Dividend payout ratio | F38: =Statement!AC168 -> 0
B39: FCF yield | C39: =Statement!AC161 -> 0.018367866 | E39: Buyback payout ratio | F39: =Statement!AC169 -> 2.0918863
B40: Dividend yield | C40: =Statement!AC163 -> 0 | E40: Full payout ratio | F40: =Statement!AC170 -> 2.0918863
B41: Buyback yield | C41: =Statement!AC164 -> 0.038423488
B42: Total shareholder yield | C42: =Statement!AC165 -> 0.038423488
B45: Ownership | E45: Cash holdings
B46: Insider ownership | C46: =Statement!AC171 -> 0.22269906 | E46: Cash per share | F46: =Statement!AC172 -> 2.6959778
E47: Net cash per share | F47: =Statement!AC175 -> 2.6959778
E48: Net cash to market cap | F48: =Statement!AC176 -> 0.2010291
B51: Stock based compensation | E51: CapEx usage
B52: Stock based compensation % OCF | C52: =Statement!AC173 -> 0.62848899 | E52: Capex to Revenue | F52: =Statement!AC177 -> 0.0059789942
B53: Stock based compensation % Revenue | C53: =Statement!AC174 -> 0.1363163 | E53: CapEx to OCF | F53: =Statement!AC178 -> 0.02756627
E54: CapEx to D&A | F54: =Statement!AC179 -> 0.39573077

Sheet Yearly Analysis
C2: =Statement!M2 -> 31.01.2022 | D2: =Statement!N2 -> 31.01.2023 | E2: =Statement!O2 -> 31.01.2024 | F2: =Statement!P2 -> 31.01.2025 | G2: =Statement!Q2 -> 31.01.2026
C3: =Statement!M3 -> 2022 | D3: =Statement!N3 -> 2023 | E3: =Statement!O3 -> 2024 | F3: =Statement!P3 -> 2025 | G3: =Statement!Q3 -> 2026 | I3: =Statement!AC3 -> TTM/YTD
B5: Overview
B6: Price | C6: =Statement!M116 -> 33.43 | D6: =Statement!N116 -> 14.57 | E6: =Statement!O116 -> 23.85 | F6: =Statement!P116 -> 14.58 | G6: =Statement!Q116 -> 12.59 | I6: =Statement!AC116 -> 13.325
B7: Market capitalization | C7: =Statement!M153 -> 18122002 | D7: =Statement!N153 -> 8121653.1 | E7: =Statement!O153 -> 13570960 | F7: =Statement!P153 -> 8040767.9 | G7: =Statement!Q153 -> 6680971.6 | I7: =Statement!AC153 -> 6989162.4
B8: Enterprise value | C8: =Statement!M154 -> 16237339 | D8: =Statement!N154 -> 6361818.1 | E8: =Statement!O154 -> 11691137 | F8: =Statement!P154 -> 6317136.9 | G8: =Statement!Q154 -> 4991495.6 | I8: =Statement!AC154 -> 5584137.4
B9: PE | C9: =Statement!M150 -> -28.818966 | D9: =Statement!N150 -> -24.283333 | E9: =Statement!O150 -> -149.0625 | F9: =Statement!P150 -> -112.15385 | G9: =Statement!Q150 -> 24.211538 | I9: =Statement!AC150 -> 19.88806
B10: PS | C10: =Statement!M151 -> 17.033432 | D10: =Statement!N151 -> 7.5428149 | E10: =Statement!O151 -> 11.9217 | F10: =Statement!P151 -> 5.710309 | G10: =Statement!Q151 -> 4.2592243 | I10: =Statement!AC151 -> 4.1332067
B11: PB | C11: =Statement!M152 -> 9.4291282 | D11: =Statement!N152 -> 4.2296796 | E11: =Statement!O152 -> 6.7312464 | F11: =Statement!P152 -> 4.3563406 | G11: =Statement!Q152 -> 3.1673001 | I11: =Statement!AC152 -> 3.5638809
B12: EV/Revenue | C12: =Statement!M155 -> 18.198153 | D12: =Statement!N155 -> 6.0097603 | E12: =Statement!O155 -> 8.9376862 | F12: =Statement!P155 -> 4.4186165 | G12: =Statement!Q155 -> 3.0992068 | I12: =Statement!AC155 -> 3.2449728
B13: EV/EBIT | C13: =Statement!M156 -> -32.413352 | D13: =Statement!N156 -> -18.266232 | E13: =Statement!O156 -> -70.97582 | F13: =Statement!P156 -> -38.858189 | G13: =Statement!Q156 -> 87.940374 | I13: =Statement!AC156 -> 36.510039
B15: Margins
B16: Gross margin | C16: =Statement!M101 -> 0.81073957 | D16: =Statement!N101 -> 0.82991287 | E16: =Statement!O101 -> 0.85021925 | F16: =Statement!P101 -> 0.8272727 | G16: =Statement!Q101 -> 0.83174673 | I16: =Statement!AC101 -> 0.82551611
B17: Operating margin | C17: =Statement!M102 -> -0.56144004 | D17: =Statement!N102 -> -0.32900931 | E17: =Statement!O102 -> -0.12592579 | F17: =Statement!P102 -> -0.11371133 | G17: =Statement!Q102 -> 0.035242138 | I17: =Statement!AC102 -> 0.08887892
B18: Net margin | C18: =Statement!M103 -> -0.58905556 | D18: =Statement!N103 -> -0.31018127 | E18: =Statement!O103 -> -0.068714107 | F18: =Statement!P103 -> -0.051546377 | G18: =Statement!Q103 -> 0.17529797 | I18: =Statement!AC103 -> 0.21031079
B20: Earnings quality
B21: Net income | C21: =Statement!M18 -> -525586 | D21: =Statement!N18 -> -328352 | E21: =Statement!O18 -> -89883 | F21: =Statement!P18 -> -73694 | G21: =Statement!Q18 -> 282330 | I21: =Statement!AC18 -> 361915
B22: Operating cash | C22: =Statement!M59 -> -54963 | D22: =Statement!N59 -> -9981 | E22: =Statement!O59 -> 299082 | F22: =Statement!P59 -> 320565 | G22: =Statement!Q59 -> 371208 | I22: =Statement!AC59 -> 373246
B23: Cash accruals | C23: =IF(OR(C21<=0, C22<=0),"N/A",C21-C22) -> N/A | D23: =IF(OR(D21<=0, D22<=0),"N/A",D21-D22) -> N/A | E23: =IF(OR(E21<=0, E22<=0),"N/A",E21-E22) -> N/A | F23: =IF(OR(F21<=0, F22<=0),"N/A",F21-F22) -> N/A | G23: =IF(OR(G21<=0, G22<=0),"N/A",G21-G22) -> -88878 | I23: =IF(OR(I21<=0, I22<=0),"N/A",I21-I22) -> -11331
B25: DuPont Identity
B26: Profit Margin (Earnings/Revenue) | C26: =Statement!M121 -> -0.58905556 | D26: =Statement!N121 -> -0.31018127 | E26: =Statement!O121 -> -0.068714107 | F26: =Statement!P121 -> -0.051546377 | G26: =Statement!Q121 -> 0.17529797 | I26: =Statement!AC121 -> 0.21031079
B27: Asset Turnover (Revenue/Total assets) | C27: =Statement!M122 -> 0.34684911 | D27: =Statement!N122 -> 0.38702058 | E27: =Statement!O122 -> 0.44270021 | F27: =Statement!P122 -> 0.4989631 | G27: =Statement!Q122 -> 0.50659663 | I27: =Statement!AC122 -> 0.59189569
B28: ROA | C28: =Statement!M123 -> -0.2043134 | D28: =Statement!N123 -> -0.12004653 | E28: =Statement!O123 -> -0.03041975 | F28: =Statement!P123 -> -0.02571974 | G28: =Statement!Q123 -> 0.08880536 | I28: =Statement!AC123 -> 0.12448205
B29: Equity Multiplier (Total assets/Equity) | C29: =Statement!M124 -> 1.3384813 | D29: =Statement!N124 -> 1.4244692 | E29: =Statement!O124 -> 1.4655709 | F29: =Statement!P124 -> 1.5523507 | G29: =Statement!Q124 -> 1.5265629 | I29: =Statement!AC124 -> 1.4920662
B30: ROE | C30: =Statement!M125 -> -0.27346967 | D30: =Statement!N125 -> -0.17100259 | E30: =Statement!O125 -> -0.0445823 | F30: =Statement!P125 -> -0.039926058 | G30: =Statement!Q125 -> 0.13556697 | I30: =Statement!AC125 -> 0.18573545
B32: Performance Indicators
B33: ROA | C33: =C28 -> -0.2043134 | D33: =D28 -> -0.12004653 | E33: =E28 -> -0.03041975 | F33: =F28 -> -0.02571974 | G33: =G28 -> 0.08880536 | I33: =I28 -> 0.12448205
B34: ROE | C34: =C30 -> -0.27346967 | D34: =D30 -> -0.17100259 | E34: =E30 -> -0.0445823 | F34: =F30 -> -0.039926058 | G34: =G30 -> 0.13556697 | I34: =I30 -> 0.18573545
B35: ROIC | C35: =Statement!M140 -> -13.446771 | D35: =Statement!N140 -> -2.1723833 | E35: =Statement!O140 -> -1.2085904 | F35: =Statement!P140 -> -1.3311035 | G35: =Statement!Q140 -> 0.1443867 | I35: =Statement!AC140 -> 0.2813996
B37: Cash conversion cycle
B38: DSO | C38: =Statement!M141 -> 133.69422 | D38: =Statement!N141 -> 152.9114 | E38: =Statement!O141 -> 145.23661 | F38: =Statement!P141 -> 137.83035 | G38: =Statement!Q141 -> 131.60376 | I38: =Statement!AC141 -> 65.139529
B39: DIO | C39: =Statement!M142 -> 0 | D39: =Statement!N142 -> 0 | E39: =Statement!O142 -> 0 | F39: =Statement!P142 -> 0 | G39: =Statement!Q142 -> 0 | I39: =Statement!AC142 -> 0
B40: DPO | C40: =Statement!M143 -> 24.889115 | D40: =Statement!N143 -> 18.023865 | E40: =Statement!O143 -> 6.4216482 | F40: =Statement!P143 -> 49.039734 | G40: =Statement!Q143 -> 13.686288 | I40: =Statement!AC143 -> 20.038033
B41: Net trade cycle | C41: =Statement!M144 -> 108.80511 | D41: =Statement!N144 -> 134.88754 | E41: =Statement!O144 -> 138.81496 | F41: =Statement!P144 -> 88.790616 | G41: =Statement!Q144 -> 117.91747 | I41: =Statement!AC144 -> 45.101496
B43: Liquidity ratios
B44: Debt/Equity | C44: =Statement!M145 -> 0 | D44: =Statement!N145 -> 0 | E44: =Statement!O145 -> 0 | F44: =Statement!P145 -> 0 | G44: =Statement!Q145 -> 0 | I44: =Statement!AC145 -> 0
B45: Net Debt/Equity | C45: =Statement!M146 -> -0.98061623 | D45: =Statement!N146 -> -0.91650531 | E45: =Statement!O146 -> -0.93239916 | F45: =Statement!P146 -> -0.93383166 | G45: =Statement!Q146 -> -0.8112391 | I45: =Statement!AC146 -> -0.72106145
B46: Quick ratio | C46: =Statement!M147 -> 4.192375 | D46: =Statement!N147 -> 3.5171282 | E46: =Statement!O147 -> 3.372694 | F46: =Statement!P147 -> 2.8331961 | G46: =Statement!Q147 -> 2.5073154 | I46: =Statement!AC147 -> 2.1209291
B47: Current ratio | C47: =Statement!M148 -> 4.3171501 | D47: =Statement!N148 -> 3.742357 | E47: =Statement!O148 -> 3.6257477 | F47: =Statement!P148 -> 2.9271504 | G47: =Statement!Q148 -> 2.4783389 | I47: =Statement!AC148 -> 2.3866348
B48: Interest coverage | C48: =Statement!M149 -> N/A | D48: =Statement!N149 -> N/A | E48: =Statement!O149 -> N/A | F48: =Statement!P149 -> N/A | G48: =Statement!Q149 -> N/A | I48: =Statement!AC149 -> N/A
...

Sheet Quarter analysis
C3: Latest 2 quarters | F3: YoY
C4: =Statement!Z2 -> 30.04.2026 | D4: =Statement!AA2 -> 31.07.2026 | F4: =Statement!W2 -> 31.07.2025 | G4: =Statement!AA2 -> 31.07.2026
B5: Income statement growth | C5: =Statement!Z3 -> Q1 2027 | D5: =Statement!AA3 -> Q2 2027 | F5: =Statement!W3 -> Q2 2026 | G5: =Statement!AA3 -> Q2 2027
B6: Revenue | C6: =Statement!Z5 -> 418382 | D6: =Statement!AA5 -> 410256 | F6: =Statement!W5 -> 361728 | G6: =Statement!AA5 -> 410256
B7: Growth | C7: =Statement!AA89 -> -0.019422442 | F7: =IF(F6=0, IF(G6=0,0,IF(G6>0,1,-1)), (G6-F6)/ABS(F6) ) -> 0.13415605
B8: COGS | C8: =Statement!Z6 -> 76928 | D8: =Statement!AA6 -> 80587 | F8: =Statement!W6 -> 64380 | G8: =Statement!AA6 -> 80587
B9: Growth | C9: =Statement!AA90 -> 0.047563956 | F9: =IF(F8=0, IF(G8=0,0,IF(G8>0,1,-1)), (G8-F8)/ABS(F8) ) -> 0.25173967
B10: Gross Profit | C10: =Statement!Z7 -> 341454 | D10: =Statement!AA7 -> 329669 | F10: =Statement!W7 -> 297348 | G10: =Statement!AA7 -> 329669
B11: Growth | C11: =Statement!AA91 -> -0.034514166 | F11: =IF(F10=0, IF(G10=0,0,IF(G10>0,1,-1)), (G10-F10)/ABS(F10) ) -> 0.10869755
B12: OpEx | C12: =Statement!Z11 -> 313467 | D12: =Statement!AA11 -> 298065 | F12: =Statement!W11 -> 317533 | G12: =Statement!AA11 -> 298065
B13: Growth | C13: =Statement!AA95 -> -0.049134359 | F13: =IF(F12=0, IF(G12=0,0,IF(G12>0,1,-1)), (G12-F12)/ABS(F12) ) -> -0.061310163
B14: Operating profit | C14: =Statement!Z12 -> 27987 | D14: =Statement!AA12 -> 31604 | F14: =Statement!W12 -> -20185 | G14: =Statement!AA12 -> 31604
B15: Growth | C15: =Statement!AA96 -> 0.12923858 | F15: =IF(F14=0, IF(G14=0,0,IF(G14>0,1,-1)), (G14-F14)/ABS(F14) ) -> 2.5657171
B16: Net income | C16: =Statement!Z18 -> 22525 | D16: =Statement!AA18 -> 36089 | F16: =Statement!W18 -> 1584 | G16: =Statement!AA18 -> 36089
B17: Growth | C17: =Statement!AA98 -> 0.60217536 | F17: =IF(F16=0, IF(G16=0,0,IF(G16>0,1,-1)), (G16-F16)/ABS(F16) ) -> 21.78346
B18: Diluted shares outstanding | C18: =Statement!Z22 -> 527818 | D18: =Statement!AA22 -> 523013 | F18: =Statement!W22 -> 542865 | G18: =Statement!AA22 -> 523013
B19: Growth | C19: =IF(C18=0, IF(D18=0,0,IF(D18>0,1,-1)), (D18-C18)/ABS(C18) ) -> -0.0091035167 | F19: =IF(F18=0, IF(G18=0,0,IF(G18>0,1,-1)), (G18-F18)/ABS(F18) ) -> -0.036568944
B20: Diluted EPS | C20: =Statement!Z26 -> 0.04 | D20: =Statement!AA26 -> 0.07 | F20: =Statement!W26 -> 0 | G20: =Statement!AA26 -> 0.07
B21: Growth | C21: =IF(C20=0, IF(D20=0,0,IF(D20>0,1,-1)), (D20-C20)/ABS(C20) ) -> 0.75 | F21: =IF(F20=0, IF(G20=0,0,IF(G20>0,1,-1)), (G20-F20)/ABS(F20) ) -> 1
B23: Revenue breakdown | C23: =C5 -> Q1 2027 | D23: =D5 -> Q2 2027 | F23: =F5 -> Q2 2026 | G23: =G5 -> Q2 2027
B24: Licenses | C24: =Statement!Z187 -> 149309 | D24: =Statement!AA187 -> 123843 | F24: =Statement!W187 -> 112161 | G24: =Statement!AA187 -> 123843
B25: Growth | C25: =IF(C24=0, IF(D24=0,0,IF(D24>0,1,-1)), (D24-C24)/ABS(C24) ) -> -0.17055904 | F25: =IF(F24=0, IF(G24=0,0,IF(G24>0,1,-1)), (G24-F24)/ABS(F24) ) -> 0.10415385
B26: Subscription services | C26: =Statement!Z188 -> 252903 | D26: =Statement!AA188 -> 266067 | F26: =Statement!W188 -> 238363 | G26: =Statement!AA188 -> 266067
B27: Growth | C27: =IF(C26=0, IF(D26=0,0,IF(D26>0,1,-1)), (D26-C26)/ABS(C26) ) -> 0.052051577 | F27: =IF(F26=0, IF(G26=0,0,IF(G26>0,1,-1)), (G26-F26)/ABS(F26) ) -> 0.11622609
B28: Professional services | C28: =Statement!Z189 -> 16170 | D28: =Statement!AA189 -> 20346 | F28: =Statement!W189 -> 11204 | G28: =Statement!AA189 -> 20346
B29: Growth | C29: =IF(C28=0, IF(D28=0,0,IF(D28>0,1,-1)), (D28-C28)/ABS(C28) ) -> 0.25825603 | F29: =IF(F28=0, IF(G28=0,0,IF(G28>0,1,-1)), (G28-F28)/ABS(F28) ) -> 0.81595859
B31: Metrics growth | C31: =C5 -> Q1 2027 | D31: =D5 -> Q2 2027 | F31: =F5 -> Q2 2026 | G31: =G5 -> Q2 2027
B32: ARR | C32: =Statement!Z213 -> 1901211 | D32: =Statement!AA213 -> 1937722 | F32: =Statement!W213 -> 1723401 | G32: =Statement!AA213 -> 1937722
B33: Growth | C33: =IF(C32=0, IF(D32=0,0,IF(D32>0,1,-1)), (D32-C32)/ABS(C32) ) -> 0.019204076 | F33: =IF(F32=0, IF(G32=0,0,IF(G32>0,1,-1)), (G32-F32)/ABS(F32) ) -> 0.12435933
B34: Customers >= 100K | C34: =Statement!Z217 -> 2624 | D34: =Statement!AA217 -> 2666 | F34: =Statement!W217 -> 2432 | G34: =Statement!AA217 -> 2666
B35: Growth | C35: =IF(C34=0, IF(D34=0,0,IF(D34>0,1,-1)), (D34-C34)/ABS(C34) ) -> 0.016006098 | F35: =IF(F34=0, IF(G34=0,0,IF(G34>0,1,-1)), (G34-F34)/ABS(F34) ) -> 0.096217105

Sheet Graphs Year
C55: =Statement!H2 -> 0 | D55: =Statement!I2 -> 0 | E55: =Statement!J2 -> 0 | F55: =Statement!K2 -> 0 | G55: =Statement!L2 -> 0 | H55: =Statement!M2 -> 31.01.2022 | I55: =Statement!N2 -> 31.01.2023 | J55: =Statement!O2 -> 31.01.2024 | ... L55: =Statement!Q2 -> 31.01.2026
C56: =Statement!H3 -> 0 | D56: =Statement!I3 -> 0 | E56: =Statement!J3 -> 0 | F56: =Statement!K3 -> 0 | G56: =Statement!L3 -> 0 | H56: =Statement!M3 -> 2022 | I56: =Statement!N3 -> 2023 | J56: =Statement!O3 -> 2024 | ... L56: =Statement!Q3 -> 2026
B57: Revenue | C57: =Statement!H5 -> 0 | D57: =Statement!I5 -> 0 | E57: =Statement!J5 -> 0 | F57: =Statement!K5 -> 0 | G57: =Statement!L5 -> 0 | H57: =Statement!M5 -> 892252 | I57: =Statement!N5 -> 1058581 | J57: =Statement!O5 -> 1308072 | ... L57: =Statement!Q5 -> 1610572
B58: Operating income | C58: =Statement!H12 -> 0 | D58: =Statement!I12 -> 0 | E58: =Statement!J12 -> 0 | F58: =Statement!K12 -> 0 | G58: =Statement!L12 -> 0 | H58: =Statement!M12 -> -500946 | I58: =Statement!N12 -> -348283 | J58: =Statement!O12 -> -164720 | ... L58: =Statement!Q12 -> 56760
B59: Net income | C59: =Statement!H18 -> 0 | D59: =Statement!I18 -> 0 | E59: =Statement!J18 -> 0 | F59: =Statement!K18 -> 0 | G59: =Statement!L18 -> 0 | H59: =Statement!M18 -> -525586 | I59: =Statement!N18 -> -328352 | J59: =Statement!O18 -> -89883 | ... L59: =Statement!Q18 -> 282330
B60: FCFE | C60: =Statement!H157 -> 0 | D60: =Statement!I157 -> 0 | E60: =Statement!J157 -> 0 | F60: =Statement!K157 -> 0 | G60: =Statement!L157 -> 0 | H60: =Statement!M157 -> -582375 | I60: =Statement!N157 -> -403636 | J60: =Statement!O157 -> -80215 | ... L60: =Statement!Q157 -> 61484
B61: FCFF | C61: =Statement!H158 -> 0 | D61: =Statement!I158 -> 0 | E61: =Statement!J158 -> 0 | F61: =Statement!K158 -> 0 | G61: =Statement!L158 -> 0 | H61: =Statement!M158 -> -603972 | I61: =Statement!N158 -> -500062 | J61: =Statement!O158 -> -216393 | ... L61: =Statement!Q158 -> -94526
B62: Gross margin | C62: =Statement!H101 -> 0 | D62: =Statement!I101 -> 0 | E62: =Statement!J101 -> 0 | F62: =Statement!K101 -> 0 | G62: =Statement!L101 -> 0 | H62: =Statement!M101 -> 0.81073957 | I62: =Statement!N101 -> 0.82991287 | J62: =Statement!O101 -> 0.85021925 | ... L62: =Statement!Q101 -> 0.83174673
B63: Operating margin | C63: =Statement!H102 -> 0 | D63: =Statement!I102 -> 0 | E63: =Statement!J102 -> 0 | F63: =Statement!K102 -> 0 | G63: =Statement!L102 -> 0 | H63: =Statement!M102 -> -0.56144004 | I63: =Statement!N102 -> -0.32900931 | J63: =Statement!O102 -> -0.12592579 | ... L63: =Statement!Q102 -> 0.035242138
B64: Net margin | C64: =Statement!H103 -> 0 | D64: =Statement!I103 -> 0 | E64: =Statement!J103 -> 0 | F64: =Statement!K103 -> 0 | G64: =Statement!L103 -> 0 | H64: =Statement!M103 -> -0.58905556 | I64: =Statement!N103 -> -0.31018127 | J64: =Statement!O103 -> -0.068714107 | ... L64: =Statement!Q103 -> 0.17529797
B65: Revenue Licenses | C65: =Statement!H187 -> 0 | D65: =Statement!I187 -> 0 | E65: =Statement!J187 -> 0 | F65: =Statement!K187 -> 0 | G65: =Statement!L187 -> 0 | H65: =Statement!M187 -> 481427 | I65: =Statement!N187 -> 497836 | J65: =Statement!O187 -> 621392 | ... L65: =Statement!Q187 -> 606394
B66: Revenue Subscription | C66: =Statement!H188 -> 0 | D66: =Statement!I188 -> 0 | E66: =Statement!J188 -> 0 | F66: =Statement!K188 -> 0 | G66: =Statement!L188 -> 0 | H66: =Statement!M188 -> 369867 | I66: =Statement!N188 -> 508823 | J66: =Statement!O188 -> 649918 | ... L66: =Statement!Q188 -> 954472
B67: Revenue Professional | C67: =Statement!H189 -> 0 | D67: =Statement!I189 -> 0 | E67: =Statement!J189 -> 0 | F67: =Statement!K189 -> 0 | G67: =Statement!L189 -> 0 | H67: =Statement!M189 -> 40958 | I67: =Statement!N189 -> 51922 | J67: =Statement!O189 -> 36762 | ... L67: =Statement!Q189 -> 49706
B68: ROA | C68: =Statement!H123 -> 0 | D68: =Statement!I123 -> 0 | E68: =Statement!J123 -> 0 | F68: =Statement!K123 -> 0 | G68: =Statement!L123 -> 0 | H68: =Statement!M123 -> -0.2043134 | I68: =Statement!N123 -> -0.12004653 | J68: =Statement!O123 -> -0.03041975 | ... L68: =Statement!Q123 -> 0.08880536
B69: ROE | C69: =Statement!H125 -> 0 | D69: =Statement!I125 -> 0 | E69: =Statement!J125 -> 0 | F69: =Statement!K125 -> 0 | G69: =Statement!L125 -> 0 | H69: =Statement!M125 -> -0.27346967 | I69: =Statement!N125 -> -0.17100259 | J69: =Statement!O125 -> -0.0445823 | ... L69: =Statement!Q125 -> 0.13556697
B70: ROIC | C70: =Statement!H140 -> 0 | D70: =Statement!I140 -> 0 | E70: =Statement!J140 -> 0 | F70: =Statement!K140 -> 0 | G70: =Statement!L140 -> 0 | H70: =Statement!M140 -> -13.446771 | I70: =Statement!N140 -> -2.1723833 | J70: =Statement!O140 -> -1.2085904 | ... L70: =Statement!Q140 -> 0.1443867
B71: Price 5y | C71: =Statement!H207 -> 0 | D71: =Statement!I207 -> 0 | E71: =Statement!J207 -> 0 | F71: =Statement!K207 -> 0 | G71: =Statement!L207 -> 0 | H71: =Statement!M207 -> 100 | I71: =Statement!N207 -> 43.583608 | J71: =Statement!O207 -> 71.343105 | ... L71: =Statement!Q207 -> 37.660784
B72: Revenue 5y | C72: =Statement!H208 -> 0 | D72: =Statement!I208 -> 0 | E72: =Statement!J208 -> 0 | F72: =Statement!K208 -> 0 | G72: =Statement!L208 -> 0 | H72: =Statement!M208 -> 100 | I72: =Statement!N208 -> 118.64148 | J72: =Statement!O208 -> 146.60343 | ... L72: =Statement!Q208 -> 180.5064
B73: EPS 5y | C73: =Statement!H209 -> 0 | D73: =Statement!I209 -> 0 | E73: =Statement!J209 -> 0 | F73: =Statement!K209 -> 0 | G73: =Statement!L209 -> 0 | H73: =Statement!M209 -> 100 | I73: =Statement!N209 -> 148.27586 | J73: =Statement!O209 -> 186.2069 | ... L73: =Statement!Q209 -> 244.82759

Sheet Graphs Quarter
C55: =Statement!T2 -> 31.10.2024 | D55: =Statement!U2 -> 31.01.2025 | E55: =Statement!V2 -> 30.04.2025 | F55: =Statement!W2 -> 31.07.2025 | G55: =Statement!X2 -> 31.10.2025 | H55: =Statement!Y2 -> 31.01.2026 | I55: =Statement!Z2 -> 30.04.2026 | J55: =Statement!AA2 -> 31.07.2026
C56: =Statement!T3 -> Q3 2025 | D56: =Statement!U3 -> Q4 2025 | E56: =Statement!V3 -> Q1 2026 | F56: =Statement!W3 -> Q2 2026 | G56: =Statement!X3 -> Q3 2026 | H56: =Statement!Y3 -> Q4 2026 | I56: =Statement!Z3 -> Q1 2027 | J56: =Statement!AA3 -> Q2 2027
B57: Revenue | C57: =Statement!T5 -> 354653 | D57: =Statement!U5 -> 423646 | E57: =Statement!V5 -> 356624 | F57: =Statement!W5 -> 361728 | G57: =Statement!X5 -> 411113 | H57: =Statement!Y5 -> 481107 | I57: =Statement!Z5 -> 418382 | J57: =Statement!AA5 -> 410256
B58: Operating income | C58: =Statement!T12 -> -43364 | D58: =Statement!U12 -> 33609 | E58: =Statement!V12 -> -16412 | F58: =Statement!W12 -> -20185 | G58: =Statement!X12 -> 13071 | H58: =Statement!Y12 -> 80286 | I58: =Statement!Z12 -> 27987 | J58: =Statement!AA12 -> 31604
B59: Net income | C59: =Statement!T18 -> -10655 | D59: =Statement!U18 -> 51794 | E59: =Statement!V18 -> -22555 | F59: =Statement!W18 -> 1584 | G59: =Statement!X18 -> 198839 | H59: =Statement!Y18 -> 104462 | I59: =Statement!Z18 -> 22525 | J59: =Statement!AA18 -> 36089
B60: Gross margin | C60: =Statement!T101 -> 0.82021018 | D60: =Statement!U101 -> 0.84766999 | E60: =Statement!V101 -> 0.82094026 | F60: =Statement!W101 -> 0.82202097 | G60: =Statement!X101 -> 0.83262023 | H60: =Statement!Y101 -> 0.84632317 | I60: =Statement!Z101 -> 0.81612976 | J60: =Statement!AA101 -> 0.80356899
B61: Operating margin | C61: =Statement!T102 -> -0.12227163 | D61: =Statement!U102 -> 0.079332745 | E61: =Statement!V102 -> -0.046020459 | F61: =Statement!W102 -> -0.055801597 | G61: =Statement!X102 -> 0.031794178 | H61: =Statement!Y102 -> 0.16687764 | I61: =Statement!Z102 -> 0.066893413 | J61: =Statement!AA102 -> 0.077034827
B62: Net margin | C62: =Statement!T103 -> -0.030043451 | D62: =Statement!U103 -> 0.12225773 | E62: =Statement!V103 -> -0.063245884 | F62: =Statement!W103 -> 0.0043789809 | G62: =Statement!X103 -> 0.48366021 | H62: =Statement!Y103 -> 0.21712841 | I62: =Statement!Z103 -> 0.053838358 | J62: =Statement!AA103 -> 0.087967025
B63: Revenue Licenses | C63: =Statement!T187 -> 137174 | D63: =Statement!U187 -> 197609 | E63: =Statement!V187 -> 128286 | F63: =Statement!W187 -> 112161 | G63: =Statement!X187 -> 150043 | H63: =Statement!Y187 -> 215904 | I63: =Statement!Z187 -> 149309 | J63: =Statement!AA187 -> 123843
B64: Revenue Subscription | C64: =Statement!T188 -> 206922 | D64: =Statement!U188 -> 215221 | E64: =Statement!V188 -> 217303 | F64: =Statement!W188 -> 238363 | G64: =Statement!X188 -> 247573 | H64: =Statement!Y188 -> 251233 | I64: =Statement!Z188 -> 252903 | J64: =Statement!AA188 -> 266067
B65: Revenue Professional | C65: =Statement!T189 -> 10557 | D65: =Statement!U189 -> 10816 | E65: =Statement!V189 -> 11035 | F65: =Statement!W189 -> 11204 | G65: =Statement!X189 -> 13497 | H65: =Statement!Y189 -> 13970 | I65: =Statement!Z189 -> 16170 | J65: =Statement!AA189 -> 20346
B66: FCFE | C66: =Statement!T157 -> -64293 | D66: =Statement!U157 -> 0 | E66: =Statement!V157 -> 29809 | F66: =Statement!W157 -> -36419 | G66: =Statement!X157 -> -46368 | H66: =Statement!Y157 -> 114462 | I66: =Statement!Z157 -> 75934 | J66: =Statement!AA157 -> -15652

Sheet Forecast ->
H5: Links
H6: Overview'!B3
H7: Financials ->'!B13
H8: Analysis ->'!B13
H9: Forecast ->'!B13
H10: Valuation ->'!B13
B13: Forecast ->

Sheet Revenue
B1: Revenue forecast
C2: History | H2: Forecast | S2: History | AA2: Forecast | AE2: TTM
C4: Revenues | S4: Revenues
B5: Revenues (thousand) | C5: =Statement!M3 -> 2022 | D5: =Statement!N3 -> 2023 | E5: =Statement!O3 -> 2024 | F5: =Statement!P3 -> 2025 | G5: =Statement!Q3 -> 2026 | H5: =G5+1 -> 2027 | I5: =H5+1 -> 2028 | J5: =I5+1 -> 2029 | K5: =J5+1 -> 2030 | L5: =K5+1 -> 2031 | R5: =B5 -> Revenues (thousand) | S5: =Statement!T3 -> Q3 2025 | T5: =Statement!U3 -> Q4 2025 | U5: =Statement!V3 -> Q1 2026 | V5: =Statement!W3 -> Q2 2026 | W5: =Statement!X3 -> Q3 2026 | X5: =Statement!Y3 -> Q4 2026 | Y5: =Statement!Z3 -> Q1 2027 | Z5: =Statement!AA3 -> Q2 2027 | AA5: FQ1 | AB5: FQ2 | AC5: FQ3 | AE5: FQ1
B6: =Statement!B187 -> Licenses | C6: =Statement!M187 -> 481427 | D6: =Statement!N187 -> 497836 | E6: =Statement!O187 -> 621392 | F6: =Statement!P187 -> 587152 | G6: =Statement!Q187 -> 606394 | H6: =H9*H29 -> 626739.4 | I6: =I9*I29 -> 642960.25 | J6: =J9*J29 -> 663901.02 | K6: =K9*K29 -> 690821.45 | L6: =L9*L29 -> 692587.69 | N6: Revenue * Licenses % revenue | Q6: Revenue * Licenses % revenue | R6: =B6 -> Licenses | S6: =Statement!T187 -> 137174 | T6: =Statement!U187 -> 197609 | U6: =Statement!V187 -> 128286 | V6: =Statement!W187 -> 112161 | W6: =Statement!X187 -> 150043 | X6: =Statement!Y187 -> 215904 | Y6: =Statement!Z187 -> 149309 | Z6: =Statement!AA187 -> 123843 | AA6: =AA9*AA29 -> 153538 | AE6: =SUM(X6:AA6) -> 642594
B7: =Statement!B188 -> Subscription services | C7: =Statement!M188 -> 369867 | D7: =Statement!N188 -> 508823 | E7: =Statement!O188 -> 649918 | F7: =Statement!P188 -> 801947 | G7: =Statement!Q188 -> 954472 | H7: =H9-H6-H8 -> 1092317.2 | I7: =I9-I6-I8 -> 1241108.1 | J7: =J9-J6-J8 -> 1417749.9 | K7: =K9-K6-K8 -> 1552045.5 | L7: =L9-L6-L8 -> 1719101.6 | N7: Revenue - License - Professional services | Q7: Revenue - License - Professional services | R7: =B7 -> Subscription services | S7: =Statement!T188 -> 206922 | T7: =Statement!U188 -> 215221 | U7: =Statement!V188 -> 217303 | V7: =Statement!W188 -> 238363 | W7: =Statement!X188 -> 247573 | X7: =Statement!Y188 -> 251233 | Y7: =Statement!Z188 -> 252903 | Z7: =Statement!AA188 -> 266067 | AA7: =AA9-AA6-AA8 -> 263208 | AE7: =SUM(X7:AA7) -> 1033411
B8: =Statement!B189 -> Professional services | C8: =Statement!M189 -> 40958 | D8: =Statement!N189 -> 51922 | E8: =Statement!O189 -> 36762 | F8: =Statement!P189 -> 40555 | G8: =Statement!Q189 -> 49706 | H8: =H9*H28 -> 71627.36 | I8: =I9*I28 -> 64296.025 | J8: =J9*J28 -> 59965.253 | K8: =K9*K28 -> 59871.192 | L8: =L9*L28 -> 61838.186 | N8: Revenue * Professional services % revenue | Q8: Revenue * Professional services % revenue | R8: =B8 -> Professional services | S8: =Statement!T189 -> 10557 | T8: =Statement!U189 -> 10816 | U8: =Statement!V189 -> 11035 | V8: =Statement!W189 -> 11204 | W8: =Statement!X189 -> 13497 | X8: =Statement!Y189 -> 13970 | Y8: =Statement!Z189 -> 16170 | Z8: =Statement!AA189 -> 20346 | AA8: =AA9*AA28 -> 21934 | AE8: =SUM(X8:AA8) -> 72420
B9: Total | C9: =Statement!M5 -> 892252 | D9: =Statement!N5 -> 1058581 | E9: =Statement!O5 -> 1308072 | F9: =Statement!P5 -> 1429664 | G9: =Statement!Q5 -> 1610572 | H9: =H21*H27 -> 1790684 | I9: =I21*I27 -> 1948364.4 | J9: =J21*J27 -> 2141616.2 | K9: =K21*K27 -> 2302738.2 | L9: =L21*L27 -> 2473527.4 | N9: ARR * Revenue to ARR | Q9: ARR * Revenue to ARR | R9: Total | S9: =Statement!T5 -> 354653 | T9: =Statement!U5 -> 423646 | U9: =Statement!V5 -> 356624 | V9: =Statement!W5 -> 361728 | W9: =Statement!X5 -> 411113 | X9: =Statement!Y5 -> 481107 | Y9: =Statement!Z5 -> 418382 | Z9: =Statement!AA5 -> 410256 | AA9: =AA21*AA27 -> 438680 | AE9: =SUM(X9:AA9) -> 1748425
C11: Growth rates | S11: Growth rates
B12: Revenue growth % | C12: =C5 -> 2022 | D12: =D5 -> 2023 | E12: =E5 -> 2024 | F12: =F5 -> 2025 | G12: =G5 -> 2026 | H12: =H5 -> 2027 | I12: =I5 -> 2028 | J12: =J5 -> 2029 | ... L12: =L5 -> 2031 | R12: Revenue growth % | S12: =S5 -> Q3 2025 | T12: =T5 -> Q4 2025 | U12: =U5 -> Q1 2026 | V12: =V5 -> Q2 2026 | W12: =W5 -> Q3 2026 | X12: =X5 -> Q4 2026 | Y12: =Y5 -> Q1 2027 | Z12: =Z5 -> Q2 2027 | ... AC12: =AC5 -> FQ3
B13: =B6 -> Licenses | D13: =D6/C6-1 -> 0.034084088 | E13: =E6/D6-1 -> 0.24818615 | F13: =F6/E6-1 -> -0.055102093 | G13: =G6/F6-1 -> 0.032771752 | H13: =H6/G6-1 -> 0.033551453 | I13: =I6/H6-1 -> 0.025881334 | J13: =J6/I6-1 -> 0.032569301 | K13: =K6/J6-1 -> 0.04054886 | L13: =L6/K6-1 -> 0.0025567213 | R13: =R6 -> Licenses | T13: =T6/S6-1 -> 0.44057183 | U13: =U6/T6-1 -> -0.35080892 | V13: =V6/U6-1 -> -0.12569571 | W13: =W6/V6-1 -> 0.33774663 | X13: =X6/W6-1 -> 0.4389475 | Y13: =Y6/X6-1 -> -0.30844727 | Z13: =Z6/Y6-1 -> -0.17055904 | AA13: =AA6/Z6-1 -> 0.2397794
B14: =B7 -> Subscription services | D14: =D7/C7-1 -> 0.3756918 | E14: =E7/D7-1 -> 0.27729682 | F14: =F7/E7-1 -> 0.23392028 | G14: =G7/F7-1 -> 0.19019337 | H14: =H7/G7-1 -> 0.14442041 | I14: =I7/H7-1 -> 0.13621581 | J14: =J7/I7-1 -> 0.14232587 | K14: =K7/J7-1 -> 0.094724465 | L14: =L7/K7-1 -> 0.10763606 | R14: =R7 -> Subscription services | T14: =T7/S7-1 -> 0.0401069 | U14: =U7/T7-1 -> 0.0096737772 | V14: =V7/U7-1 -> 0.096915367 | W14: =W7/V7-1 -> 0.038638547 | X14: =X7/W7-1 -> 0.014783518 | Y14: =Y7/X7-1 -> 0.0066472159 | Z14: =Z7/Y7-1 -> 0.052051577 | AA14: =AA7/Z7-1 -> -0.010745414
B15: =B8 -> Professional services | D15: =D8/C8-1 -> 0.26768885 | E15: =E8/D8-1 -> -0.29197643 | F15: =F8/E8-1 -> 0.10317719 | G15: =G8/F8-1 -> 0.22564419 | H15: =H8/G8-1 -> 0.4410204 | I15: =I8/H8-1 -> -0.10235383 | J15: =J8/I8-1 -> -0.067356761 | K15: =K8/J8-1 -> -0.0015685938 | L15: =L8/K8-1 -> 0.032853765 | R15: =R8 -> Professional services | T15: =T8/S8-1 -> 0.024533485 | U15: =U8/T8-1 -> 0.020247781 | V15: =V8/U8-1 -> 0.015314907 | W15: =W8/V8-1 -> 0.20465905 | X15: =X8/W8-1 -> 0.035044825 | Y15: =Y8/X8-1 -> 0.15748031 | Z15: =Z8/Y8-1 -> 0.25825603 | AA15: =AA8/Z8-1 -> 0.07804974
B16: =B9 -> Total | D16: =D9/C9-1 -> 0.18641482 | E16: =E9/D9-1 -> 0.23568437 | F16: =F9/E9-1 -> 0.092955128 | G16: =G9/F9-1 -> 0.12653882 | H16: =H9/G9-1 -> 0.11183108 | I16: =I9/H9-1 -> 0.088055961 | J16: =J9/I9-1 -> 0.099186675 | K16: =K9/J9-1 -> 0.075233822 | L16: =L9/K9-1 -> 0.074167916 | R16: =R9 -> Total | T16: =T9/S9-1 -> 0.19453663 | U16: =U9/T9-1 -> -0.15820284 | V16: =V9/U9-1 -> 0.014311992 | W16: =W9/V9-1 -> 0.13652523 | X16: =X9/W9-1 -> 0.17025489 | Y16: =Y9/X9-1 -> -0.1303764 | Z16: =Z9/Y9-1 -> -0.019422442 | AA16: =AA9/Z9-1 -> 0.069283569
C19: Drivers and metrics | S19: Drivers and metrics | AE19: =AE4 -> 0
B20: Metric (thousand) | C20: =C5 -> 2022 | D20: =D5 -> 2023 | E20: =E5 -> 2024 | F20: =F5 -> 2025 | G20: =G5 -> 2026 | H20: =H5 -> 2027 | I20: =I5 -> 2028 | J20: =J5 -> 2029 | ... L20: =L5 -> 2031 | R20: Metric (thousand) | S20: =S5 -> Q3 2025 | T20: =T5 -> Q4 2025 | U20: =U5 -> Q1 2026 | V20: =V5 -> Q2 2026 | W20: =W5 -> Q3 2026 | X20: =X5 -> Q4 2026 | Y20: =Y5 -> Q1 2027 | Z20: =Z5 -> Q2 2027 | ... AC20: =AC5 -> FQ3 | AE20: =AE5 -> FQ1
B21: ARR | C21: =Statement!M213 -> 925276 | D21: =Statement!N213 -> 1203845 | E21: =Statement!O213 -> 1463698 | F21: =Statement!P213 -> 1666136 | G21: =Statement!Q213 -> 1852567 | H21: 2063000 | I21: =(H21*I22)+I24 -> 2265540 | J21: =(I21*J22)+J24 -> 2461627.8 | K21: =(J21*K22)+K24 -> 2646825.5 | L21: =(K21*L22)+L24 -> 2843135 | N21: ARR(t-1) * NRR + New logo ARR | Q21: ARR(t-1) * NRR + New logo ARR | R21: ARR | S21: =Statement!T213 -> 1606561 | T21: =Statement!U213 -> 1666136 | U21: =Statement!V213 -> 1692683 | V21: =Statement!W213 -> 1723401 | W21: =Statement!X213 -> 1782384 | X21: =Statement!Y213 -> 1852567 | Y21: =Statement!Z213 -> 1901211 | Z21: =Statement!AA213 -> 1937722 | AA21: 1994000 | AE21: =AA21 -> 1994000
B22: Net retention rate | C22: =Statement!M215 -> 1.45 | D22: =Statement!N215 -> 1.23 | E22: =Statement!O215 -> 1.19 | F22: =Statement!P215 -> 1.1 | G22: =Statement!Q215 -> 1.07 | H22: 1.08 | I22: 1.08 | J22: 1.07 | K22: 1.06 | L22: 1.06 | R22: Net retention rate | S22: =Statement!T215 -> 1.13 | T22: =Statement!U215 -> 1.1 | U22: =Statement!V215 -> 1.08 | V22: =Statement!W215 -> 1.08 | W22: =Statement!X215 -> 1.07 | X22: =Statement!Y215 -> 1.07 | Y22: =Statement!Z215 -> 1.09 | Z22: =Statement!AA215 -> 1.09 | AA22: 1.08 | AE22: =AA22 -> 1.08
B23: New ARR | C23: =Statement!M214 -> 344793 | D23: =Statement!N214 -> 278569 | E23: =Statement!O214 -> 259853 | F23: =Statement!P214 -> 202438 | G23: =Statement!Q214 -> 186431 | H23: =H21-G21 -> 210433 | I23: =I21-H21 -> 202540 | J23: =J21-I21 -> 196087.8 | K23: =K21-J21 -> 185197.67 | L23: =L21-K21 -> 196309.53 | N23: ARR(t) - ARR(t-1) | Q23: ARR(t) - ARR(t-1) | R23: New ARR | S23: =Statement!T214 -> 56000 | T23: =Statement!U214 -> 60000 | U23: =Statement!V214 -> 27000 | V23: =Statement!W214 -> 31000 | W23: =Statement!X214 -> 59000 | X23: =Statement!Y214 -> 70000 | Y23: =Statement!Z214 -> 49000 | Z23: =Statement!AA214 -> 37000 | AA23: =AA21-Z21 -> 56278 | AE23: =SUM(X23:AA23) -> 212278
B24: New logo ARR | H24: =H25*H26 -> 37500 | I24: =I25*I26 -> 37500 | J24: =J25*J26 -> 37500 | K24: =K25*K26 -> 37500 | L24: =L25*L26 -> 37500 | N24: New customers * avg initial contract value | Q24: New customers * avg initial contract value | R24: New logo ARR | AA24: =AA25*AA26 -> 7500
B25: New Customers >= 100k | D25: =Statement!N217-Statement!M217 -> 292 | E25: =Statement!O217-Statement!N217 -> 269 | F25: =Statement!P217-Statement!O217 -> 238 | G25: =Statement!Q217-Statement!P217 -> 273 | H25: 250 | I25: 250 | J25: 250 | K25: 250 | L25: 250 | R25: New Customers >= 100k | T25: =Statement!U217-Statement!T217 -> 57 | U25: =Statement!V217-Statement!U217 -> 73 | V25: =Statement!W217-Statement!V217 -> 67 | W25: =Statement!X217-Statement!W217 -> 74 | X25: =Statement!Y217-Statement!X217 -> 59 | Y25: =Statement!Z217-Statement!Y217 -> 59 | Z25: =Statement!AA217-Statement!Z217 -> 42 | AA25: 50 | AE25: =SUM(X25:AA25) -> 210
B26: Avg initial contract value | H26: 150 | I26: 150 | J26: 150 | K26: 150 | L26: 150 | R26: Avg initial contract value | AA26: 150
B27: Revenue to ARR | C27: =C9/C21 -> 0.96430903 | D27: =D9/D21 -> 0.8793333 | E27: =E9/E21 -> 0.89367615 | F27: =F9/F21 -> 0.85807161 | G27: =G9/G21 -> 0.86937315 | H27: 0.868 | I27: 0.86 | J27: 0.87 | K27: 0.87 | L27: 0.87 | R27: Revenue to ARR | S27: =S9/S21 -> 0.2207529 | T27: =T9/T21 -> 0.25426856 | U27: =U9/U21 -> 0.21068564 | V27: =V9/V21 -> 0.20989195 | W27: =W9/W21 -> 0.23065344 | X27: =X9/X21 -> 0.25969749 | Y27: =Y9/Y21 -> 0.22006079 | Z27: =Z9/Z21 -> 0.21172077 | AA27: 0.22
B28: Professional services % revenue | C28: =C8/C9 -> 0.045904072 | D28: =D8/D9 -> 0.049048679 | E28: =E8/E9 -> 0.028103958 | F28: =F8/F9 -> 0.028366805 | G28: =G8/G9 -> 0.030862327 | H28: 0.04 | I28: 0.033 | J28: 0.028 | K28: 0.026 | L28: 0.025 | R28: Professional services % revenue | S28: =S8/S9 -> 0.029767124 | T28: =T8/T9 -> 0.02553075 | U28: =U8/U9 -> 0.030942954 | V28: =V8/V9 -> 0.030973549 | W28: =W8/W9 -> 0.03283039 | X28: =X8/X9 -> 0.0290372 | Y28: =Y8/Y9 -> 0.03864889 | Z28: =Z8/Z9 -> 0.049593425 | AA28: 0.05
B29: Licenses % revenue | C29: =C6/C9 -> 0.53956393 | D29: =D6/D9 -> 0.47028617 | E29: =E6/E9 -> 0.47504419 | F29: =F6/F9 -> 0.4106923 | G29: =G6/G9 -> 0.37650847 | H29: 0.35 | I29: 0.33 | J29: 0.31 | K29: 0.3 | L29: 0.28 | R29: Licenses % revenue | S29: =S6/S9 -> 0.3867837 | T29: =T6/T9 -> 0.4664484 | U29: =U6/U9 -> 0.35972341 | V29: =V6/V9 -> 0.31007 | W29: =W6/W9 -> 0.36496778 | X29: =X6/X9 -> 0.44876504 | Y29: =Y6/Y9 -> 0.35687243 | Z29: =Z6/Z9 -> 0.30186761 | AA29: 0.35
C32: Growth rates for metrics | S32: Growth rates for metrics
B33: Metrics growth % | C33: =C5 -> 2022 | D33: =D5 -> 2023 | E33: =E5 -> 2024 | F33: =F5 -> 2025 | G33: =G5 -> 2026 | H33: =H5 -> 2027 | I33: =I5 -> 2028 | J33: =J5 -> 2029 | ... L33: =L5 -> 2031 | R33: Metrics growth % | S33: =S5 -> Q3 2025 | T33: =T5 -> Q4 2025 | U33: =U5 -> Q1 2026 | V33: =V5 -> Q2 2026 | W33: =W5 -> Q3 2026 | X33: =X5 -> Q4 2026 | Y33: =Y5 -> Q1 2027 | Z33: =Z5 -> Q2 2027 | ... AC33: =AC5 -> FQ3
B34: ARR | D34: =D21/C21-1 -> 0.30106584 | E34: =E21/D21-1 -> 0.21585254 | F34: =F21/E21-1 -> 0.13830585 | G34: =G21/F21-1 -> 0.11189423 | H34: =H21/G21-1 -> 0.11358995 | I34: =I21/H21-1 -> 0.098177412 | J34: =J21/I21-1 -> 0.086552345 | K34: =K21/J21-1 -> 0.075233822 | L34: =L21/K21-1 -> 0.074167916 | R34: =B34 -> ARR | T34: =T21/S21-1 -> 0.037082314 | U34: =U21/T21-1 -> 0.015933273 | V34: =V21/U21-1 -> 0.018147521 | W34: =W21/V21-1 -> 0.034224768 | X34: =X21/W21-1 -> 0.039375915 | Y34: =Y21/X21-1 -> 0.02625762 | Z34: =Z21/Y21-1 -> 0.019204076 | AA34: =AA21/Z21-1 -> 0.029043382
B35: New ARR | D35: =D23/C23-1 -> -0.19206886 | E35: =E23/D23-1 -> -0.067186227 | F35: =F23/E23-1 -> -0.22095185 | G35: =G23/F23-1 -> -0.079071123 | H35: =H23/G23-1 -> 0.12874468 | I35: =I23/H23-1 -> -0.037508376 | J35: =J23/I23-1 -> -0.031856423 | K35: =K23/J23-1 -> -0.05553702 | L35: =L23/K23-1 -> 0.06 | R35: =B35 -> New ARR | T35: =T23/S23-1 -> 0.071428571 | U35: =U23/T23-1 -> -0.55 | V35: =V23/U23-1 -> 0.14814815 | W35: =W23/V23-1 -> 0.90322581 | X35: =X23/W23-1 -> 0.18644068 | Y35: =Y23/X23-1 -> -0.3 | Z35: =Z23/Y23-1 -> -0.24489796 | AA35: =AA23/Z23-1 -> 0.52102703

Sheet COGS & OpEx
B1: COGS & OpEx forecast
C2: History | H2: Forecast | P2: History | X2: Forecast | AB2: TTM
C4: Revenues | P4: Revenues
B5: =Revenue!B5 -> Revenues (thousand) | C5: =Revenue!C5 -> 2022 | D5: =Revenue!D5 -> 2023 | E5: =Revenue!E5 -> 2024 | F5: =Revenue!F5 -> 2025 | G5: =Revenue!G5 -> 2026 | H5: =G5+1 -> 2027 | I5: =H5+1 -> 2028 | J5: =I5+1 -> 2029 | K5: =J5+1 -> 2030 | L5: =K5+1 -> 2031 | O5: Revenues (thousand) | P5: =Revenue!S5 -> Q3 2025 | Q5: =Revenue!T5 -> Q4 2025 | R5: =Revenue!U5 -> Q1 2026 | S5: =Revenue!V5 -> Q2 2026 | T5: =Revenue!W5 -> Q3 2026 | U5: =Revenue!X5 -> Q4 2026 | V5: =Revenue!Y5 -> Q1 2027 | W5: =Revenue!Z5 -> Q2 2027 | X5: FQ1 | Y5: FQ2 | Z5: FQ3 | AB5: =Revenue!AE5 -> FQ1
B6: Revenue | C6: =Revenue!C9 -> 892252 | D6: =Revenue!D9 -> 1058581 | E6: =Revenue!E9 -> 1308072 | F6: =Revenue!F9 -> 1429664 | G6: =Revenue!G9 -> 1610572 | H6: =Revenue!H9 -> 1790684 | I6: =Revenue!I9 -> 1948364.4 | J6: =Revenue!J9 -> 2141616.2 | ... L6: =Revenue!L9 -> 2473527.4 | O6: Revenue | P6: =Revenue!S9 -> 354653 | Q6: =Revenue!T9 -> 423646 | R6: =Revenue!U9 -> 356624 | S6: =Revenue!V9 -> 361728 | T6: =Revenue!W9 -> 411113 | U6: =Revenue!X9 -> 481107 | V6: =Revenue!Y9 -> 418382 | W6: =Revenue!Z9 -> 410256 | X6: =Revenue!AA9 -> 438680 | AB6: =Revenue!AE9 -> 1748425
C9: COGS and OpEx | P9: COGS & OpEx | AB9: =AB4 -> 0
B10: Expenses (tnousand) | C10: =C5 -> 2022 | D10: =D5 -> 2023 | E10: =E5 -> 2024 | F10: =F5 -> 2025 | G10: =G5 -> 2026 | H10: =H5 -> 2027 | I10: =I5 -> 2028 | J10: =J5 -> 2029 | ... L10: =L5 -> 2031 | O10: Expenses (thousand) | P10: =P5 -> Q3 2025 | Q10: =Q5 -> Q4 2025 | R10: =R5 -> Q1 2026 | S10: =S5 -> Q2 2026 | T10: =T5 -> Q3 2026 | U10: =U5 -> Q4 2026 | V10: =V5 -> Q1 2027 | W10: =W5 -> Q2 2027 | ... Z10: =Z5 -> FQ3 | AB10: =AB5 -> FQ1
B11: =Statement!B191 -> Licenses COGS | C11: =Statement!M191 -> 11888 | D11: =Statement!N191 -> 10421 | E11: =Statement!O191 -> 10469 | F11: =Statement!P191 -> 8565 | G11: =Statement!Q191 -> 5334 | H11: =H6*H23 -> 5372.052 | I11: =I6*I23 -> 5845.0932 | J11: =J6*J23 -> 4283.2324 | K11: =K6*K23 -> 4605.4763 | L11: =L6*L23 -> 4947.0549 | O11: =B11 -> Licenses COGS | P11: =Statement!T191 -> 2340 | Q11: =Statement!U191 -> 1231 | R11: =Statement!V191 -> 1268 | S11: =Statement!W191 -> 1200 | T11: =Statement!X191 -> 1311 | U11: =Statement!Y191 -> 1555 | V11: =Statement!Z191 -> 1664 | W11: =Statement!AA191 -> 1462 | X11: =X23*X$6 -> 1316.04 | AB11: =SUM(U11:X11) -> 5997.04
B12: =Statement!B192 -> Subscription services COGS | C12: =Statement!M192 -> 60565 | D12: =Statement!N192 -> 87366 | E12: =Statement!O192 -> 111922 | F12: =Statement!P192 -> 167630 | G12: =Statement!Q192 -> 157588 | H12: =H6*H24 -> 179068.4 | I12: =I6*I24 -> 194836.44 | J12: =J6*J24 -> 192745.46 | K12: =K6*K24 -> 207246.43 | L12: =L6*L24 -> 197882.2 | O12: =B12 -> Subscription services COGS | P12: =Statement!T192 -> 43487 | Q12: =Statement!U192 -> 43860 | R12: =Statement!V192 -> 38468 | S12: =Statement!W192 -> 38229 | T12: =Statement!X192 -> 40121 | U12: =Statement!Y192 -> 40770 | V12: =Statement!Z192 -> 43988 | W12: =Statement!AA192 -> 39679 | X12: =X24*X$6 -> 39481.2 | AB12: =SUM(U12:X12) -> 163918.2
B13: =Statement!B193 -> Professional services COGS | C13: =Statement!M193 -> 96415 | D13: =Statement!N193 -> 82264 | E13: =Statement!O193 -> 73533 | F13: =Statement!P193 -> 70747 | G13: =Statement!Q193 -> 108062 | H13: =H6*H25 -> 125347.88 | I13: =I6*I25 -> 126643.69 | J13: =J6*J25 -> 117788.89 | K13: =K6*K25 -> 115136.91 | L13: =L6*L25 -> 111308.74 | O13: =B13 -> Professional services COGS | P13: =Statement!T193 -> 17936 | Q13: =Statement!U193 -> 19443 | R13: =Statement!V193 -> 24121 | S13: =Statement!W193 -> 24951 | T13: =Statement!X193 -> 27380 | U13: =Statement!Y193 -> 31610 | V13: =Statement!Z193 -> 31276 | W13: =Statement!AA193 -> 39446 | X13: =X25*X$6 -> 35094.4 | AB13: =SUM(U13:X13) -> 137426.4
B14: COGS | C14: =Statement!M6 -> 168868 | D14: =Statement!N6 -> 180051 | E14: =Statement!O6 -> 195924 | F14: =Statement!P6 -> 246942 | G14: =Statement!Q6 -> 270984 | H14: =SUM(H11:H13) -> 309788.33 | I14: =SUM(I11:I13) -> 327325.22 | J14: =SUM(J11:J13) -> 314817.58 | K14: =SUM(K11:K13) -> 326988.82 | L14: =SUM(L11:L13) -> 314137.99 | O14: =B14 -> COGS | P14: =Statement!T6 -> 63763 | Q14: =Statement!U6 -> 64534 | R14: =Statement!V6 -> 63857 | S14: =Statement!W6 -> 64380 | T14: =Statement!X6 -> 68812 | U14: =Statement!Y6 -> 73935 | V14: =Statement!Z6 -> 76928 | W14: =Statement!AA6 -> 80587 | X14: =SUM(X11:X13) -> 75891.64 | AB14: =SUM(AB11:AB13) -> 307341.64
B15: =Statement!B8 -> Sales and marketing | C15: =Statement!M8 -> 697682 | D15: =Statement!N8 -> 701558 | E15: =Statement!O8 -> 713130 | F15: =Statement!P8 -> 738493 | G15: =Statement!Q8 -> 683329 | H15: =H6*H27 -> 716273.6 | I15: =I6*I27 -> 779345.76 | J15: =J6*J27 -> 813814.15 | K15: =K6*K27 -> 875040.5 | L15: =L6*L27 -> 890469.88 | O15: =B15 -> Sales and marketing | P15: =Statement!T8 -> 187188 | Q15: =Statement!U8 -> 176836 | R15: =Statement!V8 -> 159661 | S15: =Statement!W8 -> 166303 | T15: =Statement!X8 -> 179186 | U15: =Statement!Y8 -> 178179 | V15: =Statement!Z8 -> 167859 | W15: =Statement!AA8 -> 164606 | X15: =X27*X$6 -> 175472 | AB15: =SUM(U15:X15) -> 686116
B16: =Statement!B9 -> R&D | C16: =Statement!M9 -> 276657 | D16: =Statement!N9 -> 285750 | E16: =Statement!O9 -> 332101 | F16: =Statement!P9 -> 380682 | G16: =Statement!Q9 -> 385208 | H16: =H6*H28 -> 447671 | I16: =I6*I28 -> 487091.1 | J16: =J6*J28 -> 524695.97 | K16: =K6*K28 -> 552657.16 | L16: =L6*L28 -> 593646.59 | O16: =B16 -> R&D | P16: =Statement!T9 -> 96976 | Q16: =Statement!U9 -> 99670 | R16: =Statement!V9 -> 94839 | S16: =Statement!W9 -> 98341 | T16: =Statement!X9 -> 96869 | U16: =Statement!Y9 -> 95159 | V16: =Statement!Z9 -> 92902 | W16: =Statement!AA9 -> 83393 | X16: =X28*X$6 -> 100896.4 | AB16: =SUM(U16:X16) -> 372350.4
B17: =Statement!B10 -> General and administrative | C17: =Statement!M10 -> 249991 | D17: =Statement!N10 -> 239505 | E17: =Statement!O10 -> 231637 | F17: =Statement!P10 -> 226116 | G17: =Statement!Q10 -> 214291 | H17: =H6*H29 -> 214882.08 | I17: =I6*I29 -> 233803.73 | J17: =J6*J29 -> 235577.78 | K17: =K6*K29 -> 253301.2 | L17: =L6*L29 -> 247352.74 | O17: =B17 -> General and administrative | P17: =Statement!T10 -> 50090 | Q17: =Statement!U10 -> 48997 | R17: =Statement!V10 -> 54679 | S17: =Statement!W10 -> 52889 | T17: =Statement!X10 -> 53175 | U17: =Statement!Y10 -> 53548 | V17: =Statement!Z10 -> 52706 | W17: =Statement!AA10 -> 50066 | X17: =X29*X$6 -> 57028.4 | AB17: =SUM(U17:X17) -> 213348.4
