Workbook

Sheet Overview
B2: Automatic Data | E2: At a glance | H2: Valuation | K2: Links
B3: Company | C3: #VALUE! | E3: Market capitalization | F3: =Statement!AC153 -> 816194.86 | H3: ='AVG target price'!B5 -> DCF price | I3: ='AVG target price'!C5 -> 11.213353 | K3: Financials ->'!B13
B4: Ticker | C4: {=_FV(C3,"Ticker symbol",TRUE)} -> PHR | E4: Enterprise value | F4: =Statement!AC154 -> 809695.86 | H4: ='AVG target price'!B6 -> EV/EBIT price | I4: ='AVG target price'!C6 -> 17.829749 | K4: Analysis ->'!B13
B5: Price | C5: {=_FV(C3,"Price",TRUE)} -> 12.61 | E5: EPS | F5: =Statement!AC28 -> -0.017861847 | H5: ='AVG target price'!B7 -> PS price | I5: ='AVG target price'!C7 -> 17.048124 | K5: Forecast ->'!B13
B6: Price Extended Hours | C6: {=_FV(C3,"Price (Extended hours)",TRUE)} -> 12.59 | E6: PE | F6: =Statement!AC150 -> -705.97403 | H6: ='AVG target price'!B8 -> EV/FCFF price | I6: ='AVG target price'!C8 -> 14.29173 | K6: Valuation ->'!B13
B7: Day change | C7: {=_FV(C3,"Change")} -> -0.09 | E7: PS | F7: =Statement!AC151 -> 1.5369177 | H7: ='AVG target price'!B9 -> EV/Sales price | I7: ='AVG target price'!C9 -> 25.875822
B8: Day change extended | C8: {=_FV(C3,"Change (extended hours)",TRUE)} -> -0.02 | E8: FCF Yield | F8: =Statement!AC161 -> 0.0099191999 | H8: ='AVG target price'!B10 -> AVG price | I8: ='AVG target price'!C10 -> 17.251756
B9: Day change % | C9: {=_FV(C3,"Change (%)",TRUE)} -> -0.007087 | E9: Earnings Yield | F9: =Statement!AC162 -> -0.0014164827 | H9: ='AVG target price'!B12 -> Upside/Downside | I9: ='AVG target price'!C12 -> 0.36810118
B10: Day change extended % | C10: {=_FV(C3,"Change % (extended hours)",TRUE)} -> -0.001586 | E10: Buyback Yield | F10: =Statement!AC164 -> 0
B11: 52 week high | C11: {=_FV(C3,"52 week high",TRUE)} -> 23.8651 | E11: Dividend Yield | F11: =Statement!AC163 -> 0 | H11: DDM price | I11: =DDM!C26 -> 0
B12: 52 week low | C12: {=_FV(C3,"52 week low",TRUE)} -> 7.77 | E12: ROA | F12: =Statement!AC127 -> -0.0018099561
B13: Beta | C13: {=_FV(C3,"Beta")} -> 0.7583 | E13: ROE | F13: =Statement!AC129 -> -0.0031491108 | H13: Reverse DCF rate | I13: ='Reverse DCF'!C17 -> 0.45
B14: Avg volume | C14: {=_FV(C3,"Volume average",TRUE)} -> 679066 | E14: ROIC | F14: =Statement!AC140 -> -0.014540196 | H14: Reverse DCF price | I14: ='Reverse DCF'!C16 -> 11.046079
E15: Net Cash/Market Cap | F15: =Statement!AC176 -> 0.0079625593
E16: Net Cash/Share | F16: =Statement!AC175 -> 0.10470268 | H16: Discount rates used
B17: Unit data and other info | E17: Insider Ownership | F17: =Statement!AC171 -> 0.050026265 | H17: WACC | I17: =DCF!C15 -> 0.081545315
B18: Units | C18: K | E18: Net Trade Cycle | F18: =Statement!AC144 -> 37.184518 | H18: Cost of Equity | I18: =Multiples!C54 -> 0.0840035
B19: Units conversion | C19: 1000 | E19: Net Debt/Equity | F19: =Statement!AC146 -> -0.01747743
B20: Has operating lease | C20: Yes | E20: Quick Ratio | F20: =Statement!AC147 -> 1.1287308
B21: Has finance lease | C21: Yes
B22: Has debt | C22: Yes
B25: Constants | E25: 10 Year Bond Yield
B26: Default tax rate | C26: 0.21 | E26: #VALUE! | F26: {=_FV(E26,"Price")} -> 49.88
B27: Cost of debt | C27: 0.065 | E27: Percentage | F27: =F26/1000 -> 0.04988
B28: Manual WACC | C28: 0
B29: Manual Cost of Equity | C29: 0
B33: Info
B35: Mission: | C35: Address 3 challenges in healthcare: access to care, affordability of care, health patient outcomes
B36: Auditor: | C36: KPMG
B42: Notes
B44: Date: | C44: 30.03.2026 | E44: Q4 2026
B45: - | C45: Revenue outlook for FY 2027 will be in the range 510-520 million
B46: - | C46: Network solution clients commiting lower spend levels for second half of fiscal 2027
B47: - | C47: AccessOne will contribute about 37 million to the total revenue range
B48: - | C48: Adjusted EBITDA in the range 125 to 135 million
B49: - | C49: AHSC growth in the mid single digit percentage range
B50: - | C50: Total revenue per AHSC in low single digit percentage range
B51: - | C51: TAM of 24B
B52: - | C52: It is expected that subscription growth will be slower than the other 2 revenue streams
B53: - | C53: Got a $250k revolving credit maturing on 13.03.2031
...

Sheet Financials ->
H5: Links
H6: Overview'!B3
H7: Financials ->'!B13
H8: Analysis ->'!B13
H9: Forecast ->'!B13
H10: Valuation ->'!B13
B13: Financials ->

Sheet Statement
B2: Date | M2: 31.01.2022 | N2: 31.01.2023 | O2: 31.01.2024 | P2: 31.01.2025 | Q2: 31.01.2026 | T2: 31.10.2024 | U2: 31.01.2025 | V2: 30.04.2025 | W2: 31.07.2025 | X2: 31.10.2025 | Y2: 31.01.2026 | Z2: 30.04.2026 | AA2: 31.07.2026
B3: FY | M3: 2022 | N3: 2023 | O3: 2024 | P3: 2025 | Q3: 2026 | T3: Q3 2025 | U3: Q4 2025 | V3: Q1 2026 | W3: Q2 2026 | X3: Q3 2026 | Y3: Q4 2026 | Z3: Q1 2027 | AA3: Q2 2027 | AC3: TTM/YTD
B4: Income statement
B5: Revenue | M5: 213233 | N5: 280910 | O5: 356299 | P5: 419813 | Q5: 480591 | T5: 106800 | U5: 109681 | V5: 115936 | W5: 117255 | X5: 120333 | Y5: 127067 | Z5: 130935 | AA5: 129458 | AC5: =SUM(X5:AA5) -> 507793
B6: COGS | M6: 81388 | N6: 109267 | O6: 124011 | P6: 134934 | Q6: 154123 | T6: 34537 | U6: 33566 | V6: 38065 | W6: 37641 | X6: 38027 | Y6: 40390 | Z6: =17659+25675 -> 43334 | AA6: =19271+23914 -> 43185 | AC6: =SUM(X6:AA6) -> 164936
B7: Gross Profit | C7: =C5-C6 -> 0 | D7: =D5-D6 -> 0 | E7: =E5-E6 -> 0 | F7: =F5-F6 -> 0 | G7: =G5-G6 -> 0 | H7: =H5-H6 -> 0 | I7: =I5-I6 -> 0 | J7: =J5-J6 -> 0 | ... Q7: =Q5-Q6 -> 326468 | T7: =T5-T6 -> 72263 | U7: =U5-U6 -> 76115 | V7: =V5-V6 -> 77871 | W7: =W5-W6 -> 79614 | X7: =X5-X6 -> 82306 | Y7: =Y5-Y6 -> 86677 | Z7: =Z5-Z6 -> 87601 | AA7: =AA5-AA6 -> 86273 | AC7: =SUM(X7:AA7) -> 342857
B8: Sales and marketing | M8: 106421 | N8: 151263 | O8: 147008 | P8: 121129 | Q8: 100243 | T8: 30071 | U8: 28863 | V8: 26043 | W8: 25396 | X8: 24148 | Y8: 24656 | Z8: 24209 | AA8: 24587 | AC8: =SUM(X8:AA8) -> 97600
B9: R&D | M9: 52265 | N9: 91244 | O9: 112346 | P9: 117364 | Q9: 121481 | T9: 29315 | U9: 29626 | V9: 31829 | W9: 29274 | X9: 29453 | Y9: 30925 | Z9: 28328 | AA9: 27571 | AC9: =SUM(X9:AA9) -> 116277
B10: General and administrative | M10: 68674 | N10: 80384 | O10: 79926 | P10: 76597 | Q10: 79903 | T10: 19633 | U10: 18415 | V10: 16408 | W10: 19042 | X10: 17488 | Y10: 26965 | Z10: 18361 | AA10: 16512 | AC10: =SUM(X10:AA10) -> 79326
B11: Depreciation | M11: 14985 | N11: 17988 | O11: 17584 | P11: 14183 | Q11: 12972 | T11: 3566 | U11: 3172 | V11: 2986 | W11: 3279 | X11: 3199 | Y11: 3508 | Z11: 3371 | AA11: 3340 | AC11: =SUM(X11:AA11) -> 13418
B12: Amortization | M12: 6317 | N12: 7316 | O12: 11903 | P12: 13703 | Q12: 18481 | T12: 3521 | U12: 3651 | V12: 3892 | W12: 4130 | X12: 4279 | Y12: 6180 | Z12: 6583 | AA12: 6655 | AC12: =SUM(X12:AA12) -> 23697
B13: OpEx | C13: =SUM(C8:C12) -> 0 | D13: =SUM(D8:D12) -> 0 | E13: =SUM(E8:E12) -> 0 | F13: =SUM(F8:F12) -> 0 | G13: =SUM(G8:G12) -> 0 | H13: =SUM(H8:H12) -> 0 | I13: =SUM(I8:I12) -> 0 | J13: =SUM(J8:J12) -> 0 | ... Q13: =SUM(Q8:Q12) -> 333080 | T13: =SUM(T8:T12) -> 86106 | U13: =SUM(U8:U12) -> 83727 | V13: =SUM(V8:V12) -> 81158 | W13: =SUM(W8:W12) -> 81121 | X13: =SUM(X8:X12) -> 78567 | Y13: =SUM(Y8:Y12) -> 92234 | Z13: =SUM(Z8:Z12) -> 80852 | AA13: =SUM(AA8:AA12) -> 78665 | AC13: =SUM(X13:AA13) -> 330318
B14: Operating income | M14: -116817 | N14: -176552 | O14: -136479 | P14: -58097 | Q14: -6612 | T14: -13843 | U14: -7612 | V14: -3287 | W14: -1507 | X14: 3739 | Y14: -5557 | Z14: 6749 | AA14: 7608 | AC14: =SUM(X14:AA14) -> 12539
B15: Interest income/expense | M15: -1084 | N15: 1064 | O15: 2211 | P15: 330 | Q15: =2173-6953 -> -4780 | T15: 26 | U15: 19 | V15: -230 | W15: 608 | X15: 380 | Y15: =269-5807 -> -5538 | Z15: =-2299+297 -> -2002 | AA15: =-1729+248 -> -1481 | AC15: =SUM(X15:AA15) -> -8641
B16: Other income/expense | M16: -78 | N16: -175 | O16: =44-1118 -> -1074 | P16: 1956 | Q16: =2953-501 -> 2452 | T16: -144 | U16: 2217 | V16: 338 | W16: 336 | X16: 1006 | Y16: =1273-501 -> 772 | Z16: -24 | AA16: -2888 | AC16: =SUM(X16:AA16) -> -1134
B17: Income before taxes | M17: -117979 | N17: -175663 | O17: -135342 | P17: -55811 | Q17: -8940 | T17: -13961 | U17: -5376 | V17: -3179 | W17: -563 | X17: 5125 | Y17: -10323 | Z17: 4723 | AA17: 3239 | AC17: =SUM(X17:AA17) -> 2764
B18: Income tax expense/benefit | M18: -182 | N18: -483 | O18: -1543 | P18: -2716 | Q18: -372 | T18: -442 | U18: -1014 | V18: -735 | W18: 1217 | X18: -854 | Y18: 0 | Z18: -1760 | AA18: -1321 | AC18: =SUM(X18:AA18) -> -3935
B19: Non-controlling interest | M19: 0 | N19: 0 | O19: 0 | P19: 0 | Q19: 0 | T19: 0 | U19: 0 | V19: 0 | W19: 0 | X19: 0 | Y19: 0 | Z19: 0 | AA19: 0 | AC19: =SUM(X19:AA19) -> 0
B20: Net income | M20: -118161 | N20: -176146 | O20: -136885 | P20: -58527 | Q20: -9312 | T20: -14403 | U20: -6390 | V20: -3914 | W20: 654 | X20: 4271 | Y20: -10323 | Z20: 2963 | AA20: 1918 | AC20: =SUM(X20:AA20) -> -1171
B21: Basic Shares outstanding avg | M21: 49888 | N21: 52440 | O21: 54561 | P21: 57590 | Q21: 59738 | T21: 57892 | U21: 58278 | V21: 58921 | W21: 59592 | X21: 60009 | Y21: 60404 | Z21: 60945 | AA21: 61878 | AC21: =AVERAGE(X21:AA21) -> 60809
B22: Basic Shares outstanding avg adjusted | C22: =C21*C$87 -> 0 | D22: =D21*D$87 -> 0 | E22: =E21*E$87 -> 0 | F22: =F21*F$87 -> 0 | G22: =G21*G$87 -> 0 | H22: =H21*H$87 -> 0 | I22: =I21*I$87 -> 0 | J22: =J21*J$87 -> 0 | ... Q22: =Q21*Q$87 -> 59738 | T22: =T21*T$87 -> 57892 | U22: =U21*U$87 -> 58278 | V22: =V21*V$87 -> 58921 | W22: =W21*W$87 -> 59592 | X22: =X21*X$87 -> 60009 | Y22: =Y21*Y$87 -> 60404 | Z22: =Z21*Z$87 -> 60945 | AA22: =AA21*AA$87 -> 61878 | AC22: =AC21*AC$87 -> 60809
B23: Diluted Shares outstanding avg | M23: 49888 | N23: 52440 | O23: 54561 | P23: 57590 | Q23: 61495 | T23: 57892 | U23: 58278 | V23: 58921 | W23: 61686 | X23: 61560 | Y23: 61497 | Z23: 62041 | AA23: 62463 | AC23: =AVERAGE(X23:AA23) -> 61890.25
B24: Diluted Shares outstanding avg adjusted | C24: =C23*C$87 -> 0 | D24: =D23*D$87 -> 0 | E24: =E23*E$87 -> 0 | F24: =F23*F$87 -> 0 | G24: =G23*G$87 -> 0 | H24: =H23*H$87 -> 0 | I24: =I23*I$87 -> 0 | J24: =J23*J$87 -> 0 | ... Q24: =Q23*Q$87 -> 61495 | T24: =T23*T$87 -> 57892 | U24: =U23*U$87 -> 58278 | V24: =V23*V$87 -> 58921 | W24: =W23*W$87 -> 61686 | X24: =X23*X$87 -> 61560 | Y24: =Y23*Y$87 -> 61497 | Z24: =Z23*Z$87 -> 62041 | AA24: =AA23*AA$87 -> 62463 | AC24: =AC23*AC$87 -> 61890.25
B25: Basic EPS | M25: -2.37 | N25: -3.36 | O25: -2.51 | P25: -1.02 | Q25: -0.16 | T25: -0.25 | U25: -0.11 | V25: -0.07 | W25: 0.01 | X25: 0.07 | Y25: -0.17089928 | Z25: 0.05 | AA25: 0.03 | AC25: =SUM(X25:AA25) -> -0.020899278
B26: Basic EPS adjusted | M26: =M25/M$87 -> -2.37 | N26: =N25/N$87 -> -3.36 | O26: =O25/O$87 -> -2.51 | P26: =P25/P$87 -> -1.02 | Q26: =Q25/Q$87 -> -0.16 | T26: =T25/T$87 -> -0.25 | U26: =U25/U$87 -> -0.11 | V26: =V25/V$87 -> -0.07 | W26: =W25/W$87 -> 0.01 | X26: =X25/X$87 -> 0.07 | Y26: =Y25/Y$87 -> -0.17089928 | Z26: =Z25/Z$87 -> 0.05 | AA26: =AA25/AA$87 -> 0.03 | AC26: =AC25/AC$87 -> -0.020899278
B27: Diluted EPS | M27: -2.37 | N27: -3.36 | O27: -2.51 | P27: -1.02 | Q27: -0.16 | T27: -0.25 | U27: -0.11 | V27: -0.07 | W27: 0.01 | X27: 0.07 | Y27: -0.16786185 | Z27: 0.05 | AA27: 0.03 | AC27: =SUM(X27:AA27) -> -0.017861847
B28: Diluted EPS adjusted | M28: =M27/M$87 -> -2.37 | N28: =N27/N$87 -> -3.36 | O28: =O27/O$87 -> -2.51 | P28: =P27/P$87 -> -1.02 | Q28: =Q27/Q$87 -> -0.16 | T28: =T27/T$87 -> -0.25 | U28: =U27/U$87 -> -0.11 | V28: =V27/V$87 -> -0.07 | W28: =W27/W$87 -> 0.01 | X28: =X27/X$87 -> 0.07 | Y28: =Y27/Y$87 -> -0.16786185 | Z28: =Z27/Z$87 -> 0.05 | AA28: =AA27/AA$87 -> 0.03 | AC28: =AC27/AC$87 -> -0.017861847
B30: Balance sheet
B31: Cash and cash equivalents | M31: 313812 | N31: 176683 | O31: 87520 | P31: 84220 | Q31: 73830 | T31: 81740 | U31: 84220 | V31: 90871 | W31: 98266 | X31: 106371 | Y31: 73830 | Z31: 74706 | AA31: 72945 | AC31: =AA31 -> 72945
B32: Acc receivable | M32: 40262 | N32: 51394 | O32: 64863 | P32: 73617 | Q32: 97453 | T32: 71408 | U32: 73617 | V32: 75099 | W32: 76842 | X32: 88257 | Y32: 97453 | Z32: 89607 | AA32: 89406 | AC32: =AA32 -> 89406
B33: Inventory | M33: 0 | N33: 0 | O33: 0 | P33: 0 | Q33: 0 | T33: 0 | U33: 0 | V33: 0 | W33: 0 | X33: 0 | Y33: 0 | Z33: 0 | AA33: 0 | AC33: =AA33 -> 0
B34: Current assets | M34: 386349 | N34: 262441 | O34: 195684 | P34: 203285 | Q34: 279843 | T34: 189573 | U34: 203285 | V34: 215409 | W34: 222641 | X34: 240906 | Y34: 279843 | Z34: 267251 | AA34: 253503 | AC34: =AA34 -> 253503
B35: PP&E | M35: =34645+17643 -> 52288 | N35: =21670+35150 -> 56820 | O35: =16902+46139 -> 63041 | P35: =23651+52763 -> 76414 | Q35: =20332+54270 -> 74602 | T35: =25973+51322 -> 77295 | U35: =23651+52763 -> 76414 | V35: =23492+53531 -> 77023 | W35: =22769+53881 -> 76650 | X35: =21111+54093 -> 75204 | Y35: =20332+54270 -> 74602 | Z35: =20568+54624 -> 75192 | AA35: =18122+54127 -> 72249 | AC35: =AA35 -> 72249
B36: Marketable securities and investments | M36: 0 | N36: 0 | O36: 0 | P36: 0 | Q36: 0 | T36: 0 | U36: 0 | V36: 0 | W36: 0 | X36: 0 | Y36: 0 | Z36: 0 | AA36: 0 | AC36: =AA36 -> 0
B37: Goodwill | M37: 33621 | N37: 33736 | O37: 75845 | P37: 75845 | Q37: 170064 | T37: 75845 | U37: 75845 | V37: 75845 | W37: 75845 | X37: 75845 | Y37: 170064 | Z37: 169513 | AA37: 171468 | AC37: =AA37 -> 171468
B38: Long term assets | M38: =M39-M34 -> 108127 | N38: =N39-N34 -> 107616 | O38: =O39-O34 -> 174642 | P38: =P39-P34 -> 185130 | Q38: =Q39-Q34 -> 383947 | T38: =T39-T34 -> 186130 | U38: =U39-U34 -> 185130 | V38: =V39-V34 -> 184986 | W38: =W39-W34 -> 185988 | X38: =X39-X34 -> 182566 | Y38: =Y39-Y34 -> 383947 | Z38: =Z39-Z34 -> 398890 | AA38: =AA39-AA34 -> 393474 | AC38: =AA38 -> 393474
B39: Total assets | M39: 494476 | N39: 370057 | O39: 370326 | P39: 388415 | Q39: 663790 | T39: 375703 | U39: 388415 | V39: 400395 | W39: 408629 | X39: 423472 | Y39: 663790 | Z39: 666141 | AA39: 646977 | AC39: =AA39 -> 646977
B40: Acc payable | M40: 5119 | N40: 10836 | O40: 8480 | P40: 5622 | Q40: 11477 | T40: 15870 | U40: 5622 | V40: 3204 | W40: 6527 | X40: 6218 | Y40: 11477 | Z40: 11891 | AA40: 12237 | AC40: =AA40 -> 12237
B41: Debt | M41: 5821 | N41: 5172 | O41: 6056 | P41: 8043 | Q41: 7971 | T41: 8866 | U41: 8043 | V41: 8348 | W41: 7096 | X41: 6199 | Y41: 7971 | Z41: 5301 | AA41: 5281 | AC41: =AA41 -> 5281
B42: Current liabilities | M42: 68432 | N42: 79039 | O42: 110119 | P42: 114023 | Q42: 183241 | T42: 109201 | U42: 114023 | V42: 110720 | W42: 105135 | X42: 98783 | Y42: 183241 | Z42: 152109 | AA42: 143835 | AC42: =AA42 -> 143835
...

Sheet Analysis ->
H5: Links
H6: Overview'!B3
H7: Financials ->'!B13
H8: Analysis ->'!B13
H9: Forecast ->'!B13
H10: Valuation ->'!B13
B13: Analysis ->

Sheet Basic
B1: TTM/YTD data
B4: Overview | E4: CAGR
B5: Price | C5: =Overview!C5 -> 12.61 | F5: 5Y | G5: 10Y
B6: Market capitalization | C6: =Statement!AC153 -> 816194.86 | E6: Revenue | F6: =IF(Statement!M5<=0,"N/A",_xlfn.RRI(4,Statement!M5,Statement!Q5)) -> 0.22526578 | G6: =IF(Statement!H5<=0,"N/A",_xlfn.RRI(9,Statement!H5,Statement!Q5)) -> N/A
B7: Enterprise value | C7: =Statement!AC154 -> 809695.86 | E7: Net income | F7: =IF(OR(Statement!M20<=0, Statement!Q20<=0), "N/A", _xlfn.RRI(4, Statement!M20, Statement!Q20)) -> N/A | G7: =IF(OR(Statement!H20<=0, Statement!Q20<=0), "N/A", _xlfn.RRI(9, Statement!H20, Statement!Q20)) -> N/A
B8: PE | C8: =Statement!AC150 -> -705.97403 | E8: EPS | F8: =IF(OR(Statement!M28<=0, Statement!Q28<=0), "N/A", _xlfn.RRI(4, Statement!M28, Statement!Q28)) -> N/A | G8: =IF(OR(Statement!H28<=0, Statement!Q28<=0), "N/A", _xlfn.RRI(9, Statement!H28, Statement!Q28)) -> N/A
B9: PS | C9: =Statement!AC151 -> 1.5369177 | E9: Dividend | F9: =IF(Statement!M84<=0,"N/A",_xlfn.RRI(4,Statement!M84,Statement!Q84)) -> N/A | G9: =IF(Statement!H84<=0,"N/A",_xlfn.RRI(9,Statement!H84,Statement!Q84)) -> N/A
B10: PB | C10: =Statement!AC152 -> 2.1049165 | E10: Price | F10: =IF(Statement!M121<=0,"N/A",_xlfn.RRI(4,Statement!M121,Statement!Q121)) -> -0.17103422 | G10: =IF(Statement!H121<=0,"N/A",_xlfn.RRI(9,Statement!H121,Statement!Q121)) -> N/A
B11: EV/Revenue | C11: =Statement!AC155 -> 1.5945392
B12: EV/EBIT | C12: =Statement!AC156 -> 64.574197
B15: Margins | E15: Earnings quality
B16: Gross margin | C16: =Statement!AC105 -> 0.67519048 | E16: Net income | F16: =Statement!AC20 -> -1171
B17: Operating margin | C17: =Statement!AC106 -> 0.024693133 | E17: Operating cash | F17: =Statement!AC61 -> 91379
B18: Net margin | C18: =Statement!AC107 -> -0.0023060578 | E18: Cash accruals | F18: =IF(OR(F16<=0, F17<=0),"N/A",F16-F17) -> N/A
B21: DuPont Identity | E21: Performance indicators
B22: Profit Margin (Earnings/Revenue) | C22: =Statement!AC125 -> -0.0023060578 | E22: ROA | F22: =C24 -> -0.0018099561
B23: Asset Turnover (Revenue/Total assets) | C23: =Statement!AC126 -> 0.78487025 | E23: ROE | F23: =C26 -> -0.0031491108
B24: ROA | C24: =Statement!AC127 -> -0.0018099561 | E24: ROIC | F24: =Statement!AC140 -> -0.014540196
B25: Equity Multiplier (Total assets/Equity) | C25: =Statement!AC128 -> 1.7398824
B26: ROE | C26: =Statement!AC129 -> -0.0031491108
B29: Cash conversion cycle | E29: Liquidity ratios
B30: DSO | C30: =Statement!AC141 -> 64.26475 | E30: Debt/Equity | F30: =Statement!AC145 -> 0.17868985
B31: DIO | C31: =Statement!AC142 -> 0 | E31: Net Debt/Equity | F31: =Statement!AC146 -> -0.01747743
B32: DPO | C32: =Statement!AC143 -> 27.080231 | E32: Current ratio | F32: =Statement!AC148 -> 1.762457
B33: Net trade cycle | C33: =Statement!AC144 -> 37.184518 | E33: Quick ratio | F33: =Statement!AC147 -> 1.1287308
E34: Interest coverage | F34: =Statement!AC149 -> 1.4511052
B37: Earnings yields | E37: Payout ratios
B38: Earnings yield | C38: =Statement!AC162 -> -0.0014164827 | E38: Dividend payout ratio | F38: =Statement!AC168 -> 0
B39: FCF yield | C39: =Statement!AC161 -> 0.0099191999 | E39: Buyback payout ratio | F39: =Statement!AC169 -> 0
B40: Dividend yield | C40: =Statement!AC163 -> 0 | E40: Full payout ratio | F40: =Statement!AC170 -> 0
B41: Buyback yield | C41: =Statement!AC164 -> 0
B42: Total shareholder yield | C42: =Statement!AC165 -> 0
B45: Ownership | E45: Cash holdings
B46: Insider ownership | C46: =Statement!AC171 -> 0.050026265 | E46: Cash per share | F46: =Statement!AC172 -> 1.1751865
E47: Net cash per share | F47: =Statement!AC175 -> 0.10470268
E48: Net cash to market cap | F48: =Statement!AC176 -> 0.0079625593
B51: Stock based compensation | E51: CapEx usage
B52: Stock based compensation % OCF | C52: =Statement!AC173 -> 0.65032447 | E52: Capex to Revenue | F52: =Statement!AC177 -> 0.046981743
B53: Stock based compensation % Revenue | C53: =Statement!AC174 -> 0.117028 | E53: CapEx to OCF | F53: =Statement!AC178 -> 0.26107749
E54: CapEx to D&A | F54: =Statement!AC179 -> 0.64278594

Sheet Yearly Analysis
C2: =Statement!M2 -> 31.01.2022 | D2: =Statement!N2 -> 31.01.2023 | E2: =Statement!O2 -> 31.01.2024 | F2: =Statement!P2 -> 31.01.2025 | G2: =Statement!Q2 -> 31.01.2026
C3: =Statement!M3 -> 2022 | D3: =Statement!N3 -> 2023 | E3: =Statement!O3 -> 2024 | F3: =Statement!P3 -> 2025 | G3: =Statement!Q3 -> 2026 | I3: =Statement!AC3 -> TTM/YTD
B5: Overview
B6: Price | C6: =Statement!M120 -> 28.44 | D6: =Statement!N120 -> 36.19 | E6: =Statement!O120 -> 25.61 | F6: =Statement!P120 -> 29 | G6: =Statement!Q120 -> 13.43 | I6: =Statement!AC120 -> 12.61
B7: Market capitalization | C7: =Statement!M153 -> 1477344.2 | D7: =Statement!N153 -> 1930917.4 | E7: =Statement!O153 -> 1444071.1 | F7: =Statement!P153 -> 1704388 | G7: =Statement!Q153 -> 839630.17 | I7: =Statement!AC153 -> 816194.86
B8: Enterprise value | C8: =Statement!M154 -> 1176776.2 | D8: =Statement!N154 -> 1762131.4 | E8: =Statement!O154 -> 1368007.1 | F8: =Statement!P154 -> 1636361 | G8: =Statement!Q154 -> 865888.17 | I8: =Statement!AC154 -> 809695.86
B9: PE | C9: =Statement!M150 -> -12 | D9: =Statement!N150 -> -10.770833 | E9: =Statement!O150 -> -10.203187 | F9: =Statement!P150 -> -28.431373 | G9: =Statement!Q150 -> -83.9375 | I9: =Statement!AC150 -> -705.97403
B10: PS | C10: =Statement!M151 -> 6.6538234 | D10: =Statement!N151 -> 6.7559133 | E10: =Statement!O151 -> 3.9217264 | F10: =Statement!P151 -> 3.9782236 | G10: =Statement!Q151 -> 1.718463 | I10: =Statement!AC151 -> 1.5369177
B11: PB | C11: =Statement!M152 -> 3.5404147 | D11: =Statement!N152 -> 6.7087908 | E11: =Statement!O152 -> 5.7429979 | F11: =Statement!P152 -> 6.4363161 | G11: =Statement!Q152 -> 2.4200182 | I11: =Statement!AC152 -> 2.1049165
B12: EV/Revenue | C12: =Statement!M155 -> 5.5187342 | D12: =Statement!N155 -> 6.2729396 | E12: =Statement!O155 -> 3.8394917 | F12: =Statement!P155 -> 3.8978331 | G12: =Statement!Q155 -> 1.8017153 | I12: =Statement!AC155 -> 1.5945392
B13: EV/EBIT | C13: =Statement!M156 -> -10.073673 | D13: =Statement!N156 -> -9.9808071 | E13: =Statement!O156 -> -10.023572 | F13: =Statement!P156 -> -28.166015 | G13: =Statement!Q156 -> -130.95707 | I13: =Statement!AC156 -> 64.574197
B15: Margins
B16: Gross margin | C16: =Statement!M105 -> 0.61831424 | D16: =Statement!N105 -> 0.61102488 | E16: =Statement!O105 -> 0.65194682 | F16: =Statement!P105 -> 0.67858547 | G16: =Statement!Q105 -> 0.67930527 | I16: =Statement!AC105 -> 0.67519048
B17: Operating margin | C17: =Statement!M106 -> -0.54783734 | D17: =Statement!N106 -> -0.62850023 | E17: =Statement!O106 -> -0.38304626 | F17: =Statement!P106 -> -0.13838781 | G17: =Statement!Q106 -> -0.01375806 | I17: =Statement!AC106 -> 0.024693133
B18: Net margin | C18: =Statement!M107 -> -0.55414031 | D18: =Statement!N107 -> -0.62705493 | E18: =Statement!O107 -> -0.38418575 | F18: =Statement!P107 -> -0.13941207 | G18: =Statement!Q107 -> -0.019376143 | I18: =Statement!AC107 -> -0.0023060578
B20: Earnings quality
B21: Net income | C21: =Statement!M20 -> -118161 | D21: =Statement!N20 -> -176146 | E21: =Statement!O20 -> -136885 | F21: =Statement!P20 -> -58527 | G21: =Statement!Q20 -> -9312 | I21: =Statement!AC20 -> -1171
B22: Operating cash | C22: =Statement!M61 -> -74710 | D22: =Statement!N61 -> -90123 | E22: =Statement!O61 -> -32378 | F22: =Statement!P61 -> 32381 | G22: =Statement!Q61 -> 78814 | I22: =Statement!AC61 -> 91379
B23: Cash accruals | C23: =IF(OR(C21<=0, C22<=0),"N/A",C21-C22) -> N/A | D23: =IF(OR(D21<=0, D22<=0),"N/A",D21-D22) -> N/A | E23: =IF(OR(E21<=0, E22<=0),"N/A",E21-E22) -> N/A | F23: =IF(OR(F21<=0, F22<=0),"N/A",F21-F22) -> N/A | G23: =IF(OR(G21<=0, G22<=0),"N/A",G21-G22) -> N/A | I23: =IF(OR(I21<=0, I22<=0),"N/A",I21-I22) -> N/A
B25: DuPont Identity
B26: Profit Margin (Earnings/Revenue) | C26: =Statement!M125 -> -0.55414031 | D26: =Statement!N125 -> -0.62705493 | E26: =Statement!O125 -> -0.38418575 | F26: =Statement!P125 -> -0.13941207 | G26: =Statement!Q125 -> -0.019376143 | I26: =Statement!AC125 -> -0.0023060578
B27: Asset Turnover (Revenue/Total assets) | C27: =Statement!M126 -> 0.43123023 | D27: =Statement!N126 -> 0.75909927 | E27: =Statement!O126 -> 0.96212256 | F27: =Statement!P126 -> 1.0808362 | G27: =Statement!Q126 -> 0.72401061 | I27: =Statement!AC126 -> 0.78487025
B28: ROA | C28: =Statement!M127 -> -0.23896205 | D28: =Statement!N127 -> -0.47599694 | E28: =Statement!O127 -> -0.36963378 | F28: =Statement!P127 -> -0.15068162 | G28: =Statement!Q127 -> -0.014028533 | I28: =Statement!AC127 -> -0.0018099561
B29: Equity Multiplier (Total assets/Equity) | C29: =Statement!M128 -> 1.1849981 | D29: =Statement!N128 -> 1.2857282 | E29: =Statement!O128 -> 1.4727678 | F29: =Statement!P128 -> 1.4667797 | G29: =Statement!Q128 -> 1.9684941 | I29: =Statement!AC128 -> 1.7398824
B30: ROE | C30: =Statement!M129 -> -0.28316957 | D30: =Statement!N129 -> -0.61200268 | E30: =Statement!O129 -> -0.54438475 | F30: =Statement!P129 -> -0.22101674 | G30: =Statement!Q129 -> -0.027615085 | I30: =Statement!AC129 -> -0.0031491108
B32: Performance Indicators
B33: ROA | C33: =C28 -> -0.23896205 | D33: =D28 -> -0.47599694 | E33: =E28 -> -0.36963378 | F33: =F28 -> -0.15068162 | G33: =G28 -> -0.014028533 | I33: =I28 -> -0.0018099561
B34: ROE | C34: =C30 -> -0.28316957 | D34: =D30 -> -0.61200268 | E34: =E30 -> -0.54438475 | F34: =F30 -> -0.22101674 | G34: =G30 -> -0.027615085 | I34: =I30 -> -0.0031491108
B35: ROIC | C35: =Statement!M140 -> -1.0008997 | D35: =Statement!N140 -> -1.4832189 | E35: =Statement!O140 -> -0.77816803 | F35: =Statement!P140 -> -0.29523684 | G35: =Statement!Q140 -> -0.018191573 | I35: =Statement!AC140 -> -0.014540196
B37: Cash conversion cycle
B38: DSO | C38: =Statement!M141 -> 68.918179 | D38: =Statement!N141 -> 66.778719 | E38: =Statement!O141 -> 66.446987 | F38: =Statement!P141 -> 64.005176 | G38: =Statement!Q141 -> 74.013756 | I38: =Statement!AC141 -> 64.26475
B39: DIO | C39: =Statement!M142 -> 0 | D39: =Statement!N142 -> 0 | E39: =Statement!O142 -> 0 | F39: =Statement!P142 -> 0 | G39: =Statement!Q142 -> 0 | I39: =Statement!AC142 -> 0
B40: DPO | C40: =Statement!M143 -> 22.957131 | D40: =Statement!N143 -> 36.197022 | E40: =Statement!O143 -> 24.959076 | F40: =Statement!P143 -> 15.207657 | G40: =Statement!Q143 -> 27.180272 | I40: =Statement!AC143 -> 27.080231
B41: Net trade cycle | C41: =Statement!M144 -> 45.961047 | D41: =Statement!N144 -> 30.581697 | E41: =Statement!O144 -> 41.487911 | F41: =Statement!P144 -> 48.797519 | G41: =Statement!Q144 -> 46.833484 | I41: =Statement!AC144 -> 37.184518
B43: Liquidity ratios
B44: Debt/Equity | C44: =Statement!M145 -> 0.03173888 | D44: =Statement!N145 -> 0.027437383 | E44: =Statement!O145 -> 0.045559935 | F44: =Statement!P145 -> 0.061149965 | G44: =Statement!Q145 -> 0.29681472 | I44: =Statement!AC145 -> 0.17868985
B45: Net Debt/Equity | C45: =Statement!M146 -> -0.72030291 | D45: =Statement!N146 -> -0.58643106 | E45: =Statement!O146 -> -0.30250269 | F45: =Statement!P146 -> -0.25689179 | G45: =Statement!Q146 -> 0.077869083 | I45: =Statement!AC146 -> -0.01747743
B46: Quick ratio | C46: =Statement!M147 -> 5.1740998 | D46: =Statement!N147 -> 2.8856261 | E46: =Statement!O147 -> 1.383803 | F46: =Statement!P147 -> 1.3842558 | G46: =Statement!Q147 -> 0.93474168 | I46: =Statement!AC147 -> 1.1287308
B47: Current ratio | C47: =Statement!M148 -> 5.6457359 | D47: =Statement!N148 -> 3.3203988 | E47: =Statement!O148 -> 1.777023 | F47: =Statement!P148 -> 1.7828421 | G47: =Statement!Q148 -> 1.5271855 | I47: =Statement!AC148 -> 1.762457
B48: Interest coverage | C48: =Statement!M149 -> N/A | D48: =Statement!N149 -> N/A | E48: =Statement!O149 -> N/A | F48: =Statement!P149 -> N/A | G48: =Statement!Q149 -> N/A | I48: =Statement!AC149 -> 1.4511052
...

Sheet Quarter analysis
C3: Latest 2 quarters | F3: YoY
C4: =Statement!Z2 -> 30.04.2026 | D4: =Statement!AA2 -> 31.07.2026 | F4: =Statement!W2 -> 31.07.2025 | G4: =Statement!AA2 -> 31.07.2026
B5: Income statement growth | C5: =Statement!Z3 -> Q1 2027 | D5: =Statement!AA3 -> Q2 2027 | F5: =Statement!W3 -> Q2 2026 | G5: =Statement!AA3 -> Q2 2027
B6: Revenue | C6: =Statement!Z5 -> 130935 | D6: =Statement!AA5 -> 129458 | F6: =Statement!W5 -> 117255 | G6: =Statement!AA5 -> 129458
B7: Growth | C7: =Statement!AA91 -> -0.011280406 | F7: =IF(F6=0, IF(G6=0,0,IF(G6>0,1,-1)), (G6-F6)/ABS(F6) ) -> 0.10407232
B8: COGS | C8: =Statement!Z6 -> 43334 | D8: =Statement!AA6 -> 43185 | F8: =Statement!W6 -> 37641 | G8: =Statement!AA6 -> 43185
B9: Growth | C9: =Statement!AA92 -> -0.0034384086 | F9: =IF(F8=0, IF(G8=0,0,IF(G8>0,1,-1)), (G8-F8)/ABS(F8) ) -> 0.1472862
B10: Gross Profit | C10: =Statement!Z7 -> 87601 | D10: =Statement!AA7 -> 86273 | F10: =Statement!W7 -> 79614 | G10: =Statement!AA7 -> 86273
B11: Growth | C11: =Statement!AA93 -> -0.015159644 | F11: =IF(F10=0, IF(G10=0,0,IF(G10>0,1,-1)), (G10-F10)/ABS(F10) ) -> 0.083641068
B12: OpEx | C12: =Statement!Z13 -> 80852 | D12: =Statement!AA13 -> 78665 | F12: =Statement!W13 -> 81121 | G12: =Statement!AA13 -> 78665
B13: Growth | C13: =Statement!AA99 -> -0.027049424 | F13: =IF(F12=0, IF(G12=0,0,IF(G12>0,1,-1)), (G12-F12)/ABS(F12) ) -> -0.030275761
B14: Operating profit | C14: =Statement!Z14 -> 6749 | D14: =Statement!AA14 -> 7608 | F14: =Statement!W14 -> -1507 | G14: =Statement!AA14 -> 7608
B15: Growth | C15: =Statement!AA100 -> 0.12727812 | F15: =IF(F14=0, IF(G14=0,0,IF(G14>0,1,-1)), (G14-F14)/ABS(F14) ) -> 6.0484406
B16: Net income | C16: =Statement!Z20 -> 2963 | D16: =Statement!AA20 -> 1918 | F16: =Statement!W20 -> 654 | G16: =Statement!AA20 -> 1918
B17: Growth | C17: =Statement!AA102 -> -0.35268309 | F17: =IF(F16=0, IF(G16=0,0,IF(G16>0,1,-1)), (G16-F16)/ABS(F16) ) -> 1.9327217
B18: Diluted shares outstanding | C18: =Statement!Z24 -> 62041 | D18: =Statement!AA24 -> 62463 | F18: =Statement!W24 -> 61686 | G18: =Statement!AA24 -> 62463
B19: Growth | C19: =IF(C18=0, IF(D18=0,0,IF(D18>0,1,-1)), (D18-C18)/ABS(C18) ) -> 0.0068019535 | F19: =IF(F18=0, IF(G18=0,0,IF(G18>0,1,-1)), (G18-F18)/ABS(F18) ) -> 0.012596051
B20: Diluted EPS | C20: =Statement!Z28 -> 0.05 | D20: =Statement!AA28 -> 0.03 | F20: =Statement!W28 -> 0.01 | G20: =Statement!AA28 -> 0.03
B21: Growth | C21: =IF(C20=0, IF(D20=0,0,IF(D20>0,1,-1)), (D20-C20)/ABS(C20) ) -> -0.4 | F21: =IF(F20=0, IF(G20=0,0,IF(G20>0,1,-1)), (G20-F20)/ABS(F20) ) -> 2
B23: Revenue breakdown | C23: =C5 -> Q1 2027 | D23: =D5 -> Q2 2027 | F23: =F5 -> Q2 2026 | G23: =G5 -> Q2 2027
B24: =Statement!B193 -> Subscription and related services | C24: =Statement!Z187 -> 52721 | D24: =Statement!AA187 -> 52695 | F24: =Statement!W187 -> 53702 | G24: =Statement!AA187 -> 52695
B25: Growth | C25: =IF(C24=0, IF(D24=0,0,IF(D24>0,1,-1)), (D24-C24)/ABS(C24) ) -> -0.00049316212 | F25: =IF(F24=0, IF(G24=0,0,IF(G24>0,1,-1)), (G24-F24)/ABS(F24) ) -> -0.018751629
B26: =Statement!B194 -> Payment solutions | C26: =Statement!Z188 -> 41941 | D26: =Statement!AA188 -> 38489 | F26: =Statement!W188 -> 28392 | G26: =Statement!AA188 -> 38489
B27: Growth | C27: =IF(C26=0, IF(D26=0,0,IF(D26>0,1,-1)), (D26-C26)/ABS(C26) ) -> -0.082306097 | F27: =IF(F26=0, IF(G26=0,0,IF(G26>0,1,-1)), (G26-F26)/ABS(F26) ) -> 0.35562835
B28: =Statement!B195 -> Network solutions | C28: =Statement!Z189 -> 36273 | D28: =Statement!AA189 -> 38274 | F28: =Statement!W189 -> 35161 | G28: =Statement!AA189 -> 38274
B29: Growth | C29: =IF(C28=0, IF(D28=0,0,IF(D28>0,1,-1)), (D28-C28)/ABS(C28) ) -> 0.055164999 | F29: =IF(F28=0, IF(G28=0,0,IF(G28>0,1,-1)), (G28-F28)/ABS(F28) ) -> 0.088535593
B31: Metrics growth | C31: =C5 -> Q1 2027 | D31: =D5 -> Q2 2027 | F31: =F5 -> Q2 2026 | G31: =G5 -> Q2 2027
B32: =Statement!B209 -> AHSC | C32: =Statement!Z209 -> 4708 | D32: =Statement!AA209 -> 4744 | F32: =Statement!W209 -> 4467 | G32: =Statement!AA209 -> 4744
B33: Growth | C33: =IF(C32=0, IF(D32=0,0,IF(D32>0,1,-1)), (D32-C32)/ABS(C32) ) -> 0.007646559 | F33: =IF(F32=0, IF(G32=0,0,IF(G32>0,1,-1)), (G32-F32)/ABS(F32) ) -> 0.062010298
B34: =Statement!B210 -> Avg subscription revenue per AHSC | C34: =Statement!Z210 -> 11.198173 | D34: =Statement!AA210 -> 11.107715 | F34: =Statement!W210 -> 12.021939 | G34: =Statement!AA210 -> 11.107715
B35: Growth | C35: =IF(C34=0, IF(D34=0,0,IF(D34>0,1,-1)), (D34-C34)/ABS(C34) ) -> -0.0080779526 | F35: =IF(F34=0, IF(G34=0,0,IF(G34>0,1,-1)), (G34-F34)/ABS(F34) ) -> -0.076046275

Sheet Graphs Year
C55: =Statement!H2 -> 0 | D55: =Statement!I2 -> 0 | E55: =Statement!J2 -> 0 | F55: =Statement!K2 -> 0 | G55: =Statement!L2 -> 0 | H55: =Statement!M2 -> 31.01.2022 | I55: =Statement!N2 -> 31.01.2023 | J55: =Statement!O2 -> 31.01.2024 | ... L55: =Statement!Q2 -> 31.01.2026
C56: =Statement!H3 -> 0 | D56: =Statement!I3 -> 0 | E56: =Statement!J3 -> 0 | F56: =Statement!K3 -> 0 | G56: =Statement!L3 -> 0 | H56: =Statement!M3 -> 2022 | I56: =Statement!N3 -> 2023 | J56: =Statement!O3 -> 2024 | ... L56: =Statement!Q3 -> 2026
B57: Revenue | C57: =Statement!H5 -> 0 | D57: =Statement!I5 -> 0 | E57: =Statement!J5 -> 0 | F57: =Statement!K5 -> 0 | G57: =Statement!L5 -> 0 | H57: =Statement!M5 -> 213233 | I57: =Statement!N5 -> 280910 | J57: =Statement!O5 -> 356299 | ... L57: =Statement!Q5 -> 480591
B58: Operating income | C58: =Statement!H14 -> 0 | D58: =Statement!I14 -> 0 | E58: =Statement!J14 -> 0 | F58: =Statement!K14 -> 0 | G58: =Statement!L14 -> 0 | H58: =Statement!M14 -> -116817 | I58: =Statement!N14 -> -176552 | J58: =Statement!O14 -> -136479 | ... L58: =Statement!Q14 -> -6612
B59: Net income | C59: =Statement!H20 -> 0 | D59: =Statement!I20 -> 0 | E59: =Statement!J20 -> 0 | F59: =Statement!K20 -> 0 | G59: =Statement!L20 -> 0 | H59: =Statement!M20 -> -118161 | I59: =Statement!N20 -> -176146 | J59: =Statement!O20 -> -136885 | ... L59: =Statement!Q20 -> -9312
B60: FCFE | C60: =Statement!H157 -> 0 | D60: =Statement!I157 -> 0 | E60: =Statement!J157 -> 0 | F60: =Statement!K157 -> 0 | G60: =Statement!L157 -> 0 | H60: =Statement!M157 -> -141659 | I60: =Statement!N157 -> -175101 | J60: =Statement!O157 -> -129088 | ... L60: =Statement!Q157 -> -13035
B61: FCFF | C61: =Statement!H158 -> 0 | D61: =Statement!I158 -> 0 | E61: =Statement!J158 -> 0 | F61: =Statement!K158 -> 0 | G61: =Statement!L158 -> 0 | H61: =Statement!M158 -> -144891 | I61: =Statement!N158 -> -181313 | J61: =Statement!O158 -> -133726 | ... L61: =Statement!Q158 -> -13646
B62: Gross margin | C62: =Statement!H105 -> 0 | D62: =Statement!I105 -> 0 | E62: =Statement!J105 -> 0 | F62: =Statement!K105 -> 0 | G62: =Statement!L105 -> 0 | H62: =Statement!M105 -> 0.61831424 | I62: =Statement!N105 -> 0.61102488 | J62: =Statement!O105 -> 0.65194682 | ... L62: =Statement!Q105 -> 0.67930527
B63: Operating margin | C63: =Statement!H106 -> 0 | D63: =Statement!I106 -> 0 | E63: =Statement!J106 -> 0 | F63: =Statement!K106 -> 0 | G63: =Statement!L106 -> 0 | H63: =Statement!M106 -> -0.54783734 | I63: =Statement!N106 -> -0.62850023 | J63: =Statement!O106 -> -0.38304626 | ... L63: =Statement!Q106 -> -0.01375806
B64: Net margin | C64: =Statement!H107 -> 0 | D64: =Statement!I107 -> 0 | E64: =Statement!J107 -> 0 | F64: =Statement!K107 -> 0 | G64: =Statement!L107 -> 0 | H64: =Statement!M107 -> -0.55414031 | I64: =Statement!N107 -> -0.62705493 | J64: =Statement!O107 -> -0.38418575 | ... L64: =Statement!Q107 -> -0.019376143
B65: ="Revenue "&Statement!B193 -> Revenue Subscription and related services | C65: =Statement!H187 -> 0 | D65: =Statement!I187 -> 0 | E65: =Statement!J187 -> 0 | F65: =Statement!K187 -> 0 | G65: =Statement!L187 -> 0 | H65: =Statement!M187 -> 95514 | I65: =Statement!N187 -> 128975 | J65: =Statement!O187 -> 165436 | ... L65: =Statement!Q187 -> 219461
B66: ="Revenue "&Statement!B194 -> Revenue Payment solutions | C66: =Statement!H188 -> 0 | D66: =Statement!I188 -> 0 | E66: =Statement!J188 -> 0 | F66: =Statement!K188 -> 0 | G66: =Statement!L188 -> 0 | H66: =Statement!M188 -> 65201 | I66: =Statement!N188 -> 78368 | J66: =Statement!O188 -> 94610 | ... L66: =Statement!Q188 -> 121459
B67: ="Revenue "&Statement!B195 -> Revenue Network solutions | C67: =Statement!H189 -> 0 | D67: =Statement!I189 -> 0 | E67: =Statement!J189 -> 0 | F67: =Statement!K189 -> 0 | G67: =Statement!L189 -> 0 | H67: =Statement!M189 -> 52518 | I67: =Statement!N189 -> 73567 | J67: =Statement!O189 -> 96253 | ... L67: =Statement!Q189 -> 139671
B68: ROA | C68: =Statement!H127 -> 0 | D68: =Statement!I127 -> 0 | E68: =Statement!J127 -> 0 | F68: =Statement!K127 -> 0 | G68: =Statement!L127 -> 0 | H68: =Statement!M127 -> -0.23896205 | I68: =Statement!N127 -> -0.47599694 | J68: =Statement!O127 -> -0.36963378 | ... L68: =Statement!Q127 -> -0.014028533
B69: ROE | C69: =Statement!H129 -> 0 | D69: =Statement!I129 -> 0 | E69: =Statement!J129 -> 0 | F69: =Statement!K129 -> 0 | G69: =Statement!L129 -> 0 | H69: =Statement!M129 -> -0.28316957 | I69: =Statement!N129 -> -0.61200268 | J69: =Statement!O129 -> -0.54438475 | ... L69: =Statement!Q129 -> -0.027615085
B70: ROIC | C70: =Statement!H140 -> 0 | D70: =Statement!I140 -> 0 | E70: =Statement!J140 -> 0 | F70: =Statement!K140 -> 0 | G70: =Statement!L140 -> 0 | H70: =Statement!M140 -> -1.0008997 | I70: =Statement!N140 -> -1.4832189 | J70: =Statement!O140 -> -0.77816803 | ... L70: =Statement!Q140 -> -0.018191573
B71: Price 5y | C71: =Statement!H203 -> 0 | D71: =Statement!I203 -> 0 | E71: =Statement!J203 -> 0 | F71: =Statement!K203 -> 0 | G71: =Statement!L203 -> 0 | H71: =Statement!M203 -> 100 | I71: =Statement!N203 -> 127.25035 | J71: =Statement!O203 -> 90.049226 | ... L71: =Statement!Q203 -> 47.222222
B72: Revenue 5y | C72: =Statement!H204 -> 0 | D72: =Statement!I204 -> 0 | E72: =Statement!J204 -> 0 | F72: =Statement!K204 -> 0 | G72: =Statement!L204 -> 0 | H72: =Statement!M204 -> 100 | I72: =Statement!N204 -> 131.73852 | J72: =Statement!O204 -> 167.09374 | ... L72: =Statement!Q204 -> 225.38303
B73: EPS 5y | C73: =Statement!H205 -> 0 | D73: =Statement!I205 -> 0 | E73: =Statement!J205 -> 0 | F73: =Statement!K205 -> 0 | G73: =Statement!L205 -> 0 | H73: =Statement!M205 -> 100 | I73: =Statement!N205 -> 58.227848 | J73: =Statement!O205 -> 94.092827 | ... L73: =Statement!Q205 -> 193.24895

Sheet Graphs Quarter
C55: =Statement!T2 -> 31.10.2024 | D55: =Statement!U2 -> 31.01.2025 | E55: =Statement!V2 -> 30.04.2025 | F55: =Statement!W2 -> 31.07.2025 | G55: =Statement!X2 -> 31.10.2025 | H55: =Statement!Y2 -> 31.01.2026 | I55: =Statement!Z2 -> 30.04.2026 | J55: =Statement!AA2 -> 31.07.2026
C56: =Statement!T3 -> Q3 2025 | D56: =Statement!U3 -> Q4 2025 | E56: =Statement!V3 -> Q1 2026 | F56: =Statement!W3 -> Q2 2026 | G56: =Statement!X3 -> Q3 2026 | H56: =Statement!Y3 -> Q4 2026 | I56: =Statement!Z3 -> Q1 2027 | J56: =Statement!AA3 -> Q2 2027
B57: Revenue | C57: =Statement!T5 -> 106800 | D57: =Statement!U5 -> 109681 | E57: =Statement!V5 -> 115936 | F57: =Statement!W5 -> 117255 | G57: =Statement!X5 -> 120333 | H57: =Statement!Y5 -> 127067 | I57: =Statement!Z5 -> 130935 | J57: =Statement!AA5 -> 129458
B58: Operating income | C58: =Statement!T14 -> -13843 | D58: =Statement!U14 -> -7612 | E58: =Statement!V14 -> -3287 | F58: =Statement!W14 -> -1507 | G58: =Statement!X14 -> 3739 | H58: =Statement!Y14 -> -5557 | I58: =Statement!Z14 -> 6749 | J58: =Statement!AA14 -> 7608
B59: Net income | C59: =Statement!T20 -> -14403 | D59: =Statement!U20 -> -6390 | E59: =Statement!V20 -> -3914 | F59: =Statement!W20 -> 654 | G59: =Statement!X20 -> 4271 | H59: =Statement!Y20 -> -10323 | I59: =Statement!Z20 -> 2963 | J59: =Statement!AA20 -> 1918
B60: Gross margin | C60: =Statement!T105 -> 0.67661985 | D60: =Statement!U105 -> 0.69396705 | E60: =Statement!V105 -> 0.6716723 | F60: =Statement!W105 -> 0.67898171 | G60: =Statement!X105 -> 0.68398527 | H60: =Statement!Y105 -> 0.6821362 | I60: =Statement!Z105 -> 0.66904189 | J60: =Statement!AA105 -> 0.66641691
B61: Operating margin | C61: =Statement!T106 -> -0.1296161 | D61: =Statement!U106 -> -0.069401264 | E61: =Statement!V106 -> -0.028351849 | F61: =Statement!W106 -> -0.01285233 | G61: =Statement!X106 -> 0.031072108 | H61: =Statement!Y106 -> -0.043732834 | I61: =Statement!Z106 -> 0.05154466 | J61: =Statement!AA106 -> 0.058768095
B62: Net margin | C62: =Statement!T107 -> -0.13485955 | D62: =Statement!U107 -> -0.058259863 | E62: =Statement!V107 -> -0.033760006 | F62: =Statement!W107 -> 0.0055775873 | G62: =Statement!X107 -> 0.035493173 | H62: =Statement!Y107 -> -0.081240605 | I62: =Statement!Z107 -> 0.022629549 | J62: =Statement!AA107 -> 0.014815616
B63: ="Revenue "&Statement!B193 -> Revenue Subscription and related services | C63: =Statement!T187 -> 49363 | D63: =Statement!U187 -> 51793 | E63: =Statement!V187 -> 54355 | F63: =Statement!W187 -> 53702 | G63: =Statement!X187 -> 55480 | H63: =Statement!Y187 -> 55924 | I63: =Statement!Z187 -> 52721 | J63: =Statement!AA187 -> 52695
B64: ="Revenue "&Statement!B194 -> Revenue Payment solutions | C64: =Statement!T188 -> 24704 | D64: =Statement!U188 -> 24676 | E64: =Statement!V188 -> 29925 | F64: =Statement!W188 -> 28392 | G64: =Statement!X188 -> 27422 | H64: =Statement!Y188 -> 35720 | I64: =Statement!Z188 -> 41941 | J64: =Statement!AA188 -> 38489
B65: ="Revenue "&Statement!B195 -> Revenue Network solutions | C65: =Statement!T189 -> 32733 | D65: =Statement!U189 -> 33212 | E65: =Statement!V189 -> 31656 | F65: =Statement!W189 -> 35161 | G65: =Statement!X189 -> 37431 | H65: =Statement!Y189 -> 35423 | I65: =Statement!Z189 -> 36273 | J65: =Statement!AA189 -> 38274
B66: FCFE | C66: =Statement!T157 -> -14922 | D66: =Statement!U157 -> -7964 | E66: =Statement!V157 -> -9767 | F66: =Statement!W157 -> -6597 | G66: =Statement!X157 -> -7158 | H66: =Statement!Y157 -> 10487 | I66: =Statement!Z157 -> 2818 | J66: =Statement!AA157 -> 1949

Sheet Forecast ->
H5: Links
H6: Overview'!B3
H7: Financials ->'!B13
H8: Analysis ->'!B13
H9: Forecast ->'!B13
H10: Valuation ->'!B13
B13: Forecast ->

Sheet Revenue
B1: Revenue forecast
C2: History | H2: Forecast | S2: History | AA2: Forecast | AE2: TTM
C4: Revenues | S4: Revenues
B5: Revenues (thousand) | C5: =Statement!M3 -> 2022 | D5: =Statement!N3 -> 2023 | E5: =Statement!O3 -> 2024 | F5: =Statement!P3 -> 2025 | G5: =Statement!Q3 -> 2026 | H5: =G5+1 -> 2027 | I5: =H5+1 -> 2028 | J5: =I5+1 -> 2029 | K5: =J5+1 -> 2030 | L5: =K5+1 -> 2031 | R5: =B5 -> Revenues (thousand) | S5: =Statement!T3 -> Q3 2025 | T5: =Statement!U3 -> Q4 2025 | U5: =Statement!V3 -> Q1 2026 | V5: =Statement!W3 -> Q2 2026 | W5: =Statement!X3 -> Q3 2026 | X5: =Statement!Y3 -> Q4 2026 | Y5: =Statement!Z3 -> Q1 2027 | Z5: =Statement!AA3 -> Q2 2027 | AA5: FQ1 | AB5: FQ2 | AC5: FQ3 | AE5: FQ1
B6: =Statement!B187 -> Subscription and related services | C6: =Statement!M187 -> 95514 | D6: =Statement!N187 -> 128975 | E6: =Statement!O187 -> 165436 | F6: =Statement!P187 -> 196510 | G6: =Statement!Q187 -> 219461 | H6: =H25*H27 -> 236161.98 | I6: =I25*I27 -> 255285.2 | J6: =J25*J27 -> 274214.6 | K6: =K25*K27 -> 304652.42 | L6: =L25*L27 -> 346328.87 | N6: AHSC * avg sub revenue per AHSC | Q6: AHSC * avg sub revenue per AHSC | R6: =B6 -> Subscription and related services | S6: =Statement!T187 -> 49363 | T6: =Statement!U187 -> 51793 | U6: =Statement!V187 -> 54355 | V6: =Statement!W187 -> 53702 | W6: =Statement!X187 -> 55480 | X6: =Statement!Y187 -> 55924 | Y6: =Statement!Z187 -> 52721 | Z6: =Statement!AA187 -> 52695 | AA6: =AA25*AA27 -> 52689.731 | AE6: =SUM(X6:AA6) -> 214029.73
B7: =Statement!B188 -> Payment solutions | C7: =Statement!M188 -> 65201 | D7: =Statement!N188 -> 78368 | E7: =Statement!O188 -> 94610 | F7: =Statement!P188 -> 101740 | G7: =Statement!Q188 -> 121459 | H7: =H21*H23*H24 -> 132935.44 | I7: =I21*I23*I24 -> 139763.93 | J7: =J21*J23*J24 -> 148905.4 | K7: =K21*K23*K24 -> 159800.92 | L7: =L21*L23*L24 -> 171621.91 | N7: pacient payment volume * facilitator * take rate | Q7: pacient payment volume * facilitator * take rate | R7: =B7 -> Payment solutions | S7: =Statement!T188 -> 24704 | T7: =Statement!U188 -> 24676 | U7: =Statement!V188 -> 29925 | V7: =Statement!W188 -> 28392 | W7: =Statement!X188 -> 27422 | X7: =Statement!Y188 -> 35720 | Y7: =Statement!Z188 -> 41941 | Z7: =Statement!AA188 -> 38489 | AA7: =AA21*AA24 -> 37398 | AE7: =SUM(X7:AA7) -> 153548
B8: =Statement!B189 -> Network solutions | C8: =Statement!M189 -> 52518 | D8: =Statement!N189 -> 73567 | E8: =Statement!O189 -> 96253 | F8: =Statement!P189 -> 121563 | G8: =Statement!Q189 -> 139671 | H8: =H29*H33 -> 142906.53 | I8: =I29*I33 -> 149029.79 | J8: =J29*J33 -> 168084.37 | K8: =K29*K33 -> 205674.75 | L8: =L29*L33 -> 268479.6 | N8: annual patient visits * revenue per visit | Q8: network solutions per AHSC * AHSC | R8: =B8 -> Network solutions | S8: =Statement!T189 -> 32733 | T8: =Statement!U189 -> 33212 | U8: =Statement!V189 -> 31656 | V8: =Statement!W189 -> 35161 | W8: =Statement!X189 -> 37431 | X8: =Statement!Y189 -> 35423 | Y8: =Statement!Z189 -> 36273 | Z8: =Statement!AA189 -> 38274 | AA8: =AA25*AA29 -> 37497.038 | AE8: =SUM(X8:AA8) -> 147467.04
B9: Total | C9: =Statement!M5 -> 213233 | D9: =Statement!N5 -> 280910 | E9: =Statement!O5 -> 356299 | F9: =Statement!P5 -> 419813 | G9: =Statement!Q5 -> 480591 | H9: =SUM(H6:H8) -> 512003.95 | I9: =SUM(I6:I8) -> 544078.91 | J9: =SUM(J6:J8) -> 591204.37 | K9: =SUM(K6:K8) -> 670128.09 | L9: =SUM(L6:L8) -> 786430.37 | R9: Total | S9: =Statement!T5 -> 106800 | T9: =Statement!U5 -> 109681 | U9: =Statement!V5 -> 115936 | V9: =Statement!W5 -> 117255 | W9: =Statement!X5 -> 120333 | X9: =Statement!Y5 -> 127067 | Y9: =Statement!Z5 -> 130935 | Z9: =Statement!AA5 -> 129458 | AA9: =SUM(AA6:AA8) -> 127584.77 | AE9: =SUM(X9:AA9) -> 515044.77
C11: Growth rates | S11: Growth rates
B12: Revenue growth % | C12: =C5 -> 2022 | D12: =D5 -> 2023 | E12: =E5 -> 2024 | F12: =F5 -> 2025 | G12: =G5 -> 2026 | H12: =H5 -> 2027 | I12: =I5 -> 2028 | J12: =J5 -> 2029 | ... L12: =L5 -> 2031 | R12: Revenue growth % | S12: =S5 -> Q3 2025 | T12: =T5 -> Q4 2025 | U12: =U5 -> Q1 2026 | V12: =V5 -> Q2 2026 | W12: =W5 -> Q3 2026 | X12: =X5 -> Q4 2026 | Y12: =Y5 -> Q1 2027 | Z12: =Z5 -> Q2 2027 | ... AC12: =AC5 -> FQ3
B13: =B6 -> Subscription and related services | D13: =D6/C6-1 -> 0.35032561 | E13: =E6/D6-1 -> 0.2826982 | F13: =F6/E6-1 -> 0.18783094 | G13: =G6/F6-1 -> 0.11679304 | H13: =H6/G6-1 -> 0.0761 | I13: =I6/H6-1 -> 0.080975 | J13: =J6/I6-1 -> 0.07415 | K13: =K6/J6-1 -> 0.111 | L13: =L6/K6-1 -> 0.1368 | R13: =R6 -> Subscription and related services | T13: =T6/S6-1 -> 0.049227154 | U13: =U6/T6-1 -> 0.049466144 | V13: =V6/U6-1 -> -0.012013614 | W13: =W6/V6-1 -> 0.033108637 | X13: =X6/W6-1 -> 0.0080028839 | Y13: =Y6/X6-1 -> -0.057274158 | Z13: =Z6/Y6-1 -> -0.00049316212 | AA13: =AA6/Z6-1 -> -0.0001
B14: =B7 -> Payment solutions | D14: =D7/C7-1 -> 0.20194476 | E14: =E7/D7-1 -> 0.20725296 | F14: =F7/E7-1 -> 0.075362012 | G14: =G7/F7-1 -> 0.19381757 | H14: =H7/G7-1 -> 0.094488181 | I14: =I7/H7-1 -> 0.051366935 | J14: =J7/I7-1 -> 0.065406556 | K14: =K7/J7-1 -> 0.073170732 | L14: =L7/K7-1 -> 0.073973214 | R14: =R7 -> Payment solutions | T14: =T7/S7-1 -> -0.0011334197 | U14: =U7/T7-1 -> 0.21271681 | V14: =V7/U7-1 -> -0.05122807 | W14: =W7/V7-1 -> -0.034164553 | X14: =X7/W7-1 -> 0.30260375 | Y14: =Y7/X7-1 -> 0.17416013 | Z14: =Z7/Y7-1 -> -0.082306097 | AA14: =AA7/Z7-1 -> -0.028345761
B15: =B8 -> Network solutions | D15: =D8/C8-1 -> 0.40079592 | E15: =E8/D8-1 -> 0.30837196 | F15: =F8/E8-1 -> 0.26295284 | G15: =G8/F8-1 -> 0.1489598 | H15: =H8/G8-1 -> 0.023165375 | I15: =I8/H8-1 -> 0.042848 | J15: =J8/I8-1 -> 0.1278575 | K15: =K8/J8-1 -> 0.22364 | L15: =L8/K8-1 -> 0.30536 | R15: =R8 -> Network solutions | T15: =T8/S8-1 -> 0.01463355 | U15: =U8/T8-1 -> -0.046850536 | V15: =V8/U8-1 -> 0.11072151 | W15: =W8/V8-1 -> 0.064560166 | X15: =X8/W8-1 -> -0.053645374 | Y15: =Y8/X8-1 -> 0.023995709 | Z15: =Z8/Y8-1 -> 0.055164999 | AA15: =AA8/Z8-1 -> -0.0203
B16: =B9 -> Total | D16: =D9/C9-1 -> 0.31738521 | E16: =E9/D9-1 -> 0.26837421 | F16: =F9/E9-1 -> 0.17826039 | G16: =G9/F9-1 -> 0.14477398 | H16: =H9/G9-1 -> 0.065363174 | I16: =I9/H9-1 -> 0.062645926 | J16: =J9/I9-1 -> 0.086615102 | K16: =K9/J9-1 -> 0.13349652 | L16: =L9/K9-1 -> 0.17355231 | R16: =R9 -> Total | T16: =T9/S9-1 -> 0.026975655 | U16: =U9/T9-1 -> 0.057029021 | V16: =V9/U9-1 -> 0.011376967 | W16: =W9/V9-1 -> 0.02625048 | X16: =X9/W9-1 -> 0.055961374 | Y16: =Y9/X9-1 -> 0.030440634 | Z16: =Z9/Y9-1 -> -0.011280406 | AA16: =AA9/Z9-1 -> -0.014469803
C19: Drivers and metrics | S19: Drivers and metrics | AE19: =AE4 -> 0
B20: Metric (thousand) | C20: =C5 -> 2022 | D20: =D5 -> 2023 | E20: =E5 -> 2024 | F20: =F5 -> 2025 | G20: =G5 -> 2026 | H20: =H5 -> 2027 | I20: =I5 -> 2028 | J20: =J5 -> 2029 | ... L20: =L5 -> 2031 | R20: Metric (thousand) | S20: =S5 -> Q3 2025 | T20: =T5 -> Q4 2025 | U20: =U5 -> Q1 2026 | V20: =V5 -> Q2 2026 | W20: =W5 -> Q3 2026 | X20: =X5 -> Q4 2026 | Y20: =Y5 -> Q1 2027 | Z20: =Z5 -> Q2 2027 | ... AC20: =AC5 -> FQ3 | AE20: =AE5 -> FQ1
B21: Patient payment volume | C21: =Statement!M211 -> 2768000 | D21: =Statement!N211 -> 3284000 | E21: =Statement!O211 -> 3947000 | F21: =Statement!P211 -> 4420000 | G21: =Statement!Q211 -> 4873000 | H21: =G21*(1+H22) -> 5360300 | I21: =H21*(1+I22) -> 5949933 | J21: =I21*(1+J22) -> 6485427 | K21: =J21*(1+K22) -> 7133969.7 | L21: =K21*(1+L22) -> 7847366.6 | N21: Patient payment volume growth | Q21: Patient payment volume growth | R21: Patient payment volume | S21: =Statement!T211 -> 1081000 | T21: =Statement!U211 -> 1080000 | U21: =Statement!V211 -> 1314000 | V21: =Statement!W211 -> 1250000 | W21: =Statement!X211 -> 1181000 | X21: =Statement!Y211 -> 1128000 | Y21: =Statement!Z211 -> 1786000 | Z21: =Statement!AA211 -> 1626000 | AA21: =Z21*(1+AA22) -> 1626000 | AE21: =SUM(X21:AA21) -> 6166000
B22: Patient payment volume growth | D22: =(D21-C21)/C21 -> 0.18641618 | E22: =(E21-D21)/D21 -> 0.20188794 | F22: =(F21-E21)/E21 -> 0.11983785 | G22: =(G21-F21)/F21 -> 0.10248869 | H22: 0.1 | I22: 0.11 | J22: 0.09 | K22: 0.1 | L22: 0.1 | R22: Patient payment volume growth | T22: =(T21-S21)/S21 -> -0.00092506938 | U22: =(U21-T21)/T21 -> 0.21666667 | V22: =(V21-U21)/U21 -> -0.04870624 | W22: =(W21-V21)/V21 -> -0.0552 | X22: =(X21-W21)/W21 -> -0.044877223 | Y22: =(Y21-X21)/X21 -> 0.58333333 | Z22: =(Z21-Y21)/Y21 -> -0.089585666 | AA22: 0
B23: Payment facilitator volume | C23: =Statement!M212 -> 0.79 | D23: =Statement!N212 -> 0.8 | E23: =Statement!O212 -> 0.82 | F23: =Statement!P212 -> 0.81 | G23: =Statement!Q212 -> 0.83 | H23: 0.8 | I23: 0.81 | J23: 0.82 | K23: 0.8 | L23: 0.81 | R23: Payment facilitator volume | S23: =Statement!T212 -> 0.81 | T23: =Statement!U212 -> 0.82 | U23: =Statement!V212 -> 0.82 | V23: =Statement!W212 -> 0.82 | W23: =Statement!X212 -> 0.85 | X23: =Statement!Y212 -> 0.84 | Y23: =Statement!Z212 -> 0 | Z23: =Statement!AA212 -> 0 | AA23: 0 | AE23: =AA23 -> 0
B24: Take rate | C24: =Statement!M213 -> 0.0298 | D24: =Statement!N213 -> 0.0298 | E24: =Statement!O213 -> 0.0292 | F24: =Statement!P213 -> 0.0283 | G24: =Statement!Q213 -> 0.030029991 | H24: 0.031 | I24: 0.029 | J24: 0.028 | K24: 0.028 | L24: 0.027 | R24: Take rate | S24: =Statement!T213 -> 0.028 | T24: =Statement!U213 -> 0.028 | U24: =Statement!V213 -> 0.028 | V24: =Statement!W213 -> 0.028 | W24: =Statement!X213 -> 0.027 | X24: =Statement!Y213 -> 0.037698413 | Y24: =Statement!Z213 -> 0.023 | Z24: =Statement!AA213 -> 0.024 | AA24: 0.023
B25: AHSC | C25: =Statement!M209 -> 2074 | D25: =Statement!N209 -> 2856 | E25: =Statement!O209 -> 3601 | F25: =Statement!P209 -> 4203 | G25: =Statement!Q209 -> 4514 | H25: =G25*(1+H26) -> 4762.27 | I25: =H25*(1+I26) -> 5071.8175 | J25: =I25*(1+J26) -> 5502.922 | K25: =J25*(1+K26) -> 6053.2142 | L25: =K25*(1+L26) -> 6779.6 | N25: AHSC growth | Q25: AHSC growth | R25: AHSC | S25: =Statement!T209 -> 4237 | T25: =Statement!U209 -> 4341 | U25: =Statement!V209 -> 4411 | V25: =Statement!W209 -> 4467 | W25: =Statement!X209 -> 4520 | X25: =Statement!Y209 -> 4658 | Y25: =Statement!Z209 -> 4708 | Z25: =Statement!AA209 -> 4744 | AA25: =Z25*(1+AA26) -> 4791.44 | AE25: =AA25 -> 4791.44
B26: AHSC Growth | D26: =(D25-C25)/C25 -> 0.37704918 | E26: =(E25-D25)/D25 -> 0.26085434 | F26: =(F25-E25)/E25 -> 0.16717578 | G26: =(G25-F25)/F25 -> 0.073994766 | H26: 0.055 | I26: 0.065 | J26: 0.085 | K26: 0.1 | L26: 0.12 | R26: AHSC Growth | T26: =(T25-S25)/S25 -> 0.024545669 | U26: =(U25-T25)/T25 -> 0.016125317 | V26: =(V25-U25)/U25 -> 0.012695534 | W26: =(W25-V25)/V25 -> 0.011864786 | X26: =(X25-W25)/W25 -> 0.030530973 | Y26: =(Y25-X25)/X25 -> 0.010734221 | Z26: =(Z25-Y25)/Y25 -> 0.007646559 | AA26: 0.01
B27: Avg subscription revenue per AHSC | C27: =Statement!M210 -> 46.053038 | D27: =Statement!N210 -> 45.159314 | E27: =Statement!O210 -> 45.941683 | F27: =Statement!P210 -> 46.754699 | G27: =Statement!Q210 -> 48.617856 | H27: =G27*(1+H28) -> 49.590213 | I27: =H27*(1+I28) -> 50.334066 | J27: =I27*(1+J28) -> 49.830725 | K27: =J27*(1+K28) -> 50.329032 | L27: =K27*(1+L28) -> 51.083968 | N27: Avg revenue per AHSC growth | Q27: Avg revenue per AHSC growth | R27: Avg subscription revenue per AHSC | S27: =Statement!T210 -> 11.65046 | T27: =Statement!U210 -> 11.931122 | U27: =Statement!V210 -> 12.322603 | V27: =Statement!W210 -> 12.021939 | W27: =Statement!X210 -> 12.274336 | X27: =Statement!Y210 -> 12.006011 | Y27: =Statement!Z210 -> 11.198173 | Z27: =Statement!AA210 -> 11.107715 | AA27: =Z27*(1+AA28) -> 10.996638 | AE27: =SUM(X27:AA27) -> 45.308537
B28: Avg revenue AHSC growth | D28: =(D27-C27)/C27 -> -0.019406405 | E28: =(E27-D27)/D27 -> 0.017324646 | F28: =(F27-E27)/E27 -> 0.0176967 | G28: =(G27-F27)/F27 -> 0.03984961 | H28: 0.02 | I28: 0.015 | J28: -0.01 | K28: 0.01 | L28: 0.015 | R28: Avg revenue AHSC growth | T28: =(T27-S27)/S27 -> 0.024090175 | U28: =(U27-T27)/T27 -> 0.032811728 | V28: =(V27-U27)/U27 -> -0.024399385 | W28: =(W27-V27)/V27 -> 0.020994752 | X28: =(X27-W27)/W27 -> -0.021860662 | Y28: =(Y27-X27)/X27 -> -0.067286114 | Z28: =(Z27-Y27)/Y27 -> -0.0080779526 | AA28: -0.01
B29: Annual patient visits | D29: =Statement!N214 -> 120000 | E29: =Statement!O214 -> 150000 | F29: =Statement!P214 -> 170000 | G29: =Statement!Q214 -> 180000 | H29: =H25*H31 -> 183253.5 | I29: =I25*I31 -> 187358.38 | J29: =J25*J31 -> 201251 | K29: =K25*K31 -> 228017.39 | L29: =L25*L31 -> 268148.45 | N29: AHSC * patient visit per AHSC | Q29: Network revenue per AHSC growth | R29: Network solutions revenue per AHSC | S29: =Statement!T217 -> 7.7255133 | T29: =Statement!U217 -> 7.6507717 | U29: =Statement!V217 -> 7.1766039 | V29: =Statement!W217 -> 7.8712783 | W29: =Statement!X217 -> 8.2811947 | X29: =Statement!Y217 -> 7.604766 | Y29: =Statement!Z217 -> 7.7045455 | Z29: =Statement!AA217 -> 8.0678752 | AA29: =Z29*(1+AA30) -> 7.825839 | AE29: =SUM(X29:AA29) -> 31.203026
B30: Annual patient visits growth | E30: =(E29-D29)/D29 -> 0.25 | F30: =(F29-E29)/E29 -> 0.13333333 | G30: =(G29-F29)/F29 -> 0.058823529 | H30: =(H29-G29)/G29 -> 0.018075 | I30: =(I29-H29)/H29 -> 0.0224 | J30: =(J29-I29)/I29 -> 0.07415 | K30: =(K29-J29)/J29 -> 0.133 | L30: =(L29-K29)/K29 -> 0.176 | R30: Nw solutions revenue growth | T30: =(T29-S29)/S29 -> -0.0096746482 | U30: =(U29-T29)/T29 -> -0.061976463 | V30: =(V29-U29)/U29 -> 0.096797082 | W30: =(W29-V29)/V29 -> 0.052077492 | X30: =(X29-W29)/W29 -> -0.081682501 | Y30: =(Y29-X29)/X29 -> 0.013120648 | Z30: =(Z29-Y29)/Y29 -> 0.047157844 | AA30: -0.03
B31: Patient visits per AHSC | D31: =Statement!N215 -> 42.016807 | E31: =Statement!O215 -> 41.655096 | F31: =Statement!P215 -> 40.4473 | G31: =Statement!Q215 -> 39.875942 | H31: =G31*(1+H32) -> 38.480284 | I31: =H31*(1+I32) -> 36.941072 | J31: =I31*(1+J32) -> 36.571661 | K31: =J31*(1+K32) -> 37.668811 | L31: =K31*(1+L32) -> 39.552252 | N31: Patient visit per AHSC growth
B32: Patient visit per AHSC growth | E32: =(E31-D31)/D31 -> -0.0086087198 | F32: =(F31-E31)/E31 -> -0.028995162 | G32: =(G31-F31)/F31 -> -0.014125987 | H32: -0.035 | I32: -0.04 | J32: -0.01 | K32: 0.03 | L32: 0.05
B33: Revenue per visit | D33: =Statement!N216 -> 0.61305833 | E33: =Statement!O216 -> 0.64168667 | F33: =Statement!P216 -> 0.71507647 | G33: =Statement!Q216 -> 0.77595 | H33: =G33*(1+H34) -> 0.77982975 | I33: =H33*(1+I34) -> 0.79542634 | J33: =I33*(1+J34) -> 0.83519766 | K33: =J33*(1+K34) -> 0.90201348 | L33: =K33*(1+L34) -> 1.001235 | N33: Revenue per visit growth
B34: Revenue per visit growth | E34: =(E33-D33)/D33 -> 0.046697568 | F34: =(F33-E33)/E33 -> 0.11437016 | G34: =(G33-F33)/F33 -> 0.085128699 | H34: 0.005 | I34: 0.02 | J34: 0.05 | K34: 0.08 | L34: 0.11

Sheet COGS & OpEx
B1: COGS & OpEx forecast
C2: History | H2: Forecast | P2: History | X2: Forecast | AB2: TTM
C4: Revenues | P4: Revenues
B5: =Revenue!B5 -> Revenues (thousand) | C5: =Revenue!C5 -> 2022 | D5: =Revenue!D5 -> 2023 | E5: =Revenue!E5 -> 2024 | F5: =Revenue!F5 -> 2025 | G5: =Revenue!G5 -> 2026 | H5: =G5+1 -> 2027 | I5: =H5+1 -> 2028 | J5: =I5+1 -> 2029 | K5: =J5+1 -> 2030 | L5: =K5+1 -> 2031 | O5: Revenues (thousand) | P5: =Revenue!S5 -> Q3 2025 | Q5: =Revenue!T5 -> Q4 2025 | R5: =Revenue!U5 -> Q1 2026 | S5: =Revenue!V5 -> Q2 2026 | T5: =Revenue!W5 -> Q3 2026 | U5: =Revenue!X5 -> Q4 2026 | V5: =Revenue!Y5 -> Q1 2027 | W5: =Revenue!Z5 -> Q2 2027 | X5: FQ1 | Y5: FQ2 | Z5: FQ3 | AB5: =Revenue!AE5 -> FQ1
B6: Revenue | C6: =Revenue!C9 -> 213233 | D6: =Revenue!D9 -> 280910 | E6: =Revenue!E9 -> 356299 | F6: =Revenue!F9 -> 419813 | G6: =Revenue!G9 -> 480591 | H6: =Revenue!H9 -> 512003.95 | I6: =Revenue!I9 -> 544078.91 | J6: =Revenue!J9 -> 591204.37 | ... L6: =Revenue!L9 -> 786430.37 | O6: Revenue | P6: =Revenue!S9 -> 106800 | Q6: =Revenue!T9 -> 109681 | R6: =Revenue!U9 -> 115936 | S6: =Revenue!V9 -> 117255 | T6: =Revenue!W9 -> 120333 | U6: =Revenue!X9 -> 127067 | V6: =Revenue!Y9 -> 130935 | W6: =Revenue!Z9 -> 129458 | X6: =Revenue!AA9 -> 127584.77 | AB6: =Revenue!AE9 -> 515044.77
C9: COGS and OpEx | P9: COGS & OpEx | AB9: =AB4 -> 0
B10: Expenses (tnousand) | C10: =C5 -> 2022 | D10: =D5 -> 2023 | E10: =E5 -> 2024 | F10: =F5 -> 2025 | G10: =G5 -> 2026 | H10: =H5 -> 2027 | I10: =I5 -> 2028 | J10: =J5 -> 2029 | ... L10: =L5 -> 2031 | O10: Expenses (thousand) | P10: =P5 -> Q3 2025 | Q10: =Q5 -> Q4 2025 | R10: =R5 -> Q1 2026 | S10: =S5 -> Q2 2026 | T10: =T5 -> Q3 2026 | U10: =U5 -> Q4 2026 | V10: =V5 -> Q1 2027 | W10: =W5 -> Q2 2027 | ... Z10: =Z5 -> FQ3 | AB10: =AB5 -> FQ1
B11: COGS | C11: =Statement!M6 -> 81388 | D11: =Statement!N6 -> 109267 | E11: =Statement!O6 -> 124011 | F11: =Statement!P6 -> 134934 | G11: =Statement!Q6 -> 154123 | H11: =H6*H22 -> 158721.23 | I11: =I6*I22 -> 157782.89 | J11: =J6*J22 -> 165537.22 | K11: =K6*K22 -> 187635.87 | L11: =L6*L22 -> 228064.81 | O11: =B11 -> COGS | P11: =Statement!T6 -> 34537 | Q11: =Statement!U6 -> 33566 | R11: =Statement!V6 -> 38065 | S11: =Statement!W6 -> 37641 | T11: =Statement!X6 -> 38027 | U11: =Statement!Y6 -> 40390 | V11: =Statement!Z6 -> 43334 | W11: =Statement!AA6 -> 43185 | X11: =X6*X22 -> 40827.126 | AB11: =SUM(U11:X11) -> 167736.13
B12: =Statement!B8 -> Sales and marketing | C12: =Statement!M8 -> 106421 | D12: =Statement!N8 -> 151263 | E12: =Statement!O8 -> 147008 | F12: =Statement!P8 -> 121129 | G12: =Statement!Q8 -> 100243 | H12: =H6*H23 -> 107520.83 | I12: =I6*I23 -> 119697.36 | J12: =J6*J23 -> 124152.92 | K12: =K6*K23 -> 134025.62 | L12: =L6*L23 -> 157286.07 | O12: =B12 -> Sales and marketing | P12: =Statement!T8 -> 30071 | Q12: =Statement!U8 -> 28863 | R12: =Statement!V8 -> 26043 | S12: =Statement!W8 -> 25396 | T12: =Statement!X8 -> 24148 | U12: =Statement!Y8 -> 24656 | V12: =Statement!Z8 -> 24209 | W12: =Statement!AA8 -> 24587 | X12: =X23*X$6 -> 24241.106 | AB12: =SUM(U12:X12) -> 97693.106
B13: =Statement!B9 -> R&D | C13: =Statement!M9 -> 52265 | D13: =Statement!N9 -> 91244 | E13: =Statement!O9 -> 112346 | F13: =Statement!P9 -> 117364 | G13: =Statement!Q9 -> 121481 | H13: =H6*H24 -> 133121.03 | I13: =I6*I24 -> 141460.52 | J13: =J6*J24 -> 147801.09 | K13: =K6*K24 -> 147428.18 | L13: =L6*L24 -> 165150.38 | O13: =B13 -> R&D | P13: =Statement!T9 -> 29315 | Q13: =Statement!U9 -> 29626 | R13: =Statement!V9 -> 31829 | S13: =Statement!W9 -> 29274 | T13: =Statement!X9 -> 29453 | U13: =Statement!Y9 -> 30925 | V13: =Statement!Z9 -> 28328 | W13: =Statement!AA9 -> 27571 | X13: =X24*X$6 -> 29344.497 | AB13: =SUM(U13:X13) -> 116168.5
B14: =Statement!B10 -> General and administrative | C14: =Statement!M10 -> 68674 | D14: =Statement!N10 -> 80384 | E14: =Statement!O10 -> 79926 | F14: =Statement!P10 -> 76597 | G14: =Statement!Q10 -> 79903 | H14: =H6*H25 -> 79360.613 | I14: =I6*I25 -> 89228.942 | J14: =J6*J25 -> 94592.699 | K14: =K6*K25 -> 113921.78 | L14: =L6*L25 -> 125828.86 | O14: =B14 -> General and administrative | P14: =Statement!T10 -> 19633 | Q14: =Statement!U10 -> 18415 | R14: =Statement!V10 -> 16408 | S14: =Statement!W10 -> 19042 | T14: =Statement!X10 -> 17488 | U14: =Statement!Y10 -> 26965 | V14: =Statement!Z10 -> 18361 | W14: =Statement!AA10 -> 16512 | X14: =X25*X$6 -> 21689.411 | AB14: =SUM(U14:X14) -> 83527.411
B15: =Statement!B11 -> Depreciation | C15: =Statement!M11 -> 14985 | D15: =Statement!N11 -> 17988 | E15: =Statement!O11 -> 17584 | F15: =Statement!P11 -> 14183 | G15: =Statement!Q11 -> 12972 | H15: =H6*H26 -> 12288.095 | I15: =I6*I26 -> 13601.973 | J15: =J6*J26 -> 13597.7 | K15: =K6*K26 -> 13402.562 | L15: =L6*L26 -> 13369.316 | O15: =B15 -> Depreciation | P15: =Statement!T11 -> 3566 | Q15: =Statement!U11 -> 3172 | R15: =Statement!V11 -> 2986 | S15: =Statement!W11 -> 3279 | T15: =Statement!X11 -> 3199 | U15: =Statement!Y11 -> 3508 | V15: =Statement!Z11 -> 3371 | W15: =Statement!AA11 -> 3340 | X15: =X6*X26 -> 3827.543 | AB15: =SUM(U15:X15) -> 14046.543
