Workbook

Sheet Overview
B2: Ticker | C2: SN
B3: Price | C3: =[1]Sheet1!$C$9 -> 115.49
B7: Units | C7: K
B9: Market cap | C9: =C3*'Statement Q'!J18 -> 16301529
B10: Net debt | C10: =(Statements!R40+Statements!R42+Statements!R43)-Statements!R23 -> 99831
B11: EV | C11: =C9+Overview!C10 -> 16401360
B13: PE | C13: =C3/'Statement Q'!N21 -> 23.394508
B14: PS | C14: =C3/('Statement Q'!N5/'Statement Q'!N19) -> 2.5641221
B16: Notes
B17: 10-K for SN are 20-F
B18: 10-Q for SN are 6-K
B19: Proxy for SN are 6-K

Sheet Statement Y
B2: Date | C2: 31.12.2021 | D2: 31.12.2022 | E2: 31.12.2023 | F2: 31.12.2024 | G2: 31.12.2025
B3: FY | C3: 2021 | D3: =C3+1 -> 2022 | E3: =D3+1 -> 2023 | F3: =E3+1 -> 2024 | G3: =F3+1 -> 2025 | H3: =G3+1 -> 2026 | I3: =H3+1 -> 2027 | J3: =I3+1 -> 2028 | K3: =J3+1 -> 2029
B4: Income statement
B5: Revenue | C5: 3726994 | D5: 3717366 | E5: 4253710 | F5: 5528639 | G5: 6399188
B6: COGS | C6: 2288810 | D6: 2307172 | E6: 2345858 | F6: 2866648 | G6: 3262698
B7: Gross Profit | C7: =C5-C6 -> 1438184 | D7: =D5-D6 -> 1410194 | E7: =E5-E6 -> 1907852 | F7: =F5-F6 -> 2661991 | G7: =G5-G6 -> 3136490 | H7: =H5-H6 -> 0 | I7: =I5-I6 -> 0 | J7: =J5-J6 -> 0 | K7: =K5-K6 -> 0
B8: R&D | C8: 200641 | D8: 215660 | E8: 249387 | F8: 341289 | G8: 368073
B9: Sales and marketing | C9: 619162 | D9: 621953 | E9: 897585 | F9: 1243145 | G9: 1458027
B10: General and administrative | C10: 180124 | D10: 251207 | E10: 387316 | F10: 433395 | G10: 390109
B11: OpEx | C11: =SUM(C8:C10) -> 999927 | D11: =SUM(D8:D10) -> 1088820 | E11: =SUM(E8:E10) -> 1534288 | F11: =SUM(F8:F10) -> 2017829 | G11: =SUM(G8:G10) -> 2216209 | H11: =SUM(H8:H10) -> 0 | I11: =SUM(I8:I10) -> 0 | J11: =SUM(J8:J10) -> 0 | K11: =SUM(K8:K10) -> 0
B12: Operating income | C12: 438257 | D12: 321374 | E12: 373564 | F12: 644162 | G12: 920281
B13: Interest income/expense | C13: -16287 | D13: -27021 | E13: -44909 | F13: -63715 | G13: -48600
B14: Other income/expense | C14: -7644 | D14: 7631 | E14: -35427 | F14: -7980 | G14: 28597
B15: Income before taxes | C15: 414326 | D15: 301984 | E15: 293228 | F15: 572467 | G15: 900278
B16: Income tax expense/benefit | C16: -83213 | D16: -69630 | E16: -126150 | F16: -133762 | G16: -198904
B17: Net income | C17: 331113 | D17: 232354 | E17: 167078 | F17: 438705 | G17: 701374
B18: Basic Shares outstanding avg | C18: 138983 | D18: 138983 | E18: 139026 | F18: 139936 | G18: 140984
B19: Diluted Shares outstanding avg | C19: 138983 | D19: 138983 | E19: 139420 | F19: 141084 | G19: 142090
B20: Basic EPS | C20: 2.38 | D20: 1.67 | E20: 1.2 | F20: 3.14 | G20: 4.97
B21: Diluted EPS | C21: 2.38 | D21: 1.67 | E21: 1.2 | F21: 3.11 | G21: 4.94
B23: Balance sheet
B24: Cash and cash equivalents | D24: 192890 | E24: 154061 | F24: 363669 | G24: 777289
B25: Restricted cash | D25: 25880 | E25: 0 | F25: 0 | G25: 0
B26: Acc receivable | D26: 766503 | E26: 985172 | F26: 1266595 | G26: 1667143
B27: Inventories | D27: 548588 | E27: 699740 | F27: 899989 | G27: 1002205
B28: Prepaid expenses & Other current | D28: 181831 | E28: 58311 | F28: 114008 | G28: 164628
B29: Current assets | D29: 1715692 | E29: 1897284 | F29: 2644261 | G29: 3611265
B30: PP&E | D30: 137341 | E30: 166252 | F30: 211464 | G30: 232226
B31: Operating lease right of use | D31: 67321 | E31: 63333 | F31: 146257 | G31: 142487
B32: Intangible assets | D32: 492709 | E32: 477816 | F32: 462678 | G32: 451137
B33: Goodwill | D33: 840148 | E33: 834203 | F33: 834781 | G33: 834781
B34: Deferred tax assets | D34: 6291 | E34: 12 | F34: 43093 | G34: 10706
B35: Other assets | D35: 35389 | E35: 48170 | F35: 51625 | G35: 66832
B36: Long term assets | C36: =SUM(C30:C35) -> 0 | D36: =SUM(D30:D35) -> 1579199 | E36: =SUM(E30:E35) -> 1589786 | F36: =SUM(F30:F35) -> 1749898 | G36: =SUM(G30:G35) -> 1738169 | H36: =SUM(H30:H35) -> 0 | I36: =SUM(I30:I35) -> 0 | J36: =SUM(J30:J35) -> 0 | K36: =SUM(K30:K35) -> 0
B37: Total assets | D37: 3294891 | E37: 3487070 | F37: 4394159 | G37: 5349434
B38: Acc payable | D38: 328122 | E38: 459651 | F38: 612031 | G38: 679534
B39: Accrued expenses | D39: 552023 | E39: 620333 | F39: 841529 | G39: 1016645
B40: Tax payable | D40: 1581 | E40: 20991 | F40: 36548 | G40: 38092
B41: Current portion long term debt | D41: 86972 | E41: 24157 | F41: 39344 | G41: 39344
B42: Current liabilities | D42: 968698 | E42: 1125132 | F42: 1529452 | G42: 1773615
...

Sheet Statement Q
B2: Date | C2: 31.03.2024 | D2: 30.06.2024 | E2: 30.09.2024 | F2: 31.12.2024 | G2: 31.03.2025 | H2: 30.06.2025 | I2: 30.09.2025 | J2: 31.12.2025
B3: Q | C3: Q1 2024 | D3: Q2 2024 | E3: Q3 2024 | F3: Q4 2024 | G3: Q1 2025 | H3: Q2 2025 | I3: Q3 2025 | J3: Q4 2025 | P3: =I3 -> Q3 2025 | Q3: =J3 -> Q4 2025 | R3: Growth Rate
B4: Income statement | N4: TTM | P4: Quarter compare
B5: Revenue | C5: 1066228 | D5: 1248658 | E5: 1426566 | F5: 1787187 | G5: 1222638 | H5: 1444876 | I5: 1630240 | J5: 2101434 | N5: =SUM(G5:J5) -> 6399188 | P5: =I5 -> 1630240 | Q5: =J5 -> 2101434 | R5: =IF(P5=0, IF(Q5=0,0,IF(Q5>0,1,-1)), (Q5-P5)/ABS(P5) ) -> 0.28903352
B6: COGS | C6: 539611 | D6: 647759 | E6: 731559 | F6: 947719 | G6: 619412 | H6: 736709 | I6: 812771 | J6: 1093806 | N6: =SUM(G6:J6) -> 3262698 | P6: =I6 -> 812771 | Q6: =J6 -> 1093806 | R6: =IF(P6=0, IF(Q6=0,0,IF(Q6>0,1,-1)), (Q6-P6)/ABS(P6) ) -> 0.3457739
B7: Gross Profit | C7: =C5-C6 -> 526617 | D7: =D5-D6 -> 600899 | E7: =E5-E6 -> 695007 | F7: =F5-F6 -> 839468 | G7: =G5-G6 -> 603226 | H7: =H5-H6 -> 708167 | I7: =I5-I6 -> 817469 | J7: =J5-J6 -> 1007628 | N7: =SUM(G7:J7) -> 3136490 | P7: =I7 -> 817469 | Q7: =J7 -> 1007628 | R7: =IF(P7=0, IF(Q7=0,0,IF(Q7>0,1,-1)), (Q7-P7)/ABS(P7) ) -> 0.23261922
B8: R&D | C8: 69596 | D8: 90053 | E8: 94808 | F8: 86832 | G8: 87603 | H8: 89409 | I8: 92826 | J8: 98235 | N8: =SUM(G8:J8) -> 368073 | P8: =I8 -> 92826 | Q8: =J8 -> 98235 | R8: =IF(P8=0, IF(Q8=0,0,IF(Q8>0,1,-1)), (Q8-P8)/ABS(P8) ) -> 0.058270312
B9: Sales and marketing | C9: 214568 | D9: 303185 | E9: 300841 | F9: 424551 | G9: 275737 | H9: 357720 | I9: 365919 | J9: 458651 | N9: =SUM(G9:J9) -> 1458027 | P9: =I9 -> 365919 | Q9: =J9 -> 458651 | R9: =IF(P9=0, IF(Q9=0,0,IF(Q9>0,1,-1)), (Q9-P9)/ABS(P9) ) -> 0.25342221
B10: General and administrative | C10: 87511 | D10: 103825 | E10: 119096 | F10: 122963 | G10: 94940 | H10: 92391 | I10: 95833 | J10: 106945 | N10: =SUM(G10:J10) -> 390109 | P10: =I10 -> 95833 | Q10: =J10 -> 106945 | R10: =IF(P10=0, IF(Q10=0,0,IF(Q10>0,1,-1)), (Q10-P10)/ABS(P10) ) -> 0.11595171
B11: OpEx | C11: =SUM(C8:C10) -> 371675 | D11: =SUM(D8:D10) -> 497063 | E11: =SUM(E8:E10) -> 514745 | F11: =SUM(F8:F10) -> 634346 | G11: =SUM(G8:G10) -> 458280 | H11: =SUM(H8:H10) -> 539520 | I11: =SUM(I8:I10) -> 554578 | J11: =SUM(J8:J10) -> 663831 | N11: =SUM(G11:J11) -> 2216209 | P11: =I11 -> 554578 | Q11: =J11 -> 663831 | R11: =IF(P11=0, IF(Q11=0,0,IF(Q11>0,1,-1)), (Q11-P11)/ABS(P11) ) -> 0.19700204
B12: Operating income | C12: 154942 | D12: 103836 | E12: 180262 | F12: 205122 | G12: 144946 | H12: 168647 | I12: 262891 | J12: 343797 | N12: =SUM(G12:J12) -> 920281 | P12: =I12 -> 262891 | Q12: =J12 -> 343797 | R12: =IF(P12=0, IF(Q12=0,0,IF(Q12>0,1,-1)), (Q12-P12)/ABS(P12) ) -> 0.30775493
B13: Interest income/expense | C13: -14722 | D13: -14844 | E13: -16916 | F13: -17233 | G13: -12629 | H13: -13765 | I13: -12782 | J13: -9424 | N13: =SUM(G13:J13) -> -48600 | P13: =I13 -> -12782 | Q13: =J13 -> -9424 | R13: =IF(P13=0, IF(Q13=0,0,IF(Q13>0,1,-1)), (Q13-P13)/ABS(P13) ) -> 0.26271319
B14: Other income/expense | C14: 3248 | D14: 689 | E14: 11031 | F14: -22948 | G14: 13216 | H14: 26003 | I14: -6116 | J14: -4506 | N14: =SUM(G14:J14) -> 28597 | P14: =I14 -> -6116 | Q14: =J14 -> -4506 | R14: =IF(P14=0, IF(Q14=0,0,IF(Q14>0,1,-1)), (Q14-P14)/ABS(P14) ) -> 0.26324395
B15: Income before taxes | C15: 143468 | D15: 89681 | E15: 174377 | F15: 164941 | G15: 145533 | H15: 180885 | I15: 243993 | J15: 329867 | N15: =SUM(G15:J15) -> 900278 | P15: =I15 -> 243993 | Q15: =J15 -> 329867 | R15: =IF(P15=0, IF(Q15=0,0,IF(Q15>0,1,-1)), (Q15-P15)/ABS(P15) ) -> 0.35195272
B16: Income tax expense/benefit | C16: -33856 | D16: -21633 | E16: -42048 | F16: -36225 | G16: -27698 | H16: -41287 | I16: -55264 | J16: -74655 | N16: =SUM(G16:J16) -> -198904 | P16: =I16 -> -55264 | Q16: =J16 -> -74655 | R16: =IF(P16=0, IF(Q16=0,0,IF(Q16>0,1,-1)), (Q16-P16)/ABS(P16) ) -> -0.35087942
B17: Net income | C17: 109612 | D17: 68048 | E17: 132329 | F17: 128716 | G17: 117835 | H17: 139598 | I17: 188729 | J17: 255212 | N17: =SUM(G17:J17) -> 701374 | P17: =I17 -> 188729 | Q17: =J17 -> 255212 | R17: =IF(P17=0, IF(Q17=0,0,IF(Q17>0,1,-1)), (Q17-P17)/ABS(P17) ) -> 0.35226701
B18: Basic Shares outstanding avg | C18: 139449 | D18: 139888 | E18: 140114 | F18: 140285 | G18: 140622 | H18: 141044 | I18: 141112 | J18: 141151 | N18: =AVERAGE(G18:J18) -> 140982.25 | P18: =I18 -> 141112 | Q18: =J18 -> 141151 | R18: =IF(P18=0, IF(Q18=0,0,IF(Q18>0,1,-1)), (Q18-P18)/ABS(P18) ) -> 0.00027637621
B19: Diluted Shares outstanding avg | C19: 140703 | D19: 140924 | E19: 141306 | F19: 141518 | G19: 142183 | H19: 141871 | I19: 142119 | J19: 142129 | N19: =AVERAGE((G19:J19)) -> 142075.5 | P19: =I19 -> 142119 | Q19: =J19 -> 142129 | R19: =IF(P19=0, IF(Q19=0,0,IF(Q19>0,1,-1)), (Q19-P19)/ABS(P19) ) -> 7.0363569e-05
B20: Basic EPS | C20: 0.79 | D20: 0.49 | E20: 0.94 | F20: 0.92 | G20: 0.84 | H20: 0.99 | I20: 1.34 | J20: 1.81 | N20: =N17/N18 -> 4.97491 | P20: =I20 -> 1.34 | Q20: =J20 -> 1.81 | R20: =IF(P20=0, IF(Q20=0,0,IF(Q20>0,1,-1)), (Q20-P20)/ABS(P20) ) -> 0.35074627
B21: Diluted EPS | C21: 0.78 | D21: 0.48 | E21: 0.94 | F21: 0.91 | G21: 0.83 | H21: 0.98 | I21: 1.33 | J21: 1.8 | N21: =N17/N19 -> 4.9366288 | P21: =I21 -> 1.33 | Q21: =J21 -> 1.8 | R21: =IF(P21=0, IF(Q21=0,0,IF(Q21>0,1,-1)), (Q21-P21)/ABS(P21) ) -> 0.35338346
B23: Balance sheet
B24: Cash and cash equivalents | F24: 363669 | G24: 224696 | H24: 188229 | I24: 263816 | J24: 777289
B25: Restricted cash | F25: 0 | G25: 0 | H25: 0 | I25: 0 | J25: 0
B26: Acc receivable | F26: 1266595 | G26: 1040635 | H26: 1324984 | I26: 1595180 | J26: 1667143
B27: Inventories | F27: 899989 | G27: 973198 | H27: 1052711 | I27: 1158345 | J27: 1002205
B28: Prepaid expenses & Other current | F28: 114008 | G28: 157521 | H28: 190586 | I28: 226561 | J28: 164628
B29: Current assets | F29: 2644261 | G29: 2396050 | H29: 2756510 | I29: 3243902 | J29: 3611265
B30: PP&E | F30: 211464 | G30: 221700 | H30: 212771 | I30: 214693 | J30: 232226
B31: Operating lease right of use | F31: 146257 | G31: 143479 | H31: 140714 | I31: 147707 | J31: 142487
B32: Intangible assets | F32: 462678 | G32: 459539 | H32: 457536 | I32: 454477 | J32: 451137
B33: Goodwill | F33: 834781 | G33: 834781 | H33: 834781 | I33: 834781 | J33: 834781
B34: Deferred tax assets | F34: 43093 | G34: 58628 | H34: 73721 | I34: 10943 | J34: 10706
B35: Other assets | F35: 51625 | G35: 61225 | H35: 63224 | I35: 68469 | J35: 66832
B36: Long term assets | C36: =SUM(C30:C35) -> 0 | D36: =SUM(D30:D35) -> 0 | E36: =SUM(E30:E35) -> 0 | F36: =SUM(F30:F35) -> 1749898 | G36: =SUM(G30:G35) -> 1779352 | H36: =SUM(H30:H35) -> 1782747 | I36: =SUM(I30:I35) -> 1731070 | J36: =SUM(J30:J35) -> 1738169
B37: Total assets | F37: 4394159 | G37: 4175402 | H37: 4539257 | I37: 4974972 | J37: 5349434
B38: Acc payable | F38: 612031 | G38: 462495 | H38: 582560 | I38: 681808 | J38: 679534
B39: Accrued expenses | F39: 841529 | G39: 641667 | H39: 766630 | I39: 892459 | J39: 1016645
B40: Tax payable | F40: 36548 | G40: 70487 | H40: 29992 | I40: 43941 | J40: 38092
B41: Current portion long term debt | F41: 39344 | G41: 39344 | H41: 39344 | I41: 39344 | J41: 39344
B42: Current liabilities | F42: 1529452 | G42: 1213993 | H42: 1418526 | I42: 1657631 | J42: 1773615
...

Sheet Statements
B2: Date | C2: ='Statement Y'!C2 -> 31.12.2021 | D2: ='Statement Y'!D2 -> 31.12.2022 | E2: ='Statement Y'!E2 -> 31.12.2023 | F2: ='Statement Y'!F2 -> 31.12.2024 | G2: ='Statement Y'!G2 -> 31.12.2025 | I2: ='Statement Q'!C2 -> 31.03.2024 | J2: ='Statement Q'!D2 -> 30.06.2024 | K2: ='Statement Q'!E2 -> 30.09.2024 | L2: ='Statement Q'!F2 -> 31.12.2024 | M2: ='Statement Q'!G2 -> 31.03.2025 | N2: ='Statement Q'!H2 -> 30.06.2025 | O2: ='Statement Q'!I2 -> 30.09.2025 | P2: ='Statement Q'!J2 -> 31.12.2025
B3: FY | C3: ='Statement Y'!C3 -> 2021 | D3: ='Statement Y'!D3 -> 2022 | E3: ='Statement Y'!E3 -> 2023 | F3: ='Statement Y'!F3 -> 2024 | G3: ='Statement Y'!G3 -> 2025 | I3: ='Statement Q'!C3 -> Q1 2024 | J3: ='Statement Q'!D3 -> Q2 2024 | K3: ='Statement Q'!E3 -> Q3 2024 | L3: ='Statement Q'!F3 -> Q4 2024 | M3: ='Statement Q'!G3 -> Q1 2025 | N3: ='Statement Q'!H3 -> Q2 2025 | O3: ='Statement Q'!I3 -> Q3 2025 | P3: ='Statement Q'!J3 -> Q4 2025 | R3: TTM
B4: Income statement
B5: Revenue | C5: ='Statement Y'!C5 -> 3726994 | D5: ='Statement Y'!D5 -> 3717366 | E5: ='Statement Y'!E5 -> 4253710 | F5: ='Statement Y'!F5 -> 5528639 | G5: ='Statement Y'!G5 -> 6399188 | I5: ='Statement Q'!C5 -> 1066228 | J5: ='Statement Q'!D5 -> 1248658 | K5: ='Statement Q'!E5 -> 1426566 | L5: ='Statement Q'!F5 -> 1787187 | M5: ='Statement Q'!G5 -> 1222638 | N5: ='Statement Q'!H5 -> 1444876 | O5: ='Statement Q'!I5 -> 1630240 | P5: ='Statement Q'!J5 -> 2101434 | R5: =SUM(M5:P5) -> 6399188
B6: COGS | C6: ='Statement Y'!C6 -> 2288810 | D6: ='Statement Y'!D6 -> 2307172 | E6: ='Statement Y'!E6 -> 2345858 | F6: ='Statement Y'!F6 -> 2866648 | G6: ='Statement Y'!G6 -> 3262698 | I6: ='Statement Q'!C6 -> 539611 | J6: ='Statement Q'!D6 -> 647759 | K6: ='Statement Q'!E6 -> 731559 | L6: ='Statement Q'!F6 -> 947719 | M6: ='Statement Q'!G6 -> 619412 | N6: ='Statement Q'!H6 -> 736709 | O6: ='Statement Q'!I6 -> 812771 | P6: ='Statement Q'!J6 -> 1093806 | R6: =SUM(M6:P6) -> 3262698
B7: Gross Profit | C7: ='Statement Y'!C7 -> 1438184 | D7: ='Statement Y'!D7 -> 1410194 | E7: ='Statement Y'!E7 -> 1907852 | F7: ='Statement Y'!F7 -> 2661991 | G7: ='Statement Y'!G7 -> 3136490 | I7: ='Statement Q'!C7 -> 526617 | J7: ='Statement Q'!D7 -> 600899 | K7: ='Statement Q'!E7 -> 695007 | L7: ='Statement Q'!F7 -> 839468 | M7: ='Statement Q'!G7 -> 603226 | N7: ='Statement Q'!H7 -> 708167 | O7: ='Statement Q'!I7 -> 817469 | P7: ='Statement Q'!J7 -> 1007628 | R7: =SUM(M7:P7) -> 3136490
B8: R&D | C8: ='Statement Y'!C8 -> 200641 | D8: ='Statement Y'!D8 -> 215660 | E8: ='Statement Y'!E8 -> 249387 | F8: ='Statement Y'!F8 -> 341289 | G8: ='Statement Y'!G8 -> 368073 | I8: ='Statement Q'!C8 -> 69596 | J8: ='Statement Q'!D8 -> 90053 | K8: ='Statement Q'!E8 -> 94808 | L8: ='Statement Q'!F8 -> 86832 | M8: ='Statement Q'!G8 -> 87603 | N8: ='Statement Q'!H8 -> 89409 | O8: ='Statement Q'!I8 -> 92826 | P8: ='Statement Q'!J8 -> 98235 | R8: =SUM(M8:P8) -> 368073
B9: Sales and marketing | C9: ='Statement Y'!C9 -> 619162 | D9: ='Statement Y'!D9 -> 621953 | E9: ='Statement Y'!E9 -> 897585 | F9: ='Statement Y'!F9 -> 1243145 | G9: ='Statement Y'!G9 -> 1458027 | I9: ='Statement Q'!C9 -> 214568 | J9: ='Statement Q'!D9 -> 303185 | K9: ='Statement Q'!E9 -> 300841 | L9: ='Statement Q'!F9 -> 424551 | M9: ='Statement Q'!G9 -> 275737 | N9: ='Statement Q'!H9 -> 357720 | O9: ='Statement Q'!I9 -> 365919 | P9: ='Statement Q'!J9 -> 458651 | R9: =SUM(M9:P9) -> 1458027
B10: General and administrative | C10: ='Statement Y'!C10 -> 180124 | D10: ='Statement Y'!D10 -> 251207 | E10: ='Statement Y'!E10 -> 387316 | F10: ='Statement Y'!F10 -> 433395 | G10: ='Statement Y'!G10 -> 390109 | I10: ='Statement Q'!C10 -> 87511 | J10: ='Statement Q'!D10 -> 103825 | K10: ='Statement Q'!E10 -> 119096 | L10: ='Statement Q'!F10 -> 122963 | M10: ='Statement Q'!G10 -> 94940 | N10: ='Statement Q'!H10 -> 92391 | O10: ='Statement Q'!I10 -> 95833 | P10: ='Statement Q'!J10 -> 106945 | R10: =SUM(M10:P10) -> 390109
B11: OpEx | C11: ='Statement Y'!C11 -> 999927 | D11: ='Statement Y'!D11 -> 1088820 | E11: ='Statement Y'!E11 -> 1534288 | F11: ='Statement Y'!F11 -> 2017829 | G11: ='Statement Y'!G11 -> 2216209 | I11: ='Statement Q'!C11 -> 371675 | J11: ='Statement Q'!D11 -> 497063 | K11: ='Statement Q'!E11 -> 514745 | L11: ='Statement Q'!F11 -> 634346 | M11: ='Statement Q'!G11 -> 458280 | N11: ='Statement Q'!H11 -> 539520 | O11: ='Statement Q'!I11 -> 554578 | P11: ='Statement Q'!J11 -> 663831 | R11: =SUM(M11:P11) -> 2216209
B12: Operating income | C12: ='Statement Y'!C12 -> 438257 | D12: ='Statement Y'!D12 -> 321374 | E12: ='Statement Y'!E12 -> 373564 | F12: ='Statement Y'!F12 -> 644162 | G12: ='Statement Y'!G12 -> 920281 | I12: ='Statement Q'!C12 -> 154942 | J12: ='Statement Q'!D12 -> 103836 | K12: ='Statement Q'!E12 -> 180262 | L12: ='Statement Q'!F12 -> 205122 | M12: ='Statement Q'!G12 -> 144946 | N12: ='Statement Q'!H12 -> 168647 | O12: ='Statement Q'!I12 -> 262891 | P12: ='Statement Q'!J12 -> 343797 | R12: =SUM(M12:P12) -> 920281
B13: EBITDA | C13: =C12+C57 -> 516440 | D13: =D12+D57 -> 408082 | E13: =E12+E57 -> 477385 | F13: =F12+F57 -> 767271 | G13: =G12+G57 -> 1059912 | I13: =I12+I57 -> 154942 | J13: =J12+J57 -> 103836 | K13: =K12+K57 -> 180262 | L13: =L12+L57 -> 205122 | M13: =M12+M57 -> 176892 | N13: =N12+N57 -> 203718 | O13: =O12+O57 -> 296564 | P13: =P12+P57 -> 382738 | R13: =SUM(M13:P13) -> 1059912
B14: Other income/expense | C14: ='Statement Y'!C13 -> -16287 | D14: ='Statement Y'!D13 -> -27021 | E14: ='Statement Y'!E13 -> -44909 | F14: ='Statement Y'!F13 -> -63715 | G14: ='Statement Y'!G13 -> -48600 | I14: ='Statement Q'!C13 -> -14722 | J14: ='Statement Q'!D13 -> -14844 | K14: ='Statement Q'!E13 -> -16916 | L14: ='Statement Q'!F13 -> -17233 | M14: ='Statement Q'!G13 -> -12629 | N14: ='Statement Q'!H13 -> -13765 | O14: ='Statement Q'!I13 -> -12782 | P14: ='Statement Q'!J13 -> -9424 | R14: =SUM(M14:P14) -> -48600
B15: Interest income | C15: ='Statement Y'!C14 -> -7644 | D15: ='Statement Y'!D14 -> 7631 | E15: ='Statement Y'!E14 -> -35427 | F15: ='Statement Y'!F14 -> -7980 | G15: ='Statement Y'!G14 -> 28597 | I15: ='Statement Q'!C14 -> 3248 | J15: ='Statement Q'!D14 -> 689 | K15: ='Statement Q'!E14 -> 11031 | L15: ='Statement Q'!F14 -> -22948 | M15: ='Statement Q'!G14 -> 13216 | N15: ='Statement Q'!H14 -> 26003 | O15: ='Statement Q'!I14 -> -6116 | P15: ='Statement Q'!J14 -> -4506 | R15: =SUM(M15:P15) -> 28597
B16: Income before taxes | C16: ='Statement Y'!C15 -> 414326 | D16: ='Statement Y'!D15 -> 301984 | E16: ='Statement Y'!E15 -> 293228 | F16: ='Statement Y'!F15 -> 572467 | G16: ='Statement Y'!G15 -> 900278 | I16: ='Statement Q'!C15 -> 143468 | J16: ='Statement Q'!D15 -> 89681 | K16: ='Statement Q'!E15 -> 174377 | L16: ='Statement Q'!F15 -> 164941 | M16: ='Statement Q'!G15 -> 145533 | N16: ='Statement Q'!H15 -> 180885 | O16: ='Statement Q'!I15 -> 243993 | P16: ='Statement Q'!J15 -> 329867 | R16: =SUM(M16:P16) -> 900278
B17: Income tax expense/benefit | C17: ='Statement Y'!C16 -> -83213 | D17: ='Statement Y'!D16 -> -69630 | E17: ='Statement Y'!E16 -> -126150 | F17: ='Statement Y'!F16 -> -133762 | G17: ='Statement Y'!G16 -> -198904 | I17: ='Statement Q'!C16 -> -33856 | J17: ='Statement Q'!D16 -> -21633 | K17: ='Statement Q'!E16 -> -42048 | L17: ='Statement Q'!F16 -> -36225 | M17: ='Statement Q'!G16 -> -27698 | N17: ='Statement Q'!H16 -> -41287 | O17: ='Statement Q'!I16 -> -55264 | P17: ='Statement Q'!J16 -> -74655 | R17: =SUM(M17:P17) -> -198904
B18: Net income | C18: ='Statement Y'!C17 -> 331113 | D18: ='Statement Y'!D17 -> 232354 | E18: ='Statement Y'!E17 -> 167078 | F18: ='Statement Y'!F17 -> 438705 | G18: ='Statement Y'!G17 -> 701374 | I18: ='Statement Q'!C17 -> 109612 | J18: ='Statement Q'!D17 -> 68048 | K18: ='Statement Q'!E17 -> 132329 | L18: ='Statement Q'!F17 -> 128716 | M18: ='Statement Q'!G17 -> 117835 | N18: ='Statement Q'!H17 -> 139598 | O18: ='Statement Q'!I17 -> 188729 | P18: ='Statement Q'!J17 -> 255212 | R18: =SUM(M18:P18) -> 701374
B19: Diluted Shares outstanding avg | C19: ='Statement Y'!C19 -> 138983 | D19: ='Statement Y'!D19 -> 138983 | E19: ='Statement Y'!E19 -> 139420 | F19: ='Statement Y'!F19 -> 141084 | G19: ='Statement Y'!G19 -> 142090 | I19: ='Statement Q'!C19 -> 140703 | J19: ='Statement Q'!D19 -> 140924 | K19: ='Statement Q'!E19 -> 141306 | L19: ='Statement Q'!F19 -> 141518 | M19: ='Statement Q'!G19 -> 142183 | N19: ='Statement Q'!H19 -> 141871 | O19: ='Statement Q'!I19 -> 142119 | P19: ='Statement Q'!J19 -> 142129 | R19: =AVERAGE(M19:P19) -> 142075.5
B20: Diluted EPS | C20: ='Statement Y'!C21 -> 2.38 | D20: ='Statement Y'!D21 -> 1.67 | E20: ='Statement Y'!E21 -> 1.2 | F20: ='Statement Y'!F21 -> 3.11 | G20: ='Statement Y'!G21 -> 4.94 | I20: ='Statement Q'!C21 -> 0.78 | J20: ='Statement Q'!D21 -> 0.48 | K20: ='Statement Q'!E21 -> 0.94 | L20: ='Statement Q'!F21 -> 0.91 | M20: ='Statement Q'!G21 -> 0.83 | N20: ='Statement Q'!H21 -> 0.98 | O20: ='Statement Q'!I21 -> 1.33 | P20: ='Statement Q'!J21 -> 1.8 | R20: =SUM(M20:P20) -> 4.94
B22: Balance sheet
B23: Cash and cash equivalents | C23: ='Statement Y'!C24 -> 0 | D23: ='Statement Y'!D24 -> 192890 | E23: ='Statement Y'!E24 -> 154061 | F23: ='Statement Y'!F24 -> 363669 | G23: ='Statement Y'!G24 -> 777289 | I23: ='Statement Q'!C24 -> 0 | J23: ='Statement Q'!D24 -> 0 | K23: ='Statement Q'!E24 -> 0 | L23: ='Statement Q'!F24 -> 363669 | M23: ='Statement Q'!G24 -> 224696 | N23: ='Statement Q'!H24 -> 188229 | O23: ='Statement Q'!I24 -> 263816 | P23: ='Statement Q'!J24 -> 777289 | R23: =P23 -> 777289
B24: Restricted cash | C24: ='Statement Y'!C25 -> 0 | D24: ='Statement Y'!D25 -> 25880 | E24: ='Statement Y'!E25 -> 0 | F24: ='Statement Y'!F25 -> 0 | G24: ='Statement Y'!G25 -> 0 | I24: ='Statement Q'!C25 -> 0 | J24: ='Statement Q'!D25 -> 0 | K24: ='Statement Q'!E25 -> 0 | L24: ='Statement Q'!F25 -> 0 | M24: ='Statement Q'!G25 -> 0 | N24: ='Statement Q'!H25 -> 0 | O24: ='Statement Q'!I25 -> 0 | P24: ='Statement Q'!J25 -> 0 | R24: =P24 -> 0
B25: Acc receivable | C25: ='Statement Y'!C26 -> 0 | D25: ='Statement Y'!D26 -> 766503 | E25: ='Statement Y'!E26 -> 985172 | F25: ='Statement Y'!F26 -> 1266595 | G25: ='Statement Y'!G26 -> 1667143 | I25: ='Statement Q'!C26 -> 0 | J25: ='Statement Q'!D26 -> 0 | K25: ='Statement Q'!E26 -> 0 | L25: ='Statement Q'!F26 -> 1266595 | M25: ='Statement Q'!G26 -> 1040635 | N25: ='Statement Q'!H26 -> 1324984 | O25: ='Statement Q'!I26 -> 1595180 | P25: ='Statement Q'!J26 -> 1667143 | R25: =P25 -> 1667143
B26: Inventories | C26: ='Statement Y'!C27 -> 0 | D26: ='Statement Y'!D27 -> 548588 | E26: ='Statement Y'!E27 -> 699740 | F26: ='Statement Y'!F27 -> 899989 | G26: ='Statement Y'!G27 -> 1002205 | I26: ='Statement Q'!C27 -> 0 | J26: ='Statement Q'!D27 -> 0 | K26: ='Statement Q'!E27 -> 0 | L26: ='Statement Q'!F27 -> 899989 | M26: ='Statement Q'!G27 -> 973198 | N26: ='Statement Q'!H27 -> 1052711 | O26: ='Statement Q'!I27 -> 1158345 | P26: ='Statement Q'!J27 -> 1002205 | R26: =P26 -> 1002205
B27: Prepaid expenses & Other current | C27: ='Statement Y'!C28 -> 0 | D27: ='Statement Y'!D28 -> 181831 | E27: ='Statement Y'!E28 -> 58311 | F27: ='Statement Y'!F28 -> 114008 | G27: ='Statement Y'!G28 -> 164628 | I27: ='Statement Q'!C28 -> 0 | J27: ='Statement Q'!D28 -> 0 | K27: ='Statement Q'!E28 -> 0 | L27: ='Statement Q'!F28 -> 114008 | M27: ='Statement Q'!G28 -> 157521 | N27: ='Statement Q'!H28 -> 190586 | O27: ='Statement Q'!I28 -> 226561 | P27: ='Statement Q'!J28 -> 164628 | R27: =P27 -> 164628
B28: Current assets | C28: ='Statement Y'!C29 -> 0 | D28: ='Statement Y'!D29 -> 1715692 | E28: ='Statement Y'!E29 -> 1897284 | F28: ='Statement Y'!F29 -> 2644261 | G28: ='Statement Y'!G29 -> 3611265 | I28: ='Statement Q'!C29 -> 0 | J28: ='Statement Q'!D29 -> 0 | K28: ='Statement Q'!E29 -> 0 | L28: ='Statement Q'!F29 -> 2644261 | M28: ='Statement Q'!G29 -> 2396050 | N28: ='Statement Q'!H29 -> 2756510 | O28: ='Statement Q'!I29 -> 3243902 | P28: ='Statement Q'!J29 -> 3611265 | R28: =P28 -> 3611265
B29: PP&E | C29: ='Statement Y'!C30 -> 0 | D29: ='Statement Y'!D30 -> 137341 | E29: ='Statement Y'!E30 -> 166252 | F29: ='Statement Y'!F30 -> 211464 | G29: ='Statement Y'!G30 -> 232226 | I29: ='Statement Q'!C30 -> 0 | J29: ='Statement Q'!D30 -> 0 | K29: ='Statement Q'!E30 -> 0 | L29: ='Statement Q'!F30 -> 211464 | M29: ='Statement Q'!G30 -> 221700 | N29: ='Statement Q'!H30 -> 212771 | O29: ='Statement Q'!I30 -> 214693 | P29: ='Statement Q'!J30 -> 232226 | R29: =P29 -> 232226
B30: Operating lease right of use | C30: ='Statement Y'!C31 -> 0 | D30: ='Statement Y'!D31 -> 67321 | E30: ='Statement Y'!E31 -> 63333 | F30: ='Statement Y'!F31 -> 146257 | G30: ='Statement Y'!G31 -> 142487 | I30: ='Statement Q'!C31 -> 0 | J30: ='Statement Q'!D31 -> 0 | K30: ='Statement Q'!E31 -> 0 | L30: ='Statement Q'!F31 -> 146257 | M30: ='Statement Q'!G31 -> 143479 | N30: ='Statement Q'!H31 -> 140714 | O30: ='Statement Q'!I31 -> 147707 | P30: ='Statement Q'!J31 -> 142487 | R30: =P30 -> 142487
B31: Intangible assets | C31: ='Statement Y'!C32 -> 0 | D31: ='Statement Y'!D32 -> 492709 | E31: ='Statement Y'!E32 -> 477816 | F31: ='Statement Y'!F32 -> 462678 | G31: ='Statement Y'!G32 -> 451137 | I31: ='Statement Q'!C32 -> 0 | J31: ='Statement Q'!D32 -> 0 | K31: ='Statement Q'!E32 -> 0 | L31: ='Statement Q'!F32 -> 462678 | M31: ='Statement Q'!G32 -> 459539 | N31: ='Statement Q'!H32 -> 457536 | O31: ='Statement Q'!I32 -> 454477 | P31: ='Statement Q'!J32 -> 451137 | R31: =P31 -> 451137
B32: Goodwill | C32: ='Statement Y'!C33 -> 0 | D32: ='Statement Y'!D33 -> 840148 | E32: ='Statement Y'!E33 -> 834203 | F32: ='Statement Y'!F33 -> 834781 | G32: ='Statement Y'!G33 -> 834781 | I32: ='Statement Q'!C33 -> 0 | J32: ='Statement Q'!D33 -> 0 | K32: ='Statement Q'!E33 -> 0 | L32: ='Statement Q'!F33 -> 834781 | M32: ='Statement Q'!G33 -> 834781 | N32: ='Statement Q'!H33 -> 834781 | O32: ='Statement Q'!I33 -> 834781 | P32: ='Statement Q'!J33 -> 834781 | R32: =P32 -> 834781
B33: Deferred tax assets | C33: ='Statement Y'!C34 -> 0 | D33: ='Statement Y'!D34 -> 6291 | E33: ='Statement Y'!E34 -> 12 | F33: ='Statement Y'!F34 -> 43093 | G33: ='Statement Y'!G34 -> 10706 | I33: ='Statement Q'!C34 -> 0 | J33: ='Statement Q'!D34 -> 0 | K33: ='Statement Q'!E34 -> 0 | L33: ='Statement Q'!F34 -> 43093 | M33: ='Statement Q'!G34 -> 58628 | N33: ='Statement Q'!H34 -> 73721 | O33: ='Statement Q'!I34 -> 10943 | P33: ='Statement Q'!J34 -> 10706 | R33: =P33 -> 10706
B34: Other assets | C34: ='Statement Y'!C35 -> 0 | D34: ='Statement Y'!D35 -> 35389 | E34: ='Statement Y'!E35 -> 48170 | F34: ='Statement Y'!F35 -> 51625 | G34: ='Statement Y'!G35 -> 66832 | I34: ='Statement Q'!C35 -> 0 | J34: ='Statement Q'!D35 -> 0 | K34: ='Statement Q'!E35 -> 0 | L34: ='Statement Q'!F35 -> 51625 | M34: ='Statement Q'!G35 -> 61225 | N34: ='Statement Q'!H35 -> 63224 | O34: ='Statement Q'!I35 -> 68469 | P34: ='Statement Q'!J35 -> 66832 | R34: =P34 -> 66832
... B53: Total liabilities and equity | C53: ='Statement Y'!C54 -> 0 | D53: ='Statement Y'!D54 -> 3294891 | E53: ='Statement Y'!E54 -> 3487070 | F53: ='Statement Y'!F54 -> 4394159 | G53: ='Statement Y'!G54 -> 5349434 | I53: ='Statement Q'!C54 -> 0 | J53: ='Statement Q'!D54 -> 0 | K53: ='Statement Q'!E54 -> 0 | L53: ='Statement Q'!F54 -> 4394159 | M53: ='Statement Q'!G54 -> 4175402 | N53: ='Statement Q'!H54 -> 4539257 | O53: ='Statement Q'!I54 -> 4974972 | P53: ='Statement Q'!J54 -> 5349434 | R53: =P53 -> 5349434
B55: Cashflow statement
B56: Net income | C56: ='Statement Y'!C57 -> 331113 | D56: ='Statement Y'!D57 -> 232354 | E56: ='Statement Y'!E57 -> 167078 | F56: ='Statement Y'!F57 -> 438705 | G56: ='Statement Y'!G57 -> 701374 | I56: ='Statement Q'!C57 -> 109612 | J56: ='Statement Q'!D57 -> 68048 | K56: ='Statement Q'!E57 -> 132329 | L56: ='Statement Q'!F57 -> 128716 | M56: ='Statement Q'!G57 -> 117835 | N56: ='Statement Q'!H57 -> 139598 | O56: ='Statement Q'!I57 -> 188729 | P56: ='Statement Q'!J57 -> 255212 | R56: =SUM(M56:P56) -> 701374
B57: D&A | C57: ='Statement Y'!C58 -> 78183 | D57: ='Statement Y'!D58 -> 86708 | E57: ='Statement Y'!E58 -> 103821 | F57: ='Statement Y'!F58 -> 123109 | G57: ='Statement Y'!G58 -> 139631 | I57: ='Statement Q'!C58 -> 0 | J57: ='Statement Q'!D58 -> 0 | K57: ='Statement Q'!E58 -> 0 | L57: ='Statement Q'!F58 -> 0 | M57: ='Statement Q'!G58 -> 31946 | N57: ='Statement Q'!H58 -> 35071 | O57: ='Statement Q'!I58 -> 33673 | P57: ='Statement Q'!J58 -> 38941 | R57: =SUM(M57:P57) -> 139631
B58: Stock-based compensation | C58: ='Statement Y'!C59 -> 13924 | D58: ='Statement Y'!D59 -> 5509 | E58: ='Statement Y'!E59 -> 46966 | F58: ='Statement Y'!F59 -> 84531 | G58: ='Statement Y'!G59 -> 43872 | I58: ='Statement Q'!C59 -> 0 | J58: ='Statement Q'!D59 -> 0 | K58: ='Statement Q'!E59 -> 0 | L58: ='Statement Q'!F59 -> 0 | M58: ='Statement Q'!G59 -> 11550 | N58: ='Statement Q'!H59 -> 10928 | O58: ='Statement Q'!I59 -> 9120 | P58: ='Statement Q'!J59 -> 12274 | R58: =SUM(M58:P58) -> 43872
B59: Shareholder executive bonuses | C59: ='Statement Y'!C60 -> 0 | D59: ='Statement Y'!D60 -> 0 | E59: ='Statement Y'!E60 -> 32200 | F59: ='Statement Y'!F60 -> 0 | G59: ='Statement Y'!G60 -> 0 | I59: ='Statement Q'!C60 -> 0 | J59: ='Statement Q'!D60 -> 0 | K59: ='Statement Q'!E60 -> 0 | L59: ='Statement Q'!F60 -> 0 | M59: ='Statement Q'!G60 -> 0 | N59: ='Statement Q'!H60 -> 0 | O59: ='Statement Q'!I60 -> 0 | P59: ='Statement Q'!J60 -> 0 | R59: =SUM(M59:P59) -> 0
B60: Provision for credit losses | C60: ='Statement Y'!C61 -> 7913 | D60: ='Statement Y'!D61 -> 8965 | E60: ='Statement Y'!E61 -> 4474 | F60: ='Statement Y'!F61 -> 4724 | G60: ='Statement Y'!G61 -> 4740 | I60: ='Statement Q'!C61 -> 0 | J60: ='Statement Q'!D61 -> 0 | K60: ='Statement Q'!E61 -> 0 | L60: ='Statement Q'!F61 -> 0 | M60: ='Statement Q'!G61 -> 3178 | N60: ='Statement Q'!H61 -> 204 | O60: ='Statement Q'!I61 -> 90 | P60: ='Statement Q'!J61 -> 1268 | R60: =SUM(M60:P60) -> 4740
B61: Non-cash lease expense | C61: ='Statement Y'!C63 -> 13062 | D61: ='Statement Y'!D63 -> 15475 | E61: ='Statement Y'!E63 -> 14708 | F61: ='Statement Y'!F63 -> 19466 | G61: ='Statement Y'!G63 -> 20431 | I61: ='Statement Q'!C63 -> 0 | J61: ='Statement Q'!D63 -> 0 | K61: ='Statement Q'!E63 -> 0 | L61: ='Statement Q'!F63 -> 0 | M61: ='Statement Q'!G63 -> 4993 | N61: ='Statement Q'!H63 -> 4925 | O61: ='Statement Q'!I63 -> 5187 | P61: ='Statement Q'!J63 -> 5326 | R61: =SUM(M61:P61) -> 20431
...
