Workbook

Sheet Overview
B2: Automatic Data | E2: At a glance | H2: Valuation | K2: Links
B3: Company | C3: #VALUE! | E3: Market capitalization | F3: =Statement!AC151 -> 160394.49 | H3: ='AVG target price'!B5 -> DCF price | I3: ='AVG target price'!C5 -> 134.65123 | K3: Financials ->'!B13
B4: Ticker | C4: {=_FV(C3,"Ticker symbol",TRUE)} -> STX | E4: Enterprise value | F4: =Statement!AC152 -> 162255.49 | H4: ='AVG target price'!B6 -> EV/EBIT price | I4: ='AVG target price'!C6 -> 212.51771 | K4: Analysis ->'!B13
B5: Price | C5: {=_FV(C3,"Price",TRUE)} -> 676.77 | E5: EPS | F5: =Statement!AC25 -> 13.88 | H5: ='AVG target price'!B7 -> PS price | I5: ='AVG target price'!C7 -> 146.73746 | K5: Forecast ->'!B13
B6: Price Extended Hours | C6: {=_FV(C3,"Price (Extended hours)",TRUE)} -> #VALUE! | E6: PE | F6: =Statement!AC148 -> 48.758646 | H6: ='AVG target price'!B8 -> EV/FCFF price | I6: ='AVG target price'!C8 -> 227.6838 | K6: Valuation ->'!B13
B7: Day change | C7: {=_FV(C3,"Change")} -> 32.56 | E7: PS | F7: =Statement!AC149 -> 12.69464 | H7: ='AVG target price'!B9 -> EV/Sales | I7: ='AVG target price'!C9 -> 218.83792
B8: Day change extended | C8: {=_FV(C3,"Change (extended hours)",TRUE)} -> #VALUE! | E8: FCF Yield | F8: =Statement!AC159 -> 0.018030545 | H8: ='AVG target price'!B10 -> AVG price | I8: ='AVG target price'!C10 -> 188.08562
B9: Day change % | C9: {=_FV(C3,"Change (%)",TRUE)} -> 0.050543 | E9: Earnings Yield | F9: =Statement!AC160 -> 0.020509183 | H9: ='AVG target price'!B12 -> Upside/Downside | I9: ='AVG target price'!C12 -> -0.72208339
B10: Day change extended % | C10: {=_FV(C3,"Change % (extended hours)",TRUE)} -> #VALUE! | E10: Buyback Yield | F10: =Statement!AC162 -> 0.0010972946
B11: 52 week high | C11: {=_FV(C3,"52 week high",TRUE)} -> 1145 | E11: Dividend Yield | F11: =Statement!AC161 -> 0.0043146121 | H11: DDM price | I11: =DDM!C26 -> 23.779348
B12: 52 week low | C12: {=_FV(C3,"52 week low",TRUE)} -> 217.67 | E12: ROA | F12: =Statement!AC121 -> 0.31929402
B13: Beta | C13: {=_FV(C3,"Beta")} -> 2.1471 | E13: ROE | F13: =Statement!AC123 -> 1.4693124 | H13: Reverse DCF rate | I13: ='Reverse DCF'!C17 -> 0.56
B14: Avg volume | C14: {=_FV(C3,"Volume average",TRUE)} -> 4848790 | E14: ROIC | F14: =Statement!AC138 -> 0.87701106 | H14: Reverse DCF price | I14: ='Reverse DCF'!C16 -> 682.17154
E15: Net Cash/Market Cap | F15: =Statement!AC174 -> -0.011602643
E16: Net Cash/Share | F16: =Statement!AC173 -> -8.1982379 | H16: Discount rates used
B17: Unit data and other info | E17: Insider Ownership | F17: =Statement!AC169 -> 0.0084388186 | H17: WACC | I17: =DCF!C15 -> 0.1443252
B18: Units | C18: M | E18: Net Trade Cycle | F18: =Statement!AC142 -> 36.179013 | H18: Cost of Equity | I18: =Multiples!C54 -> 0.1464795
B19: Units conversion | C19: 1000000 | E19: Net Debt/Equity | F19: =Statement!AC144 -> 0.85879096
B20: Has operating lease | C20: No | E20: Quick Ratio | F20: =Statement!AC145 -> 1.0354973
B21: Has finance lease | C21: No
B22: Has debt | C22: Yes
B25: Constants | E25: 10 Year Bond Yield
B26: Default tax rate | C26: 0.21 | E26: #VALUE! | F26: {=_FV(E26,"Price")} -> 49.86
B27: Cost of debt | C27: 0.06 | E27: Percentage | F27: =F26/1000 -> 0.04986
B28: Manual WACC | C28: 0
B29: Manual Cost of Equity | C29: 0
B33: Info
B35: Mission: | C35: Enable enterprises and end-users to confidently store and unlock value of their data
B36: Auditor: | C36: Erns & young
B37: Business units: | C37: Datacenter represents high capacity nearline products sold to clouds and enterprise customers
C38: Edge & IoT includes consumer and client markets
B39: Competitors: | C39: Kioxia Holdings
C40: Micron
C41: Samsung Electronics
C42: Sandisk
C43: SK Hynix
C44: Western Digital
C45: Toshiba Corporation
B46: Patents: | C46: =3036+226 -> 3262
B52: Notes
...

Sheet Financials ->
H5: Links
H6: Overview'!B3
H7: Financials ->'!B13
H8: Analysis ->'!B13
H9: Forecast ->'!B13
H10: Valuation ->'!B13
B13: Financials ->

Sheet Statement
B2: Date | L2: 02.07.2021 | M2: 01.07.2022 | N2: 30.06.2023 | O2: 28.06.2024 | P2: 27.06.2025 | Q2: 03.07.2026 | T2: 27.09.2024 | U2: 27.12.2024 | V2: 28.03.2025 | W2: 27.06.2025 | X2: 03.10.2025 | Y2: 02.01.2026 | Z2: 03.04.2026 | AA2: 03.07.2026
B3: FY | L3: 2021 | M3: 2022 | N3: 2023 | O3: 2024 | P3: 2025 | Q3: 2026 | T3: Q1 2025 | U3: Q2 2025 | V3: Q3 2025 | W3: Q4 2025 | X3: Q1 2026 | Y3: Q2 2026 | Z3: Q3 2026 | AA3: Q4 2026 | AC3: TTM/YTD
B4: Income statement
B5: Revenue | L5: 10681 | M5: 11661 | N5: 7384 | O5: 6551 | P5: 9097 | Q5: 12195 | T5: 2168 | U5: 2325 | V5: 2160 | W5: 2444 | X5: 2629 | Y5: 2825 | Z5: 3112 | AA5: 3629 | AC5: =SUM(X5:AA5) -> 12195
B6: COGS | L6: 7764 | M6: 8192 | N6: 6033 | O6: 5015 | P6: 5897 | Q6: 6637 | T6: 1454 | U6: 1513 | V6: 1400 | W6: 1530 | X6: 1592 | Y6: 1649 | Z6: 1665 | AA6: 1731 | AC6: =SUM(X6:AA6) -> 6637
B7: Gross Profit | C7: =C5-C6 -> 0 | D7: =D5-D6 -> 0 | E7: =E5-E6 -> 0 | F7: =F5-F6 -> 0 | G7: =G5-G6 -> 0 | H7: =H5-H6 -> 0 | I7: =I5-I6 -> 0 | J7: =J5-J6 -> 0 | ... Q7: =Q5-Q6 -> 5558 | T7: =T5-T6 -> 714 | U7: =U5-U6 -> 812 | V7: =V5-V6 -> 760 | W7: =W5-W6 -> 914 | X7: =X5-X6 -> 1037 | Y7: =Y5-Y6 -> 1176 | Z7: =Z5-Z6 -> 1447 | AA7: =AA5-AA6 -> 1898 | AC7: =SUM(X7:AA7) -> 5558
B8: R&D | L8: 903 | M8: 941 | N8: 797 | O8: 654 | P8: 724 | Q8: 755 | T8: 181 | U8: 184 | V8: 180 | W8: 179 | X8: 186 | Y8: 187 | Z8: 194 | AA8: 188 | AC8: =SUM(X8:AA8) -> 755
B9: SG&A | L9: 502 | M9: 559 | N9: 491 | O9: 460 | P9: 561 | Q9: 577 | T9: 129 | U9: 139 | V9: 139 | W9: 154 | X9: 144 | Y9: 143 | Z9: 143 | AA9: 147 | AC9: =SUM(X9:AA9) -> 577
B10: Opex | L10: =903+502+20 -> 1425 | M10: =941+559+14 -> 1514 | N10: =797+491+3+300+102 -> 1693 | O10: =654+430 -> 1084 | P10: =724+561+25 -> 1310 | Q10: =755+577+105+27 -> 1464 | T10: =181+130 -> 311 | U10: =184+140 -> 324 | V10: =180+139+10 -> 329 | W10: =179+154+13 -> 346 | X10: =186+144+13 -> 343 | Y10: =187+146 -> 333 | Z10: =194+143+112 -> 449 | AA10: =188+147+4 -> 339 | AC10: =SUM(X10:AA10) -> 1464
B11: Operating income | L11: 1492 | M11: 1955 | N11: -342 | O11: 452 | P11: 1890 | Q11: 4094 | T11: 403 | U11: 488 | V11: 431 | W11: 568 | X11: 694 | Y11: 843 | Z11: 998 | AA11: 1559 | AC11: =SUM(X11:AA11) -> 4094
B12: Interest income/expense | L12: -218 | M12: -247 | N12: -303 | O12: =15-332 -> -317 | P12: =25-321 -> -296 | Q12: -254 | T12: -78 | U12: -76 | V12: -73 | W12: -69 | X12: -73 | Y12: -65 | Z12: -62 | AA12: -54 | AC12: =SUM(X12:AA12) -> -254
B13: Other income/expense | L13: 74 | M13: -29 | N13: =190-41 -> 149 | O13: =417-29-78 -> 310 | P13: -81 | Q13: -150 | T13: -9 | U13: -62 | V13: -3 | W13: -7 | X13: -7 | Y13: -71 | Z13: -72 | AA13: 0 | AC13: =SUM(X13:AA13) -> -150
B14: Income before taxes | L14: 1348 | M14: 1679 | N14: -496 | O14: 445 | P14: 1513 | Q14: 3690 | T14: 316 | U14: 350 | V14: 355 | W14: 492 | X14: 614 | Y14: 707 | Z14: 864 | AA14: 1505 | AC14: =SUM(X14:AA14) -> 3690
B15: Income tax expense/benefit | L15: -34 | M15: -30 | N15: -33 | O15: -110 | P15: -44 | Q15: -506 | T15: -11 | U15: -14 | V15: -15 | W15: -4 | X15: -65 | Y15: -114 | Z15: -116 | AA15: -211 | AC15: =SUM(X15:AA15) -> -506
B16: Non-controlling interest | L16: 0 | M16: 0 | N16: 0 | O16: 0 | P16: 0 | Q16: 0 | T16: 0 | U16: 0 | V16: 0 | W16: 0 | X16: 0 | Y16: 0 | Z16: 0 | AA16: 0 | AC16: =SUM(X16:AA16) -> 0
B17: Net income | L17: 1314 | M17: 1649 | N17: -529 | O17: 335 | P17: 1469 | Q17: 3184 | T17: 305 | U17: 336 | V17: 340 | W17: 488 | X17: 549 | Y17: 593 | Z17: 748 | AA17: 1294 | AC17: =SUM(X17:AA17) -> 3184
B18: Basic Shares outstanding avg | L18: 242 | M18: 220 | N18: 207 | O18: 209 | P18: 212 | Q18: 219 | T18: 211 | U18: 212 | V18: 212 | W18: 212 | X18: 213 | Y18: 216 | Z18: 221 | AA18: 225 | AC18: =AVERAGE(X18:AA18) -> 218.75
B19: Basic Shares outstanding avg adjusted | C19: =C18*C$84 -> 0 | D19: =D18*D$84 -> 0 | E19: =E18*E$84 -> 0 | F19: =F18*F$84 -> 0 | G19: =G18*G$84 -> 0 | H19: =H18*H$84 -> 0 | I19: =I18*I$84 -> 0 | J19: =J18*J$84 -> 0 | ... Q19: =Q18*Q$84 -> 219 | T19: =T18*T$84 -> 211 | U19: =U18*U$84 -> 212 | V19: =V18*V$84 -> 212 | W19: =W18*W$84 -> 212 | X19: =X18*X$84 -> 213 | Y19: =Y18*Y$84 -> 216 | Z19: =Z18*Z$84 -> 221 | AA19: =AA18*AA$84 -> 225 | AC19: =AC18*AC$84 -> 218.75
B20: Diluted Shares outstanding avg | L20: 245 | M20: 224 | N20: 207 | O20: 212 | P20: 217 | Q20: 229 | T20: 216 | U20: 217 | V20: 216 | W20: 218 | X20: 226 | Y20: 228 | Z20: 229 | AA20: 232 | AC20: =AVERAGE(X20:AA20) -> 228.75
B21: Diluted Shares outstanding avg adjusted | C21: =C20*C$84 -> 0 | D21: =D20*D$84 -> 0 | E21: =E20*E$84 -> 0 | F21: =F20*F$84 -> 0 | G21: =G20*G$84 -> 0 | H21: =H20*H$84 -> 0 | I21: =I20*I$84 -> 0 | J21: =J20*J$84 -> 0 | ... Q21: =Q20*Q$84 -> 229 | T21: =T20*T$84 -> 216 | U21: =U20*U$84 -> 217 | V21: =V20*V$84 -> 216 | W21: =W20*W$84 -> 218 | X21: =X20*X$84 -> 226 | Y21: =Y20*Y$84 -> 228 | Z21: =Z20*Z$84 -> 229 | AA21: =AA20*AA$84 -> 232 | AC21: =AC20*AC$84 -> 228.75
B22: Basic EPS | L22: 5.43 | M22: 7.5 | N22: -2.56 | O22: 1.6 | P22: 6.93 | Q22: 14.54 | T22: 1.45 | U22: 1.58 | V22: 1.6 | W22: 2.3 | X22: 2.58 | Y22: 2.75 | Z22: 3.38 | AA22: 5.75 | AC22: =SUM(X22:AA22) -> 14.46
B23: Basic EPS adjusted | L23: =L22/L$84 -> 5.43 | M23: =M22/M$84 -> 7.5 | N23: =N22/N$84 -> -2.56 | O23: =O22/O$84 -> 1.6 | P23: =P22/P$84 -> 6.93 | Q23: =Q22/Q$84 -> 14.54 | T23: =T22/T$84 -> 1.45 | U23: =U22/U$84 -> 1.58 | V23: =V22/V$84 -> 1.6 | W23: =W22/W$84 -> 2.3 | X23: =X22/X$84 -> 2.58 | Y23: =Y22/Y$84 -> 2.75 | Z23: =Z22/Z$84 -> 3.38 | AA23: =AA22/AA$84 -> 5.75 | AC23: =AC22/AC$84 -> 14.46
B24: Diluted EPS | L24: 5.36 | M24: 7.36 | N24: -2.56 | O24: 1.58 | P24: 6.77 | Q24: 13.9 | T24: 1.41 | U24: 1.55 | V24: 1.57 | W24: 2.24 | X24: 2.43 | Y24: 2.6 | Z24: 3.27 | AA24: 5.58 | AC24: =SUM(X24:AA24) -> 13.88
B25: Diluted EPS adjusted | L25: =L24/L$84 -> 5.36 | M25: =M24/M$84 -> 7.36 | N25: =N24/N$84 -> -2.56 | O25: =O24/O$84 -> 1.58 | P25: =P24/P$84 -> 6.77 | Q25: =Q24/Q$84 -> 13.9 | T25: =T24/T$84 -> 1.41 | U25: =U24/U$84 -> 1.55 | V25: =V24/V$84 -> 1.57 | W25: =W24/W$84 -> 2.24 | X25: =X24/X$84 -> 2.43 | Y25: =Y24/Y$84 -> 2.6 | Z25: =Z24/Z$84 -> 3.27 | AA25: =AA24/AA$84 -> 5.58 | AC25: =AC24/AC$84 -> 13.88
B27: Balance sheet
B28: Cash and cash equivalents | L28: 1209 | M28: 615 | N28: 786 | O28: 1358 | P28: 891 | Q28: 1704 | T28: 1239 | U28: 1238 | V28: 814 | W28: 891 | X28: 1112 | Y28: 1046 | Z28: 1146 | AA28: 1704 | AC28: =AA28 -> 1704
B29: Acc receivable | L29: 1158 | M29: 1532 | N29: 621 | O29: 429 | P29: 959 | Q29: 1534 | T29: 628 | U29: 587 | V29: 622 | W29: 959 | X29: 1073 | Y29: 1246 | Z29: 1197 | AA29: 1534 | AC29: =AA29 -> 1534
B30: Inventory | L30: 1204 | M30: 1565 | N30: 1140 | O30: 1239 | P30: 1440 | Q30: 1571 | T30: 1383 | U30: 1473 | V30: 1472 | W30: 1440 | X30: 1496 | Y30: 1498 | Z30: 1530 | AA30: 1571 | AC30: =AA30 -> 1571
B31: Current assets | L31: 3779 | M31: 4033 | N31: 2905 | O31: 3332 | P31: 3653 | Q31: 5221 | T31: 3608 | U31: 3662 | V31: 3282 | W31: 3653 | X31: 4032 | Y31: 4209 | Z31: 4299 | AA31: 5221 | AC31: =AA31 -> 5221
B32: PP&E | L32: 2181 | M32: 2239 | N32: 1706 | O32: 1614 | P32: 1657 | Q32: 2034 | T32: 1599 | U32: 1595 | V32: 1613 | W32: 1657 | X32: 1688 | Y32: 1771 | Z32: 1852 | AA32: 2034 | AC32: =AA32 -> 2034
B33: Marketable securities and investments | L33: 0 | M33: 0 | N33: 0 | O33: 0 | P33: 0 | Q33: 0 | T33: 0 | U33: 0 | V33: 0 | W33: 0 | X33: 0 | Y33: 0 | Z33: 0 | AA33: 0 | AC33: =AA33 -> 0
B34: Goodwill | L34: 1237 | M34: 1237 | N34: 1237 | O34: 1219 | P34: 1221 | Q34: 1221 | T34: 1219 | U34: 1219 | V34: 1219 | W34: 1221 | X34: 1221 | Y34: 1221 | Z34: 1221 | AA34: 1221 | AC34: =AA34 -> 1221
B35: Long term assets | L35: =L36-L31 -> 4896 | M35: =M36-M31 -> 4911 | N35: =N36-N31 -> 4651 | O35: =O36-O31 -> 4407 | P35: =P36-P31 -> 4370 | Q35: =Q36-Q31 -> 4751 | T35: =T36-T31 -> 4364 | U35: =U36-U31 -> 4297 | V35: =V36-V31 -> 4282 | W35: =W36-W31 -> 4370 | X35: =X36-X31 -> 4410 | Y35: =Y36-Y31 -> 4499 | Z35: =Z36-Z31 -> 4593 | AA35: =AA36-AA31 -> 4751 | AC35: =AA35 -> 4751
B36: Total assets | L36: 8675 | M36: 8944 | N36: 7556 | O36: 7739 | P36: 8023 | Q36: 9972 | T36: 7972 | U36: 7959 | V36: 7564 | W36: 8023 | X36: 8442 | Y36: 8708 | Z36: 8892 | AA36: 9972 | AC36: =AA36 -> 9972
B37: Acc payable | L37: 1725 | M37: 2058 | N37: 1603 | O37: 1786 | P37: 1604 | Q37: 1748 | T37: 1778 | U37: 1567 | V37: 1467 | W37: 1604 | X37: 1673 | Y37: 1771 | Z37: 1694 | AA37: 1748 | AC37: =AA37 -> 1748
B38: Debt | L38: 245 | M38: 584 | N38: 63 | O38: 479 | P38: 0 | Q38: 185 | T38: 479 | U38: 479 | V38: 0 | W38: 0 | X38: 1496 | Y38: 998 | Z38: 398 | AA38: 185 | AC38: =AA38 -> 185
B39: Current liabilities | L39: 2921 | M39: 3555 | N39: 2592 | O39: 3099 | P39: 2648 | Q39: 3127 | T39: 3161 | U39: 2969 | V39: 2412 | W39: 2648 | X39: 4117 | Y39: 3761 | Z39: 3241 | AA39: 3127 | AC39: =AA39 -> 3127
B40: Debt | L40: 4894 | M40: 5062 | N40: 5388 | O40: 5195 | P40: 4995 | Q40: 3380 | T40: 5197 | U40: 5200 | V40: 5146 | W40: 4995 | X40: 3498 | Y40: 3501 | Z40: 3465 | AA40: 3380 | AC40: =AA40 -> 3380
B41: Long term liabilities | L41: =L42-L39 -> 5123 | M41: =M42-M39 -> 5280 | N41: =N42-N39 -> 6163 | O41: =O42-O39 -> 6131 | P41: =P42-P39 -> 5828 | Q41: =Q42-Q39 -> 4678 | T41: =T42-T39 -> 6111 | U41: =U42-U39 -> 6069 | V41: =V42-V39 -> 5981 | W41: =W42-W39 -> 5828 | X41: =X42-X39 -> 4388 | Y41: =Y42-Y39 -> 4488 | Z41: =Z42-Z39 -> 4556 | AA41: =AA42-AA39 -> 4678 | AC41: =AA41 -> 4678
B42: Total liabilities | L42: 8044 | M42: 8835 | N42: 8755 | O42: 9230 | P42: 8476 | Q42: 7805 | T42: 9272 | U42: 9038 | V42: 8393 | W42: 8476 | X42: 8505 | Y42: 8249 | Z42: 7797 | AA42: 7805 | AC42: =AA42 -> 7805
...

Sheet Analysis ->
H5: Links
H6: Overview'!B3
H7: Financials ->'!B13
H8: Analysis ->'!B13
H9: Forecast ->'!B13
H10: Valuation ->'!B13
B13: Analysis ->

Sheet Basic
B1: TTM/YTD data
B4: Overview | E4: CAGR
B5: Price | C5: =Overview!C5 -> 676.77 | F5: 5Y | G5: 10Y
B6: Market capitalization | C6: =Statement!AC151 -> 160394.49 | E6: Revenue | F6: =IF(Statement!M5<=0,"N/A",_xlfn.RRI(4,Statement!M5,Statement!Q5)) -> 0.01125691 | G6: =IF(Statement!H5<=0,"N/A",_xlfn.RRI(9,Statement!H5,Statement!Q5)) -> N/A
B7: Enterprise value | C7: =Statement!AC152 -> 162255.49 | E7: Net income | F7: =IF(OR(Statement!M17<=0, Statement!Q17<=0), "N/A", _xlfn.RRI(4, Statement!M17, Statement!Q17)) -> 0.1787945 | G7: =IF(OR(Statement!H17<=0, Statement!Q17<=0), "N/A", _xlfn.RRI(9, Statement!H17, Statement!Q17)) -> N/A
B8: PE | C8: =Statement!AC148 -> 48.758646 | E8: EPS | F8: =IF(OR(Statement!M25<=0, Statement!Q25<=0), "N/A", _xlfn.RRI(4, Statement!M25, Statement!Q25)) -> 0.1722878 | G8: =IF(OR(Statement!H25<=0, Statement!Q25<=0), "N/A", _xlfn.RRI(9, Statement!H25, Statement!Q25)) -> N/A
B9: PS | C9: =Statement!AC149 -> 12.69464 | E9: Dividend | F9: =IF(Statement!M81<=0,"N/A",_xlfn.RRI(4,Statement!M81,Statement!Q81)) -> 0.013271367 | G9: =IF(Statement!H81<=0,"N/A",_xlfn.RRI(9,Statement!H81,Statement!Q81)) -> N/A
B10: PB | C10: =Statement!AC150 -> 70.893766 | E10: Price | F10: =IF(Statement!M115<=0,"N/A",_xlfn.RRI(4,Statement!M115,Statement!Q115)) -> 0.85618324 | G10: =IF(Statement!H115<=0,"N/A",_xlfn.RRI(9,Statement!H115,Statement!Q115)) -> N/A
B11: EV/Revenue | C11: =Statement!AC153 -> 13.305083
B12: EV/EBIT | C12: =Statement!AC154 -> 39.632509
B15: Margins | E15: Earnings quality
B16: Gross margin | C16: =Statement!AC99 -> 0.45576056 | E16: Net income | F16: =Statement!AC17 -> 3184
B17: Operating margin | C17: =Statement!AC100 -> 0.33571136 | E17: Operating cash | F17: =Statement!AC58 -> 3674
B18: Net margin | C18: =Statement!AC101 -> 0.26109061 | E18: Cash accruals | F18: =IF(OR(F16<=0, F17<=0),"N/A",F16-F17) -> -490
B21: DuPont Identity | E21: Performance indicators
B22: Profit Margin (Earnings/Revenue) | C22: =Statement!AC119 -> 0.26109061 | E22: ROA | F22: =C24 -> 0.31929402
B23: Asset Turnover (Revenue/Total assets) | C23: =Statement!AC120 -> 1.2229242 | E23: ROE | F23: =C26 -> 1.4693124
B24: ROA | C24: =Statement!AC121 -> 0.31929402 | E24: ROIC | F24: =Statement!AC138 -> 0.87701106
B25: Equity Multiplier (Total assets/Equity) | C25: =Statement!AC122 -> 4.6017536
B26: ROE | C26: =Statement!AC123 -> 1.4693124
B29: Cash conversion cycle | E29: Liquidity ratios
B30: DSO | C30: =Statement!AC139 -> 45.913079 | E30: Debt/Equity | F30: =Statement!AC143 -> 1.6451315
B31: DIO | C31: =Statement!AC140 -> 86.396715 | E31: Net Debt/Equity | F31: =Statement!AC144 -> 0.85879096
B32: DPO | C32: =Statement!AC141 -> 96.130782 | E32: Current ratio | F32: =Statement!AC146 -> 1.6696514
B33: Net trade cycle | C33: =Statement!AC142 -> 36.179013 | E33: Quick ratio | F33: =Statement!AC145 -> 1.0354973
E34: Interest coverage | F34: =Statement!AC147 -> 16.11811
B37: Earnings yields | E37: Payout ratios
B38: Earnings yield | C38: =Statement!AC160 -> 0.020509183 | E38: Dividend payout ratio | F38: =Statement!AC166 -> 0.21922545
B39: FCF yield | C39: =Statement!AC159 -> 0.018030545 | E39: Buyback payout ratio | F39: =Statement!AC167 -> 0.060857538
B40: Dividend yield | C40: =Statement!AC161 -> 0.0043146121 | E40: Full payout ratio | F40: =Statement!AC168 -> 0.28008299
B41: Buyback yield | C41: =Statement!AC162 -> 0.0010972946
B42: Total shareholder yield | C42: =Statement!AC163 -> 0.0050500488
B45: Ownership | E45: Cash holdings
B46: Insider ownership | C46: =Statement!AC169 -> 0.0084388186 | E46: Cash per share | F46: =Statement!AC170 -> 7.5066079
E47: Net cash per share | F47: =Statement!AC173 -> -8.1982379
E48: Net cash to market cap | F48: =Statement!AC174 -> -0.011602643
B51: Stock based compensation | E51: CapEx usage
B52: Stock based compensation % OCF | C52: =Statement!AC171 -> 0.057974959 | E52: Capex to Revenue | F52: =Statement!AC175 -> 0.046658467
B53: Stock based compensation % Revenue | C53: =Statement!AC172 -> 0.017466175 | E53: CapEx to OCF | F53: =Statement!AC176 -> 0.15487207
E54: CapEx to D&A | F54: =Statement!AC177 -> 2.0615942
...

Sheet Yearly Analysis
C2: =Statement!M2 -> 01.07.2022 | D2: =Statement!N2 -> 30.06.2023 | E2: =Statement!O2 -> 28.06.2024 | F2: =Statement!P2 -> 27.06.2025 | G2: =Statement!Q2 -> 03.07.2026
C3: =Statement!M3 -> 2022 | D3: =Statement!N3 -> 2023 | E3: =Statement!O3 -> 2024 | F3: =Statement!P3 -> 2025 | G3: =Statement!Q3 -> 2026 | I3: =Statement!AC3 -> TTM/YTD
B5: Overview
B6: Price | C6: =Statement!M114 -> 69.09 | D6: =Statement!N114 -> 61.87 | E6: =Statement!O114 -> 103.27 | F6: =Statement!P114 -> 141.44 | G6: =Statement!Q114 -> 820.16 | I6: =Statement!AC114 -> 676.77
B7: Market capitalization | C7: =Statement!M151 -> 14716.17 | D7: =Statement!N151 -> 12807.09 | E7: =Statement!O151 -> 21996.51 | F7: =Statement!P151 -> 30833.92 | G7: =Statement!Q151 -> 194377.92 | I7: =Statement!AC151 -> 160394.49
B8: Enterprise value | C8: =Statement!M152 -> 19747.17 | D8: =Statement!N152 -> 17472.09 | E8: =Statement!O152 -> 26312.51 | F8: =Statement!P152 -> 34937.92 | G8: =Statement!Q152 -> 196238.92 | I8: =Statement!AC152 -> 162255.49
B9: PE | C9: =Statement!M148 -> 9.3872283 | D9: =Statement!N148 -> -24.167969 | E9: =Statement!O148 -> 65.360759 | F9: =Statement!P148 -> 20.892171 | G9: =Statement!Q148 -> 59.004317 | I9: =Statement!AC148 -> 48.758646
B10: PS | C10: =Statement!M149 -> 1.3271726 | D10: =Statement!N149 -> 1.734438 | E10: =Statement!O149 -> 3.3419692 | F10: =Statement!P149 -> 3.3739123 | G10: =Statement!Q149 -> 15.401118 | I10: =Statement!AC149 -> 12.69464
B11: PB | C11: =Statement!M150 -> 132.47532 | D11: =Statement!N150 -> -10.681476 | E11: =Statement!O150 -> -14.54507 | F11: =Statement!P150 -> -66.504901 | G11: =Statement!Q150 -> 85.914315 | I11: =Statement!AC150 -> 70.893766
B12: EV/Revenue | C12: =Statement!M153 -> 1.6934371 | D12: =Statement!N153 -> 2.3662094 | E12: =Statement!O153 -> 4.0165639 | F12: =Statement!P153 -> 3.840598 | G12: =Statement!Q153 -> 16.091752 | I12: =Statement!AC153 -> 13.305083
B13: EV/EBIT | C13: =Statement!M154 -> 10.100854 | D13: =Statement!N154 -> -51.087982 | E13: =Statement!O154 -> 58.213518 | F13: =Statement!P154 -> 18.485672 | G13: =Statement!Q154 -> 47.933298 | I13: =Statement!AC154 -> 39.632509
B15: Margins
B16: Gross margin | C16: =Statement!M99 -> 0.29748735 | D16: =Statement!N99 -> 0.18296316 | E16: =Statement!O99 -> 0.23446802 | F16: =Statement!P99 -> 0.35176432 | G16: =Statement!Q99 -> 0.45576056 | I16: =Statement!AC99 -> 0.45576056
B17: Operating margin | C17: =Statement!M100 -> 0.16765286 | D17: =Statement!N100 -> -0.04631636 | E17: =Statement!O100 -> 0.0689971 | F17: =Statement!P100 -> 0.2077608 | G17: =Statement!Q100 -> 0.33571136 | I17: =Statement!AC100 -> 0.33571136
B18: Net margin | C18: =Statement!M101 -> 0.14141154 | D18: =Statement!N101 -> -0.071641387 | E18: =Statement!O101 -> 0.051137231 | F18: =Statement!P101 -> 0.16148181 | G18: =Statement!Q101 -> 0.26109061 | I18: =Statement!AC101 -> 0.26109061
B20: Earnings quality
B21: Net income | C21: =Statement!M17 -> 1649 | D21: =Statement!N17 -> -529 | E21: =Statement!O17 -> 335 | F21: =Statement!P17 -> 1469 | G21: =Statement!Q17 -> 3184 | I21: =Statement!AC17 -> 3184
B22: Operating cash | C22: =Statement!M58 -> 1657 | D22: =Statement!N58 -> 942 | E22: =Statement!O58 -> 918 | F22: =Statement!P58 -> 1083 | G22: =Statement!Q58 -> 3674 | I22: =Statement!AC58 -> 3674
B23: Cash accruals | C23: =IF(OR(C21<=0, C22<=0),"N/A",C21-C22) -> -8 | D23: =IF(OR(D21<=0, D22<=0),"N/A",D21-D22) -> N/A | E23: =IF(OR(E21<=0, E22<=0),"N/A",E21-E22) -> -583 | F23: =IF(OR(F21<=0, F22<=0),"N/A",F21-F22) -> 386 | G23: =IF(OR(G21<=0, G22<=0),"N/A",G21-G22) -> -490 | I23: =IF(OR(I21<=0, I22<=0),"N/A",I21-I22) -> -490
B25: DuPont Identity
B26: Profit Margin (Earnings/Revenue) | C26: =Statement!M119 -> 0.14141154 | D26: =Statement!N119 -> -0.071641387 | E26: =Statement!O119 -> 0.051137231 | F26: =Statement!P119 -> 0.16148181 | G26: =Statement!Q119 -> 0.26109061 | I26: =Statement!AC119 -> 0.26109061
B27: Asset Turnover (Revenue/Total assets) | C27: =Statement!M120 -> 1.3037791 | D27: =Statement!N120 -> 0.97723663 | E27: =Statement!O120 -> 0.84649179 | F27: =Statement!P120 -> 1.1338651 | G27: =Statement!Q120 -> 1.2229242 | I27: =Statement!AC120 -> 1.2229242
B28: ROA | C28: =Statement!M121 -> 0.18436941 | D28: =Statement!N121 -> -0.070010588 | E28: =Statement!O121 -> 0.043287246 | F28: =Statement!P121 -> 0.18309859 | G28: =Statement!Q121 -> 0.31929402 | I28: =Statement!AC121 -> 0.31929402
B29: Equity Multiplier (Total assets/Equity) | C29: =Statement!M122 -> 82.055046 | D29: =Statement!N122 -> -6.3019183 | E29: =Statement!O122 -> -5.1904762 | F29: =Statement!P122 -> -17.710817 | G29: =Statement!Q122 -> 4.6017536 | I29: =Statement!AC122 -> 4.6017536
B30: ROE | C30: =Statement!M123 -> 15.12844 | D30: =Statement!N123 -> 0.441201 | E30: =Statement!O123 -> -0.22468142 | F30: =Statement!P123 -> -3.2428256 | G30: =Statement!Q123 -> 1.4693124 | I30: =Statement!AC123 -> 1.4693124
B32: Performance Indicators
B33: ROA | C33: =C28 -> 0.18436941 | D33: =D28 -> -0.070010588 | E33: =E28 -> 0.043287246 | F33: =F28 -> 0.18309859 | G33: =G28 -> 0.31929402 | I33: =I28 -> 0.31929402
B34: ROE | C34: =C30 -> 15.12844 | D34: =D30 -> 0.441201 | E34: =E30 -> -0.22468142 | F34: =F30 -> -3.2428256 | G34: =G30 -> 1.4693124 | I34: =I30 -> 1.4693124
B35: ROIC | C35: =Statement!M138 -> 0.37355418 | D35: =Statement!N138 -> -0.098672822 | E35: =Statement!O138 -> 0.12044944 | F35: =Statement!P138 -> 0.50261198 | G35: =Statement!Q138 -> 0.87701106 | I35: =Statement!AC138 -> 0.87701106
B37: Cash conversion cycle
B38: DSO | C38: =Statement!M139 -> 47.953006 | D38: =Statement!N139 -> 30.696777 | E38: =Statement!O139 -> 23.902458 | F38: =Statement!P139 -> 38.47807 | G38: =Statement!Q139 -> 45.913079 | I38: =Statement!AC139 -> 45.913079
B39: DIO | C39: =Statement!M140 -> 69.729614 | D39: =Statement!N140 -> 68.970661 | E39: =Statement!O140 -> 90.176471 | F39: =Statement!P140 -> 89.130066 | G39: =Statement!Q140 -> 86.396715 | I39: =Statement!AC140 -> 86.396715
B40: DPO | C40: =Statement!M141 -> 91.695557 | D40: =Statement!N141 -> 96.98243 | E40: =Statement!O141 -> 129.98804 | F40: =Statement!P141 -> 99.28099 | G40: =Statement!Q141 -> 96.130782 | I40: =Statement!AC141 -> 96.130782
B41: Net trade cycle | C41: =Statement!M142 -> 25.987063 | D41: =Statement!N142 -> 2.6850082 | E41: =Statement!O142 -> -15.909108 | F41: =Statement!P142 -> 28.327145 | G41: =Statement!Q142 -> 36.179013 | I41: =Statement!AC142 -> 36.179013
B43: Liquidity ratios
B44: Debt/Equity | C44: =Statement!M143 -> 51.798165 | D44: =Statement!N143 -> -4.5462886 | E44: =Statement!O143 -> -3.8054997 | F44: =Statement!P143 -> -11.02649 | G44: =Statement!Q143 -> 1.6451315 | I44: =Statement!AC143 -> 1.6451315
B45: Net Debt/Equity | C45: =Statement!M144 -> 46.155963 | D45: =Statement!N144 -> -3.8907423 | E45: =Statement!O144 -> -2.8947015 | F45: =Statement!P144 -> -9.0596026 | G45: =Statement!Q144 -> 0.85879096 | I45: =Statement!AC144 -> 0.85879096
B46: Quick ratio | C46: =Statement!M145 -> 0.60393812 | D46: =Statement!N145 -> 0.54282407 | E46: =Statement!O145 -> 0.57663763 | F46: =Statement!P145 -> 0.69864048 | G46: =Statement!Q145 -> 1.0354973 | I46: =Statement!AC145 -> 1.0354973
B47: Current ratio | C47: =Statement!M146 -> 1.1344585 | D47: =Statement!N146 -> 1.1207562 | E47: =Statement!O146 -> 1.0751855 | F47: =Statement!P146 -> 1.3795317 | G47: =Statement!Q146 -> 1.6696514 | I47: =Statement!AC146 -> 1.6696514
B48: Interest coverage | C48: =Statement!M147 -> 7.9149798 | D48: =Statement!N147 -> N/A | E48: =Statement!O147 -> 1.4258675 | F48: =Statement!P147 -> 6.3851351 | G48: =Statement!Q147 -> 16.11811 | I48: =Statement!AC147 -> 16.11811
...

Sheet Quarter analysis
C3: Latest 2 quarters | F3: YoY
C4: =Statement!Z2 -> 03.04.2026 | D4: =Statement!AA2 -> 03.07.2026 | F4: =Statement!W2 -> 27.06.2025 | G4: =Statement!AA2 -> 03.07.2026
B5: Income statement growth | C5: =Statement!Z3 -> Q3 2026 | D5: =Statement!AA3 -> Q4 2026 | F5: =Statement!W3 -> Q4 2025 | G5: =Statement!AA3 -> Q4 2026
B6: Revenue | C6: =Statement!Z5 -> 3112 | D6: =Statement!AA5 -> 3629 | F6: =Statement!W5 -> 2444 | G6: =Statement!AA5 -> 3629
B7: Growth | C7: =Statement!AA88 -> 0.16613111 | F7: =IF(F6=0, IF(G6=0,0,IF(G6>0,1,-1)), (G6-F6)/ABS(F6) ) -> 0.48486088
B8: COGS | C8: =Statement!Z6 -> 1665 | D8: =Statement!AA6 -> 1731 | F8: =Statement!W6 -> 1530 | G8: =Statement!AA6 -> 1731
B9: Growth | C9: =Statement!AA89 -> 0.03963964 | F9: =IF(F8=0, IF(G8=0,0,IF(G8>0,1,-1)), (G8-F8)/ABS(F8) ) -> 0.13137255
B10: Gross Profit | C10: =Statement!Z7 -> 1447 | D10: =Statement!AA7 -> 1898 | F10: =Statement!W7 -> 914 | G10: =Statement!AA7 -> 1898
B11: Growth | C11: =Statement!AA90 -> 0.31167934 | F11: =IF(F10=0, IF(G10=0,0,IF(G10>0,1,-1)), (G10-F10)/ABS(F10) ) -> 1.0765864
B12: OpEx | C12: =Statement!Z10 -> 449 | D12: =Statement!AA10 -> 339 | F12: =Statement!W10 -> 346 | G12: =Statement!AA10 -> 339
B13: Growth | C13: =Statement!AA93 -> -0.24498886 | F13: =IF(F12=0, IF(G12=0,0,IF(G12>0,1,-1)), (G12-F12)/ABS(F12) ) -> -0.020231214
B14: Operating profit | C14: =Statement!Z11 -> 998 | D14: =Statement!AA11 -> 1559 | F14: =Statement!W11 -> 568 | G14: =Statement!AA11 -> 1559
B15: Growth | C15: =Statement!AA94 -> 0.56212425 | F15: =IF(F14=0, IF(G14=0,0,IF(G14>0,1,-1)), (G14-F14)/ABS(F14) ) -> 1.7447183
B16: Net income | C16: =Statement!Z17 -> 748 | D16: =Statement!AA17 -> 1294 | F16: =Statement!W17 -> 488 | G16: =Statement!AA17 -> 1294
B17: Growth | C17: =Statement!AA96 -> 0.72994652 | F17: =IF(F16=0, IF(G16=0,0,IF(G16>0,1,-1)), (G16-F16)/ABS(F16) ) -> 1.6516393
B18: Diluted shares outstanding | C18: =Statement!Z21 -> 229 | D18: =Statement!AA21 -> 232 | F18: =Statement!W21 -> 218 | G18: =Statement!AA21 -> 232
B19: Growth | C19: =IF(C18=0, IF(D18=0,0,IF(D18>0,1,-1)), (D18-C18)/ABS(C18) ) -> 0.013100437 | F19: =IF(F18=0, IF(G18=0,0,IF(G18>0,1,-1)), (G18-F18)/ABS(F18) ) -> 0.064220183
B20: Diluted EPS | C20: =Statement!Z25 -> 3.27 | D20: =Statement!AA25 -> 5.58 | F20: =Statement!W25 -> 2.24 | G20: =Statement!AA25 -> 5.58
B21: Growth | C21: =IF(C20=0, IF(D20=0,0,IF(D20>0,1,-1)), (D20-C20)/ABS(C20) ) -> 0.70642202 | F21: =IF(F20=0, IF(G20=0,0,IF(G20>0,1,-1)), (G20-F20)/ABS(F20) ) -> 1.4910714
B23: Revenue breakdown | C23: =C5 -> Q3 2026 | D23: =D5 -> Q4 2026 | F23: =F5 -> Q4 2025 | G23: =G5 -> Q4 2026
B24: =Statement!B185 -> Datacenter | C24: =Statement!Z185 -> 2500 | D24: =Statement!AA185 -> 2933 | F24: =Statement!W185 -> 1863 | G24: =Statement!AA185 -> 2933
B25: Growth | C25: =IF(C24=0, IF(D24=0,0,IF(D24>0,1,-1)), (D24-C24)/ABS(C24) ) -> 0.1732 | F25: =IF(F24=0, IF(G24=0,0,IF(G24>0,1,-1)), (G24-F24)/ABS(F24) ) -> 0.57434246
B26: =Statement!B186 -> Edge & IoT | C26: =Statement!Z186 -> 612 | D26: =Statement!AA186 -> 697 | F26: =Statement!W186 -> 581 | G26: =Statement!AA186 -> 697
B27: Growth | C27: =IF(C26=0, IF(D26=0,0,IF(D26>0,1,-1)), (D26-C26)/ABS(C26) ) -> 0.13888889 | F27: =IF(F26=0, IF(G26=0,0,IF(G26>0,1,-1)), (G26-F26)/ABS(F26) ) -> 0.19965577

Sheet Graphs Year
C55: =Statement!H2 -> 0 | D55: =Statement!I2 -> 0 | E55: =Statement!J2 -> 0 | F55: =Statement!K2 -> 0 | G55: =Statement!L2 -> 02.07.2021 | H55: =Statement!M2 -> 01.07.2022 | I55: =Statement!N2 -> 30.06.2023 | J55: =Statement!O2 -> 28.06.2024 | ... L55: =Statement!Q2 -> 03.07.2026
C56: =Statement!H3 -> 0 | D56: =Statement!I3 -> 0 | E56: =Statement!J3 -> 0 | F56: =Statement!K3 -> 0 | G56: =Statement!L3 -> 2021 | H56: =Statement!M3 -> 2022 | I56: =Statement!N3 -> 2023 | J56: =Statement!O3 -> 2024 | ... L56: =Statement!Q3 -> 2026
B57: Revenue | C57: =Statement!H5 -> 0 | D57: =Statement!I5 -> 0 | E57: =Statement!J5 -> 0 | F57: =Statement!K5 -> 0 | G57: =Statement!L5 -> 10681 | H57: =Statement!M5 -> 11661 | I57: =Statement!N5 -> 7384 | J57: =Statement!O5 -> 6551 | ... L57: =Statement!Q5 -> 12195
B58: Operating income | C58: =Statement!H11 -> 0 | D58: =Statement!I11 -> 0 | E58: =Statement!J11 -> 0 | F58: =Statement!K11 -> 0 | G58: =Statement!L11 -> 1492 | H58: =Statement!M11 -> 1955 | I58: =Statement!N11 -> -342 | J58: =Statement!O11 -> 452 | ... L58: =Statement!Q11 -> 4094
B59: Net income | C59: =Statement!H17 -> 0 | D59: =Statement!I17 -> 0 | E59: =Statement!J17 -> 0 | F59: =Statement!K17 -> 0 | G59: =Statement!L17 -> 1314 | H59: =Statement!M17 -> 1649 | I59: =Statement!N17 -> -529 | J59: =Statement!O17 -> 335 | ... L59: =Statement!Q17 -> 3184
B60: FCFE | C60: =Statement!H155 -> 0 | D60: =Statement!I155 -> 0 | E60: =Statement!J155 -> 0 | F60: =Statement!K155 -> 0 | G60: =Statement!L155 -> 1016 | H60: =Statement!M155 -> 1131 | I60: =Statement!N155 -> 511 | J60: =Statement!O155 -> 537 | ... L60: =Statement!Q155 -> 2892
B61: FCFF | C61: =Statement!H156 -> 0 | D61: =Statement!I156 -> 0 | E61: =Statement!J156 -> 0 | F61: =Statement!K156 -> 0 | G61: =Statement!L156 -> 1209.368 | H61: =Statement!M156 -> 1347.0685 | I61: =Statement!N156 -> 1017 | J61: =Statement!O156 -> 736.26966 | ... L61: =Statement!Q156 -> 3080.6005
B62: Gross margin | C62: =Statement!H99 -> 0 | D62: =Statement!I99 -> 0 | E62: =Statement!J99 -> 0 | F62: =Statement!K99 -> 0 | G62: =Statement!L99 -> 0.27310177 | H62: =Statement!M99 -> 0.29748735 | I62: =Statement!N99 -> 0.18296316 | J62: =Statement!O99 -> 0.23446802 | ... L62: =Statement!Q99 -> 0.45576056
B63: Operating margin | C63: =Statement!H100 -> 0 | D63: =Statement!I100 -> 0 | E63: =Statement!J100 -> 0 | F63: =Statement!K100 -> 0 | G63: =Statement!L100 -> 0.1396873 | H63: =Statement!M100 -> 0.16765286 | I63: =Statement!N100 -> -0.04631636 | J63: =Statement!O100 -> 0.0689971 | ... L63: =Statement!Q100 -> 0.33571136
B64: Net margin | C64: =Statement!H101 -> 0 | D64: =Statement!I101 -> 0 | E64: =Statement!J101 -> 0 | F64: =Statement!K101 -> 0 | G64: =Statement!L101 -> 0.12302219 | H64: =Statement!M101 -> 0.14141154 | I64: =Statement!N101 -> -0.071641387 | J64: =Statement!O101 -> 0.051137231 | ... L64: =Statement!Q101 -> 0.26109061
B65: ="Revenue "&Statement!B185 -> Revenue Datacenter | C65: =Statement!H185 -> 0 | D65: =Statement!I185 -> 0 | E65: =Statement!J185 -> 0 | F65: =Statement!K185 -> 0 | G65: =Statement!L185 -> 0 | H65: =Statement!M185 -> 0 | I65: =Statement!N185 -> 0 | J65: =Statement!O185 -> 0 | ... L65: =Statement!Q185 -> 9771
B66: ="Revenue "&Statement!B186 -> Revenue Edge & IoT | C66: =Statement!H186 -> 0 | D66: =Statement!I186 -> 0 | E66: =Statement!J186 -> 0 | F66: =Statement!K186 -> 0 | G66: =Statement!L186 -> 0 | H66: =Statement!M186 -> 0 | I66: =Statement!N186 -> 0 | J66: =Statement!O186 -> 0 | ... L66: =Statement!Q186 -> 2425
B67: ROA | C67: =Statement!H121 -> 0 | D67: =Statement!I121 -> 0 | E67: =Statement!J121 -> 0 | F67: =Statement!K121 -> 0 | G67: =Statement!L121 -> 0.15146974 | H67: =Statement!M121 -> 0.18436941 | I67: =Statement!N121 -> -0.070010588 | J67: =Statement!O121 -> 0.043287246 | ... L67: =Statement!Q121 -> 0.31929402
B68: ROE | C68: =Statement!H123 -> 0 | D68: =Statement!I123 -> 0 | E68: =Statement!J123 -> 0 | F68: =Statement!K123 -> 0 | G68: =Statement!L123 -> 2.0824089 | H68: =Statement!M123 -> 15.12844 | I68: =Statement!N123 -> 0.441201 | J68: =Statement!O123 -> -0.22468142 | ... L68: =Statement!Q123 -> 1.4693124
B69: ROIC | C69: =Statement!H138 -> 0 | D69: =Statement!I138 -> 0 | E69: =Statement!J138 -> 0 | F69: =Statement!K138 -> 0 | G69: =Statement!L138 -> 0.31887041 | H69: =Statement!M138 -> 0.37355418 | I69: =Statement!N138 -> -0.098672822 | J69: =Statement!O138 -> 0.12044944 | ... L69: =Statement!Q138 -> 0.87701106
B70: Price 5y | C70: =Statement!H199 -> 0 | D70: =Statement!I199 -> 0 | E70: =Statement!J199 -> 0 | F70: =Statement!K199 -> 0 | G70: =Statement!L199 -> 100 | H70: =Statement!M199 -> 100 | I70: =Statement!N199 -> 89.549862 | J70: =Statement!O199 -> 149.4717 | ... L70: =Statement!Q199 -> 1187.0893
B71: Revenue 5y | C71: =Statement!H200 -> 0 | D71: =Statement!I200 -> 0 | E71: =Statement!J200 -> 0 | F71: =Statement!K200 -> 0 | G71: =Statement!L200 -> 100 | H71: =Statement!M200 -> 100 | I71: =Statement!N200 -> 63.322185 | J71: =Statement!O200 -> 56.178715 | ... L71: =Statement!Q200 -> 104.57937
B72: EPS 5y | C72: =Statement!H201 -> 0 | D72: =Statement!I201 -> 0 | E72: =Statement!J201 -> 0 | F72: =Statement!K201 -> 0 | G72: =Statement!L201 -> 100 | H72: =Statement!M201 -> 100 | I72: =Statement!N201 -> -34.782609 | J72: =Statement!O201 -> 21.467391 | ... L72: =Statement!Q201 -> 188.8587

Sheet Graphs Quarter
C55: =Statement!T2 -> 27.09.2024 | D55: =Statement!U2 -> 27.12.2024 | E55: =Statement!V2 -> 28.03.2025 | F55: =Statement!W2 -> 27.06.2025 | G55: =Statement!X2 -> 03.10.2025 | H55: =Statement!Y2 -> 02.01.2026 | I55: =Statement!Z2 -> 03.04.2026 | J55: =Statement!AA2 -> 03.07.2026
C56: =Statement!T3 -> Q1 2025 | D56: =Statement!U3 -> Q2 2025 | E56: =Statement!V3 -> Q3 2025 | F56: =Statement!W3 -> Q4 2025 | G56: =Statement!X3 -> Q1 2026 | H56: =Statement!Y3 -> Q2 2026 | I56: =Statement!Z3 -> Q3 2026 | J56: =Statement!AA3 -> Q4 2026
B57: Revenue | C57: =Statement!T5 -> 2168 | D57: =Statement!U5 -> 2325 | E57: =Statement!V5 -> 2160 | F57: =Statement!W5 -> 2444 | G57: =Statement!X5 -> 2629 | H57: =Statement!Y5 -> 2825 | I57: =Statement!Z5 -> 3112 | J57: =Statement!AA5 -> 3629
B58: Operating income | C58: =Statement!T11 -> 403 | D58: =Statement!U11 -> 488 | E58: =Statement!V11 -> 431 | F58: =Statement!W11 -> 568 | G58: =Statement!X11 -> 694 | H58: =Statement!Y11 -> 843 | I58: =Statement!Z11 -> 998 | J58: =Statement!AA11 -> 1559
B59: Net income | C59: =Statement!T17 -> 305 | D59: =Statement!U17 -> 336 | E59: =Statement!V17 -> 340 | F59: =Statement!W17 -> 488 | G59: =Statement!X17 -> 549 | H59: =Statement!Y17 -> 593 | I59: =Statement!Z17 -> 748 | J59: =Statement!AA17 -> 1294
B60: Gross margin | C60: =Statement!T99 -> 0.32933579 | D60: =Statement!U99 -> 0.34924731 | E60: =Statement!V99 -> 0.35185185 | F60: =Statement!W99 -> 0.37397709 | G60: =Statement!X99 -> 0.39444656 | H60: =Statement!Y99 -> 0.41628319 | I60: =Statement!Z99 -> 0.46497429 | J60: =Statement!AA99 -> 0.52300909
B61: Operating margin | C61: =Statement!T100 -> 0.18588561 | D61: =Statement!U100 -> 0.20989247 | E61: =Statement!V100 -> 0.19953704 | F61: =Statement!W100 -> 0.23240589 | G61: =Statement!X100 -> 0.2639787 | H61: =Statement!Y100 -> 0.29840708 | I61: =Statement!Z100 -> 0.32069409 | J61: =Statement!AA100 -> 0.42959493
B62: Net margin | C62: =Statement!T101 -> 0.14068266 | D62: =Statement!U101 -> 0.14451613 | E62: =Statement!V101 -> 0.15740741 | F62: =Statement!W101 -> 0.19967267 | G62: =Statement!X101 -> 0.20882465 | H62: =Statement!Y101 -> 0.2099115 | I62: =Statement!Z101 -> 0.2403599 | J62: =Statement!AA101 -> 0.35657206
B63: ="Revenue "&Statement!B185 -> Revenue Datacenter | C63: =Statement!T185 -> 1582 | D63: =Statement!U185 -> 1736 | E63: =Statement!V185 -> 1615 | F63: =Statement!W185 -> 1863 | G63: =Statement!X185 -> 2114 | H63: =Statement!Y185 -> 2224 | I63: =Statement!Z185 -> 2500 | J63: =Statement!AA185 -> 2933
B64: ="Revenue "&Statement!B186 -> Revenue Edge & IoT | C64: =Statement!T186 -> 585 | D64: =Statement!U186 -> 589 | E64: =Statement!V186 -> 545 | F64: =Statement!W186 -> 581 | G64: =Statement!X186 -> 515 | H64: =Statement!Y186 -> 601 | I64: =Statement!Z186 -> 612 | J64: =Statement!AA186 -> 697
B65: FCFE | C65: =Statement!T155 -> -11 | D65: =Statement!U155 -> 101 | E65: =Statement!V155 -> 162 | F65: =Statement!W155 -> 366 | G65: =Statement!X155 -> 375 | H65: =Statement!Y155 -> 554 | I65: =Statement!Z155 -> 899 | J65: =Statement!AA155 -> 1064

Sheet Forecast ->
H5: Links
H6: Overview'!B3
H7: Financials ->'!B13
H8: Analysis ->'!B13
H9: Forecast ->'!B13
H10: Valuation ->'!B13
B13: Forecast ->

Sheet Revenue
B1: Revenue forecast
C2: History | H2: Forecast | S2: History | AA2: Forecast | AE2: TTM
C4: Revenues | S4: Revenues
B5: Revenues (thousand) | C5: =Statement!M3 -> 2022 | D5: =Statement!N3 -> 2023 | E5: =Statement!O3 -> 2024 | F5: =Statement!P3 -> 2025 | G5: =Statement!Q3 -> 2026 | H5: =G5+1 -> 2027 | I5: =H5+1 -> 2028 | J5: =I5+1 -> 2029 | K5: =J5+1 -> 2030 | L5: =K5+1 -> 2031 | R5: =B5 -> Revenues (thousand) | S5: =Statement!T3 -> Q1 2025 | T5: =Statement!U3 -> Q2 2025 | U5: =Statement!V3 -> Q3 2025 | V5: =Statement!W3 -> Q4 2025 | W5: =Statement!X3 -> Q1 2026 | X5: =Statement!Y3 -> Q2 2026 | Y5: =Statement!Z3 -> Q3 2026 | Z5: =Statement!AA3 -> Q4 2026 | AA5: FQ1 | AB5: FQ2 | AC5: FQ3 | AE5: FQ1
B6: =Statement!B185 -> Datacenter | C6: =Statement!M185 -> 0 | D6: =Statement!N185 -> 0 | E6: =Statement!O185 -> 0 | F6: =Statement!P185 -> 6796 | G6: =Statement!Q185 -> 9771 | H6: =H19*H20 -> 13366.728 | I6: =I19*I20 -> 17543.831 | J6: =J19*J20 -> 18333.303 | K6: =K19*K20 -> 17416.638 | L6: =L19*L20 -> 14891.225 | N6: Nearline exabytes * price per exabyte | Q6: Nearline exabytes * price per exabyte | R6: =B6 -> Datacenter | S6: =Statement!T185 -> 1582 | T6: =Statement!U185 -> 1736 | U6: =Statement!V185 -> 1615 | V6: =Statement!W185 -> 1863 | W6: =Statement!X185 -> 2114 | X6: =Statement!Y185 -> 2224 | Y6: =Statement!Z185 -> 2500 | Z6: =Statement!AA185 -> 2933 | AA6: =AA19*AA20 -> 3262.6692 | AE6: =SUM(X6:AA6) -> 10919.669
B7: =Statement!B186 -> Edge & IoT | C7: =Statement!M186 -> 0 | D7: =Statement!N186 -> 0 | E7: =Statement!O186 -> 0 | F7: =Statement!P186 -> 2300 | G7: =Statement!Q186 -> 2425 | H7: =G7*(1+H13) -> 2788.75 | I7: =H7*(1+I13) -> 3346.5 | J7: =I7*(1+J13) -> 3681.15 | K7: =J7*(1+K13) -> 3865.2075 | L7: =K7*(1+L13) -> 3478.6868 | N7: Edge & IoT Growth Rate | Q7: Edge & IoT Growth Rate | R7: =B7 -> Edge & IoT | S7: =Statement!T186 -> 585 | T7: =Statement!U186 -> 589 | U7: =Statement!V186 -> 545 | V7: =Statement!W186 -> 581 | W7: =Statement!X186 -> 515 | X7: =Statement!Y186 -> 601 | Y7: =Statement!Z186 -> 612 | Z7: =Statement!AA186 -> 697 | AA7: =Z7*(1+AA13) -> 738.82 | AE7: =SUM(X7:AA7) -> 2648.82
B8: Total | C8: =Statement!M5 -> 11661 | D8: =Statement!N5 -> 7384 | E8: =Statement!O5 -> 6551 | F8: =Statement!P5 -> 9097 | G8: =Statement!Q5 -> 12195 | H8: =SUM(H6:H7) -> 16155.478 | I8: =SUM(I6:I7) -> 20890.331 | J8: =SUM(J6:J7) -> 22014.453 | K8: =SUM(K6:K7) -> 21281.845 | L8: =SUM(L6:L7) -> 18369.912 | R8: Total | S8: =Statement!T5 -> 2168 | T8: =Statement!U5 -> 2325 | U8: =Statement!V5 -> 2160 | V8: =Statement!W5 -> 2444 | W8: =Statement!X5 -> 2629 | X8: =Statement!Y5 -> 2825 | Y8: =Statement!Z5 -> 3112 | Z8: =Statement!AA5 -> 3629 | AA8: =SUM(AA6:AA7) -> 4001.4892 | AE8: =SUM(X8:AA8) -> 13567.489
C10: Growth rates | S10: Growth rates
B11: Revenue growth % | C11: =C5 -> 2022 | D11: =D5 -> 2023 | E11: =E5 -> 2024 | F11: =F5 -> 2025 | G11: =G5 -> 2026 | H11: =H5 -> 2027 | I11: =I5 -> 2028 | J11: =J5 -> 2029 | ... L11: =L5 -> 2031 | R11: Revenue growth % | S11: =S5 -> Q1 2025 | T11: =T5 -> Q2 2025 | U11: =U5 -> Q3 2025 | V11: =V5 -> Q4 2025 | W11: =W5 -> Q1 2026 | X11: =X5 -> Q2 2026 | Y11: =Y5 -> Q3 2026 | Z11: =Z5 -> Q4 2026 | ... AC11: =AC5 -> FQ3
B12: =B6 -> Datacenter | D12: =D6/C6-1 -> #DIV/0! | E12: =E6/D6-1 -> #DIV/0! | F12: =F6/E6-1 -> #DIV/0! | G12: =G6/F6-1 -> 0.4377575 | H12: =H6/G6-1 -> 0.368 | I12: =I6/H6-1 -> 0.3125 | J12: =J6/I6-1 -> 0.045 | K12: =K6/J6-1 -> -0.05 | L12: =L6/K6-1 -> -0.145 | R12: =R6 -> Datacenter | T12: =T6/S6-1 -> 0.097345133 | U12: =U6/T6-1 -> -0.069700461 | V12: =V6/U6-1 -> 0.15356037 | W12: =W6/V6-1 -> 0.13472893 | X12: =X6/W6-1 -> 0.052034059 | Y12: =Y6/X6-1 -> 0.12410072 | Z12: =Z6/Y6-1 -> 0.1732 | AA12: =AA6/Z6-1 -> 0.1124
B13: =B7 -> Edge & IoT | D13: =D7/C7-1 -> #DIV/0! | E13: =E7/D7-1 -> #DIV/0! | F13: =F7/E7-1 -> #DIV/0! | G13: =G7/F7-1 -> 0.054347826 | H13: 0.15 | I13: 0.2 | J13: 0.1 | K13: 0.05 | L13: -0.1 | R13: =R7 -> Edge & IoT | T13: =T7/S7-1 -> 0.0068376068 | U13: =U7/T7-1 -> -0.074702886 | V13: =V7/U7-1 -> 0.066055046 | W13: =W7/V7-1 -> -0.11359725 | X13: =X7/W7-1 -> 0.16699029 | Y13: =Y7/X7-1 -> 0.018302829 | Z13: =Z7/Y7-1 -> 0.13888889 | AA13: 0.06
B14: =B8 -> Total | D14: =D8/C8-1 -> -0.36677815 | E14: =E8/D8-1 -> -0.11281148 | F14: =F8/E8-1 -> 0.38864296 | G14: =G8/F8-1 -> 0.34055183 | H14: =H8/G8-1 -> 0.32476244 | I14: =I8/H8-1 -> 0.29308031 | J14: =J8/I8-1 -> 0.053810655 | K14: =K8/J8-1 -> -0.033278485 | L14: =L8/K8-1 -> -0.1368271 | R14: =R8 -> Total | T14: =T8/S8-1 -> 0.072416974 | U14: =U8/T8-1 -> -0.070967742 | V14: =V8/U8-1 -> 0.13148148 | W14: =W8/V8-1 -> 0.075695581 | X14: =X8/W8-1 -> 0.074553062 | Y14: =Y8/X8-1 -> 0.10159292 | Z14: =Z8/Y8-1 -> 0.16613111 | AA14: =AA8/Z8-1 -> 0.10264238
C17: Metrics | S17: Revenues
C18: =C5 -> 2022 | D18: =D5 -> 2023 | E18: =E5 -> 2024 | F18: =F5 -> 2025 | G18: =G5 -> 2026 | H18: =H5 -> 2027 | I18: =I5 -> 2028 | J18: =J5 -> 2029 | ... L18: =L5 -> 2031 | S18: =S5 -> Q1 2025 | T18: =T5 -> Q2 2025 | U18: =U5 -> Q3 2025 | V18: =V5 -> Q4 2025 | W18: =W5 -> Q1 2026 | X18: =X5 -> Q2 2026 | Y18: =Y5 -> Q3 2026 | Z18: =Z5 -> Q4 2026 | ... AC18: =AC5 -> FQ3 | AE18: =AE5 -> FQ1
B19: =Statement!B206&" exabytes" -> Nearline exabytes | C19: =Statement!M206 -> 0 | D19: =Statement!N206 -> 0 | E19: =Statement!O206 -> 0 | F19: =Statement!P206 -> 496.6 | G19: =Statement!Q206 -> 695 | H19: =G19*(1+H21) -> 834 | I19: =H19*(1+I21) -> 1042.5 | J19: =I19*(1+J21) -> 1146.75 | K19: =J19*(1+K21) -> 1146.75 | L19: =K19*(1+L21) -> 1032.075 | N19: Nearline exabytes growth rate | Q19: Nearline exabytes growth rate | R19: =B19 -> Nearline exabytes | S19: =Statement!T206 -> 114 | T19: =Statement!U206 -> 126 | U19: =Statement!V206 -> 119.6 | V19: =Statement!W206 -> 137 | W19: =Statement!X206 -> 159 | X19: =Statement!Y206 -> 165 | Y19: =Statement!Z206 -> 175.4 | Z19: =Statement!AA206 -> 195 | AA19: =Z19*(1+AA21) -> 210.6 | AE19: =SUM(X19:AA19) -> 746
B20: =Statement!B209 -> Price per Exabyte | C20: =Statement!M209 -> #DIV/0! | D20: =Statement!N209 -> #DIV/0! | E20: =Statement!O209 -> #DIV/0! | F20: =Statement!P209 -> 13.685058 | G20: =Statement!Q209 -> 14.058993 | H20: =G20*(1+H22) -> 16.027252 | I20: =H20*(1+I22) -> 16.828614 | J20: =I20*(1+J22) -> 15.987184 | K20: =J20*(1+K22) -> 15.187824 | L20: =K20*(1+L22) -> 14.428433 | N20: Price per exabyte growth rate | Q20: Price per exabyte growth rate | R20: =B20 -> Price per Exabyte | S20: =Statement!T209 -> 13.877193 | T20: =Statement!U209 -> 13.777778 | U20: =Statement!V209 -> 13.503344 | V20: =Statement!W209 -> 13.59854 | W20: =Statement!X209 -> 13.295597 | X20: =Statement!Y209 -> 13.478788 | Y20: =Statement!Z209 -> 14.253136 | Z20: =Statement!AA209 -> 15.041026 | AA20: =Z20*(1+AA22) -> 15.492256 | AE20: =AE6/AE19 -> 14.637626
B21: =B19&" growth" -> Nearline exabytes growth | D21: =D19/C19-1 -> #DIV/0! | E21: =E19/D19-1 -> #DIV/0! | F21: =F19/E19-1 -> #DIV/0! | G21: =G19/F19-1 -> 0.39951671 | H21: 0.2 | I21: 0.25 | J21: 0.1 | K21: 0 | L21: -0.1 | R21: =R19&" growth" -> Nearline exabytes growth | T21: =T19/S19-1 -> 0.10526316 | U21: =U19/T19-1 -> -0.050793651 | V21: =V19/U19-1 -> 0.14548495 | W21: =W19/V19-1 -> 0.16058394 | X21: =X19/W19-1 -> 0.037735849 | Y21: =Y19/X19-1 -> 0.063030303 | Z21: =Z19/Y19-1 -> 0.11174458 | AA21: 0.08
B22: =B20&" growth" -> Price per Exabyte growth | D22: =D20/C20-1 -> #DIV/0! | E22: =E20/D20-1 -> #DIV/0! | F22: =F20/E20-1 -> #DIV/0! | G22: =G20/F20-1 -> 0.027324283 | H22: 0.14 | I22: 0.05 | J22: -0.05 | K22: -0.05 | L22: -0.05 | R22: =R20&" growth" -> Price per Exabyte growth | T22: =T20/S20-1 -> -0.0071639275 | U22: =U20/T20-1 -> -0.019918546 | V22: =V20/U20-1 -> 0.0070497842 | W22: =W20/V20-1 -> -0.022277587 | X22: =X20/W20-1 -> 0.013778275 | Y22: =Y20/X20-1 -> 0.057449365 | Z22: =Z20/Y20-1 -> 0.055278359 | AA22: 0.03

Sheet COGS & OpEx
B1: COGS & OpEx forecast
C2: History | H2: Forecast | P2: History | X2: Forecast | AB2: TTM
C4: Revenues | P4: Revenues
B5: =Revenue!B5 -> Revenues (thousand) | C5: =Revenue!C5 -> 2022 | D5: =Revenue!D5 -> 2023 | E5: =Revenue!E5 -> 2024 | F5: =Revenue!F5 -> 2025 | G5: =Revenue!G5 -> 2026 | H5: =G5+1 -> 2027 | I5: =H5+1 -> 2028 | J5: =I5+1 -> 2029 | K5: =J5+1 -> 2030 | L5: =K5+1 -> 2031 | O5: Revenues (thousand) | P5: =Revenue!S5 -> Q1 2025 | Q5: =Revenue!T5 -> Q2 2025 | R5: =Revenue!U5 -> Q3 2025 | S5: =Revenue!V5 -> Q4 2025 | T5: =Revenue!W5 -> Q1 2026 | U5: =Revenue!X5 -> Q2 2026 | V5: =Revenue!Y5 -> Q3 2026 | W5: =Revenue!Z5 -> Q4 2026 | X5: FQ1 | Y5: FQ2 | Z5: FQ3 | AB5: =Revenue!AE5 -> FQ1
B6: Revenue | C6: =Revenue!C8 -> 11661 | D6: =Revenue!D8 -> 7384 | E6: =Revenue!E8 -> 6551 | F6: =Revenue!F8 -> 9097 | G6: =Revenue!G8 -> 12195 | H6: =Revenue!H8 -> 16155.478 | I6: =Revenue!I8 -> 20890.331 | J6: =Revenue!J8 -> 22014.453 | ... L6: =Revenue!L8 -> 18369.912 | O6: Revenue | P6: =Revenue!S8 -> 2168 | Q6: =Revenue!T8 -> 2325 | R6: =Revenue!U8 -> 2160 | S6: =Revenue!V8 -> 2444 | T6: =Revenue!W8 -> 2629 | U6: =Revenue!X8 -> 2825 | V6: =Revenue!Y8 -> 3112 | W6: =Revenue!Z8 -> 3629 | X6: =Revenue!AA8 -> 4001.4892 | AB6: =Revenue!AE8 -> 13567.489
C9: COGS and OpEx | P9: COGS & OpEx | AB9: =AB4 -> 0
B10: Expenses (tnousand) | C10: =C5 -> 2022 | D10: =D5 -> 2023 | E10: =E5 -> 2024 | F10: =F5 -> 2025 | G10: =G5 -> 2026 | H10: =H5 -> 2027 | I10: =I5 -> 2028 | J10: =J5 -> 2029 | ... L10: =L5 -> 2031 | O10: Expenses (thousand) | P10: =P5 -> Q1 2025 | Q10: =Q5 -> Q2 2025 | R10: =R5 -> Q3 2025 | S10: =S5 -> Q4 2025 | T10: =T5 -> Q1 2026 | U10: =U5 -> Q2 2026 | V10: =V5 -> Q3 2026 | W10: =W5 -> Q4 2026 | ... Z10: =Z5 -> FQ3 | AB10: =AB5 -> FQ1
B11: COGS | C11: =Statement!M6 -> 8192 | D11: =Statement!N6 -> 6033 | E11: =Statement!O6 -> 5015 | F11: =Statement!P6 -> 5897 | G11: =Statement!Q6 -> 6637 | H11: =H6*H19 -> 8885.5129 | I11: =I6*I19 -> 10027.359 | J11: =J6*J19 -> 10346.793 | K11: =K6*K19 -> 10428.104 | L11: =L6*L19 -> 10103.452 | O11: =B11 -> COGS | P11: =Statement!T6 -> 1454 | Q11: =Statement!U6 -> 1513 | R11: =Statement!V6 -> 1400 | S11: =Statement!W6 -> 1530 | T11: =Statement!X6 -> 1592 | U11: =Statement!Y6 -> 1649 | V11: =Statement!Z6 -> 1665 | W11: =Statement!AA6 -> 1731 | X11: =X6*X19 -> 1800.6701 | AB11: =SUM(U11:X11) -> 6845.6701
B12: =Statement!B8 -> R&D | C12: =Statement!M8 -> 941 | D12: =Statement!N8 -> 797 | E12: =Statement!O8 -> 654 | F12: =Statement!P8 -> 724 | G12: =Statement!Q8 -> 755 | H12: =H6*H20 -> 1130.8835 | I12: =I6*I20 -> 1671.2264 | J12: =J6*J20 -> 1981.3008 | K12: =K6*K20 -> 1915.3661 | L12: =L6*L20 -> 1836.9912 | O12: =B12 -> R&D | P12: =Statement!T8 -> 181 | Q12: =Statement!U8 -> 184 | R12: =Statement!V8 -> 180 | S12: =Statement!W8 -> 179 | T12: =Statement!X8 -> 186 | U12: =Statement!Y8 -> 187 | V12: =Statement!Z8 -> 194 | W12: =Statement!AA8 -> 188 | X12: =X20*X$6 -> 200.07446 | AB12: =SUM(U12:X12) -> 769.07446
B13: =Statement!B9 -> SG&A | C13: =Statement!M9 -> 559 | D13: =Statement!N9 -> 491 | E13: =Statement!O9 -> 460 | F13: =Statement!P9 -> 561 | G13: =Statement!Q9 -> 577 | H13: =H6*H21 -> 726.99651 | I13: =I6*I21 -> 1044.5165 | J13: =J6*J21 -> 1320.8672 | K13: =K6*K21 -> 1702.5476 | L13: =L6*L21 -> 2020.6903 | O13: =B13 -> SG&A | P13: =Statement!T9 -> 129 | Q13: =Statement!U9 -> 139 | R13: =Statement!V9 -> 139 | S13: =Statement!W9 -> 154 | T13: =Statement!X9 -> 144 | U13: =Statement!Y9 -> 143 | V13: =Statement!Z9 -> 143 | W13: =Statement!AA9 -> 147 | X13: =X21*X$6 -> 160.05957 | AB13: =SUM(U13:X13) -> 593.05957
B14: OpEx | C14: =Statement!M10 -> 1514 | D14: =Statement!N10 -> 1693 | E14: =Statement!O10 -> 1084 | F14: =Statement!P10 -> 1310 | G14: =Statement!Q10 -> 1464 | H14: =SUM(H12:H13) -> 1857.88 | I14: =SUM(I12:I13) -> 2715.743 | J14: =SUM(J12:J13) -> 3302.1679 | K14: =SUM(K12:K13) -> 3617.9137 | L14: =SUM(L12:L13) -> 3857.6815 | O14: =B14 -> OpEx | P14: =Statement!T10 -> 311 | Q14: =Statement!U10 -> 324 | R14: =Statement!V10 -> 329 | S14: =Statement!W10 -> 346 | T14: =Statement!X10 -> 343 | U14: =Statement!Y10 -> 333 | V14: =Statement!Z10 -> 449 | W14: =Statement!AA10 -> 339 | X14: =SUM(X12:X13) -> 360.13403 | AB14: =SUM(U14:X14) -> 1481.134
C17: Expenses % of Revenue | P17: Expenses % of Revenue
B18: % of revenue | C18: =C5 -> 2022 | D18: =D5 -> 2023 | E18: =E5 -> 2024 | F18: =F5 -> 2025 | G18: =G5 -> 2026 | H18: =H5 -> 2027 | I18: =I5 -> 2028 | J18: =J5 -> 2029 | ... L18: =L5 -> 2031 | O18: % of revenue | P18: =P5 -> Q1 2025 | Q18: =Q5 -> Q2 2025 | R18: =R5 -> Q3 2025 | S18: =S5 -> Q4 2025 | T18: =T5 -> Q1 2026 | U18: =U5 -> Q2 2026 | V18: =V5 -> Q3 2026 | W18: =W5 -> Q4 2026 | ... Z18: =Z5 -> FQ3
B19: =B11 -> COGS | C19: =C11/C$6 -> 0.70251265 | D19: =D11/D$6 -> 0.81703684 | E19: =E11/E$6 -> 0.76553198 | F19: =F11/F$6 -> 0.64823568 | G19: =G11/G$6 -> 0.54423944 | H19: 0.55 | I19: 0.48 | J19: 0.47 | K19: 0.49 | L19: 0.55 | O19: =O11 -> COGS | P19: =P11/P$6 -> 0.67066421 | Q19: =Q11/Q$6 -> 0.65075269 | R19: =R11/R$6 -> 0.64814815 | S19: =S11/S$6 -> 0.62602291 | T19: =T11/T$6 -> 0.60555344 | U19: =U11/U$6 -> 0.58371681 | V19: =V11/V$6 -> 0.53502571 | W19: =W11/W$6 -> 0.47699091 | X19: 0.45
B20: =B12 -> R&D | C20: =C12/C$6 -> 0.080696338 | D20: =D12/D$6 -> 0.10793608 | E20: =E12/E$6 -> 0.099832087 | F20: =F12/F$6 -> 0.079586677 | G20: =G12/G$6 -> 0.061910619 | H20: 0.07 | I20: 0.08 | J20: 0.09 | K20: 0.09 | L20: 0.1 | O20: =O12 -> R&D | P20: =P12/P$6 -> 0.083487085 | Q20: =Q12/Q$6 -> 0.079139785 | R20: =R12/R$6 -> 0.083333333 | S20: =S12/S$6 -> 0.073240589 | T20: =T12/T$6 -> 0.070749334 | U20: =U12/U$6 -> 0.06619469 | V20: =V12/V$6 -> 0.062339332 | W20: =W12/W$6 -> 0.051804905 | X20: 0.05
B21: =B13 -> SG&A | C21: =C13/C$6 -> 0.04793757 | D21: =D13/D$6 -> 0.066495125 | E21: =E13/E$6 -> 0.070218287 | F21: =F13/F$6 -> 0.061668682 | G21: =G13/G$6 -> 0.047314473 | H21: 0.045 | I21: 0.05 | J21: 0.06 | K21: 0.08 | L21: 0.11 | O21: =O13 -> SG&A | P21: =P13/P$6 -> 0.059501845 | Q21: =Q13/Q$6 -> 0.059784946 | R21: =R13/R$6 -> 0.064351852 | S21: =S13/S$6 -> 0.063011457 | T21: =T13/T$6 -> 0.054773678 | U21: =U13/U$6 -> 0.050619469 | V21: =V13/V$6 -> 0.045951157 | W21: =W13/W$6 -> 0.040507027 | X21: 0.04
B22: =B14 -> OpEx | C22: =C14/C$6 -> 0.12983449 | D22: =D14/D$6 -> 0.22927952 | E22: =E14/E$6 -> 0.16547092 | F22: =F14/F$6 -> 0.14400352 | G22: =G14/G$6 -> 0.1200492 | H22: =H14/H$6 -> 0.115 | I22: =I14/I$6 -> 0.13 | J22: =J14/J$6 -> 0.15 | ... L22: =L14/L$6 -> 0.21 | O22: =O14 -> OpEx | P22: =P14/P$6 -> 0.14345018 | Q22: =Q14/Q$6 -> 0.13935484 | R22: =R14/R$6 -> 0.15231481 | S22: =S14/S$6 -> 0.14157119 | T22: =T14/T$6 -> 0.13046786 | U22: =U14/U$6 -> 0.11787611 | V22: =V14/V$6 -> 0.14428021 | W22: =W14/W$6 -> 0.093414164 | X22: =X14/X$6 -> 0.09

Sheet WC & Investments
B1: Working Capital, Capex, D&A
C3: History | H3: Forecast
C5: Revenues
B6: Revenues (thousand) | C6: =Revenue!C5 -> 2022 | D6: =Revenue!D5 -> 2023 | E6: =Revenue!E5 -> 2024 | F6: =Revenue!F5 -> 2025 | G6: =Revenue!G5 -> 2026 | H6: =G6+1 -> 2027 | I6: =H6+1 -> 2028 | J6: =I6+1 -> 2029 | K6: =J6+1 -> 2030 | L6: =K6+1 -> 2031
B7: Revenue | C7: =Revenue!C8 -> 11661 | D7: =Revenue!D8 -> 7384 | E7: =Revenue!E8 -> 6551 | F7: =Revenue!F8 -> 9097 | G7: =Revenue!G8 -> 12195 | H7: =Revenue!H8 -> 16155.478 | I7: =Revenue!I8 -> 20890.331 | J7: =Revenue!J8 -> 22014.453 | ... L7: =Revenue!L8 -> 18369.912
B8: COGS | C8: ='COGS & OpEx'!C11 -> 8192 | D8: ='COGS & OpEx'!D11 -> 6033 | E8: ='COGS & OpEx'!E11 -> 5015 | F8: ='COGS & OpEx'!F11 -> 5897 | G8: ='COGS & OpEx'!G11 -> 6637 | H8: ='COGS & OpEx'!H11 -> 8885.5129 | I8: ='COGS & OpEx'!I11 -> 10027.359 | J8: ='COGS & OpEx'!J11 -> 10346.793 | ... L8: ='COGS & OpEx'!L11 -> 10103.452
C11: Working Capital
B12: $ (thousand) | C12: =C6 -> 2022 | D12: =D6 -> 2023 | E12: =E6 -> 2024 | F12: =F6 -> 2025 | G12: =G6 -> 2026 | H12: =H6 -> 2027 | I12: =I6 -> 2028 | J12: =J6 -> 2029 | ... L12: =L6 -> 2031
B13: Accounts receivable | C13: =Statement!M29 -> 1532 | D13: =Statement!N29 -> 621 | E13: =Statement!O29 -> 429 | F13: =Statement!P29 -> 959 | G13: =Statement!Q29 -> 1534 | H13: =H20*H7/365 -> 1770.4633 | I13: =I20*I7/365 -> 2289.3513 | J13: =J20*J7/365 -> 2412.5428 | K13: =K20*K7/365 -> 2332.257 | L13: =L20*L7/365 -> 2013.141
B14: Inventory | C14: =Statement!M30 -> 1565 | D14: =Statement!N30 -> 1140 | E14: =Statement!O30 -> 1239 | F14: =Statement!P30 -> 1440 | G14: =Statement!Q30 -> 1571 | H14: =H21*H8/365 -> 1923.1658 | I14: =I21*I8/365 -> 2170.305 | J14: =J21*J8/365 -> 2239.4428 | K14: =K21*K8/365 -> 2257.0417 | L14: =L21*L8/365 -> 2186.7745
B15: Accounts payable | C15: =Statement!M37 -> 2058 | D15: =Statement!N37 -> 1603 | E15: =Statement!O37 -> 1786 | F15: =Statement!P37 -> 1604 | G15: =Statement!Q37 -> 1748 | H15: =H22*H8/365 -> 2312.6677 | I15: =I22*I8/365 -> 2609.8605 | J15: =J22*J8/365 -> 2693.0009 | K15: =K22*K8/365 -> 2714.1641 | L15: =L22*L8/365 -> 2629.6655
C18: WC metrics and drivers
B19: Days | C19: =C6 -> 2022 | D19: =D6 -> 2023 | E19: =E6 -> 2024 | F19: =F6 -> 2025 | G19: =G6 -> 2026 | H19: =H6 -> 2027 | I19: =I6 -> 2028 | J19: =J6 -> 2029 | ... L19: =L6 -> 2031
B20: DSO | C20: =C13/C7*365 -> 47.953006 | D20: =D13/D7*365 -> 30.696777 | E20: =E13/E7*365 -> 23.902458 | F20: =F13/F7*365 -> 38.47807 | G20: =G13/G7*365 -> 45.913079 | H20: 40 | I20: 40 | J20: 40 | K20: 40 | L20: 40
B21: DIO | C21: =C14/C8*365 -> 69.729614 | D21: =D14/D8*365 -> 68.970661 | E21: =E14/E8*365 -> 90.176471 | F21: =F14/F8*365 -> 89.130066 | G21: =G14/G8*365 -> 86.396715 | H21: 79 | I21: 79 | J21: 79 | K21: 79 | L21: 79
B22: DPO | C22: =C15/C8*365 -> 91.695557 | D22: =D15/D8*365 -> 96.98243 | E22: =E15/E8*365 -> 129.98804 | F22: =F15/F8*365 -> 99.28099 | G22: =G15/G8*365 -> 96.130782 | H22: 95 | I22: 95 | J22: 95 | K22: 95 | L22: 95
B23: Net trade cycle | C23: =C20+C21-C22 -> 25.987063 | D23: =D20+D21-D22 -> 2.6850082 | E23: =E20+E21-E22 -> -15.909108 | F23: =F20+F21-F22 -> 28.327145 | G23: =G20+G21-G22 -> 36.179013 | H23: =H20+H21-H22 -> 24 | I23: =I20+I21-I22 -> 24 | J23: =J20+J21-J22 -> 24 | ... L23: =L20+L21-L22 -> 24
C26: Change in SIP NWC
B27: $ (thousand) | C27: =C6 -> 2022 | D27: =D6 -> 2023 | E27: =E6 -> 2024 | F27: =F6 -> 2025 | G27: =G6 -> 2026 | H27: =H6 -> 2027 | I27: =I6 -> 2028 | J27: =J6 -> 2029 | ... L27: =L6 -> 2031
B28: Change in acc receivable | C28: =Statement!M54 -> -374 | D28: =Statement!N54 -> 911 | E28: =Statement!O54 -> 192 | F28: =Statement!P54 -> -513 | G28: =Statement!Q54 -> -575 | H28: =-(H13-G13) -> -236.46334 | I28: =-(I13-H13) -> -518.88795 | J28: =-(J13-I13) -> -123.19149 | K28: =-(K13-J13) -> 80.285769 | L28: =-(L13-K13) -> 319.11597
B29: Change in inventory | C29: =Statement!M55 -> -361 | D29: =Statement!N55 -> 425 | E29: =Statement!O55 -> -99 | F29: =Statement!P55 -> -201 | G29: =Statement!Q55 -> -131 | H29: =-(H14-G14) -> -352.16581 | I29: =-(I14-H14) -> -247.13921 | J29: =-(J14-I14) -> -69.137815 | K29: =-(K14-J14) -> -17.598887 | L29: =-(L14-K14) -> 70.267266
B30: Change in acc payable | C30: =Statement!M56 -> 228 | D30: =Statement!N56 -> -421 | E30: =Statement!O56 -> 227 | F30: =Statement!P56 -> -242 | G30: =Statement!Q56 -> 66 | H30: =H15-G15 -> 564.66774 | I30: =I15-H15 -> 297.19273 | J30: =J15-I15 -> 83.140411 | K30: =K15-J15 -> 21.163218 | L30: =L15-K15 -> -84.498611
C33: Total change in NWC and less SIP
B34: $ (thousand) | C34: =C6 -> 2022 | D34: =D6 -> 2023 | E34: =E6 -> 2024 | F34: =F6 -> 2025 | G34: =G6 -> 2026 | H34: =H6 -> 2027 | I34: =I6 -> 2028 | J34: =J6 -> 2029 | ... L34: =L6 -> 2031
B35: Total change in NWC | C35: =Statement!M54+Statement!M55+Statement!M56+Statement!M57 -> -643 | D35: =Statement!N54+Statement!N55+Statement!N56+Statement!N57 -> 1162 | E35: =Statement!O54+Statement!O55+Statement!O56+Statement!O57 -> 386 | F35: =Statement!P54+Statement!P55+Statement!P56+Statement!P57 -> -965 | G35: =Statement!Q54+Statement!Q55+Statement!Q56+Statement!Q57 -> -159 | H35: =H36+H28+H29+H30 -> 299.14815 | I35: =I36+I28+I29+I30 -> -51.027823 | J35: =J36+J28+J29+J30 -> 331.10016 | K35: =K36+K28+K29+K30 -> 509.48701 | L35: =L36+L28+L29+L30 -> 672.28286
B36: Change in NWC less SIP | C36: =C35-C28-C29-C30 -> -136 | D36: =D35-D28-D29-D30 -> 247 | E36: =E35-E28-E29-E30 -> 66 | F36: =F35-F28-F29-F30 -> -9 | G36: =G35-G28-G29-G30 -> 481 | H36: =H7*H37 -> 323.10956 | I36: =I7*I37 -> 417.80661 | J36: =J7*J37 -> 440.28906 | K36: =K7*K37 -> 425.6369 | L36: =L7*L37 -> 367.39824
B37: % of revenue | C37: =C36/C7 -> -0.011662808 | D37: =D36/D7 -> 0.033450704 | E37: =E36/E7 -> 0.010074798 | F37: =F36/F7 -> -0.00098933714 | G37: =G36/G7 -> 0.039442394 | H37: 0.02 | I37: 0.02 | J37: 0.02 | K37: 0.02 | L37: 0.02
C40: Investments
B41: $ (thousand) | C41: =C6 -> 2022 | D41: =D6 -> 2023 | E41: =E6 -> 2024 | F41: =F6 -> 2025 | G41: =G6 -> 2026 | H41: =H6 -> 2027 | I41: =I6 -> 2028 | J41: =J6 -> 2029 | ... L41: =L6 -> 2031
B42: D&A | C42: =Statement!M52 -> 451 | D42: =Statement!N52 -> 513 | E42: =Statement!O52 -> 264 | F42: =Statement!P52 -> 251 | G42: =Statement!Q52 -> 276 | H42: =H7*H43 -> 484.66434 | I42: =I7*I43 -> 626.70992 | J42: =J7*J43 -> 660.43359 | K42: =K7*K43 -> 638.45536 | L42: =L7*L43 -> 551.09736
B43: % of Revenue | C43: =C42/C7 -> 0.038675928 | D43: =D42/D7 -> 0.06947454 | E43: =E42/E7 -> 0.040299191 | F43: =F42/F7 -> 0.027591514 | G43: =G42/G7 -> 0.022632226 | H43: 0.03 | I43: 0.03 | J43: 0.03 | K43: 0.03 | L43: 0.03
B44: % of CapEx | C44: =C42/C45 -> 1.183727 | D44: =D42/D45 -> 1.6234177 | E44: =E42/E45 -> 1.0393701 | F44: =F42/F45 -> 0.94716981 | G44: =G42/G45 -> 0.48506151 | H44: =H42/H45 -> 0.66666667 | I44: =I42/I45 -> 0.66666667 | J44: =J42/J45 -> 0.66666667 | ... L44: =L42/L45 -> 0.66666667
B45: CapEx | C45: =-Statement!M108 -> 381 | D45: =-Statement!N108 -> 316 | E45: =-Statement!O108 -> 254 | F45: =-Statement!P108 -> 265 | G45: =-Statement!Q108 -> 569 | H45: =H7*H46 -> 726.99651 | I45: =I7*I46 -> 940.06487 | J45: =J7*J46 -> 990.65038 | K45: =K7*K46 -> 957.68304 | L45: =L7*L46 -> 826.64604
B46: % of Revenue | C46: =C45/C7 -> 0.032673013 | D46: =D45/D7 -> 0.042795233 | E46: =E45/E7 -> 0.038772706 | F46: =F45/F7 -> 0.029130483 | G46: =G45/G7 -> 0.046658467 | H46: 0.045 | I46: 0.045 | J46: 0.045 | K46: 0.045 | L46: 0.045

Sheet FCF & Other
B1: Results
C2: History | H2: Forecast
C4: Income statement
B5: $ (thousand) | C5: =Revenue!C5 -> 2022 | D5: =Revenue!D5 -> 2023 | E5: =Revenue!E5 -> 2024 | F5: =Revenue!F5 -> 2025 | G5: =Revenue!G5 -> 2026 | H5: =G5+1 -> 2027 | I5: =H5+1 -> 2028 | J5: =I5+1 -> 2029 | K5: =J5+1 -> 2030 | L5: =K5+1 -> 2031
